{
  "version": 8,
  "blockIdVersion": 11,
  "anchorX": 0,
  "anchorY": 0,
  "anchorZ": 0,
  "blocks": [
    {
      "x": -8,
      "y": 48,
      "z": 7,
      "name": "Plant_Moss_Wall_Green_Dark",
      "rotation": 3
    },
    {
      "x": -7,
      "y": 48,
      "z": -8,
      "name": "Plant_Moss_Wall_Green_Dark",
      "rotation": 2
    },
    {
      "x": -7,
      "y": 46,
      "z": -7,
      "name": "Rock_Shale_Brick_Smooth"
    },
    {
      "x": -7,
      "y": 47,
      "z": -7,
      "name": "Deko_Block_Test"
    },
    {
      "x": -7,
      "y": 48,
      "z": -7,
      "name": "Rock_Shale_Brick_Smooth",
      "rotation": 3
    },
    {
      "x": -7,
      "y": 49,
      "z": -7,
      "name": "Plant_Moss_Rug_Green_Dark"
    },
    {
      "x": -7,
      "y": 48,
      "z": -6,
      "name": "Plant_Moss_Wall_Green_Dark",
      "rotation": 3
    },
    {
      "x": -7,
      "y": 49,
      "z": -6,
      "name": "Plant_Moss_Wall_Green_Dark",
      "rotation": 3
    },
    {
      "x": -7,
      "y": 47,
      "z": -2,
      "name": "Plant_Moss_Wall_Green_Dark",
      "rotation": 3
    },
    {
      "x": -7,
      "y": 0,
      "z": 1,
      "name": "Metal_Iron_Glowing_Pipe",
      "support": 15
    },
    {
      "x": -7,
      "y": 1,
      "z": 1,
      "name": "Metal_Iron_Glowing_Pipe",
      "support": 15
    },
    {
      "x": -7,
      "y": 2,
      "z": 1,
      "name": "Metal_Iron_Glowing_Pipe",
      "support": 15
    },
    {
      "x": -7,
      "y": 3,
      "z": 1,
      "name": "Metal_Iron_Glowing_Pipe",
      "support": 15
    },
    {
      "x": -7,
      "y": 4,
      "z": 1,
      "name": "Metal_Iron_Glowing_Pipe",
      "support": 15
    },
    {
      "x": -7,
      "y": 5,
      "z": 1,
      "name": "Metal_Iron_Glowing_Pipe_Corner",
      "support": 15,
      "rotation": 14
    },
    {
      "x": -7,
      "y": 21,
      "z": 1,
      "name": "Plant_Moss_Wall_Green_Dark",
      "support": 15,
      "rotation": 3
    },
    {
      "x": -7,
      "y": 5,
      "z": 2,
      "name": "Metal_Iron_Glowing_Pipe",
      "support": 15,
      "rotation": 4
    },
    {
      "x": -7,
      "y": 5,
      "z": 3,
      "name": "Metal_Iron_Glowing_Pipe_Corner",
      "support": 15,
      "rotation": 19
    },
    {
      "x": -7,
      "y": 46,
      "z": 3,
      "name": "Metal_Iron_Glowing_Pipe_Corner",
      "rotation": 3
    },
    {
      "x": -7,
      "y": 47,
      "z": 3,
      "name": "Metal_Iron_Glowing_Pipe"
    },
    {
      "x": -7,
      "y": 48,
      "z": 3,
      "name": "Metal_Iron_Glowing_Pipe_Corner",
      "support": 15,
      "rotation": 9
    },
    {
      "x": -7,
      "y": 46,
      "z": 7,
      "name": "Rock_Shale_Brick_Smooth"
    },
    {
      "x": -7,
      "y": 47,
      "z": 7,
      "name": "Deko_Block_Test"
    },
    {
      "x": -7,
      "y": 48,
      "z": 7,
      "name": "Rock_Shale_Brick_Smooth"
    },
    {
      "x": -7,
      "y": 49,
      "z": 7,
      "name": "Plant_Moss_Rug_Green_Dark"
    },
    {
      "x": -7,
      "y": 48,
      "z": 8,
      "name": "Plant_Moss_Wall_Green_Dark"
    },
    {
      "x": -6,
      "y": 45,
      "z": -6,
      "name": "Rock_Shale_Brick_Smooth"
    },
    {
      "x": -6,
      "y": 46,
      "z": -6,
      "name": "Rock_Shale_Brick_Smooth"
    },
    {
      "x": -6,
      "y": 47,
      "z": -6,
      "name": "Rock_Shale_Brick_Smooth"
    },
    {
      "x": -6,
      "y": 48,
      "z": -6,
      "name": "Rock_Shale_Brick_Smooth",
      "rotation": 3
    },
    {
      "x": -6,
      "y": 49,
      "z": -6,
      "name": "Rock_Shale_Brick_Smooth",
      "rotation": 3
    },
    {
      "x": -6,
      "y": 50,
      "z": -6,
      "name": "Plant_Moss_Rug_Green_Dark"
    },
    {
      "x": -6,
      "y": 47,
      "z": -5,
      "name": "Rock_Shale_Brick_Smooth"
    },
    {
      "x": -6,
      "y": 47,
      "z": -4,
      "name": "Rock_Shale_Brick_Smooth"
    },
    {
      "x": -6,
      "y": 49,
      "z": -4,
      "name": "Plant_Moss_Wall_Green_Dark",
      "rotation": 3
    },
    {
      "x": -6,
      "y": 47,
      "z": -3,
      "name": "Rock_Shale_Brick_Smooth",
      "support": 15
    },
    {
      "x": -6,
      "y": 47,
      "z": -2,
      "name": "Rock_Shale_Brick_Smooth"
    },
    {
      "x": -6,
      "y": 48,
      "z": -2,
      "name": "Plant_Moss_Rug_Green_Dark"
    },
    {
      "x": -6,
      "y": 47,
      "z": -1,
      "name": "Rock_Shale_Brick_Smooth"
    },
    {
      "x": -6,
      "y": 48,
      "z": -1,
      "name": "Plant_Moss_Rug_Green_Dark"
    },
    {
      "x": -6,
      "y": 0,
      "z": 0,
      "name": "Rock_Shale_Cobble"
    },
    {
      "x": -6,
      "y": 1,
      "z": 0,
      "name": "Rock_Shale_Cobble"
    },
    {
      "x": -6,
      "y": 2,
      "z": 0,
      "name": "Rock_Shale_Cobble"
    },
    {
      "x": -6,
      "y": 3,
      "z": 0,
      "name": "Rock_Shale_Cobble"
    },
    {
      "x": -6,
      "y": 4,
      "z": 0,
      "name": "Rock_Shale_Cobble"
    },
    {
      "x": -6,
      "y": 5,
      "z": 0,
      "name": "Build_Lightsource_Cyan",
      "rotation": 5
    },
    {
      "x": -6,
      "y": 6,
      "z": 0,
      "name": "Build_Lightsource_Cyan",
      "rotation": 5
    },
    {
      "x": -6,
      "y": 7,
      "z": 0,
      "name": "Build_Lightsource_Cyan",
      "rotation": 5
    },
    {
      "x": -6,
      "y": 8,
      "z": 0,
      "name": "Build_Lightsource_Cyan",
      "rotation": 5
    },
    {
      "x": -6,
      "y": 9,
      "z": 0,
      "name": "Build_Lightsource_Cyan",
      "rotation": 5
    },
    {
      "x": -6,
      "y": 10,
      "z": 0,
      "name": "Build_Lightsource_Cyan",
      "rotation": 5
    },
    {
      "x": -6,
      "y": 11,
      "z": 0,
      "name": "Build_Lightsource_Cyan"
    },
    {
      "x": -6,
      "y": 12,
      "z": 0,
      "name": "Rock_Shale_Cobble"
    },
    {
      "x": -6,
      "y": 13,
      "z": 0,
      "name": "Rock_Shale_Cobble"
    },
    {
      "x": -6,
      "y": 14,
      "z": 0,
      "name": "Rock_Shale_Cobble"
    },
    {
      "x": -6,
      "y": 15,
      "z": 0,
      "name": "Rock_Shale_Cobble"
    },
    {
      "x": -6,
      "y": 16,
      "z": 0,
      "name": "Rock_Shale_Cobble"
    },
    {
      "x": -6,
      "y": 17,
      "z": 0,
      "name": "Rock_Shale_Cobble"
    },
    {
      "x": -6,
      "y": 18,
      "z": 0,
      "name": "Rock_Shale_Cobble"
    },
    {
      "x": -6,
      "y": 19,
      "z": 0,
      "name": "Rock_Shale_Cobble"
    },
    {
      "x": -6,
      "y": 20,
      "z": 0,
      "name": "Rock_Shale_Cobble"
    },
    {
      "x": -6,
      "y": 21,
      "z": 0,
      "name": "Rock_Shale_Cobble"
    },
    {
      "x": -6,
      "y": 47,
      "z": 0,
      "name": "Rock_Shale_Brick_Smooth"
    },
    {
      "x": -6,
      "y": 0,
      "z": 1,
      "name": "Rock_Shale_Cobble"
    },
    {
      "x": -6,
      "y": 1,
      "z": 1,
      "name": "Rock_Shale_Cobble"
    },
    {
      "x": -6,
      "y": 2,
      "z": 1,
      "name": "Rock_Shale_Cobble"
    },
    {
      "x": -6,
      "y": 3,
      "z": 1,
      "name": "Rock_Shale_Cobble"
    },
    {
      "x": -6,
      "y": 4,
      "z": 1,
      "name": "Rock_Shale_Cobble"
    },
    {
      "x": -6,
      "y": 5,
      "z": 1,
      "name": "Rock_Shale_Cobble"
    },
    {
      "x": -6,
      "y": 6,
      "z": 1,
      "name": "Rock_Shale_Cobble"
    },
    {
      "x": -6,
      "y": 7,
      "z": 1,
      "name": "Rock_Shale_Cobble"
    },
    {
      "x": -6,
      "y": 8,
      "z": 1,
      "name": "Rock_Shale_Cobble"
    },
    {
      "x": -6,
      "y": 9,
      "z": 1,
      "name": "Rock_Shale_Cobble"
    },
    {
      "x": -6,
      "y": 10,
      "z": 1,
      "name": "Rock_Shale_Cobble"
    },
    {
      "x": -6,
      "y": 11,
      "z": 1,
      "name": "Rock_Shale_Cobble"
    },
    {
      "x": -6,
      "y": 12,
      "z": 1,
      "name": "Rock_Shale_Cobble"
    },
    {
      "x": -6,
      "y": 13,
      "z": 1,
      "name": "Rock_Shale_Cobble"
    },
    {
      "x": -6,
      "y": 14,
      "z": 1,
      "name": "Rock_Shale_Cobble"
    },
    {
      "x": -6,
      "y": 15,
      "z": 1,
      "name": "Rock_Shale_Cobble"
    },
    {
      "x": -6,
      "y": 16,
      "z": 1,
      "name": "Rock_Shale_Cobble"
    },
    {
      "x": -6,
      "y": 17,
      "z": 1,
      "name": "Rock_Shale_Cobble"
    },
    {
      "x": -6,
      "y": 18,
      "z": 1,
      "name": "Build_Lightsource_Cyan"
    },
    {
      "x": -6,
      "y": 19,
      "z": 1,
      "name": "Build_Lightsource_Cyan"
    },
    {
      "x": -6,
      "y": 20,
      "z": 1,
      "name": "Build_Lightsource_Cyan",
      "rotation": 5
    },
    {
      "x": -6,
      "y": 21,
      "z": 1,
      "name": "Build_Lightsource_Cyan"
    },
    {
      "x": -6,
      "y": 22,
      "z": 1,
      "name": "Plant_Moss_Rug_Green_Dark",
      "support": 15
    },
    {
      "x": -6,
      "y": 44,
      "z": 1,
      "name": "Metal_Iron_Glowing_Pipe_Corner",
      "rotation": 3
    },
    {
      "x": -6,
      "y": 45,
      "z": 1,
      "name": "Metal_Iron_Glowing_Pipe_Corner",
      "rotation": 8
    },
    {
      "x": -6,
      "y": 47,
      "z": 1,
      "name": "Rock_Shale_Brick_Smooth"
    },
    {
      "x": -6,
      "y": 49,
      "z": 1,
      "name": "Metal_Iron_Glowing_Pipe_Corner",
      "rotation": 18
    },
    {
      "x": -6,
      "y": 0,
      "z": 2,
      "name": "Rock_Shale_Cobble"
    },
    {
      "x": -6,
      "y": 1,
      "z": 2,
      "name": "Rock_Shale_Cobble"
    },
    {
      "x": -6,
      "y": 2,
      "z": 2,
      "name": "Rock_Shale_Cobble"
    },
    {
      "x": -6,
      "y": 3,
      "z": 2,
      "name": "Rock_Shale_Cobble"
    },
    {
      "x": -6,
      "y": 4,
      "z": 2,
      "name": "Rock_Shale_Cobble"
    },
    {
      "x": -6,
      "y": 5,
      "z": 2,
      "name": "Rock_Shale_Cobble"
    },
    {
      "x": -6,
      "y": 6,
      "z": 2,
      "name": "Rock_Shale_Cobble"
    },
    {
      "x": -6,
      "y": 7,
      "z": 2,
      "name": "Rock_Shale_Cobble"
    },
    {
      "x": -6,
      "y": 8,
      "z": 2,
      "name": "Rock_Shale_Cobble"
    },
    {
      "x": -6,
      "y": 9,
      "z": 2,
      "name": "Rock_Shale_Cobble"
    },
    {
      "x": -6,
      "y": 10,
      "z": 2,
      "name": "Rock_Shale_Cobble"
    },
    {
      "x": -6,
      "y": 11,
      "z": 2,
      "name": "Rock_Shale_Cobble"
    },
    {
      "x": -6,
      "y": 12,
      "z": 2,
      "name": "Rock_Shale_Cobble"
    },
    {
      "x": -6,
      "y": 13,
      "z": 2,
      "name": "Rock_Shale_Cobble"
    },
    {
      "x": -6,
      "y": 14,
      "z": 2,
      "name": "Rock_Shale_Cobble"
    },
    {
      "x": -6,
      "y": 15,
      "z": 2,
      "name": "Rock_Shale_Cobble"
    },
    {
      "x": -6,
      "y": 16,
      "z": 2,
      "name": "Rock_Shale_Cobble"
    },
    {
      "x": -6,
      "y": 17,
      "z": 2,
      "name": "Rock_Shale_Cobble"
    },
    {
      "x": -6,
      "y": 18,
      "z": 2,
      "name": "Rock_Shale_Cobble"
    },
    {
      "x": -6,
      "y": 19,
      "z": 2,
      "name": "Rock_Shale_Cobble"
    },
    {
      "x": -6,
      "y": 20,
      "z": 2,
      "name": "Rock_Shale_Cobble"
    },
    {
      "x": -6,
      "y": 21,
      "z": 2,
      "name": "Rock_Shale_Cobble"
    },
    {
      "x": -6,
      "y": 45,
      "z": 2,
      "name": "Metal_Iron_Glowing_Pipe",
      "rotation": 4
    },
    {
      "x": -6,
      "y": 47,
      "z": 2,
      "name": "Rock_Shale_Brick_Smooth"
    },
    {
      "x": -6,
      "y": 49,
      "z": 2,
      "name": "Metal_Iron_Glowing_Pipe",
      "rotation": 4
    },
    {
      "x": -6,
      "y": 5,
      "z": 3,
      "name": "Metal_Iron_Glowing_Pipe_Corner",
      "support": 15,
      "rotation": 1
    },
    {
      "x": -6,
      "y": 6,
      "z": 3,
      "name": "Metal_Iron_Glowing_Pipe",
      "support": 15
    },
    {
      "x": -6,
      "y": 7,
      "z": 3,
      "name": "Metal_Iron_Glowing_Pipe",
      "support": 15
    },
    {
      "x": -6,
      "y": 8,
      "z": 3,
      "name": "Metal_Iron_Glowing_Pipe",
      "support": 15
    },
    {
      "x": -6,
      "y": 9,
      "z": 3,
      "name": "Metal_Iron_Glowing_Pipe",
      "support": 15
    },
    {
      "x": -6,
      "y": 10,
      "z": 3,
      "name": "Metal_Iron_Glowing_Pipe",
      "support": 15
    },
    {
      "x": -6,
      "y": 11,
      "z": 3,
      "name": "Metal_Iron_Glowing_Pipe",
      "support": 15
    },
    {
      "x": -6,
      "y": 12,
      "z": 3,
      "name": "Metal_Iron_Glowing_Pipe",
      "support": 15
    },
    {
      "x": -6,
      "y": 13,
      "z": 3,
      "name": "Metal_Iron_Glowing_Pipe",
      "support": 15
    },
    {
      "x": -6,
      "y": 14,
      "z": 3,
      "name": "Metal_Iron_Glowing_Pipe",
      "support": 15
    },
    {
      "x": -6,
      "y": 15,
      "z": 3,
      "name": "Metal_Iron_Glowing_Pipe",
      "support": 15
    },
    {
      "x": -6,
      "y": 16,
      "z": 3,
      "name": "Metal_Iron_Glowing_Pipe_Corner",
      "support": 15,
      "rotation": 9
    },
    {
      "x": -6,
      "y": 45,
      "z": 3,
      "name": "Metal_Iron_Glowing_Pipe_Corner"
    },
    {
      "x": -6,
      "y": 46,
      "z": 3,
      "name": "Metal_Iron_Glowing_Pipe_Corner",
      "rotation": 11
    },
    {
      "x": -6,
      "y": 47,
      "z": 3,
      "name": "Rock_Shale_Brick_Smooth"
    },
    {
      "x": -6,
      "y": 48,
      "z": 3,
      "name": "Metal_Iron_Glowing_Pipe_Corner",
      "rotation": 1
    },
    {
      "x": -6,
      "y": 49,
      "z": 3,
      "name": "Metal_Iron_Glowing_Pipe_Corner",
      "rotation": 10
    },
    {
      "x": -6,
      "y": 47,
      "z": 4,
      "name": "Rock_Shale_Brick_Smooth"
    },
    {
      "x": -6,
      "y": 47,
      "z": 5,
      "name": "Rock_Shale_Brick_Smooth"
    },
    {
      "x": -6,
      "y": 45,
      "z": 6,
      "name": "Rock_Shale_Brick_Smooth"
    },
    {
      "x": -6,
      "y": 46,
      "z": 6,
      "name": "Rock_Shale_Brick_Smooth"
    },
    {
      "x": -6,
      "y": 47,
      "z": 6,
      "name": "Rock_Shale_Brick_Smooth"
    },
    {
      "x": -6,
      "y": 48,
      "z": 6,
      "name": "Rock_Shale_Brick_Smooth"
    },
    {
      "x": -6,
      "y": 49,
      "z": 6,
      "name": "Rock_Shale_Brick_Smooth"
    },
    {
      "x": -6,
      "y": 50,
      "z": 6,
      "name": "Plant_Moss_Rug_Green_Dark"
    },
    {
      "x": -5,
      "y": 47,
      "z": -6,
      "name": "Rock_Shale_Brick_Smooth"
    },
    {
      "x": -5,
      "y": 44,
      "z": -5,
      "name": "Rock_Shale_Brick_Smooth"
    },
    {
      "x": -5,
      "y": 45,
      "z": -5,
      "name": "Rock_Shale_Cobble"
    },
    {
      "x": -5,
      "y": 46,
      "z": -5,
      "name": "Rock_Shale_Cobble"
    },
    {
      "x": -5,
      "y": 47,
      "z": -5,
      "name": "Rock_Shale_Brick_Smooth"
    },
    {
      "x": -5,
      "y": 48,
      "z": -5,
      "name": "Rock_Shale_Cobble",
      "rotation": 3
    },
    {
      "x": -5,
      "y": 49,
      "z": -5,
      "name": "Rock_Shale_Cobble",
      "rotation": 3
    },
    {
      "x": -5,
      "y": 50,
      "z": -5,
      "name": "Rock_Shale_Brick_Smooth",
      "rotation": 3
    },
    {
      "x": -5,
      "y": 51,
      "z": -5,
      "name": "Rock_Shale_Brick_Smooth",
      "rotation": 3
    },
    {
      "x": -5,
      "y": 45,
      "z": -4,
      "name": "Rock_Shale_Cobble"
    },
    {
      "x": -5,
      "y": 46,
      "z": -4,
      "name": "Plant_Moss_Rug_Green_Dark"
    },
    {
      "x": -5,
      "y": 47,
      "z": -4,
      "name": "Rock_Shale_Brick_Smooth"
    },
    {
      "x": -5,
      "y": 49,
      "z": -4,
      "name": "Rock_Shale_Cobble",
      "rotation": 3
    },
    {
      "x": -5,
      "y": 50,
      "z": -4,
      "name": "Plant_Moss_Rug_Green_Dark"
    },
    {
      "x": -5,
      "y": 46,
      "z": -3,
      "name": "Rock_Shale_Cobble",
      "support": 15
    },
    {
      "x": -5,
      "y": 47,
      "z": -3,
      "name": "Rock_Shale_Brick_Smooth",
      "support": 15
    },
    {
      "x": -5,
      "y": 48,
      "z": -3,
      "name": "Rock_Shale_Cobble",
      "rotation": 3
    },
    {
      "x": -5,
      "y": 45,
      "z": -2,
      "name": "Rock_Shale_Cobble"
    },
    {
      "x": -5,
      "y": 46,
      "z": -2,
      "name": "Rock_Shale_Cobble"
    },
    {
      "x": -5,
      "y": 47,
      "z": -2,
      "name": "Rock_Shale_Brick_Smooth"
    },
    {
      "x": -5,
      "y": 48,
      "z": -2,
      "name": "Rock_Shale_Cobble",
      "support": 15,
      "rotation": 3
    },
    {
      "x": -5,
      "y": 49,
      "z": -2,
      "name": "Rock_Shale_Cobble",
      "rotation": 3
    },
    {
      "x": -5,
      "y": 15,
      "z": -1,
      "name": "Plant_Moss_Wall_Green_Dark",
      "support": 15,
      "rotation": 3
    },
    {
      "x": -5,
      "y": 44,
      "z": -1,
      "name": "Metal_Iron_Glowing_Pipe_Corner",
      "rotation": 25
    },
    {
      "x": -5,
      "y": 45,
      "z": -1,
      "name": "Rock_Shale_Cobble"
    },
    {
      "x": -5,
      "y": 47,
      "z": -1,
      "name": "Rock_Shale_Brick_Smooth"
    },
    {
      "x": -5,
      "y": 48,
      "z": -1,
      "name": "Plant_Moss_Rug_Green_Dark"
    },
    {
      "x": -5,
      "y": 49,
      "z": -1,
      "name": "Rock_Shale_Cobble",
      "rotation": 3
    },
    {
      "x": -5,
      "y": 0,
      "z": 0,
      "name": "Rock_Shale_Cobble"
    },
    {
      "x": -5,
      "y": 1,
      "z": 0,
      "name": "Rock_Shale_Cobble"
    },
    {
      "x": -5,
      "y": 2,
      "z": 0,
      "name": "Rock_Shale_Cobble"
    },
    {
      "x": -5,
      "y": 3,
      "z": 0,
      "name": "Rock_Shale_Cobble"
    },
    {
      "x": -5,
      "y": 4,
      "z": 0,
      "name": "Rock_Shale_Cobble"
    },
    {
      "x": -5,
      "y": 5,
      "z": 0,
      "name": "Rock_Shale_Cobble"
    },
    {
      "x": -5,
      "y": 6,
      "z": 0,
      "name": "Rock_Shale_Cobble"
    },
    {
      "x": -5,
      "y": 7,
      "z": 0,
      "name": "Rock_Shale_Cobble"
    },
    {
      "x": -5,
      "y": 8,
      "z": 0,
      "name": "Rock_Shale_Cobble"
    },
    {
      "x": -5,
      "y": 9,
      "z": 0,
      "name": "Rock_Shale_Cobble"
    },
    {
      "x": -5,
      "y": 10,
      "z": 0,
      "name": "Rock_Shale_Cobble"
    },
    {
      "x": -5,
      "y": 11,
      "z": 0,
      "name": "Rock_Shale_Cobble"
    },
    {
      "x": -5,
      "y": 12,
      "z": 0,
      "name": "Rock_Shale_Cobble"
    },
    {
      "x": -5,
      "y": 13,
      "z": 0,
      "name": "Rock_Shale_Cobble"
    },
    {
      "x": -5,
      "y": 14,
      "z": 0,
      "name": "Rock_Shale_Cobble"
    },
    {
      "x": -5,
      "y": 15,
      "z": 0,
      "name": "Rock_Shale_Cobble"
    },
    {
      "x": -5,
      "y": 16,
      "z": 0,
      "name": "Rock_Shale_Cobble"
    },
    {
      "x": -5,
      "y": 17,
      "z": 0,
      "name": "Rock_Shale_Cobble"
    },
    {
      "x": -5,
      "y": 18,
      "z": 0,
      "name": "Rock_Shale_Cobble"
    },
    {
      "x": -5,
      "y": 19,
      "z": 0,
      "name": "Rock_Shale_Cobble"
    },
    {
      "x": -5,
      "y": 20,
      "z": 0,
      "name": "Rock_Shale_Cobble"
    },
    {
      "x": -5,
      "y": 21,
      "z": 0,
      "name": "Rock_Shale_Cobble"
    },
    {
      "x": -5,
      "y": 22,
      "z": 0,
      "name": "Plant_Moss_Rug_Green_Dark",
      "support": 15
    },
    {
      "x": -5,
      "y": 44,
      "z": 0,
      "name": "Metal_Iron_Glowing_Pipe",
      "rotation": 4
    },
    {
      "x": -5,
      "y": 47,
      "z": 0,
      "name": "Rock_Shale_Brick_Smooth"
    },
    {
      "x": -5,
      "y": 48,
      "z": 0,
      "name": "Plant_Moss_Rug_Green_Dark"
    },
    {
      "x": -5,
      "y": 50,
      "z": 0,
      "name": "Rock_Shale_Cobble_Half"
    },
    {
      "x": -5,
      "y": 0,
      "z": 1,
      "name": "Rock_Shale_Cobble"
    },
    {
      "x": -5,
      "y": 1,
      "z": 1,
      "name": "Rock_Shale_Cobble"
    },
    {
      "x": -5,
      "y": 2,
      "z": 1,
      "name": "Rock_Shale_Cobble"
    },
    {
      "x": -5,
      "y": 3,
      "z": 1,
      "name": "Rock_Shale_Cobble"
    },
    {
      "x": -5,
      "y": 4,
      "z": 1,
      "name": "Build_Lightsource_Cyan",
      "rotation": 4
    },
    {
      "x": -5,
      "y": 5,
      "z": 1,
      "name": "Rock_Shale_Cobble"
    },
    {
      "x": -5,
      "y": 6,
      "z": 1,
      "name": "Rock_Shale_Cobble"
    },
    {
      "x": -5,
      "y": 7,
      "z": 1,
      "name": "Rock_Shale_Cobble"
    },
    {
      "x": -5,
      "y": 8,
      "z": 1,
      "name": "Rock_Shale_Cobble"
    },
    {
      "x": -5,
      "y": 9,
      "z": 1,
      "name": "Rock_Shale_Cobble"
    },
    {
      "x": -5,
      "y": 10,
      "z": 1,
      "name": "Rock_Shale_Cobble"
    },
    {
      "x": -5,
      "y": 11,
      "z": 1,
      "name": "Rock_Shale_Cobble"
    },
    {
      "x": -5,
      "y": 12,
      "z": 1,
      "name": "Rock_Shale_Cobble"
    },
    {
      "x": -5,
      "y": 13,
      "z": 1,
      "name": "Rock_Shale_Cobble"
    },
    {
      "x": -5,
      "y": 14,
      "z": 1,
      "name": "Rock_Shale_Cobble"
    },
    {
      "x": -5,
      "y": 15,
      "z": 1,
      "name": "Rock_Shale_Cobble"
    },
    {
      "x": -5,
      "y": 16,
      "z": 1,
      "name": "Rock_Shale_Cobble"
    },
    {
      "x": -5,
      "y": 17,
      "z": 1,
      "name": "Rock_Shale_Cobble"
    },
    {
      "x": -5,
      "y": 18,
      "z": 1,
      "name": "Rock_Shale_Cobble"
    },
    {
      "x": -5,
      "y": 19,
      "z": 1,
      "name": "Rock_Shale_Cobble"
    },
    {
      "x": -5,
      "y": 20,
      "z": 1,
      "name": "Rock_Shale_Cobble"
    },
    {
      "x": -5,
      "y": 21,
      "z": 1,
      "name": "Build_Lightsource_Cyan",
      "rotation": 5
    },
    {
      "x": -5,
      "y": 22,
      "z": 1,
      "name": "Plant_Moss_Rug_Green_Dark",
      "support": 15
    },
    {
      "x": -5,
      "y": 44,
      "z": 1,
      "name": "Metal_Iron_Glowing_Pipe_Corner",
      "rotation": 16
    },
    {
      "x": -5,
      "y": 45,
      "z": 1,
      "name": "Rock_Shale_Cobble"
    },
    {
      "x": -5,
      "y": 47,
      "z": 1,
      "name": "Rock_Shale_Brick_Smooth"
    },
    {
      "x": -5,
      "y": 49,
      "z": 1,
      "name": "Rock_Shale_Cobble"
    },
    {
      "x": -5,
      "y": 0,
      "z": 2,
      "name": "Build_Lightsource_Cyan"
    },
    {
      "x": -5,
      "y": 1,
      "z": 2,
      "name": "Build_Lightsource_Cyan",
      "rotation": 4
    },
    {
      "x": -5,
      "y": 2,
      "z": 2,
      "name": "Build_Lightsource_Cyan",
      "rotation": 4
    },
    {
      "x": -5,
      "y": 3,
      "z": 2,
      "name": "Build_Lightsource_Cyan",
      "rotation": 4
    },
    {
      "x": -5,
      "y": 4,
      "z": 2,
      "name": "Build_Lightsource_Cyan",
      "rotation": 4
    },
    {
      "x": -5,
      "y": 5,
      "z": 2,
      "name": "Build_Lightsource_Cyan",
      "rotation": 4
    },
    {
      "x": -5,
      "y": 6,
      "z": 2,
      "name": "Build_Lightsource_Cyan",
      "rotation": 4
    },
    {
      "x": -5,
      "y": 7,
      "z": 2,
      "name": "Rock_Shale_Cobble"
    },
    {
      "x": -5,
      "y": 8,
      "z": 2,
      "name": "Rock_Shale_Cobble"
    },
    {
      "x": -5,
      "y": 9,
      "z": 2,
      "name": "Rock_Shale_Cobble"
    },
    {
      "x": -5,
      "y": 10,
      "z": 2,
      "name": "Rock_Shale_Cobble"
    },
    {
      "x": -5,
      "y": 11,
      "z": 2,
      "name": "Rock_Shale_Cobble"
    },
    {
      "x": -5,
      "y": 12,
      "z": 2,
      "name": "Rock_Shale_Cobble"
    },
    {
      "x": -5,
      "y": 13,
      "z": 2,
      "name": "Rock_Shale_Cobble"
    },
    {
      "x": -5,
      "y": 14,
      "z": 2,
      "name": "Rock_Shale_Cobble"
    },
    {
      "x": -5,
      "y": 15,
      "z": 2,
      "name": "Rock_Shale_Cobble"
    },
    {
      "x": -5,
      "y": 16,
      "z": 2,
      "name": "Rock_Shale_Cobble"
    },
    {
      "x": -5,
      "y": 17,
      "z": 2,
      "name": "Rock_Shale_Cobble"
    },
    {
      "x": -5,
      "y": 18,
      "z": 2,
      "name": "Rock_Shale_Cobble"
    },
    {
      "x": -5,
      "y": 19,
      "z": 2,
      "name": "Rock_Shale_Cobble"
    },
    {
      "x": -5,
      "y": 20,
      "z": 2,
      "name": "Rock_Shale_Cobble"
    },
    {
      "x": -5,
      "y": 21,
      "z": 2,
      "name": "Rock_Shale_Cobble"
    },
    {
      "x": -5,
      "y": 22,
      "z": 2,
      "name": "Plant_Moss_Rug_Green_Dark",
      "support": 15
    },
    {
      "x": -5,
      "y": 45,
      "z": 2,
      "name": "Rock_Shale_Cobble"
    },
    {
      "x": -5,
      "y": 46,
      "z": 2,
      "name": "Rock_Shale_Cobble"
    },
    {
      "x": -5,
      "y": 47,
      "z": 2,
      "name": "Rock_Shale_Brick_Smooth"
    },
    {
      "x": -5,
      "y": 48,
      "z": 2,
      "name": "Rock_Shale_Cobble"
    },
    {
      "x": -5,
      "y": 49,
      "z": 2,
      "name": "Rock_Shale_Cobble"
    },
    {
      "x": -5,
      "y": 50,
      "z": 2,
      "name": "Plant_Moss_Rug_Green_Dark"
    },
    {
      "x": -5,
      "y": 16,
      "z": 3,
      "name": "Metal_Iron_Glowing_Pipe",
      "support": 15,
      "rotation": 5
    },
    {
      "x": -5,
      "y": 21,
      "z": 3,
      "name": "Plant_Moss_Wall_Green_Dark",
      "support": 15
    },
    {
      "x": -5,
      "y": 46,
      "z": 3,
      "name": "Rock_Shale_Cobble"
    },
    {
      "x": -5,
      "y": 47,
      "z": 3,
      "name": "Rock_Shale_Brick_Smooth"
    },
    {
      "x": -5,
      "y": 48,
      "z": 3,
      "name": "Rock_Shale_Cobble"
    },
    {
      "x": -5,
      "y": 49,
      "z": 3,
      "name": "Plant_Moss_Wall_Green_Dark"
    },
    {
      "x": -5,
      "y": 51,
      "z": 3,
      "name": "Plant_Moss_Wall_Green_Dark",
      "rotation": 3
    },
    {
      "x": -5,
      "y": 45,
      "z": 4,
      "name": "Rock_Shale_Cobble"
    },
    {
      "x": -5,
      "y": 46,
      "z": 4,
      "name": "Plant_Moss_Rug_Green_Dark"
    },
    {
      "x": -5,
      "y": 47,
      "z": 4,
      "name": "Rock_Shale_Brick_Smooth"
    },
    {
      "x": -5,
      "y": 49,
      "z": 4,
      "name": "Rock_Shale_Cobble"
    },
    {
      "x": -5,
      "y": 44,
      "z": 5,
      "name": "Rock_Shale_Brick_Smooth"
    },
    {
      "x": -5,
      "y": 45,
      "z": 5,
      "name": "Rock_Shale_Cobble"
    },
    {
      "x": -5,
      "y": 46,
      "z": 5,
      "name": "Rock_Shale_Cobble"
    },
    {
      "x": -5,
      "y": 47,
      "z": 5,
      "name": "Rock_Shale_Brick_Smooth"
    },
    {
      "x": -5,
      "y": 48,
      "z": 5,
      "name": "Rock_Shale_Cobble"
    },
    {
      "x": -5,
      "y": 49,
      "z": 5,
      "name": "Rock_Shale_Cobble"
    },
    {
      "x": -5,
      "y": 50,
      "z": 5,
      "name": "Rock_Shale_Brick_Smooth"
    },
    {
      "x": -5,
      "y": 51,
      "z": 5,
      "name": "Rock_Shale_Brick_Smooth"
    },
    {
      "x": -5,
      "y": 47,
      "z": 6,
      "name": "Rock_Shale_Brick_Smooth"
    },
    {
      "x": -5,
      "y": 48,
      "z": 6,
      "name": "Metal_Iron_Glowing_Pipe_Corner"
    },
    {
      "x": -5,
      "y": 49,
      "z": 6,
      "name": "Metal_Iron_Glowing_Pipe_Corner",
      "rotation": 15
    },
    {
      "x": -4,
      "y": 47,
      "z": -6,
      "name": "Rock_Shale_Brick_Smooth"
    },
    {
      "x": -4,
      "y": 45,
      "z": -5,
      "name": "Rock_Shale_Cobble"
    },
    {
      "x": -4,
      "y": 46,
      "z": -5,
      "name": "Plant_Moss_Rug_Green_Dark"
    },
    {
      "x": -4,
      "y": 47,
      "z": -5,
      "name": "Rock_Shale_Brick_Smooth"
    },
    {
      "x": -4,
      "y": 49,
      "z": -5,
      "name": "Rock_Shale_Cobble",
      "rotation": 3
    },
    {
      "x": -4,
      "y": 43,
      "z": -4,
      "name": "Rock_Shale_Brick_Smooth"
    },
    {
      "x": -4,
      "y": 44,
      "z": -4,
      "name": "Rock_Shale_Cobble"
    },
    {
      "x": -4,
      "y": 45,
      "z": -4,
      "name": "Rock_Shale_Cobble"
    },
    {
      "x": -4,
      "y": 46,
      "z": -4,
      "name": "Build_Lightsource_Cyan",
      "rotation": 5
    },
    {
      "x": -4,
      "y": 47,
      "z": -4,
      "name": "Rock_Shale_Brick_Smooth"
    },
    {
      "x": -4,
      "y": 48,
      "z": -4,
      "name": "Build_Lightsource_Cyan",
      "rotation": 7
    },
    {
      "x": -4,
      "y": 49,
      "z": -4,
      "name": "Build_Lightsource_Cyan",
      "rotation": 7
    },
    {
      "x": -4,
      "y": 50,
      "z": -4,
      "name": "Rock_Shale_Cobble",
      "rotation": 3
    },
    {
      "x": -4,
      "y": 51,
      "z": -4,
      "name": "Rock_Shale_Cobble",
      "rotation": 3
    },
    {
      "x": -4,
      "y": 52,
      "z": -4,
      "name": "Rock_Shale_Brick_Smooth",
      "rotation": 3
    },
    {
      "x": -4,
      "y": 53,
      "z": -4,
      "name": "Metal_Iron_Glowing_Pipe_Corner",
      "rotation": 18
    },
    {
      "x": -4,
      "y": 44,
      "z": -3,
      "name": "Rock_Shale_Cobble"
    },
    {
      "x": -4,
      "y": 45,
      "z": -3,
      "name": "Build_Lightsource_Cyan",
      "rotation": 5
    },
    {
      "x": -4,
      "y": 46,
      "z": -3,
      "name": "Rock_Shale_Cobble"
    },
    {
      "x": -4,
      "y": 47,
      "z": -3,
      "name": "Rock_Shale_Brick_Smooth"
    },
    {
      "x": -4,
      "y": 48,
      "z": -3,
      "name": "Rock_Shale_Cobble",
      "rotation": 3
    },
    {
      "x": -4,
      "y": 49,
      "z": -3,
      "name": "Build_Lightsource_Cyan",
      "rotation": 3
    },
    {
      "x": -4,
      "y": 51,
      "z": -3,
      "name": "Rock_Shale_Cobble",
      "rotation": 3
    },
    {
      "x": -4,
      "y": 53,
      "z": -3,
      "name": "Metal_Iron_Glowing_Pipe",
      "rotation": 4
    },
    {
      "x": -4,
      "y": 15,
      "z": -2,
      "name": "Plant_Moss_Wall_Green_Dark",
      "support": 15,
      "rotation": 2
    },
    {
      "x": -4,
      "y": 45,
      "z": -2,
      "name": "Rock_Shale_Cobble"
    },
    {
      "x": -4,
      "y": 46,
      "z": -2,
      "name": "Rock_Shale_Cobble"
    },
    {
      "x": -4,
      "y": 47,
      "z": -2,
      "name": "Rock_Shale_Brick_Smooth"
    },
    {
      "x": -4,
      "y": 48,
      "z": -2,
      "name": "Rock_Shale_Cobble",
      "rotation": 3
    },
    {
      "x": -4,
      "y": 49,
      "z": -2,
      "name": "Rock_Shale_Cobble",
      "rotation": 3
    },
    {
      "x": -4,
      "y": 50,
      "z": -2,
      "name": "Rock_Shale_Cobble",
      "rotation": 3
    },
    {
      "x": -4,
      "y": 53,
      "z": -2,
      "name": "Metal_Iron_Glowing_Pipe_Corner",
      "rotation": 19
    },
    {
      "x": -4,
      "y": 0,
      "z": -1,
      "name": "Rock_Shale_Cobble"
    },
    {
      "x": -4,
      "y": 1,
      "z": -1,
      "name": "Rock_Shale_Cobble"
    },
    {
      "x": -4,
      "y": 2,
      "z": -1,
      "name": "Rock_Shale_Cobble"
    },
    {
      "x": -4,
      "y": 3,
      "z": -1,
      "name": "Rock_Shale_Cobble"
    },
    {
      "x": -4,
      "y": 4,
      "z": -1,
      "name": "Rock_Shale_Cobble"
    },
    {
      "x": -4,
      "y": 5,
      "z": -1,
      "name": "Rock_Shale_Cobble"
    },
    {
      "x": -4,
      "y": 6,
      "z": -1,
      "name": "Rock_Shale_Cobble"
    },
    {
      "x": -4,
      "y": 7,
      "z": -1,
      "name": "Rock_Shale_Cobble"
    },
    {
      "x": -4,
      "y": 8,
      "z": -1,
      "name": "Rock_Shale_Cobble"
    },
    {
      "x": -4,
      "y": 9,
      "z": -1,
      "name": "Rock_Shale_Cobble"
    },
    {
      "x": -4,
      "y": 10,
      "z": -1,
      "name": "Rock_Shale_Cobble"
    },
    {
      "x": -4,
      "y": 11,
      "z": -1,
      "name": "Rock_Shale_Cobble"
    },
    {
      "x": -4,
      "y": 12,
      "z": -1,
      "name": "Rock_Shale_Cobble"
    },
    {
      "x": -4,
      "y": 13,
      "z": -1,
      "name": "Rock_Shale_Cobble"
    },
    {
      "x": -4,
      "y": 14,
      "z": -1,
      "name": "Rock_Shale_Cobble"
    },
    {
      "x": -4,
      "y": 15,
      "z": -1,
      "name": "Rock_Shale_Cobble"
    },
    {
      "x": -4,
      "y": 16,
      "z": -1,
      "name": "Plant_Moss_Rug_Green_Dark",
      "support": 15
    },
    {
      "x": -4,
      "y": 44,
      "z": -1,
      "name": "Rock_Shale_Cobble"
    },
    {
      "x": -4,
      "y": 45,
      "z": -1,
      "name": "Rock_Shale_Cobble"
    },
    {
      "x": -4,
      "y": 46,
      "z": -1,
      "name": "Build_Lightsource_Cyan",
      "rotation": 5
    },
    {
      "x": -4,
      "y": 47,
      "z": -1,
      "name": "Rock_Shale_Brick_Smooth"
    },
    {
      "x": -4,
      "y": 48,
      "z": -1,
      "name": "Build_Lightsource_Cyan",
      "support": 15,
      "rotation": 7
    },
    {
      "x": -4,
      "y": 49,
      "z": -1,
      "name": "Rock_Shale_Cobble",
      "rotation": 3
    },
    {
      "x": -4,
      "y": 50,
      "z": -1,
      "name": "Rock_Shale_Cobble",
      "rotation": 3
    },
    {
      "x": -4,
      "y": 51,
      "z": -1,
      "name": "Rock_Shale_Cobble",
      "rotation": 2
    },
    {
      "x": -4,
      "y": 0,
      "z": 0,
      "name": "Rock_Shale_Cobble"
    },
    {
      "x": -4,
      "y": 1,
      "z": 0,
      "name": "Rock_Shale_Cobble"
    },
    {
      "x": -4,
      "y": 2,
      "z": 0,
      "name": "Rock_Shale_Cobble"
    },
    {
      "x": -4,
      "y": 3,
      "z": 0,
      "name": "Rock_Shale_Cobble"
    },
    {
      "x": -4,
      "y": 4,
      "z": 0,
      "name": "Rock_Shale_Cobble"
    },
    {
      "x": -4,
      "y": 5,
      "z": 0,
      "name": "Rock_Shale_Cobble"
    },
    {
      "x": -4,
      "y": 6,
      "z": 0,
      "name": "Rock_Shale_Cobble"
    },
    {
      "x": -4,
      "y": 7,
      "z": 0,
      "name": "Rock_Shale_Cobble"
    },
    {
      "x": -4,
      "y": 8,
      "z": 0,
      "name": "Rock_Shale_Cobble"
    },
    {
      "x": -4,
      "y": 9,
      "z": 0,
      "name": "Rock_Shale_Cobble"
    },
    {
      "x": -4,
      "y": 10,
      "z": 0,
      "name": "Rock_Shale_Cobble"
    },
    {
      "x": -4,
      "y": 11,
      "z": 0,
      "name": "Rock_Shale_Cobble"
    },
    {
      "x": -4,
      "y": 12,
      "z": 0,
      "name": "Rock_Shale_Cobble"
    },
    {
      "x": -4,
      "y": 13,
      "z": 0,
      "name": "Rock_Shale_Cobble"
    },
    {
      "x": -4,
      "y": 14,
      "z": 0,
      "name": "Rock_Shale_Cobble"
    },
    {
      "x": -4,
      "y": 15,
      "z": 0,
      "name": "Rock_Shale_Cobble"
    },
    {
      "x": -4,
      "y": 16,
      "z": 0,
      "name": "Rock_Shale_Cobble"
    },
    {
      "x": -4,
      "y": 17,
      "z": 0,
      "name": "Rock_Shale_Cobble"
    },
    {
      "x": -4,
      "y": 18,
      "z": 0,
      "name": "Rock_Shale_Cobble"
    },
    {
      "x": -4,
      "y": 19,
      "z": 0,
      "name": "Rock_Shale_Cobble"
    },
    {
      "x": -4,
      "y": 20,
      "z": 0,
      "name": "Rock_Shale_Cobble"
    },
    {
      "x": -4,
      "y": 21,
      "z": 0,
      "name": "Rock_Shale_Cobble"
    },
    {
      "x": -4,
      "y": 22,
      "z": 0,
      "name": "Metal_Iron_Glowing_Pipe",
      "support": 15
    },
    {
      "x": -4,
      "y": 23,
      "z": 0,
      "name": "Metal_Iron_Glowing_Pipe",
      "support": 15
    },
    {
      "x": -4,
      "y": 24,
      "z": 0,
      "name": "Metal_Iron_Glowing_Pipe",
      "support": 15
    },
    {
      "x": -4,
      "y": 25,
      "z": 0,
      "name": "Metal_Iron_Glowing_Pipe",
      "support": 15
    },
    {
      "x": -4,
      "y": 26,
      "z": 0,
      "name": "Metal_Iron_Glowing_Pipe",
      "support": 15
    },
    {
      "x": -4,
      "y": 27,
      "z": 0,
      "name": "Metal_Iron_Glowing_Pipe_Corner",
      "support": 15,
      "rotation": 9
    },
    {
      "x": -4,
      "y": 44,
      "z": 0,
      "name": "Rock_Shale_Cobble"
    },
    {
      "x": -4,
      "y": 45,
      "z": 0,
      "name": "Build_Lightsource_Cyan",
      "rotation": 5
    },
    {
      "x": -4,
      "y": 46,
      "z": 0,
      "name": "Build_Lightsource_Cyan",
      "rotation": 5
    },
    {
      "x": -4,
      "y": 47,
      "z": 0,
      "name": "Rock_Shale_Brick_Smooth"
    },
    {
      "x": -4,
      "y": 48,
      "z": 0,
      "name": "Build_Lightsource_Cyan",
      "rotation": 7
    },
    {
      "x": -4,
      "y": 49,
      "z": 0,
      "name": "Build_Lightsource_Cyan",
      "rotation": 7
    },
    {
      "x": -4,
      "y": 50,
      "z": 0,
      "name": "Rock_Shale_Cobble",
      "rotation": 3
    },
    {
      "x": -4,
      "y": 51,
      "z": 0,
      "name": "Rock_Shale_Cobble",
      "rotation": 3
    },
    {
      "x": -4,
      "y": 0,
      "z": 1,
      "name": "Rock_Shale_Cobble"
    },
    {
      "x": -4,
      "y": 1,
      "z": 1,
      "name": "Rock_Shale_Cobble"
    },
    {
      "x": -4,
      "y": 2,
      "z": 1,
      "name": "Rock_Shale_Cobble"
    },
    {
      "x": -4,
      "y": 3,
      "z": 1,
      "name": "Rock_Shale_Cobble"
    },
    {
      "x": -4,
      "y": 4,
      "z": 1,
      "name": "Rock_Shale_Cobble"
    },
    {
      "x": -4,
      "y": 5,
      "z": 1,
      "name": "Rock_Shale_Cobble"
    },
    {
      "x": -4,
      "y": 6,
      "z": 1,
      "name": "Rock_Shale_Cobble"
    },
    {
      "x": -4,
      "y": 7,
      "z": 1,
      "name": "Rock_Shale_Cobble"
    },
    {
      "x": -4,
      "y": 8,
      "z": 1,
      "name": "Rock_Shale_Cobble"
    },
    {
      "x": -4,
      "y": 9,
      "z": 1,
      "name": "Rock_Shale_Cobble"
    },
    {
      "x": -4,
      "y": 10,
      "z": 1,
      "name": "Rock_Shale_Cobble"
    },
    {
      "x": -4,
      "y": 11,
      "z": 1,
      "name": "Rock_Shale_Cobble"
    },
    {
      "x": -4,
      "y": 12,
      "z": 1,
      "name": "Rock_Shale_Cobble"
    },
    {
      "x": -4,
      "y": 13,
      "z": 1,
      "name": "Rock_Shale_Cobble"
    },
    {
      "x": -4,
      "y": 14,
      "z": 1,
      "name": "Rock_Shale_Cobble"
    },
    {
      "x": -4,
      "y": 15,
      "z": 1,
      "name": "Rock_Shale_Cobble"
    },
    {
      "x": -4,
      "y": 16,
      "z": 1,
      "name": "Rock_Shale_Cobble"
    },
    {
      "x": -4,
      "y": 17,
      "z": 1,
      "name": "Rock_Shale_Cobble"
    },
    {
      "x": -4,
      "y": 18,
      "z": 1,
      "name": "Rock_Shale_Cobble"
    },
    {
      "x": -4,
      "y": 19,
      "z": 1,
      "name": "Rock_Shale_Cobble"
    },
    {
      "x": -4,
      "y": 20,
      "z": 1,
      "name": "Rock_Shale_Cobble"
    },
    {
      "x": -4,
      "y": 21,
      "z": 1,
      "name": "Build_Lightsource_Cyan",
      "rotation": 5
    },
    {
      "x": -4,
      "y": 25,
      "z": 1,
      "name": "Plant_Moss_Wall_Green_Dark",
      "support": 15,
      "rotation": 3
    },
    {
      "x": -4,
      "y": 26,
      "z": 1,
      "name": "Plant_Moss_Wall_Green_Dark",
      "support": 15,
      "rotation": 3
    },
    {
      "x": -4,
      "y": 44,
      "z": 1,
      "name": "Rock_Shale_Cobble"
    },
    {
      "x": -4,
      "y": 45,
      "z": 1,
      "name": "Rock_Shale_Cobble"
    },
    {
      "x": -4,
      "y": 46,
      "z": 1,
      "name": "Build_Lightsource_Cyan",
      "rotation": 5
    },
    {
      "x": -4,
      "y": 47,
      "z": 1,
      "name": "Rock_Shale_Brick_Smooth"
    },
    {
      "x": -4,
      "y": 48,
      "z": 1,
      "name": "Build_Lightsource_Cyan",
      "rotation": 7
    },
    {
      "x": -4,
      "y": 49,
      "z": 1,
      "name": "Rock_Shale_Cobble"
    },
    {
      "x": -4,
      "y": 50,
      "z": 1,
      "name": "Rock_Shale_Cobble"
    },
    {
      "x": -4,
      "y": 51,
      "z": 1,
      "name": "Rock_Shale_Cobble"
    },
    {
      "x": -4,
      "y": 0,
      "z": 2,
      "name": "Rock_Shale_Cobble"
    },
    {
      "x": -4,
      "y": 1,
      "z": 2,
      "name": "Rock_Shale_Cobble"
    },
    {
      "x": -4,
      "y": 2,
      "z": 2,
      "name": "Rock_Shale_Cobble"
    },
    {
      "x": -4,
      "y": 3,
      "z": 2,
      "name": "Rock_Shale_Cobble"
    },
    {
      "x": -4,
      "y": 4,
      "z": 2,
      "name": "Rock_Shale_Cobble"
    },
    {
      "x": -4,
      "y": 5,
      "z": 2,
      "name": "Rock_Shale_Cobble"
    },
    {
      "x": -4,
      "y": 6,
      "z": 2,
      "name": "Rock_Shale_Cobble"
    },
    {
      "x": -4,
      "y": 7,
      "z": 2,
      "name": "Rock_Shale_Cobble"
    },
    {
      "x": -4,
      "y": 8,
      "z": 2,
      "name": "Rock_Shale_Cobble"
    },
    {
      "x": -4,
      "y": 9,
      "z": 2,
      "name": "Rock_Shale_Cobble"
    },
    {
      "x": -4,
      "y": 10,
      "z": 2,
      "name": "Rock_Shale_Cobble"
    },
    {
      "x": -4,
      "y": 11,
      "z": 2,
      "name": "Rock_Shale_Cobble"
    },
    {
      "x": -4,
      "y": 12,
      "z": 2,
      "name": "Rock_Shale_Cobble"
    },
    {
      "x": -4,
      "y": 13,
      "z": 2,
      "name": "Rock_Shale_Cobble"
    },
    {
      "x": -4,
      "y": 14,
      "z": 2,
      "name": "Rock_Shale_Cobble"
    },
    {
      "x": -4,
      "y": 15,
      "z": 2,
      "name": "Rock_Shale_Cobble"
    },
    {
      "x": -4,
      "y": 16,
      "z": 2,
      "name": "Rock_Shale_Cobble"
    },
    {
      "x": -4,
      "y": 17,
      "z": 2,
      "name": "Rock_Shale_Cobble"
    },
    {
      "x": -4,
      "y": 18,
      "z": 2,
      "name": "Rock_Shale_Cobble"
    },
    {
      "x": -4,
      "y": 19,
      "z": 2,
      "name": "Rock_Shale_Cobble"
    },
    {
      "x": -4,
      "y": 20,
      "z": 2,
      "name": "Rock_Shale_Cobble"
    },
    {
      "x": -4,
      "y": 21,
      "z": 2,
      "name": "Rock_Shale_Cobble"
    },
    {
      "x": -4,
      "y": 22,
      "z": 2,
      "name": "Plant_Moss_Rug_Green_Dark",
      "support": 15
    },
    {
      "x": -4,
      "y": 45,
      "z": 2,
      "name": "Rock_Shale_Cobble"
    },
    {
      "x": -4,
      "y": 46,
      "z": 2,
      "name": "Rock_Shale_Cobble"
    },
    {
      "x": -4,
      "y": 47,
      "z": 2,
      "name": "Rock_Shale_Brick_Smooth"
    },
    {
      "x": -4,
      "y": 48,
      "z": 2,
      "name": "Rock_Shale_Cobble"
    },
    {
      "x": -4,
      "y": 49,
      "z": 2,
      "name": "Rock_Shale_Cobble"
    },
    {
      "x": -4,
      "y": 50,
      "z": 2,
      "name": "Rock_Shale_Cobble"
    },
    {
      "x": -4,
      "y": 51,
      "z": 2,
      "name": "Plant_Moss_Rug_Green_Dark"
    },
    {
      "x": -4,
      "y": 0,
      "z": 3,
      "name": "Rock_Shale_Cobble"
    },
    {
      "x": -4,
      "y": 1,
      "z": 3,
      "name": "Rock_Shale_Cobble"
    },
    {
      "x": -4,
      "y": 2,
      "z": 3,
      "name": "Rock_Shale_Cobble"
    },
    {
      "x": -4,
      "y": 3,
      "z": 3,
      "name": "Rock_Shale_Cobble"
    },
    {
      "x": -4,
      "y": 4,
      "z": 3,
      "name": "Rock_Shale_Cobble"
    },
    {
      "x": -4,
      "y": 5,
      "z": 3,
      "name": "Rock_Shale_Cobble"
    },
    {
      "x": -4,
      "y": 6,
      "z": 3,
      "name": "Rock_Shale_Cobble"
    },
    {
      "x": -4,
      "y": 7,
      "z": 3,
      "name": "Rock_Shale_Cobble"
    },
    {
      "x": -4,
      "y": 8,
      "z": 3,
      "name": "Rock_Shale_Cobble"
    },
    {
      "x": -4,
      "y": 9,
      "z": 3,
      "name": "Rock_Shale_Cobble"
    },
    {
      "x": -4,
      "y": 10,
      "z": 3,
      "name": "Rock_Shale_Cobble"
    },
    {
      "x": -4,
      "y": 11,
      "z": 3,
      "name": "Rock_Shale_Cobble"
    },
    {
      "x": -4,
      "y": 12,
      "z": 3,
      "name": "Rock_Shale_Cobble"
    },
    {
      "x": -4,
      "y": 13,
      "z": 3,
      "name": "Rock_Shale_Cobble"
    },
    {
      "x": -4,
      "y": 14,
      "z": 3,
      "name": "Rock_Shale_Cobble"
    },
    {
      "x": -4,
      "y": 15,
      "z": 3,
      "name": "Rock_Shale_Cobble"
    },
    {
      "x": -4,
      "y": 16,
      "z": 3,
      "name": "Metal_Iron_Glowing_Pipe",
      "support": 15,
      "rotation": 5
    },
    {
      "x": -4,
      "y": 20,
      "z": 3,
      "name": "Plant_Moss_Wall_Green_Dark",
      "support": 15
    },
    {
      "x": -4,
      "y": 21,
      "z": 3,
      "name": "Plant_Moss_Wall_Green_Dark",
      "support": 15
    },
    {
      "x": -4,
      "y": 44,
      "z": 3,
      "name": "Rock_Shale_Cobble"
    },
    {
      "x": -4,
      "y": 45,
      "z": 3,
      "name": "Build_Lightsource_Cyan",
      "rotation": 5
    },
    {
      "x": -4,
      "y": 46,
      "z": 3,
      "name": "Rock_Shale_Cobble"
    },
    {
      "x": -4,
      "y": 47,
      "z": 3,
      "name": "Rock_Shale_Brick_Smooth"
    },
    {
      "x": -4,
      "y": 48,
      "z": 3,
      "name": "Rock_Shale_Cobble"
    },
    {
      "x": -4,
      "y": 49,
      "z": 3,
      "name": "Build_Lightsource_Cyan",
      "rotation": 7
    },
    {
      "x": -4,
      "y": 51,
      "z": 3,
      "name": "Rock_Shale_Cobble"
    },
    {
      "x": -4,
      "y": 52,
      "z": 3,
      "name": "Plant_Moss_Rug_Green_Dark"
    },
    {
      "x": -4,
      "y": 43,
      "z": 4,
      "name": "Rock_Shale_Brick_Smooth"
    },
    {
      "x": -4,
      "y": 44,
      "z": 4,
      "name": "Rock_Shale_Cobble"
    },
    {
      "x": -4,
      "y": 45,
      "z": 4,
      "name": "Rock_Shale_Cobble"
    },
    {
      "x": -4,
      "y": 46,
      "z": 4,
      "name": "Build_Lightsource_Cyan",
      "rotation": 5
    },
    {
      "x": -4,
      "y": 47,
      "z": 4,
      "name": "Rock_Shale_Brick_Smooth"
    },
    {
      "x": -4,
      "y": 48,
      "z": 4,
      "name": "Build_Lightsource_Cyan",
      "rotation": 4
    },
    {
      "x": -4,
      "y": 49,
      "z": 4,
      "name": "Build_Lightsource_Cyan",
      "rotation": 4
    },
    {
      "x": -4,
      "y": 50,
      "z": 4,
      "name": "Rock_Shale_Cobble"
    },
    {
      "x": -4,
      "y": 51,
      "z": 4,
      "name": "Rock_Shale_Cobble"
    },
    {
      "x": -4,
      "y": 52,
      "z": 4,
      "name": "Rock_Shale_Brick_Smooth"
    },
    {
      "x": -4,
      "y": 45,
      "z": 5,
      "name": "Rock_Shale_Cobble"
    },
    {
      "x": -4,
      "y": 47,
      "z": 5,
      "name": "Rock_Shale_Brick_Smooth"
    },
    {
      "x": -4,
      "y": 49,
      "z": 5,
      "name": "Rock_Shale_Cobble"
    },
    {
      "x": -4,
      "y": 50,
      "z": 5,
      "name": "Metal_Iron_Glowing_Pipe_Corner",
      "rotation": 2
    },
    {
      "x": -4,
      "y": 51,
      "z": 5,
      "name": "Metal_Iron_Glowing_Pipe_Corner",
      "rotation": 9
    },
    {
      "x": -4,
      "y": 47,
      "z": 6,
      "name": "Rock_Shale_Brick_Smooth"
    },
    {
      "x": -4,
      "y": 48,
      "z": 6,
      "name": "Plant_Moss_Rug_Green_Dark"
    },
    {
      "x": -4,
      "y": 49,
      "z": 6,
      "name": "Metal_Iron_Glowing_Pipe_Corner",
      "rotation": 1
    },
    {
      "x": -4,
      "y": 50,
      "z": 6,
      "name": "Metal_Iron_Glowing_Pipe_Corner",
      "rotation": 10
    },
    {
      "x": -3,
      "y": 47,
      "z": -6,
      "name": "Rock_Shale_Brick_Smooth"
    },
    {
      "x": -3,
      "y": 46,
      "z": -5,
      "name": "Rock_Shale_Cobble"
    },
    {
      "x": -3,
      "y": 47,
      "z": -5,
      "name": "Rock_Shale_Brick_Smooth"
    },
    {
      "x": -3,
      "y": 48,
      "z": -5,
      "name": "Rock_Shale_Cobble",
      "rotation": 3
    },
    {
      "x": -3,
      "y": 50,
      "z": -5,
      "name": "Metal_Iron_Glowing_Pipe_Corner",
      "rotation": 3
    },
    {
      "x": -3,
      "y": 51,
      "z": -5,
      "name": "Metal_Iron_Glowing_Pipe"
    },
    {
      "x": -3,
      "y": 52,
      "z": -5,
      "name": "Metal_Iron_Glowing_Pipe"
    },
    {
      "x": -3,
      "y": 53,
      "z": -5,
      "name": "Metal_Iron_Glowing_Pipe_Corner",
      "rotation": 8
    },
    {
      "x": -3,
      "y": 44,
      "z": -4,
      "name": "Rock_Shale_Cobble"
    },
    {
      "x": -3,
      "y": 45,
      "z": -4,
      "name": "Build_Lightsource_Cyan",
      "rotation": 4
    },
    {
      "x": -3,
      "y": 46,
      "z": -4,
      "name": "Rock_Shale_Cobble"
    },
    {
      "x": -3,
      "y": 47,
      "z": -4,
      "name": "Rock_Shale_Brick_Smooth"
    },
    {
      "x": -3,
      "y": 48,
      "z": -4,
      "name": "Rock_Shale_Cobble",
      "rotation": 3
    },
    {
      "x": -3,
      "y": 49,
      "z": -4,
      "name": "Build_Lightsource_Cyan",
      "rotation": 6
    },
    {
      "x": -3,
      "y": 51,
      "z": -4,
      "name": "Rock_Shale_Cobble",
      "rotation": 3
    },
    {
      "x": -3,
      "y": 53,
      "z": -4,
      "name": "Metal_Iron_Glowing_Pipe_Corner",
      "rotation": 27
    },
    {
      "x": -3,
      "y": 42,
      "z": -3,
      "name": "Rock_Shale_Brick_Smooth"
    },
    {
      "x": -3,
      "y": 43,
      "z": -3,
      "name": "Rock_Shale_Cobble"
    },
    {
      "x": -3,
      "y": 44,
      "z": -3,
      "name": "Rock_Shale_Cobble"
    },
    {
      "x": -3,
      "y": 45,
      "z": -3,
      "name": "Rock_Shale_Cobble"
    },
    {
      "x": -3,
      "y": 46,
      "z": -3,
      "name": "Rock_Shale_Cobble"
    },
    {
      "x": -3,
      "y": 47,
      "z": -3,
      "name": "Rock_Shale_Brick_Smooth"
    },
    {
      "x": -3,
      "y": 48,
      "z": -3,
      "name": "Rock_Shale_Cobble",
      "rotation": 3
    },
    {
      "x": -3,
      "y": 49,
      "z": -3,
      "name": "Rock_Shale_Cobble",
      "rotation": 3
    },
    {
      "x": -3,
      "y": 50,
      "z": -3,
      "name": "Build_Lightsource_Cyan",
      "rotation": 6
    },
    {
      "x": -3,
      "y": 51,
      "z": -3,
      "name": "Rock_Shale_Cobble",
      "rotation": 3
    },
    {
      "x": -3,
      "y": 52,
      "z": -3,
      "name": "Rock_Shale_Cobble",
      "rotation": 3
    },
    {
      "x": -3,
      "y": 53,
      "z": -3,
      "name": "Rock_Shale_Brick_Smooth",
      "rotation": 3
    },
    {
      "x": -3,
      "y": 54,
      "z": -3,
      "name": "Rock_Shale_Brick_Smooth",
      "rotation": 3
    },
    {
      "x": -3,
      "y": 43,
      "z": -2,
      "name": "Rock_Shale_Cobble"
    },
    {
      "x": -3,
      "y": 44,
      "z": -2,
      "name": "Build_Lightsource_Cyan",
      "rotation": 5
    },
    {
      "x": -3,
      "y": 45,
      "z": -2,
      "name": "Rock_Shale_Cobble"
    },
    {
      "x": -3,
      "y": 46,
      "z": -2,
      "name": "Rock_Shale_Cobble"
    },
    {
      "x": -3,
      "y": 47,
      "z": -2,
      "name": "Rock_Shale_Brick_Smooth"
    },
    {
      "x": -3,
      "y": 48,
      "z": -2,
      "name": "Rock_Shale_Cobble",
      "rotation": 3
    },
    {
      "x": -3,
      "y": 49,
      "z": -2,
      "name": "Rock_Shale_Cobble",
      "rotation": 3
    },
    {
      "x": -3,
      "y": 50,
      "z": -2,
      "name": "Build_Lightsource_Cyan",
      "rotation": 3
    },
    {
      "x": -3,
      "y": 51,
      "z": -2,
      "name": "Build_Lightsource_Cyan",
      "rotation": 7
    },
    {
      "x": -3,
      "y": 52,
      "z": -2,
      "name": "Rock_Shale_Cobble",
      "rotation": 3
    },
    {
      "x": -3,
      "y": 53,
      "z": -2,
      "name": "Metal_Iron_Glowing_Pipe_Corner",
      "rotation": 1
    },
    {
      "x": -3,
      "y": 54,
      "z": -2,
      "name": "Metal_Iron_Glowing_Pipe_Corner",
      "rotation": 14
    },
    {
      "x": -3,
      "y": 0,
      "z": -1,
      "name": "Build_Lightsource_Cyan"
    },
    {
      "x": -3,
      "y": 1,
      "z": -1,
      "name": "Build_Lightsource_Cyan",
      "rotation": 4
    },
    {
      "x": -3,
      "y": 2,
      "z": -1,
      "name": "Build_Lightsource_Cyan",
      "rotation": 4
    },
    {
      "x": -3,
      "y": 3,
      "z": -1,
      "name": "Build_Lightsource_Cyan",
      "rotation": 4
    },
    {
      "x": -3,
      "y": 4,
      "z": -1,
      "name": "Build_Lightsource_Cyan"
    },
    {
      "x": -3,
      "y": 5,
      "z": -1,
      "name": "Rock_Shale_Cobble"
    },
    {
      "x": -3,
      "y": 6,
      "z": -1,
      "name": "Rock_Shale_Cobble"
    },
    {
      "x": -3,
      "y": 7,
      "z": -1,
      "name": "Rock_Shale_Cobble"
    },
    {
      "x": -3,
      "y": 8,
      "z": -1,
      "name": "Rock_Shale_Cobble"
    },
    {
      "x": -3,
      "y": 9,
      "z": -1,
      "name": "Rock_Shale_Cobble"
    },
    {
      "x": -3,
      "y": 10,
      "z": -1,
      "name": "Rock_Shale_Cobble"
    },
    {
      "x": -3,
      "y": 11,
      "z": -1,
      "name": "Rock_Shale_Cobble"
    },
    {
      "x": -3,
      "y": 12,
      "z": -1,
      "name": "Rock_Shale_Cobble"
    },
    {
      "x": -3,
      "y": 13,
      "z": -1,
      "name": "Rock_Shale_Cobble"
    },
    {
      "x": -3,
      "y": 14,
      "z": -1,
      "name": "Build_Lightsource_Cyan"
    },
    {
      "x": -3,
      "y": 15,
      "z": -1,
      "name": "Build_Lightsource_Cyan"
    },
    {
      "x": -3,
      "y": 16,
      "z": -1,
      "name": "Plant_Moss_Rug_Green_Dark",
      "support": 15
    },
    {
      "x": -3,
      "y": 44,
      "z": -1,
      "name": "Rock_Shale_Cobble"
    },
    {
      "x": -3,
      "y": 45,
      "z": -1,
      "name": "Rock_Shale_Cobble"
    },
    {
      "x": -3,
      "y": 46,
      "z": -1,
      "name": "Rock_Shale_Cobble"
    },
    {
      "x": -3,
      "y": 47,
      "z": -1,
      "name": "Rock_Shale_Brick_Smooth"
    },
    {
      "x": -3,
      "y": 48,
      "z": -1,
      "name": "Rock_Shale_Cobble",
      "rotation": 3
    },
    {
      "x": -3,
      "y": 49,
      "z": -1,
      "name": "Rock_Shale_Cobble",
      "rotation": 3
    },
    {
      "x": -3,
      "y": 50,
      "z": -1,
      "name": "Rock_Shale_Cobble",
      "rotation": 3
    },
    {
      "x": -3,
      "y": 51,
      "z": -1,
      "name": "Rock_Shale_Cobble",
      "rotation": 3
    },
    {
      "x": -3,
      "y": 54,
      "z": -1,
      "name": "Metal_Iron_Glowing_Pipe_Corner"
    },
    {
      "x": -3,
      "y": 55,
      "z": -1,
      "name": "Metal_Iron_Glowing_Pipe_Corner",
      "rotation": 9
    },
    {
      "x": -3,
      "y": 0,
      "z": 0,
      "name": "Rock_Shale_Cobble"
    },
    {
      "x": -3,
      "y": 1,
      "z": 0,
      "name": "Rock_Shale_Cobble"
    },
    {
      "x": -3,
      "y": 2,
      "z": 0,
      "name": "Rock_Shale_Cobble"
    },
    {
      "x": -3,
      "y": 3,
      "z": 0,
      "name": "Rock_Shale_Cobble"
    },
    {
      "x": -3,
      "y": 4,
      "z": 0,
      "name": "Rock_Shale_Cobble"
    },
    {
      "x": -3,
      "y": 5,
      "z": 0,
      "name": "Rock_Shale_Cobble"
    },
    {
      "x": -3,
      "y": 6,
      "z": 0,
      "name": "Rock_Shale_Cobble"
    },
    {
      "x": -3,
      "y": 7,
      "z": 0,
      "name": "Rock_Shale_Cobble"
    },
    {
      "x": -3,
      "y": 8,
      "z": 0,
      "name": "Rock_Shale_Cobble"
    },
    {
      "x": -3,
      "y": 9,
      "z": 0,
      "name": "Rock_Shale_Cobble"
    },
    {
      "x": -3,
      "y": 10,
      "z": 0,
      "name": "Rock_Shale_Cobble"
    },
    {
      "x": -3,
      "y": 11,
      "z": 0,
      "name": "Rock_Shale_Cobble"
    },
    {
      "x": -3,
      "y": 12,
      "z": 0,
      "name": "Rock_Shale_Cobble"
    },
    {
      "x": -3,
      "y": 13,
      "z": 0,
      "name": "Rock_Shale_Cobble"
    },
    {
      "x": -3,
      "y": 14,
      "z": 0,
      "name": "Rock_Shale_Cobble"
    },
    {
      "x": -3,
      "y": 15,
      "z": 0,
      "name": "Rock_Shale_Cobble"
    },
    {
      "x": -3,
      "y": 16,
      "z": 0,
      "name": "Build_Lightsource_Cyan",
      "rotation": 4
    },
    {
      "x": -3,
      "y": 17,
      "z": 0,
      "name": "Build_Lightsource_Cyan",
      "rotation": 4
    },
    {
      "x": -3,
      "y": 18,
      "z": 0,
      "name": "Build_Lightsource_Cyan",
      "rotation": 4
    },
    {
      "x": -3,
      "y": 19,
      "z": 0,
      "name": "Build_Lightsource_Cyan",
      "rotation": 4
    },
    {
      "x": -3,
      "y": 20,
      "z": 0,
      "name": "Build_Lightsource_Cyan",
      "rotation": 4
    },
    {
      "x": -3,
      "y": 21,
      "z": 0,
      "name": "Rock_Shale_Cobble"
    },
    {
      "x": -3,
      "y": 22,
      "z": 0,
      "name": "Rock_Shale_Cobble"
    },
    {
      "x": -3,
      "y": 23,
      "z": 0,
      "name": "Rock_Shale_Cobble"
    },
    {
      "x": -3,
      "y": 24,
      "z": 0,
      "name": "Rock_Shale_Cobble"
    },
    {
      "x": -3,
      "y": 25,
      "z": 0,
      "name": "Rock_Shale_Cobble"
    },
    {
      "x": -3,
      "y": 26,
      "z": 0,
      "name": "Rock_Shale_Cobble"
    },
    {
      "x": -3,
      "y": 27,
      "z": 0,
      "name": "Metal_Iron_Glowing_Pipe",
      "support": 15,
      "rotation": 5
    },
    {
      "x": -3,
      "y": 44,
      "z": 0,
      "name": "Rock_Shale_Cobble"
    },
    {
      "x": -3,
      "y": 45,
      "z": 0,
      "name": "Rock_Shale_Cobble"
    },
    {
      "x": -3,
      "y": 46,
      "z": 0,
      "name": "Rock_Shale_Cobble"
    },
    {
      "x": -3,
      "y": 47,
      "z": 0,
      "name": "Rock_Shale_Brick_Smooth"
    },
    {
      "x": -3,
      "y": 48,
      "z": 0,
      "name": "Rock_Shale_Cobble",
      "rotation": 3
    },
    {
      "x": -3,
      "y": 49,
      "z": 0,
      "name": "Rock_Shale_Cobble",
      "rotation": 3
    },
    {
      "x": -3,
      "y": 50,
      "z": 0,
      "name": "Rock_Shale_Cobble",
      "rotation": 3
    },
    {
      "x": -3,
      "y": 51,
      "z": 0,
      "name": "Rock_Shale_Cobble",
      "rotation": 3
    },
    {
      "x": -3,
      "y": 52,
      "z": 0,
      "name": "Rock_Shale_Cobble",
      "rotation": 3
    },
    {
      "x": -3,
      "y": 0,
      "z": 1,
      "name": "Rock_Shale_Cobble"
    },
    {
      "x": -3,
      "y": 1,
      "z": 1,
      "name": "Rock_Shale_Cobble"
    },
    {
      "x": -3,
      "y": 2,
      "z": 1,
      "name": "Rock_Shale_Cobble"
    },
    {
      "x": -3,
      "y": 3,
      "z": 1,
      "name": "Rock_Shale_Cobble"
    },
    {
      "x": -3,
      "y": 4,
      "z": 1,
      "name": "Rock_Shale_Cobble"
    },
    {
      "x": -3,
      "y": 5,
      "z": 1,
      "name": "Rock_Shale_Cobble"
    },
    {
      "x": -3,
      "y": 6,
      "z": 1,
      "name": "Rock_Shale_Cobble"
    },
    {
      "x": -3,
      "y": 7,
      "z": 1,
      "name": "Rock_Shale_Cobble"
    },
    {
      "x": -3,
      "y": 8,
      "z": 1,
      "name": "Rock_Shale_Cobble"
    },
    {
      "x": -3,
      "y": 9,
      "z": 1,
      "name": "Rock_Shale_Cobble"
    },
    {
      "x": -3,
      "y": 10,
      "z": 1,
      "name": "Rock_Shale_Cobble"
    },
    {
      "x": -3,
      "y": 11,
      "z": 1,
      "name": "Rock_Shale_Cobble"
    },
    {
      "x": -3,
      "y": 12,
      "z": 1,
      "name": "Rock_Shale_Cobble"
    },
    {
      "x": -3,
      "y": 13,
      "z": 1,
      "name": "Rock_Shale_Cobble"
    },
    {
      "x": -3,
      "y": 14,
      "z": 1,
      "name": "Rock_Shale_Cobble"
    },
    {
      "x": -3,
      "y": 15,
      "z": 1,
      "name": "Rock_Shale_Cobble"
    },
    {
      "x": -3,
      "y": 16,
      "z": 1,
      "name": "Rock_Shale_Cobble"
    },
    {
      "x": -3,
      "y": 17,
      "z": 1,
      "name": "Rock_Shale_Cobble"
    },
    {
      "x": -3,
      "y": 18,
      "z": 1,
      "name": "Rock_Shale_Cobble"
    },
    {
      "x": -3,
      "y": 19,
      "z": 1,
      "name": "Rock_Shale_Cobble"
    },
    {
      "x": -3,
      "y": 20,
      "z": 1,
      "name": "Rock_Shale_Cobble"
    },
    {
      "x": -3,
      "y": 21,
      "z": 1,
      "name": "Rock_Shale_Cobble"
    },
    {
      "x": -3,
      "y": 22,
      "z": 1,
      "name": "Build_Lightsource_Cyan"
    },
    {
      "x": -3,
      "y": 23,
      "z": 1,
      "name": "Build_Lightsource_Cyan"
    },
    {
      "x": -3,
      "y": 24,
      "z": 1,
      "name": "Build_Lightsource_Cyan"
    },
    {
      "x": -3,
      "y": 25,
      "z": 1,
      "name": "Build_Lightsource_Cyan",
      "rotation": 5
    },
    {
      "x": -3,
      "y": 26,
      "z": 1,
      "name": "Rock_Shale_Cobble"
    },
    {
      "x": -3,
      "y": 27,
      "z": 1,
      "name": "Plant_Moss_Rug_Green_Dark",
      "support": 15
    },
    {
      "x": -3,
      "y": 44,
      "z": 1,
      "name": "Rock_Shale_Cobble"
    },
    {
      "x": -3,
      "y": 45,
      "z": 1,
      "name": "Rock_Shale_Cobble"
    },
    {
      "x": -3,
      "y": 46,
      "z": 1,
      "name": "Rock_Shale_Cobble"
    },
    {
      "x": -3,
      "y": 47,
      "z": 1,
      "name": "Rock_Shale_Brick_Smooth"
    },
    {
      "x": -3,
      "y": 48,
      "z": 1,
      "name": "Rock_Shale_Cobble"
    },
    {
      "x": -3,
      "y": 49,
      "z": 1,
      "name": "Rock_Shale_Cobble"
    },
    {
      "x": -3,
      "y": 50,
      "z": 1,
      "name": "Rock_Shale_Cobble"
    },
    {
      "x": -3,
      "y": 51,
      "z": 1,
      "name": "Rock_Shale_Cobble"
    },
    {
      "x": -3,
      "y": 0,
      "z": 2,
      "name": "Rock_Shale_Cobble"
    },
    {
      "x": -3,
      "y": 1,
      "z": 2,
      "name": "Rock_Shale_Cobble"
    },
    {
      "x": -3,
      "y": 2,
      "z": 2,
      "name": "Rock_Shale_Cobble"
    },
    {
      "x": -3,
      "y": 3,
      "z": 2,
      "name": "Rock_Shale_Cobble"
    },
    {
      "x": -3,
      "y": 4,
      "z": 2,
      "name": "Rock_Shale_Cobble"
    },
    {
      "x": -3,
      "y": 5,
      "z": 2,
      "name": "Rock_Shale_Cobble"
    },
    {
      "x": -3,
      "y": 6,
      "z": 2,
      "name": "Rock_Shale_Cobble"
    },
    {
      "x": -3,
      "y": 7,
      "z": 2,
      "name": "Rock_Shale_Cobble"
    },
    {
      "x": -3,
      "y": 8,
      "z": 2,
      "name": "Rock_Shale_Cobble"
    },
    {
      "x": -3,
      "y": 9,
      "z": 2,
      "name": "Rock_Shale_Cobble"
    },
    {
      "x": -3,
      "y": 10,
      "z": 2,
      "name": "Rock_Shale_Cobble"
    },
    {
      "x": -3,
      "y": 11,
      "z": 2,
      "name": "Rock_Shale_Cobble"
    },
    {
      "x": -3,
      "y": 12,
      "z": 2,
      "name": "Rock_Shale_Cobble"
    },
    {
      "x": -3,
      "y": 13,
      "z": 2,
      "name": "Rock_Shale_Cobble"
    },
    {
      "x": -3,
      "y": 14,
      "z": 2,
      "name": "Rock_Shale_Cobble"
    },
    {
      "x": -3,
      "y": 15,
      "z": 2,
      "name": "Rock_Shale_Cobble"
    },
    {
      "x": -3,
      "y": 16,
      "z": 2,
      "name": "Rock_Shale_Cobble"
    },
    {
      "x": -3,
      "y": 17,
      "z": 2,
      "name": "Rock_Shale_Cobble"
    },
    {
      "x": -3,
      "y": 18,
      "z": 2,
      "name": "Rock_Shale_Cobble"
    },
    {
      "x": -3,
      "y": 19,
      "z": 2,
      "name": "Rock_Shale_Cobble"
    },
    {
      "x": -3,
      "y": 20,
      "z": 2,
      "name": "Rock_Shale_Cobble"
    },
    {
      "x": -3,
      "y": 21,
      "z": 2,
      "name": "Rock_Shale_Cobble"
    },
    {
      "x": -3,
      "y": 22,
      "z": 2,
      "name": "Rock_Shale_Cobble"
    },
    {
      "x": -3,
      "y": 23,
      "z": 2,
      "name": "Rock_Shale_Cobble"
    },
    {
      "x": -3,
      "y": 24,
      "z": 2,
      "name": "Rock_Shale_Cobble"
    },
    {
      "x": -3,
      "y": 25,
      "z": 2,
      "name": "Rock_Shale_Cobble"
    },
    {
      "x": -3,
      "y": 26,
      "z": 2,
      "name": "Rock_Shale_Cobble"
    },
    {
      "x": -3,
      "y": 27,
      "z": 2,
      "name": "Build_Lightsource_Cyan"
    },
    {
      "x": -3,
      "y": 28,
      "z": 2,
      "name": "Build_Lightsource_Cyan"
    },
    {
      "x": -3,
      "y": 29,
      "z": 2,
      "name": "Build_Lightsource_Cyan"
    },
    {
      "x": -3,
      "y": 30,
      "z": 2,
      "name": "Build_Lightsource_Cyan"
    },
    {
      "x": -3,
      "y": 31,
      "z": 2,
      "name": "Build_Lightsource_Cyan"
    },
    {
      "x": -3,
      "y": 32,
      "z": 2,
      "name": "Build_Lightsource_Cyan"
    },
    {
      "x": -3,
      "y": 33,
      "z": 2,
      "name": "Build_Lightsource_Cyan"
    },
    {
      "x": -3,
      "y": 34,
      "z": 2,
      "name": "Build_Lightsource_Cyan"
    },
    {
      "x": -3,
      "y": 35,
      "z": 2,
      "name": "Build_Lightsource_Cyan"
    },
    {
      "x": -3,
      "y": 36,
      "z": 2,
      "name": "Build_Lightsource_Cyan"
    },
    {
      "x": -3,
      "y": 43,
      "z": 2,
      "name": "Rock_Shale_Cobble"
    },
    {
      "x": -3,
      "y": 44,
      "z": 2,
      "name": "Build_Lightsource_Cyan",
      "rotation": 5
    },
    {
      "x": -3,
      "y": 45,
      "z": 2,
      "name": "Rock_Shale_Cobble"
    },
    {
      "x": -3,
      "y": 46,
      "z": 2,
      "name": "Rock_Shale_Cobble"
    },
    {
      "x": -3,
      "y": 47,
      "z": 2,
      "name": "Rock_Shale_Brick_Smooth"
    },
    {
      "x": -3,
      "y": 48,
      "z": 2,
      "name": "Rock_Shale_Cobble"
    },
    {
      "x": -3,
      "y": 49,
      "z": 2,
      "name": "Rock_Shale_Cobble",
      "support": 15
    },
    {
      "x": -3,
      "y": 50,
      "z": 2,
      "name": "Rock_Shale_Cobble"
    },
    {
      "x": -3,
      "y": 51,
      "z": 2,
      "name": "Build_Lightsource_Cyan",
      "rotation": 7
    },
    {
      "x": -3,
      "y": 52,
      "z": 2,
      "name": "Rock_Shale_Cobble"
    },
    {
      "x": -3,
      "y": 0,
      "z": 3,
      "name": "Rock_Shale_Cobble"
    },
    {
      "x": -3,
      "y": 1,
      "z": 3,
      "name": "Rock_Shale_Cobble"
    },
    {
      "x": -3,
      "y": 2,
      "z": 3,
      "name": "Rock_Shale_Cobble"
    },
    {
      "x": -3,
      "y": 3,
      "z": 3,
      "name": "Rock_Shale_Cobble"
    },
    {
      "x": -3,
      "y": 4,
      "z": 3,
      "name": "Rock_Shale_Cobble"
    },
    {
      "x": -3,
      "y": 5,
      "z": 3,
      "name": "Rock_Shale_Cobble"
    },
    {
      "x": -3,
      "y": 6,
      "z": 3,
      "name": "Rock_Shale_Cobble"
    },
    {
      "x": -3,
      "y": 7,
      "z": 3,
      "name": "Rock_Shale_Cobble"
    },
    {
      "x": -3,
      "y": 8,
      "z": 3,
      "name": "Rock_Shale_Cobble"
    },
    {
      "x": -3,
      "y": 9,
      "z": 3,
      "name": "Rock_Shale_Cobble"
    },
    {
      "x": -3,
      "y": 10,
      "z": 3,
      "name": "Rock_Shale_Cobble"
    },
    {
      "x": -3,
      "y": 11,
      "z": 3,
      "name": "Rock_Shale_Cobble"
    },
    {
      "x": -3,
      "y": 12,
      "z": 3,
      "name": "Rock_Shale_Cobble"
    },
    {
      "x": -3,
      "y": 13,
      "z": 3,
      "name": "Rock_Shale_Cobble"
    },
    {
      "x": -3,
      "y": 14,
      "z": 3,
      "name": "Rock_Shale_Cobble"
    },
    {
      "x": -3,
      "y": 15,
      "z": 3,
      "name": "Rock_Shale_Cobble"
    },
    {
      "x": -3,
      "y": 16,
      "z": 3,
      "name": "Metal_Iron_Glowing_Pipe_Corner",
      "support": 15,
      "rotation": 16
    },
    {
      "x": -3,
      "y": 42,
      "z": 3,
      "name": "Rock_Shale_Brick_Smooth"
    },
    {
      "x": -3,
      "y": 43,
      "z": 3,
      "name": "Rock_Shale_Cobble"
    },
    {
      "x": -3,
      "y": 44,
      "z": 3,
      "name": "Rock_Shale_Cobble"
    },
    {
      "x": -3,
      "y": 45,
      "z": 3,
      "name": "Rock_Shale_Cobble"
    },
    {
      "x": -3,
      "y": 46,
      "z": 3,
      "name": "Rock_Shale_Cobble"
    },
    {
      "x": -3,
      "y": 47,
      "z": 3,
      "name": "Rock_Shale_Brick_Smooth"
    },
    {
      "x": -3,
      "y": 48,
      "z": 3,
      "name": "Rock_Shale_Cobble"
    },
    {
      "x": -3,
      "y": 49,
      "z": 3,
      "name": "Rock_Shale_Cobble"
    },
    {
      "x": -3,
      "y": 50,
      "z": 3,
      "name": "Build_Lightsource_Cyan",
      "rotation": 7
    },
    {
      "x": -3,
      "y": 51,
      "z": 3,
      "name": "Rock_Shale_Cobble"
    },
    {
      "x": -3,
      "y": 52,
      "z": 3,
      "name": "Rock_Shale_Cobble"
    },
    {
      "x": -3,
      "y": 53,
      "z": 3,
      "name": "Rock_Shale_Brick_Smooth"
    },
    {
      "x": -3,
      "y": 54,
      "z": 3,
      "name": "Rock_Shale_Brick_Smooth"
    },
    {
      "x": -3,
      "y": 55,
      "z": 3,
      "name": "Plant_Moss_Rug_Green_Dark"
    },
    {
      "x": -3,
      "y": 44,
      "z": 4,
      "name": "Rock_Shale_Cobble"
    },
    {
      "x": -3,
      "y": 45,
      "z": 4,
      "name": "Build_Lightsource_Cyan",
      "rotation": 4
    },
    {
      "x": -3,
      "y": 46,
      "z": 4,
      "name": "Rock_Shale_Cobble"
    },
    {
      "x": -3,
      "y": 47,
      "z": 4,
      "name": "Rock_Shale_Brick_Smooth"
    },
    {
      "x": -3,
      "y": 48,
      "z": 4,
      "name": "Rock_Shale_Cobble"
    },
    {
      "x": -3,
      "y": 49,
      "z": 4,
      "name": "Build_Lightsource_Cyan"
    },
    {
      "x": -3,
      "y": 51,
      "z": 4,
      "name": "Rock_Shale_Cobble"
    },
    {
      "x": -3,
      "y": 46,
      "z": 5,
      "name": "Rock_Shale_Cobble"
    },
    {
      "x": -3,
      "y": 47,
      "z": 5,
      "name": "Rock_Shale_Brick_Smooth"
    },
    {
      "x": -3,
      "y": 48,
      "z": 5,
      "name": "Rock_Shale_Cobble"
    },
    {
      "x": -3,
      "y": 51,
      "z": 5,
      "name": "Metal_Iron_Glowing_Pipe",
      "rotation": 5
    },
    {
      "x": -3,
      "y": 47,
      "z": 6,
      "name": "Rock_Shale_Brick_Smooth"
    },
    {
      "x": -3,
      "y": 48,
      "z": 6,
      "name": "Plant_Moss_Rug_Green_Dark"
    },
    {
      "x": -3,
      "y": 47,
      "z": 7,
      "name": "Plant_Moss_Wall_Green_Dark"
    },
    {
      "x": -2,
      "y": 44,
      "z": -6,
      "name": "Metal_Iron_Glowing_Pipe_Corner",
      "rotation": 2
    },
    {
      "x": -2,
      "y": 45,
      "z": -6,
      "name": "Metal_Iron_Glowing_Pipe"
    },
    {
      "x": -2,
      "y": 46,
      "z": -6,
      "name": "Metal_Iron_Glowing_Pipe_Corner",
      "rotation": 8
    },
    {
      "x": -2,
      "y": 47,
      "z": -6,
      "name": "Rock_Shale_Brick_Smooth"
    },
    {
      "x": -2,
      "y": 43,
      "z": -5,
      "name": "Metal_Iron_Glowing_Pipe_Corner",
      "rotation": 2
    },
    {
      "x": -2,
      "y": 44,
      "z": -5,
      "name": "Metal_Iron_Glowing_Pipe_Corner",
      "rotation": 12
    },
    {
      "x": -2,
      "y": 45,
      "z": -5,
      "name": "Rock_Shale_Cobble"
    },
    {
      "x": -2,
      "y": 46,
      "z": -5,
      "name": "Rock_Shale_Cobble"
    },
    {
      "x": -2,
      "y": 47,
      "z": -5,
      "name": "Rock_Shale_Brick_Smooth"
    },
    {
      "x": -2,
      "y": 48,
      "z": -5,
      "name": "Rock_Shale_Cobble",
      "rotation": 3
    },
    {
      "x": -2,
      "y": 49,
      "z": -5,
      "name": "Rock_Shale_Cobble",
      "rotation": 3
    },
    {
      "x": -2,
      "y": 50,
      "z": -5,
      "name": "Metal_Iron_Glowing_Pipe",
      "rotation": 5
    },
    {
      "x": -2,
      "y": 42,
      "z": -4,
      "name": "Metal_Iron_Glowing_Pipe_Corner",
      "rotation": 2
    },
    {
      "x": -2,
      "y": 43,
      "z": -4,
      "name": "Metal_Iron_Glowing_Pipe_Corner",
      "rotation": 10
    },
    {
      "x": -2,
      "y": 45,
      "z": -4,
      "name": "Rock_Shale_Cobble"
    },
    {
      "x": -2,
      "y": 46,
      "z": -4,
      "name": "Rock_Shale_Cobble"
    },
    {
      "x": -2,
      "y": 47,
      "z": -4,
      "name": "Rock_Shale_Brick_Smooth"
    },
    {
      "x": -2,
      "y": 48,
      "z": -4,
      "name": "Rock_Shale_Cobble",
      "rotation": 3
    },
    {
      "x": -2,
      "y": 49,
      "z": -4,
      "name": "Rock_Shale_Cobble",
      "rotation": 3
    },
    {
      "x": -2,
      "y": 50,
      "z": -4,
      "name": "Rock_Shale_Cobble",
      "rotation": 3
    },
    {
      "x": -2,
      "y": 42,
      "z": -3,
      "name": "Metal_Iron_Glowing_Pipe_Corner",
      "rotation": 19
    },
    {
      "x": -2,
      "y": 43,
      "z": -3,
      "name": "Rock_Shale_Cobble",
      "rotation": 2
    },
    {
      "x": -2,
      "y": 44,
      "z": -3,
      "name": "Build_Lightsource_Cyan",
      "rotation": 4
    },
    {
      "x": -2,
      "y": 45,
      "z": -3,
      "name": "Rock_Shale_Cobble"
    },
    {
      "x": -2,
      "y": 46,
      "z": -3,
      "name": "Rock_Shale_Cobble"
    },
    {
      "x": -2,
      "y": 47,
      "z": -3,
      "name": "Rock_Shale_Brick_Smooth"
    },
    {
      "x": -2,
      "y": 48,
      "z": -3,
      "name": "Rock_Shale_Cobble",
      "rotation": 3
    },
    {
      "x": -2,
      "y": 49,
      "z": -3,
      "name": "Rock_Shale_Cobble",
      "rotation": 3
    },
    {
      "x": -2,
      "y": 50,
      "z": -3,
      "name": "Rock_Shale_Cobble",
      "rotation": 3
    },
    {
      "x": -2,
      "y": 51,
      "z": -3,
      "name": "Build_Lightsource_Cyan",
      "rotation": 6
    },
    {
      "x": -2,
      "y": 52,
      "z": -3,
      "name": "Rock_Shale_Cobble",
      "rotation": 3
    },
    {
      "x": -2,
      "y": 42,
      "z": -2,
      "name": "Rock_Shale_Brick_Smooth"
    },
    {
      "x": -2,
      "y": 43,
      "z": -2,
      "name": "Rock_Shale_Cobble"
    },
    {
      "x": -2,
      "y": 44,
      "z": -2,
      "name": "Rock_Shale_Cobble"
    },
    {
      "x": -2,
      "y": 45,
      "z": -2,
      "name": "Rock_Shale_Cobble"
    },
    {
      "x": -2,
      "y": 46,
      "z": -2,
      "name": "Rock_Shale_Cobble"
    },
    {
      "x": -2,
      "y": 47,
      "z": -2,
      "name": "Rock_Shale_Brick_Smooth"
    },
    {
      "x": -2,
      "y": 48,
      "z": -2,
      "name": "Rock_Shale_Cobble",
      "rotation": 3
    },
    {
      "x": -2,
      "y": 49,
      "z": -2,
      "name": "Rock_Shale_Cobble",
      "rotation": 3
    },
    {
      "x": -2,
      "y": 50,
      "z": -2,
      "name": "Rock_Shale_Cobble",
      "rotation": 3
    },
    {
      "x": -2,
      "y": 51,
      "z": -2,
      "name": "Rock_Shale_Cobble",
      "rotation": 3
    },
    {
      "x": -2,
      "y": 52,
      "z": -2,
      "name": "Rock_Shale_Cobble",
      "rotation": 3
    },
    {
      "x": -2,
      "y": 53,
      "z": -2,
      "name": "Rock_Shale_Cobble",
      "rotation": 3
    },
    {
      "x": -2,
      "y": 54,
      "z": -2,
      "name": "Rock_Shale_Cobble",
      "rotation": 3
    },
    {
      "x": -2,
      "y": 55,
      "z": -2,
      "name": "Rock_Shale_Brick_Smooth",
      "rotation": 3
    },
    {
      "x": -2,
      "y": 56,
      "z": -2,
      "name": "Rock_Shale_Brick_Smooth",
      "rotation": 3
    },
    {
      "x": -2,
      "y": 0,
      "z": -1,
      "name": "Rock_Shale_Cobble"
    },
    {
      "x": -2,
      "y": 1,
      "z": -1,
      "name": "Rock_Shale_Cobble"
    },
    {
      "x": -2,
      "y": 2,
      "z": -1,
      "name": "Rock_Shale_Cobble"
    },
    {
      "x": -2,
      "y": 3,
      "z": -1,
      "name": "Rock_Shale_Cobble"
    },
    {
      "x": -2,
      "y": 4,
      "z": -1,
      "name": "Rock_Shale_Cobble"
    },
    {
      "x": -2,
      "y": 5,
      "z": -1,
      "name": "Rock_Shale_Cobble"
    },
    {
      "x": -2,
      "y": 6,
      "z": -1,
      "name": "Rock_Shale_Cobble"
    },
    {
      "x": -2,
      "y": 7,
      "z": -1,
      "name": "Rock_Shale_Cobble"
    },
    {
      "x": -2,
      "y": 8,
      "z": -1,
      "name": "Rock_Shale_Cobble"
    },
    {
      "x": -2,
      "y": 9,
      "z": -1,
      "name": "Rock_Shale_Cobble"
    },
    {
      "x": -2,
      "y": 10,
      "z": -1,
      "name": "Rock_Shale_Cobble"
    },
    {
      "x": -2,
      "y": 11,
      "z": -1,
      "name": "Rock_Shale_Cobble"
    },
    {
      "x": -2,
      "y": 12,
      "z": -1,
      "name": "Rock_Shale_Cobble"
    },
    {
      "x": -2,
      "y": 13,
      "z": -1,
      "name": "Rock_Shale_Cobble"
    },
    {
      "x": -2,
      "y": 14,
      "z": -1,
      "name": "Rock_Shale_Cobble"
    },
    {
      "x": -2,
      "y": 15,
      "z": -1,
      "name": "Rock_Shale_Cobble"
    },
    {
      "x": -2,
      "y": 43,
      "z": -1,
      "name": "Build_Lightsource_Cyan",
      "rotation": 5
    },
    {
      "x": -2,
      "y": 44,
      "z": -1,
      "name": "Rock_Shale_Cobble"
    },
    {
      "x": -2,
      "y": 45,
      "z": -1,
      "name": "Rock_Shale_Cobble"
    },
    {
      "x": -2,
      "y": 46,
      "z": -1,
      "name": "Rock_Shale_Cobble"
    },
    {
      "x": -2,
      "y": 47,
      "z": -1,
      "name": "Rock_Shale_Brick_Smooth"
    },
    {
      "x": -2,
      "y": 48,
      "z": -1,
      "name": "Rock_Shale_Cobble",
      "support": 15,
      "rotation": 3
    },
    {
      "x": -2,
      "y": 49,
      "z": -1,
      "name": "Rock_Shale_Cobble",
      "rotation": 3
    },
    {
      "x": -2,
      "y": 50,
      "z": -1,
      "name": "Rock_Shale_Cobble",
      "rotation": 3
    },
    {
      "x": -2,
      "y": 51,
      "z": -1,
      "name": "Rock_Shale_Cobble",
      "rotation": 3
    },
    {
      "x": -2,
      "y": 52,
      "z": -1,
      "name": "Build_Lightsource_Cyan",
      "rotation": 7
    },
    {
      "x": -2,
      "y": 54,
      "z": -1,
      "name": "Rock_Shale_Cobble",
      "rotation": 3
    },
    {
      "x": -2,
      "y": 55,
      "z": -1,
      "name": "Metal_Iron_Glowing_Pipe",
      "rotation": 5
    },
    {
      "x": -2,
      "y": 0,
      "z": 0,
      "name": "Rock_Shale_Cobble"
    },
    {
      "x": -2,
      "y": 1,
      "z": 0,
      "name": "Rock_Shale_Cobble"
    },
    {
      "x": -2,
      "y": 2,
      "z": 0,
      "name": "Rock_Shale_Cobble"
    },
    {
      "x": -2,
      "y": 3,
      "z": 0,
      "name": "Rock_Shale_Cobble"
    },
    {
      "x": -2,
      "y": 4,
      "z": 0,
      "name": "Rock_Shale_Cobble"
    },
    {
      "x": -2,
      "y": 5,
      "z": 0,
      "name": "Rock_Shale_Cobble"
    },
    {
      "x": -2,
      "y": 6,
      "z": 0,
      "name": "Rock_Shale_Cobble"
    },
    {
      "x": -2,
      "y": 7,
      "z": 0,
      "name": "Rock_Shale_Cobble"
    },
    {
      "x": -2,
      "y": 8,
      "z": 0,
      "name": "Rock_Shale_Cobble"
    },
    {
      "x": -2,
      "y": 9,
      "z": 0,
      "name": "Rock_Shale_Cobble"
    },
    {
      "x": -2,
      "y": 10,
      "z": 0,
      "name": "Rock_Shale_Cobble"
    },
    {
      "x": -2,
      "y": 11,
      "z": 0,
      "name": "Rock_Shale_Cobble"
    },
    {
      "x": -2,
      "y": 12,
      "z": 0,
      "name": "Rock_Shale_Cobble"
    },
    {
      "x": -2,
      "y": 13,
      "z": 0,
      "name": "Rock_Shale_Cobble"
    },
    {
      "x": -2,
      "y": 14,
      "z": 0,
      "name": "Rock_Shale_Cobble"
    },
    {
      "x": -2,
      "y": 15,
      "z": 0,
      "name": "Rock_Shale_Cobble"
    },
    {
      "x": -2,
      "y": 16,
      "z": 0,
      "name": "Rock_Shale_Cobble"
    },
    {
      "x": -2,
      "y": 17,
      "z": 0,
      "name": "Rock_Shale_Cobble"
    },
    {
      "x": -2,
      "y": 18,
      "z": 0,
      "name": "Rock_Shale_Cobble"
    },
    {
      "x": -2,
      "y": 19,
      "z": 0,
      "name": "Rock_Shale_Cobble"
    },
    {
      "x": -2,
      "y": 20,
      "z": 0,
      "name": "Rock_Shale_Cobble"
    },
    {
      "x": -2,
      "y": 21,
      "z": 0,
      "name": "Rock_Shale_Cobble"
    },
    {
      "x": -2,
      "y": 22,
      "z": 0,
      "name": "Rock_Shale_Cobble"
    },
    {
      "x": -2,
      "y": 23,
      "z": 0,
      "name": "Rock_Shale_Cobble"
    },
    {
      "x": -2,
      "y": 24,
      "z": 0,
      "name": "Rock_Shale_Cobble"
    },
    {
      "x": -2,
      "y": 25,
      "z": 0,
      "name": "Rock_Shale_Cobble"
    },
    {
      "x": -2,
      "y": 26,
      "z": 0,
      "name": "Rock_Shale_Cobble"
    },
    {
      "x": -2,
      "y": 27,
      "z": 0,
      "name": "Metal_Iron_Glowing_Pipe_Corner",
      "support": 15,
      "rotation": 1
    },
    {
      "x": -2,
      "y": 28,
      "z": 0,
      "name": "Metal_Iron_Glowing_Pipe",
      "support": 15
    },
    {
      "x": -2,
      "y": 29,
      "z": 0,
      "name": "Metal_Iron_Glowing_Pipe",
      "support": 15
    },
    {
      "x": -2,
      "y": 30,
      "z": 0,
      "name": "Metal_Iron_Glowing_Pipe",
      "support": 15
    },
    {
      "x": -2,
      "y": 31,
      "z": 0,
      "name": "Metal_Iron_Glowing_Pipe_Corner",
      "support": 15,
      "rotation": 9
    },
    {
      "x": -2,
      "y": 43,
      "z": 0,
      "name": "Build_Lightsource_Cyan",
      "rotation": 5
    },
    {
      "x": -2,
      "y": 44,
      "z": 0,
      "name": "Rock_Shale_Cobble"
    },
    {
      "x": -2,
      "y": 45,
      "z": 0,
      "name": "Rock_Shale_Cobble"
    },
    {
      "x": -2,
      "y": 46,
      "z": 0,
      "name": "Rock_Shale_Cobble"
    },
    {
      "x": -2,
      "y": 47,
      "z": 0,
      "name": "Rock_Shale_Brick_Smooth"
    },
    {
      "x": -2,
      "y": 48,
      "z": 0,
      "name": "Rock_Shale_Cobble",
      "support": 15,
      "rotation": 3
    },
    {
      "x": -2,
      "y": 49,
      "z": 0,
      "name": "Rock_Shale_Cobble",
      "rotation": 3
    },
    {
      "x": -2,
      "y": 50,
      "z": 0,
      "name": "Rock_Shale_Cobble",
      "rotation": 3
    },
    {
      "x": -2,
      "y": 51,
      "z": 0,
      "name": "Rock_Shale_Cobble",
      "rotation": 3
    },
    {
      "x": -2,
      "y": 52,
      "z": 0,
      "name": "Rock_Shale_Cobble",
      "rotation": 3
    },
    {
      "x": -2,
      "y": 53,
      "z": 0,
      "name": "Rock_Shale_Cobble",
      "rotation": 3
    },
    {
      "x": -2,
      "y": 0,
      "z": 1,
      "name": "Rock_Shale_Cobble"
    },
    {
      "x": -2,
      "y": 1,
      "z": 1,
      "name": "Rock_Shale_Cobble"
    },
    {
      "x": -2,
      "y": 2,
      "z": 1,
      "name": "Rock_Shale_Cobble"
    },
    {
      "x": -2,
      "y": 3,
      "z": 1,
      "name": "Rock_Shale_Cobble"
    },
    {
      "x": -2,
      "y": 4,
      "z": 1,
      "name": "Rock_Shale_Cobble"
    },
    {
      "x": -2,
      "y": 5,
      "z": 1,
      "name": "Rock_Shale_Cobble"
    },
    {
      "x": -2,
      "y": 6,
      "z": 1,
      "name": "Rock_Shale_Cobble"
    },
    {
      "x": -2,
      "y": 7,
      "z": 1,
      "name": "Rock_Shale_Cobble"
    },
    {
      "x": -2,
      "y": 8,
      "z": 1,
      "name": "Rock_Shale_Cobble"
    },
    {
      "x": -2,
      "y": 9,
      "z": 1,
      "name": "Rock_Shale_Cobble"
    },
    {
      "x": -2,
      "y": 10,
      "z": 1,
      "name": "Rock_Shale_Cobble"
    },
    {
      "x": -2,
      "y": 11,
      "z": 1,
      "name": "Rock_Shale_Cobble"
    },
    {
      "x": -2,
      "y": 12,
      "z": 1,
      "name": "Rock_Shale_Cobble"
    },
    {
      "x": -2,
      "y": 13,
      "z": 1,
      "name": "Rock_Shale_Cobble"
    },
    {
      "x": -2,
      "y": 14,
      "z": 1,
      "name": "Rock_Shale_Cobble"
    },
    {
      "x": -2,
      "y": 15,
      "z": 1,
      "name": "Rock_Shale_Cobble"
    },
    {
      "x": -2,
      "y": 16,
      "z": 1,
      "name": "Rock_Shale_Cobble"
    },
    {
      "x": -2,
      "y": 17,
      "z": 1,
      "name": "Rock_Shale_Cobble"
    },
    {
      "x": -2,
      "y": 18,
      "z": 1,
      "name": "Rock_Shale_Cobble"
    },
    {
      "x": -2,
      "y": 19,
      "z": 1,
      "name": "Rock_Shale_Cobble"
    },
    {
      "x": -2,
      "y": 20,
      "z": 1,
      "name": "Rock_Shale_Cobble"
    },
    {
      "x": -2,
      "y": 21,
      "z": 1,
      "name": "Rock_Shale_Cobble"
    },
    {
      "x": -2,
      "y": 22,
      "z": 1,
      "name": "Rock_Shale_Cobble"
    },
    {
      "x": -2,
      "y": 23,
      "z": 1,
      "name": "Rock_Shale_Cobble"
    },
    {
      "x": -2,
      "y": 24,
      "z": 1,
      "name": "Rock_Shale_Cobble"
    },
    {
      "x": -2,
      "y": 25,
      "z": 1,
      "name": "Rock_Shale_Cobble"
    },
    {
      "x": -2,
      "y": 26,
      "z": 1,
      "name": "Rock_Shale_Cobble"
    },
    {
      "x": -2,
      "y": 27,
      "z": 1,
      "name": "Rock_Shale_Cobble"
    },
    {
      "x": -2,
      "y": 28,
      "z": 1,
      "name": "Rock_Shale_Cobble"
    },
    {
      "x": -2,
      "y": 29,
      "z": 1,
      "name": "Rock_Shale_Cobble"
    },
    {
      "x": -2,
      "y": 30,
      "z": 1,
      "name": "Rock_Shale_Cobble"
    },
    {
      "x": -2,
      "y": 31,
      "z": 1,
      "name": "Rock_Shale_Cobble"
    },
    {
      "x": -2,
      "y": 32,
      "z": 1,
      "name": "Rock_Shale_Cobble"
    },
    {
      "x": -2,
      "y": 33,
      "z": 1,
      "name": "Rock_Shale_Cobble"
    },
    {
      "x": -2,
      "y": 34,
      "z": 1,
      "name": "Rock_Shale_Cobble"
    },
    {
      "x": -2,
      "y": 35,
      "z": 1,
      "name": "Metal_Iron_Glowing_Pipe",
      "support": 15
    },
    {
      "x": -2,
      "y": 36,
      "z": 1,
      "name": "Metal_Iron_Glowing_Pipe",
      "support": 15
    },
    {
      "x": -2,
      "y": 43,
      "z": 1,
      "name": "Build_Lightsource_Cyan",
      "rotation": 5
    },
    {
      "x": -2,
      "y": 44,
      "z": 1,
      "name": "Rock_Shale_Cobble"
    },
    {
      "x": -2,
      "y": 45,
      "z": 1,
      "name": "Rock_Shale_Cobble"
    },
    {
      "x": -2,
      "y": 46,
      "z": 1,
      "name": "Rock_Shale_Cobble"
    },
    {
      "x": -2,
      "y": 47,
      "z": 1,
      "name": "Rock_Shale_Brick_Smooth"
    },
    {
      "x": -2,
      "y": 48,
      "z": 1,
      "name": "Rock_Shale_Cobble"
    },
    {
      "x": -2,
      "y": 49,
      "z": 1,
      "name": "Rock_Shale_Cobble"
    },
    {
      "x": -2,
      "y": 50,
      "z": 1,
      "name": "Rock_Shale_Cobble"
    },
    {
      "x": -2,
      "y": 51,
      "z": 1,
      "name": "Rock_Shale_Cobble"
    },
    {
      "x": -2,
      "y": 52,
      "z": 1,
      "name": "Build_Lightsource_Cyan",
      "rotation": 7
    },
    {
      "x": -2,
      "y": 54,
      "z": 1,
      "name": "Rock_Shale_Cobble"
    },
    {
      "x": -2,
      "y": 56,
      "z": 1,
      "name": "Plant_Moss_Wall_Green_Dark",
      "rotation": 3
    },
    {
      "x": -2,
      "y": 57,
      "z": 1,
      "name": "Plant_Moss_Wall_Green_Dark",
      "rotation": 3
    },
    {
      "x": -2,
      "y": 0,
      "z": 2,
      "name": "Rock_Shale_Cobble"
    },
    {
      "x": -2,
      "y": 1,
      "z": 2,
      "name": "Rock_Shale_Cobble"
    },
    {
      "x": -2,
      "y": 2,
      "z": 2,
      "name": "Rock_Shale_Cobble"
    },
    {
      "x": -2,
      "y": 3,
      "z": 2,
      "name": "Rock_Shale_Cobble"
    },
    {
      "x": -2,
      "y": 4,
      "z": 2,
      "name": "Rock_Shale_Cobble"
    },
    {
      "x": -2,
      "y": 5,
      "z": 2,
      "name": "Rock_Shale_Cobble"
    },
    {
      "x": -2,
      "y": 6,
      "z": 2,
      "name": "Rock_Shale_Cobble"
    },
    {
      "x": -2,
      "y": 8,
      "z": 2,
      "name": "Rock_Shale_Cobble"
    },
    {
      "x": -2,
      "y": 9,
      "z": 2,
      "name": "Rock_Shale_Cobble"
    },
    {
      "x": -2,
      "y": 10,
      "z": 2,
      "name": "Rock_Shale_Cobble"
    },
    {
      "x": -2,
      "y": 11,
      "z": 2,
      "name": "Rock_Shale_Cobble"
    },
    {
      "x": -2,
      "y": 12,
      "z": 2,
      "name": "Rock_Shale_Cobble"
    },
    {
      "x": -2,
      "y": 13,
      "z": 2,
      "name": "Rock_Shale_Cobble"
    },
    {
      "x": -2,
      "y": 14,
      "z": 2,
      "name": "Rock_Shale_Cobble"
    },
    {
      "x": -2,
      "y": 15,
      "z": 2,
      "name": "Rock_Shale_Cobble"
    },
    {
      "x": -2,
      "y": 16,
      "z": 2,
      "name": "Rock_Shale_Cobble"
    },
    {
      "x": -2,
      "y": 17,
      "z": 2,
      "name": "Rock_Shale_Cobble"
    },
    {
      "x": -2,
      "y": 18,
      "z": 2,
      "name": "Rock_Shale_Cobble"
    },
    {
      "x": -2,
      "y": 19,
      "z": 2,
      "name": "Rock_Shale_Cobble"
    },
    {
      "x": -2,
      "y": 20,
      "z": 2,
      "name": "Rock_Shale_Cobble"
    },
    {
      "x": -2,
      "y": 21,
      "z": 2,
      "name": "Rock_Shale_Cobble"
    },
    {
      "x": -2,
      "y": 22,
      "z": 2,
      "name": "Rock_Shale_Cobble"
    },
    {
      "x": -2,
      "y": 23,
      "z": 2,
      "name": "Rock_Shale_Cobble"
    },
    {
      "x": -2,
      "y": 24,
      "z": 2,
      "name": "Rock_Shale_Cobble"
    },
    {
      "x": -2,
      "y": 25,
      "z": 2,
      "name": "Rock_Shale_Cobble"
    },
    {
      "x": -2,
      "y": 26,
      "z": 2,
      "name": "Rock_Shale_Cobble"
    },
    {
      "x": -2,
      "y": 42,
      "z": 2,
      "name": "Rock_Shale_Brick_Smooth"
    },
    {
      "x": -2,
      "y": 43,
      "z": 2,
      "name": "Rock_Shale_Cobble"
    },
    {
      "x": -2,
      "y": 44,
      "z": 2,
      "name": "Rock_Shale_Cobble"
    },
    {
      "x": -2,
      "y": 45,
      "z": 2,
      "name": "Rock_Shale_Cobble"
    },
    {
      "x": -2,
      "y": 46,
      "z": 2,
      "name": "Rock_Shale_Cobble"
    },
    {
      "x": -2,
      "y": 47,
      "z": 2,
      "name": "Rock_Shale_Brick_Smooth"
    },
    {
      "x": -2,
      "y": 48,
      "z": 2,
      "name": "Rock_Shale_Cobble",
      "support": 15
    },
    {
      "x": -2,
      "y": 49,
      "z": 2,
      "name": "Rock_Shale_Cobble"
    },
    {
      "x": -2,
      "y": 50,
      "z": 2,
      "name": "Rock_Shale_Cobble"
    },
    {
      "x": -2,
      "y": 51,
      "z": 2,
      "name": "Rock_Shale_Cobble"
    },
    {
      "x": -2,
      "y": 52,
      "z": 2,
      "name": "Rock_Shale_Cobble"
    },
    {
      "x": -2,
      "y": 53,
      "z": 2,
      "name": "Rock_Shale_Cobble"
    },
    {
      "x": -2,
      "y": 54,
      "z": 2,
      "name": "Rock_Shale_Cobble"
    },
    {
      "x": -2,
      "y": 55,
      "z": 2,
      "name": "Rock_Shale_Brick_Smooth"
    },
    {
      "x": -2,
      "y": 56,
      "z": 2,
      "name": "Rock_Shale_Brick_Smooth"
    },
    {
      "x": -2,
      "y": 0,
      "z": 3,
      "name": "Rock_Shale_Cobble"
    },
    {
      "x": -2,
      "y": 1,
      "z": 3,
      "name": "Rock_Shale_Cobble"
    },
    {
      "x": -2,
      "y": 2,
      "z": 3,
      "name": "Rock_Shale_Cobble"
    },
    {
      "x": -2,
      "y": 3,
      "z": 3,
      "name": "Rock_Shale_Cobble"
    },
    {
      "x": -2,
      "y": 4,
      "z": 3,
      "name": "Rock_Shale_Cobble"
    },
    {
      "x": -2,
      "y": 5,
      "z": 3,
      "name": "Rock_Shale_Cobble"
    },
    {
      "x": -2,
      "y": 6,
      "z": 3,
      "name": "Rock_Shale_Cobble"
    },
    {
      "x": -2,
      "y": 7,
      "z": 3,
      "name": "Build_Lightsource_Cyan"
    },
    {
      "x": -2,
      "y": 8,
      "z": 3,
      "name": "Build_Lightsource_Cyan"
    },
    {
      "x": -2,
      "y": 9,
      "z": 3,
      "name": "Build_Lightsource_Cyan"
    },
    {
      "x": -2,
      "y": 10,
      "z": 3,
      "name": "Build_Lightsource_Cyan"
    },
    {
      "x": -2,
      "y": 11,
      "z": 3,
      "name": "Build_Lightsource_Cyan"
    },
    {
      "x": -2,
      "y": 12,
      "z": 3,
      "name": "Build_Lightsource_Cyan",
      "rotation": 4
    },
    {
      "x": -2,
      "y": 13,
      "z": 3,
      "name": "Rock_Shale_Cobble"
    },
    {
      "x": -2,
      "y": 14,
      "z": 3,
      "name": "Rock_Shale_Cobble"
    },
    {
      "x": -2,
      "y": 15,
      "z": 3,
      "name": "Rock_Shale_Cobble"
    },
    {
      "x": -2,
      "y": 16,
      "z": 3,
      "name": "Plant_Moss_Rug_Green_Dark",
      "support": 15
    },
    {
      "x": -2,
      "y": 43,
      "z": 3,
      "name": "Rock_Shale_Cobble"
    },
    {
      "x": -2,
      "y": 44,
      "z": 3,
      "name": "Build_Lightsource_Cyan",
      "rotation": 4
    },
    {
      "x": -2,
      "y": 45,
      "z": 3,
      "name": "Rock_Shale_Cobble"
    },
    {
      "x": -2,
      "y": 46,
      "z": 3,
      "name": "Rock_Shale_Cobble"
    },
    {
      "x": -2,
      "y": 47,
      "z": 3,
      "name": "Rock_Shale_Brick_Smooth"
    },
    {
      "x": -2,
      "y": 48,
      "z": 3,
      "name": "Rock_Shale_Cobble",
      "support": 15
    },
    {
      "x": -2,
      "y": 49,
      "z": 3,
      "name": "Rock_Shale_Cobble"
    },
    {
      "x": -2,
      "y": 50,
      "z": 3,
      "name": "Build_Lightsource_Cyan"
    },
    {
      "x": -2,
      "y": 51,
      "z": 3,
      "name": "Build_Lightsource_Cyan",
      "rotation": 4
    },
    {
      "x": -2,
      "y": 52,
      "z": 3,
      "name": "Rock_Shale_Cobble"
    },
    {
      "x": -2,
      "y": 53,
      "z": 3,
      "name": "Plant_Moss_Rug_Green_Dark"
    },
    {
      "x": -2,
      "y": 45,
      "z": 4,
      "name": "Rock_Shale_Cobble"
    },
    {
      "x": -2,
      "y": 46,
      "z": 4,
      "name": "Rock_Shale_Cobble"
    },
    {
      "x": -2,
      "y": 47,
      "z": 4,
      "name": "Rock_Shale_Brick_Smooth",
      "support": 15
    },
    {
      "x": -2,
      "y": 48,
      "z": 4,
      "name": "Rock_Shale_Cobble"
    },
    {
      "x": -2,
      "y": 49,
      "z": 4,
      "name": "Rock_Shale_Cobble"
    },
    {
      "x": -2,
      "y": 50,
      "z": 4,
      "name": "Rock_Shale_Cobble"
    },
    {
      "x": -2,
      "y": 45,
      "z": 5,
      "name": "Rock_Shale_Cobble"
    },
    {
      "x": -2,
      "y": 46,
      "z": 5,
      "name": "Rock_Shale_Cobble",
      "support": 15
    },
    {
      "x": -2,
      "y": 47,
      "z": 5,
      "name": "Rock_Shale_Brick_Smooth"
    },
    {
      "x": -2,
      "y": 48,
      "z": 5,
      "name": "Rock_Shale_Cobble"
    },
    {
      "x": -2,
      "y": 49,
      "z": 5,
      "name": "Rock_Shale_Cobble"
    },
    {
      "x": -2,
      "y": 51,
      "z": 5,
      "name": "Metal_Iron_Glowing_Pipe",
      "rotation": 5
    },
    {
      "x": -2,
      "y": 47,
      "z": 6,
      "name": "Rock_Shale_Brick_Smooth"
    },
    {
      "x": -1,
      "y": 47,
      "z": -6,
      "name": "Rock_Shale_Brick_Smooth"
    },
    {
      "x": -1,
      "y": 45,
      "z": -5,
      "name": "Rock_Shale_Cobble"
    },
    {
      "x": -1,
      "y": 47,
      "z": -5,
      "name": "Rock_Shale_Brick_Smooth"
    },
    {
      "x": -1,
      "y": 49,
      "z": -5,
      "name": "Rock_Shale_Cobble",
      "rotation": 3
    },
    {
      "x": -1,
      "y": 50,
      "z": -5,
      "name": "Metal_Iron_Glowing_Pipe_Corner",
      "rotation": 24
    },
    {
      "x": -1,
      "y": 15,
      "z": -4,
      "name": "Plant_Moss_Wall_Green_Dark",
      "support": 15,
      "rotation": 3
    },
    {
      "x": -1,
      "y": 44,
      "z": -4,
      "name": "Rock_Shale_Cobble"
    },
    {
      "x": -1,
      "y": 45,
      "z": -4,
      "name": "Rock_Shale_Cobble"
    },
    {
      "x": -1,
      "y": 46,
      "z": -4,
      "name": "Build_Lightsource_Cyan",
      "rotation": 4
    },
    {
      "x": -1,
      "y": 47,
      "z": -4,
      "name": "Rock_Shale_Brick_Smooth"
    },
    {
      "x": -1,
      "y": 48,
      "z": -4,
      "name": "Build_Lightsource_Cyan",
      "rotation": 6
    },
    {
      "x": -1,
      "y": 49,
      "z": -4,
      "name": "Rock_Shale_Cobble",
      "rotation": 3
    },
    {
      "x": -1,
      "y": 50,
      "z": -4,
      "name": "Rock_Shale_Cobble",
      "rotation": 3
    },
    {
      "x": -1,
      "y": 51,
      "z": -4,
      "name": "Rock_Shale_Cobble",
      "rotation": 3
    },
    {
      "x": -1,
      "y": 42,
      "z": -3,
      "name": "Metal_Iron_Glowing_Pipe_Corner",
      "rotation": 24
    },
    {
      "x": -1,
      "y": 44,
      "z": -3,
      "name": "Rock_Shale_Cobble"
    },
    {
      "x": -1,
      "y": 45,
      "z": -3,
      "name": "Rock_Shale_Cobble"
    },
    {
      "x": -1,
      "y": 46,
      "z": -3,
      "name": "Rock_Shale_Cobble"
    },
    {
      "x": -1,
      "y": 47,
      "z": -3,
      "name": "Rock_Shale_Brick_Smooth"
    },
    {
      "x": -1,
      "y": 48,
      "z": -3,
      "name": "Rock_Shale_Cobble",
      "rotation": 3
    },
    {
      "x": -1,
      "y": 49,
      "z": -3,
      "name": "Rock_Shale_Cobble",
      "rotation": 3
    },
    {
      "x": -1,
      "y": 50,
      "z": -3,
      "name": "Rock_Shale_Cobble",
      "rotation": 3
    },
    {
      "x": -1,
      "y": 51,
      "z": -3,
      "name": "Rock_Shale_Cobble",
      "rotation": 3
    },
    {
      "x": -1,
      "y": 52,
      "z": -3,
      "name": "Plant_Moss_Rug_Green_Dark"
    },
    {
      "x": -1,
      "y": 10,
      "z": -2,
      "name": "Metal_Iron_Pipe_Corner",
      "support": 15,
      "rotation": 2
    },
    {
      "x": -1,
      "y": 11,
      "z": -2,
      "name": "Metal_Iron_Glowing_Pipe",
      "support": 15
    },
    {
      "x": -1,
      "y": 12,
      "z": -2,
      "name": "Metal_Iron_Glowing_Pipe",
      "support": 15
    },
    {
      "x": -1,
      "y": 13,
      "z": -2,
      "name": "Metal_Iron_Glowing_Pipe",
      "support": 15
    },
    {
      "x": -1,
      "y": 14,
      "z": -2,
      "name": "Metal_Iron_Glowing_Pipe",
      "support": 15
    },
    {
      "x": -1,
      "y": 15,
      "z": -2,
      "name": "Metal_Iron_Glowing_Pipe",
      "support": 15
    },
    {
      "x": -1,
      "y": 16,
      "z": -2,
      "name": "Metal_Iron_Glowing_Pipe_Corner",
      "support": 15,
      "rotation": 14
    },
    {
      "x": -1,
      "y": 26,
      "z": -2,
      "name": "Plant_Moss_Wall_Green_Dark",
      "support": 15,
      "rotation": 3
    },
    {
      "x": -1,
      "y": 42,
      "z": -2,
      "name": "Metal_Iron_Glowing_Pipe",
      "rotation": 4
    },
    {
      "x": -1,
      "y": 43,
      "z": -2,
      "name": "Build_Lightsource_Cyan",
      "rotation": 4
    },
    {
      "x": -1,
      "y": 44,
      "z": -2,
      "name": "Rock_Shale_Cobble"
    },
    {
      "x": -1,
      "y": 45,
      "z": -2,
      "name": "Rock_Shale_Cobble"
    },
    {
      "x": -1,
      "y": 46,
      "z": -2,
      "name": "Rock_Shale_Cobble"
    },
    {
      "x": -1,
      "y": 47,
      "z": -2,
      "name": "Rock_Shale_Brick_Smooth"
    },
    {
      "x": -1,
      "y": 48,
      "z": -2,
      "name": "Rock_Shale_Cobble",
      "rotation": 3
    },
    {
      "x": -1,
      "y": 49,
      "z": -2,
      "name": "Rock_Shale_Cobble",
      "rotation": 3
    },
    {
      "x": -1,
      "y": 50,
      "z": -2,
      "name": "Rock_Shale_Cobble",
      "rotation": 3
    },
    {
      "x": -1,
      "y": 51,
      "z": -2,
      "name": "Rock_Shale_Cobble",
      "rotation": 3
    },
    {
      "x": -1,
      "y": 52,
      "z": -2,
      "name": "Build_Lightsource_Cyan",
      "rotation": 6
    },
    {
      "x": -1,
      "y": 53,
      "z": -2,
      "name": "Plant_Moss_Rug_Green_Dark"
    },
    {
      "x": -1,
      "y": 54,
