{
  "version": 8,
  "blockIdVersion": 11,
  "anchorX": 0,
  "anchorY": 0,
  "anchorZ": 0,
  "blocks": [
    {
      "x": -15,
      "y": 12,
      "z": -13,
      "name": "Rock_Shale_Brick_Smooth_Half",
      "rotation": 7
    },
    {
      "x": -15,
      "y": 13,
      "z": -13,
      "name": "Rock_Shale_Brick_Smooth_Half",
      "rotation": 7
    },
    {
      "x": -15,
      "y": 14,
      "z": -13,
      "name": "Rock_Shale_Brick_Smooth_Half",
      "rotation": 7
    },
    {
      "x": -15,
      "y": 31,
      "z": -13,
      "name": "Rock_Shale_Brick_Smooth_Half",
      "rotation": 7
    },
    {
      "x": -15,
      "y": 32,
      "z": -13,
      "name": "Rock_Shale_Brick_Smooth_Half",
      "rotation": 7
    },
    {
      "x": -15,
      "y": 33,
      "z": -13,
      "name": "Rock_Shale_Brick_Smooth_Half",
      "rotation": 7
    },
    {
      "x": -15,
      "y": 11,
      "z": -12,
      "name": "Rock_Shale_Brick_Smooth_Half",
      "rotation": 7
    },
    {
      "x": -15,
      "y": 12,
      "z": -12,
      "name": "Rock_Shale_Brick_Smooth_Half",
      "rotation": 7
    },
    {
      "x": -15,
      "y": 13,
      "z": -12,
      "name": "Rock_Shale_Brick_Smooth_Half",
      "rotation": 7
    },
    {
      "x": -15,
      "y": 30,
      "z": -12,
      "name": "Rock_Shale_Brick_Smooth_Half",
      "rotation": 7
    },
    {
      "x": -15,
      "y": 31,
      "z": -12,
      "name": "Rock_Shale_Brick_Smooth_Half",
      "rotation": 7
    },
    {
      "x": -15,
      "y": 32,
      "z": -12,
      "name": "Rock_Shale_Brick_Smooth_Half",
      "rotation": 7
    },
    {
      "x": -15,
      "y": 10,
      "z": -11,
      "name": "Rock_Shale_Brick_Smooth_Half",
      "rotation": 7
    },
    {
      "x": -15,
      "y": 11,
      "z": -11,
      "name": "Rock_Shale_Brick_Smooth_Half",
      "rotation": 7
    },
    {
      "x": -15,
      "y": 12,
      "z": -11,
      "name": "Rock_Shale_Brick_Smooth_Half",
      "rotation": 7
    },
    {
      "x": -15,
      "y": 29,
      "z": -11,
      "name": "Rock_Shale_Brick_Smooth_Half",
      "rotation": 7
    },
    {
      "x": -15,
      "y": 30,
      "z": -11,
      "name": "Rock_Shale_Brick_Smooth_Half",
      "rotation": 7
    },
    {
      "x": -15,
      "y": 31,
      "z": -11,
      "name": "Rock_Shale_Brick_Smooth_Half",
      "rotation": 7
    },
    {
      "x": -15,
      "y": 10,
      "z": -10,
      "name": "Rock_Shale_Brick_Smooth_Half",
      "rotation": 7
    },
    {
      "x": -15,
      "y": 11,
      "z": -10,
      "name": "Rock_Shale_Brick_Smooth_Half",
      "rotation": 7
    },
    {
      "x": -15,
      "y": 29,
      "z": -10,
      "name": "Rock_Shale_Brick_Smooth_Half",
      "rotation": 7
    },
    {
      "x": -15,
      "y": 30,
      "z": -10,
      "name": "Rock_Shale_Brick_Smooth_Half",
      "rotation": 7
    },
    {
      "x": -15,
      "y": 9,
      "z": -9,
      "name": "Rock_Shale_Brick_Smooth_Half",
      "rotation": 7
    },
    {
      "x": -15,
      "y": 10,
      "z": -9,
      "name": "Rock_Shale_Brick_Smooth_Half",
      "rotation": 7
    },
    {
      "x": -15,
      "y": 28,
      "z": -9,
      "name": "Rock_Shale_Brick_Smooth_Half",
      "rotation": 7
    },
    {
      "x": -15,
      "y": 29,
      "z": -9,
      "name": "Rock_Shale_Brick_Smooth_Half",
      "rotation": 7
    },
    {
      "x": -15,
      "y": 9,
      "z": 9,
      "name": "Rock_Shale_Brick_Smooth_Half",
      "rotation": 7
    },
    {
      "x": -15,
      "y": 10,
      "z": 9,
      "name": "Rock_Shale_Brick_Smooth_Half",
      "rotation": 7
    },
    {
      "x": -15,
      "y": 28,
      "z": 9,
      "name": "Rock_Shale_Brick_Smooth_Half",
      "rotation": 7
    },
    {
      "x": -15,
      "y": 29,
      "z": 9,
      "name": "Rock_Shale_Brick_Smooth_Half",
      "rotation": 7
    },
    {
      "x": -15,
      "y": 10,
      "z": 10,
      "name": "Rock_Shale_Brick_Smooth_Half",
      "rotation": 7
    },
    {
      "x": -15,
      "y": 11,
      "z": 10,
      "name": "Rock_Shale_Brick_Smooth_Half",
      "rotation": 7
    },
    {
      "x": -15,
      "y": 29,
      "z": 10,
      "name": "Rock_Shale_Brick_Smooth_Half",
      "rotation": 7
    },
    {
      "x": -15,
      "y": 30,
      "z": 10,
      "name": "Rock_Shale_Brick_Smooth_Half",
      "rotation": 7
    },
    {
      "x": -15,
      "y": 10,
      "z": 11,
      "name": "Rock_Shale_Brick_Smooth_Half",
      "rotation": 7
    },
    {
      "x": -15,
      "y": 11,
      "z": 11,
      "name": "Rock_Shale_Brick_Smooth_Half",
      "rotation": 7
    },
    {
      "x": -15,
      "y": 12,
      "z": 11,
      "name": "Rock_Shale_Brick_Smooth_Half",
      "rotation": 7
    },
    {
      "x": -15,
      "y": 29,
      "z": 11,
      "name": "Rock_Shale_Brick_Smooth_Half",
      "rotation": 7
    },
    {
      "x": -15,
      "y": 30,
      "z": 11,
      "name": "Rock_Shale_Brick_Smooth_Half",
      "rotation": 7
    },
    {
      "x": -15,
      "y": 31,
      "z": 11,
      "name": "Rock_Shale_Brick_Smooth_Half",
      "rotation": 7
    },
    {
      "x": -15,
      "y": 11,
      "z": 12,
      "name": "Rock_Shale_Brick_Smooth_Half",
      "rotation": 7
    },
    {
      "x": -15,
      "y": 12,
      "z": 12,
      "name": "Rock_Shale_Brick_Smooth_Half",
      "rotation": 7
    },
    {
      "x": -15,
      "y": 13,
      "z": 12,
      "name": "Rock_Shale_Brick_Smooth_Half",
      "rotation": 7
    },
    {
      "x": -15,
      "y": 30,
      "z": 12,
      "name": "Rock_Shale_Brick_Smooth_Half",
      "rotation": 7
    },
    {
      "x": -15,
      "y": 31,
      "z": 12,
      "name": "Rock_Shale_Brick_Smooth_Half",
      "rotation": 7
    },
    {
      "x": -15,
      "y": 32,
      "z": 12,
      "name": "Rock_Shale_Brick_Smooth_Half",
      "rotation": 7
    },
    {
      "x": -15,
      "y": 12,
      "z": 13,
      "name": "Rock_Shale_Brick_Smooth_Half",
      "rotation": 7
    },
    {
      "x": -15,
      "y": 13,
      "z": 13,
      "name": "Rock_Shale_Brick_Smooth_Half",
      "rotation": 7
    },
    {
      "x": -15,
      "y": 14,
      "z": 13,
      "name": "Rock_Shale_Brick_Smooth_Half",
      "rotation": 7
    },
    {
      "x": -15,
      "y": 31,
      "z": 13,
      "name": "Rock_Shale_Brick_Smooth_Half",
      "rotation": 7
    },
    {
      "x": -15,
      "y": 32,
      "z": 13,
      "name": "Rock_Shale_Brick_Smooth_Half",
      "rotation": 7
    },
    {
      "x": -15,
      "y": 33,
      "z": 13,
      "name": "Rock_Shale_Brick_Smooth_Half",
      "rotation": 7
    },
    {
      "x": -14,
      "y": 12,
      "z": -14,
      "name": "Rock_Shale_Brick_Stairs",
      "rotation": 24
    },
    {
      "x": -14,
      "y": 13,
      "z": -14,
      "name": "Rock_Shale_Brick_Stairs",
      "rotation": 24
    },
    {
      "x": -14,
      "y": 14,
      "z": -14,
      "name": "Rock_Shale_Brick_Stairs",
      "rotation": 24
    },
    {
      "x": -14,
      "y": 15,
      "z": -14,
      "name": "Rock_Shale_Brick_Stairs",
      "rotation": 24
    },
    {
      "x": -14,
      "y": 16,
      "z": -14,
      "name": "Rock_Shale_Brick_Stairs",
      "rotation": 24
    },
    {
      "x": -14,
      "y": 17,
      "z": -14,
      "name": "Rock_Shale_Brick_Beam"
    },
    {
      "x": -14,
      "y": 31,
      "z": -14,
      "name": "Rock_Shale_Brick_Stairs",
      "rotation": 24
    },
    {
      "x": -14,
      "y": 32,
      "z": -14,
      "name": "Rock_Shale_Brick_Stairs",
      "rotation": 24
    },
    {
      "x": -14,
      "y": 33,
      "z": -14,
      "name": "Rock_Shale_Brick_Stairs",
      "rotation": 24
    },
    {
      "x": -14,
      "y": 34,
      "z": -14,
      "name": "Rock_Shale_Brick_Stairs",
      "rotation": 24
    },
    {
      "x": -14,
      "y": 35,
      "z": -14,
      "name": "Rock_Shale_Brick_Stairs",
      "rotation": 24
    },
    {
      "x": -14,
      "y": 36,
      "z": -14,
      "name": "Rock_Shale_Brick_Beam"
    },
    {
      "x": -14,
      "y": 11,
      "z": -13,
      "name": "Rock_Shale_Brick_Smooth_Half",
      "rotation": 6
    },
    {
      "x": -14,
      "y": 12,
      "z": -13,
      "name": "Rock_Runic_Teal_Brick_Stairs",
      "rotation": 9
    },
    {
      "x": -14,
      "y": 13,
      "z": -13,
      "name": "Rock_Shale_Brick_Smooth_Half",
      "rotation": 4
    },
    {
      "x": -14,
      "y": 14,
      "z": -13,
      "name": "Rock_Shale_Brick_Smooth_Half",
      "rotation": 4
    },
    {
      "x": -14,
      "y": 15,
      "z": -13,
      "name": "Rock_Shale_Brick_Smooth_Half",
      "rotation": 4
    },
    {
      "x": -14,
      "y": 30,
      "z": -13,
      "name": "Rock_Shale_Brick_Smooth_Half",
      "rotation": 6
    },
    {
      "x": -14,
      "y": 31,
      "z": -13,
      "name": "Rock_Runic_Teal_Brick_Stairs",
      "rotation": 9
    },
    {
      "x": -14,
      "y": 32,
      "z": -13,
      "name": "Rock_Shale_Brick_Smooth_Half",
      "rotation": 4
    },
    {
      "x": -14,
      "y": 33,
      "z": -13,
      "name": "Rock_Shale_Brick_Smooth_Half",
      "rotation": 4
    },
    {
      "x": -14,
      "y": 34,
      "z": -13,
      "name": "Rock_Shale_Brick_Smooth_Half",
      "rotation": 4
    },
    {
      "x": -14,
      "y": 10,
      "z": -12,
      "name": "Rock_Shale_Brick_Smooth_Half",
      "rotation": 6
    },
    {
      "x": -14,
      "y": 11,
      "z": -12,
      "name": "Rock_Runic_Teal_Brick_Stairs",
      "rotation": 9
    },
    {
      "x": -14,
      "y": 12,
      "z": -12,
      "name": "Rock_Shale_Brick_Smooth_Half",
      "rotation": 4
    },
    {
      "x": -14,
      "y": 29,
      "z": -12,
      "name": "Rock_Shale_Brick_Smooth_Half",
      "rotation": 6
    },
    {
      "x": -14,
      "y": 30,
      "z": -12,
      "name": "Rock_Runic_Teal_Brick_Stairs",
      "rotation": 9
    },
    {
      "x": -14,
      "y": 31,
      "z": -12,
      "name": "Rock_Shale_Brick_Smooth_Half",
      "rotation": 4
    },
    {
      "x": -14,
      "y": 48,
      "z": -12,
      "name": "*Rock_Shale_Brick_Roof_Steep_State_Definitions_Corner_Left",
      "rotation": 2
    },
    {
      "x": -14,
      "y": 49,
      "z": -12,
      "name": "*Rock_Shale_Brick_Roof_Steep_State_Definitions_Corner_Left",
      "filler": 1024,
      "rotation": 2
    },
    {
      "x": -14,
      "y": 8,
      "z": -11,
      "name": "Rock_Shale_Brick_Smooth_Half",
      "rotation": 7
    },
    {
      "x": -14,
      "y": 9,
      "z": -11,
      "name": "Rock_Shale_Brick_Smooth_Half",
      "rotation": 7
    },
    {
      "x": -14,
      "y": 10,
      "z": -11,
      "name": "Rock_Runic_Teal_Brick_Stairs",
      "rotation": 9
    },
    {
      "x": -14,
      "y": 11,
      "z": -11,
      "name": "Rock_Shale_Brick_Smooth_Half",
      "rotation": 4
    },
    {
      "x": -14,
      "y": 27,
      "z": -11,
      "name": "Rock_Shale_Brick_Smooth_Half",
      "rotation": 7
    },
    {
      "x": -14,
      "y": 28,
      "z": -11,
      "name": "Rock_Shale_Brick_Smooth_Half",
      "rotation": 7
    },
    {
      "x": -14,
      "y": 29,
      "z": -11,
      "name": "Rock_Runic_Teal_Brick_Stairs",
      "rotation": 9
    },
    {
      "x": -14,
      "y": 30,
      "z": -11,
      "name": "Rock_Shale_Brick_Smooth_Half",
      "rotation": 4
    },
    {
      "x": -14,
      "y": 48,
      "z": -11,
      "name": "Rock_Shale_Brick_Roof_Steep",
      "rotation": 3
    },
    {
      "x": -14,
      "y": 49,
      "z": -11,
      "name": "Rock_Shale_Brick_Roof_Steep",
      "filler": 1024,
      "rotation": 3
    },
    {
      "x": -14,
      "y": 8,
      "z": -10,
      "name": "Rock_Shale_Brick_Smooth_Half",
      "rotation": 7
    },
    {
      "x": -14,
      "y": 9,
      "z": -10,
      "name": "Rock_Shale_Brick_Smooth_Half",
      "rotation": 7
    },
    {
      "x": -14,
      "y": 10,
      "z": -10,
      "name": "Rock_Shale_Brick_Smooth_Half",
      "rotation": 4
    },
    {
      "x": -14,
      "y": 27,
      "z": -10,
      "name": "Rock_Shale_Brick_Smooth_Half",
      "rotation": 7
    },
    {
      "x": -14,
      "y": 28,
      "z": -10,
      "name": "Rock_Shale_Brick_Smooth_Half",
      "rotation": 7
    },
    {
      "x": -14,
      "y": 29,
      "z": -10,
      "name": "Rock_Shale_Brick_Smooth_Half",
      "rotation": 4
    },
    {
      "x": -14,
      "y": 48,
      "z": -10,
      "name": "Rock_Shale_Brick_Roof_Steep",
      "rotation": 3
    },
    {
      "x": -14,
      "y": 49,
      "z": -10,
      "name": "Rock_Shale_Brick_Roof_Steep",
      "filler": 1024,
      "rotation": 3
    },
    {
      "x": -14,
      "y": 8,
      "z": -9,
      "name": "Rock_Shale_Brick_Smooth_Half",
      "rotation": 7
    },
    {
      "x": -14,
      "y": 9,
      "z": -9,
      "name": "Rock_Shale_Brick_Smooth_Half",
      "rotation": 7
    },
    {
      "x": -14,
      "y": 10,
      "z": -9,
      "name": "Rock_Shale_Brick_Smooth_Half",
      "rotation": 7
    },
    {
      "x": -14,
      "y": 27,
      "z": -9,
      "name": "Rock_Shale_Brick_Smooth_Half",
      "rotation": 7
    },
    {
      "x": -14,
      "y": 28,
      "z": -9,
      "name": "Rock_Shale_Brick_Smooth_Half",
      "rotation": 7
    },
    {
      "x": -14,
      "y": 29,
      "z": -9,
      "name": "Rock_Shale_Brick_Smooth_Half",
      "rotation": 7
    },
    {
      "x": -14,
      "y": 48,
      "z": -9,
      "name": "Rock_Shale_Brick_Roof_Steep",
      "rotation": 3
    },
    {
      "x": -14,
      "y": 49,
      "z": -9,
      "name": "Rock_Shale_Brick_Roof_Steep",
      "filler": 1024,
      "rotation": 3
    },
    {
      "x": -14,
      "y": 7,
      "z": -8,
      "name": "Rock_Shale_Brick_Smooth_Half",
      "rotation": 7
    },
    {
      "x": -14,
      "y": 8,
      "z": -8,
      "name": "Rock_Shale_Brick_Smooth_Half",
      "rotation": 7
    },
    {
      "x": -14,
      "y": 9,
      "z": -8,
      "name": "Rock_Shale_Brick_Smooth_Half",
      "rotation": 7
    },
    {
      "x": -14,
      "y": 10,
      "z": -8,
      "name": "Rock_Shale_Brick_Smooth_Half",
      "rotation": 7
    },
    {
      "x": -14,
      "y": 26,
      "z": -8,
      "name": "Rock_Shale_Brick_Smooth_Half",
      "rotation": 7
    },
    {
      "x": -14,
      "y": 27,
      "z": -8,
      "name": "Rock_Shale_Brick_Smooth_Half",
      "rotation": 7
    },
    {
      "x": -14,
      "y": 28,
      "z": -8,
      "name": "Rock_Shale_Brick_Smooth_Half",
      "rotation": 7
    },
    {
      "x": -14,
      "y": 29,
      "z": -8,
      "name": "Rock_Shale_Brick_Smooth_Half",
      "rotation": 7
    },
    {
      "x": -14,
      "y": 48,
      "z": -8,
      "name": "*Rock_Shale_Brick_Roof_Steep_State_Definitions_Corner_Right"
    },
    {
      "x": -14,
      "y": 49,
      "z": -8,
      "name": "*Rock_Shale_Brick_Roof_Steep_State_Definitions_Corner_Right",
      "filler": 1024
    },
    {
      "x": -14,
      "y": 7,
      "z": 8,
      "name": "Rock_Shale_Brick_Smooth_Half",
      "rotation": 7
    },
    {
      "x": -14,
      "y": 8,
      "z": 8,
      "name": "Rock_Shale_Brick_Smooth_Half",
      "rotation": 7
    },
    {
      "x": -14,
      "y": 9,
      "z": 8,
      "name": "Rock_Shale_Brick_Smooth_Half",
      "rotation": 7
    },
    {
      "x": -14,
      "y": 10,
      "z": 8,
      "name": "Rock_Shale_Brick_Smooth_Half",
      "rotation": 7
    },
    {
      "x": -14,
      "y": 26,
      "z": 8,
      "name": "Rock_Shale_Brick_Smooth_Half",
      "rotation": 7
    },
    {
      "x": -14,
      "y": 27,
      "z": 8,
      "name": "Rock_Shale_Brick_Smooth_Half",
      "rotation": 7
    },
    {
      "x": -14,
      "y": 28,
      "z": 8,
      "name": "Rock_Shale_Brick_Smooth_Half",
      "rotation": 7
    },
    {
      "x": -14,
      "y": 29,
      "z": 8,
      "name": "Rock_Shale_Brick_Smooth_Half",
      "rotation": 7
    },
    {
      "x": -14,
      "y": 48,
      "z": 8,
      "name": "*Rock_Shale_Brick_Roof_Steep_State_Definitions_Corner_Left",
      "rotation": 2
    },
    {
      "x": -14,
      "y": 49,
      "z": 8,
      "name": "*Rock_Shale_Brick_Roof_Steep_State_Definitions_Corner_Left",
      "filler": 1024,
      "rotation": 2
    },
    {
      "x": -14,
      "y": 8,
      "z": 9,
      "name": "Rock_Shale_Brick_Smooth_Half",
      "rotation": 7
    },
    {
      "x": -14,
      "y": 9,
      "z": 9,
      "name": "Rock_Shale_Brick_Smooth_Half",
      "rotation": 7
    },
    {
      "x": -14,
      "y": 10,
      "z": 9,
      "name": "Rock_Shale_Brick_Smooth_Half",
      "rotation": 7
    },
    {
      "x": -14,
      "y": 27,
      "z": 9,
      "name": "Rock_Shale_Brick_Smooth_Half",
      "rotation": 7
    },
    {
      "x": -14,
      "y": 28,
      "z": 9,
      "name": "Rock_Shale_Brick_Smooth_Half",
      "rotation": 7
    },
    {
      "x": -14,
      "y": 29,
      "z": 9,
      "name": "Rock_Shale_Brick_Smooth_Half",
      "rotation": 7
    },
    {
      "x": -14,
      "y": 48,
      "z": 9,
      "name": "Rock_Shale_Brick_Roof_Steep",
      "rotation": 3
    },
    {
      "x": -14,
      "y": 49,
      "z": 9,
      "name": "Rock_Shale_Brick_Roof_Steep",
      "filler": 1024,
      "rotation": 3
    },
    {
      "x": -14,
      "y": 8,
      "z": 10,
      "name": "Rock_Shale_Brick_Smooth_Half",
      "rotation": 7
    },
    {
      "x": -14,
      "y": 9,
      "z": 10,
      "name": "Rock_Shale_Brick_Smooth_Half",
      "rotation": 7
    },
    {
      "x": -14,
      "y": 10,
      "z": 10,
      "name": "Rock_Shale_Brick_Smooth_Half",
      "rotation": 6
    },
    {
      "x": -14,
      "y": 27,
      "z": 10,
      "name": "Rock_Shale_Brick_Smooth_Half",
      "rotation": 7
    },
    {
      "x": -14,
      "y": 28,
      "z": 10,
      "name": "Rock_Shale_Brick_Smooth_Half",
      "rotation": 7
    },
    {
      "x": -14,
      "y": 29,
      "z": 10,
      "name": "Rock_Shale_Brick_Smooth_Half",
      "rotation": 6
    },
    {
      "x": -14,
      "y": 48,
      "z": 10,
      "name": "Rock_Shale_Brick_Roof_Steep",
      "rotation": 3
    },
    {
      "x": -14,
      "y": 49,
      "z": 10,
      "name": "Rock_Shale_Brick_Roof_Steep",
      "filler": 1024,
      "rotation": 3
    },
    {
      "x": -14,
      "y": 8,
      "z": 11,
      "name": "Rock_Shale_Brick_Smooth_Half",
      "rotation": 7
    },
    {
      "x": -14,
      "y": 9,
      "z": 11,
      "name": "Rock_Shale_Brick_Smooth_Half",
      "rotation": 7
    },
    {
      "x": -14,
      "y": 10,
      "z": 11,
      "name": "Rock_Runic_Teal_Brick_Stairs",
      "rotation": 9
    },
    {
      "x": -14,
      "y": 11,
      "z": 11,
      "name": "Rock_Shale_Brick_Smooth_Half",
      "rotation": 6
    },
    {
      "x": -14,
      "y": 27,
      "z": 11,
      "name": "Rock_Shale_Brick_Smooth_Half",
      "rotation": 7
    },
    {
      "x": -14,
      "y": 28,
      "z": 11,
      "name": "Rock_Shale_Brick_Smooth_Half",
      "rotation": 7
    },
    {
      "x": -14,
      "y": 29,
      "z": 11,
      "name": "Rock_Runic_Teal_Brick_Stairs",
      "rotation": 9
    },
    {
      "x": -14,
      "y": 30,
      "z": 11,
      "name": "Rock_Shale_Brick_Smooth_Half",
      "rotation": 6
    },
    {
      "x": -14,
      "y": 48,
      "z": 11,
      "name": "Rock_Shale_Brick_Roof_Steep",
      "rotation": 3
    },
    {
      "x": -14,
      "y": 49,
      "z": 11,
      "name": "Rock_Shale_Brick_Roof_Steep",
      "filler": 1024,
      "rotation": 3
    },
    {
      "x": -14,
      "y": 10,
      "z": 12,
      "name": "Rock_Shale_Brick_Smooth_Half",
      "rotation": 4
    },
    {
      "x": -14,
      "y": 11,
      "z": 12,
      "name": "Rock_Runic_Teal_Brick_Stairs",
      "rotation": 9
    },
    {
      "x": -14,
      "y": 12,
      "z": 12,
      "name": "Rock_Shale_Brick_Smooth_Half",
      "rotation": 6
    },
    {
      "x": -14,
      "y": 29,
      "z": 12,
      "name": "Rock_Shale_Brick_Smooth_Half",
      "rotation": 4
    },
    {
      "x": -14,
      "y": 30,
      "z": 12,
      "name": "Rock_Runic_Teal_Brick_Stairs",
      "rotation": 9
    },
    {
      "x": -14,
      "y": 31,
      "z": 12,
      "name": "Rock_Shale_Brick_Smooth_Half",
      "rotation": 6
    },
    {
      "x": -14,
      "y": 48,
      "z": 12,
      "name": "*Rock_Shale_Brick_Roof_Steep_State_Definitions_Corner_Right"
    },
    {
      "x": -14,
      "y": 49,
      "z": 12,
      "name": "*Rock_Shale_Brick_Roof_Steep_State_Definitions_Corner_Right",
      "filler": 1024
    },
    {
      "x": -14,
      "y": 11,
      "z": 13,
      "name": "Rock_Shale_Brick_Smooth_Half",
      "rotation": 4
    },
    {
      "x": -14,
      "y": 12,
      "z": 13,
      "name": "Rock_Runic_Teal_Brick_Stairs",
      "rotation": 9
    },
    {
      "x": -14,
      "y": 13,
      "z": 13,
      "name": "Rock_Shale_Brick_Smooth_Half",
      "rotation": 6
    },
    {
      "x": -14,
      "y": 14,
      "z": 13,
      "name": "Rock_Shale_Brick_Smooth_Half",
      "rotation": 6
    },
    {
      "x": -14,
      "y": 15,
      "z": 13,
      "name": "Rock_Shale_Brick_Smooth_Half",
      "rotation": 6
    },
    {
      "x": -14,
      "y": 30,
      "z": 13,
      "name": "Rock_Shale_Brick_Smooth_Half",
      "rotation": 4
    },
    {
      "x": -14,
      "y": 31,
      "z": 13,
      "name": "Rock_Runic_Teal_Brick_Stairs",
      "rotation": 9
    },
    {
      "x": -14,
      "y": 32,
      "z": 13,
      "name": "Rock_Shale_Brick_Smooth_Half",
      "rotation": 6
    },
    {
      "x": -14,
      "y": 33,
      "z": 13,
      "name": "Rock_Shale_Brick_Smooth_Half",
      "rotation": 6
    },
    {
      "x": -14,
      "y": 34,
      "z": 13,
      "name": "Rock_Shale_Brick_Smooth_Half",
      "rotation": 6
    },
    {
      "x": -14,
      "y": 12,
      "z": 14,
      "name": "Rock_Shale_Brick_Stairs",
      "rotation": 25
    },
    {
      "x": -14,
      "y": 13,
      "z": 14,
      "name": "Rock_Shale_Brick_Stairs",
      "rotation": 25
    },
    {
      "x": -14,
      "y": 14,
      "z": 14,
      "name": "Rock_Shale_Brick_Stairs",
      "rotation": 25
    },
    {
      "x": -14,
      "y": 15,
      "z": 14,
      "name": "Rock_Shale_Brick_Stairs",
      "rotation": 25
    },
    {
      "x": -14,
      "y": 16,
      "z": 14,
      "name": "Rock_Shale_Brick_Stairs",
      "rotation": 25
    },
    {
      "x": -14,
      "y": 17,
      "z": 14,
      "name": "Rock_Shale_Brick_Beam"
    },
    {
      "x": -14,
      "y": 31,
      "z": 14,
      "name": "Rock_Shale_Brick_Stairs",
      "rotation": 25
    },
    {
      "x": -14,
      "y": 32,
      "z": 14,
      "name": "Rock_Shale_Brick_Stairs",
      "rotation": 25
    },
    {
      "x": -14,
      "y": 33,
      "z": 14,
      "name": "Rock_Shale_Brick_Stairs",
      "rotation": 25
    },
    {
      "x": -14,
      "y": 34,
      "z": 14,
      "name": "Rock_Shale_Brick_Stairs",
      "rotation": 25
    },
    {
      "x": -14,
      "y": 35,
      "z": 14,
      "name": "Rock_Shale_Brick_Stairs",
      "rotation": 51
    },
    {
      "x": -14,
      "y": 36,
      "z": 14,
      "name": "Rock_Shale_Brick_Beam"
    },
    {
      "x": -13,
      "y": 12,
      "z": -15,
      "name": "Rock_Shale_Brick_Smooth_Half",
      "rotation": 6
    },
    {
      "x": -13,
      "y": 13,
      "z": -15,
      "name": "Rock_Shale_Brick_Smooth_Half",
      "rotation": 6
    },
    {
      "x": -13,
      "y": 14,
      "z": -15,
      "name": "Rock_Shale_Brick_Smooth_Half",
      "rotation": 6
    },
    {
      "x": -13,
      "y": 31,
      "z": -15,
      "name": "Rock_Shale_Brick_Smooth_Half",
      "rotation": 6
    },
    {
      "x": -13,
      "y": 32,
      "z": -15,
      "name": "Rock_Shale_Brick_Smooth_Half",
      "rotation": 6
    },
    {
      "x": -13,
      "y": 33,
      "z": -15,
      "name": "Rock_Shale_Brick_Smooth_Half",
      "rotation": 6
    },
    {
      "x": -13,
      "y": 11,
      "z": -14,
      "name": "Rock_Shale_Brick_Smooth_Half",
      "rotation": 7
    },
    {
      "x": -13,
      "y": 12,
      "z": -14,
      "name": "Rock_Runic_Teal_Brick_Stairs",
      "rotation": 8
    },
    {
      "x": -13,
      "y": 13,
      "z": -14,
      "name": "Rock_Shale_Brick_Smooth_Half",
      "rotation": 5
    },
    {
      "x": -13,
      "y": 14,
      "z": -14,
      "name": "Rock_Shale_Brick_Smooth_Half",
      "rotation": 5
    },
    {
      "x": -13,
      "y": 15,
      "z": -14,
      "name": "Rock_Shale_Brick_Smooth_Half",
      "rotation": 5
    },
    {
      "x": -13,
      "y": 30,
      "z": -14,
      "name": "Rock_Shale_Brick_Smooth_Half",
      "rotation": 7
    },
    {
      "x": -13,
      "y": 31,
      "z": -14,
      "name": "Rock_Runic_Teal_Brick_Stairs",
      "rotation": 8
    },
    {
      "x": -13,
      "y": 32,
      "z": -14,
      "name": "Rock_Shale_Brick_Smooth_Half",
      "rotation": 5
    },
    {
      "x": -13,
      "y": 33,
      "z": -14,
      "name": "Rock_Shale_Brick_Smooth_Half",
      "rotation": 5
    },
    {
      "x": -13,
      "y": 34,
      "z": -14,
      "name": "Rock_Shale_Brick_Smooth_Half",
      "rotation": 5
    },
    {
      "x": -13,
      "y": 12,
      "z": -13,
      "name": "Rock_Shale_Brick_Smooth"
    },
    {
      "x": -13,
      "y": 31,
      "z": -13,
      "name": "Rock_Shale_Brick_Smooth"
    },
    {
      "x": -13,
      "y": 8,
      "z": -12,
      "name": "Rock_Shale_Brick_Smooth_Half",
      "rotation": 6
    },
    {
      "x": -13,
      "y": 9,
      "z": -12,
      "name": "Rock_Shale_Brick_Smooth_Half",
      "rotation": 7
    },
    {
      "x": -13,
      "y": 10,
      "z": -12,
      "name": "Rock_Shale_Brick_Smooth_Half",
      "rotation": 7
    },
    {
      "x": -13,
      "y": 11,
      "z": -12,
      "name": "Rock_Shale_Brick_Smooth"
    },
    {
      "x": -13,
      "y": 27,
      "z": -12,
      "name": "Rock_Shale_Brick_Smooth_Half",
      "rotation": 6
    },
    {
      "x": -13,
      "y": 28,
      "z": -12,
      "name": "Rock_Shale_Brick_Smooth_Half",
      "rotation": 7
    },
    {
      "x": -13,
      "y": 29,
      "z": -12,
      "name": "Rock_Shale_Brick_Smooth_Half",
      "rotation": 7
    },
    {
      "x": -13,
      "y": 30,
      "z": -12,
      "name": "Rock_Shale_Brick_Smooth"
    },
    {
      "x": -13,
      "y": 40,
      "z": -12,
      "name": "Rock_Shale_Brick_Smooth"
    },
    {
      "x": -13,
      "y": 41,
      "z": -12,
      "name": "Rock_Shale_Brick_Smooth"
    },
    {
      "x": -13,
      "y": 42,
      "z": -12,
      "name": "Rock_Shale_Brick_Smooth"
    },
    {
      "x": -13,
      "y": 43,
      "z": -12,
      "name": "Rock_Shale_Brick_Smooth"
    },
    {
      "x": -13,
      "y": 44,
      "z": -12,
      "name": "Rock_Shale_Brick_Smooth"
    },
    {
      "x": -13,
      "y": 45,
      "z": -12,
      "name": "Rock_Shale_Brick_Smooth"
    },
    {
      "x": -13,
      "y": 46,
      "z": -12,
      "name": "Rock_Shale_Brick_Smooth"
    },
    {
      "x": -13,
      "y": 47,
      "z": -12,
      "name": "Rock_Shale_Brick_Smooth"
    },
    {
      "x": -13,
      "y": 48,
      "z": -12,
      "name": "*Rock_Shale_Brick_Roof_Steep_State_Definitions_Inverted_Corner_Right",
      "rotation": 3
    },
    {
      "x": -13,
      "y": 49,
      "z": -12,
      "name": "*Rock_Shale_Brick_Roof_Steep_State_Definitions_Inverted_Corner_Right",
      "filler": 1024,
      "rotation": 3
    },
    {
      "x": -13,
      "y": 0,
      "z": -11,
      "name": "Rock_Shale_Brick_Smooth"
    },
    {
      "x": -13,
      "y": 1,
      "z": -11,
      "name": "Rock_Shale_Brick_Smooth"
    },
    {
      "x": -13,
      "y": 2,
      "z": -11,
      "name": "Rock_Shale_Brick_Smooth"
    },
    {
      "x": -13,
      "y": 3,
      "z": -11,
      "name": "Rock_Shale_Brick_Smooth"
    },
    {
      "x": -13,
      "y": 4,
      "z": -11,
      "name": "Rock_Shale_Brick_Smooth"
    },
    {
      "x": -13,
      "y": 5,
      "z": -11,
      "name": "Rock_Shale_Brick_Smooth"
    },
    {
      "x": -13,
      "y": 6,
      "z": -11,
      "name": "Rock_Shale_Brick_Smooth"
    },
    {
      "x": -13,
      "y": 8,
      "z": -11,
      "name": "Rock_Runic_Teal_Brick_Stairs",
      "rotation": 9
    },
    {
      "x": -13,
      "y": 9,
      "z": -11,
      "name": "Rock_Shale_Brick_Smooth_Half",
      "rotation": 4
    },
    {
      "x": -13,
      "y": 10,
      "z": -11,
      "name": "Rock_Shale_Brick_Smooth_Half",
      "rotation": 5
    },
    {
      "x": -13,
      "y": 11,
      "z": -11,
      "name": "Rock_Shale_Brick_Smooth_Half",
      "rotation": 7
    },
    {
      "x": -13,
      "y": 12,
      "z": -11,
      "name": "Rock_Shale_Brick_Smooth_Half",
      "rotation": 7
    },
    {
      "x": -13,
      "y": 13,
      "z": -11,
      "name": "Rock_Shale_Brick_Smooth_Half",
      "rotation": 7
    },
    {
      "x": -13,
      "y": 14,
      "z": -11,
      "name": "Rock_Shale_Brick_Smooth_Half",
      "rotation": 7
    },
    {
      "x": -13,
      "y": 26,
      "z": -11,
      "name": "Rock_Shale_Brick_Smooth_Half",
      "rotation": 7
    },
    {
      "x": -13,
      "y": 27,
      "z": -11,
      "name": "Rock_Runic_Teal_Brick_Stairs",
      "rotation": 9
    },
    {
      "x": -13,
      "y": 28,
      "z": -11,
      "name": "Rock_Shale_Brick_Smooth_Half",
      "rotation": 4
    },
    {
      "x": -13,
      "y": 29,
      "z": -11,
      "name": "Rock_Shale_Brick_Smooth_Half",
      "rotation": 5
    },
    {
      "x": -13,
      "y": 30,
      "z": -11,
      "name": "Rock_Shale_Brick_Smooth_Half",
      "rotation": 7
    },
    {
      "x": -13,
      "y": 31,
      "z": -11,
      "name": "Rock_Shale_Brick_Smooth_Half",
      "rotation": 7
    },
    {
      "x": -13,
      "y": 32,
      "z": -11,
      "name": "Rock_Shale_Brick_Smooth_Half",
      "rotation": 7
    },
    {
      "x": -13,
      "y": 33,
      "z": -11,
      "name": "Rock_Shale_Brick_Smooth_Half",
      "rotation": 7
    },
    {
      "x": -13,
      "y": 40,
      "z": -11,
      "name": "Rock_Shale_Brick_Smooth"
    },
    {
      "x": -13,
      "y": 41,
      "z": -11,
      "name": "Rock_Shale_Brick_Half",
      "rotation": 7
    },
    {
      "x": -13,
      "y": 42,
      "z": -11,
      "name": "Rock_Shale_Brick_Smooth_Half",
      "rotation": 2
    },
    {
      "x": -13,
      "y": 45,
      "z": -11,
      "name": "Rock_Shale_Brick_Ornate",
      "rotation": 2
    },
    {
      "x": -13,
      "y": 46,
      "z": -11,
      "name": "Rock_Shale_Brick_Half",
      "rotation": 7
    },
    {
      "x": -13,
      "y": 47,
      "z": -11,
      "name": "Rock_Shale_Brick_Stairs",
      "rotation": 35
    },
    {
      "x": -13,
      "y": 49,
      "z": -11,
      "name": "Rock_Shale_Brick_Stairs",
      "rotation": 33
    },
    {
      "x": -13,
      "y": 50,
      "z": -11,
      "name": "*Rock_Shale_Brick_Roof_Steep_State_Definitions_Corner_Left",
      "rotation": 2
    },
    {
      "x": -13,
      "y": 51,
      "z": -11,
      "name": "*Rock_Shale_Brick_Roof_Steep_State_Definitions_Corner_Left",
      "filler": 1024,
      "rotation": 2
    },
    {
      "x": -13,
      "y": 0,
      "z": -10,
      "name": "Rock_Shale_Brick_Smooth"
    },
    {
      "x": -13,
      "y": 1,
      "z": -10,
      "name": "Rock_Shale_Brick_Smooth"
    },
    {
      "x": -13,
      "y": 2,
      "z": -10,
      "name": "Rock_Shale_Brick_Smooth"
    },
    {
      "x": -13,
      "y": 3,
      "z": -10,
      "name": "Rock_Shale_Brick_Smooth"
    },
    {
      "x": -13,
      "y": 4,
      "z": -10,
      "name": "Rock_Shale_Brick_Smooth"
    },
    {
      "x": -13,
      "y": 5,
      "z": -10,
      "name": "Rock_Shale_Brick_Smooth_Half",
      "rotation": 7
    },
    {
      "x": -13,
      "y": 6,
      "z": -10,
      "name": "Rock_Shale_Brick_Smooth_Half",
      "rotation": 7
    },
    {
      "x": -13,
      "y": 7,
      "z": -10,
      "name": "Rock_Shale_Brick_Smooth_Half",
      "rotation": 7
    },
    {
      "x": -13,
      "y": 8,
      "z": -10,
      "name": "Rock_Runic_Teal_Brick_Stairs",
      "rotation": 9
    },
    {
      "x": -13,
      "y": 10,
      "z": -10,
      "name": "Rock_Shale_Brick_Smooth_Half",
      "rotation": 7
    },
    {
      "x": -13,
      "y": 11,
      "z": -10,
      "name": "Rock_Shale_Brick_Smooth_Half",
      "rotation": 7
    },
    {
      "x": -13,
      "y": 24,
      "z": -10,
      "name": "Rock_Shale_Brick_Smooth_Half",
      "rotation": 7
    },
    {
      "x": -13,
      "y": 25,
      "z": -10,
      "name": "Rock_Shale_Brick_Smooth_Half",
      "rotation": 7
    },
    {
      "x": -13,
      "y": 26,
      "z": -10,
      "name": "Rock_Shale_Brick_Smooth_Half",
      "rotation": 7
    },
    {
      "x": -13,
      "y": 27,
      "z": -10,
      "name": "Rock_Runic_Teal_Brick_Stairs",
      "rotation": 9
    },
    {
      "x": -13,
      "y": 29,
      "z": -10,
      "name": "Rock_Shale_Brick_Smooth_Half",
      "rotation": 7
    },
    {
      "x": -13,
      "y": 30,
      "z": -10,
      "name": "Rock_Shale_Brick_Smooth_Half",
      "rotation": 7
    },
    {
      "x": -13,
      "y": 39,
      "z": -10,
      "name": "Rock_Shale_Brick_Stairs",
      "rotation": 9
    },
    {
      "x": -13,
      "y": 40,
      "z": -10,
      "name": "Rock_Shale_Brick_Smooth"
    },
    {
      "x": -13,
      "y": 41,
      "z": -10,
      "name": "Rock_Shale_Brick_Half",
      "rotation": 7
    },
    {
      "x": -13,
      "y": 42,
      "z": -10,
      "name": "Rock_Shale_Brick_Smooth_Half",
      "rotation": 2
    },
    {
      "x": -13,
      "y": 45,
      "z": -10,
      "name": "Rock_Shale_Brick_Ornate",
      "rotation": 2
    },
    {
      "x": -13,
      "y": 46,
      "z": -10,
      "name": "Rock_Shale_Brick_Half",
      "rotation": 7
    },
    {
      "x": -13,
      "y": 47,
      "z": -10,
      "name": "Rock_Shale_Brick_Stairs",
      "rotation": 35
    },
    {
      "x": -13,
      "y": 49,
      "z": -10,
      "name": "Rock_Shale_Brick_Stairs",
      "rotation": 33
    },
    {
      "x": -13,
      "y": 50,
      "z": -10,
      "name": "Rock_Shale_Brick_Roof_Steep",
      "rotation": 3
    },
    {
      "x": -13,
      "y": 51,
      "z": -10,
      "name": "Rock_Shale_Brick_Roof_Steep",
      "filler": 1024,
      "rotation": 3
    },
    {
      "x": -13,
      "y": 0,
      "z": -9,
      "name": "Rock_Shale_Brick_Smooth"
    },
    {
      "x": -13,
      "y": 1,
      "z": -9,
      "name": "Rock_Shale_Brick_Smooth"
    },
    {
      "x": -13,
      "y": 2,
      "z": -9,
      "name": "Rock_Shale_Brick_Smooth_Half",
      "rotation": 7
    },
    {
      "x": -13,
      "y": 3,
      "z": -9,
      "name": "Rock_Shale_Brick_Smooth_Half",
      "rotation": 7
    },
    {
      "x": -13,
      "y": 4,
      "z": -9,
      "name": "Rock_Shale_Brick_Smooth_Half",
      "rotation": 7
    },
    {
      "x": -13,
      "y": 5,
      "z": -9,
      "name": "Rock_Shale_Brick_Smooth_Half",
      "rotation": 7
    },
    {
      "x": -13,
      "y": 6,
      "z": -9,
      "name": "Rock_Shale_Brick_Smooth_Half",
      "rotation": 7
    },
    {
      "x": -13,
      "y": 7,
      "z": -9,
      "name": "Rock_Shale_Brick_Smooth_Half",
      "rotation": 7
    },
    {
      "x": -13,
      "y": 8,
      "z": -9,
      "name": "Rock_Runic_Teal_Brick_Stairs",
      "rotation": 9
    },
    {
      "x": -13,
      "y": 21,
      "z": -9,
      "name": "Rock_Shale_Brick_Smooth_Half",
      "rotation": 7
    },
    {
      "x": -13,
      "y": 22,
      "z": -9,
      "name": "Rock_Shale_Brick_Smooth_Half",
      "rotation": 7
    },
    {
      "x": -13,
      "y": 23,
      "z": -9,
      "name": "Rock_Shale_Brick_Smooth_Half",
      "rotation": 7
    },
    {
      "x": -13,
      "y": 24,
      "z": -9,
      "name": "Rock_Shale_Brick_Smooth_Half",
      "rotation": 7
    },
    {
      "x": -13,
      "y": 25,
      "z": -9,
      "name": "Rock_Shale_Brick_Smooth_Half",
      "rotation": 7
    },
    {
      "x": -13,
      "y": 26,
      "z": -9,
      "name": "Rock_Shale_Brick_Smooth_Half",
      "rotation": 7
    },
    {
      "x": -13,
      "y": 27,
      "z": -9,
      "name": "Rock_Runic_Teal_Brick_Stairs",
      "rotation": 9
    },
    {
      "x": -13,
      "y": 40,
      "z": -9,
      "name": "Rock_Shale_Brick_Smooth"
    },
    {
      "x": -13,
      "y": 41,
      "z": -9,
      "name": "Rock_Shale_Brick_Half",
      "rotation": 7
    },
    {
      "x": -13,
      "y": 42,
      "z": -9,
      "name": "Rock_Shale_Brick_Smooth_Half",
      "rotation": 2
    },
    {
      "x": -13,
      "y": 45,
      "z": -9,
      "name": "Rock_Shale_Brick_Ornate",
      "rotation": 2
    },
    {
      "x": -13,
      "y": 46,
      "z": -9,
      "name": "Rock_Shale_Brick_Half",
      "rotation": 7
    },
    {
      "x": -13,
      "y": 47,
      "z": -9,
      "name": "Rock_Shale_Brick_Stairs",
      "rotation": 35
    },
    {
      "x": -13,
      "y": 49,
      "z": -9,
      "name": "Rock_Shale_Brick_Stairs",
      "rotation": 33
    },
    {
      "x": -13,
      "y": 50,
      "z": -9,
      "name": "*Rock_Shale_Brick_Roof_Steep_State_Definitions_Corner_Left",
      "rotation": 3
    },
    {
      "x": -13,
      "y": 51,
      "z": -9,
      "name": "*Rock_Shale_Brick_Roof_Steep_State_Definitions_Corner_Left",
      "filler": 1024,
      "rotation": 3
    },
    {
      "x": -13,
      "y": 7,
      "z": -8,
      "name": "Rock_Runic_Teal_Brick_Stairs",
      "rotation": 10
    },
    {
      "x": -13,
      "y": 8,
      "z": -8,
      "name": "Rock_Shale_Brick_Smooth_Half",
      "rotation": 6
    },
    {
      "x": -13,
      "y": 9,
      "z": -8,
      "name": "Rock_Shale_Brick_Smooth_Half",
      "rotation": 6
    },
    {
      "x": -13,
      "y": 10,
      "z": -8,
      "name": "Rock_Shale_Brick_Smooth_Half",
      "rotation": 6
    },
    {
      "x": -13,
      "y": 26,
      "z": -8,
      "name": "Rock_Runic_Teal_Brick_Stairs",
      "rotation": 10
    },
    {
      "x": -13,
      "y": 27,
      "z": -8,
      "name": "Rock_Shale_Brick_Smooth_Half",
      "rotation": 6
    },
    {
      "x": -13,
      "y": 28,
      "z": -8,
      "name": "Rock_Shale_Brick_Smooth_Half",
      "rotation": 6
    },
    {
      "x": -13,
      "y": 29,
      "z": -8,
      "name": "Rock_Shale_Brick_Smooth_Half",
      "rotation": 6
    },
    {
      "x": -13,
      "y": 40,
      "z": -8,
      "name": "Rock_Shale_Brick_Smooth"
    },
    {
      "x": -13,
      "y": 41,
      "z": -8,
      "name": "Rock_Shale_Brick_Smooth"
    },
    {
      "x": -13,
      "y": 42,
      "z": -8,
      "name": "Rock_Shale_Brick_Smooth"
    },
    {
      "x": -13,
      "y": 43,
      "z": -8,
      "name": "Rock_Shale_Brick_Smooth"
    },
    {
      "x": -13,
      "y": 44,
      "z": -8,
      "name": "Rock_Shale_Brick_Smooth"
    },
    {
      "x": -13,
      "y": 45,
      "z": -8,
      "name": "Rock_Shale_Brick_Smooth"
    },
    {
      "x": -13,
      "y": 46,
      "z": -8,
      "name": "Rock_Shale_Brick_Smooth"
    },
    {
      "x": -13,
      "y": 47,
      "z": -8,
      "name": "Rock_Shale_Brick_Smooth"
    },
    {
      "x": -13,
      "y": 48,
      "z": -8,
      "name": "*Rock_Shale_Brick_Roof_Steep_State_Definitions_Inverted_Corner_Left",
      "rotation": 3
    },
    {
      "x": -13,
      "y": 49,
      "z": -8,
      "name": "*Rock_Shale_Brick_Roof_Steep_State_Definitions_Inverted_Corner_Left",
      "filler": 1024,
      "rotation": 3
    },
    {
      "x": -13,
      "y": 7,
      "z": -7,
      "name": "Rock_Shale_Brick_Smooth_Half",
      "rotation": 7
    },
    {
      "x": -13,
      "y": 8,
      "z": -7,
      "name": "Rock_Shale_Brick_Smooth_Half",
      "rotation": 7
    },
    {
      "x": -13,
      "y": 9,
      "z": -7,
      "name": "Rock_Shale_Brick_Smooth_Half",
      "rotation": 7
    },
    {
      "x": -13,
      "y": 26,
      "z": -7,
      "name": "Rock_Shale_Brick_Smooth_Half",
      "rotation": 7
    },
    {
      "x": -13,
      "y": 27,
      "z": -7,
      "name": "Rock_Shale_Brick_Smooth_Half",
      "rotation": 7
    },
    {
      "x": -13,
      "y": 28,
      "z": -7,
      "name": "Rock_Shale_Brick_Smooth_Half",
      "rotation": 7
    },
    {
      "x": -13,
      "y": 7,
      "z": 7,
      "name": "Rock_Shale_Brick_Smooth_Half",
      "rotation": 7
    },
    {
      "x": -13,
      "y": 8,
      "z": 7,
      "name": "Rock_Shale_Brick_Smooth_Half",
      "rotation": 7
    },
    {
      "x": -13,
      "y": 9,
      "z": 7,
      "name": "Rock_Shale_Brick_Smooth_Half",
      "rotation": 7
    },
    {
      "x": -13,
      "y": 26,
      "z": 7,
      "name": "Rock_Shale_Brick_Smooth_Half",
      "rotation": 7
    },
    {
      "x": -13,
      "y": 27,
      "z": 7,
      "name": "Rock_Shale_Brick_Smooth_Half",
      "rotation": 7
    },
    {
      "x": -13,
      "y": 28,
      "z": 7,
      "name": "Rock_Shale_Brick_Smooth_Half",
      "rotation": 7
    },
    {
      "x": -13,
      "y": 7,
      "z": 8,
      "name": "Rock_Runic_Teal_Brick_Stairs",
      "rotation": 8
    },
    {
      "x": -13,
      "y": 8,
      "z": 8,
      "name": "Rock_Shale_Brick_Smooth_Half",
      "rotation": 4
    },
    {
      "x": -13,
      "y": 9,
      "z": 8,
      "name": "Rock_Shale_Brick_Smooth_Half",
      "rotation": 4
    },
    {
      "x": -13,
      "y": 10,
      "z": 8,
      "name": "Rock_Shale_Brick_Smooth_Half",
      "rotation": 4
    },
    {
      "x": -13,
      "y": 26,
      "z": 8,
      "name": "Rock_Runic_Teal_Brick_Stairs",
      "rotation": 8
    },
    {
      "x": -13,
      "y": 27,
      "z": 8,
      "name": "Rock_Shale_Brick_Smooth_Half",
      "rotation": 4
    },
    {
      "x": -13,
      "y": 28,
      "z": 8,
      "name": "Rock_Shale_Brick_Smooth_Half",
      "rotation": 4
    },
    {
      "x": -13,
      "y": 29,
      "z": 8,
      "name": "Rock_Shale_Brick_Smooth_Half",
      "rotation": 4
    },
    {
      "x": -13,
      "y": 40,
      "z": 8,
      "name": "Rock_Shale_Brick_Smooth"
    },
    {
      "x": -13,
      "y": 41,
      "z": 8,
      "name": "Rock_Shale_Brick_Smooth"
    },
    {
      "x": -13,
      "y": 42,
      "z": 8,
      "name": "Rock_Shale_Brick_Smooth"
    },
    {
      "x": -13,
      "y": 43,
      "z": 8,
      "name": "Rock_Shale_Brick_Smooth"
    },
    {
      "x": -13,
      "y": 44,
      "z": 8,
      "name": "Rock_Shale_Brick_Smooth"
    },
    {
      "x": -13,
      "y": 45,
      "z": 8,
      "name": "Rock_Shale_Brick_Smooth"
    },
    {
      "x": -13,
      "y": 46,
      "z": 8,
      "name": "Rock_Shale_Brick_Smooth"
    },
    {
      "x": -13,
      "y": 47,
      "z": 8,
      "name": "Rock_Shale_Brick_Smooth"
    },
    {
      "x": -13,
      "y": 48,
      "z": 8,
      "name": "*Rock_Shale_Brick_Roof_Steep_State_Definitions_Inverted_Corner_Right",
      "rotation": 3
    },
    {
      "x": -13,
      "y": 49,
      "z": 8,
      "name": "*Rock_Shale_Brick_Roof_Steep_State_Definitions_Inverted_Corner_Right",
      "filler": 1024,
      "rotation": 3
    },
    {
      "x": -13,
      "y": 2,
      "z": 9,
      "name": "Rock_Shale_Brick_Smooth_Half",
      "rotation": 7
    },
    {
      "x": -13,
      "y": 3,
      "z": 9,
      "name": "Rock_Shale_Brick_Smooth_Half",
      "rotation": 7
    },
    {
      "x": -13,
      "y": 4,
      "z": 9,
      "name": "Rock_Shale_Brick_Smooth_Half",
      "rotation": 7
    },
    {
      "x": -13,
      "y": 5,
      "z": 9,
      "name": "Rock_Shale_Brick_Smooth_Half",
      "rotation": 7
    },
    {
      "x": -13,
      "y": 6,
      "z": 9,
      "name": "Rock_Shale_Brick_Smooth_Half",
      "rotation": 7
    },
    {
      "x": -13,
      "y": 7,
      "z": 9,
      "name": "Rock_Shale_Brick_Smooth_Half",
      "rotation": 7
    },
    {
      "x": -13,
      "y": 8,
      "z": 9,
      "name": "Rock_Runic_Teal_Brick_Stairs",
      "rotation": 9
    },
    {
      "x": -13,
      "y": 21,
      "z": 9,
      "name": "Rock_Shale_Brick_Smooth_Half",
      "rotation": 7
    },
    {
      "x": -13,
      "y": 22,
      "z": 9,
      "name": "Rock_Shale_Brick_Smooth_Half",
      "rotation": 7
    },
    {
      "x": -13,
      "y": 23,
      "z": 9,
      "name": "Rock_Shale_Brick_Smooth_Half",
      "rotation": 7
    },
    {
      "x": -13,
      "y": 24,
      "z": 9,
      "name": "Rock_Shale_Brick_Smooth_Half",
      "rotation": 7
    },
    {
      "x": -13,
      "y": 25,
      "z": 9,
      "name": "Rock_Shale_Brick_Smooth_Half",
      "rotation": 7
    },
    {
      "x": -13,
      "y": 26,
      "z": 9,
      "name": "Rock_Shale_Brick_Smooth_Half",
      "rotation": 7
    },
    {
      "x": -13,
      "y": 27,
      "z": 9,
      "name": "Rock_Runic_Teal_Brick_Stairs",
      "rotation": 9
    },
    {
      "x": -13,
      "y": 40,
      "z": 9,
      "name": "Rock_Shale_Brick_Smooth"
    },
    {
      "x": -13,
      "y": 41,
      "z": 9,
      "name": "Rock_Shale_Brick_Half",
      "rotation": 7
    },
    {
      "x": -13,
      "y": 42,
      "z": 9,
      "name": "Rock_Shale_Brick_Smooth_Half",
      "rotation": 3
    },
    {
      "x": -13,
      "y": 45,
      "z": 9,
      "name": "Rock_Shale_Brick_Ornate",
      "rotation": 3
    },
    {
      "x": -13,
      "y": 46,
      "z": 9,
      "name": "Rock_Shale_Brick_Half",
      "rotation": 7
    },
    {
      "x": -13,
      "y": 47,
      "z": 9,
      "name": "Rock_Shale_Brick_Stairs",
      "rotation": 35
    },
    {
      "x": -13,
      "y": 49,
      "z": 9,
      "name": "Rock_Shale_Brick_Stairs",
      "rotation": 33
    },
    {
      "x": -13,
      "y": 50,
      "z": 9,
      "name": "*Rock_Shale_Brick_Roof_Steep_State_Definitions_Corner_Left",
      "rotation": 2
    },
    {
      "x": -13,
      "y": 51,
      "z": 9,
      "name": "*Rock_Shale_Brick_Roof_Steep_State_Definitions_Corner_Left",
      "filler": 1024,
      "rotation": 2
    },
    {
      "x": -13,
      "y": 5,
      "z": 10,
      "name": "Rock_Shale_Brick_Smooth_Half",
      "rotation": 7
    },
    {
      "x": -13,
      "y": 6,
      "z": 10,
      "name": "Rock_Shale_Brick_Smooth_Half",
      "rotation": 7
    },
    {
      "x": -13,
      "y": 7,
      "z": 10,
      "name": "Rock_Shale_Brick_Smooth_Half",
      "rotation": 7
    },
    {
      "x": -13,
      "y": 8,
      "z": 10,
      "name": "Rock_Runic_Teal_Brick_Stairs",
      "rotation": 9
    },
    {
      "x": -13,
      "y": 11,
      "z": 10,
      "name": "Rock_Shale_Brick_Smooth_Half",
      "rotation": 7
    },
    {
      "x": -13,
      "y": 24,
      "z": 10,
      "name": "Rock_Shale_Brick_Smooth_Half",
      "rotation": 7
    },
    {
      "x": -13,
      "y": 25,
      "z": 10,
      "name": "Rock_Shale_Brick_Smooth_Half",
      "rotation": 7
    },
    {
      "x": -13,
      "y": 26,
      "z": 10,
      "name": "Rock_Shale_Brick_Smooth_Half",
      "rotation": 7
    },
    {
      "x": -13,
      "y": 27,
      "z": 10,
      "name": "Rock_Runic_Teal_Brick_Stairs",
      "rotation": 9
    },
    {
      "x": -13,
      "y": 30,
      "z": 10,
      "name": "Rock_Shale_Brick_Smooth_Half",
      "rotation": 7
    },
    {
      "x": -13,
      "y": 39,
      "z": 10,
      "name": "Rock_Shale_Brick_Stairs",
      "rotation": 35
    },
    {
      "x": -13,
      "y": 40,
      "z": 10,
      "name": "Rock_Shale_Brick_Smooth"
    },
    {
      "x": -13,
      "y": 41,
      "z": 10,
      "name": "Rock_Shale_Brick_Half",
      "rotation": 7
    },
    {
      "x": -13,
      "y": 42,
      "z": 10,
      "name": "Rock_Shale_Brick_Smooth_Half",
      "rotation": 3
    },
    {
      "x": -13,
      "y": 45,
      "z": 10,
      "name": "Rock_Shale_Brick_Ornate",
      "rotation": 3
    },
    {
      "x": -13,
      "y": 46,
      "z": 10,
      "name": "Rock_Shale_Brick_Half",
      "rotation": 7
    },
    {
      "x": -13,
      "y": 47,
      "z": 10,
      "name": "Rock_Shale_Brick_Stairs",
      "rotation": 35
    },
    {
      "x": -13,
      "y": 49,
      "z": 10,
      "name": "Rock_Shale_Brick_Stairs",
      "rotation": 33
    },
    {
      "x": -13,
      "y": 50,
      "z": 10,
      "name": "Rock_Shale_Brick_Roof_Steep",
      "rotation": 3
    },
    {
      "x": -13,
      "y": 51,
      "z": 10,
      "name": "Rock_Shale_Brick_Roof_Steep",
      "filler": 1024,
      "rotation": 3
    },
    {
      "x": -13,
      "y": 7,
      "z": 11,
      "name": "Rock_Shale_Brick_Smooth_Half",
      "rotation": 7
    },
    {
      "x": -13,
      "y": 8,
      "z": 11,
      "name": "Rock_Runic_Teal_Brick_Stairs",
      "rotation": 9
    },
    {
      "x": -13,
      "y": 9,
      "z": 11,
      "name": "Rock_Shale_Brick_Smooth_Half",
      "rotation": 6
    },
    {
      "x": -13,
      "y": 10,
      "z": 11,
      "name": "Rock_Shale_Brick_Smooth_Half",
      "rotation": 5
    },
    {
      "x": -13,
      "y": 11,
      "z": 11,
      "name": "Rock_Shale_Brick_Smooth_Half",
      "rotation": 7
    },
    {
      "x": -13,
      "y": 12,
      "z": 11,
      "name": "Rock_Shale_Brick_Smooth_Half",
      "rotation": 7
    },
    {
      "x": -13,
      "y": 13,
      "z": 11,
      "name": "Rock_Shale_Brick_Smooth_Half",
      "rotation": 7
    },
    {
      "x": -13,
      "y": 14,
      "z": 11,
      "name": "Rock_Shale_Brick_Smooth_Half",
      "rotation": 7
    },
    {
      "x": -13,
      "y": 26,
      "z": 11,
      "name": "Rock_Shale_Brick_Smooth_Half",
      "rotation": 7
    },
    {
      "x": -13,
      "y": 27,
      "z": 11,
      "name": "Rock_Runic_Teal_Brick_Stairs",
      "rotation": 9
    },
    {
      "x": -13,
      "y": 28,
      "z": 11,
      "name": "Rock_Shale_Brick_Smooth_Half",
      "rotation": 6
    },
    {
      "x": -13,
      "y": 29,
      "z": 11,
      "name": "Rock_Shale_Brick_Smooth_Half",
      "rotation": 5
    },
    {
      "x": -13,
      "y": 30,
      "z": 11,
      "name": "Rock_Shale_Brick_Smooth_Half",
      "rotation": 7
    },
    {
      "x": -13,
      "y": 31,
      "z": 11,
      "name": "Rock_Shale_Brick_Smooth_Half",
      "rotation": 7
    },
    {
      "x": -13,
      "y": 32,
      "z": 11,
      "name": "Rock_Shale_Brick_Smooth_Half",
      "rotation": 7
    },
    {
      "x": -13,
      "y": 33,
      "z": 11,
      "name": "Rock_Shale_Brick_Smooth_Half",
      "rotation": 7
    },
    {
      "x": -13,
      "y": 40,
      "z": 11,
      "name": "Rock_Shale_Brick_Smooth"
    },
    {
      "x": -13,
      "y": 41,
      "z": 11,
      "name": "Rock_Shale_Brick_Half",
      "rotation": 7
    },
    {
      "x": -13,
      "y": 42,
      "z": 11,
      "name": "Rock_Shale_Brick_Smooth_Half",
      "rotation": 3
    },
    {
      "x": -13,
      "y": 45,
      "z": 11,
      "name": "Rock_Shale_Brick_Ornate",
      "rotation": 3
    },
    {
      "x": -13,
      "y": 46,
      "z": 11,
      "name": "Rock_Shale_Brick_Half",
      "rotation": 7
    },
    {
      "x": -13,
      "y": 47,
      "z": 11,
      "name": "Rock_Shale_Brick_Stairs",
      "rotation": 35
    },
    {
      "x": -13,
      "y": 49,
      "z": 11,
      "name": "Rock_Shale_Brick_Stairs",
      "rotation": 33
    },
    {
      "x": -13,
      "y": 50,
      "z": 11,
      "name": "*Rock_Shale_Brick_Roof_Steep_State_Definitions_Corner_Left",
      "rotation": 3
    },
    {
      "x": -13,
      "y": 51,
      "z": 11,
      "name": "*Rock_Shale_Brick_Roof_Steep_State_Definitions_Corner_Left",
      "filler": 1024,
      "rotation": 3
    },
    {
      "x": -13,
      "y": 8,
      "z": 12,
      "name": "Rock_Shale_Brick_Smooth_Half",
      "rotation": 4
    },
    {
      "x": -13,
      "y": 9,
      "z": 12,
      "name": "Rock_Shale_Brick_Smooth_Half",
      "rotation": 7
    },
    {
      "x": -13,
      "y": 10,
      "z": 12,
      "name": "Rock_Shale_Brick_Smooth_Half",
      "rotation": 7
    },
    {
      "x": -13,
      "y": 11,
      "z": 12,
      "name": "Rock_Shale_Brick_Smooth"
    },
    {
      "x": -13,
      "y": 27,
      "z": 12,
      "name": "Rock_Shale_Brick_Smooth_Half",
      "rotation": 4
    },
    {
      "x": -13,
      "y": 28,
      "z": 12,
      "name": "Rock_Shale_Brick_Smooth_Half",
      "rotation": 7
    },
    {
      "x": -13,
      "y": 29,
      "z": 12,
      "name": "Rock_Shale_Brick_Smooth_Half",
      "rotation": 7
    },
    {
      "x": -13,
      "y": 30,
      "z": 12,
      "name": "Rock_Shale_Brick_Smooth"
    },
    {
      "x": -13,
      "y": 40,
      "z": 12,
      "name": "Rock_Shale_Brick_Smooth"
    },
    {
      "x": -13,
      "y": 41,
      "z": 12,
      "name": "Rock_Shale_Brick_Smooth"
    },
    {
      "x": -13,
      "y": 42,
      "z": 12,
      "name": "Rock_Shale_Brick_Smooth"
    },
    {
      "x": -13,
      "y": 43,
      "z": 12,
      "name": "Rock_Shale_Brick_Smooth"
    },
    {
      "x": -13,
      "y": 44,
      "z": 12,
      "name": "Rock_Shale_Brick_Smooth"
    },
    {
      "x": -13,
      "y": 45,
      "z": 12,
      "name": "Rock_Shale_Brick_Smooth"
    },
    {
      "x": -13,
      "y": 46,
      "z": 12,
      "name": "Rock_Shale_Brick_Smooth"
    },
    {
      "x": -13,
      "y": 47,
      "z": 12,
      "name": "Rock_Shale_Brick_Smooth"
    },
    {
      "x": -13,
      "y": 48,
      "z": 12,
      "name": "*Rock_Shale_Brick_Roof_Steep_State_Definitions_Inverted_Corner_Left",
      "rotation": 3
    },
    {
      "x": -13,
      "y": 49,
      "z": 12,
      "name": "*Rock_Shale_Brick_Roof_Steep_State_Definitions_Inverted_Corner_Left",
      "filler": 1024,
      "rotation": 3
    },
    {
      "x": -13,
      "y": 12,
      "z": 13,
      "name": "Rock_Shale_Brick_Smooth"
    },
    {
      "x": -13,
      "y": 31,
      "z": 13,
      "name": "Rock_Shale_Brick_Smooth"
    },
    {
      "x": -13,
      "y": 11,
      "z": 14,
      "name": "Rock_Shale_Brick_Smooth_Half",
      "rotation": 7
    },
    {
      "x": -13,
      "y": 12,
      "z": 14,
      "name": "Rock_Runic_Teal_Brick_Stairs",
      "rotation": 10
    },
    {
      "x": -13,
      "y": 13,
      "z": 14,
      "name": "Rock_Shale_Brick_Smooth_Half",
      "rotation": 5
    },
    {
      "x": -13,
      "y": 14,
      "z": 14,
      "name": "Rock_Shale_Brick_Smooth_Half",
      "rotation": 5
    },
    {
      "x": -13,
      "y": 15,
      "z": 14,
      "name": "Rock_Shale_Brick_Smooth_Half",
      "rotation": 5
    },
    {
      "x": -13,
      "y": 30,
      "z": 14,
      "name": "Rock_Shale_Brick_Smooth_Half",
      "rotation": 7
    },
    {
      "x": -13,
      "y": 31,
      "z": 14,
      "name": "Rock_Runic_Teal_Brick_Stairs",
      "rotation": 10
    },
    {
      "x": -13,
      "y": 32,
      "z": 14,
      "name": "Rock_Shale_Brick_Smooth_Half",
      "rotation": 5
    },
    {
      "x": -13,
      "y": 33,
      "z": 14,
      "name": "Rock_Shale_Brick_Smooth_Half",
      "rotation": 5
    },
    {
      "x": -13,
      "y": 34,
      "z": 14,
      "name": "Rock_Shale_Brick_Smooth_Half",
      "rotation": 5
    },
    {
      "x": -13,
      "y": 12,
      "z": 15,
      "name": "Rock_Shale_Brick_Smooth_Half",
      "rotation": 4
    },
    {
      "x": -13,
      "y": 13,
      "z": 15,
      "name": "Rock_Shale_Brick_Smooth_Half",
      "rotation": 4
    },
    {
      "x": -13,
      "y": 14,
      "z": 15,
      "name": "Rock_Shale_Brick_Smooth_Half",
      "rotation": 4
    },
    {
      "x": -13,
      "y": 31,
      "z": 15,
      "name": "Rock_Shale_Brick_Smooth_Half",
      "rotation": 4
    },
    {
      "x": -13,
      "y": 32,
      "z": 15,
      "name": "Rock_Shale_Brick_Smooth_Half",
      "rotation": 4
    },
    {
      "x": -13,
      "y": 33,
      "z": 15,
      "name": "Rock_Shale_Brick_Smooth_Half",
      "rotation": 4
    },
    {
      "x": -12,
      "y": 11,
      "z": -15,
      "name": "Rock_Shale_Brick_Smooth_Half",
      "rotation": 6
    },
    {
      "x": -12,
      "y": 12,
      "z": -15,
      "name": "Rock_Shale_Brick_Smooth_Half",
      "rotation": 6
    },
    {
      "x": -12,
      "y": 13,
      "z": -15,
      "name": "Rock_Shale_Brick_Smooth_Half",
      "rotation": 6
    },
    {
      "x": -12,
      "y": 30,
      "z": -15,
      "name": "Rock_Shale_Brick_Smooth_Half",
      "rotation": 6
    },
    {
      "x": -12,
      "y": 31,
      "z": -15,
      "name": "Rock_Shale_Brick_Smooth_Half",
      "rotation": 6
    },
    {
      "x": -12,
      "y": 32,
      "z": -15,
      "name": "Rock_Shale_Brick_Smooth_Half",
      "rotation": 6
    },
    {
      "x": -12,
      "y": 10,
      "z": -14,
      "name": "Rock_Shale_Brick_Smooth_Half",
      "rotation": 7
    },
    {
      "x": -12,
      "y": 11,
      "z": -14,
      "name": "Rock_Runic_Teal_Brick_Stairs",
      "rotation": 8
    },
    {
      "x": -12,
      "y": 12,
      "z": -14,
      "name": "Rock_Shale_Brick_Smooth_Half",
      "rotation": 5
    },
    {
      "x": -12,
      "y": 29,
      "z": -14,
      "name": "Rock_Shale_Brick_Smooth_Half",
      "rotation": 7
    },
    {
      "x": -12,
      "y": 30,
      "z": -14,
      "name": "Rock_Runic_Teal_Brick_Stairs",
      "rotation": 8
    },
    {
      "x": -12,
      "y": 31,
      "z": -14,
      "name": "Rock_Shale_Brick_Smooth_Half",
      "rotation": 5
    },
    {
      "x": -12,
      "y": 48,
      "z": -14,
      "name": "*Rock_Shale_Brick_Roof_Steep_State_Definitions_Corner_Right",
      "rotation": 3
    },
    {
      "x": -12,
      "y": 49,
      "z": -14,
      "name": "*Rock_Shale_Brick_Roof_Steep_State_Definitions_Corner_Right",
      "filler": 1024,
      "rotation": 3
    },
    {
      "x": -12,
      "y": 8,
      "z": -13,
      "name": "Rock_Shale_Brick_Smooth_Half",
      "rotation": 7
    },
    {
      "x": -12,
      "y": 9,
      "z": -13,
      "name": "Rock_Shale_Brick_Smooth_Half",
      "rotation": 6
    },
    {
      "x": -12,
      "y": 10,
      "z": -13,
      "name": "Rock_Shale_Brick_Smooth_Half",
      "rotation": 6
    },
    {
      "x": -12,
      "y": 11,
      "z": -13,
      "name": "Rock_Shale_Brick_Smooth"
    },
    {
      "x": -12,
      "y": 27,
      "z": -13,
      "name": "Rock_Shale_Brick_Smooth_Half",
      "rotation": 7
    },
    {
      "x": -12,
      "y": 28,
      "z": -13,
      "name": "Rock_Shale_Brick_Smooth_Half",
      "rotation": 6
    },
    {
      "x": -12,
      "y": 29,
      "z": -13,
      "name": "Rock_Shale_Brick_Smooth_Half",
      "rotation": 6
    },
    {
      "x": -12,
      "y": 30,
      "z": -13,
      "name": "Rock_Shale_Brick_Smooth"
    },
    {
      "x": -12,
      "y": 40,
      "z": -13,
      "name": "Rock_Shale_Brick_Smooth"
    },
    {
      "x": -12,
      "y": 41,
      "z": -13,
      "name": "Rock_Shale_Brick_Smooth"
    },
    {
      "x": -12,
      "y": 42,
      "z": -13,
      "name": "Rock_Shale_Brick_Smooth"
    },
    {
      "x": -12,
      "y": 43,
      "z": -13,
      "name": "Rock_Shale_Brick_Smooth"
    },
    {
      "x": -12,
      "y": 44,
      "z": -13,
      "name": "Rock_Shale_Brick_Smooth"
    },
    {
      "x": -12,
      "y": 45,
      "z": -13,
      "name": "Rock_Shale_Brick_Smooth"
    },
    {
      "x": -12,
      "y": 46,
      "z": -13,
      "name": "Rock_Shale_Brick_Smooth"
    },
    {
      "x": -12,
      "y": 47,
      "z": -13,
      "name": "Rock_Shale_Brick_Smooth"
    },
    {
      "x": -12,
      "y": 48,
      "z": -13,
      "name": "*Rock_Shale_Brick_Roof_Steep_State_Definitions_Inverted_Corner_Left",
      "rotation": 2
    },
    {
      "x": -12,
      "y": 49,
      "z": -13,
      "name": "*Rock_Shale_Brick_Roof_Steep_State_Definitions_Inverted_Corner_Left",
      "filler": 1024,
      "rotation": 2
    },
    {
      "x": -12,
      "y": 0,
      "z": -12,
      "name": "Rock_Shale_Brick_Smooth"
    },
    {
      "x": -12,
      "y": 1,
      "z": -12,
      "name": "Rock_Shale_Brick_Smooth"
    },
    {
      "x": -12,
      "y": 2,
      "z": -12,
      "name": "Rock_Shale_Brick_Smooth"
    },
    {
      "x": -12,
      "y": 3,
      "z": -12,
      "name": "Rock_Shale_Brick_Smooth"
    },
    {
      "x": -12,
      "y": 4,
      "z": -12,
      "name": "Rock_Shale_Brick_Smooth"
    },
    {
      "x": -12,
      "y": 5,
      "z": -12,
      "name": "Rock_Shale_Brick_Smooth"
    },
    {
      "x": -12,
      "y": 6,
      "z": -12,
      "name": "Rock_Shale_Brick_Smooth"
    },
    {
      "x": -12,
      "y": 8,
      "z": -12,
      "name": "Rock_Shale_Brick_Smooth_Half",
      "rotation": 11
    },
    {
      "x": -12,
      "y": 9,
      "z": -12,
      "name": "Rock_Runic_Teal_Brick_Stairs",
      "rotation": 8
    },
    {
      "x": -12,
      "y": 13,
      "z": -12,
      "name": "Rock_Shale_Brick_Stairs",
      "rotation": 24
    },
    {
      "x": -12,
      "y": 14,
      "z": -12,
      "name": "Rock_Shale_Brick_Stairs",
      "rotation": 24
    },
    {
      "x": -12,
      "y": 15,
      "z": -12,
      "name": "Rock_Shale_Brick_Stairs",
      "rotation": 24
    },
    {
      "x": -12,
      "y": 16,
      "z": -12,
      "name": "Rock_Shale_Brick_Stairs",
      "rotation": 24
    },
    {
      "x": -12,
      "y": 17,
      "z": -12,
      "name": "Rock_Shale_Brick_Stairs",
      "rotation": 24
    },
    {
      "x": -12,
      "y": 27,
      "z": -12,
      "name": "Rock_Shale_Brick_Smooth_Half",
      "rotation": 11
    },
    {
      "x": -12,
      "y": 28,
      "z": -12,
      "name": "Rock_Runic_Teal_Brick_Stairs",
      "rotation": 8
    },
    {
      "x": -12,
      "y": 32,
      "z": -12,
      "name": "Rock_Shale_Brick_Stairs",
      "rotation": 24
    },
    {
      "x": -12,
      "y": 33,
      "z": -12,
      "name": "Rock_Shale_Brick_Stairs",
      "rotation": 24
    },
    {
      "x": -12,
      "y": 34,
      "z": -12,
      "name": "Rock_Shale_Brick_Stairs",
      "rotation": 24
    },
    {
      "x": -12,
      "y": 35,
      "z": -12,
      "name": "Rock_Shale_Brick_Stairs",
      "rotation": 24
    },
    {
      "x": -12,
      "y": 36,
      "z": -12,
      "name": "Rock_Shale_Brick_Stairs",
      "rotation": 24
    },
    {
      "x": -12,
      "y": 39,
      "z": -12,
      "name": "Rock_Shale_Brick_Half",
      "rotation": 8
    },
    {
      "x": -12,
      "y": 40,
      "z": -12,
      "name": "Rock_Shale_Brick_Smooth"
    },
    {
      "x": -12,
      "y": 41,
      "z": -12,
      "name": "Rock_Shale_Brick_Pillar_Base"
    },
    {
      "x": -12,
      "y": 42,
      "z": -12,
      "name": "Furniture_SK_Monuments_Brazier"
    },
    {
      "x": -12,
      "y": 49,
      "z": -12,
      "name": "Rock_Shale_Brick_Half",
      "rotation": 32
    },
    {
      "x": -12,
      "y": 50,
      "z": -12,
      "name": "*Rock_Shale_Brick_Roof_Steep_State_Definitions_Corner_Left",
      "rotation": 2
    },
    {
      "x": -12,
      "y": 51,
      "z": -12,
      "name": "*Rock_Shale_Brick_Roof_Steep_State_Definitions_Corner_Left",
      "filler": 1024,
      "rotation": 2
    },
    {
      "x": -12,
      "y": 0,
      "z": -11,
      "name": "Rock_Shale_Brick_Smooth"
    },
    {
      "x": -12,
      "y": 1,
      "z": -11,
      "name": "Rock_Shale_Brick_Smooth"
    },
    {
      "x": -12,
      "y": 2,
      "z": -11,
      "name": "Rock_Shale_Brick_Smooth"
    },
    {
      "x": -12,
      "y": 3,
      "z": -11,
      "name": "Rock_Shale_Brick_Smooth"
    },
    {
      "x": -12,
      "y": 4,
      "z": -11,
      "name": "Rock_Shale_Brick_Smooth"
    },
    {
      "x": -12,
      "y": 5,
      "z": -11,
      "name": "Rock_Shale_Brick_Smooth"
    },
    {
      "x": -12,
      "y": 6,
      "z": -11,
      "name": "Rock_Shale_Brick_Smooth"
    },
    {
      "x": -12,
      "y": 7,
      "z": -11,
      "name": "Rock_Shale_Brick_Smooth"
    },
    {
      "x": -12,
      "y": 8,
      "z": -11,
      "name": "Rock_Shale_Brick_Smooth"
    },
    {
      "x": -12,
      "y": 9,
      "z": -11,
      "name": "Rock_Shale_Brick_Smooth"
    },
    {
      "x": -12,
      "y": 10,
      "z": -11,
      "name": "Rock_Shale_Brick_Smooth"
    },
    {
      "x": -12,
      "y": 11,
      "z": -11,
      "name": "Rock_Shale_Brick_Smooth"
    },
    {
      "x": -12,
      "y": 12,
      "z": -11,
      "name": "Rock_Shale_Brick_Smooth"
    },
    {
      "x": -12,
      "y": 13,
      "z": -11,
      "name": "Rock_Shale_Brick_Smooth"
    },
    {
      "x": -12,
      "y": 14,
      "z": -11,
      "name": "Rock_Shale_Brick_Ornate",
      "rotation": 3
    },
    {
      "x": -12,
      "y": 15,
      "z": -11,
      "name": "Rock_Shale_Brick_Smooth"
    },
    {
      "x": -12,
      "y": 16,
      "z": -11,
      "name": "Rock_Shale_Brick_Smooth"
    },
    {
      "x": -12,
      "y": 17,
      "z": -11,
      "name": "Rock_Shale_Brick_Smooth"
    },
    {
      "x": -12,
      "y": 18,
      "z": -11,
      "name": "Rock_Shale_Brick_Smooth"
    },
    {
      "x": -12,
      "y": 19,
      "z": -11,
      "name": "Rock_Shale_Brick_Smooth"
    },
    {
      "x": -12,
      "y": 20,
      "z": -11,
      "name": "Rock_Shale_Brick_Smooth"
    },
    {
      "x": -12,
      "y": 21,
      "z": -11,
      "name": "Rock_Shale_Brick_Smooth"
    },
    {
      "x": -12,
      "y": 22,
      "z": -11,
      "name": "Rock_Shale_Brick_Smooth"
    },
    {
      "x": -12,
      "y": 23,
      "z": -11,
      "name": "Rock_Shale_Brick_Smooth"
    },
    {
      "x": -12,
      "y": 24,
      "z": -11,
      "name": "Rock_Shale_Brick_Smooth"
    },
    {
      "x": -12,
      "y": 25,
      "z": -11,
      "name": "Rock_Shale_Brick_Smooth"
    },
    {
      "x": -12,
      "y": 26,
      "z": -11,
      "name": "Rock_Shale_Brick_Smooth"
    },
    {
      "x": -12,
      "y": 27,
      "z": -11,
      "name": "Rock_Shale_Brick_Smooth"
    },
    {
      "x": -12,
      "y": 28,
      "z": -11,
      "name": "Rock_Shale_Brick_Smooth"
    },
    {
      "x": -12,
      "y": 29,
      "z": -11,
      "name": "Rock_Shale_Brick_Smooth"
    },
    {
      "x": -12,
      "y": 30,
      "z": -11,
      "name": "Rock_Shale_Brick_Smooth"
    },
    {
      "x": -12,
      "y": 31,
      "z": -11,
      "name": "Rock_Shale_Brick_Smooth"
    },
    {
      "x": -12,
      "y": 32,
      "z": -11,
      "name": "Rock_Shale_Brick_Smooth"
    },
    {
      "x": -12,
      "y": 33,
      "z": -11,
      "name": "Rock_Shale_Brick_Ornate",
      "rotation": 3
    },
    {
      "x": -12,
      "y": 34,
      "z": -11,
      "name": "Rock_Shale_Brick_Smooth"
    },
    {
      "x": -12,
      "y": 35,
      "z": -11,
      "name": "Rock_Shale_Brick_Smooth"
    },
    {
      "x": -12,
      "y": 36,
      "z": -11,
      "name": "Rock_Shale_Brick_Smooth"
    },
    {
      "x": -12,
      "y": 37,
      "z": -11,
      "name": "Rock_Shale_Brick_Smooth"
    },
    {
      "x": -12,
      "y": 38,
      "z": -11,
      "name": "Rock_Shale_Brick_Ornate"
    },
    {
      "x": -12,
      "y": 39,
      "z": -11,
      "name": "Rock_Shale_Brick"
    },
    {
      "x": -12,
      "y": 40,
      "z": -11,
      "name": "Rock_Shale_Brick_Smooth_Half",
      "rotation": 8
    },
    {
      "x": -12,
      "y": 41,
      "z": -11,
      "name": "Rock_Shale_Brick_Stairs",
      "rotation": 1
    },
    {
      "x": -12,
      "y": 50,
      "z": -11,
      "name": "*Rock_Shale_Brick_Roof_Steep_State_Definitions_Inverted_Corner_Right",
      "rotation": 3
    },
    {
      "x": -12,
      "y": 51,
      "z": -11,
      "name": "*Rock_Shale_Brick_Roof_Steep_State_Definitions_Inverted_Corner_Right",
      "filler": 1024,
      "rotation": 3
    },
    {
      "x": -12,
      "y": 0,
      "z": -10,
      "name": "Rock_Shale_Brick_Smooth"
    },
    {
      "x": -12,
      "y": 1,
      "z": -10,
      "name": "Rock_Shale_Brick_Smooth"
    },
    {
      "x": -12,
      "y": 2,
      "z": -10,
      "name": "Rock_Shale_Brick_Smooth"
    },
    {
      "x": -12,
      "y": 3,
      "z": -10,
      "name": "Rock_Shale_Brick_Smooth"
    },
    {
      "x": -12,
      "y": 4,
      "z": -10,
      "name": "Rock_Shale_Brick_Smooth"
    },
    {
      "x": -12,
      "y": 5,
      "z": -10,
      "name": "Rock_Shale_Brick_Smooth"
    },
    {
      "x": -12,
      "y": 6,
      "z": -10,
      "name": "Rock_Shale_Brick_Smooth"
    },
    {
      "x": -12,
      "y": 7,
      "z": -10,
      "name": "Rock_Shale_Brick_Smooth"
    },
    {
      "x": -12,
      "y": 8,
      "z": -10,
      "name": "Rock_Shale_Brick_Smooth"
    },
    {
      "x": -12,
      "y": 9,
      "z": -10,
      "name": "Rock_Shale_Brick_Smooth"
    },
    {
      "x": -12,
      "y": 10,
      "z": -10,
      "name": "Rock_Shale_Brick_Smooth"
    },
    {
      "x": -12,
      "y": 11,
      "z": -10,
      "name": "Rock_Shale_Brick_Smooth"
    },
    {
      "x": -12,
      "y": 12,
      "z": -10,
      "name": "Furniture_Temple_Dark_Window",
      "rotation": 1
    },
    {
      "x": -12,
      "y": 13,
      "z": -10,
      "name": "Furniture_Temple_Dark_Window",
      "rotation": 1
    },
    {
      "x": -12,
      "y": 14,
      "z": -10,
      "name": "Rock_Shale_Brick_Ornate",
      "rotation": 3
    },
    {
      "x": -12,
      "y": 15,
      "z": -10,
      "name": "Rock_Shale_Brick_Smooth"
    },
    {
      "x": -12,
      "y": 16,
      "z": -10,
      "name": "Rock_Shale_Brick_Smooth_Half",
      "rotation": 7
    },
    {
      "x": -12,
      "y": 17,
      "z": -10,
      "name": "Rock_Shale_Brick_Smooth_Half",
      "rotation": 7
    },
    {
      "x": -12,
      "y": 18,
      "z": -10,
      "name": "Rock_Shale_Brick_Smooth"
    },
    {
      "x": -12,
      "y": 19,
      "z": -10,
      "name": "Rock_Shale_Brick_Smooth"
    },
    {
      "x": -12,
      "y": 20,
      "z": -10,
      "name": "Rock_Shale_Brick_Smooth"
    },
    {
      "x": -12,
      "y": 21,
      "z": -10,
      "name": "Rock_Shale_Brick_Smooth"
    },
    {
      "x": -12,
      "y": 22,
      "z": -10,
      "name": "Rock_Shale_Brick_Smooth"
    },
    {
      "x": -12,
      "y": 23,
      "z": -10,
      "name": "Rock_Shale_Brick_Smooth"
    },
    {
      "x": -12,
      "y": 24,
      "z": -10,
      "name": "Rock_Shale_Brick_Smooth"
    },
    {
      "x": -12,
      "y": 25,
      "z": -10,
      "name": "Rock_Shale_Brick_Smooth"
    },
    {
      "x": -12,
      "y": 26,
      "z": -10,
      "name": "Rock_Shale_Brick_Smooth"
    },
    {
      "x": -12,
      "y": 27,
      "z": -10,
      "name": "Rock_Shale_Brick_Smooth"
    },
    {
      "x": -12,
      "y": 28,
      "z": -10,
      "name": "Rock_Shale_Brick_Smooth"
    },
    {
      "x": -12,
      "y": 29,
      "z": -10,
      "name": "Rock_Shale_Brick_Smooth"
    },
    {
      "x": -12,
      "y": 30,
      "z": -10,
      "name": "Rock_Shale_Brick_Smooth"
    },
    {
      "x": -12,
      "y": 31,
      "z": -10,
      "name": "Furniture_Temple_Dark_Window",
      "rotation": 1
    },
    {
      "x": -12,
      "y": 32,
      "z": -10,
      "name": "Furniture_Temple_Dark_Window",
      "rotation": 1
    },
    {
      "x": -12,
      "y": 33,
      "z": -10,
      "name": "Rock_Shale_Brick_Ornate",
      "rotation": 3
    },
    {
      "x": -12,
      "y": 34,
      "z": -10,
      "name": "Rock_Shale_Brick_Smooth"
    },
    {
      "x": -12,
      "y": 35,
      "z": -10,
      "name": "Rock_Shale_Brick_Smooth_Half",
      "rotation": 7
    },
    {
      "x": -12,
      "y": 36,
      "z": -10,
      "name": "Rock_Shale_Brick_Smooth_Half",
      "rotation": 7
    },
    {
      "x": -12,
      "y": 37,
      "z": -10,
      "name": "Rock_Shale_Brick_Smooth"
    },
    {
      "x": -12,
      "y": 38,
      "z": -10,
      "name": "Rock_Shale_Brick_Ornate"
    },
    {
      "x": -12,
      "y": 39,
      "z": -10,
      "name": "Rock_Shale_Brick"
    },
    {
      "x": -12,
      "y": 40,
      "z": -10,
      "name": "Rock_Shale_Brick_Smooth_Half",
      "rotation": 8
    },
    {
      "x": -12,
      "y": 41,
      "z": -10,
      "name": "Rock_Shale_Brick_Stairs",
      "rotation": 1
    },
    {
      "x": -12,
      "y": 51,
      "z": -10,
      "name": "Rock_Shale_Brick_Half",
      "rotation": 32
    },
    {
      "x": -12,
      "y": 52,
      "z": -10,
      "name": "Rock_Shale_Brick_Pillar_Base",
      "rotation": 2
    },
    {
      "x": -12,
      "y": 53,
      "z": -10,
      "name": "Rock_Shale_Brick_Beam",
      "rotation": 2
    },
    {
      "x": -12,
      "y": 54,
      "z": -10,
      "name": "Rock_Shale_Brick_Beam",
      "rotation": 2
    },
    {
      "x": -12,
      "y": 0,
      "z": -9,
      "name": "Rock_Shale_Brick_Smooth"
    },
    {
      "x": -12,
      "y": 1,
      "z": -9,
      "name": "Rock_Shale_Brick_Smooth"
    },
    {
      "x": -12,
      "y": 2,
      "z": -9,
      "name": "Rock_Shale_Brick_Smooth"
    },
    {
      "x": -12,
      "y": 3,
      "z": -9,
      "name": "Rock_Shale_Brick_Smooth"
    },
    {
      "x": -12,
      "y": 4,
      "z": -9,
      "name": "Rock_Shale_Brick_Smooth"
    },
    {
      "x": -12,
      "y": 5,
      "z": -9,
      "name": "Rock_Shale_Brick_Smooth"
    },
    {
      "x": -12,
      "y": 6,
      "z": -9,
      "name": "Rock_Shale_Brick_Smooth"
    },
    {
      "x": -12,
      "y": 7,
      "z": -9,
      "name": "Rock_Shale_Brick_Smooth"
    },
    {
      "x": -12,
      "y": 8,
      "z": -9,
      "name": "Rock_Shale_Brick_Smooth"
    },
    {
      "x": -12,
      "y": 9,
      "z": -9,
      "name": "Rock_Shale_Brick_Smooth"
    },
    {
      "x": -12,
      "y": 10,
      "z": -9,
      "name": "Rock_Shale_Brick_Smooth"
    },
    {
      "x": -12,
      "y": 11,
      "z": -9,
      "name": "Rock_Shale_Brick_Smooth"
    },
    {
      "x": -12,
      "y": 12,
      "z": -9,
      "name": "Rock_Shale_Brick_Smooth"
    },
    {
      "x": -12,
      "y": 13,
      "z": -9,
      "name": "Rock_Shale_Brick_Smooth"
    },
    {
      "x": -12,
      "y": 14,
      "z": -9,
      "name": "Rock_Shale_Brick_Ornate",
      "rotation": 3
    },
    {
      "x": -12,
      "y": 15,
      "z": -9,
      "name": "Rock_Shale_Brick_Smooth"
    },
    {
      "x": -12,
      "y": 16,
      "z": -9,
      "name": "Rock_Shale_Brick_Smooth"
    },
    {
      "x": -12,
      "y": 17,
      "z": -9,
      "name": "Rock_Shale_Brick_Smooth"
    },
    {
      "x": -12,
      "y": 18,
      "z": -9,
      "name": "Rock_Shale_Brick_Smooth"
    },
    {
      "x": -12,
      "y": 19,
      "z": -9,
      "name": "Rock_Shale_Brick_Smooth"
    },
    {
      "x": -12,
      "y": 20,
      "z": -9,
      "name": "Rock_Shale_Brick_Smooth"
    },
    {
      "x": -12,
      "y": 21,
      "z": -9,
      "name": "Rock_Shale_Brick_Smooth"
    },
    {
      "x": -12,
      "y": 22,
      "z": -9,
      "name": "Rock_Shale_Brick_Smooth"
    },
    {
      "x": -12,
      "y": 23,
      "z": -9,
      "name": "Rock_Shale_Brick_Smooth"
    },
    {
      "x": -12,
      "y": 24,
      "z": -9,
      "name": "Rock_Shale_Brick_Smooth"
    },
    {
      "x": -12,
      "y": 25,
      "z": -9,
      "name": "Rock_Shale_Brick_Smooth"
    },
    {
      "x": -12,
      "y": 26,
      "z": -9,
      "name": "Rock_Shale_Brick_Smooth"
    },
    {
      "x": -12,
      "y": 27,
      "z": -9,
      "name": "Rock_Shale_Brick_Smooth"
    },
    {
      "x": -12,
      "y": 28,
      "z": -9,
      "name": "Rock_Shale_Brick_Smooth"
    },
    {
      "x": -12,
      "y": 29,
      "z": -9,
      "name": "Rock_Shale_Brick_Smooth"
    },
    {
      "x": -12,
      "y": 30,
      "z": -9,
      "name": "Rock_Shale_Brick_Smooth"
    },
    {
      "x": -12,
      "y": 31,
      "z": -9,
      "name": "Rock_Shale_Brick_Smooth"
    },
    {
      "x": -12,
      "y": 32,
      "z": -9,
      "name": "Rock_Shale_Brick_Smooth"
    },
    {
      "x": -12,
      "y": 33,
      "z": -9,
      "name": "Rock_Shale_Brick_Ornate",
      "rotation": 3
    },
    {
      "x": -12,
      "y": 34,
      "z": -9,
      "name": "Rock_Shale_Brick_Smooth"
    },
    {
      "x": -12,
      "y": 35,
      "z": -9,
      "name": "Rock_Shale_Brick_Smooth"
    },
    {
      "x": -12,
      "y": 36,
      "z": -9,
      "name": "Rock_Shale_Brick_Smooth"
    },
    {
      "x": -12,
      "y": 37,
      "z": -9,
      "name": "Rock_Shale_Brick_Smooth"
    },
    {
      "x": -12,
      "y": 38,
      "z": -9,
      "name": "Rock_Shale_Brick_Ornate"
    },
    {
      "x": -12,
      "y": 39,
      "z": -9,
      "name": "Rock_Shale_Brick"
    },
    {
      "x": -12,
      "y": 40,
      "z": -9,
      "name": "Rock_Shale_Brick_Smooth_Half",
      "rotation": 8
    },
    {
      "x": -12,
      "y": 41,
      "z": -9,
      "name": "Rock_Shale_Brick_Stairs",
      "rotation": 1
    },
    {
      "x": -12,
      "y": 50,
      "z": -9,
      "name": "*Rock_Shale_Brick_Roof_Steep_State_Definitions_Inverted_Corner_Right"
    },
    {
      "x": -12,
      "y": 51,
      "z": -9,
      "name": "*Rock_Shale_Brick_Roof_Steep_State_Definitions_Inverted_Corner_Right",
      "filler": 1024
    },
    {
      "x": -12,
      "y": 0,
      "z": -8,
      "name": "Rock_Shale_Brick_Smooth_Half",
      "rotation": 4
    },
    {
      "x": -12,
      "y": 1,
      "z": -8,
      "name": "Rock_Shale_Brick_Smooth_Half",
      "rotation": 4
    },
    {
      "x": -12,
      "y": 2,
      "z": -8,
      "name": "Rock_Shale_Brick_Smooth_Half",
      "rotation": 4
    },
    {
      "x": -12,
      "y": 3,
      "z": -8,
      "name": "Rock_Shale_Brick_Smooth_Half",
      "rotation": 4
    },
    {
      "x": -12,
      "y": 4,
      "z": -8,
      "name": "Rock_Shale_Brick_Smooth_Half",
      "rotation": 4
    },
    {
      "x": -12,
      "y": 5,
      "z": -8,
      "name": "Rock_Shale_Brick_Smooth_Half",
      "rotation": 4
    },
    {
      "x": -12,
      "y": 6,
      "z": -8,
      "name": "Rock_Shale_Brick_Smooth_Half",
      "rotation": 4
    },
    {
      "x": -12,
      "y": 7,
      "z": -8,
      "name": "*Rock_Runic_Teal_Brick_Stairs_State_Definitions_Inverted_Corner_Right",
      "rotation": 9
    },
    {
      "x": -12,
      "y": 19,
      "z": -8,
      "name": "Rock_Shale_Brick_Smooth_Half",
      "rotation": 4
    },
    {
      "x": -12,
      "y": 20,
      "z": -8,
      "name": "Rock_Shale_Brick_Smooth_Half",
      "rotation": 4
    },
    {
      "x": -12,
      "y": 21,
      "z": -8,
      "name": "Rock_Shale_Brick_Smooth_Half",
      "rotation": 4
    },
    {
      "x": -12,
      "y": 22,
      "z": -8,
      "name": "Rock_Shale_Brick_Smooth_Half",
      "rotation": 4
    },
    {
      "x": -12,
      "y": 23,
      "z": -8,
      "name": "Rock_Shale_Brick_Smooth_Half",
      "rotation": 4
    },
    {
      "x": -12,
      "y": 24,
      "z": -8,
      "name": "Rock_Shale_Brick_Smooth_Half",
      "rotation": 4
    },
    {
      "x": -12,
      "y": 25,
      "z": -8,
      "name": "Rock_Shale_Brick_Smooth_Half",
      "rotation": 4
    },
    {
      "x": -12,
      "y": 26,
      "z": -8,
      "name": "*Rock_Runic_Teal_Brick_Stairs_State_Definitions_Inverted_Corner_Right",
      "rotation": 9
    },
    {
      "x": -12,
      "y": 39,
      "z": -8,
      "name": "Rock_Shale_Brick_Stairs",
      "rotation": 9
    },
    {
      "x": -12,
      "y": 40,
      "z": -8,
      "name": "Rock_Shale_Brick_Smooth"
    },
    {
      "x": -12,
      "y": 49,
      "z": -8,
      "name": "Rock_Shale_Brick_Half",
      "rotation": 32
    },
    {
      "x": -12,
      "y": 50,
      "z": -8,
      "name": "*Rock_Shale_Brick_Roof_Steep_State_Definitions_Corner_Left",
      "rotation": 3
    },
    {
      "x": -12,
      "y": 51,
      "z": -8,
      "name": "*Rock_Shale_Brick_Roof_Steep_State_Definitions_Corner_Left",
      "filler": 1024,
      "rotation": 3
    },
    {
      "x": -12,
      "y": 7,
      "z": -7,
      "name": "*Rock_Runic_Teal_Brick_Stairs_State_Definitions_Corner_Left",
      "rotation": 10
    },
    {
      "x": -12,
      "y": 26,
      "z": -7,
      "name": "*Rock_Runic_Teal_Brick_Stairs_State_Definitions_Corner_Left",
      "rotation": 10
    },
    {
      "x": -12,
      "y": 40,
      "z": -7,
      "name": "Rock_Shale_Brick_Smooth"
    },
    {
      "x": -12,
      "y": 41,
      "z": -7,
      "name": "Rock_Shale_Brick_Smooth"
    },
    {
      "x": -12,
      "y": 42,
      "z": -7,
      "name": "Rock_Shale_Brick_Smooth"
    },
    {
      "x": -12,
      "y": 43,
      "z": -7,
      "name": "Rock_Shale_Brick_Smooth"
    },
    {
      "x": -12,
      "y": 44,
      "z": -7,
      "name": "Rock_Shale_Brick_Smooth"
    },
    {
      "x": -12,
      "y": 45,
      "z": -7,
      "name": "Rock_Shale_Brick_Smooth"
    },
    {
      "x": -12,
      "y": 46,
      "z": -7,
      "name": "Rock_Shale_Brick_Smooth"
    },
    {
      "x": -12,
      "y": 47,
      "z": -7,
      "name": "Rock_Shale_Brick_Smooth"
    },
    {
      "x": -12,
      "y": 48,
      "z": -7,
      "name": "*Rock_Shale_Brick_Roof_Steep_State_Definitions_Inverted_Corner_Right"
    },
    {
      "x": -12,
      "y": 49,
      "z": -7,
      "name": "*Rock_Shale_Brick_Roof_Steep_State_Definitions_Inverted_Corner_Right",
      "filler": 1024
    },
    {
      "x": -12,
      "y": 7,
      "z": -6,
      "name": "Rock_Shale_Brick_Smooth_Half",
      "rotation": 4
    },
    {
      "x": -12,
      "y": 8,
      "z": -6,
      "name": "Rock_Shale_Brick_Smooth_Half",
      "rotation": 4
    },
    {
      "x": -12,
      "y": 9,
      "z": -6,
      "name": "Rock_Shale_Brick_Smooth_Half",
      "rotation": 4
    },
    {
      "x": -12,
      "y": 26,
      "z": -6,
      "name": "Rock_Shale_Brick_Smooth_Half",
      "rotation": 4
    },
    {
      "x": -12,
      "y": 27,
      "z": -6,
      "name": "Rock_Shale_Brick_Smooth_Half",
      "rotation": 4
    },
    {
      "x": -12,
      "y": 28,
      "z": -6,
      "name": "Rock_Shale_Brick_Smooth_Half",
      "rotation": 4
    },
    {
      "x": -12,
      "y": 48,
      "z": -6,
      "name": "*Rock_Shale_Brick_Roof_Steep_State_Definitions_Corner_Left",
      "rotation": 3
    },
    {
      "x": -12,
      "y": 49,
      "z": -6,
      "name": "*Rock_Shale_Brick_Roof_Steep_State_Definitions_Corner_Left",
      "filler": 1024,
      "rotation": 3
    },
    {
      "x": -12,
      "y": 7,
      "z": 6,
      "name": "Rock_Shale_Brick_Smooth_Half",
      "rotation": 6
    },
    {
      "x": -12,
      "y": 8,
      "z": 6,
      "name": "Rock_Shale_Brick_Smooth_Half",
      "rotation": 6
    },
    {
      "x": -12,
      "y": 9,
      "z": 6,
      "name": "Rock_Shale_Brick_Smooth_Half",
      "rotation": 6
    },
    {
      "x": -12,
      "y": 26,
      "z": 6,
      "name": "Rock_Shale_Brick_Smooth_Half",
      "rotation": 6
    },
    {
      "x": -12,
      "y": 27,
      "z": 6,
      "name": "Rock_Shale_Brick_Smooth_Half",
      "rotation": 6
    },
    {
      "x": -12,
      "y": 28,
      "z": 6,
      "name": "Rock_Shale_Brick_Smooth_Half",
      "rotation": 6
    },
    {
      "x": -12,
      "y": 48,
      "z": 6,
      "name": "*Rock_Shale_Brick_Roof_Steep_State_Definitions_Corner_Right",
      "rotation": 3
    },
    {
      "x": -12,
      "y": 49,
      "z": 6,
      "name": "*Rock_Shale_Brick_Roof_Steep_State_Definitions_Corner_Right",
      "filler": 1024,
      "rotation": 3
    },
    {
      "x": -12,
      "y": 7,
      "z": 7,
      "name": "*Rock_Runic_Teal_Brick_Stairs_State_Definitions_Corner_Right",
      "rotation": 8
    },
    {
      "x": -12,
      "y": 26,
      "z": 7,
      "name": "*Rock_Runic_Teal_Brick_Stairs_State_Definitions_Corner_Right",
      "rotation": 8
    },
    {
      "x": -12,
      "y": 40,
      "z": 7,
      "name": "Rock_Shale_Brick_Smooth"
    },
    {
      "x": -12,
      "y": 41,
      "z": 7,
      "name": "Rock_Shale_Brick_Smooth"
    },
    {
      "x": -12,
      "y": 42,
      "z": 7,
      "name": "Rock_Shale_Brick_Smooth"
    },
    {
      "x": -12,
      "y": 43,
      "z": 7,
      "name": "Rock_Shale_Brick_Smooth"
    },
    {
      "x": -12,
      "y": 44,
      "z": 7,
      "name": "Rock_Shale_Brick_Smooth"
    },
    {
      "x": -12,
      "y": 45,
      "z": 7,
      "name": "Rock_Shale_Brick_Smooth"
    },
    {
      "x": -12,
      "y": 46,
      "z": 7,
      "name": "Rock_Shale_Brick_Smooth"
    },
    {
      "x": -12,
      "y": 47,
      "z": 7,
      "name": "Rock_Shale_Brick_Smooth"
    },
    {
      "x": -12,
      "y": 48,
      "z": 7,
      "name": "*Rock_Shale_Brick_Roof_Steep_State_Definitions_Inverted_Corner_Left",
      "rotation": 2
    },
    {
      "x": -12,
      "y": 49,
      "z": 7,
      "name": "*Rock_Shale_Brick_Roof_Steep_State_Definitions_Inverted_Corner_Left",
      "filler": 1024,
      "rotation": 2
    },
    {
      "x": -12,
      "y": 0,
      "z": 8,
      "name": "Rock_Shale_Brick_Smooth_Half",
      "rotation": 6
    },
    {
      "x": -12,
      "y": 1,
      "z": 8,
      "name": "Rock_Shale_Brick_Smooth_Half",
      "rotation": 6
    },
    {
      "x": -12,
      "y": 2,
      "z": 8,
      "name": "Rock_Shale_Brick_Smooth_Half",
      "rotation": 6
    },
    {
      "x": -12,
      "y": 3,
      "z": 8,
      "name": "Rock_Shale_Brick_Smooth_Half",
      "rotation": 6
    },
    {
      "x": -12,
      "y": 4,
      "z": 8,
      "name": "Rock_Shale_Brick_Smooth_Half",
      "rotation": 6
    },
    {
      "x": -12,
      "y": 5,
      "z": 8,
      "name": "Rock_Shale_Brick_Smooth_Half",
      "rotation": 6
    },
    {
      "x": -12,
      "y": 6,
      "z": 8,
      "name": "Rock_Shale_Brick_Smooth_Half",
      "rotation": 6
    },
    {
      "x": -12,
      "y": 7,
      "z": 8,
      "name": "*Rock_Runic_Teal_Brick_Stairs_State_Definitions_Inverted_Corner_Left",
      "rotation": 9
    },
    {
      "x": -12,
      "y": 19,
      "z": 8,
      "name": "Rock_Shale_Brick_Smooth_Half",
      "rotation": 6
    },
    {
      "x": -12,
      "y": 20,
      "z": 8,
      "name": "Rock_Shale_Brick_Smooth_Half",
      "rotation": 6
    },
    {
      "x": -12,
      "y": 21,
      "z": 8,
      "name": "Rock_Shale_Brick_Smooth_Half",
      "rotation": 6
    },
    {
      "x": -12,
      "y": 22,
      "z": 8,
      "name": "Rock_Shale_Brick_Smooth_Half",
      "rotation": 6
    },
    {
      "x": -12,
      "y": 23,
      "z": 8,
      "name": "Rock_Shale_Brick_Smooth_Half",
      "rotation": 6
    },
    {
      "x": -12,
      "y": 24,
      "z": 8,
      "name": "Rock_Shale_Brick_Smooth_Half",
      "rotation": 6
    },
    {
      "x": -12,
      "y": 25,
      "z": 8,
      "name": "Rock_Shale_Brick_Smooth_Half",
      "rotation": 6
    },
    {
      "x": -12,
      "y": 26,
      "z": 8,
      "name": "*Rock_Runic_Teal_Brick_Stairs_State_Definitions_Inverted_Corner_Left",
      "rotation": 9
    },
    {
      "x": -12,
      "y": 39,
      "z": 8,
      "name": "Rock_Shale_Brick_Stairs",
      "rotation": 35
    },
    {
      "x": -12,
      "y": 40,
      "z": 8,
      "name": "Rock_Shale_Brick_Smooth"
    },
    {
      "x": -12,
      "y": 49,
      "z": 8,
      "name": "Rock_Shale_Brick_Half",
      "rotation": 33
    },
    {
      "x": -12,
      "y": 50,
      "z": 8,
      "name": "*Rock_Shale_Brick_Roof_Steep_State_Definitions_Corner_Left",
      "rotation": 2
    },
    {
      "x": -12,
      "y": 51,
      "z": 8,
      "name": "*Rock_Shale_Brick_Roof_Steep_State_Definitions_Corner_Left",
      "filler": 1024,
      "rotation": 2
    },
    {
      "x": -12,
      "y": 0,
      "z": 9,
      "name": "Rock_Shale_Brick_Smooth"
    },
    {
      "x": -12,
      "y": 1,
      "z": 9,
      "name": "Rock_Shale_Brick_Smooth"
    },
    {
      "x": -12,
      "y": 2,
      "z": 9,
      "name": "Rock_Shale_Brick_Smooth"
    },
    {
      "x": -12,
      "y": 3,
      "z": 9,
      "name": "Rock_Shale_Brick_Smooth"
    },
    {
      "x": -12,
      "y": 4,
      "z": 9,
      "name": "Rock_Shale_Brick_Smooth"
    },
    {
      "x": -12,
      "y": 5,
      "z": 9,
      "name": "Rock_Shale_Brick_Smooth"
    },
    {
      "x": -12,
      "y": 6,
      "z": 9,
      "name": "Rock_Shale_Brick_Smooth"
    },
    {
      "x": -12,
      "y": 7,
      "z": 9,
      "name": "Rock_Shale_Brick_Smooth"
    },
    {
      "x": -12,
      "y": 8,
      "z": 9,
      "name": "Rock_Shale_Brick_Smooth"
    },
    {
      "x": -12,
      "y": 9,
      "z": 9,
      "name": "Rock_Shale_Brick_Smooth"
    },
    {
      "x": -12,
      "y": 10,
      "z": 9,
      "name": "Rock_Shale_Brick_Smooth"
    },
    {
      "x": -12,
      "y": 11,
      "z": 9,
      "name": "Rock_Shale_Brick_Smooth"
    },
    {
      "x": -12,
      "y": 12,
      "z": 9,
      "name": "Rock_Shale_Brick_Smooth"
    },
    {
      "x": -12,
      "y": 13,
      "z": 9,
      "name": "Rock_Shale_Brick_Smooth"
    },
    {
      "x": -12,
      "y": 14,
      "z": 9,
      "name": "Rock_Shale_Brick_Ornate"
    },
    {
      "x": -12,
      "y": 15,
      "z": 9,
      "name": "Rock_Shale_Brick_Smooth"
    },
    {
      "x": -12,
      "y": 16,
      "z": 9,
      "name": "Rock_Shale_Brick_Smooth"
    },
    {
      "x": -12,
      "y": 17,
      "z": 9,
      "name": "Rock_Shale_Brick_Smooth"
    },
    {
      "x": -12,
      "y": 18,
      "z": 9,
      "name": "Rock_Shale_Brick_Smooth"
    },
    {
      "x": -12,
      "y": 19,
      "z": 9,
      "name": "Rock_Shale_Brick_Smooth"
    },
    {
      "x": -12,
      "y": 20,
      "z": 9,
      "name": "Rock_Shale_Brick_Smooth"
    },
    {
      "x": -12,
      "y": 21,
      "z": 9,
      "name": "Rock_Shale_Brick_Smooth"
    },
    {
      "x": -12,
      "y": 22,
      "z": 9,
      "name": "Rock_Shale_Brick_Smooth"
    },
    {
      "x": -12,
      "y": 23,
      "z": 9,
      "name": "Rock_Shale_Brick_Smooth"
    },
    {
      "x": -12,
      "y": 24,
      "z": 9,
      "name": "Rock_Shale_Brick_Smooth"
    },
    {
      "x": -12,
      "y": 25,
      "z": 9,
      "name": "Rock_Shale_Brick_Smooth"
    },
    {
      "x": -12,
      "y": 26,
      "z": 9,
      "name": "Rock_Shale_Brick_Smooth"
    },
    {
      "x": -12,
      "y": 27,
      "z": 9,
      "name": "Rock_Shale_Brick_Smooth"
    },
    {
      "x": -12,
      "y": 28,
      "z": 9,
      "name": "Rock_Shale_Brick_Smooth"
    },
    {
      "x": -12,
      "y": 29,
      "z": 9,
      "name": "Rock_Shale_Brick_Smooth"
    },
    {
      "x": -12,
      "y": 30,
      "z": 9,
      "name": "Rock_Shale_Brick_Smooth"
    },
    {
      "x": -12,
      "y": 31,
      "z": 9,
      "name": "Rock_Shale_Brick_Smooth"
    },
    {
      "x": -12,
      "y": 32,
      "z": 9,
      "name": "Rock_Shale_Brick_Smooth"
    },
    {
      "x": -12,
      "y": 33,
      "z": 9,
      "name": "Rock_Shale_Brick_Ornate"
    },
    {
      "x": -12,
      "y": 34,
      "z": 9,
      "name": "Rock_Shale_Brick_Smooth"
    },
    {
      "x": -12,
      "y": 35,
      "z": 9,
      "name": "Rock_Shale_Brick_Smooth"
    },
    {
      "x": -12,
      "y": 36,
      "z": 9,
      "name": "Rock_Shale_Brick_Smooth"
    },
    {
      "x": -12,
      "y": 37,
      "z": 9,
      "name": "Rock_Shale_Brick_Smooth"
    },
    {
      "x": -12,
      "y": 38,
      "z": 9,
      "name": "Rock_Shale_Brick_Ornate",
      "rotation": 1
    },
    {
      "x": -12,
      "y": 39,
      "z": 9,
      "name": "Rock_Shale_Brick"
    },
    {
      "x": -12,
      "y": 40,
      "z": 9,
      "name": "Rock_Shale_Brick_Smooth_Half",
      "rotation": 35
    },
    {
      "x": -12,
      "y": 41,
      "z": 9,
      "name": "Rock_Shale_Brick_Stairs",
      "rotation": 1
    },
    {
      "x": -12,
      "y": 50,
      "z": 9,
      "name": "*Rock_Shale_Brick_Roof_Steep_State_Definitions_Inverted_Corner_Right",
      "rotation": 3
    },
    {
      "x": -12,
      "y": 51,
      "z": 9,
      "name": "*Rock_Shale_Brick_Roof_Steep_State_Definitions_Inverted_Corner_Right",
      "filler": 1024,
      "rotation": 3
    },
    {
      "x": -12,
      "y": 0,
      "z": 10,
      "name": "Rock_Shale_Brick_Smooth"
    },
    {
      "x": -12,
      "y": 1,
      "z": 10,
      "name": "Rock_Shale_Brick_Smooth"
    },
    {
      "x": -12,
      "y": 2,
      "z": 10,
      "name": "Rock_Shale_Brick_Smooth"
    },
    {
      "x": -12,
      "y": 3,
      "z": 10,
      "name": "Rock_Shale_Brick_Smooth"
    },
    {
      "x": -12,
      "y": 4,
      "z": 10,
      "name": "Rock_Shale_Brick_Smooth"
    },
    {
      "x": -12,
      "y": 5,
      "z": 10,
      "name": "Rock_Shale_Brick_Smooth"
    },
    {
      "x": -12,
      "y": 6,
      "z": 10,
      "name": "Rock_Shale_Brick_Smooth"
    },
    {
      "x": -12,
      "y": 7,
      "z": 10,
      "name": "Rock_Shale_Brick_Smooth"
    },
    {
      "x": -12,
      "y": 8,
      "z": 10,
      "name": "Rock_Shale_Brick_Smooth"
    },
    {
      "x": -12,
      "y": 9,
      "z": 10,
      "name": "Rock_Shale_Brick_Smooth"
    },
    {
      "x": -12,
      "y": 10,
      "z": 10,
      "name": "Rock_Shale_Brick_Smooth"
    },
    {
      "x": -12,
      "y": 11,
      "z": 10,
      "name": "Rock_Shale_Brick_Smooth"
    },
    {
      "x": -12,
      "y": 12,
      "z": 10,
      "name": "Furniture_Temple_Dark_Window",
      "rotation": 1
    },
    {
      "x": -12,
      "y": 13,
      "z": 10,
      "name": "Furniture_Temple_Dark_Window",
      "rotation": 1
    },
    {
      "x": -12,
      "y": 14,
      "z": 10,
      "name": "Rock_Shale_Brick_Ornate"
    },
    {
      "x": -12,
      "y": 15,
      "z": 10,
      "name": "Rock_Shale_Brick_Smooth"
    },
    {
      "x": -12,
      "y": 16,
      "z": 10,
      "name": "Rock_Shale_Brick_Smooth_Half",
      "rotation": 7
    },
    {
      "x": -12,
      "y": 17,
      "z": 10,
      "name": "Rock_Shale_Brick_Smooth_Half",
      "rotation": 7
    },
    {
      "x": -12,
      "y": 18,
      "z": 10,
      "name": "Rock_Shale_Brick_Smooth"
    },
    {
      "x": -12,
      "y": 19,
      "z": 10,
      "name": "Rock_Shale_Brick_Smooth"
    },
    {
      "x": -12,
      "y": 20,
      "z": 10,
      "name": "Rock_Shale_Brick_Smooth"
    },
    {
      "x": -12,
      "y": 21,
      "z": 10,
      "name": "Rock_Shale_Brick_Smooth"
    },
    {
      "x": -12,
      "y": 22,
      "z": 10,
      "name": "Rock_Shale_Brick_Smooth"
    },
    {
      "x": -12,
      "y": 23,
      "z": 10,
      "name": "Rock_Shale_Brick_Smooth"
    },
    {
      "x": -12,
      "y": 24,
      "z": 10,
      "name": "Rock_Shale_Brick_Smooth"
    },
    {
      "x": -12,
      "y": 25,
      "z": 10,
      "name": "Rock_Shale_Brick_Smooth"
    },
    {
      "x": -12,
      "y": 26,
      "z": 10,
      "name": "Rock_Shale_Brick_Smooth"
    },
    {
      "x": -12,
      "y": 27,
      "z": 10,
      "name": "Rock_Shale_Brick_Smooth"
    },
    {
      "x": -12,
      "y": 28,
      "z": 10,
      "name": "Rock_Shale_Brick_Smooth"
    },
    {
      "x": -12,
      "y": 29,
      "z": 10,
      "name": "Rock_Shale_Brick_Smooth"
    },
    {
      "x": -12,
      "y": 30,
      "z": 10,
      "name": "Rock_Shale_Brick_Smooth"
    },
    {
      "x": -12,
      "y": 31,
      "z": 10,
      "name": "Furniture_Temple_Dark_Window",
      "rotation": 1
    },
    {
      "x": -12,
      "y": 32,
      "z": 10,
      "name": "Furniture_Temple_Dark_Window",
      "rotation": 1
    },
    {
      "x": -12,
      "y": 33,
      "z": 10,
      "name": "Rock_Shale_Brick_Ornate"
    },
    {
      "x": -12,
      "y": 34,
      "z": 10,
      "name": "Rock_Shale_Brick_Smooth"
    },
    {
      "x": -12,
      "y": 35,
      "z": 10,
      "name": "Rock_Shale_Brick_Smooth_Half",
      "rotation": 7
    },
    {
      "x": -12,
      "y": 36,
      "z": 10,
      "name": "Rock_Shale_Brick_Smooth_Half",
      "rotation": 7
    },
    {
      "x": -12,
      "y": 37,
      "z": 10,
      "name": "Rock_Shale_Brick_Smooth"
    },
    {
      "x": -12,
      "y": 38,
      "z": 10,
      "name": "Rock_Shale_Brick_Ornate",
      "rotation": 1
    },
    {
      "x": -12,
      "y": 39,
      "z": 10,
      "name": "Rock_Shale_Brick"
    },
    {
      "x": -12,
      "y": 40,
      "z": 10,
      "name": "Rock_Shale_Brick_Smooth_Half",
      "rotation": 35
    },
    {
      "x": -12,
      "y": 41,
      "z": 10,
      "name": "Rock_Shale_Brick_Stairs",
      "rotation": 1
    },
    {
      "x": -12,
      "y": 51,
      "z": 10,
      "name": "Rock_Shale_Brick_Half",
      "rotation": 33
    },
    {
      "x": -12,
      "y": 52,
      "z": 10,
      "name": "Rock_Shale_Brick_Pillar_Base",
      "rotation": 3
    },
    {
      "x": -12,
      "y": 53,
      "z": 10,
      "name": "Rock_Shale_Brick_Beam",
      "rotation": 3
    },
    {
      "x": -12,
      "y": 54,
      "z": 10,
      "name": "Rock_Shale_Brick_Beam",
      "rotation": 3
    },
    {
      "x": -12,
      "y": 0,
      "z": 11,
      "name": "Rock_Shale_Brick_Smooth"
    },
    {
      "x": -12,
      "y": 1,
      "z": 11,
      "name": "Rock_Shale_Brick_Smooth"
    },
    {
      "x": -12,
      "y": 2,
      "z": 11,
      "name": "Rock_Shale_Brick_Smooth"
    },
    {
      "x": -12,
      "y": 3,
      "z": 11,
      "name": "Rock_Shale_Brick_Smooth"
    },
    {
      "x": -12,
      "y": 4,
      "z": 11,
      "name": "Rock_Shale_Brick_Smooth"
    },
    {
      "x": -12,
      "y": 5,
      "z": 11,
      "name": "Rock_Shale_Brick_Smooth"
    },
    {
      "x": -12,
      "y": 6,
      "z": 11,
      "name": "Rock_Shale_Brick_Smooth"
    },
    {
      "x": -12,
      "y": 7,
      "z": 11,
      "name": "Rock_Shale_Brick_Smooth"
    },
    {
      "x": -12,
      "y": 8,
      "z": 11,
      "name": "Rock_Shale_Brick_Smooth"
    },
    {
      "x": -12,
      "y": 9,
      "z": 11,
      "name": "Rock_Shale_Brick_Smooth"
    },
    {
      "x": -12,
      "y": 10,
      "z": 11,
      "name": "Rock_Shale_Brick_Smooth"
    },
    {
      "x": -12,
      "y": 11,
      "z": 11,
      "name": "Rock_Shale_Brick_Smooth"
    },
    {
      "x": -12,
      "y": 12,
      "z": 11,
      "name": "Rock_Shale_Brick_Smooth"
    },
    {
      "x": -12,
      "y": 13,
      "z": 11,
      "name": "Rock_Shale_Brick_Smooth"
    },
    {
      "x": -12,
      "y": 14,
      "z": 11,
      "name": "Rock_Shale_Brick_Ornate"
    },
    {
      "x": -12,
      "y": 15,
      "z": 11,
      "name": "Rock_Shale_Brick_Smooth"
    },
    {
      "x": -12,
      "y": 16,
      "z": 11,
      "name": "Rock_Shale_Brick_Smooth"
    },
    {
      "x": -12,
      "y": 17,
      "z": 11,
      "name": "Rock_Shale_Brick_Smooth"
    },
    {
      "x": -12,
      "y": 18,
      "z": 11,
      "name": "Rock_Shale_Brick_Smooth"
    },
    {
      "x": -12,
      "y": 19,
      "z": 11,
      "name": "Rock_Shale_Brick_Smooth"
    },
    {
      "x": -12,
      "y": 20,
      "z": 11,
      "name": "Rock_Shale_Brick_Smooth"
    },
    {
      "x": -12,
      "y": 21,
      "z": 11,
      "name": "Rock_Shale_Brick_Smooth"
    },
    {
      "x": -12,
      "y": 22,
      "z": 11,
      "name": "Rock_Shale_Brick_Smooth"
    },
    {
      "x": -12,
      "y": 23,
      "z": 11,
      "name": "Rock_Shale_Brick_Smooth"
    },
    {
      "x": -12,
      "y": 24,
      "z": 11,
      "name": "Rock_Shale_Brick_Smooth"
    },
    {
      "x": -12,
      "y": 25,
