{
  "version": 8,
  "blockIdVersion": 11,
  "anchorX": 0,
  "anchorY": 0,
  "anchorZ": 0,
  "blocks": [
    {
      "x": -15,
      "y": 0,
      "z": -15,
      "name": "Soil_Dirt"
    },
    {
      "x": -15,
      "y": 1,
      "z": -15,
      "name": "Soil_Dirt"
    },
    {
      "x": -15,
      "y": 2,
      "z": -15,
      "name": "Soil_Dirt"
    },
    {
      "x": -15,
      "y": 3,
      "z": -15,
      "name": "Soil_Dirt"
    },
    {
      "x": -15,
      "y": 4,
      "z": -15,
      "name": "Soil_Dirt"
    },
    {
      "x": -15,
      "y": 5,
      "z": -15,
      "name": "Soil_Dirt"
    },
    {
      "x": -15,
      "y": 6,
      "z": -15,
      "name": "Soil_Dirt"
    },
    {
      "x": -15,
      "y": 7,
      "z": -15,
      "name": "Soil_Dirt"
    },
    {
      "x": -15,
      "y": 8,
      "z": -15,
      "name": "Soil_Grass"
    },
    {
      "x": -15,
      "y": 0,
      "z": -14,
      "name": "Soil_Dirt"
    },
    {
      "x": -15,
      "y": 1,
      "z": -14,
      "name": "Soil_Dirt"
    },
    {
      "x": -15,
      "y": 2,
      "z": -14,
      "name": "Soil_Dirt"
    },
    {
      "x": -15,
      "y": 3,
      "z": -14,
      "name": "Soil_Dirt"
    },
    {
      "x": -15,
      "y": 4,
      "z": -14,
      "name": "Soil_Dirt"
    },
    {
      "x": -15,
      "y": 5,
      "z": -14,
      "name": "Soil_Dirt"
    },
    {
      "x": -15,
      "y": 6,
      "z": -14,
      "name": "Soil_Dirt"
    },
    {
      "x": -15,
      "y": 7,
      "z": -14,
      "name": "Soil_Dirt"
    },
    {
      "x": -15,
      "y": 8,
      "z": -14,
      "name": "Soil_Dirt"
    },
    {
      "x": -15,
      "y": 9,
      "z": -14,
      "name": "Soil_Grass"
    },
    {
      "x": -15,
      "y": 10,
      "z": -14,
      "name": "Plant_Grass_Sharp_Overgrown",
      "support": 15
    },
    {
      "x": -15,
      "y": 11,
      "z": -14,
      "name": "Plant_Grass_Sharp_Overgrown",
      "filler": 1024
    },
    {
      "x": -15,
      "y": 0,
      "z": -13,
      "name": "Soil_Dirt"
    },
    {
      "x": -15,
      "y": 1,
      "z": -13,
      "name": "Soil_Dirt"
    },
    {
      "x": -15,
      "y": 2,
      "z": -13,
      "name": "Soil_Dirt"
    },
    {
      "x": -15,
      "y": 3,
      "z": -13,
      "name": "Soil_Dirt"
    },
    {
      "x": -15,
      "y": 4,
      "z": -13,
      "name": "Soil_Dirt"
    },
    {
      "x": -15,
      "y": 5,
      "z": -13,
      "name": "Soil_Dirt"
    },
    {
      "x": -15,
      "y": 6,
      "z": -13,
      "name": "Soil_Dirt"
    },
    {
      "x": -15,
      "y": 7,
      "z": -13,
      "name": "Soil_Dirt"
    },
    {
      "x": -15,
      "y": 8,
      "z": -13,
      "name": "Soil_Dirt"
    },
    {
      "x": -15,
      "y": 9,
      "z": -13,
      "name": "Soil_Grass"
    },
    {
      "x": -15,
      "y": 10,
      "z": -13,
      "name": "Plant_Grass_Sharp_Overgrown",
      "support": 15
    },
    {
      "x": -15,
      "y": 11,
      "z": -13,
      "name": "Plant_Grass_Sharp_Overgrown",
      "filler": 1024
    },
    {
      "x": -15,
      "y": 24,
      "z": -13,
      "name": "Rock_Shale_Brick_Smooth_Half",
      "rotation": 7
    },
    {
      "x": -15,
      "y": 25,
      "z": -13,
      "name": "Rock_Shale_Brick_Smooth_Half",
      "rotation": 7
    },
    {
      "x": -15,
      "y": 26,
      "z": -13,
      "name": "Rock_Shale_Brick_Smooth_Half",
      "rotation": 7
    },
    {
      "x": -15,
      "y": 43,
      "z": -13,
      "name": "Rock_Shale_Brick_Smooth_Half",
      "rotation": 7
    },
    {
      "x": -15,
      "y": 44,
      "z": -13,
      "name": "Rock_Shale_Brick_Smooth_Half",
      "rotation": 7
    },
    {
      "x": -15,
      "y": 45,
      "z": -13,
      "name": "Rock_Shale_Brick_Smooth_Half",
      "rotation": 7
    },
    {
      "x": -15,
      "y": 0,
      "z": -12,
      "name": "Soil_Dirt"
    },
    {
      "x": -15,
      "y": 1,
      "z": -12,
      "name": "Soil_Dirt"
    },
    {
      "x": -15,
      "y": 2,
      "z": -12,
      "name": "Soil_Dirt"
    },
    {
      "x": -15,
      "y": 3,
      "z": -12,
      "name": "Soil_Dirt"
    },
    {
      "x": -15,
      "y": 4,
      "z": -12,
      "name": "Soil_Dirt"
    },
    {
      "x": -15,
      "y": 5,
      "z": -12,
      "name": "Soil_Dirt"
    },
    {
      "x": -15,
      "y": 6,
      "z": -12,
      "name": "Soil_Dirt"
    },
    {
      "x": -15,
      "y": 7,
      "z": -12,
      "name": "Soil_Dirt"
    },
    {
      "x": -15,
      "y": 8,
      "z": -12,
      "name": "Soil_Dirt"
    },
    {
      "x": -15,
      "y": 9,
      "z": -12,
      "name": "Soil_Grass"
    },
    {
      "x": -15,
      "y": 23,
      "z": -12,
      "name": "Rock_Shale_Brick_Smooth_Half",
      "rotation": 7
    },
    {
      "x": -15,
      "y": 24,
      "z": -12,
      "name": "Rock_Shale_Brick_Smooth_Half",
      "rotation": 7
    },
    {
      "x": -15,
      "y": 25,
      "z": -12,
      "name": "Rock_Shale_Brick_Smooth_Half",
      "rotation": 7
    },
    {
      "x": -15,
      "y": 42,
      "z": -12,
      "name": "Rock_Shale_Brick_Smooth_Half",
      "rotation": 7
    },
    {
      "x": -15,
      "y": 43,
      "z": -12,
      "name": "Rock_Shale_Brick_Smooth_Half",
      "rotation": 7
    },
    {
      "x": -15,
      "y": 44,
      "z": -12,
      "name": "Rock_Shale_Brick_Smooth_Half",
      "rotation": 7
    },
    {
      "x": -15,
      "y": 0,
      "z": -11,
      "name": "Soil_Dirt"
    },
    {
      "x": -15,
      "y": 1,
      "z": -11,
      "name": "Soil_Dirt"
    },
    {
      "x": -15,
      "y": 2,
      "z": -11,
      "name": "Soil_Dirt"
    },
    {
      "x": -15,
      "y": 3,
      "z": -11,
      "name": "Soil_Dirt"
    },
    {
      "x": -15,
      "y": 4,
      "z": -11,
      "name": "Soil_Dirt"
    },
    {
      "x": -15,
      "y": 5,
      "z": -11,
      "name": "Soil_Dirt"
    },
    {
      "x": -15,
      "y": 6,
      "z": -11,
      "name": "Soil_Dirt"
    },
    {
      "x": -15,
      "y": 7,
      "z": -11,
      "name": "Soil_Dirt"
    },
    {
      "x": -15,
      "y": 8,
      "z": -11,
      "name": "Soil_Grass"
    },
    {
      "x": -15,
      "y": 22,
      "z": -11,
      "name": "Rock_Shale_Brick_Smooth_Half",
      "rotation": 7
    },
    {
      "x": -15,
      "y": 23,
      "z": -11,
      "name": "Rock_Shale_Brick_Smooth_Half",
      "rotation": 7
    },
    {
      "x": -15,
      "y": 24,
      "z": -11,
      "name": "Rock_Shale_Brick_Smooth_Half",
      "rotation": 7
    },
    {
      "x": -15,
      "y": 41,
      "z": -11,
      "name": "Rock_Shale_Brick_Smooth_Half",
      "rotation": 7
    },
    {
      "x": -15,
      "y": 42,
      "z": -11,
      "name": "Rock_Shale_Brick_Smooth_Half",
      "rotation": 7
    },
    {
      "x": -15,
      "y": 43,
      "z": -11,
      "name": "Rock_Shale_Brick_Smooth_Half",
      "rotation": 7
    },
    {
      "x": -15,
      "y": 0,
      "z": -10,
      "name": "Soil_Dirt"
    },
    {
      "x": -15,
      "y": 1,
      "z": -10,
      "name": "Soil_Dirt"
    },
    {
      "x": -15,
      "y": 2,
      "z": -10,
      "name": "Soil_Dirt"
    },
    {
      "x": -15,
      "y": 3,
      "z": -10,
      "name": "Soil_Dirt"
    },
    {
      "x": -15,
      "y": 4,
      "z": -10,
      "name": "Soil_Dirt"
    },
    {
      "x": -15,
      "y": 5,
      "z": -10,
      "name": "Soil_Dirt"
    },
    {
      "x": -15,
      "y": 6,
      "z": -10,
      "name": "Soil_Dirt"
    },
    {
      "x": -15,
      "y": 7,
      "z": -10,
      "name": "Soil_Dirt"
    },
    {
      "x": -15,
      "y": 8,
      "z": -10,
      "name": "Soil_Dirt"
    },
    {
      "x": -15,
      "y": 9,
      "z": -10,
      "name": "Soil_Grass"
    },
    {
      "x": -15,
      "y": 22,
      "z": -10,
      "name": "Rock_Shale_Brick_Smooth_Half",
      "rotation": 7
    },
    {
      "x": -15,
      "y": 23,
      "z": -10,
      "name": "Rock_Shale_Brick_Smooth_Half",
      "rotation": 7
    },
    {
      "x": -15,
      "y": 41,
      "z": -10,
      "name": "Rock_Shale_Brick_Smooth_Half",
      "rotation": 7
    },
    {
      "x": -15,
      "y": 42,
      "z": -10,
      "name": "Rock_Shale_Brick_Smooth_Half",
      "rotation": 7
    },
    {
      "x": -15,
      "y": 0,
      "z": -9,
      "name": "Soil_Dirt"
    },
    {
      "x": -15,
      "y": 1,
      "z": -9,
      "name": "Soil_Dirt"
    },
    {
      "x": -15,
      "y": 2,
      "z": -9,
      "name": "Soil_Dirt"
    },
    {
      "x": -15,
      "y": 3,
      "z": -9,
      "name": "Soil_Dirt"
    },
    {
      "x": -15,
      "y": 4,
      "z": -9,
      "name": "Soil_Dirt"
    },
    {
      "x": -15,
      "y": 5,
      "z": -9,
      "name": "Soil_Dirt"
    },
    {
      "x": -15,
      "y": 6,
      "z": -9,
      "name": "Soil_Dirt"
    },
    {
      "x": -15,
      "y": 7,
      "z": -9,
      "name": "Soil_Dirt"
    },
    {
      "x": -15,
      "y": 8,
      "z": -9,
      "name": "Soil_Dirt"
    },
    {
      "x": -15,
      "y": 9,
      "z": -9,
      "name": "Soil_Grass"
    },
    {
      "x": -15,
      "y": 10,
      "z": -9,
      "name": "Plant_Grass_Sharp_Tall",
      "support": 15
    },
    {
      "x": -15,
      "y": 11,
      "z": -9,
      "name": "Plant_Grass_Sharp_Tall",
      "filler": 1024
    },
    {
      "x": -15,
      "y": 21,
      "z": -9,
      "name": "Rock_Shale_Brick_Smooth_Half",
      "rotation": 7
    },
    {
      "x": -15,
      "y": 22,
      "z": -9,
      "name": "Rock_Shale_Brick_Smooth_Half",
      "rotation": 7
    },
    {
      "x": -15,
      "y": 40,
      "z": -9,
      "name": "Rock_Shale_Brick_Smooth_Half",
      "rotation": 7
    },
    {
      "x": -15,
      "y": 41,
      "z": -9,
      "name": "Rock_Shale_Brick_Smooth_Half",
      "rotation": 7
    },
    {
      "x": -15,
      "y": 0,
      "z": -8,
      "name": "Soil_Dirt"
    },
    {
      "x": -15,
      "y": 1,
      "z": -8,
      "name": "Soil_Dirt"
    },
    {
      "x": -15,
      "y": 2,
      "z": -8,
      "name": "Soil_Dirt"
    },
    {
      "x": -15,
      "y": 3,
      "z": -8,
      "name": "Soil_Dirt"
    },
    {
      "x": -15,
      "y": 4,
      "z": -8,
      "name": "Soil_Dirt"
    },
    {
      "x": -15,
      "y": 5,
      "z": -8,
      "name": "Soil_Dirt"
    },
    {
      "x": -15,
      "y": 6,
      "z": -8,
      "name": "Soil_Dirt"
    },
    {
      "x": -15,
      "y": 7,
      "z": -8,
      "name": "Soil_Dirt"
    },
    {
      "x": -15,
      "y": 8,
      "z": -8,
      "name": "Soil_Grass"
    },
    {
      "x": -15,
      "y": 0,
      "z": -7,
      "name": "Soil_Dirt"
    },
    {
      "x": -15,
      "y": 1,
      "z": -7,
      "name": "Soil_Dirt"
    },
    {
      "x": -15,
      "y": 2,
      "z": -7,
      "name": "Soil_Dirt"
    },
    {
      "x": -15,
      "y": 3,
      "z": -7,
      "name": "Soil_Dirt"
    },
    {
      "x": -15,
      "y": 4,
      "z": -7,
      "name": "Soil_Dirt"
    },
    {
      "x": -15,
      "y": 5,
      "z": -7,
      "name": "Soil_Dirt"
    },
    {
      "x": -15,
      "y": 6,
      "z": -7,
      "name": "Soil_Dirt"
    },
    {
      "x": -15,
      "y": 7,
      "z": -7,
      "name": "Soil_Dirt"
    },
    {
      "x": -15,
      "y": 8,
      "z": -7,
      "name": "Soil_Grass"
    },
    {
      "x": -15,
      "y": 0,
      "z": -6,
      "name": "Soil_Dirt"
    },
    {
      "x": -15,
      "y": 1,
      "z": -6,
      "name": "Soil_Dirt"
    },
    {
      "x": -15,
      "y": 2,
      "z": -6,
      "name": "Soil_Dirt"
    },
    {
      "x": -15,
      "y": 3,
      "z": -6,
      "name": "Soil_Dirt"
    },
    {
      "x": -15,
      "y": 4,
      "z": -6,
      "name": "Soil_Dirt"
    },
    {
      "x": -15,
      "y": 5,
      "z": -6,
      "name": "Soil_Dirt"
    },
    {
      "x": -15,
      "y": 6,
      "z": -6,
      "name": "Soil_Dirt"
    },
    {
      "x": -15,
      "y": 7,
      "z": -6,
      "name": "Soil_Dirt"
    },
    {
      "x": -15,
      "y": 8,
      "z": -6,
      "name": "Soil_Grass"
    },
    {
      "x": -15,
      "y": 0,
      "z": -5,
      "name": "Soil_Dirt"
    },
    {
      "x": -15,
      "y": 1,
      "z": -5,
      "name": "Soil_Dirt"
    },
    {
      "x": -15,
      "y": 2,
      "z": -5,
      "name": "Soil_Dirt"
    },
    {
      "x": -15,
      "y": 3,
      "z": -5,
      "name": "Soil_Dirt"
    },
    {
      "x": -15,
      "y": 4,
      "z": -5,
      "name": "Soil_Dirt"
    },
    {
      "x": -15,
      "y": 5,
      "z": -5,
      "name": "Soil_Dirt"
    },
    {
      "x": -15,
      "y": 6,
      "z": -5,
      "name": "Soil_Dirt"
    },
    {
      "x": -15,
      "y": 7,
      "z": -5,
      "name": "Soil_Dirt"
    },
    {
      "x": -15,
      "y": 8,
      "z": -5,
      "name": "Soil_Grass"
    },
    {
      "x": -15,
      "y": 0,
      "z": -4,
      "name": "Soil_Dirt"
    },
    {
      "x": -15,
      "y": 1,
      "z": -4,
      "name": "Soil_Dirt"
    },
    {
      "x": -15,
      "y": 2,
      "z": -4,
      "name": "Soil_Dirt"
    },
    {
      "x": -15,
      "y": 3,
      "z": -4,
      "name": "Soil_Dirt"
    },
    {
      "x": -15,
      "y": 4,
      "z": -4,
      "name": "Soil_Dirt"
    },
    {
      "x": -15,
      "y": 5,
      "z": -4,
      "name": "Soil_Dirt"
    },
    {
      "x": -15,
      "y": 6,
      "z": -4,
      "name": "Soil_Dirt"
    },
    {
      "x": -15,
      "y": 7,
      "z": -4,
      "name": "Soil_Dirt"
    },
    {
      "x": -15,
      "y": 8,
      "z": -4,
      "name": "Soil_Grass"
    },
    {
      "x": -15,
      "y": 0,
      "z": -3,
      "name": "Soil_Dirt"
    },
    {
      "x": -15,
      "y": 1,
      "z": -3,
      "name": "Soil_Dirt"
    },
    {
      "x": -15,
      "y": 2,
      "z": -3,
      "name": "Soil_Dirt"
    },
    {
      "x": -15,
      "y": 3,
      "z": -3,
      "name": "Soil_Dirt"
    },
    {
      "x": -15,
      "y": 4,
      "z": -3,
      "name": "Soil_Dirt"
    },
    {
      "x": -15,
      "y": 5,
      "z": -3,
      "name": "Soil_Dirt"
    },
    {
      "x": -15,
      "y": 6,
      "z": -3,
      "name": "Soil_Dirt"
    },
    {
      "x": -15,
      "y": 7,
      "z": -3,
      "name": "Soil_Dirt"
    },
    {
      "x": -15,
      "y": 8,
      "z": -3,
      "name": "Soil_Dirt"
    },
    {
      "x": -15,
      "y": 9,
      "z": -3,
      "name": "Soil_Grass"
    },
    {
      "x": -15,
      "y": 0,
      "z": -2,
      "name": "Soil_Dirt"
    },
    {
      "x": -15,
      "y": 1,
      "z": -2,
      "name": "Soil_Dirt"
    },
    {
      "x": -15,
      "y": 2,
      "z": -2,
      "name": "Soil_Dirt"
    },
    {
      "x": -15,
      "y": 3,
      "z": -2,
      "name": "Soil_Dirt"
    },
    {
      "x": -15,
      "y": 4,
      "z": -2,
      "name": "Soil_Dirt"
    },
    {
      "x": -15,
      "y": 5,
      "z": -2,
      "name": "Soil_Dirt"
    },
    {
      "x": -15,
      "y": 6,
      "z": -2,
      "name": "Soil_Dirt"
    },
    {
      "x": -15,
      "y": 7,
      "z": -2,
      "name": "Soil_Dirt"
    },
    {
      "x": -15,
      "y": 8,
      "z": -2,
      "name": "Soil_Dirt"
    },
    {
      "x": -15,
      "y": 9,
      "z": -2,
      "name": "Soil_Grass"
    },
    {
      "x": -15,
      "y": 0,
      "z": -1,
      "name": "Soil_Dirt"
    },
    {
      "x": -15,
      "y": 1,
      "z": -1,
      "name": "Soil_Dirt"
    },
    {
      "x": -15,
      "y": 2,
      "z": -1,
      "name": "Soil_Dirt"
    },
    {
      "x": -15,
      "y": 3,
      "z": -1,
      "name": "Soil_Dirt"
    },
    {
      "x": -15,
      "y": 4,
      "z": -1,
      "name": "Soil_Dirt"
    },
    {
      "x": -15,
      "y": 5,
      "z": -1,
      "name": "Soil_Dirt"
    },
    {
      "x": -15,
      "y": 6,
      "z": -1,
      "name": "Soil_Dirt"
    },
    {
      "x": -15,
      "y": 7,
      "z": -1,
      "name": "Soil_Dirt"
    },
    {
      "x": -15,
      "y": 8,
      "z": -1,
      "name": "Soil_Dirt"
    },
    {
      "x": -15,
      "y": 9,
      "z": -1,
      "name": "Soil_Grass"
    },
    {
      "x": -15,
      "y": 10,
      "z": -1,
      "name": "Plant_Grass_Sharp_Overgrown",
      "support": 15
    },
    {
      "x": -15,
      "y": 11,
      "z": -1,
      "name": "Plant_Grass_Sharp_Overgrown",
      "filler": 1024
    },
    {
      "x": -15,
      "y": 0,
      "z": 0,
      "name": "Soil_Dirt"
    },
    {
      "x": -15,
      "y": 1,
      "z": 0,
      "name": "Soil_Dirt"
    },
    {
      "x": -15,
      "y": 2,
      "z": 0,
      "name": "Soil_Dirt"
    },
    {
      "x": -15,
      "y": 3,
      "z": 0,
      "name": "Soil_Dirt"
    },
    {
      "x": -15,
      "y": 4,
      "z": 0,
      "name": "Soil_Dirt"
    },
    {
      "x": -15,
      "y": 5,
      "z": 0,
      "name": "Soil_Dirt"
    },
    {
      "x": -15,
      "y": 6,
      "z": 0,
      "name": "Soil_Dirt"
    },
    {
      "x": -15,
      "y": 7,
      "z": 0,
      "name": "Soil_Dirt"
    },
    {
      "x": -15,
      "y": 8,
      "z": 0,
      "name": "Soil_Dirt"
    },
    {
      "x": -15,
      "y": 9,
      "z": 0,
      "name": "Soil_Dirt"
    },
    {
      "x": -15,
      "y": 10,
      "z": 0,
      "name": "Soil_Grass"
    },
    {
      "x": -15,
      "y": 0,
      "z": 1,
      "name": "Soil_Dirt"
    },
    {
      "x": -15,
      "y": 1,
      "z": 1,
      "name": "Soil_Dirt"
    },
    {
      "x": -15,
      "y": 2,
      "z": 1,
      "name": "Soil_Dirt"
    },
    {
      "x": -15,
      "y": 3,
      "z": 1,
      "name": "Soil_Dirt"
    },
    {
      "x": -15,
      "y": 4,
      "z": 1,
      "name": "Soil_Dirt"
    },
    {
      "x": -15,
      "y": 5,
      "z": 1,
      "name": "Soil_Dirt"
    },
    {
      "x": -15,
      "y": 6,
      "z": 1,
      "name": "Soil_Dirt"
    },
    {
      "x": -15,
      "y": 7,
      "z": 1,
      "name": "Soil_Dirt"
    },
    {
      "x": -15,
      "y": 8,
      "z": 1,
      "name": "Soil_Grass"
    },
    {
      "x": -15,
      "y": 0,
      "z": 2,
      "name": "Soil_Dirt"
    },
    {
      "x": -15,
      "y": 1,
      "z": 2,
      "name": "Soil_Dirt"
    },
    {
      "x": -15,
      "y": 2,
      "z": 2,
      "name": "Soil_Dirt"
    },
    {
      "x": -15,
      "y": 3,
      "z": 2,
      "name": "Soil_Dirt"
    },
    {
      "x": -15,
      "y": 4,
      "z": 2,
      "name": "Soil_Dirt"
    },
    {
      "x": -15,
      "y": 5,
      "z": 2,
      "name": "Soil_Dirt"
    },
    {
      "x": -15,
      "y": 6,
      "z": 2,
      "name": "Soil_Dirt"
    },
    {
      "x": -15,
      "y": 7,
      "z": 2,
      "name": "Soil_Dirt"
    },
    {
      "x": -15,
      "y": 8,
      "z": 2,
      "name": "Soil_Grass"
    },
    {
      "x": -15,
      "y": 0,
      "z": 3,
      "name": "Soil_Dirt"
    },
    {
      "x": -15,
      "y": 1,
      "z": 3,
      "name": "Soil_Dirt"
    },
    {
      "x": -15,
      "y": 2,
      "z": 3,
      "name": "Soil_Dirt"
    },
    {
      "x": -15,
      "y": 3,
      "z": 3,
      "name": "Soil_Dirt"
    },
    {
      "x": -15,
      "y": 4,
      "z": 3,
      "name": "Soil_Dirt"
    },
    {
      "x": -15,
      "y": 5,
      "z": 3,
      "name": "Soil_Dirt"
    },
    {
      "x": -15,
      "y": 6,
      "z": 3,
      "name": "Soil_Dirt"
    },
    {
      "x": -15,
      "y": 7,
      "z": 3,
      "name": "Soil_Dirt"
    },
    {
      "x": -15,
      "y": 8,
      "z": 3,
      "name": "Soil_Grass"
    },
    {
      "x": -15,
      "y": 9,
      "z": 3,
      "name": "Plant_Grass_Jungle_Tall",
      "support": 15
    },
    {
      "x": -15,
      "y": 0,
      "z": 4,
      "name": "Soil_Dirt"
    },
    {
      "x": -15,
      "y": 1,
      "z": 4,
      "name": "Soil_Dirt"
    },
    {
      "x": -15,
      "y": 2,
      "z": 4,
      "name": "Soil_Dirt"
    },
    {
      "x": -15,
      "y": 3,
      "z": 4,
      "name": "Soil_Dirt"
    },
    {
      "x": -15,
      "y": 4,
      "z": 4,
      "name": "Soil_Dirt"
    },
    {
      "x": -15,
      "y": 5,
      "z": 4,
      "name": "Soil_Dirt"
    },
    {
      "x": -15,
      "y": 6,
      "z": 4,
      "name": "Soil_Dirt"
    },
    {
      "x": -15,
      "y": 7,
      "z": 4,
      "name": "Soil_Dirt"
    },
    {
      "x": -15,
      "y": 8,
      "z": 4,
      "name": "Soil_Dirt"
    },
    {
      "x": -15,
      "y": 9,
      "z": 4,
      "name": "Soil_Grass"
    },
    {
      "x": -15,
      "y": 10,
      "z": 4,
      "name": "Plant_Grass_Jungle_Tall",
      "support": 15
    },
    {
      "x": -15,
      "y": 0,
      "z": 5,
      "name": "Soil_Dirt"
    },
    {
      "x": -15,
      "y": 1,
      "z": 5,
      "name": "Soil_Dirt"
    },
    {
      "x": -15,
      "y": 2,
      "z": 5,
      "name": "Soil_Dirt"
    },
    {
      "x": -15,
      "y": 3,
      "z": 5,
      "name": "Soil_Dirt"
    },
    {
      "x": -15,
      "y": 4,
      "z": 5,
      "name": "Soil_Dirt"
    },
    {
      "x": -15,
      "y": 5,
      "z": 5,
      "name": "Soil_Dirt"
    },
    {
      "x": -15,
      "y": 6,
      "z": 5,
      "name": "Soil_Dirt"
    },
    {
      "x": -15,
      "y": 7,
      "z": 5,
      "name": "Soil_Dirt"
    },
    {
      "x": -15,
      "y": 8,
      "z": 5,
      "name": "Soil_Dirt"
    },
    {
      "x": -15,
      "y": 9,
      "z": 5,
      "name": "Soil_Grass"
    },
    {
      "x": -15,
      "y": 0,
      "z": 6,
      "name": "Soil_Dirt"
    },
    {
      "x": -15,
      "y": 1,
      "z": 6,
      "name": "Soil_Dirt"
    },
    {
      "x": -15,
      "y": 2,
      "z": 6,
      "name": "Soil_Dirt"
    },
    {
      "x": -15,
      "y": 3,
      "z": 6,
      "name": "Soil_Dirt"
    },
    {
      "x": -15,
      "y": 4,
      "z": 6,
      "name": "Soil_Dirt"
    },
    {
      "x": -15,
      "y": 5,
      "z": 6,
      "name": "Soil_Dirt"
    },
    {
      "x": -15,
      "y": 6,
      "z": 6,
      "name": "Soil_Dirt"
    },
    {
      "x": -15,
      "y": 7,
      "z": 6,
      "name": "Soil_Dirt"
    },
    {
      "x": -15,
      "y": 8,
      "z": 6,
      "name": "Soil_Dirt"
    },
    {
      "x": -15,
      "y": 9,
      "z": 6,
      "name": "Soil_Grass"
    },
    {
      "x": -15,
      "y": 0,
      "z": 7,
      "name": "Soil_Dirt"
    },
    {
      "x": -15,
      "y": 1,
      "z": 7,
      "name": "Soil_Dirt"
    },
    {
      "x": -15,
      "y": 2,
      "z": 7,
      "name": "Soil_Dirt"
    },
    {
      "x": -15,
      "y": 3,
      "z": 7,
      "name": "Soil_Dirt"
    },
    {
      "x": -15,
      "y": 4,
      "z": 7,
      "name": "Soil_Dirt"
    },
    {
      "x": -15,
      "y": 5,
      "z": 7,
      "name": "Soil_Dirt"
    },
    {
      "x": -15,
      "y": 6,
      "z": 7,
      "name": "Soil_Dirt"
    },
    {
      "x": -15,
      "y": 7,
      "z": 7,
      "name": "Soil_Dirt"
    },
    {
      "x": -15,
      "y": 8,
      "z": 7,
      "name": "Soil_Dirt"
    },
    {
      "x": -15,
      "y": 9,
      "z": 7,
      "name": "Soil_Grass"
    },
    {
      "x": -15,
      "y": 0,
      "z": 8,
      "name": "Soil_Dirt"
    },
    {
      "x": -15,
      "y": 1,
      "z": 8,
      "name": "Soil_Dirt"
    },
    {
      "x": -15,
      "y": 2,
      "z": 8,
      "name": "Soil_Dirt"
    },
    {
      "x": -15,
      "y": 3,
      "z": 8,
      "name": "Soil_Dirt"
    },
    {
      "x": -15,
      "y": 4,
      "z": 8,
      "name": "Soil_Dirt"
    },
    {
      "x": -15,
      "y": 5,
      "z": 8,
      "name": "Soil_Dirt"
    },
    {
      "x": -15,
      "y": 6,
      "z": 8,
      "name": "Soil_Dirt"
    },
    {
      "x": -15,
      "y": 7,
      "z": 8,
      "name": "Soil_Dirt"
    },
    {
      "x": -15,
      "y": 8,
      "z": 8,
      "name": "Soil_Grass"
    },
    {
      "x": -15,
      "y": 0,
      "z": 9,
      "name": "Soil_Dirt"
    },
    {
      "x": -15,
      "y": 1,
      "z": 9,
      "name": "Soil_Dirt"
    },
    {
      "x": -15,
      "y": 2,
      "z": 9,
      "name": "Soil_Dirt"
    },
    {
      "x": -15,
      "y": 3,
      "z": 9,
      "name": "Soil_Dirt"
    },
    {
      "x": -15,
      "y": 4,
      "z": 9,
      "name": "Soil_Dirt"
    },
    {
      "x": -15,
      "y": 5,
      "z": 9,
      "name": "Soil_Dirt"
    },
    {
      "x": -15,
      "y": 6,
      "z": 9,
      "name": "Soil_Dirt"
    },
    {
      "x": -15,
      "y": 7,
      "z": 9,
      "name": "Soil_Dirt"
    },
    {
      "x": -15,
      "y": 8,
      "z": 9,
      "name": "Soil_Grass"
    },
    {
      "x": -15,
      "y": 21,
      "z": 9,
      "name": "Rock_Shale_Brick_Smooth_Half",
      "rotation": 7
    },
    {
      "x": -15,
      "y": 22,
      "z": 9,
      "name": "Rock_Shale_Brick_Smooth_Half",
      "rotation": 7
    },
    {
      "x": -15,
      "y": 40,
      "z": 9,
      "name": "Rock_Shale_Brick_Smooth_Half",
      "rotation": 7
    },
    {
      "x": -15,
      "y": 41,
      "z": 9,
      "name": "Rock_Shale_Brick_Smooth_Half",
      "rotation": 7
    },
    {
      "x": -15,
      "y": 0,
      "z": 10,
      "name": "Soil_Dirt"
    },
    {
      "x": -15,
      "y": 1,
      "z": 10,
      "name": "Soil_Dirt"
    },
    {
      "x": -15,
      "y": 2,
      "z": 10,
      "name": "Soil_Dirt"
    },
    {
      "x": -15,
      "y": 3,
      "z": 10,
      "name": "Soil_Dirt"
    },
    {
      "x": -15,
      "y": 4,
      "z": 10,
      "name": "Soil_Dirt"
    },
    {
      "x": -15,
      "y": 5,
      "z": 10,
      "name": "Soil_Dirt"
    },
    {
      "x": -15,
      "y": 6,
      "z": 10,
      "name": "Soil_Dirt"
    },
    {
      "x": -15,
      "y": 7,
      "z": 10,
      "name": "Soil_Dirt"
    },
    {
      "x": -15,
      "y": 8,
      "z": 10,
      "name": "Soil_Grass"
    },
    {
      "x": -15,
      "y": 9,
      "z": 10,
      "name": "Plant_Grass_Jungle_Tall",
      "support": 15
    },
    {
      "x": -15,
      "y": 22,
      "z": 10,
      "name": "Rock_Shale_Brick_Smooth_Half",
      "rotation": 7
    },
    {
      "x": -15,
      "y": 23,
      "z": 10,
      "name": "Rock_Shale_Brick_Smooth_Half",
      "rotation": 7
    },
    {
      "x": -15,
      "y": 41,
      "z": 10,
      "name": "Rock_Shale_Brick_Smooth_Half",
      "rotation": 7
    },
    {
      "x": -15,
      "y": 42,
      "z": 10,
      "name": "Rock_Shale_Brick_Smooth_Half",
      "rotation": 7
    },
    {
      "x": -15,
      "y": 0,
      "z": 11,
      "name": "Soil_Dirt"
    },
    {
      "x": -15,
      "y": 1,
      "z": 11,
      "name": "Soil_Dirt"
    },
    {
      "x": -15,
      "y": 2,
      "z": 11,
      "name": "Soil_Dirt"
    },
    {
      "x": -15,
      "y": 3,
      "z": 11,
      "name": "Soil_Dirt"
    },
    {
      "x": -15,
      "y": 4,
      "z": 11,
      "name": "Soil_Dirt"
    },
    {
      "x": -15,
      "y": 5,
      "z": 11,
      "name": "Soil_Dirt"
    },
    {
      "x": -15,
      "y": 6,
      "z": 11,
      "name": "Soil_Dirt"
    },
    {
      "x": -15,
      "y": 7,
      "z": 11,
      "name": "Soil_Dirt"
    },
    {
      "x": -15,
      "y": 8,
      "z": 11,
      "name": "Soil_Dirt"
    },
    {
      "x": -15,
      "y": 9,
      "z": 11,
      "name": "Soil_Grass"
    },
    {
      "x": -15,
      "y": 10,
      "z": 11,
      "name": "Plant_Grass_Jungle_Tall",
      "support": 15
    },
    {
      "x": -15,
      "y": 22,
      "z": 11,
      "name": "Rock_Shale_Brick_Smooth_Half",
      "rotation": 7
    },
    {
      "x": -15,
      "y": 23,
      "z": 11,
      "name": "Rock_Shale_Brick_Smooth_Half",
      "rotation": 7
    },
    {
      "x": -15,
      "y": 24,
      "z": 11,
      "name": "Rock_Shale_Brick_Smooth_Half",
      "rotation": 7
    },
    {
      "x": -15,
      "y": 41,
      "z": 11,
      "name": "Rock_Shale_Brick_Smooth_Half",
      "rotation": 7
    },
    {
      "x": -15,
      "y": 42,
      "z": 11,
      "name": "Rock_Shale_Brick_Smooth_Half",
      "rotation": 7
    },
    {
      "x": -15,
      "y": 43,
      "z": 11,
      "name": "Rock_Shale_Brick_Smooth_Half",
      "rotation": 7
    },
    {
      "x": -15,
      "y": 0,
      "z": 12,
      "name": "Soil_Dirt"
    },
    {
      "x": -15,
      "y": 1,
      "z": 12,
      "name": "Soil_Dirt"
    },
    {
      "x": -15,
      "y": 2,
      "z": 12,
      "name": "Soil_Dirt"
    },
    {
      "x": -15,
      "y": 3,
      "z": 12,
      "name": "Soil_Dirt"
    },
    {
      "x": -15,
      "y": 4,
      "z": 12,
      "name": "Soil_Dirt"
    },
    {
      "x": -15,
      "y": 5,
      "z": 12,
      "name": "Soil_Dirt"
    },
    {
      "x": -15,
      "y": 6,
      "z": 12,
      "name": "Soil_Dirt"
    },
    {
      "x": -15,
      "y": 7,
      "z": 12,
      "name": "Soil_Dirt"
    },
    {
      "x": -15,
      "y": 8,
      "z": 12,
      "name": "Soil_Dirt"
    },
    {
      "x": -15,
      "y": 9,
      "z": 12,
      "name": "Soil_Grass"
    },
    {
      "x": -15,
      "y": 10,
      "z": 12,
      "name": "Plant_Grass_Sharp_Tall",
      "support": 15
    },
    {
      "x": -15,
      "y": 11,
      "z": 12,
      "name": "Plant_Grass_Sharp_Tall",
      "filler": 1024
    },
    {
      "x": -15,
      "y": 23,
      "z": 12,
      "name": "Rock_Shale_Brick_Smooth_Half",
      "rotation": 7
    },
    {
      "x": -15,
      "y": 24,
      "z": 12,
      "name": "Rock_Shale_Brick_Smooth_Half",
      "rotation": 7
    },
    {
      "x": -15,
      "y": 25,
      "z": 12,
      "name": "Rock_Shale_Brick_Smooth_Half",
      "rotation": 7
    },
    {
      "x": -15,
      "y": 42,
      "z": 12,
      "name": "Rock_Shale_Brick_Smooth_Half",
      "rotation": 7
    },
    {
      "x": -15,
      "y": 43,
      "z": 12,
      "name": "Rock_Shale_Brick_Smooth_Half",
      "rotation": 7
    },
    {
      "x": -15,
      "y": 44,
      "z": 12,
      "name": "Rock_Shale_Brick_Smooth_Half",
      "rotation": 7
    },
    {
      "x": -15,
      "y": 0,
      "z": 13,
      "name": "Soil_Dirt"
    },
    {
      "x": -15,
      "y": 1,
      "z": 13,
      "name": "Soil_Dirt"
    },
    {
      "x": -15,
      "y": 2,
      "z": 13,
      "name": "Soil_Dirt"
    },
    {
      "x": -15,
      "y": 3,
      "z": 13,
      "name": "Soil_Dirt"
    },
    {
      "x": -15,
      "y": 4,
      "z": 13,
      "name": "Soil_Dirt"
    },
    {
      "x": -15,
      "y": 5,
      "z": 13,
      "name": "Soil_Dirt"
    },
    {
      "x": -15,
      "y": 6,
      "z": 13,
      "name": "Soil_Dirt"
    },
    {
      "x": -15,
      "y": 7,
      "z": 13,
      "name": "Soil_Dirt"
    },
    {
      "x": -15,
      "y": 8,
      "z": 13,
      "name": "Soil_Grass"
    },
    {
      "x": -15,
      "y": 24,
      "z": 13,
      "name": "Rock_Shale_Brick_Smooth_Half",
      "rotation": 7
    },
    {
      "x": -15,
      "y": 25,
      "z": 13,
      "name": "Rock_Shale_Brick_Smooth_Half",
      "rotation": 7
    },
    {
      "x": -15,
      "y": 26,
      "z": 13,
      "name": "Rock_Shale_Brick_Smooth_Half",
      "rotation": 7
    },
    {
      "x": -15,
      "y": 43,
      "z": 13,
      "name": "Rock_Shale_Brick_Smooth_Half",
      "rotation": 7
    },
    {
      "x": -15,
      "y": 44,
      "z": 13,
      "name": "Rock_Shale_Brick_Smooth_Half",
      "rotation": 7
    },
    {
      "x": -15,
      "y": 45,
      "z": 13,
      "name": "Rock_Shale_Brick_Smooth_Half",
      "rotation": 7
    },
    {
      "x": -15,
      "y": 0,
      "z": 14,
      "name": "Soil_Dirt"
    },
    {
      "x": -15,
      "y": 1,
      "z": 14,
      "name": "Soil_Dirt"
    },
    {
      "x": -15,
      "y": 2,
      "z": 14,
      "name": "Soil_Dirt"
    },
    {
      "x": -15,
      "y": 3,
      "z": 14,
      "name": "Soil_Dirt"
    },
    {
      "x": -15,
      "y": 4,
      "z": 14,
      "name": "Soil_Dirt"
    },
    {
      "x": -15,
      "y": 5,
      "z": 14,
      "name": "Soil_Dirt"
    },
    {
      "x": -15,
      "y": 6,
      "z": 14,
      "name": "Soil_Dirt"
    },
    {
      "x": -15,
      "y": 7,
      "z": 14,
      "name": "Soil_Grass"
    },
    {
      "x": -15,
      "y": 0,
      "z": 15,
      "name": "Soil_Dirt"
    },
    {
      "x": -15,
      "y": 1,
      "z": 15,
      "name": "Soil_Dirt"
    },
    {
      "x": -15,
      "y": 2,
      "z": 15,
      "name": "Soil_Dirt"
    },
    {
      "x": -15,
      "y": 3,
      "z": 15,
      "name": "Soil_Dirt"
    },
    {
      "x": -15,
      "y": 4,
      "z": 15,
      "name": "Soil_Dirt"
    },
    {
      "x": -15,
      "y": 5,
      "z": 15,
      "name": "Soil_Dirt"
    },
    {
      "x": -15,
      "y": 6,
      "z": 15,
      "name": "Soil_Grass"
    },
    {
      "x": -14,
      "y": 0,
      "z": -15,
      "name": "Soil_Dirt"
    },
    {
      "x": -14,
      "y": 1,
      "z": -15,
      "name": "Soil_Dirt"
    },
    {
      "x": -14,
      "y": 2,
      "z": -15,
      "name": "Soil_Dirt"
    },
    {
      "x": -14,
      "y": 3,
      "z": -15,
      "name": "Soil_Dirt"
    },
    {
      "x": -14,
      "y": 4,
      "z": -15,
      "name": "Soil_Dirt"
    },
    {
      "x": -14,
      "y": 5,
      "z": -15,
      "name": "Soil_Dirt"
    },
    {
      "x": -14,
      "y": 6,
      "z": -15,
      "name": "Soil_Dirt"
    },
    {
      "x": -14,
      "y": 7,
      "z": -15,
      "name": "Soil_Dirt"
    },
    {
      "x": -14,
      "y": 8,
      "z": -15,
      "name": "Soil_Dirt"
    },
    {
      "x": -14,
      "y": 9,
      "z": -15,
      "name": "Soil_Grass"
    },
    {
      "x": -14,
      "y": 0,
      "z": -14,
      "name": "Soil_Dirt"
    },
    {
      "x": -14,
      "y": 1,
      "z": -14,
      "name": "Soil_Dirt"
    },
    {
      "x": -14,
      "y": 2,
      "z": -14,
      "name": "Soil_Dirt"
    },
    {
      "x": -14,
      "y": 3,
      "z": -14,
      "name": "Soil_Dirt"
    },
    {
      "x": -14,
      "y": 4,
      "z": -14,
      "name": "Soil_Dirt"
    },
    {
      "x": -14,
      "y": 5,
      "z": -14,
      "name": "Soil_Dirt"
    },
    {
      "x": -14,
      "y": 6,
      "z": -14,
      "name": "Soil_Dirt"
    },
    {
      "x": -14,
      "y": 7,
      "z": -14,
      "name": "Soil_Dirt"
    },
    {
      "x": -14,
      "y": 8,
      "z": -14,
      "name": "Soil_Dirt"
    },
    {
      "x": -14,
      "y": 9,
      "z": -14,
      "name": "Soil_Grass"
    },
    {
      "x": -14,
      "y": 10,
      "z": -14,
      "name": "Plant_Grass_Sharp_Tall",
      "support": 15
    },
    {
      "x": -14,
      "y": 11,
      "z": -14,
      "name": "Plant_Grass_Sharp_Tall",
      "filler": 1024
    },
    {
      "x": -14,
      "y": 24,
      "z": -14,
      "name": "Rock_Shale_Brick_Stairs",
      "rotation": 24
    },
    {
      "x": -14,
      "y": 25,
      "z": -14,
      "name": "Rock_Shale_Brick_Stairs",
      "rotation": 24
    },
    {
      "x": -14,
      "y": 26,
      "z": -14,
      "name": "Rock_Shale_Brick_Stairs",
      "rotation": 24
    },
    {
      "x": -14,
      "y": 27,
      "z": -14,
      "name": "Rock_Shale_Brick_Stairs",
      "rotation": 24
    },
    {
      "x": -14,
      "y": 28,
      "z": -14,
      "name": "Rock_Shale_Brick_Stairs",
      "rotation": 24
    },
    {
      "x": -14,
      "y": 29,
      "z": -14,
      "name": "Rock_Shale_Brick_Beam"
    },
    {
      "x": -14,
      "y": 43,
      "z": -14,
      "name": "Rock_Shale_Brick_Stairs",
      "rotation": 24
    },
    {
      "x": -14,
      "y": 44,
      "z": -14,
      "name": "Rock_Shale_Brick_Stairs",
      "rotation": 24
    },
    {
      "x": -14,
      "y": 45,
      "z": -14,
      "name": "Rock_Shale_Brick_Stairs",
      "rotation": 24
    },
    {
      "x": -14,
      "y": 46,
      "z": -14,
      "name": "Rock_Shale_Brick_Stairs",
      "rotation": 24
    },
    {
      "x": -14,
      "y": 47,
      "z": -14,
      "name": "Rock_Shale_Brick_Stairs",
      "rotation": 24
    },
    {
      "x": -14,
      "y": 48,
      "z": -14,
      "name": "Rock_Shale_Brick_Beam"
    },
    {
      "x": -14,
      "y": 0,
      "z": -13,
      "name": "Soil_Dirt"
    },
    {
      "x": -14,
      "y": 1,
      "z": -13,
      "name": "Soil_Dirt"
    },
    {
      "x": -14,
      "y": 2,
      "z": -13,
      "name": "Soil_Dirt"
    },
    {
      "x": -14,
      "y": 3,
      "z": -13,
      "name": "Soil_Dirt"
    },
    {
      "x": -14,
      "y": 4,
      "z": -13,
      "name": "Soil_Dirt"
    },
    {
      "x": -14,
      "y": 5,
      "z": -13,
      "name": "Soil_Dirt"
    },
    {
      "x": -14,
      "y": 6,
      "z": -13,
      "name": "Soil_Dirt"
    },
    {
      "x": -14,
      "y": 7,
      "z": -13,
      "name": "Soil_Dirt"
    },
    {
      "x": -14,
      "y": 8,
      "z": -13,
      "name": "Soil_Dirt"
    },
    {
      "x": -14,
      "y": 9,
      "z": -13,
      "name": "Soil_Dirt"
    },
    {
      "x": -14,
      "y": 10,
      "z": -13,
      "name": "Soil_Dirt"
    },
    {
      "x": -14,
      "y": 11,
      "z": -13,
      "name": "Soil_Grass"
    },
    {
      "x": -14,
      "y": 23,
      "z": -13,
      "name": "Rock_Shale_Brick_Smooth_Half",
      "rotation": 6
    },
    {
      "x": -14,
      "y": 24,
      "z": -13,
      "name": "Rock_Runic_Teal_Brick_Stairs",
      "rotation": 9
    },
    {
      "x": -14,
      "y": 25,
      "z": -13,
      "name": "Rock_Shale_Brick_Smooth_Half",
      "rotation": 4
    },
    {
      "x": -14,
      "y": 26,
      "z": -13,
      "name": "Rock_Shale_Brick_Smooth_Half",
      "rotation": 4
    },
    {
      "x": -14,
      "y": 27,
      "z": -13,
      "name": "Rock_Shale_Brick_Smooth_Half",
      "rotation": 4
    },
    {
      "x": -14,
      "y": 42,
      "z": -13,
      "name": "Rock_Shale_Brick_Smooth_Half",
      "rotation": 6
    },
    {
      "x": -14,
      "y": 43,
      "z": -13,
      "name": "Rock_Runic_Teal_Brick_Stairs",
      "rotation": 9
    },
    {
      "x": -14,
      "y": 44,
      "z": -13,
      "name": "Rock_Shale_Brick_Smooth_Half",
      "rotation": 4
    },
    {
      "x": -14,
      "y": 45,
      "z": -13,
      "name": "Rock_Shale_Brick_Smooth_Half",
      "rotation": 4
    },
    {
      "x": -14,
      "y": 46,
      "z": -13,
      "name": "Rock_Shale_Brick_Smooth_Half",
      "rotation": 4
    },
    {
      "x": -14,
      "y": 0,
      "z": -12,
      "name": "Soil_Dirt"
    },
    {
      "x": -14,
      "y": 1,
      "z": -12,
      "name": "Soil_Dirt"
    },
    {
      "x": -14,
      "y": 2,
      "z": -12,
      "name": "Soil_Dirt"
    },
    {
      "x": -14,
      "y": 3,
      "z": -12,
      "name": "Soil_Dirt"
    },
    {
      "x": -14,
      "y": 4,
      "z": -12,
      "name": "Soil_Dirt"
    },
    {
      "x": -14,
      "y": 5,
      "z": -12,
      "name": "Soil_Dirt"
    },
    {
      "x": -14,
      "y": 6,
      "z": -12,
      "name": "Soil_Dirt"
    },
    {
      "x": -14,
      "y": 7,
      "z": -12,
      "name": "Soil_Dirt"
    },
    {
      "x": -14,
      "y": 8,
      "z": -12,
      "name": "Soil_Dirt"
    },
    {
      "x": -14,
      "y": 9,
      "z": -12,
      "name": "Soil_Dirt"
    },
    {
      "x": -14,
      "y": 10,
      "z": -12,
      "name": "Soil_Dirt"
    },
    {
      "x": -14,
      "y": 11,
      "z": -12,
      "name": "Soil_Grass"
    },
    {
      "x": -14,
      "y": 22,
      "z": -12,
      "name": "Rock_Shale_Brick_Smooth_Half",
      "rotation": 6
    },
    {
      "x": -14,
      "y": 23,
      "z": -12,
      "name": "Rock_Runic_Teal_Brick_Stairs",
      "rotation": 9
    },
    {
      "x": -14,
      "y": 24,
      "z": -12,
      "name": "Rock_Shale_Brick_Smooth_Half",
      "rotation": 4
    },
    {
      "x": -14,
      "y": 41,
      "z": -12,
      "name": "Rock_Shale_Brick_Smooth_Half",
      "rotation": 6
    },
    {
      "x": -14,
      "y": 42,
      "z": -12,
      "name": "Rock_Runic_Teal_Brick_Stairs",
      "rotation": 9
    },
    {
      "x": -14,
      "y": 43,
      "z": -12,
      "name": "Rock_Shale_Brick_Smooth_Half",
      "rotation": 4
    },
    {
      "x": -14,
      "y": 60,
      "z": -12,
      "name": "*Rock_Shale_Brick_Roof_Steep_State_Definitions_Corner_Left",
      "rotation": 2
    },
    {
      "x": -14,
      "y": 61,
      "z": -12,
      "name": "*Rock_Shale_Brick_Roof_Steep_State_Definitions_Corner_Left",
      "filler": 1024,
      "rotation": 2
    },
    {
      "x": -14,
      "y": 0,
      "z": -11,
      "name": "Soil_Dirt"
    },
    {
      "x": -14,
      "y": 1,
      "z": -11,
      "name": "Soil_Dirt"
    },
    {
      "x": -14,
      "y": 2,
      "z": -11,
      "name": "Soil_Dirt"
    },
    {
      "x": -14,
      "y": 3,
      "z": -11,
      "name": "Soil_Dirt"
    },
    {
      "x": -14,
      "y": 4,
      "z": -11,
      "name": "Soil_Dirt"
    },
    {
      "x": -14,
      "y": 5,
      "z": -11,
      "name": "Soil_Dirt"
    },
    {
      "x": -14,
      "y": 6,
      "z": -11,
      "name": "Soil_Dirt"
    },
    {
      "x": -14,
      "y": 7,
      "z": -11,
      "name": "Soil_Dirt"
    },
    {
      "x": -14,
      "y": 8,
      "z": -11,
      "name": "Soil_Dirt"
    },
    {
      "x": -14,
      "y": 9,
      "z": -11,
      "name": "Soil_Dirt"
    },
    {
      "x": -14,
      "y": 10,
      "z": -11,
      "name": "Soil_Dirt"
    },
    {
      "x": -14,
      "y": 11,
      "z": -11,
      "name": "Soil_Grass"
    },
    {
      "x": -14,
      "y": 20,
      "z": -11,
      "name": "Rock_Shale_Brick_Smooth_Half",
      "rotation": 7
    },
    {
      "x": -14,
      "y": 21,
      "z": -11,
      "name": "Rock_Shale_Brick_Smooth_Half",
      "rotation": 7
    },
    {
      "x": -14,
      "y": 22,
      "z": -11,
      "name": "Rock_Runic_Teal_Brick_Stairs",
      "rotation": 9
    },
    {
      "x": -14,
      "y": 23,
      "z": -11,
      "name": "Rock_Shale_Brick_Smooth_Half",
      "rotation": 4
    },
    {
      "x": -14,
      "y": 39,
      "z": -11,
      "name": "Rock_Shale_Brick_Smooth_Half",
      "rotation": 7
    },
    {
      "x": -14,
      "y": 40,
      "z": -11,
      "name": "Rock_Shale_Brick_Smooth_Half",
      "rotation": 7
    },
    {
      "x": -14,
      "y": 41,
      "z": -11,
      "name": "Rock_Runic_Teal_Brick_Stairs",
      "rotation": 9
    },
    {
      "x": -14,
      "y": 42,
      "z": -11,
      "name": "Rock_Shale_Brick_Smooth_Half",
      "rotation": 4
    },
    {
      "x": -14,
      "y": 60,
      "z": -11,
      "name": "Rock_Shale_Brick_Roof_Steep",
      "rotation": 3
    },
    {
      "x": -14,
      "y": 61,
      "z": -11,
      "name": "Rock_Shale_Brick_Roof_Steep",
      "filler": 1024,
      "rotation": 3
    },
    {
      "x": -14,
      "y": 0,
      "z": -10,
      "name": "Soil_Dirt"
    },
    {
      "x": -14,
      "y": 1,
      "z": -10,
      "name": "Soil_Dirt"
    },
    {
      "x": -14,
      "y": 2,
      "z": -10,
      "name": "Soil_Dirt"
    },
    {
      "x": -14,
      "y": 3,
      "z": -10,
      "name": "Soil_Dirt"
    },
    {
      "x": -14,
      "y": 4,
      "z": -10,
      "name": "Soil_Dirt"
    },
    {
      "x": -14,
      "y": 5,
      "z": -10,
      "name": "Soil_Dirt"
    },
    {
      "x": -14,
      "y": 6,
      "z": -10,
      "name": "Soil_Dirt"
    },
    {
      "x": -14,
      "y": 7,
      "z": -10,
      "name": "Soil_Dirt"
    },
    {
      "x": -14,
      "y": 8,
      "z": -10,
      "name": "Soil_Dirt"
    },
    {
      "x": -14,
      "y": 9,
      "z": -10,
      "name": "Soil_Dirt"
    },
    {
      "x": -14,
      "y": 10,
      "z": -10,
      "name": "Soil_Grass"
    },
    {
      "x": -14,
      "y": 11,
      "z": -10,
      "name": "Plant_Grass_Sharp_Tall",
      "support": 15
    },
    {
      "x": -14,
      "y": 12,
      "z": -10,
      "name": "Plant_Grass_Sharp_Tall",
      "filler": 1024
    },
    {
      "x": -14,
      "y": 20,
      "z": -10,
      "name": "Rock_Shale_Brick_Smooth_Half",
      "rotation": 7
    },
    {
      "x": -14,
      "y": 21,
      "z": -10,
      "name": "Rock_Shale_Brick_Smooth_Half",
      "rotation": 7
    },
    {
      "x": -14,
      "y": 22,
      "z": -10,
      "name": "Rock_Shale_Brick_Smooth_Half",
      "rotation": 4
    },
    {
      "x": -14,
      "y": 39,
      "z": -10,
      "name": "Rock_Shale_Brick_Smooth_Half",
      "rotation": 7
    },
    {
      "x": -14,
      "y": 40,
      "z": -10,
      "name": "Rock_Shale_Brick_Smooth_Half",
      "rotation": 7
    },
    {
      "x": -14,
      "y": 41,
      "z": -10,
      "name": "Rock_Shale_Brick_Smooth_Half",
      "rotation": 4
    },
    {
      "x": -14,
      "y": 60,
      "z": -10,
      "name": "Rock_Shale_Brick_Roof_Steep",
      "rotation": 3
    },
    {
      "x": -14,
      "y": 61,
      "z": -10,
      "name": "Rock_Shale_Brick_Roof_Steep",
      "filler": 1024,
      "rotation": 3
    },
    {
      "x": -14,
      "y": 0,
      "z": -9,
      "name": "Soil_Dirt"
    },
    {
      "x": -14,
      "y": 1,
      "z": -9,
      "name": "Soil_Dirt"
    },
    {
      "x": -14,
      "y": 2,
      "z": -9,
      "name": "Soil_Dirt"
    },
    {
      "x": -14,
      "y": 3,
      "z": -9,
      "name": "Soil_Dirt"
    },
    {
      "x": -14,
      "y": 4,
      "z": -9,
      "name": "Soil_Dirt"
    },
    {
      "x": -14,
      "y": 5,
      "z": -9,
      "name": "Soil_Dirt"
    },
    {
      "x": -14,
      "y": 6,
      "z": -9,
      "name": "Soil_Dirt"
    },
    {
      "x": -14,
      "y": 7,
      "z": -9,
      "name": "Soil_Dirt"
    },
    {
      "x": -14,
      "y": 8,
      "z": -9,
      "name": "Soil_Dirt"
    },
    {
      "x": -14,
      "y": 9,
      "z": -9,
      "name": "Soil_Dirt"
    },
    {
      "x": -14,
      "y": 10,
      "z": -9,
      "name": "Soil_Grass"
    },
    {
      "x": -14,
      "y": 11,
      "z": -9,
      "name": "Plant_Grass_Sharp_Tall",
      "support": 15
    },
    {
      "x": -14,
      "y": 12,
      "z": -9,
      "name": "Plant_Grass_Sharp_Tall",
      "filler": 1024
    },
    {
      "x": -14,
      "y": 20,
      "z": -9,
      "name": "Rock_Shale_Brick_Smooth_Half",
      "rotation": 7
    },
    {
      "x": -14,
      "y": 21,
      "z": -9,
      "name": "Rock_Shale_Brick_Smooth_Half",
      "rotation": 7
    },
    {
      "x": -14,
      "y": 22,
      "z": -9,
      "name": "Rock_Shale_Brick_Smooth_Half",
      "rotation": 7
    },
    {
      "x": -14,
      "y": 39,
      "z": -9,
      "name": "Rock_Shale_Brick_Smooth_Half",
      "rotation": 7
    },
    {
      "x": -14,
      "y": 40,
      "z": -9,
      "name": "Rock_Shale_Brick_Smooth_Half",
      "rotation": 7
    },
    {
      "x": -14,
      "y": 41,
      "z": -9,
      "name": "Rock_Shale_Brick_Smooth_Half",
      "rotation": 7
    },
    {
      "x": -14,
      "y": 60,
      "z": -9,
      "name": "Rock_Shale_Brick_Roof_Steep",
      "rotation": 3
    },
    {
      "x": -14,
      "y": 61,
      "z": -9,
      "name": "Rock_Shale_Brick_Roof_Steep",
      "filler": 1024,
      "rotation": 3
    },
    {
      "x": -14,
      "y": 0,
      "z": -8,
      "name": "Soil_Dirt"
    },
    {
      "x": -14,
      "y": 1,
      "z": -8,
      "name": "Soil_Dirt"
    },
    {
      "x": -14,
      "y": 2,
      "z": -8,
      "name": "Soil_Dirt"
    },
    {
      "x": -14,
      "y": 3,
      "z": -8,
      "name": "Soil_Dirt"
    },
    {
      "x": -14,
      "y": 4,
      "z": -8,
      "name": "Soil_Dirt"
    },
    {
      "x": -14,
      "y": 5,
      "z": -8,
      "name": "Soil_Dirt"
    },
    {
      "x": -14,
      "y": 6,
      "z": -8,
      "name": "Soil_Dirt"
    },
    {
      "x": -14,
      "y": 7,
      "z": -8,
      "name": "Soil_Dirt"
    },
    {
      "x": -14,
      "y": 8,
      "z": -8,
      "name": "Soil_Dirt"
    },
    {
      "x": -14,
      "y": 9,
      "z": -8,
      "name": "Soil_Dirt"
    },
    {
      "x": -14,
      "y": 10,
      "z": -8,
      "name": "Soil_Grass"
    },
    {
      "x": -14,
      "y": 11,
      "z": -8,
      "name": "Plant_Grass_Sharp_Tall",
      "support": 15
    },
    {
      "x": -14,
      "y": 12,
      "z": -8,
      "name": "Plant_Grass_Sharp_Tall",
      "filler": 1024
    },
    {
      "x": -14,
      "y": 19,
      "z": -8,
      "name": "Rock_Shale_Brick_Smooth_Half",
      "rotation": 7
    },
    {
      "x": -14,
      "y": 20,
      "z": -8,
      "name": "Rock_Shale_Brick_Smooth_Half",
      "rotation": 7
    },
    {
      "x": -14,
      "y": 21,
      "z": -8,
      "name": "Rock_Shale_Brick_Smooth_Half",
      "rotation": 7
    },
    {
      "x": -14,
      "y": 22,
      "z": -8,
      "name": "Rock_Shale_Brick_Smooth_Half",
      "rotation": 7
    },
    {
      "x": -14,
      "y": 38,
      "z": -8,
      "name": "Rock_Shale_Brick_Smooth_Half",
      "rotation": 7
    },
    {
      "x": -14,
      "y": 39,
      "z": -8,
      "name": "Rock_Shale_Brick_Smooth_Half",
      "rotation": 7
    },
    {
      "x": -14,
      "y": 40,
      "z": -8,
      "name": "Rock_Shale_Brick_Smooth_Half",
      "rotation": 7
    },
    {
      "x": -14,
      "y": 41,
      "z": -8,
      "name": "Rock_Shale_Brick_Smooth_Half",
      "rotation": 7
    },
    {
      "x": -14,
      "y": 60,
      "z": -8,
      "name": "*Rock_Shale_Brick_Roof_Steep_State_Definitions_Corner_Right"
    },
    {
      "x": -14,
      "y": 61,
      "z": -8,
      "name": "*Rock_Shale_Brick_Roof_Steep_State_Definitions_Corner_Right",
      "filler": 1024
    },
    {
      "x": -14,
      "y": 0,
      "z": -7,
      "name": "Soil_Dirt"
    },
    {
      "x": -14,
      "y": 1,
      "z": -7,
      "name": "Soil_Dirt"
    },
    {
      "x": -14,
      "y": 2,
      "z": -7,
      "name": "Soil_Dirt"
    },
    {
      "x": -14,
      "y": 3,
      "z": -7,
      "name": "Soil_Dirt"
    },
    {
      "x": -14,
      "y": 4,
      "z": -7,
      "name": "Soil_Dirt"
    },
    {
      "x": -14,
      "y": 5,
      "z": -7,
      "name": "Soil_Dirt"
    },
    {
      "x": -14,
      "y": 6,
      "z": -7,
      "name": "Soil_Dirt"
    },
    {
      "x": -14,
      "y": 7,
      "z": -7,
      "name": "Soil_Dirt"
    },
    {
      "x": -14,
      "y": 8,
      "z": -7,
      "name": "Soil_Dirt"
    },
    {
      "x": -14,
      "y": 9,
      "z": -7,
      "name": "Soil_Dirt"
    },
    {
      "x": -14,
      "y": 10,
      "z": -7,
      "name": "Soil_Grass"
    },
    {
      "x": -14,
      "y": 11,
      "z": -7,
      "name": "Plant_Grass_Sharp_Overgrown",
      "support": 15
    },
    {
      "x": -14,
      "y": 12,
      "z": -7,
      "name": "Plant_Grass_Sharp_Overgrown",
      "filler": 1024
    },
    {
      "x": -14,
      "y": 0,
      "z": -6,
      "name": "Soil_Dirt"
    },
    {
      "x": -14,
      "y": 1,
      "z": -6,
      "name": "Soil_Dirt"
    },
    {
      "x": -14,
      "y": 2,
      "z": -6,
      "name": "Soil_Dirt"
    },
    {
      "x": -14,
      "y": 3,
      "z": -6,
      "name": "Soil_Dirt"
    },
    {
      "x": -14,
      "y": 4,
      "z": -6,
      "name": "Soil_Dirt"
    },
    {
      "x": -14,
      "y": 5,
      "z": -6,
      "name": "Soil_Dirt"
    },
    {
      "x": -14,
      "y": 6,
      "z": -6,
      "name": "Soil_Dirt"
    },
    {
      "x": -14,
      "y": 7,
      "z": -6,
      "name": "Soil_Dirt"
    },
    {
      "x": -14,
      "y": 8,
      "z": -6,
      "name": "Soil_Dirt"
    },
    {
      "x": -14,
      "y": 9,
      "z": -6,
      "name": "Soil_Grass"
    },
    {
      "x": -14,
      "y": 10,
      "z": -6,
      "name": "Plant_Grass_Sharp_Overgrown",
      "support": 15
    },
    {
      "x": -14,
      "y": 11,
      "z": -6,
      "name": "Plant_Grass_Sharp_Overgrown",
      "filler": 1024
    },
    {
      "x": -14,
      "y": 0,
      "z": -5,
      "name": "Soil_Dirt"
    },
    {
      "x": -14,
      "y": 1,
      "z": -5,
      "name": "Soil_Dirt"
    },
    {
      "x": -14,
      "y": 2,
      "z": -5,
      "name": "Soil_Dirt"
    },
    {
      "x": -14,
      "y": 3,
      "z": -5,
      "name": "Soil_Dirt"
    },
    {
      "x": -14,
      "y": 4,
      "z": -5,
      "name": "Soil_Dirt"
    },
    {
      "x": -14,
      "y": 5,
      "z": -5,
      "name": "Soil_Dirt"
    },
    {
      "x": -14,
      "y": 6,
      "z": -5,
      "name": "Soil_Dirt"
    },
    {
      "x": -14,
      "y": 7,
      "z": -5,
      "name": "Soil_Dirt"
    },
    {
      "x": -14,
      "y": 8,
      "z": -5,
      "name": "Soil_Grass"
    },
    {
      "x": -14,
      "y": 0,
      "z": -4,
      "name": "Soil_Dirt"
    },
    {
      "x": -14,
      "y": 1,
      "z": -4,
      "name": "Soil_Dirt"
    },
    {
      "x": -14,
      "y": 2,
      "z": -4,
      "name": "Soil_Dirt"
    },
    {
      "x": -14,
      "y": 3,
      "z": -4,
      "name": "Soil_Dirt"
    },
    {
      "x": -14,
      "y": 4,
      "z": -4,
      "name": "Soil_Dirt"
    },
    {
      "x": -14,
      "y": 5,
      "z": -4,
      "name": "Soil_Dirt"
    },
    {
      "x": -14,
      "y": 6,
      "z": -4,
      "name": "Soil_Dirt"
    },
    {
      "x": -14,
      "y": 7,
      "z": -4,
      "name": "Soil_Dirt"
    },
    {
      "x": -14,
      "y": 8,
      "z": -4,
      "name": "Soil_Grass"
    },
    {
      "x": -14,
      "y": 9,
      "z": -4,
      "name": "Plant_Grass_Jungle_Tall",
      "support": 15
    },
    {
      "x": -14,
      "y": 0,
      "z": -3,
      "name": "Soil_Dirt"
    },
    {
      "x": -14,
      "y": 1,
      "z": -3,
      "name": "Soil_Dirt"
    },
    {
      "x": -14,
      "y": 2,
      "z": -3,
      "name": "Soil_Dirt"
    },
    {
      "x": -14,
      "y": 3,
      "z": -3,
      "name": "Soil_Dirt"
    },
    {
      "x": -14,
      "y": 4,
      "z": -3,
      "name": "Soil_Dirt"
    },
    {
      "x": -14,
      "y": 5,
      "z": -3,
      "name": "Soil_Dirt"
    },
    {
      "x": -14,
      "y": 6,
      "z": -3,
      "name": "Soil_Dirt"
    },
    {
      "x": -14,
      "y": 7,
      "z": -3,
      "name": "Soil_Dirt"
    },
    {
      "x": -14,
      "y": 8,
      "z": -3,
      "name": "Soil_Grass"
    },
    {
      "x": -14,
      "y": 9,
      "z": -3,
      "name": "Plant_Grass_Jungle_Tall",
      "support": 15
    },
    {
      "x": -14,
      "y": 0,
      "z": -2,
      "name": "Soil_Dirt"
    },
    {
      "x": -14,
      "y": 1,
      "z": -2,
      "name": "Soil_Dirt"
    },
    {
      "x": -14,
      "y": 2,
      "z": -2,
      "name": "Soil_Dirt"
    },
    {
      "x": -14,
      "y": 3,
      "z": -2,
      "name": "Soil_Dirt"
    },
    {
      "x": -14,
      "y": 4,
      "z": -2,
      "name": "Soil_Dirt"
    },
    {
      "x": -14,
      "y": 5,
      "z": -2,
      "name": "Soil_Dirt"
    },
    {
      "x": -14,
      "y": 6,
      "z": -2,
      "name": "Soil_Dirt"
    },
    {
      "x": -14,
      "y": 7,
      "z": -2,
      "name": "Soil_Dirt"
    },
    {
      "x": -14,
      "y": 8,
      "z": -2,
      "name": "Soil_Dirt"
    },
    {
      "x": -14,
      "y": 9,
      "z": -2,
      "name": "Soil_Dirt"
    },
    {
      "x": -14,
      "y": 10,
      "z": -2,
      "name": "Soil_Grass"
    },
    {
      "x": -14,
      "y": 0,
      "z": -1,
      "name": "Soil_Dirt"
    },
    {
      "x": -14,
      "y": 1,
      "z": -1,
      "name": "Soil_Dirt"
    },
    {
      "x": -14,
      "y": 2,
      "z": -1,
      "name": "Soil_Dirt"
    },
    {
      "x": -14,
      "y": 3,
      "z": -1,
      "name": "Soil_Dirt"
    },
    {
      "x": -14,
      "y": 4,
      "z": -1,
      "name": "Soil_Dirt"
    },
    {
      "x": -14,
      "y": 5,
      "z": -1,
      "name": "Soil_Dirt"
    },
    {
      "x": -14,
      "y": 6,
      "z": -1,
      "name": "Soil_Dirt"
    },
    {
      "x": -14,
      "y": 7,
      "z": -1,
      "name": "Soil_Dirt"
    },
    {
      "x": -14,
      "y": 8,
      "z": -1,
      "name": "Soil_Dirt"
    },
    {
      "x": -14,
      "y": 9,
      "z": -1,
      "name": "Soil_Dirt"
    },
    {
      "x": -14,
      "y": 10,
      "z": -1,
      "name": "Soil_Grass"
    },
    {
      "x": -14,
      "y": 0,
      "z": 0,
      "name": "Soil_Dirt"
    },
    {
      "x": -14,
      "y": 1,
      "z": 0,
      "name": "Soil_Dirt"
    },
    {
      "x": -14,
      "y": 2,
      "z": 0,
      "name": "Soil_Dirt"
    },
    {
      "x": -14,
      "y": 3,
      "z": 0,
      "name": "Soil_Dirt"
    },
    {
      "x": -14,
      "y": 4,
      "z": 0,
      "name": "Soil_Dirt"
    },
    {
      "x": -14,
      "y": 5,
      "z": 0,
      "name": "Soil_Dirt"
    },
    {
      "x": -14,
      "y": 6,
      "z": 0,
      "name": "Soil_Dirt"
    },
    {
      "x": -14,
      "y": 7,
      "z": 0,
      "name": "Soil_Dirt"
    },
    {
      "x": -14,
      "y": 8,
      "z": 0,
      "name": "Soil_Dirt"
    },
    {
      "x": -14,
      "y": 9,
      "z": 0,
      "name": "Soil_Dirt"
    },
    {
      "x": -14,
      "y": 10,
      "z": 0,
      "name": "Soil_Grass"
    },
    {
      "x": -14,
      "y": 0,
      "z": 1,
      "name": "Soil_Dirt"
    },
    {
      "x": -14,
      "y": 1,
      "z": 1,
      "name": "Soil_Dirt"
    },
    {
      "x": -14,
      "y": 2,
      "z": 1,
      "name": "Soil_Dirt"
    },
    {
      "x": -14,
      "y": 3,
      "z": 1,
      "name": "Soil_Dirt"
    },
    {
      "x": -14,
      "y": 4,
      "z": 1,
      "name": "Soil_Dirt"
    },
    {
      "x": -14,
      "y": 5,
      "z": 1,
      "name": "Soil_Dirt"
    },
    {
      "x": -14,
      "y": 6,
      "z": 1,
      "name": "Soil_Dirt"
    },
    {
      "x": -14,
      "y": 7,
      "z": 1,
      "name": "Soil_Dirt"
    },
    {
      "x": -14,
      "y": 8,
      "z": 1,
      "name": "Soil_Dirt"
    },
    {
      "x": -14,
      "y": 9,
      "z": 1,
      "name": "Soil_Dirt"
    },
    {
      "x": -14,
      "y": 10,
      "z": 1,
      "name": "Soil_Grass"
    },
    {
      "x": -14,
      "y": 0,
      "z": 2,
      "name": "Soil_Dirt"
    },
    {
      "x": -14,
      "y": 1,
      "z": 2,
      "name": "Soil_Dirt"
    },
    {
      "x": -14,
      "y": 2,
      "z": 2,
      "name": "Soil_Dirt"
    },
    {
      "x": -14,
      "y": 3,
      "z": 2,
      "name": "Soil_Dirt"
    },
    {
      "x": -14,
      "y": 4,
      "z": 2,
      "name": "Soil_Dirt"
    },
    {
      "x": -14,
      "y": 5,
      "z": 2,
      "name": "Soil_Dirt"
    },
    {
      "x": -14,
      "y": 6,
      "z": 2,
      "name": "Soil_Dirt"
    },
    {
      "x": -14,
      "y": 7,
      "z": 2,
      "name": "Soil_Dirt"
    },
    {
      "x": -14,
      "y": 8,
      "z": 2,
      "name": "Soil_Dirt"
    },
    {
      "x": -14,
      "y": 9,
      "z": 2,
      "name": "Soil_Dirt"
    },
    {
      "x": -14,
      "y": 10,
      "z": 2,
      "name": "Soil_Grass"
    },
    {
      "x": -14,
      "y": 11,
      "z": 2,
      "name": "Plant_Grass_Jungle_Tall",
      "support": 15
    },
    {
      "x": -14,
      "y": 0,
      "z": 3,
      "name": "Soil_Dirt"
    },
    {
      "x": -14,
      "y": 1,
      "z": 3,
      "name": "Soil_Dirt"
    },
    {
      "x": -14,
      "y": 2,
      "z": 3,
      "name": "Soil_Dirt"
    },
    {
      "x": -14,
      "y": 3,
      "z": 3,
      "name": "Soil_Dirt"
    },
    {
      "x": -14,
      "y": 4,
      "z": 3,
      "name": "Soil_Dirt"
    },
    {
      "x": -14,
      "y": 5,
      "z": 3,
      "name": "Soil_Dirt"
    },
    {
      "x": -14,
      "y": 6,
      "z": 3,
      "name": "Soil_Dirt"
    },
    {
      "x": -14,
      "y": 7,
      "z": 3,
      "name": "Soil_Dirt"
    },
    {
      "x": -14,
      "y": 8,
      "z": 3,
      "name": "Soil_Dirt"
    },
    {
      "x": -14,
      "y": 9,
      "z": 3,
      "name": "Soil_Grass"
    },
    {
      "x": -14,
      "y": 0,
      "z": 4,
      "name": "Soil_Dirt"
    },
    {
      "x": -14,
      "y": 1,
      "z": 4,
      "name": "Soil_Dirt"
    },
    {
      "x": -14,
      "y": 2,
      "z": 4,
      "name": "Soil_Dirt"
    },
    {
      "x": -14,
      "y": 3,
      "z": 4,
      "name": "Soil_Dirt"
    },
    {
      "x": -14,
      "y": 4,
      "z": 4,
      "name": "Soil_Dirt"
    },
    {
      "x": -14,
      "y": 5,
      "z": 4,
      "name": "Soil_Dirt"
    },
    {
      "x": -14,
      "y": 6,
      "z": 4,
      "name": "Soil_Dirt"
    },
    {
      "x": -14,
      "y": 7,
      "z": 4,
      "name": "Soil_Dirt"
    },
    {
      "x": -14,
      "y": 8,
      "z": 4,
      "name": "Soil_Dirt"
    },
    {
      "x": -14,
      "y": 9,
      "z": 4,
      "name": "Soil_Grass"
    },
    {
      "x": -14,
      "y": 0,
      "z": 5,
      "name": "Soil_Dirt"
    },
    {
      "x": -14,
      "y": 1,
      "z": 5,
      "name": "Soil_Dirt"
    },
    {
      "x": -14,
      "y": 2,
      "z": 5,
      "name": "Soil_Dirt"
    },
    {
      "x": -14,
      "y": 3,
      "z": 5,
      "name": "Soil_Dirt"
    },
    {
      "x": -14,
      "y": 4,
      "z": 5,
      "name": "Soil_Dirt"
    },
    {
      "x": -14,
      "y": 5,
      "z": 5,
      "name": "Soil_Dirt"
    },
    {
      "x": -14,
      "y": 6,
      "z": 5,
      "name": "Soil_Dirt"
    },
    {
      "x": -14,
      "y": 7,
      "z": 5,
      "name": "Soil_Dirt"
    },
    {
      "x": -14,
      "y": 8,
      "z": 5,
      "name": "Soil_Dirt"
    },
    {
      "x": -14,
      "y": 9,
      "z": 5,
      "name": "Soil_Grass"
    },
    {
      "x": -14,
      "y": 10,
      "z": 5,
      "name": "Plant_Grass_Sharp_Tall",
      "support": 15
    },
    {
      "x": -14,
      "y": 11,
      "z": 5,
      "name": "Plant_Grass_Sharp_Tall",
      "filler": 1024
    },
    {
      "x": -14,
      "y": 0,
      "z": 6,
      "name": "Soil_Dirt"
    },
    {
      "x": -14,
      "y": 1,
      "z": 6,
      "name": "Soil_Dirt"
    },
    {
      "x": -14,
      "y": 2,
      "z": 6,
      "name": "Soil_Dirt"
    },
    {
      "x": -14,
      "y": 3,
      "z": 6,
      "name": "Soil_Dirt"
    },
    {
      "x": -14,
      "y": 4,
      "z": 6,
      "name": "Soil_Dirt"
    },
    {
      "x": -14,
      "y": 5,
      "z": 6,
      "name": "Soil_Dirt"
    },
    {
      "x": -14,
      "y": 6,
      "z": 6,
      "name": "Soil_Dirt"
    },
    {
      "x": -14,
      "y": 7,
      "z": 6,
      "name": "Soil_Dirt"
    },
    {
      "x": -14,
      "y": 8,
      "z": 6,
      "name": "Soil_Dirt"
    },
    {
      "x": -14,
      "y": 9,
      "z": 6,
      "name": "Soil_Dirt"
    },
    {
      "x": -14,
      "y": 10,
      "z": 6,
      "name": "Soil_Grass"
    },
    {
      "x": -14,
      "y": 11,
      "z": 6,
      "name": "Plant_Grass_Sharp_Tall",
      "support": 15
    },
    {
      "x": -14,
      "y": 12,
      "z": 6,
      "name": "Plant_Grass_Sharp_Tall",
      "filler": 1024
    },
    {
      "x": -14,
      "y": 0,
      "z": 7,
      "name": "Soil_Dirt"
    },
    {
      "x": -14,
      "y": 1,
      "z": 7,
      "name": "Soil_Dirt"
    },
    {
      "x": -14,
      "y": 2,
      "z": 7,
      "name": "Soil_Dirt"
    },
    {
      "x": -14,
      "y": 3,
      "z": 7,
      "name": "Soil_Dirt"
    },
    {
      "x": -14,
      "y": 4,
      "z": 7,
      "name": "Soil_Dirt"
    },
    {
      "x": -14,
      "y": 5,
      "z": 7,
      "name": "Soil_Dirt"
    },
    {
      "x": -14,
      "y": 6,
      "z": 7,
      "name": "Soil_Dirt"
    },
    {
      "x": -14,
      "y": 7,
      "z": 7,
      "name": "Soil_Dirt"
    },
    {
      "x": -14,
      "y": 8,
      "z": 7,
      "name": "Soil_Dirt"
    },
    {
      "x": -14,
      "y": 9,
      "z": 7,
      "name": "Soil_Dirt"
    },
    {
      "x": -14,
      "y": 10,
      "z": 7,
      "name": "Soil_Grass"
    },
    {
      "x": -14,
      "y": 11,
      "z": 7,
      "name": "Plant_Grass_Sharp_Overgrown",
      "support": 15
    },
    {
      "x": -14,
      "y": 12,
      "z": 7,
      "name": "Plant_Grass_Sharp_Overgrown",
      "filler": 1024
    },
    {
      "x": -14,
      "y": 0,
      "z": 8,
      "name": "Soil_Dirt"
    },
    {
      "x": -14,
      "y": 1,
      "z": 8,
      "name": "Soil_Dirt"
    },
    {
      "x": -14,
      "y": 2,
      "z": 8,
      "name": "Soil_Dirt"
    },
    {
      "x": -14,
      "y": 3,
      "z": 8,
      "name": "Soil_Dirt"
    },
    {
      "x": -14,
      "y": 4,
      "z": 8,
      "name": "Soil_Dirt"
    },
    {
      "x": -14,
      "y": 5,
      "z": 8,
      "name": "Soil_Dirt"
    },
    {
      "x": -14,
      "y": 6,
      "z": 8,
      "name": "Soil_Dirt"
    },
    {
      "x": -14,
      "y": 7,
      "z": 8,
      "name": "Soil_Dirt"
    },
    {
      "x": -14,
      "y": 8,
      "z": 8,
      "name": "Soil_Dirt"
    },
    {
      "x": -14,
      "y": 9,
      "z": 8,
      "name": "Soil_Dirt"
    },
    {
      "x": -14,
      "y": 10,
      "z": 8,
      "name": "Soil_Grass"
    },
    {
      "x": -14,
      "y": 11,
      "z": 8,
      "name": "Plant_Grass_Sharp_Tall",
      "support": 15
    },
    {
      "x": -14,
      "y": 12,
      "z": 8,
      "name": "Plant_Grass_Sharp_Tall",
      "filler": 1024
    },
    {
      "x": -14,
      "y": 19,
      "z": 8,
      "name": "Rock_Shale_Brick_Smooth_Half",
      "rotation": 7
    },
    {
      "x": -14,
      "y": 20,
      "z": 8,
      "name": "Rock_Shale_Brick_Smooth_Half",
      "rotation": 7
    },
    {
      "x": -14,
      "y": 21,
      "z": 8,
      "name": "Rock_Shale_Brick_Smooth_Half",
      "rotation": 7
    },
    {
      "x": -14,
      "y": 22,
      "z": 8,
      "name": "Rock_Shale_Brick_Smooth_Half",
      "rotation": 7
    },
    {
      "x": -14,
      "y": 38,
      "z": 8,
      "name": "Rock_Shale_Brick_Smooth_Half",
      "rotation": 7
    },
    {
      "x": -14,
      "y": 39,
      "z": 8,
      "name": "Rock_Shale_Brick_Smooth_Half",
      "rotation": 7
    },
    {
      "x": -14,
      "y": 40,
      "z": 8,
      "name": "Rock_Shale_Brick_Smooth_Half",
      "rotation": 7
    },
    {
      "x": -14,
      "y": 41,
      "z": 8,
      "name": "Rock_Shale_Brick_Smooth_Half",
      "rotation": 7
    },
    {
      "x": -14,
      "y": 60,
      "z": 8,
      "name": "*Rock_Shale_Brick_Roof_Steep_State_Definitions_Corner_Left",
      "rotation": 2
    },
    {
      "x": -14,
      "y": 61,
      "z": 8,
      "name": "*Rock_Shale_Brick_Roof_Steep_State_Definitions_Corner_Left",
      "filler": 1024,
      "rotation": 2
    },
    {
      "x": -14,
      "y": 0,
      "z": 9,
      "name": "Soil_Dirt"
    },
    {
      "x": -14,
      "y": 1,
      "z": 9,
      "name": "Soil_Dirt"
    },
    {
      "x": -14,
      "y": 2,
      "z": 9,
      "name": "Soil_Dirt"
    },
    {
      "x": -14,
      "y": 3,
      "z": 9,
      "name": "Soil_Dirt"
    },
    {
      "x": -14,
      "y": 4,
      "z": 9,
      "name": "Soil_Dirt"
    },
    {
      "x": -14,
      "y": 5,
      "z": 9,
      "name": "Soil_Dirt"
    },
    {
      "x": -14,
      "y": 6,
      "z": 9,
      "name": "Soil_Dirt"
    },
    {
      "x": -14,
      "y": 7,
      "z": 9,
      "name": "Soil_Dirt"
    },
    {
      "x": -14,
      "y": 8,
      "z": 9,
      "name": "Soil_Dirt"
    },
    {
      "x": -14,
      "y": 9,
      "z": 9,
      "name": "Soil_Grass"
    },
    {
      "x": -14,
      "y": 10,
      "z": 9,
      "name": "Plant_Grass_Sharp_Tall",
      "support": 15
    },
    {
      "x": -14,
      "y": 11,
      "z": 9,
      "name": "Plant_Grass_Sharp_Tall",
      "filler": 1024
    },
    {
      "x": -14,
      "y": 20,
      "z": 9,
      "name": "Rock_Shale_Brick_Smooth_Half",
      "rotation": 7
    },
    {
      "x": -14,
      "y": 21,
      "z": 9,
      "name": "Rock_Shale_Brick_Smooth_Half",
      "rotation": 7
    },
    {
      "x": -14,
      "y": 22,
      "z": 9,
      "name": "Rock_Shale_Brick_Smooth_Half",
      "rotation": 7
    },
    {
      "x": -14,
      "y": 39,
      "z": 9,
      "name": "Rock_Shale_Brick_Smooth_Half",
      "rotation": 7
    },
    {
      "x": -14,
      "y": 40,
      "z": 9,
      "name": "Rock_Shale_Brick_Smooth_Half",
      "rotation": 7
    },
    {
      "x": -14,
      "y": 41,
      "z": 9,
      "name": "Rock_Shale_Brick_Smooth_Half",
      "rotation": 7
    },
    {
      "x": -14,
      "y": 60,
      "z": 9,
      "name": "Rock_Shale_Brick_Roof_Steep",
      "rotation": 3
    },
    {
      "x": -14,
      "y": 61,
      "z": 9,
      "name": "Rock_Shale_Brick_Roof_Steep",
      "filler": 1024,
      "rotation": 3
    },
    {
      "x": -14,
      "y": 0,
      "z": 10,
      "name": "Soil_Dirt"
    },
    {
      "x": -14,
      "y": 1,
      "z": 10,
      "name": "Soil_Dirt"
    },
    {
      "x": -14,
      "y": 2,
      "z": 10,
      "name": "Soil_Dirt"
    },
    {
      "x": -14,
      "y": 3,
      "z": 10,
      "name": "Soil_Dirt"
    },
    {
      "x": -14,
      "y": 4,
      "z": 10,
      "name": "Soil_Dirt"
    },
    {
      "x": -14,
      "y": 5,
      "z": 10,
      "name": "Soil_Dirt"
    },
    {
      "x": -14,
      "y": 6,
      "z": 10,
      "name": "Soil_Dirt"
    },
    {
      "x": -14,
      "y": 7,
      "z": 10,
      "name": "Soil_Dirt"
    },
    {
      "x": -14,
      "y": 8,
      "z": 10,
      "name": "Soil_Dirt"
    },
    {
      "x": -14,
      "y": 9,
      "z": 10,
      "name": "Soil_Dirt"
    },
    {
      "x": -14,
      "y": 10,
      "z": 10,
      "name": "Soil_Dirt"
    },
    {
      "x": -14,
      "y": 11,
      "z": 10,
      "name": "Soil_Grass"
    },
    {
      "x": -14,
      "y": 12,
      "z": 10,
      "name": "Plant_Grass_Sharp_Tall",
      "support": 15
    },
    {
      "x": -14,
      "y": 13,
      "z": 10,
      "name": "Plant_Grass_Sharp_Tall",
      "filler": 1024
    },
    {
      "x": -14,
      "y": 20,
      "z": 10,
      "name": "Rock_Shale_Brick_Smooth_Half",
      "rotation": 7
    },
    {
      "x": -14,
      "y": 21,
      "z": 10,
      "name": "Rock_Shale_Brick_Smooth_Half",
      "rotation": 7
    },
    {
      "x": -14,
      "y": 22,
      "z": 10,
      "name": "Rock_Shale_Brick_Smooth_Half",
      "rotation": 6
    },
    {
      "x": -14,
      "y": 39,
      "z": 10,
      "name": "Rock_Shale_Brick_Smooth_Half",
      "rotation": 7
    },
    {
      "x": -14,
      "y": 40,
      "z": 10,
      "name": "Rock_Shale_Brick_Smooth_Half",
      "rotation": 7
    },
    {
      "x": -14,
      "y": 41,
      "z": 10,
      "name": "Rock_Shale_Brick_Smooth_Half",
      "rotation": 6
    },
    {
      "x": -14,
      "y": 60,
      "z": 10,
      "name": "Rock_Shale_Brick_Roof_Steep",
      "rotation": 3
    },
    {
      "x": -14,
      "y": 61,
      "z": 10,
      "name": "Rock_Shale_Brick_Roof_Steep",
      "filler": 1024,
      "rotation": 3
    },
    {
      "x": -14,
      "y": 0,
      "z": 11,
      "name": "Soil_Dirt"
    },
    {
      "x": -14,
      "y": 1,
      "z": 11,
      "name": "Soil_Dirt"
    },
    {
      "x": -14,
      "y": 2,
      "z": 11,
      "name": "Soil_Dirt"
    },
    {
      "x": -14,
      "y": 3,
      "z": 11,
      "name": "Soil_Dirt"
    },
    {
      "x": -14,
      "y": 4,
      "z": 11,
      "name": "Soil_Dirt"
    },
    {
      "x": -14,
      "y": 5,
      "z": 11,
      "name": "Soil_Dirt"
    },
    {
      "x": -14,
      "y": 6,
      "z": 11,
      "name": "Soil_Dirt"
    },
    {
      "x": -14,
      "y": 7,
      "z": 11,
      "name": "Soil_Dirt"
    },
    {
      "x": -14,
      "y": 8,
      "z": 11,
      "name": "Soil_Dirt"
    },
    {
      "x": -14,
      "y": 9,
      "z": 11,
      "name": "Soil_Dirt"
    },
    {
      "x": -14,
      "y": 10,
      "z": 11,
      "name": "Soil_Dirt"
    },
    {
      "x": -14,
      "y": 11,
      "z": 11,
      "name": "Soil_Grass"
    },
    {
      "x": -14,
      "y": 12,
      "z": 11,
      "name": "Plant_Grass_Sharp_Tall",
      "support": 15
    },
    {
      "x": -14,
      "y": 13,
      "z": 11,
      "name": "Plant_Grass_Sharp_Tall",
      "filler": 1024
    },
    {
      "x": -14,
      "y": 20,
      "z": 11,
      "name": "Rock_Shale_Brick_Smooth_Half",
      "rotation": 7
    },
    {
      "x": -14,
      "y": 21,
      "z": 11,
      "name": "Rock_Shale_Brick_Smooth_Half",
      "rotation": 7
    },
    {
      "x": -14,
      "y": 22,
      "z": 11,
      "name": "Rock_Runic_Teal_Brick_Stairs",
      "rotation": 9
    },
    {
      "x": -14,
      "y": 23,
      "z": 11,
      "name": "Rock_Shale_Brick_Smooth_Half",
      "rotation": 6
    },
    {
      "x": -14,
      "y": 39,
      "z": 11,
      "name": "Rock_Shale_Brick_Smooth_Half",
      "rotation": 7
    },
    {
      "x": -14,
      "y": 40,
      "z": 11,
      "name": "Rock_Shale_Brick_Smooth_Half",
      "rotation": 7
    },
    {
      "x": -14,
      "y": 41,
      "z": 11,
      "name": "Rock_Runic_Teal_Brick_Stairs",
      "rotation": 9
    },
    {
      "x": -14,
      "y": 42,
      "z": 11,
      "name": "Rock_Shale_Brick_Smooth_Half",
      "rotation": 6
    },
    {
      "x": -14,
      "y": 60,
      "z": 11,
      "name": "Rock_Shale_Brick_Roof_Steep",
      "rotation": 3
    },
    {
      "x": -14,
      "y": 61,
      "z": 11,
      "name": "Rock_Shale_Brick_Roof_Steep",
      "filler": 1024,
      "rotation": 3
    },
    {
      "x": -14,
      "y": 0,
      "z": 12,
      "name": "Soil_Dirt"
    },
    {
      "x": -14,
      "y": 1,
      "z": 12,
      "name": "Soil_Dirt"
    },
    {
      "x": -14,
      "y": 2,
      "z": 12,
      "name": "Soil_Dirt"
    },
    {
      "x": -14,
      "y": 3,
      "z": 12,
      "name": "Soil_Dirt"
    },
    {
      "x": -14,
      "y": 4,
      "z": 12,
      "name": "Soil_Dirt"
    },
    {
      "x": -14,
      "y": 5,
      "z": 12,
      "name": "Soil_Dirt"
    },
    {
      "x": -14,
      "y": 6,
      "z": 12,
      "name": "Soil_Dirt"
    },
    {
      "x": -14,
      "y": 7,
      "z": 12,
      "name": "Soil_Dirt"
    },
    {
      "x": -14,
      "y": 8,
      "z": 12,
      "name": "Soil_Dirt"
    },
    {
      "x": -14,
      "y": 9,
      "z": 12,
      "name": "Soil_Dirt"
    },
    {
      "x": -14,
      "y": 10,
      "z": 12,
      "name": "Soil_Dirt"
    },
    {
      "x": -14,
      "y": 11,
      "z": 12,
      "name": "Soil_Grass"
    },
    {
      "x": -14,
      "y": 12,
      "z": 12,
      "name": "Plant_Grass_Sharp_Overgrown",
      "support": 15
    },
    {
      "x": -14,
      "y": 13,
      "z": 12,
      "name": "Plant_Grass_Sharp_Overgrown",
      "filler": 1024
    },
    {
      "x": -14,
      "y": 22,
      "z": 12,
      "name": "Rock_Shale_Brick_Smooth_Half",
      "rotation": 4
    },
    {
      "x": -14,
      "y": 23,
      "z": 12,
      "name": "Rock_Runic_Teal_Brick_Stairs",
      "rotation": 9
    },
    {
      "x": -14,
      "y": 24,
      "z": 12,
      "name": "Rock_Shale_Brick_Smooth_Half",
      "rotation": 6
    },
    {
      "x": -14,
      "y": 41,
      "z": 12,
      "name": "Rock_Shale_Brick_Smooth_Half",
      "rotation": 4
    },
    {
      "x": -14,
      "y": 42,
      "z": 12,
      "name": "Rock_Runic_Teal_Brick_Stairs",
      "rotation": 9
    },
    {
      "x": -14,
      "y": 43,
      "z": 12,
      "name": "Rock_Shale_Brick_Smooth_Half",
      "rotation": 6
    },
    {
      "x": -14,
      "y": 60,
      "z": 12,
      "name": "*Rock_Shale_Brick_Roof_Steep_State_Definitions_Corner_Right"
    },
    {
      "x": -14,
      "y": 61,
      "z": 12,
      "name": "*Rock_Shale_Brick_Roof_Steep_State_Definitions_Corner_Right",
      "filler": 1024
    },
    {
      "x": -14,
      "y": 0,
      "z": 13,
      "name": "Soil_Dirt"
    },
    {
      "x": -14,
      "y": 1,
      "z": 13,
      "name": "Soil_Dirt"
    },
    {
      "x": -14,
      "y": 2,
      "z": 13,
      "name": "Soil_Dirt"
    },
    {
      "x": -14,
      "y": 3,
      "z": 13,
      "name": "Soil_Dirt"
    },
    {
      "x": -14,
      "y": 4,
      "z": 13,
      "name": "Soil_Dirt"
    },
    {
      "x": -14,
      "y": 5,
      "z": 13,
      "name": "Soil_Dirt"
    },
    {
      "x": -14,
      "y": 6,
      "z": 13,
      "name": "Soil_Dirt"
    },
    {
      "x": -14,
      "y": 7,
      "z": 13,
      "name": "Soil_Dirt"
    },
    {
      "x": -14,
      "y": 8,
      "z": 13,
      "name": "Soil_Dirt"
    },
    {
      "x": -14,
      "y": 9,
      "z": 13,
      "name": "Soil_Dirt"
    },
    {
      "x": -14,
      "y": 10,
      "z": 13,
      "name": "Soil_Grass"
    },
    {
      "x": -14,
      "y": 11,
      "z": 13,
      "name": "Plant_Grass_Sharp_Overgrown",
      "support": 15
    },
    {
      "x": -14,
      "y": 12,
      "z": 13,
      "name": "Plant_Grass_Sharp_Overgrown",
      "filler": 1024
    },
    {
      "x": -14,
      "y": 23,
      "z": 13,
      "name": "Rock_Shale_Brick_Smooth_Half",
      "rotation": 4
    },
    {
      "x": -14,
      "y": 24,
      "z": 13,
      "name": "Rock_Runic_Teal_Brick_Stairs",
      "rotation": 9
    },
    {
      "x": -14,
      "y": 25,
      "z": 13,
      "name": "Rock_Shale_Brick_Smooth_Half",
      "rotation": 6
    },
    {
      "x": -14,
      "y": 26,
      "z": 13,
      "name": "Rock_Shale_Brick_Smooth_Half",
      "rotation": 6
    },
    {
      "x": -14,
      "y": 27,
      "z": 13,
      "name": "Rock_Shale_Brick_Smooth_Half",
      "rotation": 6
    },
    {
      "x": -14,
      "y": 42,
      "z": 13,
      "name": "Rock_Shale_Brick_Smooth_Half",
      "rotation": 4
    },
    {
      "x": -14,
      "y": 43,
      "z": 13,
      "name": "Rock_Runic_Teal_Brick_Stairs",
      "rotation": 9
    },
    {
      "x": -14,
      "y": 44,
      "z": 13,
      "name": "Rock_Shale_Brick_Smooth_Half",
      "rotation": 6
    },
    {
      "x": -14,
      "y": 45,
      "z": 13,
      "name": "Rock_Shale_Brick_Smooth_Half",
      "rotation": 6
    },
    {
      "x": -14,
      "y": 46,
      "z": 13,
      "name": "Rock_Shale_Brick_Smooth_Half",
      "rotation": 6
    },
    {
      "x": -14,
      "y": 0,
      "z": 14,
      "name": "Soil_Dirt"
    },
    {
      "x": -14,
      "y": 1,
      "z": 14,
      "name": "Soil_Dirt"
    },
    {
      "x": -14,
      "y": 2,
      "z": 14,
      "name": "Soil_Dirt"
    },
    {
      "x": -14,
      "y": 3,
      "z": 14,
      "name": "Soil_Dirt"
    },
    {
      "x": -14,
      "y": 4,
      "z": 14,
      "name": "Soil_Dirt"
    },
    {
      "x": -14,
      "y": 5,
      "z": 14,
      "name": "Soil_Dirt"
    },
    {
      "x": -14,
      "y": 6,
      "z": 14,
      "name": "Soil_Dirt"
    },
    {
      "x": -14,
      "y": 7,
      "z": 14,
      "name": "Soil_Dirt"
    },
    {
      "x": -14,
      "y": 8,
      "z": 14,
      "name": "Soil_Dirt"
    },
    {
      "x": -14,
      "y": 9,
      "z": 14,
      "name": "Soil_Grass"
    },
    {
      "x": -14,
      "y": 10,
      "z": 14,
      "name": "Plant_Grass_Sharp_Overgrown",
      "support": 15
    },
    {
      "x": -14,
      "y": 11,
      "z": 14,
      "name": "Plant_Grass_Sharp_Overgrown",
      "filler": 1024
    },
    {
      "x": -14,
      "y": 24,
      "z": 14,
      "name": "Rock_Shale_Brick_Stairs",
      "rotation": 25
    },
    {
      "x": -14,
      "y": 25,
      "z": 14,
      "name": "Rock_Shale_Brick_Stairs",
      "rotation": 25
    },
    {
      "x": -14,
      "y": 26,
      "z": 14,
      "name": "Rock_Shale_Brick_Stairs",
      "rotation": 25
    },
    {
      "x": -14,
      "y": 27,
      "z": 14,
      "name": "Rock_Shale_Brick_Stairs",
      "rotation": 25
    },
    {
      "x": -14,
      "y": 28,
      "z": 14,
      "name": "Rock_Shale_Brick_Stairs",
      "rotation": 25
    },
    {
      "x": -14,
      "y": 29,
      "z": 14,
      "name": "Rock_Shale_Brick_Beam"
    },
    {
      "x": -14,
      "y": 43,
      "z": 14,
      "name": "Rock_Shale_Brick_Stairs",
      "rotation": 25
    },
    {
      "x": -14,
      "y": 44,
      "z": 14,
      "name": "Rock_Shale_Brick_Stairs",
      "rotation": 25
    },
    {
      "x": -14,
      "y": 45,
      "z": 14,
      "name": "Rock_Shale_Brick_Stairs",
      "rotation": 25
    },
    {
      "x": -14,
      "y": 46,
      "z": 14,
      "name": "Rock_Shale_Brick_Stairs",
      "rotation": 25
    },
    {
      "x": -14,
      "y": 47,
      "z": 14,
      "name": "Rock_Shale_Brick_Stairs",
      "rotation": 25
    },
    {
      "x": -14,
      "y": 48,
      "z": 14,
      "name": "Rock_Shale_Brick_Beam"
    },
    {
      "x": -14,
      "y": 0,
      "z": 15,
      "name": "Soil_Dirt"
    },
    {
      "x": -14,
      "y": 1,
      "z": 15,
      "name": "Soil_Dirt"
    },
    {
      "x": -14,
      "y": 2,
      "z": 15,
      "name": "Soil_Dirt"
    },
    {
      "x": -14,
      "y": 3,
      "z": 15,
      "name": "Soil_Dirt"
    },
    {
      "x": -14,
      "y": 4,
      "z": 15,
      "name": "Soil_Dirt"
    },
    {
      "x": -14,
      "y": 5,
      "z": 15,
      "name": "Soil_Dirt"
    },
    {
      "x": -14,
      "y": 6,
      "z": 15,
      "name": "Soil_Dirt"
    },
    {
      "x": -14,
      "y": 7,
      "z": 15,
      "name": "Soil_Grass"
    },
    {
      "x": -13,
      "y": 0,
      "z": -15,
      "name": "Soil_Dirt"
    },
    {
      "x": -13,
      "y": 1,
      "z": -15,
      "name": "Soil_Dirt"
    },
    {
      "x": -13,
      "y": 2,
      "z": -15,
      "name": "Soil_Dirt"
    },
    {
      "x": -13,
      "y": 3,
      "z": -15,
      "name": "Soil_Dirt"
    },
    {
      "x": -13,
      "y": 4,
      "z": -15,
      "name": "Soil_Dirt"
    },
    {
      "x": -13,
      "y": 5,
      "z": -15,
      "name": "Soil_Dirt"
    },
    {
      "x": -13,
      "y": 6,
      "z": -15,
      "name": "Soil_Dirt"
    },
    {
      "x": -13,
      "y": 7,
      "z": -15,
      "name": "Soil_Dirt"
    },
    {
      "x": -13,
      "y": 8,
      "z": -15,
      "name": "Soil_Dirt"
    },
    {
      "x": -13,
      "y": 9,
      "z": -15,
      "name": "Soil_Grass"
    },
    {
      "x": -13,
      "y": 10,
      "z": -15,
      "name": "Plant_Grass_Jungle_Tall",
      "support": 15
    },
    {
      "x": -13,
      "y": 24,
      "z": -15,
      "name": "Rock_Shale_Brick_Smooth_Half",
      "rotation": 6
    },
    {
      "x": -13,
      "y": 25,
      "z": -15,
      "name": "Rock_Shale_Brick_Smooth_Half",
      "rotation": 6
    },
    {
      "x": -13,
      "y": 26,
      "z": -15,
      "name": "Rock_Shale_Brick_Smooth_Half",
      "rotation": 6
    },
    {
      "x": -13,
      "y": 43,
      "z": -15,
      "name": "Rock_Shale_Brick_Smooth_Half",
      "rotation": 6
    },
    {
      "x": -13,
      "y": 44,
      "z": -15,
      "name": "Rock_Shale_Brick_Smooth_Half",
      "rotation": 6
    },
    {
      "x": -13,
      "y": 45,
      "z": -15,
      "name": "Rock_Shale_Brick_Smooth_Half",
      "rotation": 6
    },
    {
      "x": -13,
      "y": 0,
      "z": -14,
      "name": "Soil_Dirt"
    },
    {
      "x": -13,
      "y": 1,
      "z": -14,
      "name": "Soil_Dirt"
    },
    {
      "x": -13,
      "y": 2,
      "z": -14,
      "name": "Soil_Dirt"
    },
    {
      "x": -13,
      "y": 3,
      "z": -14,
      "name": "Soil_Dirt"
    },
    {
      "x": -13,
      "y": 4,
      "z": -14,
      "name": "Soil_Dirt"
    },
    {
      "x": -13,
      "y": 5,
      "z": -14,
      "name": "Soil_Dirt"
    },
    {
      "x": -13,
      "y": 6,
      "z": -14,
      "name": "Soil_Dirt"
    },
    {
      "x": -13,
      "y": 7,
      "z": -14,
      "name": "Soil_Dirt"
    },
    {
      "x": -13,
      "y": 8,
      "z": -14,
      "name": "Soil_Dirt"
    },
    {
      "x": -13,
      "y": 9,
      "z": -14,
      "name": "Soil_Dirt"
    },
    {
      "x": -13,
      "y": 10,
      "z": -14,
      "name": "Soil_Grass"
    },
    {
      "x": -13,
      "y": 23,
      "z": -14,
      "name": "Rock_Shale_Brick_Smooth_Half",
      "rotation": 7
    },
    {
      "x": -13,
      "y": 24,
      "z": -14,
      "name": "Rock_Runic_Teal_Brick_Stairs",
      "rotation": 8
    },
    {
      "x": -13,
      "y": 25,
      "z": -14,
      "name": "Rock_Shale_Brick_Smooth_Half",
      "rotation": 5
    },
    {
      "x": -13,
      "y": 26,
      "z": -14,
      "name": "Rock_Shale_Brick_Smooth_Half",
      "rotation": 5
    },
    {
      "x": -13,
      "y": 27,
      "z": -14,
      "name": "Rock_Shale_Brick_Smooth_Half",
      "rotation": 5
    },
    {
      "x": -13,
      "y": 42,
      "z": -14,
      "name": "Rock_Shale_Brick_Smooth_Half",
      "rotation": 7
    },
    {
      "x": -13,
      "y": 43,
      "z": -14,
      "name": "Rock_Runic_Teal_Brick_Stairs",
      "rotation": 8
    },
    {
      "x": -13,
      "y": 44,
      "z": -14,
      "name": "Rock_Shale_Brick_Smooth_Half",
      "rotation": 5
    },
    {
      "x": -13,
      "y": 45,
      "z": -14,
      "name": "Rock_Shale_Brick_Smooth_Half",
      "rotation": 5
    },
    {
      "x": -13,
      "y": 46,
      "z": -14,
      "name": "Rock_Shale_Brick_Smooth_Half",
      "rotation": 5
    },
    {
      "x": -13,
      "y": 0,
      "z": -13,
      "name": "Soil_Dirt"
    },
    {
      "x": -13,
      "y": 1,
      "z": -13,
      "name": "Soil_Dirt"
    },
    {
      "x": -13,
      "y": 2,
      "z": -13,
      "name": "Soil_Dirt"
    },
    {
      "x": -13,
      "y": 3,
      "z": -13,
      "name": "Soil_Dirt"
    },
    {
      "x": -13,
      "y": 4,
      "z": -13,
      "name": "Soil_Dirt"
    },
    {
      "x": -13,
      "y": 5,
      "z": -13,
      "name": "Soil_Dirt"
    },
    {
      "x": -13,
      "y": 6,
      "z": -13,
      "name": "Soil_Dirt"
    },
    {
      "x": -13,
      "y": 7,
      "z": -13,
      "name": "Soil_Dirt"
    },
    {
      "x": -13,
      "y": 8,
      "z": -13,
      "name": "Soil_Dirt"
    },
    {
      "x": -13,
      "y": 9,
      "z": -13,
      "name": "Soil_Dirt"
    },
    {
      "x": -13,
      "y": 10,
      "z": -13,
      "name": "Soil_Dirt"
    },
    {
      "x": -13,
      "y": 11,
      "z": -13,
      "name": "Soil_Grass"
    },
    {
      "x": -13,
      "y": 24,
      "z": -13,
      "name": "Rock_Shale_Brick_Smooth"
    },
    {
      "x": -13,
      "y": 43,
      "z": -13,
      "name": "Rock_Shale_Brick_Smooth"
    },
    {
      "x": -13,
      "y": 0,
      "z": -12,
      "name": "Soil_Dirt"
    },
    {
      "x": -13,
      "y": 1,
      "z": -12,
      "name": "Soil_Dirt"
    },
    {
      "x": -13,
      "y": 2,
      "z": -12,
      "name": "Soil_Dirt"
    },
    {
      "x": -13,
      "y": 3,
      "z": -12,
      "name": "Soil_Dirt"
    },
    {
      "x": -13,
      "y": 4,
      "z": -12,
      "name": "Soil_Dirt"
    },
    {
      "x": -13,
      "y": 5,
      "z": -12,
      "name": "Soil_Dirt"
    },
    {
      "x": -13,
      "y": 6,
      "z": -12,
      "name": "Soil_Dirt"
    },
    {
      "x": -13,
      "y": 7,
      "z": -12,
      "name": "Soil_Dirt"
    },
    {
      "x": -13,
      "y": 8,
      "z": -12,
      "name": "Soil_Dirt"
    },
    {
      "x": -13,
      "y": 9,
      "z": -12,
      "name": "Soil_Dirt"
    },
    {
      "x": -13,
      "y": 10,
      "z": -12,
      "name": "Soil_Dirt"
    },
    {
      "x": -13,
      "y": 11,
      "z": -12,
      "name": "Soil_Grass"
    },
    {
      "x": -13,
      "y": 12,
      "z": -12,
      "name": "Plant_Grass_Sharp_Overgrown",
      "support": 15
    },
    {
      "x": -13,
      "y": 13,
      "z": -12,
      "name": "Plant_Grass_Sharp_Overgrown",
      "filler": 1024
    },
    {
      "x": -13,
      "y": 20,
      "z": -12,
      "name": "Rock_Shale_Brick_Smooth_Half",
      "rotation": 6
    },
    {
      "x": -13,
      "y": 21,
      "z": -12,
      "name": "Rock_Shale_Brick_Smooth_Half",
      "rotation": 7
    },
    {
      "x": -13,
      "y": 22,
      "z": -12,
      "name": "Rock_Shale_Brick_Smooth_Half",
      "rotation": 7
    },
    {
      "x": -13,
      "y": 23,
      "z": -12,
      "name": "Rock_Shale_Brick_Smooth"
    },
    {
      "x": -13,
      "y": 39,
      "z": -12,
      "name": "Rock_Shale_Brick_Smooth_Half",
      "rotation": 6
    },
    {
      "x": -13,
      "y": 40,
      "z": -12,
      "name": "Rock_Shale_Brick_Smooth_Half",
      "rotation": 7
    },
    {
      "x": -13,
      "y": 41,
      "z": -12,
      "name": "Rock_Shale_Brick_Smooth_Half",
      "rotation": 7
    },
    {
      "x": -13,
      "y": 42,
      "z": -12,
      "name": "Rock_Shale_Brick_Smooth"
    },
    {
      "x": -13,
      "y": 52,
      "z": -12,
      "name": "Rock_Shale_Brick_Smooth"
    },
    {
      "x": -13,
      "y": 53,
      "z": -12,
      "name": "Rock_Shale_Brick_Smooth"
    },
    {
      "x": -13,
      "y": 54,
      "z": -12,
      "name": "Rock_Shale_Brick_Smooth"
    },
    {
      "x": -13,
      "y": 55,
      "z": -12,
      "name": "Rock_Shale_Brick_Smooth"
    },
    {
      "x": -13,
      "y": 56,
      "z": -12,
      "name": "Rock_Shale_Brick_Smooth"
    },
    {
      "x": -13,
      "y": 57,
      "z": -12,
      "name": "Rock_Shale_Brick_Smooth"
    },
    {
      "x": -13,
      "y": 58,
      "z": -12,
      "name": "Rock_Shale_Brick_Smooth"
    },
    {
      "x": -13,
      "y": 59,
      "z": -12,
      "name": "Rock_Shale_Brick_Smooth"
    },
    {
      "x": -13,
      "y": 60,
      "z": -12,
      "name": "*Rock_Shale_Brick_Roof_Steep_State_Definitions_Inverted_Corner_Right",
      "rotation": 3
    },
    {
      "x": -13,
      "y": 61,
      "z": -12,
      "name": "*Rock_Shale_Brick_Roof_Steep_State_Definitions_Inverted_Corner_Right",
      "filler": 1024,
      "rotation": 3
    },
    {
      "x": -13,
      "y": 0,
      "z": -11,
      "name": "Soil_Dirt"
    },
    {
      "x": -13,
      "y": 1,
      "z": -11,
      "name": "Soil_Dirt"
    },
    {
      "x": -13,
      "y": 2,
      "z": -11,
      "name": "Soil_Dirt"
    },
    {
      "x": -13,
      "y": 3,
      "z": -11,
      "name": "Soil_Dirt"
    },
    {
      "x": -13,
      "y": 4,
      "z": -11,
      "name": "Soil_Dirt"
    },
    {
      "x": -13,
      "y": 5,
      "z": -11,
      "name": "Soil_Dirt"
    },
    {
      "x": -13,
      "y": 6,
      "z": -11,
      "name": "Soil_Dirt"
    },
    {
      "x": -13,
      "y": 7,
      "z": -11,
      "name": "Soil_Dirt"
    },
    {
      "x": -13,
      "y": 8,
      "z": -11,
      "name": "Soil_Dirt"
    },
    {
      "x": -13,
      "y": 9,
      "z": -11,
      "name": "Soil_Dirt"
    },
    {
      "x": -13,
      "y": 10,
      "z": -11,
      "name": "Soil_Dirt"
    },
    {
      "x": -13,
      "y": 11,
      "z": -11,
      "name": "Soil_Grass"
    },
    {
      "x": -13,
      "y": 12,
      "z": -11,
      "name": "Plant_Grass_Jungle_Tall",
      "support": 15
    },
    {
      "x": -13,
      "y": 20,
      "z": -11,
      "name": "Rock_Runic_Teal_Brick_Stairs",
      "rotation": 9
    },
    {
      "x": -13,
      "y": 21,
      "z": -11,
      "name": "Rock_Shale_Brick_Smooth_Half",
      "rotation": 4
    },
    {
      "x": -13,
      "y": 22,
      "z": -11,
      "name": "Rock_Shale_Brick_Smooth_Half",
      "rotation": 5
    },
    {
      "x": -13,
      "y": 23,
      "z": -11,
      "name": "Rock_Shale_Brick_Smooth_Half",
      "rotation": 7
    },
    {
      "x": -13,
      "y": 24,
      "z": -11,
      "name": "Rock_Shale_Brick_Smooth_Half",
      "rotation": 7
    },
    {
      "x": -13,
      "y": 25,
      "z": -11,
      "name": "Rock_Shale_Brick_Smooth_Half",
      "rotation": 7
    },
    {
      "x": -13,
      "y": 26,
      "z": -11,
      "name": "Rock_Shale_Brick_Smooth_Half",
      "rotation": 7
    },
    {
      "x": -13,
      "y": 38,
      "z": -11,
      "name": "Rock_Shale_Brick_Smooth_Half",
      "rotation": 7
    },
    {
      "x": -13,
      "y": 39,
      "z": -11,
      "name": "Rock_Runic_Teal_Brick_Stairs",
      "rotation": 9
    },
    {
      "x": -13,
      "y": 40,
      "z": -11,
      "name": "Rock_Shale_Brick_Smooth_Half",
      "rotation": 4
    },
    {
      "x": -13,
      "y": 41,
      "z": -11,
      "name": "Rock_Shale_Brick_Smooth_Half",
      "rotation": 5
    },
    {
      "x": -13,
      "y": 42,
      "z": -11,
      "name": "Rock_Shale_Brick_Smooth_Half",
      "rotation": 7
    },
    {
      "x": -13,
      "y": 43,
      "z": -11,
      "name": "Rock_Shale_Brick_Smooth_Half",
      "rotation": 7
    },
    {
      "x": -13,
      "y": 44,
      "z": -11,
      "name": "Rock_Shale_Brick_Smooth_Half",
      "rotation": 7
    },
    {
      "x": -13,
      "y": 45,
      "z": -11,
      "name": "Rock_Shale_Brick_Smooth_Half",
      "rotation": 7
    },
    {
      "x": -13,
      "y": 52,
      "z": -11,
      "name": "Rock_Shale_Brick_Smooth"
    },
    {
      "x": -13,
      "y": 53,
      "z": -11,
      "name": "Rock_Shale_Brick_Half",
      "rotation": 7
    },
    {
      "x": -13,
      "y": 54,
      "z": -11,
      "name": "Rock_Shale_Brick_Smooth_Half",
      "rotation": 2
    },
    {
      "x": -13,
      "y": 57,
      "z": -11,
      "name": "Rock_Shale_Brick_Ornate",
      "rotation": 2
    },
    {
      "x": -13,
      "y": 58,
      "z": -11,
      "name": "Rock_Shale_Brick_Half",
      "rotation": 7
    },
    {
      "x": -13,
      "y": 59,
      "z": -11,
      "name": "Rock_Shale_Brick_Stairs",
      "rotation": 9
    },
    {
      "x": -13,
      "y": 61,
      "z": -11,
      "name": "Rock_Shale_Brick_Stairs",
      "rotation": 11
    },
    {
      "x": -13,
      "y": 62,
      "z": -11,
      "name": "*Rock_Shale_Brick_Roof_Steep_State_Definitions_Corner_Left",
      "rotation": 2
    },
    {
      "x": -13,
      "y": 63,
      "z": -11,
      "name": "*Rock_Shale_Brick_Roof_Steep_State_Definitions_Corner_Left",
      "filler": 1024,
      "rotation": 2
    },
    {
      "x": -13,
      "y": 0,
      "z": -10,
      "name": "Soil_Dirt"
    },
    {
      "x": -13,
      "y": 1,
      "z": -10,
      "name": "Soil_Dirt"
    },
    {
      "x": -13,
      "y": 2,
      "z": -10,
      "name": "Soil_Dirt"
    },
    {
      "x": -13,
      "y": 3,
      "z": -10,
      "name": "Soil_Dirt"
    },
    {
      "x": -13,
      "y": 4,
      "z": -10,
      "name": "Soil_Dirt"
    },
    {
      "x": -13,
      "y": 5,
      "z": -10,
      "name": "Soil_Dirt"
    },
    {
      "x": -13,
      "y": 6,
      "z": -10,
      "name": "Soil_Dirt"
    },
    {
      "x": -13,
      "y": 7,
      "z": -10,
      "name": "Soil_Dirt"
    },
    {
      "x": -13,
      "y": 8,
      "z": -10,
      "name": "Soil_Dirt"
    },
    {
      "x": -13,
      "y": 9,
      "z": -10,
      "name": "Soil_Dirt"
    },
    {
      "x": -13,
      "y": 10,
      "z": -10,
      "name": "Soil_Dirt"
    },
    {
      "x": -13,
      "y": 11,
      "z": -10,
      "name": "Soil_Grass"
    },
    {
      "x": -13,
      "y": 12,
      "z": -10,
      "name": "Plant_Grass_Jungle_Tall",
      "support": 15
    },
    {
      "x": -13,
      "y": 17,
      "z": -10,
      "name": "Rock_Shale_Brick_Smooth_Half",
      "rotation": 7
    },
    {
      "x": -13,
      "y": 18,
      "z": -10,
      "name": "Rock_Shale_Brick_Smooth_Half",
      "rotation": 7
    },
    {
      "x": -13,
      "y": 19,
      "z": -10,
      "name": "Rock_Shale_Brick_Smooth_Half",
      "rotation": 7
    },
    {
      "x": -13,
      "y": 20,
      "z": -10,
      "name": "Rock_Runic_Teal_Brick_Stairs",
      "rotation": 9
    },
    {
      "x": -13,
      "y": 22,
      "z": -10,
      "name": "Rock_Shale_Brick_Smooth_Half",
      "rotation": 7
    },
    {
      "x": -13,
      "y": 23,
      "z": -10,
      "name": "Rock_Shale_Brick_Smooth_Half",
      "rotation": 7
    },
    {
      "x": -13,
      "y": 36,
      "z": -10,
      "name": "Rock_Shale_Brick_Smooth_Half",
      "rotation": 7
    },
    {
      "x": -13,
      "y": 37,
      "z": -10,
      "name": "Rock_Shale_Brick_Smooth_Half",
      "rotation": 7
    },
    {
      "x": -13,
      "y": 38,
      "z": -10,
      "name": "Rock_Shale_Brick_Smooth_Half",
      "rotation": 7
    },
    {
      "x": -13,
      "y": 39,
      "z": -10,
      "name": "Rock_Runic_Teal_Brick_Stairs",
      "rotation": 9
    },
    {
      "x": -13,
      "y": 41,
      "z": -10,
      "name": "Rock_Shale_Brick_Smooth_Half",
      "rotation": 7
    },
    {
      "x": -13,
      "y": 42,
      "z": -10,
      "name": "Rock_Shale_Brick_Smooth_Half",
      "rotation": 7
    },
    {
      "x": -13,
      "y": 51,
      "z": -10,
      "name": "Rock_Shale_Brick_Stairs",
      "rotation": 9
    },
    {
      "x": -13,
      "y": 52,
      "z": -10,
      "name": "Rock_Shale_Brick_Smooth"
    },
    {
      "x": -13,
      "y": 53,
      "z": -10,
      "name": "Rock_Shale_Brick_Half",
      "rotation": 7
    },
    {
      "x": -13,
      "y": 54,
      "z": -10,
      "name": "Rock_Shale_Brick_Smooth_Half",
      "rotation": 2
    },
    {
      "x": -13,
      "y": 57,
      "z": -10,
      "name": "Rock_Shale_Brick_Ornate",
      "rotation": 2
    },
    {
      "x": -13,
      "y": 58,
      "z": -10,
      "name": "Rock_Shale_Brick_Half",
      "rotation": 7
    },
    {
      "x": -13,
      "y": 59,
      "z": -10,
      "name": "Rock_Shale_Brick_Stairs",
      "rotation": 9
    },
    {
      "x": -13,
      "y": 61,
      "z": -10,
      "name": "Rock_Shale_Brick_Stairs",
      "rotation": 11
    },
    {
      "x": -13,
      "y": 62,
      "z": -10,
      "name": "Rock_Shale_Brick_Roof_Steep",
      "rotation": 3
    },
    {
      "x": -13,
      "y": 63,
      "z": -10,
      "name": "Rock_Shale_Brick_Roof_Steep",
      "filler": 1024,
      "rotation": 3
    },
    {
      "x": -13,
      "y": 0,
      "z": -9,
      "name": "Soil_Dirt"
    },
    {
      "x": -13,
      "y": 1,
      "z": -9,
      "name": "Soil_Dirt"
    },
    {
      "x": -13,
      "y": 2,
      "z": -9,
      "name": "Soil_Dirt"
    },
    {
      "x": -13,
      "y": 3,
      "z": -9,
      "name": "Soil_Dirt"
    },
    {
      "x": -13,
      "y": 4,
      "z": -9,
      "name": "Soil_Dirt"
    },
    {
      "x": -13,
      "y": 5,
      "z": -9,
      "name": "Soil_Dirt"
    },
    {
      "x": -13,
      "y": 6,
      "z": -9,
      "name": "Soil_Dirt"
    },
    {
      "x": -13,
      "y": 7,
      "z": -9,
      "name": "Soil_Dirt"
    },
    {
      "x": -13,
      "y": 8,
      "z": -9,
      "name": "Soil_Dirt"
    },
    {
      "x": -13,
      "y": 9,
      "z": -9,
      "name": "Soil_Dirt"
    },
    {
      "x": -13,
      "y": 10,
      "z": -9,
      "name": "Soil_Dirt"
    },
    {
      "x": -13,
      "y": 11,
      "z": -9,
      "name": "Soil_Grass"
    },
    {
      "x": -13,
      "y": 14,
      "z": -9,
      "name": "Rock_Shale_Brick_Smooth_Half",
      "rotation": 7
    },
    {
      "x": -13,
      "y": 15,
      "z": -9,
      "name": "Rock_Shale_Brick_Smooth_Half",
      "rotation": 7
    },
    {
      "x": -13,
      "y": 16,
      "z": -9,
      "name": "Rock_Shale_Brick_Smooth_Half",
      "rotation": 7
    },
    {
      "x": -13,
      "y": 17,
      "z": -9,
      "name": "Rock_Shale_Brick_Smooth_Half",
      "rotation": 7
    },
    {
      "x": -13,
      "y": 18,
      "z": -9,
      "name": "Rock_Shale_Brick_Smooth_Half",
      "rotation": 7
    },
    {
      "x": -13,
      "y": 19,
      "z": -9,
      "name": "Rock_Shale_Brick_Smooth_Half",
      "rotation": 7
    },
    {
      "x": -13,
      "y": 20,
      "z": -9,
      "name": "Rock_Runic_Teal_Brick_Stairs",
