{
  "version": 8,
  "blockIdVersion": 11,
  "anchorX": 0,
  "anchorY": 0,
  "anchorZ": 0,
  "blocks": [
    {
      "x": -17,
      "y": 54,
      "z": 6,
      "name": "Plant_Leaves_Beech",
      "support": 15
    },
    {
      "x": -17,
      "y": 55,
      "z": 6,
      "name": "Plant_Leaves_Beech",
      "support": 15
    },
    {
      "x": -16,
      "y": 58,
      "z": 0,
      "name": "Plant_Leaves_Beech",
      "support": 15
    },
    {
      "x": -16,
      "y": 59,
      "z": 0,
      "name": "Plant_Leaves_Beech",
      "support": 15
    },
    {
      "x": -16,
      "y": 54,
      "z": 2,
      "name": "Plant_Leaves_Beech",
      "support": 15
    },
    {
      "x": -16,
      "y": 55,
      "z": 2,
      "name": "Plant_Leaves_Beech",
      "support": 15
    },
    {
      "x": -16,
      "y": 54,
      "z": 3,
      "name": "Plant_Leaves_Beech",
      "support": 15
    },
    {
      "x": -16,
      "y": 54,
      "z": 5,
      "name": "Plant_Leaves_Beech",
      "support": 15
    },
    {
      "x": -16,
      "y": 55,
      "z": 5,
      "name": "Plant_Leaves_Beech",
      "support": 15
    },
    {
      "x": -16,
      "y": 53,
      "z": 6,
      "name": "Plant_Leaves_Beech",
      "support": 15
    },
    {
      "x": -16,
      "y": 54,
      "z": 6,
      "name": "Wood_Sallow_Branch_Corner",
      "support": 15,
      "rotation": 3
    },
    {
      "x": -16,
      "y": 55,
      "z": 6,
      "name": "Wood_Sallow_Branch_Long",
      "support": 15
    },
    {
      "x": -16,
      "y": 56,
      "z": 6,
      "name": "Plant_Leaves_Beech",
      "support": 15
    },
    {
      "x": -16,
      "y": 54,
      "z": 7,
      "name": "Plant_Leaves_Beech",
      "support": 15
    },
    {
      "x": -16,
      "y": 55,
      "z": 7,
      "name": "Plant_Leaves_Beech",
      "support": 15
    },
    {
      "x": -15,
      "y": 58,
      "z": -1,
      "name": "Plant_Leaves_Beech",
      "support": 15
    },
    {
      "x": -15,
      "y": 59,
      "z": -1,
      "name": "Plant_Leaves_Beech",
      "support": 15
    },
    {
      "x": -15,
      "y": 58,
      "z": 0,
      "name": "Wood_Sallow_Branch_Corner",
      "support": 15,
      "rotation": 3
    },
    {
      "x": -15,
      "y": 59,
      "z": 0,
      "name": "Wood_Sallow_Branch_Long",
      "support": 15
    },
    {
      "x": -15,
      "y": 60,
      "z": 0,
      "name": "Plant_Leaves_Beech",
      "support": 15
    },
    {
      "x": -15,
      "y": 54,
      "z": 1,
      "name": "Plant_Leaves_Beech",
      "support": 15
    },
    {
      "x": -15,
      "y": 55,
      "z": 1,
      "name": "Plant_Leaves_Beech",
      "support": 15
    },
    {
      "x": -15,
      "y": 58,
      "z": 1,
      "name": "Plant_Leaves_Beech",
      "support": 15
    },
    {
      "x": -15,
      "y": 59,
      "z": 1,
      "name": "Plant_Leaves_Beech",
      "support": 15
    },
    {
      "x": -15,
      "y": 54,
      "z": 2,
      "name": "Wood_Sallow_Branch_Corner",
      "support": 15,
      "rotation": 2
    },
    {
      "x": -15,
      "y": 55,
      "z": 2,
      "name": "Wood_Sallow_Branch_Long",
      "support": 15
    },
    {
      "x": -15,
      "y": 56,
      "z": 2,
      "name": "Plant_Leaves_Beech",
      "support": 15
    },
    {
      "x": -15,
      "y": 54,
      "z": 3,
      "name": "Wood_Sallow_Branch_Corner",
      "support": 15,
      "rotation": 19
    },
    {
      "x": -15,
      "y": 55,
      "z": 3,
      "name": "Plant_Leaves_Beech",
      "support": 15
    },
    {
      "x": -15,
      "y": 54,
      "z": 6,
      "name": "Wood_Sallow_Trunk",
      "support": 15,
      "rotation": 5
    },
    {
      "x": -15,
      "y": 55,
      "z": 6,
      "name": "Plant_Leaves_Beech",
      "support": 15
    },
    {
      "x": -15,
      "y": 58,
      "z": 6,
      "name": "Plant_Leaves_Beech",
      "support": 15
    },
    {
      "x": -15,
      "y": 59,
      "z": 6,
      "name": "Plant_Leaves_Beech",
      "support": 15
    },
    {
      "x": -15,
      "y": 55,
      "z": 10,
      "name": "Plant_Leaves_Beech",
      "support": 15
    },
    {
      "x": -15,
      "y": 55,
      "z": 11,
      "name": "Plant_Leaves_Beech",
      "support": 15
    },
    {
      "x": -15,
      "y": 56,
      "z": 11,
      "name": "Plant_Leaves_Beech",
      "support": 15
    },
    {
      "x": -14,
      "y": 54,
      "z": -3,
      "name": "Plant_Leaves_Beech",
      "support": 15
    },
    {
      "x": -14,
      "y": 55,
      "z": -3,
      "name": "Plant_Leaves_Beech",
      "support": 15
    },
    {
      "x": -14,
      "y": 58,
      "z": -1,
      "name": "Plant_Leaves_Beech",
      "support": 15
    },
    {
      "x": -14,
      "y": 58,
      "z": 0,
      "name": "Wood_Sallow_Branch_Long",
      "support": 15,
      "rotation": 5
    },
    {
      "x": -14,
      "y": 59,
      "z": 0,
      "name": "Plant_Leaves_Beech",
      "support": 15
    },
    {
      "x": -14,
      "y": 60,
      "z": 0,
      "name": "Plant_Leaves_Beech",
      "support": 15
    },
    {
      "x": -14,
      "y": 58,
      "z": 1,
      "name": "Plant_Leaves_Beech",
      "support": 15
    },
    {
      "x": -14,
      "y": 39,
      "z": 2,
      "name": "Plant_Vine_Liana_End",
      "support": 15,
      "rotation": 3
    },
    {
      "x": -14,
      "y": 40,
      "z": 2,
      "name": "Plant_Vine_Liana",
      "support": 15,
      "rotation": 3
    },
    {
      "x": -14,
      "y": 41,
      "z": 2,
      "name": "Plant_Vine_Liana",
      "support": 15,
      "rotation": 3
    },
    {
      "x": -14,
      "y": 42,
      "z": 2,
      "name": "Plant_Vine_Liana",
      "support": 15,
      "rotation": 3
    },
    {
      "x": -14,
      "y": 43,
      "z": 2,
      "name": "Plant_Vine_Liana",
      "support": 15,
      "rotation": 3
    },
    {
      "x": -14,
      "y": 44,
      "z": 2,
      "name": "Plant_Vine_Liana",
      "support": 15,
      "rotation": 3
    },
    {
      "x": -14,
      "y": 45,
      "z": 2,
      "name": "Plant_Vine_Liana",
      "support": 15,
      "rotation": 3
    },
    {
      "x": -14,
      "y": 46,
      "z": 2,
      "name": "Plant_Vine_Liana",
      "support": 15,
      "rotation": 3
    },
    {
      "x": -14,
      "y": 47,
      "z": 2,
      "name": "Plant_Vine_Liana",
      "support": 15,
      "rotation": 3
    },
    {
      "x": -14,
      "y": 48,
      "z": 2,
      "name": "Plant_Vine_Liana",
      "support": 15,
      "rotation": 3
    },
    {
      "x": -14,
      "y": 49,
      "z": 2,
      "name": "Plant_Vine_Liana",
      "support": 15,
      "rotation": 3
    },
    {
      "x": -14,
      "y": 50,
      "z": 2,
      "name": "Plant_Vine_Liana",
      "support": 15,
      "rotation": 3
    },
    {
      "x": -14,
      "y": 54,
      "z": 2,
      "name": "Plant_Leaves_Beech",
      "support": 15
    },
    {
      "x": -14,
      "y": 55,
      "z": 2,
      "name": "Plant_Leaves_Beech",
      "support": 15
    },
    {
      "x": -14,
      "y": 2,
      "z": 3,
      "name": "Wood_Sallow_Roots"
    },
    {
      "x": -14,
      "y": 3,
      "z": 3,
      "name": "Wood_Sallow_Trunk_Full",
      "support": 15
    },
    {
      "x": -14,
      "y": 4,
      "z": 3,
      "name": "Wood_Sallow_Trunk",
      "support": 15
    },
    {
      "x": -14,
      "y": 5,
      "z": 3,
      "name": "Wood_Sallow_Trunk",
      "support": 15
    },
    {
      "x": -14,
      "y": 6,
      "z": 3,
      "name": "Wood_Sallow_Trunk",
      "support": 15
    },
    {
      "x": -14,
      "y": 7,
      "z": 3,
      "name": "Wood_Sallow_Trunk",
      "support": 15
    },
    {
      "x": -14,
      "y": 8,
      "z": 3,
      "name": "Wood_Sallow_Trunk_Full",
      "support": 15
    },
    {
      "x": -14,
      "y": 54,
      "z": 3,
      "name": "Wood_Sallow_Branch_Corner",
      "support": 15,
      "rotation": 24
    },
    {
      "x": -14,
      "y": 54,
      "z": 4,
      "name": "Wood_Sallow_Branch_Corner",
      "support": 15,
      "rotation": 19
    },
    {
      "x": -14,
      "y": 20,
      "z": 5,
      "name": "Plant_Vine_Liana_End",
      "support": 15,
      "rotation": 3
    },
    {
      "x": -14,
      "y": 21,
      "z": 5,
      "name": "Plant_Vine_Liana",
      "support": 15,
      "rotation": 3
    },
    {
      "x": -14,
      "y": 22,
      "z": 5,
      "name": "Plant_Vine_Liana",
      "support": 15,
      "rotation": 3
    },
    {
      "x": -14,
      "y": 23,
      "z": 5,
      "name": "Plant_Vine_Liana",
      "support": 15,
      "rotation": 3
    },
    {
      "x": -14,
      "y": 24,
      "z": 5,
      "name": "Plant_Vine_Liana",
      "support": 15,
      "rotation": 3
    },
    {
      "x": -14,
      "y": 25,
      "z": 5,
      "name": "Plant_Vine_Liana",
      "support": 15,
      "rotation": 3
    },
    {
      "x": -14,
      "y": 26,
      "z": 5,
      "name": "Plant_Vine_Liana",
      "support": 15,
      "rotation": 3
    },
    {
      "x": -14,
      "y": 27,
      "z": 5,
      "name": "Plant_Vine_Liana_End",
      "support": 15,
      "rotation": 3
    },
    {
      "x": -14,
      "y": 58,
      "z": 5,
      "name": "Plant_Leaves_Beech",
      "support": 15
    },
    {
      "x": -14,
      "y": 59,
      "z": 5,
      "name": "Plant_Leaves_Beech",
      "support": 15
    },
    {
      "x": -14,
      "y": 27,
      "z": 6,
      "name": "Plant_Moss_Wall_Green_Dark",
      "support": 15,
      "rotation": 3
    },
    {
      "x": -14,
      "y": 54,
      "z": 6,
      "name": "Wood_Sallow_Trunk",
      "support": 15,
      "rotation": 5
    },
    {
      "x": -14,
      "y": 55,
      "z": 6,
      "name": "Plant_Leaves_Beech",
      "support": 15
    },
    {
      "x": -14,
      "y": 56,
      "z": 6,
      "name": "Plant_Leaves_Beech",
      "support": 15
    },
    {
      "x": -14,
      "y": 57,
      "z": 6,
      "name": "Plant_Leaves_Beech",
      "support": 15
    },
    {
      "x": -14,
      "y": 58,
      "z": 6,
      "name": "Wood_Sallow_Branch_Corner",
      "support": 15,
      "rotation": 3
    },
    {
      "x": -14,
      "y": 59,
      "z": 6,
      "name": "Wood_Sallow_Branch_Long",
      "support": 15
    },
    {
      "x": -14,
      "y": 60,
      "z": 6,
      "name": "Plant_Leaves_Beech",
      "support": 15
    },
    {
      "x": -14,
      "y": 54,
      "z": 7,
      "name": "Wood_Sallow_Branch_Long",
      "support": 15,
      "rotation": 4
    },
    {
      "x": -14,
      "y": 58,
      "z": 7,
      "name": "Plant_Leaves_Beech",
      "support": 15
    },
    {
      "x": -14,
      "y": 59,
      "z": 7,
      "name": "Plant_Leaves_Beech",
      "support": 15
    },
    {
      "x": -14,
      "y": 54,
      "z": 8,
      "name": "Wood_Sallow_Branch_Long",
      "support": 15,
      "rotation": 4
    },
    {
      "x": -14,
      "y": 54,
      "z": 9,
      "name": "Wood_Sallow_Branch_Corner",
      "support": 15
    },
    {
      "x": -14,
      "y": 55,
      "z": 9,
      "name": "Wood_Sallow_Branch_Corner",
      "support": 15,
      "rotation": 8
    },
    {
      "x": -14,
      "y": 58,
      "z": 9,
      "name": "Plant_Leaves_Beech",
      "support": 15
    },
    {
      "x": -14,
      "y": 59,
      "z": 9,
      "name": "Plant_Leaves_Beech",
      "support": 15
    },
    {
      "x": -14,
      "y": 54,
      "z": 10,
      "name": "Plant_Leaves_Beech",
      "support": 15
    },
    {
      "x": -14,
      "y": 55,
      "z": 10,
      "name": "Wood_Sallow_Branch_Long",
      "support": 15,
      "rotation": 4
    },
    {
      "x": -14,
      "y": 56,
      "z": 10,
      "name": "Plant_Leaves_Beech",
      "support": 15
    },
    {
      "x": -14,
      "y": 54,
      "z": 11,
      "name": "Plant_Leaves_Beech",
      "support": 15
    },
    {
      "x": -14,
      "y": 55,
      "z": 11,
      "name": "Wood_Sallow_Branch_Corner",
      "support": 15
    },
    {
      "x": -14,
      "y": 56,
      "z": 11,
      "name": "Wood_Sallow_Branch_Long",
      "support": 15
    },
    {
      "x": -14,
      "y": 57,
      "z": 11,
      "name": "Plant_Leaves_Beech",
      "support": 15
    },
    {
      "x": -14,
      "y": 55,
      "z": 12,
      "name": "Plant_Leaves_Beech",
      "support": 15
    },
    {
      "x": -14,
      "y": 56,
      "z": 12,
      "name": "Plant_Leaves_Beech",
      "support": 15
    },
    {
      "x": -13,
      "y": 54,
      "z": -4,
      "name": "Plant_Leaves_Beech",
      "support": 15
    },
    {
      "x": -13,
      "y": 55,
      "z": -4,
      "name": "Plant_Leaves_Beech",
      "support": 15
    },
    {
      "x": -13,
      "y": 2,
      "z": -3,
      "name": "Wood_Sallow_Roots"
    },
    {
      "x": -13,
      "y": 3,
      "z": -3,
      "name": "Wood_Sallow_Trunk_Full",
      "support": 15
    },
    {
      "x": -13,
      "y": 4,
      "z": -3,
      "name": "Wood_Sallow_Trunk",
      "support": 15
    },
    {
      "x": -13,
      "y": 5,
      "z": -3,
      "name": "Wood_Sallow_Trunk",
      "support": 15
    },
    {
      "x": -13,
      "y": 6,
      "z": -3,
      "name": "Wood_Sallow_Trunk",
      "support": 15
    },
    {
      "x": -13,
      "y": 7,
      "z": -3,
      "name": "Wood_Sallow_Trunk",
      "support": 15
    },
    {
      "x": -13,
      "y": 8,
      "z": -3,
      "name": "Wood_Sallow_Trunk_Full",
      "support": 15
    },
    {
      "x": -13,
      "y": 53,
      "z": -3,
      "name": "Plant_Leaves_Beech",
      "support": 15
    },
    {
      "x": -13,
      "y": 54,
      "z": -3,
      "name": "Wood_Sallow_Branch_Corner",
      "support": 15,
      "rotation": 3
    },
    {
      "x": -13,
      "y": 55,
      "z": -3,
      "name": "Wood_Sallow_Branch_Long",
      "support": 15
    },
    {
      "x": -13,
      "y": 56,
      "z": -3,
      "name": "Plant_Leaves_Beech",
      "support": 15
    },
    {
      "x": -13,
      "y": 4,
      "z": -2,
      "name": "Wood_Sallow_Roots"
    },
    {
      "x": -13,
      "y": 5,
      "z": -2,
      "name": "Wood_Sallow_Trunk_Full",
      "support": 15
    },
    {
      "x": -13,
      "y": 6,
      "z": -2,
      "name": "Wood_Sallow_Trunk",
      "support": 15
    },
    {
      "x": -13,
      "y": 7,
      "z": -2,
      "name": "Wood_Sallow_Trunk",
      "support": 15
    },
    {
      "x": -13,
      "y": 8,
      "z": -2,
      "name": "Wood_Sallow_Trunk",
      "support": 15
    },
    {
      "x": -13,
      "y": 9,
      "z": -2,
      "name": "Wood_Sallow_Trunk_Full",
      "support": 15
    },
    {
      "x": -13,
      "y": 54,
      "z": -2,
      "name": "Plant_Leaves_Beech",
      "support": 15
    },
    {
      "x": -13,
      "y": 55,
      "z": -2,
      "name": "Plant_Leaves_Beech",
      "support": 15
    },
    {
      "x": -13,
      "y": 10,
      "z": -1,
      "name": "Plant_Moss_Wall_Green_Dark",
      "support": 15,
      "rotation": 3
    },
    {
      "x": -13,
      "y": 60,
      "z": -1,
      "name": "Plant_Leaves_Beech",
      "support": 15
    },
    {
      "x": -13,
      "y": 27,
      "z": 0,
      "name": "Furniture_Crude_Platform",
      "rotation": 1
    },
    {
      "x": -13,
      "y": 28,
      "z": 0,
      "name": "*Wood_Hardwood_Fence_State_Definitions_Corner",
      "rotation": 1
    },
    {
      "x": -13,
      "y": 57,
      "z": 0,
      "name": "Wood_Sallow_Trunk_Full",
      "support": 15,
      "rotation": 5
    },
    {
      "x": -13,
      "y": 58,
      "z": 0,
      "name": "Wood_Sallow_Trunk",
      "support": 15
    },
    {
      "x": -13,
      "y": 59,
      "z": 0,
      "name": "Wood_Sallow_Branch_Long",
      "support": 15
    },
    {
      "x": -13,
      "y": 60,
      "z": 0,
      "name": "Wood_Sallow_Branch_Long",
      "support": 15
    },
    {
      "x": -13,
      "y": 61,
      "z": 0,
      "name": "Plant_Leaves_Beech",
      "support": 15
    },
    {
      "x": -13,
      "y": 27,
      "z": 1,
      "name": "Furniture_Crude_Platform"
    },
    {
      "x": -13,
      "y": 28,
      "z": 1,
      "name": "Wood_Hardwood_Fence",
      "rotation": 3
    },
    {
      "x": -13,
      "y": 43,
      "z": 1,
      "name": "Furniture_Crude_Platform"
    },
    {
      "x": -13,
      "y": 47,
      "z": 1,
      "name": "Furniture_Crude_Platform"
    },
    {
      "x": -13,
      "y": 48,
      "z": 1,
      "name": "*Wood_Hardwood_Fence_State_Definitions_Corner",
      "rotation": 1
    },
    {
      "x": -13,
      "y": 49,
      "z": 1,
      "name": "Wood_Hardwood_Beam"
    },
    {
      "x": -13,
      "y": 50,
      "z": 1,
      "name": "Wood_Hardwood_Beam"
    },
    {
      "x": -13,
      "y": 51,
      "z": 1,
      "name": "*Wood_Tropicalwood_Roof_State_Definitions_Corner_Right",
      "rotation": 3
    },
    {
      "x": -13,
      "y": 60,
      "z": 1,
      "name": "Plant_Leaves_Beech",
      "support": 15
    },
    {
      "x": -13,
      "y": 27,
      "z": 2,
      "name": "Furniture_Crude_Platform"
    },
    {
      "x": -13,
      "y": 28,
      "z": 2,
      "name": "Wood_Hardwood_Fence",
      "rotation": 3
    },
    {
      "x": -13,
      "y": 43,
      "z": 2,
      "name": "Furniture_Crude_Platform"
    },
    {
      "x": -13,
      "y": 47,
      "z": 2,
      "name": "Furniture_Crude_Platform"
    },
    {
      "x": -13,
      "y": 48,
      "z": 2,
      "name": "Wood_Hardwood_Fence",
      "rotation": 3
    },
    {
      "x": -13,
      "y": 50,
      "z": 2,
      "name": "Wood_Tropicalwood_Planks"
    },
    {
      "x": -13,
      "y": 51,
      "z": 2,
      "name": "Wood_Tropicalwood_Roof",
      "rotation": 3
    },
    {
      "x": -13,
      "y": 4,
      "z": 3,
      "name": "Wood_Sallow_Roots"
    },
    {
      "x": -13,
      "y": 5,
      "z": 3,
      "name": "Wood_Sallow_Trunk_Full",
      "support": 15
    },
    {
      "x": -13,
      "y": 6,
      "z": 3,
      "name": "Wood_Sallow_Trunk",
      "support": 15
    },
    {
      "x": -13,
      "y": 7,
      "z": 3,
      "name": "Wood_Sallow_Trunk",
      "support": 15
    },
    {
      "x": -13,
      "y": 8,
      "z": 3,
      "name": "Wood_Sallow_Trunk",
      "support": 15
    },
    {
      "x": -13,
      "y": 9,
      "z": 3,
      "name": "Wood_Sallow_Trunk_Full",
      "support": 15
    },
    {
      "x": -13,
      "y": 27,
      "z": 3,
      "name": "Furniture_Crude_Platform"
    },
    {
      "x": -13,
      "y": 28,
      "z": 3,
      "name": "Wood_Hardwood_Fence",
      "rotation": 3
    },
    {
      "x": -13,
      "y": 43,
      "z": 3,
      "name": "Furniture_Crude_Platform"
    },
    {
      "x": -13,
      "y": 47,
      "z": 3,
      "name": "Furniture_Crude_Platform"
    },
    {
      "x": -13,
      "y": 48,
      "z": 3,
      "name": "Wood_Hardwood_Fence",
      "rotation": 3
    },
    {
      "x": -13,
      "y": 51,
      "z": 3,
      "name": "Wood_Tropicalwood_Roof_Hollow",
      "rotation": 3
    },
    {
      "x": -13,
      "y": 10,
      "z": 4,
      "name": "Plant_Moss_Wall_Green_Dark",
      "support": 15,
      "rotation": 3
    },
    {
      "x": -13,
      "y": 27,
      "z": 4,
      "name": "Furniture_Crude_Platform"
    },
    {
      "x": -13,
      "y": 28,
      "z": 4,
      "name": "Wood_Hardwood_Fence",
      "rotation": 3
    },
    {
      "x": -13,
      "y": 43,
      "z": 4,
      "name": "Furniture_Crude_Platform"
    },
    {
      "x": -13,
      "y": 47,
      "z": 4,
      "name": "Furniture_Crude_Platform"
    },
    {
      "x": -13,
      "y": 48,
      "z": 4,
      "name": "Wood_Hardwood_Fence",
      "rotation": 3
    },
    {
      "x": -13,
      "y": 51,
      "z": 4,
      "name": "Wood_Tropicalwood_Roof_Hollow",
      "rotation": 3
    },
    {
      "x": -13,
      "y": 54,
      "z": 4,
      "name": "Wood_Sallow_Branch_Corner",
      "support": 15,
      "rotation": 24
    },
    {
      "x": -13,
      "y": 58,
      "z": 4,
      "name": "Plant_Leaves_Beech",
      "support": 15
    },
    {
      "x": -13,
      "y": 59,
      "z": 4,
      "name": "Plant_Leaves_Beech",
      "support": 15
    },
    {
      "x": -13,
      "y": 27,
      "z": 5,
      "name": "Furniture_Crude_Platform"
    },
    {
      "x": -13,
      "y": 28,
      "z": 5,
      "name": "Wood_Hardwood_Fence",
      "rotation": 3
    },
    {
      "x": -13,
      "y": 43,
      "z": 5,
      "name": "Furniture_Crude_Platform"
    },
    {
      "x": -13,
      "y": 47,
      "z": 5,
      "name": "Furniture_Crude_Platform"
    },
    {
      "x": -13,
      "y": 48,
      "z": 5,
      "name": "Wood_Hardwood_Fence",
      "rotation": 3
    },
    {
      "x": -13,
      "y": 51,
      "z": 5,
      "name": "Wood_Tropicalwood_Roof_Hollow",
      "rotation": 3
    },
    {
      "x": -13,
      "y": 52,
      "z": 5,
      "name": "Plant_Vine_Liana",
      "support": 15,
      "rotation": 3
    },
    {
      "x": -13,
      "y": 53,
      "z": 5,
      "name": "Plant_Vine_Liana_End",
      "support": 15,
      "rotation": 3
    },
    {
      "x": -13,
      "y": 54,
      "z": 5,
      "name": "Wood_Sallow_Branch_Long",
      "support": 15,
      "rotation": 4
    },
    {
      "x": -13,
      "y": 55,
      "z": 5,
      "name": "Plant_Leaves_Beech",
      "support": 15
    },
    {
      "x": -13,
      "y": 56,
      "z": 5,
      "name": "Plant_Leaves_Beech",
      "support": 15
    },
    {
      "x": -13,
      "y": 58,
      "z": 5,
      "name": "Plant_Leaves_Beech",
      "support": 15
    },
    {
      "x": -13,
      "y": 27,
      "z": 6,
      "name": "Furniture_Crude_Platform"
    },
    {
      "x": -13,
      "y": 28,
      "z": 6,
      "name": "*Wood_Hardwood_Fence_State_Definitions_Corner",
      "rotation": 2
    },
    {
      "x": -13,
      "y": 43,
      "z": 6,
      "name": "Furniture_Crude_Platform"
    },
    {
      "x": -13,
      "y": 47,
      "z": 6,
      "name": "Furniture_Crude_Platform"
    },
    {
      "x": -13,
      "y": 48,
      "z": 6,
      "name": "Wood_Hardwood_Fence",
      "rotation": 3
    },
    {
      "x": -13,
      "y": 51,
      "z": 6,
      "name": "Wood_Tropicalwood_Roof_Hollow",
      "rotation": 3
    },
    {
      "x": -13,
      "y": 54,
      "z": 6,
      "name": "Wood_Sallow_Trunk",
      "support": 15,
      "rotation": 5
    },
    {
      "x": -13,
      "y": 55,
      "z": 6,
      "name": "Wood_Sallow_Branch_Corner",
      "support": 15,
      "rotation": 3
    },
    {
      "x": -13,
      "y": 56,
      "z": 6,
      "name": "Wood_Sallow_Branch_Long",
      "support": 15
    },
    {
      "x": -13,
      "y": 57,
      "z": 6,
      "name": "Plant_Leaves_Beech",
      "support": 15
    },
    {
      "x": -13,
      "y": 58,
      "z": 6,
      "name": "Wood_Sallow_Branch_Long",
      "support": 15,
      "rotation": 5
    },
    {
      "x": -13,
      "y": 59,
      "z": 6,
      "name": "Plant_Leaves_Beech",
      "support": 15
    },
    {
      "x": -13,
      "y": 43,
      "z": 7,
      "name": "Furniture_Crude_Platform",
      "rotation": 1
    },
    {
      "x": -13,
      "y": 47,
      "z": 7,
      "name": "Furniture_Crude_Platform"
    },
    {
      "x": -13,
      "y": 48,
      "z": 7,
      "name": "*Wood_Hardwood_Fence_State_Definitions_Corner",
      "rotation": 2
    },
    {
      "x": -13,
      "y": 49,
      "z": 7,
      "name": "Wood_Hardwood_Beam"
    },
    {
      "x": -13,
      "y": 50,
      "z": 7,
      "name": "Wood_Hardwood_Beam"
    },
    {
      "x": -13,
      "y": 51,
      "z": 7,
      "name": "*Wood_Tropicalwood_Roof_State_Definitions_Corner_Right"
    },
    {
      "x": -13,
      "y": 55,
      "z": 7,
      "name": "Plant_Leaves_Beech",
      "support": 15
    },
    {
      "x": -13,
      "y": 56,
      "z": 7,
      "name": "Plant_Leaves_Beech",
      "support": 15
    },
    {
      "x": -13,
      "y": 58,
      "z": 7,
      "name": "Plant_Leaves_Beech",
      "support": 15
    },
    {
      "x": -13,
      "y": 43,
      "z": 8,
      "name": "Plant_Moss_Wall_Green_Dark",
      "support": 15,
      "rotation": 3
    },
    {
      "x": -13,
      "y": 58,
      "z": 8,
      "name": "Plant_Leaves_Beech",
      "support": 15
    },
    {
      "x": -13,
      "y": 59,
      "z": 8,
      "name": "Plant_Leaves_Beech",
      "support": 15
    },
    {
      "x": -13,
      "y": 1,
      "z": 9,
      "name": "Wood_Sallow_Roots"
    },
    {
      "x": -13,
      "y": 2,
      "z": 9,
      "name": "Wood_Sallow_Trunk_Full",
      "support": 15
    },
    {
      "x": -13,
      "y": 3,
      "z": 9,
      "name": "Wood_Sallow_Trunk",
      "support": 15
    },
    {
      "x": -13,
      "y": 4,
      "z": 9,
      "name": "Wood_Sallow_Trunk",
      "support": 15
    },
    {
      "x": -13,
      "y": 5,
      "z": 9,
      "name": "Wood_Sallow_Trunk",
      "support": 15
    },
    {
      "x": -13,
      "y": 6,
      "z": 9,
      "name": "Wood_Sallow_Trunk",
      "support": 15
    },
    {
      "x": -13,
      "y": 7,
      "z": 9,
      "name": "Wood_Sallow_Trunk",
      "support": 15
    },
    {
      "x": -13,
      "y": 8,
      "z": 9,
      "name": "Wood_Sallow_Trunk_Full",
      "support": 15
    },
    {
      "x": -13,
      "y": 9,
      "z": 9,
      "name": "Plant_Moss_Rug_Green_Dark",
      "support": 15
    },
    {
      "x": -13,
      "y": 58,
      "z": 9,
      "name": "Wood_Sallow_Branch_Corner",
      "support": 15,
      "rotation": 3
    },
    {
      "x": -13,
      "y": 59,
      "z": 9,
      "name": "Wood_Sallow_Branch_Long",
      "support": 15
    },
    {
      "x": -13,
      "y": 60,
      "z": 9,
      "name": "Plant_Leaves_Beech",
      "support": 15
    },
    {
      "x": -13,
      "y": 58,
      "z": 10,
      "name": "Plant_Leaves_Beech",
      "support": 15
    },
    {
      "x": -13,
      "y": 59,
      "z": 10,
      "name": "Plant_Leaves_Beech",
      "support": 15
    },
    {
      "x": -13,
      "y": 55,
      "z": 11,
      "name": "Plant_Leaves_Beech",
      "support": 15
    },
    {
      "x": -13,
      "y": 56,
      "z": 11,
      "name": "Plant_Leaves_Beech",
      "support": 15
    },
    {
      "x": -12,
      "y": 55,
      "z": -5,
      "name": "Plant_Leaves_Beech",
      "support": 15
    },
    {
      "x": -12,
      "y": 56,
      "z": -5,
      "name": "Plant_Leaves_Beech",
      "support": 15
    },
    {
      "x": -12,
      "y": 54,
      "z": -4,
      "name": "Plant_Leaves_Beech",
      "support": 15
    },
    {
      "x": -12,
      "y": 53,
      "z": -3,
      "name": "Plant_Leaves_Beech",
      "support": 15
    },
    {
      "x": -12,
      "y": 54,
      "z": -3,
      "name": "Wood_Sallow_Branch_Long",
      "support": 15,
      "rotation": 5
    },
    {
      "x": -12,
      "y": 55,
      "z": -3,
      "name": "Plant_Leaves_Beech",
      "support": 15
    },
    {
      "x": -12,
      "y": 54,
      "z": -2,
      "name": "Plant_Leaves_Beech",
      "support": 15
    },
    {
      "x": -12,
      "y": 57,
      "z": -2,
      "name": "Plant_Leaves_Beech",
      "support": 15
    },
    {
      "x": -12,
      "y": 58,
      "z": -2,
      "name": "Plant_Leaves_Beech",
      "support": 15
    },
    {
      "x": -12,
      "y": 4,
      "z": -1,
      "name": "Wood_Sallow_Roots"
    },
    {
      "x": -12,
      "y": 5,
      "z": -1,
      "name": "Wood_Sallow_Trunk_Full",
      "support": 15
    },
    {
      "x": -12,
      "y": 6,
      "z": -1,
      "name": "Wood_Sallow_Trunk",
      "support": 15
    },
    {
      "x": -12,
      "y": 7,
      "z": -1,
      "name": "Wood_Sallow_Trunk",
      "support": 15
    },
    {
      "x": -12,
      "y": 8,
      "z": -1,
      "name": "Wood_Sallow_Trunk",
      "support": 15
    },
    {
      "x": -12,
      "y": 9,
      "z": -1,
      "name": "Wood_Sallow_Trunk",
      "support": 15
    },
    {
      "x": -12,
      "y": 10,
      "z": -1,
      "name": "Wood_Sallow_Trunk_Full",
      "support": 15
    },
    {
      "x": -12,
      "y": 11,
      "z": -1,
      "name": "Plant_Moss_Rug_Green_Dark",
      "support": 15
    },
    {
      "x": -12,
      "y": 27,
      "z": -1,
      "name": "Furniture_Crude_Platform",
      "rotation": 1
    },
    {
      "x": -12,
      "y": 28,
      "z": -1,
      "name": "*Wood_Hardwood_Fence_State_Definitions_Corner",
      "rotation": 1
    },
    {
      "x": -12,
      "y": 57,
      "z": -1,
      "name": "Plant_Leaves_Beech",
      "support": 15
    },
    {
      "x": -12,
      "y": 62,
      "z": -1,
      "name": "Plant_Leaves_Beech",
      "support": 15
    },
    {
      "x": -12,
      "y": 63,
      "z": -1,
      "name": "Plant_Leaves_Beech",
      "support": 15
    },
    {
      "x": -12,
      "y": 10,
      "z": 0,
      "name": "Plant_Moss_Wall_Green_Dark",
      "support": 15
    },
    {
      "x": -12,
      "y": 27,
      "z": 0,
      "name": "Furniture_Crude_Platform",
      "rotation": 1
    },
    {
      "x": -12,
      "y": 28,
      "z": 0,
      "name": "*Wood_Hardwood_Fence_State_Definitions_Corner",
      "rotation": 3
    },
    {
      "x": -12,
      "y": 43,
      "z": 0,
      "name": "Furniture_Crude_Platform"
    },
    {
      "x": -12,
      "y": 47,
      "z": 0,
      "name": "Furniture_Crude_Platform"
    },
    {
      "x": -12,
      "y": 48,
      "z": 0,
      "name": "*Wood_Hardwood_Fence_State_Definitions_Corner",
      "rotation": 1
    },
    {
      "x": -12,
      "y": 49,
      "z": 0,
      "name": "Wood_Hardwood_Beam"
    },
    {
      "x": -12,
      "y": 50,
      "z": 0,
      "name": "Wood_Hardwood_Beam"
    },
    {
      "x": -12,
      "y": 51,
      "z": 0,
      "name": "*Wood_Tropicalwood_Roof_State_Definitions_Corner_Right",
      "rotation": 3
    },
    {
      "x": -12,
      "y": 57,
      "z": 0,
      "name": "Wood_Sallow_Trunk_Full",
      "support": 15,
      "rotation": 5
    },
    {
      "x": -12,
      "y": 27,
      "z": 1,
      "name": "Wood_Goldenwood_Planks_Half",
      "rotation": 8
    },
    {
      "x": -12,
      "y": 43,
      "z": 1,
      "name": "Furniture_Crude_Platform",
      "rotation": 1
    },
    {
      "x": -12,
      "y": 47,
      "z": 1,
      "name": "Furniture_Crude_Platform",
      "rotation": 1
    },
    {
      "x": -12,
      "y": 48,
      "z": 1,
      "name": "*Wood_Hardwood_Fence_State_Definitions_Corner",
      "rotation": 3
    },
    {
      "x": -12,
      "y": 51,
      "z": 1,
      "name": "*Wood_Tropicalwood_Roof_Hollow_State_Definitions_Inverted_Corner_Left",
      "rotation": 2
    },
    {
      "x": -12,
      "y": 56,
      "z": 1,
      "name": "Wood_Sallow_Trunk_Full",
      "support": 15,
      "rotation": 5
    },
    {
      "x": -12,
      "y": 57,
      "z": 1,
      "name": "Wood_Sallow_Trunk_Full",
      "support": 15,
      "rotation": 4
    },
    {
      "x": -12,
      "y": 27,
      "z": 2,
      "name": "Wood_Goldenwood_Planks_Half",
      "rotation": 8
    },
    {
      "x": -12,
      "y": 43,
      "z": 2,
      "name": "Wood_Goldenwood_Planks_Half",
      "rotation": 8
    },
    {
      "x": -12,
      "y": 44,
      "z": 2,
      "name": "*Wood_Softwood_Fence_State_Definitions_Corner",
      "rotation": 1
    },
    {
      "x": -12,
      "y": 45,
      "z": 2,
      "name": "*Wood_Softwood_Fence_State_Definitions_Corner",
      "rotation": 1
    },
    {
      "x": -12,
      "y": 46,
      "z": 2,
      "name": "*Wood_Softwood_Fence_State_Definitions_Corner",
      "rotation": 1
    },
    {
      "x": -12,
      "y": 47,
      "z": 2,
      "name": "*Wood_Goldenwood_Stairs_State_Definitions_Corner_Right",
      "rotation": 8
    },
    {
      "x": -12,
      "y": 52,
      "z": 2,
      "name": "Wood_Tropicalwood_Roof_Flat",
      "rotation": 1
    },
    {
      "x": -12,
      "y": 27,
      "z": 3,
      "name": "Wood_Goldenwood_Planks_Half",
      "rotation": 8
    },
    {
      "x": -12,
      "y": 43,
      "z": 3,
      "name": "Wood_Goldenwood_Planks_Half",
      "rotation": 8
    },
    {
      "x": -12,
      "y": 44,
      "z": 3,
      "name": "Wood_Softwood_Fence",
      "rotation": 3
    },
    {
      "x": -12,
      "y": 45,
      "z": 3,
      "name": "Wood_Softwood_Fence",
      "rotation": 3
    },
    {
      "x": -12,
      "y": 46,
      "z": 3,
      "name": "Wood_Softwood_Fence",
      "rotation": 3
    },
    {
      "x": -12,
      "y": 47,
      "z": 3,
      "name": "Wood_Goldenwood_Stairs",
      "rotation": 9
    },
    {
      "x": -12,
      "y": 52,
      "z": 3,
      "name": "Wood_Tropicalwood_Roof_Flat",
      "rotation": 1
    },
    {
      "x": -12,
      "y": 58,
      "z": 3,
      "name": "Plant_Leaves_Beech",
      "support": 15
    },
    {
      "x": -12,
      "y": 59,
      "z": 3,
      "name": "Plant_Leaves_Beech",
      "support": 15
    },
    {
      "x": -12,
      "y": 5,
      "z": 4,
      "name": "Wood_Sallow_Roots"
    },
    {
      "x": -12,
      "y": 6,
      "z": 4,
      "name": "Wood_Sallow_Trunk_Full",
      "support": 15
    },
    {
      "x": -12,
      "y": 7,
      "z": 4,
      "name": "Wood_Sallow_Trunk",
      "support": 15
    },
    {
      "x": -12,
      "y": 8,
      "z": 4,
      "name": "Wood_Sallow_Trunk",
      "support": 15
    },
    {
      "x": -12,
      "y": 9,
      "z": 4,
      "name": "Wood_Sallow_Trunk",
      "support": 15
    },
    {
      "x": -12,
      "y": 10,
      "z": 4,
      "name": "Wood_Sallow_Trunk_Full",
      "support": 15
    },
    {
      "x": -12,
      "y": 11,
      "z": 4,
      "name": "Plant_Moss_Rug_Green_Dark",
      "support": 15
    },
    {
      "x": -12,
      "y": 27,
      "z": 4,
      "name": "Wood_Goldenwood_Planks_Half",
      "rotation": 8
    },
    {
      "x": -12,
      "y": 43,
      "z": 4,
      "name": "Wood_Goldenwood_Planks_Half",
      "rotation": 8
    },
    {
      "x": -12,
      "y": 44,
      "z": 4,
      "name": "Wood_Softwood_Fence",
      "rotation": 3
    },
    {
      "x": -12,
      "y": 45,
      "z": 4,
      "name": "Wood_Goldenwood_Fence",
      "rotation": 3
    },
    {
      "x": -12,
      "y": 46,
      "z": 4,
      "name": "Wood_Softwood_Fence",
      "rotation": 3
    },
    {
      "x": -12,
      "y": 47,
      "z": 4,
      "name": "Wood_Goldenwood_Stairs",
      "rotation": 9
    },
    {
      "x": -12,
      "y": 52,
      "z": 4,
      "name": "Wood_Tropicalwood_Roof_Flat",
      "rotation": 1
    },
    {
      "x": -12,
      "y": 57,
      "z": 4,
      "name": "Plant_Leaves_Beech",
      "support": 15
    },
    {
      "x": -12,
      "y": 58,
      "z": 4,
      "name": "Wood_Sallow_Branch_Corner",
      "support": 15,
      "rotation": 3
    },
    {
      "x": -12,
      "y": 59,
      "z": 4,
      "name": "Wood_Sallow_Branch_Long",
      "support": 15
    },
    {
      "x": -12,
      "y": 60,
      "z": 4,
      "name": "Plant_Leaves_Beech",
      "support": 15
    },
    {
      "x": -12,
      "y": 27,
      "z": 5,
      "name": "Wood_Goldenwood_Planks_Half",
      "rotation": 8
    },
    {
      "x": -12,
      "y": 43,
      "z": 5,
      "name": "Wood_Goldenwood_Planks_Half",
      "rotation": 8
    },
    {
      "x": -12,
      "y": 44,
      "z": 5,
      "name": "Wood_Softwood_Fence",
      "rotation": 3
    },
    {
      "x": -12,
      "y": 45,
      "z": 5,
      "name": "Wood_Softwood_Fence",
      "rotation": 3
    },
    {
      "x": -12,
      "y": 46,
      "z": 5,
      "name": "Wood_Softwood_Fence",
      "rotation": 3
    },
    {
      "x": -12,
      "y": 47,
      "z": 5,
      "name": "Wood_Goldenwood_Stairs",
      "rotation": 9
    },
    {
      "x": -12,
      "y": 52,
      "z": 5,
      "name": "Wood_Tropicalwood_Roof_Flat",
      "rotation": 1
    },
    {
      "x": -12,
      "y": 53,
      "z": 5,
      "name": "Wood_Sallow_Trunk_Full",
      "support": 15,
      "rotation": 5
    },
    {
      "x": -12,
      "y": 55,
      "z": 5,
      "name": "Plant_Leaves_Beech",
      "support": 15
    },
    {
      "x": -12,
      "y": 58,
      "z": 5,
      "name": "Plant_Leaves_Beech",
      "support": 15
    },
    {
      "x": -12,
      "y": 59,
      "z": 5,
      "name": "Plant_Leaves_Beech",
      "support": 15
    },
    {
      "x": -12,
      "y": 27,
      "z": 6,
      "name": "Furniture_Crude_Platform"
    },
    {
      "x": -12,
      "y": 28,
      "z": 6,
      "name": "*Wood_Hardwood_Fence_State_Definitions_Corner"
    },
    {
      "x": -12,
      "y": 43,
      "z": 6,
      "name": "Wood_Goldenwood_Planks_Half",
      "rotation": 8
    },
    {
      "x": -12,
      "y": 44,
      "z": 6,
      "name": "*Wood_Softwood_Fence_State_Definitions_Corner",
      "rotation": 2
    },
    {
      "x": -12,
      "y": 45,
      "z": 6,
      "name": "*Wood_Softwood_Fence_State_Definitions_Corner",
      "rotation": 2
    },
    {
      "x": -12,
      "y": 46,
      "z": 6,
      "name": "*Wood_Softwood_Fence_State_Definitions_Corner",
      "rotation": 2
    },
    {
      "x": -12,
      "y": 47,
      "z": 6,
      "name": "*Wood_Goldenwood_Stairs_State_Definitions_Corner_Right",
      "rotation": 9
    },
    {
      "x": -12,
      "y": 52,
      "z": 6,
      "name": "Wood_Tropicalwood_Roof_Flat",
      "rotation": 1
    },
    {
      "x": -12,
      "y": 53,
      "z": 6,
      "name": "Wood_Sallow_Trunk_Full",
      "support": 15,
      "rotation": 4
    },
    {
      "x": -12,
      "y": 54,
      "z": 6,
      "name": "Wood_Sallow_Trunk_Full",
      "support": 15,
      "rotation": 5
    },
    {
      "x": -12,
      "y": 55,
      "z": 6,
      "name": "Wood_Sallow_Branch_Corner",
      "support": 15,
      "rotation": 11
    },
    {
      "x": -12,
      "y": 56,
      "z": 6,
      "name": "Plant_Leaves_Beech",
      "support": 15
    },
    {
      "x": -12,
      "y": 58,
      "z": 6,
      "name": "Wood_Sallow_Branch_Long",
      "support": 15,
      "rotation": 5
    },
    {
      "x": -12,
      "y": 27,
      "z": 7,
      "name": "Furniture_Crude_Platform",
      "rotation": 1
    },
    {
      "x": -12,
      "y": 28,
      "z": 7,
      "name": "*Wood_Hardwood_Fence_State_Definitions_Corner",
      "rotation": 2
    },
    {
      "x": -12,
      "y": 43,
      "z": 7,
      "name": "Furniture_Crude_Platform"
    },
    {
      "x": -12,
      "y": 47,
      "z": 7,
      "name": "Furniture_Crude_Platform"
    },
    {
      "x": -12,
      "y": 48,
      "z": 7,
      "name": "*Wood_Hardwood_Fence_State_Definitions_Corner"
    },
    {
      "x": -12,
      "y": 51,
      "z": 7,
      "name": "*Wood_Tropicalwood_Roof_Hollow_State_Definitions_Inverted_Corner_Left",
      "rotation": 3
    },
    {
      "x": -12,
      "y": 55,
      "z": 7,
      "name": "Plant_Leaves_Beech",
      "support": 15
    },
    {
      "x": -12,
      "y": 2,
      "z": 8,
      "name": "Wood_Sallow_Roots"
    },
    {
      "x": -12,
      "y": 3,
      "z": 8,
      "name": "Wood_Sallow_Trunk_Full",
      "support": 15
    },
    {
      "x": -12,
      "y": 4,
      "z": 8,
      "name": "Wood_Sallow_Trunk",
      "support": 15
    },
    {
      "x": -12,
      "y": 5,
      "z": 8,
      "name": "Wood_Sallow_Trunk",
      "support": 15
    },
    {
      "x": -12,
      "y": 6,
      "z": 8,
      "name": "Wood_Sallow_Trunk",
      "support": 15
    },
    {
      "x": -12,
      "y": 7,
      "z": 8,
      "name": "Wood_Sallow_Trunk",
      "support": 15
    },
    {
      "x": -12,
      "y": 8,
      "z": 8,
      "name": "Wood_Sallow_Trunk",
      "support": 15
    },
    {
      "x": -12,
      "y": 9,
      "z": 8,
      "name": "Wood_Sallow_Trunk_Full",
      "support": 15
    },
    {
      "x": -12,
      "y": 10,
      "z": 8,
      "name": "Plant_Moss_Rug_Green_Dark",
      "support": 15
    },
    {
      "x": -12,
      "y": 43,
      "z": 8,
      "name": "Furniture_Crude_Platform"
    },
    {
      "x": -12,
      "y": 44,
      "z": 8,
      "name": "Plant_Moss_Rug_Green_Dark",
      "support": 15
    },
    {
      "x": -12,
      "y": 47,
      "z": 8,
      "name": "Furniture_Crude_Platform",
      "rotation": 1
    },
    {
      "x": -12,
      "y": 48,
      "z": 8,
      "name": "*Wood_Hardwood_Fence_State_Definitions_Corner",
      "rotation": 2
    },
    {
      "x": -12,
      "y": 51,
      "z": 8,
      "name": "*Wood_Tropicalwood_Roof_Hollow_State_Definitions_Corner_Right"
    },
    {
      "x": -12,
      "y": 58,
      "z": 8,
      "name": "Plant_Leaves_Beech",
      "support": 15
    },
    {
      "x": -12,
      "y": 43,
      "z": 9,
      "name": "Plant_Moss_Wall_Green_Dark",
      "support": 15
    },
    {
      "x": -12,
      "y": 52,
      "z": 9,
      "name": "Plant_Leaves_Beech",
      "support": 15
    },
    {
      "x": -12,
      "y": 53,
      "z": 9,
      "name": "Plant_Leaves_Beech",
      "support": 15
    },
    {
      "x": -12,
      "y": 57,
      "z": 9,
      "name": "Plant_Leaves_Beech",
      "support": 15
    },
    {
      "x": -12,
      "y": 58,
      "z": 9,
      "name": "Wood_Sallow_Branch_Long",
      "support": 15,
      "rotation": 5
    },
    {
      "x": -12,
      "y": 59,
      "z": 9,
      "name": "Plant_Leaves_Beech",
      "support": 15
    },
    {
      "x": -12,
      "y": 58,
      "z": 10,
      "name": "Plant_Leaves_Beech",
      "support": 15
    },
    {
      "x": -11,
      "y": 55,
      "z": -6,
      "name": "Plant_Leaves_Beech",
      "support": 15
    },
    {
      "x": -11,
      "y": 56,
      "z": -6,
      "name": "Plant_Leaves_Beech",
      "support": 15
    },
    {
      "x": -11,
      "y": 54,
      "z": -5,
      "name": "Plant_Leaves_Beech",
      "support": 15
    },
    {
      "x": -11,
      "y": 55,
      "z": -5,
      "name": "Wood_Sallow_Branch_Corner",
      "support": 15,
      "rotation": 3
    },
    {
      "x": -11,
      "y": 56,
      "z": -5,
      "name": "Wood_Sallow_Branch_Long",
      "support": 15
    },
    {
      "x": -11,
      "y": 57,
      "z": -5,
      "name": "Plant_Leaves_Beech",
      "support": 15
    },
    {
      "x": -11,
      "y": 55,
      "z": -4,
      "name": "Plant_Leaves_Beech",
      "support": 15
    },
    {
      "x": -11,
      "y": 56,
      "z": -4,
      "name": "Plant_Leaves_Beech",
      "support": 15
    },
    {
      "x": -11,
      "y": 59,
      "z": -4,
      "name": "Plant_Leaves_Beech",
      "support": 15
    },
    {
      "x": -11,
      "y": 60,
      "z": -4,
      "name": "Plant_Leaves_Beech",
      "support": 15
    },
    {
      "x": -11,
      "y": 61,
      "z": -4,
      "name": "Plant_Leaves_Beech",
      "support": 15
    },
    {
      "x": -11,
      "y": 54,
      "z": -3,
      "name": "Wood_Sallow_Branch_Corner",
      "support": 15,
      "rotation": 24
    },
    {
      "x": -11,
      "y": 57,
      "z": -3,
      "name": "Plant_Leaves_Beech",
      "support": 15
    },
    {
      "x": -11,
      "y": 58,
      "z": -3,
      "name": "Plant_Leaves_Beech",
      "support": 15
    },
    {
      "x": -11,
      "y": 60,
      "z": -3,
      "name": "Plant_Leaves_Beech",
      "support": 15
    },
    {
      "x": -11,
      "y": 10,
      "z": -2,
      "name": "Plant_Moss_Wall_Green_Dark",
      "support": 15,
      "rotation": 2
    },
    {
      "x": -11,
      "y": 27,
      "z": -2,
      "name": "Furniture_Crude_Platform",
      "rotation": 1
    },
    {
      "x": -11,
      "y": 28,
      "z": -2,
      "name": "*Wood_Hardwood_Fence_State_Definitions_Corner",
      "rotation": 1
    },
    {
      "x": -11,
      "y": 54,
      "z": -2,
      "name": "Wood_Sallow_Branch_Corner",
      "support": 15,
      "rotation": 19
    },
    {
      "x": -11,
      "y": 56,
      "z": -2,
      "name": "Plant_Leaves_Beech",
      "support": 15
    },
    {
      "x": -11,
      "y": 57,
      "z": -2,
      "name": "Wood_Sallow_Branch_Corner",
      "support": 15,
      "rotation": 2
    },
    {
      "x": -11,
      "y": 58,
      "z": -2,
      "name": "Wood_Sallow_Branch_Long",
      "support": 15
    },
    {
      "x": -11,
      "y": 59,
      "z": -2,
      "name": "Plant_Leaves_Beech",
      "support": 15
    },
    {
      "x": -11,
      "y": 62,
      "z": -2,
      "name": "Plant_Leaves_Beech",
      "support": 15
    },
    {
      "x": -11,
      "y": 63,
      "z": -2,
      "name": "Plant_Leaves_Beech",
      "support": 15
    },
    {
      "x": -11,
      "y": 4,
      "z": -1,
      "name": "Wood_Sallow_Roots"
    },
    {
      "x": -11,
      "y": 5,
      "z": -1,
      "name": "Wood_Sallow_Trunk_Full",
      "support": 15
    },
    {
      "x": -11,
      "y": 6,
      "z": -1,
      "name": "Wood_Sallow_Trunk",
      "support": 15
    },
    {
      "x": -11,
      "y": 7,
      "z": -1,
      "name": "Wood_Sallow_Trunk",
      "support": 15
    },
    {
      "x": -11,
      "y": 8,
      "z": -1,
      "name": "Wood_Sallow_Trunk",
      "support": 15
    },
    {
      "x": -11,
      "y": 9,
      "z": -1,
      "name": "Wood_Sallow_Trunk",
      "support": 15
    },
    {
      "x": -11,
      "y": 10,
      "z": -1,
      "name": "Wood_Sallow_Trunk_Full",
      "support": 15
    },
    {
      "x": -11,
      "y": 11,
      "z": -1,
      "name": "Plant_Moss_Rug_Green_Dark",
      "support": 15
    },
    {
      "x": -11,
      "y": 27,
      "z": -1,
      "name": "Furniture_Crude_Platform",
      "rotation": 1
    },
    {
      "x": -11,
      "y": 28,
      "z": -1,
      "name": "*Wood_Hardwood_Fence_State_Definitions_Corner",
      "rotation": 3
    },
    {
      "x": -11,
      "y": 43,
      "z": -1,
      "name": "Furniture_Crude_Platform"
    },
    {
      "x": -11,
      "y": 56,
      "z": -1,
      "name": "Plant_Leaves_Beech",
      "support": 15
    },
    {
      "x": -11,
      "y": 57,
      "z": -1,
      "name": "Wood_Sallow_Branch_Long",
      "support": 15,
      "rotation": 4
    },
    {
      "x": -11,
      "y": 58,
      "z": -1,
      "name": "Plant_Leaves_Beech",
      "support": 15
    },
    {
      "x": -11,
      "y": 61,
      "z": -1,
      "name": "Plant_Leaves_Beech",
      "support": 15
    },
    {
      "x": -11,
      "y": 62,
      "z": -1,
      "name": "Wood_Sallow_Branch_Corner",
      "support": 15,
      "rotation": 3
    },
    {
      "x": -11,
      "y": 63,
      "z": -1,
      "name": "Wood_Sallow_Branch_Long",
      "support": 15
    },
    {
      "x": -11,
      "y": 64,
      "z": -1,
      "name": "Plant_Leaves_Beech",
      "support": 15
    },
    {
      "x": -11,
      "y": 27,
      "z": 0,
      "name": "Wood_Goldenwood_Planks_Half",
      "rotation": 8
    },
    {
      "x": -11,
      "y": 43,
      "z": 0,
      "name": "Furniture_Crude_Platform",
      "rotation": 1
    },
    {
      "x": -11,
      "y": 47,
      "z": 0,
      "name": "Furniture_Crude_Platform",
      "rotation": 1
    },
    {
      "x": -11,
      "y": 48,
      "z": 0,
      "name": "Wood_Hardwood_Fence",
      "rotation": 2
    },
    {
      "x": -11,
      "y": 51,
      "z": 0,
      "name": "Wood_Tropicalwood_Roof_Hollow",
      "rotation": 2
    },
    {
      "x": -11,
      "y": 57,
      "z": 0,
      "name": "Wood_Sallow_Branch_Corner",
      "support": 15,
      "rotation": 27
    },
    {
      "x": -11,
      "y": 62,
      "z": 0,
      "name": "Plant_Leaves_Beech",
      "support": 15
    },
    {
      "x": -11,
      "y": 63,
      "z": 0,
      "name": "Plant_Leaves_Beech",
      "support": 15
    },
    {
      "x": -11,
      "y": 27,
      "z": 1,
      "name": "Wood_Goldenwood_Planks_Half",
      "rotation": 8
    },
    {
      "x": -11,
      "y": 31,
      "z": 1,
      "name": "Wood_Goldenwood_Planks_Half",
      "rotation": 8
    },
    {
      "x": -11,
      "y": 39,
      "z": 1,
      "name": "Wood_Goldenwood_Planks_Half",
      "rotation": 8
    },
    {
      "x": -11,
      "y": 43,
      "z": 1,
      "name": "Wood_Goldenwood_Planks_Half",
      "rotation": 8
    },
    {
      "x": -11,
      "y": 44,
      "z": 1,
      "name": "*Wood_Softwood_Fence_State_Definitions_Corner",
      "rotation": 1
    },
    {
      "x": -11,
      "y": 45,
      "z": 1,
      "name": "*Wood_Softwood_Fence_State_Definitions_Corner",
      "rotation": 1
    },
    {
      "x": -11,
      "y": 46,
      "z": 1,
      "name": "*Wood_Softwood_Fence_State_Definitions_Corner",
      "rotation": 1
    },
    {
      "x": -11,
      "y": 47,
      "z": 1,
      "name": "*Wood_Goldenwood_Stairs_State_Definitions_Corner_Right",
      "rotation": 8
    },
    {
      "x": -11,
      "y": 52,
      "z": 1,
      "name": "Wood_Tropicalwood_Roof_Flat"
    },
    {
      "x": -11,
      "y": 56,
      "z": 1,
      "name": "Wood_Sallow_Trunk",
      "support": 15,
      "rotation": 5
    },
    {
      "x": -11,
      "y": 27,
      "z": 2,
      "name": "Wood_Goldenwood_Planks_Half",
      "rotation": 8
    },
    {
      "x": -11,
      "y": 31,
      "z": 2,
      "name": "Wood_Goldenwood_Planks_Half"
    },
    {
      "x": -11,
      "y": 39,
      "z": 2,
      "name": "Wood_Goldenwood_Planks_Half"
    },
    {
      "x": -11,
      "y": 43,
      "z": 2,
      "name": "Wood_Goldenwood_Planks_Half",
      "rotation": 8
    },
    {
      "x": -11,
      "y": 44,
      "z": 2,
      "name": "*Wood_Softwood_Fence_State_Definitions_Corner",
      "rotation": 3
    },
    {
      "x": -11,
      "y": 45,
      "z": 2,
      "name": "*Wood_Softwood_Fence_State_Definitions_Corner",
      "rotation": 3
    },
    {
      "x": -11,
      "y": 46,
      "z": 2,
      "name": "*Wood_Softwood_Fence_State_Definitions_Corner",
      "rotation": 3
    },
    {
      "x": -11,
      "y": 47,
      "z": 2,
      "name": "*Wood_Goldenwood_Stairs_State_Definitions_Inverted_Corner_Left",
      "rotation": 9
    },
    {
      "x": -11,
      "y": 52,
      "z": 2,
      "name": "Wood_Tropicalwood_Roof_Flat",
      "rotation": 1
    },
    {
      "x": -11,
      "y": 56,
      "z": 2,
      "name": "Wood_Sallow_Branch_Corner",
      "support": 15
    },
    {
      "x": -11,
      "y": 57,
      "z": 2,
      "name": "Wood_Sallow_Branch_Corner",
      "support": 15,
      "rotation": 8
    },
    {
      "x": -11,
      "y": 11,
      "z": 3,
      "name": "Plant_Moss_Wall_Green_Dark",
      "support": 15,
      "rotation": 2
    },
    {
      "x": -11,
      "y": 25,
      "z": 3,
      "name": "Wood_Sallow_Trunk_Half",
      "rotation": 7
    },
    {
      "x": -11,
      "y": 26,
      "z": 3,
      "name": "Wood_Sallow_Trunk",
      "support": 15
    },
    {
      "x": -11,
      "y": 27,
      "z": 3,
      "name": "*Wood_Goldenwood_Planks_Half_State_Definitions_Block",
      "rotation": 8
    },
    {
      "x": -11,
      "y": 30,
      "z": 3,
      "name": "Wood_Goldenwood_Planks_Half",
      "rotation": 8
    },
    {
      "x": -11,
      "y": 38,
      "z": 3,
      "name": "Wood_Goldenwood_Planks_Half",
      "rotation": 8
    },
    {
      "x": -11,
      "y": 43,
      "z": 3,
      "name": "Wood_Goldenwood_Planks_Half",
      "rotation": 8
    },
    {
      "x": -11,
      "y": 47,
      "z": 3,
      "name": "Wood_Goldenwood_Planks_Half",
      "rotation": 8
    },
    {
      "x": -11,
      "y": 52,
      "z": 3,
      "name": "Wood_Tropicalwood_Roof_Flat",
      "rotation": 1
    },
    {
      "x": -11,
      "y": 57,
      "z": 3,
      "name": "Wood_Sallow_Branch_Long",
      "support": 15,
      "rotation": 4
    },
    {
      "x": -11,
      "y": 58,
      "z": 3,
      "name": "Plant_Leaves_Beech",
      "support": 15
    },
    {
      "x": -11,
      "y": 5,
      "z": 4,
      "name": "Wood_Sallow_Roots"
    },
    {
      "x": -11,
      "y": 6,
      "z": 4,
      "name": "Wood_Sallow_Trunk_Full",
      "support": 15
    },
    {
      "x": -11,
      "y": 7,
      "z": 4,
      "name": "Wood_Sallow_Trunk",
      "support": 15
    },
    {
      "x": -11,
      "y": 8,
      "z": 4,
      "name": "Wood_Sallow_Trunk",
      "support": 15
    },
    {
      "x": -11,
      "y": 9,
      "z": 4,
      "name": "Wood_Sallow_Trunk",
      "support": 15
    },
    {
      "x": -11,
      "y": 10,
      "z": 4,
      "name": "Wood_Sallow_Trunk",
      "support": 15
    },
    {
      "x": -11,
      "y": 11,
      "z": 4,
      "name": "Wood_Sallow_Trunk_Full",
      "support": 15
    },
    {
      "x": -11,
      "y": 12,
      "z": 4,
      "name": "Plant_Moss_Rug_Green_Dark",
      "support": 15
    },
    {
      "x": -11,
      "y": 27,
      "z": 4,
      "name": "Wood_Goldenwood_Planks_Half",
      "rotation": 8
    },
    {
      "x": -11,
      "y": 30,
      "z": 4,
      "name": "Wood_Goldenwood_Planks_Half"
    },
    {
      "x": -11,
      "y": 38,
      "z": 4,
      "name": "Wood_Goldenwood_Planks_Half"
    },
    {
      "x": -11,
      "y": 43,
      "z": 4,
      "name": "Wood_Goldenwood_Planks_Half",
      "rotation": 8
    },
    {
      "x": -11,
      "y": 47,
      "z": 4,
      "name": "Wood_Goldenwood_Planks_Half",
      "rotation": 8
    },
    {
      "x": -11,
      "y": 52,
      "z": 4,
      "name": "Wood_Tropicalwood_Roof_Flat",
      "rotation": 1
    },
    {
      "x": -11,
      "y": 57,
      "z": 4,
      "name": "Wood_Sallow_Branch_Corner",
      "support": 15
    },
    {
      "x": -11,
      "y": 58,
      "z": 4,
      "name": "Wood_Sallow_Branch_Corner",
      "support": 15,
      "rotation": 11
    },
    {
      "x": -11,
      "y": 59,
      "z": 4,
      "name": "Plant_Leaves_Beech",
      "support": 15
    },
    {
      "x": -11,
      "y": 60,
      "z": 4,
      "name": "Plant_Leaves_Beech",
      "support": 15
    },
    {
      "x": -11,
      "y": 61,
      "z": 4,
      "name": "Plant_Leaves_Beech",
      "support": 15
    },
    {
      "x": -11,
      "y": 11,
      "z": 5,
      "name": "Plant_Moss_Wall_Green_Dark",
      "support": 15
    },
    {
      "x": -11,
      "y": 27,
      "z": 5,
      "name": "Wood_Goldenwood_Planks_Half",
      "rotation": 8
    },
    {
      "x": -11,
      "y": 29,
      "z": 5,
      "name": "Wood_Goldenwood_Planks_Half",
      "rotation": 8
    },
    {
      "x": -11,
      "y": 37,
      "z": 5,
      "name": "Wood_Goldenwood_Planks_Half",
      "rotation": 8
    },
    {
      "x": -11,
      "y": 43,
      "z": 5,
      "name": "Wood_Goldenwood_Planks_Half",
      "rotation": 8
    },
    {
      "x": -11,
      "y": 47,
      "z": 5,
      "name": "Wood_Goldenwood_Planks_Half",
      "rotation": 8
    },
    {
      "x": -11,
      "y": 52,
      "z": 5,
      "name": "Wood_Sallow_Trunk_Full",
      "support": 15,
      "rotation": 5
    },
    {
      "x": -11,
      "y": 53,
      "z": 5,
      "name": "Wood_Sallow_Trunk_Full",
      "support": 15,
      "rotation": 5
    },
    {
      "x": -11,
      "y": 58,
      "z": 5,
      "name": "Plant_Leaves_Beech",
      "support": 15
    },
    {
      "x": -11,
      "y": 4,
      "z": 6,
      "name": "Wood_Sallow_Roots"
    },
    {
      "x": -11,
      "y": 5,
      "z": 6,
      "name": "Wood_Sallow_Trunk_Full",
      "support": 15
    },
    {
      "x": -11,
      "y": 6,
      "z": 6,
      "name": "Wood_Sallow_Trunk",
      "support": 15
    },
    {
      "x": -11,
      "y": 7,
      "z": 6,
      "name": "Wood_Sallow_Trunk",
      "support": 15
    },
    {
      "x": -11,
      "y": 8,
      "z": 6,
      "name": "Wood_Sallow_Trunk",
      "support": 15
    },
    {
      "x": -11,
      "y": 9,
      "z": 6,
      "name": "Wood_Sallow_Trunk",
      "support": 15
    },
    {
      "x": -11,
      "y": 10,
      "z": 6,
      "name": "Wood_Sallow_Trunk_Full",
      "support": 15
    },
    {
      "x": -11,
      "y": 27,
      "z": 6,
      "name": "Wood_Goldenwood_Planks_Half",
      "rotation": 8
    },
    {
      "x": -11,
      "y": 43,
      "z": 6,
      "name": "Wood_Goldenwood_Planks_Half",
      "rotation": 8
    },
    {
      "x": -11,
      "y": 44,
      "z": 6,
      "name": "*Wood_Softwood_Fence_State_Definitions_Corner"
    },
    {
      "x": -11,
      "y": 45,
      "z": 6,
      "name": "*Wood_Softwood_Fence_State_Definitions_Corner"
    },
    {
      "x": -11,
      "y": 46,
      "z": 6,
      "name": "*Wood_Softwood_Fence_State_Definitions_Corner"
    },
    {
      "x": -11,
      "y": 47,
      "z": 6,
      "name": "*Wood_Goldenwood_Stairs_State_Definitions_Inverted_Corner_Left",
      "rotation": 10
    },
    {
      "x": -11,
      "y": 52,
      "z": 6,
      "name": "Wood_Tropicalwood_Roof_Flat",
      "rotation": 1
    },
    {
      "x": -11,
      "y": 58,
      "z": 6,
      "name": "Wood_Sallow_Branch_Corner",
      "support": 15,
      "rotation": 24
    },
    {
      "x": -11,
      "y": 3,
      "z": 7,
      "name": "Wood_Sallow_Roots"
    },
    {
      "x": -11,
      "y": 4,
      "z": 7,
      "name": "Wood_Sallow_Trunk_Full",
      "support": 15
    },
    {
      "x": -11,
      "y": 5,
      "z": 7,
      "name": "Wood_Sallow_Trunk",
      "support": 15
    },
    {
      "x": -11,
      "y": 6,
      "z": 7,
      "name": "Wood_Sallow_Trunk",
      "support": 15
    },
    {
      "x": -11,
      "y": 7,
      "z": 7,
      "name": "Wood_Sallow_Trunk",
      "support": 15
    },
    {
      "x": -11,
      "y": 8,
      "z": 7,
      "name": "Wood_Sallow_Trunk",
      "support": 15
    },
    {
      "x": -11,
      "y": 9,
      "z": 7,
      "name": "Wood_Sallow_Trunk",
      "support": 15
    },
    {
      "x": -11,
      "y": 10,
      "z": 7,
      "name": "Wood_Sallow_Trunk_Full",
      "support": 15
    },
    {
      "x": -11,
      "y": 27,
      "z": 7,
      "name": "Furniture_Crude_Platform"
    },
    {
      "x": -11,
      "y": 28,
      "z": 7,
      "name": "*Wood_Hardwood_Fence_State_Definitions_Corner"
    },
    {
      "x": -11,
      "y": 43,
      "z": 7,
      "name": "Wood_Goldenwood_Planks_Half",
      "rotation": 8
    },
    {
      "x": -11,
      "y": 44,
      "z": 7,
      "name": "*Wood_Softwood_Fence_State_Definitions_Corner",
      "rotation": 2
    },
    {
      "x": -11,
      "y": 45,
      "z": 7,
      "name": "*Wood_Softwood_Fence_State_Definitions_Corner",
      "rotation": 2
    },
    {
      "x": -11,
      "y": 46,
      "z": 7,
      "name": "*Wood_Softwood_Fence_State_Definitions_Corner",
      "rotation": 2
    },
    {
      "x": -11,
      "y": 47,
      "z": 7,
      "name": "*Wood_Goldenwood_Stairs_State_Definitions_Corner_Right",
      "rotation": 9
    },
    {
      "x": -11,
      "y": 52,
      "z": 7,
      "name": "Wood_Tropicalwood_Roof_Flat",
      "rotation": 1
    },
    {
      "x": -11,
      "y": 58,
      "z": 7,
      "name": "Wood_Sallow_Branch_Corner",
      "support": 15,
      "rotation": 19
    },
    {
      "x": -11,
      "y": 62,
      "z": 7,
      "name": "Plant_Leaves_Beech",
      "support": 15
    },
    {
      "x": -11,
      "y": 63,
      "z": 7,
      "name": "Plant_Leaves_Beech",
      "support": 15
    },
    {
      "x": -11,
      "y": 27,
      "z": 8,
      "name": "Furniture_Crude_Platform",
      "rotation": 1
    },
    {
      "x": -11,
      "y": 28,
      "z": 8,
      "name": "*Wood_Hardwood_Fence_State_Definitions_Corner",
      "rotation": 2
    },
    {
      "x": -11,
      "y": 43,
      "z": 8,
      "name": "Furniture_Crude_Platform"
    },
    {
      "x": -11,
      "y": 47,
      "z": 8,
      "name": "Furniture_Crude_Platform"
    },
    {
      "x": -11,
      "y": 48,
      "z": 8,
      "name": "*Wood_Hardwood_Fence_State_Definitions_Corner"
    },
    {
      "x": -11,
      "y": 51,
      "z": 8,
      "name": "*Wood_Tropicalwood_Roof_Hollow_State_Definitions_Inverted_Corner_Left",
      "rotation": 3
    },
    {
      "x": -11,
      "y": 52,
      "z": 8,
      "name": "Plant_Leaves_Beech",
      "support": 15
    },
    {
      "x": -11,
      "y": 53,
      "z": 8,
      "name": "Plant_Leaves_Beech",
      "support": 15
    },
    {
      "x": -11,
      "y": 43,
      "z": 9,
      "name": "Furniture_Crude_Platform",
      "rotation": 1
    },
    {
      "x": -11,
      "y": 47,
      "z": 9,
      "name": "Furniture_Crude_Platform",
      "rotation": 1
    },
    {
      "x": -11,
      "y": 48,
      "z": 9,
      "name": "*Wood_Hardwood_Fence_State_Definitions_Corner",
      "rotation": 2
    },
    {
      "x": -11,
      "y": 51,
      "z": 9,
      "name": "*Wood_Tropicalwood_Roof_Hollow_State_Definitions_Corner_Right"
    },
    {
      "x": -11,
      "y": 52,
      "z": 9,
      "name": "Wood_Sallow_Branch_Corner",
      "support": 15,
      "rotation": 3
    },
    {
      "x": -11,
      "y": 53,
      "z": 9,
      "name": "Wood_Sallow_Branch_Long",
      "support": 15
    },
    {
      "x": -11,
      "y": 54,
      "z": 9,
      "name": "Plant_Leaves_Beech",
      "support": 15
    },
    {
      "x": -11,
      "y": 58,
      "z": 9,
      "name": "Wood_Sallow_Trunk",
      "support": 15,
      "rotation": 5
    },
    {
      "x": -11,
      "y": 52,
      "z": 10,
      "name": "Plant_Leaves_Beech",
      "support": 15
    },
    {
      "x": -11,
      "y": 53,
      "z": 10,
      "name": "Plant_Leaves_Beech",
      "support": 15
    },
    {
      "x": -11,
      "y": 58,
      "z": 10,
      "name": "Plant_Leaves_Beech",
      "support": 15
    },
    {
      "x": -11,
      "y": 58,
      "z": 11,
      "name": "Plant_Leaves_Beech",
      "support": 15
    },
    {
      "x": -11,
      "y": 59,
      "z": 11,
      "name": "Plant_Leaves_Beech",
      "support": 15
    },
    {
      "x": -10,
      "y": 55,
      "z": -6,
      "name": "Plant_Leaves_Beech",
      "support": 15
    },
    {
      "x": -10,
      "y": 56,
      "z": -6,
      "name": "Plant_Leaves_Beech",
      "support": 15
    },
    {
      "x": -10,
      "y": 55,
      "z": -5,
      "name": "Wood_Sallow_Branch_Long",
      "support": 15,
      "rotation": 5
    },
    {
      "x": -10,
      "y": 56,
      "z": -5,
      "name": "Plant_Leaves_Beech",
      "support": 15
    },
    {
      "x": -10,
      "y": 60,
      "z": -5,
      "name": "Plant_Leaves_Beech",
      "support": 15
    },
    {
      "x": -10,
      "y": 61,
      "z": -5,
      "name": "Plant_Leaves_Beech",
      "support": 15
    },
    {
      "x": -10,
      "y": 55,
      "z": -4,
      "name": "Plant_Leaves_Beech",
      "support": 15
    },
    {
      "x": -10,
      "y": 59,
      "z": -4,
      "name": "Plant_Leaves_Beech",
      "support": 15
    },
    {
      "x": -10,
      "y": 60,
      "z": -4,
      "name": "Wood_Sallow_Branch_Corner",
      "support": 15,
      "rotation": 2
    },
    {
      "x": -10,
      "y": 61,
      "z": -4,
      "name": "Wood_Sallow_Branch_Long",
      "support": 15
    },
    {
      "x": -10,
      "y": 62,
      "z": -4,
      "name": "Plant_Leaves_Beech",
      "support": 15
    },
    {
      "x": -10,
      "y": 27,
      "z": -3,
      "name": "Furniture_Crude_Platform",
      "rotation": 1
    },
    {
      "x": -10,
      "y": 28,
      "z": -3,
      "name": "*Wood_Hardwood_Fence_State_Definitions_Corner",
      "rotation": 1
    },
    {
      "x": -10,
      "y": 60,
      "z": -3,
      "name": "Wood_Sallow_Branch_Long",
      "support": 15,
      "rotation": 4
    },
    {
      "x": -10,
      "y": 61,
      "z": -3,
      "name": "Plant_Leaves_Beech",
      "support": 15
    },
    {
      "x": -10,
      "y": 27,
      "z": -2,
      "name": "Furniture_Crude_Platform",
      "rotation": 1
    },
    {
      "x": -10,
      "y": 28,
      "z": -2,
      "name": "*Wood_Hardwood_Fence_State_Definitions_Corner",
      "rotation": 3
    },
    {
      "x": -10,
      "y": 54,
      "z": -2,
      "name": "Wood_Sallow_Branch_Long",
      "support": 15,
      "rotation": 5
    },
    {
      "x": -10,
      "y": 57,
      "z": -2,
      "name": "Plant_Leaves_Beech",
      "support": 15
    },
    {
      "x": -10,
      "y": 58,
      "z": -2,
      "name": "Plant_Leaves_Beech",
      "support": 15
    },
    {
      "x": -10,
      "y": 60,
      "z": -2,
      "name": "Wood_Sallow_Branch_Long",
      "support": 15,
      "rotation": 4
    },
    {
      "x": -10,
      "y": 62,
      "z": -2,
      "name": "Plant_Leaves_Beech",
      "support": 15
    },
    {
      "x": -10,
      "y": 10,
      "z": -1,
      "name": "Plant_Moss_Wall_Green_Dark",
      "support": 15,
      "rotation": 1
    },
    {
      "x": -10,
      "y": 27,
      "z": -1,
      "name": "Wood_Goldenwood_Planks_Half",
      "rotation": 8
    },
    {
      "x": -10,
      "y": 43,
      "z": -1,
      "name": "Furniture_Crude_Platform",
      "rotation": 1
    },
    {
      "x": -10,
      "y": 47,
      "z": -1,
      "name": "Plant_Moss_Wall_Green_Dark",
      "support": 15,
      "rotation": 2
    },
    {
      "x": -10,
      "y": 57,
      "z": -1,
      "name": "Plant_Leaves_Beech",
      "support": 15
    },
    {
      "x": -10,
      "y": 60,
      "z": -1,
      "name": "Wood_Sallow_Branch_Corner",
      "support": 15,
      "rotation": 19
    },
    {
      "x": -10,
      "y": 62,
      "z": -1,
      "name": "Wood_Sallow_Branch_Long",
      "support": 15,
      "rotation": 5
    },
    {
      "x": -10,
      "y": 63,
      "z": -1,
      "name": "Plant_Leaves_Beech",
      "support": 15
    },
    {
      "x": -10,
      "y": 5,
      "z": 0,
      "name": "Wood_Sallow_Roots"
    },
    {
      "x": -10,
      "y": 6,
      "z": 0,
      "name": "Wood_Sallow_Trunk_Full",
      "support": 15
    },
    {
      "x": -10,
      "y": 7,
      "z": 0,
      "name": "Wood_Sallow_Trunk",
      "support": 15
    },
    {
      "x": -10,
      "y": 8,
      "z": 0,
      "name": "Wood_Sallow_Trunk",
      "support": 15
    },
    {
      "x": -10,
      "y": 9,
      "z": 0,
      "name": "Wood_Sallow_Trunk",
      "support": 15
    },
    {
      "x": -10,
      "y": 10,
      "z": 0,
      "name": "Wood_Sallow_Trunk",
      "support": 15
    },
    {
      "x": -10,
      "y": 11,
      "z": 0,
      "name": "Wood_Sallow_Trunk_Full",
      "support": 15
    },
    {
      "x": -10,
      "y": 12,
      "z": 0,
      "name": "Plant_Moss_Wall_Green_Dark",
      "support": 15,
      "rotation": 3
    },
    {
      "x": -10,
      "y": 27,
      "z": 0,
      "name": "Wood_Goldenwood_Planks_Half",
      "rotation": 8
    },
    {
      "x": -10,
      "y": 31,
      "z": 0,
      "name": "Wood_Goldenwood_Planks_Half",
      "rotation": 8
    },
    {
      "x": -10,
      "y": 39,
      "z": 0,
      "name": "Wood_Goldenwood_Planks_Half",
      "rotation": 8
    },
    {
      "x": -10,
      "y": 43,
      "z": 0,
      "name": "Wood_Goldenwood_Planks_Half",
      "rotation": 8
    },
    {
      "x": -10,
      "y": 47,
      "z": 0,
      "name": "Furniture_Crude_Platform",
      "rotation": 1
    },
    {
      "x": -10,
      "y": 48,
      "z": 0,
      "name": "Wood_Hardwood_Fence",
      "rotation": 2
    },
    {
      "x": -10,
      "y": 51,
      "z": 0,
      "name": "Wood_Tropicalwood_Roof_Hollow",
      "rotation": 2
    },
    {
      "x": -10,
      "y": 62,
      "z": 0,
      "name": "Plant_Leaves_Beech",
      "support": 15
    },
    {
      "x": -10,
      "y": 27,
      "z": 1,
      "name": "Wood_Goldenwood_Planks_Half",
      "rotation": 8
    },
    {
      "x": -10,
      "y": 31,
      "z": 1,
      "name": "Wood_Goldenwood_Planks_Half",
      "rotation": 8
    },
    {
      "x": -10,
      "y": 39,
      "z": 1,
      "name": "Wood_Goldenwood_Planks_Half",
      "rotation": 8
    },
    {
      "x": -10,
      "y": 43,
      "z": 1,
      "name": "Wood_Goldenwood_Planks_Half",
      "rotation": 8
    },
    {
      "x": -10,
      "y": 44,
      "z": 1,
      "name": "Wood_Softwood_Fence",
      "rotation": 2
    },
    {
      "x": -10,
      "y": 45,
      "z": 1,
      "name": "Wood_Goldenwood_Fence",
      "rotation": 2
    },
    {
      "x": -10,
      "y": 46,
      "z": 1,
      "name": "Wood_Softwood_Fence",
      "rotation": 2
    },
    {
      "x": -10,
      "y": 47,
      "z": 1,
      "name": "Wood_Goldenwood_Stairs",
      "rotation": 8
    },
    {
      "x": -10,
      "y": 52,
      "z": 1,
      "name": "Wood_Tropicalwood_Roof_Flat"
    },
    {
      "x": -10,
      "y": 55,
      "z": 1,
      "name": "Wood_Sallow_Trunk_Full",
      "support": 15,
      "rotation": 4
    },
    {
      "x": -10,
      "y": 56,
      "z": 1,
      "name": "Wood_Sallow_Trunk_Full",
      "support": 15,
      "rotation": 5
    },
    {
      "x": -10,
      "y": 27,
      "z": 2,
      "name": "Wood_Goldenwood_Planks_Half",
      "rotation": 8
    },
    {
      "x": -10,
      "y": 31,
      "z": 2,
      "name": "Wood_Goldenwood_Planks_Half"
    },
    {
      "x": -10,
      "y": 39,
      "z": 2,
      "name": "Wood_Goldenwood_Planks_Half"
    },
    {
      "x": -10,
      "y": 43,
      "z": 2,
      "name": "Wood_Goldenwood_Planks_Half",
      "rotation": 8
    },
    {
      "x": -10,
      "y": 47,
      "z": 2,
      "name": "Wood_Goldenwood_Planks_Half",
      "rotation": 8
    },
    {
      "x": -10,
      "y": 52,
      "z": 2,
      "name": "Wood_Tropicalwood_Roof_Flat"
    },
    {
      "x": -10,
      "y": 55,
      "z": 2,
      "name": "Wood_Sallow_Trunk_Full",
      "support": 15,
      "rotation": 5
    },
    {
      "x": -10,
      "y": 63,
      "z": 2,
      "name": "Plant_Leaves_Beech",
      "support": 15
    },
    {
      "x": -10,
      "y": 64,
      "z": 2,
      "name": "Plant_Leaves_Beech",
      "support": 15
    },
    {
      "x": -10,
      "y": 7,
      "z": 3,
      "name": "Wood_Sallow_Trunk_Full",
      "support": 15
    },
    {
      "x": -10,
      "y": 8,
      "z": 3,
      "name": "Wood_Sallow_Trunk",
      "support": 15
    },
    {
      "x": -10,
      "y": 9,
      "z": 3,
      "name": "Wood_Sallow_Trunk",
      "support": 15
    },
    {
      "x": -10,
      "y": 10,
      "z": 3,
      "name": "Wood_Sallow_Trunk",
      "support": 15
    },
    {
      "x": -10,
      "y": 11,
      "z": 3,
      "name": "Wood_Sallow_Trunk_Full",
      "support": 15
    },
    {
      "x": -10,
      "y": 12,
      "z": 3,
      "name": "Plant_Moss_Wall_Green_Dark",
      "support": 15,
      "rotation": 3
    },
    {
      "x": -10,
      "y": 24,
      "z": 3,
      "name": "Wood_Sallow_Trunk_Half",
      "rotation": 7
    },
    {
      "x": -10,
      "y": 25,
      "z": 3,
      "name": "Wood_Sallow_Trunk",
      "support": 15
    },
    {
      "x": -10,
      "y": 26,
      "z": 3,
      "name": "Wood_Sallow_Trunk_Half",
      "rotation": 5
    },
    {
      "x": -10,
      "y": 27,
      "z": 3,
      "name": "Wood_Goldenwood_Planks_Half",
      "rotation": 8
    },
    {
      "x": -10,
      "y": 30,
      "z": 3,
      "name": "Wood_Goldenwood_Planks_Half",
      "rotation": 8
    },
    {
      "x": -10,
      "y": 38,
      "z": 3,
      "name": "Wood_Goldenwood_Planks_Half",
      "rotation": 8
    },
    {
      "x": -10,
      "y": 43,
      "z": 3,
      "name": "Wood_Goldenwood_Planks_Half",
      "rotation": 8
    },
    {
      "x": -10,
      "y": 47,
      "z": 3,
      "name": "Wood_Goldenwood_Planks_Half",
      "rotation": 8
    },
    {
      "x": -10,
      "y": 49,
      "z": 3,
      "name": "Wood_Torch_Wall",
      "rotation": 3
    },
    {
      "x": -10,
      "y": 52,
      "z": 3,
      "name": "Wood_Tropicalwood_Roof_Flat",
      "rotation": 3
    },
    {
      "x": -10,
      "y": 60,
      "z": 3,
      "name": "Plant_Leaves_Beech",
      "support": 15
    },
    {
      "x": -10,
      "y": 61,
      "z": 3,
      "name": "Plant_Leaves_Beech",
      "support": 15
    },
    {
      "x": -10,
      "y": 6,
      "z": 4,
      "name": "Wood_Sallow_Roots"
    },
    {
      "x": -10,
      "y": 7,
      "z": 4,
      "name": "Wood_Sallow_Trunk_Full",
      "support": 15
    },
    {
      "x": -10,
      "y": 8,
      "z": 4,
      "name": "Wood_Sallow_Trunk",
      "support": 15
    },
    {
      "x": -10,
      "y": 9,
      "z": 4,
      "name": "Wood_Sallow_Trunk",
      "support": 15
    },
    {
      "x": -10,
      "y": 10,
      "z": 4,
      "name": "Wood_Sallow_Trunk",
      "support": 15
    },
    {
      "x": -10,
      "y": 11,
      "z": 4,
      "name": "Wood_Sallow_Trunk",
      "support": 15
    },
    {
      "x": -10,
      "y": 12,
      "z": 4,
      "name": "Wood_Sallow_Trunk_Full",
      "support": 15
    },
    {
      "x": -10,
      "y": 13,
      "z": 4,
      "name": "Plant_Moss_Rug_Green_Dark",
      "support": 15
    },
    {
      "x": -10,
      "y": 27,
      "z": 4,
      "name": "Wood_Goldenwood_Planks_Half",
      "rotation": 8
    },
    {
      "x": -10,
      "y": 30,
      "z": 4,
      "name": "Wood_Goldenwood_Planks_Half"
    },
    {
      "x": -10,
      "y": 38,
      "z": 4,
      "name": "Wood_Goldenwood_Planks_Half"
    },
    {
      "x": -10,
      "y": 43,
      "z": 4,
      "name": "Wood_Goldenwood_Planks_Half",
      "rotation": 8
    },
    {
      "x": -10,
      "y": 47,
      "z": 4,
      "name": "Wood_Goldenwood_Planks_Half",
      "rotation": 8
    },
    {
      "x": -10,
      "y": 52,
      "z": 4,
      "name": "Wood_Tropicalwood_Roof_Flat",
      "rotation": 3
    },
    {
      "x": -10,
      "y": 59,
      "z": 4,
      "name": "Plant_Leaves_Beech",
      "support": 15
    },
    {
      "x": -10,
      "y": 60,
      "z": 4,
      "name": "Wood_Sallow_Branch_Corner",
      "support": 15,
      "rotation": 3
    },
    {
      "x": -10,
      "y": 61,
      "z": 4,
      "name": "Wood_Sallow_Branch_Long",
      "support": 15
    },
    {
      "x": -10,
      "y": 62,
      "z": 4,
      "name": "Plant_Leaves_Beech",
      "support": 15
    },
    {
      "x": -10,
      "y": 5,
      "z": 5,
      "name": "Wood_Sallow_Roots"
    },
    {
      "x": -10,
      "y": 6,
      "z": 5,
      "name": "Wood_Sallow_Trunk_Full",
      "support": 15
    },
    {
      "x": -10,
      "y": 7,
      "z": 5,
      "name": "Wood_Sallow_Trunk",
      "support": 15
    },
    {
      "x": -10,
      "y": 8,
      "z": 5,
      "name": "Wood_Sallow_Trunk",
      "support": 15
    },
    {
      "x": -10,
      "y": 9,
      "z": 5,
      "name": "Wood_Sallow_Trunk",
      "support": 15
    },
    {
      "x": -10,
      "y": 10,
      "z": 5,
      "name": "Wood_Sallow_Trunk",
      "support": 15
    },
    {
      "x": -10,
      "y": 11,
      "z": 5,
      "name": "Wood_Sallow_Trunk_Full",
      "support": 15
    },
    {
      "x": -10,
      "y": 12,
      "z": 5,
      "name": "Plant_Moss_Wall_Green_Dark",
      "support": 15
    },
    {
      "x": -10,
      "y": 27,
      "z": 5,
      "name": "Wood_Goldenwood_Planks_Half",
      "rotation": 8
    },
    {
      "x": -10,
      "y": 29,
      "z": 5,
      "name": "Wood_Goldenwood_Planks_Half",
      "rotation": 8
    },
    {
      "x": -10,
      "y": 37,
      "z": 5,
      "name": "Wood_Goldenwood_Planks_Half",
      "rotation": 8
    },
    {
      "x": -10,
      "y": 43,
      "z": 5,
      "name": "Wood_Goldenwood_Planks_Half",
      "rotation": 8
    },
    {
      "x": -10,
      "y": 47,
      "z": 5,
      "name": "Wood_Goldenwood_Planks_Half",
      "rotation": 8
    },
    {
      "x": -10,
      "y": 52,
      "z": 5,
      "name": "Wood_Sallow_Trunk",
      "support": 15,
      "rotation": 5
    },
    {
      "x": -10,
      "y": 60,
      "z": 5,
      "name": "Plant_Leaves_Beech",
      "support": 15
    },
    {
      "x": -10,
      "y": 61,
      "z": 5,
      "name": "Plant_Leaves_Beech",
      "support": 15
    },
    {
      "x": -10,
      "y": 5,
      "z": 6,
      "name": "Wood_Sallow_Roots"
    },
    {
      "x": -10,
      "y": 6,
      "z": 6,
      "name": "Wood_Sallow_Trunk_Full",
      "support": 15
    },
    {
      "x": -10,
      "y": 7,
      "z": 6,
      "name": "Wood_Sallow_Trunk",
      "support": 15
    },
    {
      "x": -10,
      "y": 8,
      "z": 6,
      "name": "Wood_Sallow_Trunk",
      "support": 15
    },
    {
      "x": -10,
      "y": 9,
      "z": 6,
      "name": "Wood_Sallow_Trunk",
      "support": 15
    },
    {
      "x": -10,
      "y": 10,
      "z": 6,
      "name": "Wood_Sallow_Trunk",
      "support": 15
    },
    {
      "x": -10,
      "y": 11,
      "z": 6,
      "name": "Wood_Sallow_Trunk_Full",
      "support": 15
    },
    {
      "x": -10,
      "y": 27,
      "z": 6,
      "name": "Wood_Goldenwood_Planks_Half",
      "rotation": 8
    },
    {
      "x": -10,
      "y": 29,
      "z": 6,
      "name": "Wood_Goldenwood_Planks_Half",
      "rotation": 8
    },
    {
      "x": -10,
      "y": 37,
      "z": 6,
      "name": "Wood_Goldenwood_Planks_Half",
      "rotation": 8
    },
    {
      "x": -10,
      "y": 43,
      "z": 6,
      "name": "Wood_Goldenwood_Planks_Half",
      "rotation": 8
    },
    {
      "x": -10,
      "y": 47,
      "z": 6,
      "name": "Wood_Goldenwood_Planks_Half",
      "rotation": 8
    },
    {
      "x": -10,
      "y": 49,
      "z": 6,
      "name": "Plant_Vine_Liana_End",
      "support": 15
    },
    {
      "x": -10,
      "y": 50,
      "z": 6,
      "name": "Plant_Vine_Liana_End",
      "support": 15
    },
    {
      "x": -10,
      "y": 51,
      "z": 6,
      "name": "Plant_Vine_Liana_End",
      "support": 15
    },
    {
      "x": -10,
      "y": 52,
      "z": 6,
      "name": "Wood_Tropicalwood_Roof_Flat",
      "rotation": 1
    },
    {
      "x": -10,
      "y": 62,
      "z": 6,
      "name": "Plant_Leaves_Beech",
      "support": 15
    },
    {
      "x": -10,
      "y": 63,
      "z": 6,
      "name": "Plant_Leaves_Beech",
      "support": 15
    },
    {
      "x": -10,
      "y": 6,
      "z": 7,
      "name": "Wood_Sallow_Trunk_Full",
      "support": 15
    },
    {
      "x": -10,
      "y": 7,
      "z": 7,
      "name": "Wood_Sallow_Trunk",
      "support": 15
    },
    {
      "x": -10,
      "y": 8,
      "z": 7,
      "name": "Wood_Sallow_Trunk",
      "support": 15
    },
    {
      "x": -10,
      "y": 9,
      "z": 7,
      "name": "Wood_Sallow_Trunk",
      "support": 15
    },
    {
      "x": -10,
      "y": 10,
      "z": 7,
      "name": "Wood_Sallow_Trunk_Full",
      "support": 15
    },
    {
      "x": -10,
      "y": 11,
      "z": 7,
      "name": "Plant_Moss_Rug_Green_Dark",
      "support": 15
    },
    {
      "x": -10,
      "y": 27,
      "z": 7,
      "name": "Wood_Goldenwood_Planks_Half",
      "rotation": 8
    },
    {
      "x": -10,
      "y": 43,
      "z": 7,
      "name": "Wood_Goldenwood_Planks_Half",
      "rotation": 8
    },
    {
      "x": -10,
      "y": 44,
      "z": 7,
      "name": "*Wood_Softwood_Fence_State_Definitions_Corner"
    },
    {
      "x": -10,
      "y": 45,
      "z": 7,
      "name": "*Wood_Softwood_Fence_State_Definitions_Corner"
    },
    {
      "x": -10,
      "y": 46,
      "z": 7,
      "name": "*Wood_Softwood_Fence_State_Definitions_Corner"
    },
    {
      "x": -10,
      "y": 47,
      "z": 7,
      "name": "*Wood_Goldenwood_Stairs_State_Definitions_Inverted_Corner_Left",
      "rotation": 10
    },
    {
      "x": -10,
      "y": 52,
      "z": 7,
      "name": "Wood_Sallow_Branch_Corner",
      "support": 15,
      "rotation": 25
    },
    {
      "x": -10,
      "y": 58,
      "z": 7,
      "name": "Wood_Sallow_Branch_Long",
      "support": 15,
      "rotation": 5
    },
    {
      "x": -10,
      "y": 62,
      "z": 7,
      "name": "Wood_Sallow_Branch_Corner",
      "support": 15,
      "rotation": 3
    },
    {
      "x": -10,
      "y": 63,
      "z": 7,
      "name": "Wood_Sallow_Branch_Long",
      "support": 15
    },
    {
      "x": -10,
      "y": 64,
      "z": 7,
      "name": "Plant_Leaves_Beech",
      "support": 15
    },
    {
      "x": -10,
      "y": 27,
      "z": 8,
      "name": "Furniture_Crude_Platform"
    },
    {
      "x": -10,
      "y": 28,
      "z": 8,
      "name": "*Wood_Hardwood_Fence_State_Definitions_Corner"
    },
    {
      "x": -10,
      "y": 43,
      "z": 8,
      "name": "Wood_Goldenwood_Planks_Half",
      "rotation": 8
    },
    {
      "x": -10,
      "y": 44,
      "z": 8,
      "name": "*Wood_Softwood_Fence_State_Definitions_Corner",
      "rotation": 2
    },
    {
      "x": -10,
      "y": 45,
      "z": 8,
      "name": "*Wood_Softwood_Fence_State_Definitions_Corner",
      "rotation": 2
    },
    {
      "x": -10,
      "y": 46,
      "z": 8,
      "name": "*Wood_Softwood_Fence_State_Definitions_Corner",
      "rotation": 2
    },
    {
      "x": -10,
      "y": 47,
      "z": 8,
      "name": "*Wood_Goldenwood_Stairs_State_Definitions_Corner_Right",
      "rotation": 9
    },
    {
      "x": -10,
      "y": 52,
      "z": 8,
      "name": "Wood_Sallow_Branch_Long",
      "support": 15,
      "rotation": 4
    },
    {
      "x": -10,
      "y": 60,
      "z": 8,
      "name": "Plant_Leaves_Beech",
      "support": 15
    },
    {
      "x": -10,
      "y": 62,
      "z": 8,
      "name": "Plant_Leaves_Beech",
      "support": 15
    },
    {
      "x": -10,
      "y": 63,
      "z": 8,
      "name": "Plant_Leaves_Beech",
      "support": 15
    },
    {
      "x": -10,
      "y": 27,
      "z": 9,
      "name": "Furniture_Crude_Platform",
      "rotation": 1
    },
    {
      "x": -10,
      "y": 28,
      "z": 9,
      "name": "*Wood_Hardwood_Fence_State_Definitions_Corner",
      "rotation": 2
    },
    {
      "x": -10,
      "y": 43,
      "z": 9,
      "name": "Furniture_Crude_Platform",
      "rotation": 1
    },
    {
      "x": -10,
      "y": 47,
      "z": 9,
      "name": "Furniture_Crude_Platform",
      "rotation": 1
    },
    {
      "x": -10,
      "y": 48,
      "z": 9,
      "name": "Wood_Hardwood_Fence"
    },
    {
      "x": -10,
      "y": 51,
      "z": 9,
      "name": "Wood_Tropicalwood_Roof_Hollow"
    },
    {
      "x": -10,
      "y": 52,
      "z": 9,
      "name": "Wood_Sallow_Branch_Corner",
      "support": 15,
      "rotation": 16
    },
    {
      "x": -10,
      "y": 53,
      "z": 9,
      "name": "Plant_Leaves_Beech",
      "support": 15
    },
    {
      "x": -10,
      "y": 58,
      "z": 9,
      "name": "Wood_Sallow_Trunk",
      "support": 15,
      "rotation": 5
    },
    {
      "x": -10,
      "y": 35,
      "z": 10,
      "name": "Plant_Vine_Liana_End",
      "support": 15
    },
    {
      "x": -10,
      "y": 36,
      "z": 10,
      "name": "Plant_Vine_Liana",
      "support": 15
    },
    {
      "x": -10,
      "y": 37,
      "z": 10,
      "name": "Plant_Vine_Liana",
      "support": 15
    },
    {
      "x": -10,
      "y": 38,
      "z": 10,
      "name": "Plant_Vine_Liana",
      "support": 15
    },
    {
      "x": -10,
      "y": 39,
      "z": 10,
      "name": "Plant_Vine_Liana",
      "support": 15
    },
    {
      "x": -10,
      "y": 40,
      "z": 10,
      "name": "Plant_Vine_Liana",
      "support": 15
    },
    {
      "x": -10,
      "y": 41,
      "z": 10,
      "name": "Plant_Vine_Liana",
      "support": 15
    },
    {
      "x": -10,
      "y": 42,
      "z": 10,
      "name": "Plant_Vine_Liana",
      "support": 15
    },
    {
      "x": -10,
      "y": 43,
      "z": 10,
      "name": "Plant_Vine_Liana",
      "support": 15
    },
    {
      "x": -10,
      "y": 44,
      "z": 10,
      "name": "Plant_Vine_Liana",
      "support": 15
    },
    {
      "x": -10,
      "y": 45,
      "z": 10,
      "name": "Plant_Vine_Liana",
      "support": 15
    },
    {
      "x": -10,
      "y": 46,
      "z": 10,
      "name": "Plant_Vine_Liana",
      "support": 15
    },
    {
      "x": -10,
      "y": 47,
      "z": 10,
      "name": "Plant_Vine_Liana",
      "support": 15
    },
    {
      "x": -10,
      "y": 48,
      "z": 10,
      "name": "Plant_Vine_Liana",
      "support": 15
    },
    {
      "x": -10,
      "y": 49,
      "z": 10,
      "name": "Plant_Vine_Liana",
      "support": 15
    },
    {
      "x": -10,
      "y": 50,
      "z": 10,
      "name": "Plant_Vine_Liana_End",
      "support": 15
    },
    {
      "x": -10,
      "y": 57,
      "z": 10,
      "name": "Plant_Leaves_Beech",
      "support": 15
    },
    {
      "x": -10,
      "y": 58,
      "z": 10,
      "name": "Wood_Sallow_Branch_Long",
      "support": 15,
      "rotation": 4
    },
    {
      "x": -10,
      "y": 59,
      "z": 10,
      "name": "Plant_Leaves_Beech",
      "support": 15
    },
    {
      "x": -10,
      "y": 2,
      "z": 11,
      "name": "Wood_Sallow_Roots"
    },
    {
      "x": -10,
      "y": 3,
      "z": 11,
      "name": "Wood_Sallow_Trunk_Full",
      "support": 15
    },
    {
      "x": -10,
      "y": 4,
      "z": 11,
      "name": "Wood_Sallow_Trunk",
      "support": 15
    },
    {
      "x": -10,
      "y": 5,
      "z": 11,
      "name": "Wood_Sallow_Trunk",
      "support": 15
    },
    {
      "x": -10,
      "y": 6,
      "z": 11,
      "name": "Wood_Sallow_Trunk",
      "support": 15
    },
    {
      "x": -10,
      "y": 7,
      "z": 11,
      "name": "Wood_Sallow_Trunk",
      "support": 15
    },
    {
      "x": -10,
      "y": 8,
      "z": 11,
      "name": "Wood_Sallow_Trunk_Full",
      "support": 15
    },
    {
      "x": -10,
      "y": 57,
      "z": 11,
      "name": "Plant_Leaves_Beech",
      "support": 15
    },
    {
      "x": -10,
      "y": 58,
      "z": 11,
      "name": "Wood_Sallow_Branch_Corner",
      "support": 15
    },
    {
      "x": -10,
      "y": 59,
      "z": 11,
      "name": "Wood_Sallow_Branch_Long",
      "support": 15
    },
    {
      "x": -10,
      "y": 60,
      "z": 11,
      "name": "Plant_Leaves_Beech",
      "support": 15
    },
    {
      "x": -10,
      "y": 58,
      "z": 12,
      "name": "Plant_Leaves_Beech",
      "support": 15
    },
    {
      "x": -10,
      "y": 59,
      "z": 12,
      "name": "Plant_Leaves_Beech",
      "support": 15
    },
    {
      "x": -9,
      "y": 55,
      "z": -7,
      "name": "Plant_Leaves_Beech",
      "support": 15
    },
    {
      "x": -9,
      "y": 56,
      "z": -7,
      "name": "Plant_Leaves_Beech",
      "support": 15
    },
    {
      "x": -9,
      "y": 8,
      "z": -6,
      "name": "Plant_Moss_Wall_Green_Dark",
      "support": 15,
      "rotation": 2
    },
    {
      "x": -9,
      "y": 55,
      "z": -6,
      "name": "Plant_Leaves_Beech",
      "support": 15
    },
    {
      "x": -9,
      "y": 2,
      "z": -5,
      "name": "Wood_Sallow_Roots"
    },
    {
      "x": -9,
      "y": 3,
      "z": -5,
      "name": "Wood_Sallow_Trunk_Full",
      "support": 15
    },
    {
      "x": -9,
      "y": 4,
      "z": -5,
      "name": "Wood_Sallow_Trunk",
      "support": 15
    },
    {
      "x": -9,
      "y": 5,
      "z": -5,
      "name": "Wood_Sallow_Trunk",
      "support": 15
    },
    {
      "x": -9,
      "y": 6,
      "z": -5,
      "name": "Wood_Sallow_Trunk",
      "support": 15
    },
    {
      "x": -9,
      "y": 7,
      "z": -5,
      "name": "Wood_Sallow_Trunk",
      "support": 15
    },
    {
      "x": -9,
      "y": 8,
      "z": -5,
      "name": "Wood_Sallow_Trunk_Full",
      "support": 15
    },
    {
      "x": -9,
      "y": 9,
      "z": -5,
      "name": "Plant_Moss_Rug_Green_Dark",
      "support": 15
    },
    {
      "x": -9,
      "y": 55,
      "z": -5,
      "name": "Wood_Sallow_Branch_Corner",
      "support": 15,
      "rotation": 24
    },
    {
      "x": -9,
      "y": 3,
      "z": -4,
      "name": "Wood_Sallow_Roots"
    },
    {
      "x": -9,
      "y": 4,
      "z": -4,
      "name": "Wood_Sallow_Trunk_Full",
      "support": 15
    },
    {
      "x": -9,
      "y": 5,
      "z": -4,
      "name": "Wood_Sallow_Trunk",
      "support": 15
    },
    {
      "x": -9,
      "y": 6,
      "z": -4,
      "name": "Wood_Sallow_Trunk",
      "support": 15
    },
    {
      "x": -9,
      "y": 7,
      "z": -4,
      "name": "Wood_Sallow_Trunk",
      "support": 15
    },
    {
      "x": -9,
      "y": 8,
      "z": -4,
      "name": "Wood_Sallow_Trunk",
      "support": 15
    },
    {
      "x": -9,
      "y": 9,
      "z": -4,
      "name": "Wood_Sallow_Trunk_Full",
      "support": 15
    },
    {
      "x": -9,
      "y": 10,
      "z": -4,
      "name": "Plant_Moss_Rug_Green_Dark",
      "support": 15
    },
    {
      "x": -9,
      "y": 55,
      "z": -4,
      "name": "Wood_Sallow_Branch_Corner",
      "support": 15,
      "rotation": 19
    },
    {
      "x": -9,
      "y": 60,
      "z": -4,
      "name": "Plant_Leaves_Beech",
      "support": 15
    },
    {
      "x": -9,
      "y": 61,
      "z": -4,
      "name": "Plant_Leaves_Beech",
      "support": 15
    },
    {
      "x": -9,
      "y": 10,
      "z": -3,
      "name": "Plant_Moss_Wall_Green_Dark",
      "support": 15,
      "rotation": 3
    },
    {
      "x": -9,
      "y": 27,
      "z": -3,
      "name": "Furniture_Crude_Platform",
      "rotation": 1
    },
    {
      "x": -9,
      "y": 28,
      "z": -3,
      "name": "Wood_Hardwood_Fence",
      "rotation": 2
    },
    {
      "x": -9,
      "y": 57,
      "z": -3,
      "name": "Plant_Leaves_Beech",
      "support": 15
    },
    {
      "x": -9,
      "y": 60,
      "z": -3,
      "name": "Plant_Leaves_Beech",
      "support": 15
    },
    {
      "x": -9,
      "y": 62,
      "z": -3,
      "name": "Plant_Leaves_Beech",
      "support": 15
    },
    {
      "x": -9,
      "y": 63,
      "z": -3,
      "name": "Plant_Leaves_Beech",
      "support": 15
    },
    {
      "x": -9,
      "y": 27,
      "z": -2,
      "name": "Wood_Goldenwood_Planks_Half",
      "rotation": 8
    },
    {
      "x": -9,
      "y": 54,
      "z": -2,
      "name": "Wood_Sallow_Branch_Long",
      "support": 15,
      "rotation": 5
    },
    {
      "x": -9,
      "y": 62,
      "z": -2,
      "name": "Plant_Leaves_Beech",
      "support": 15
    },
    {
      "x": -9,
      "y": 27,
      "z": -1,
      "name": "Wood_Goldenwood_Planks_Half",
      "rotation": 8
    },
    {
      "x": -9,
      "y": 31,
      "z": -1,
      "name": "Wood_Goldenwood_Planks_Half",
      "rotation": 8
    },
    {
      "x": -9,
      "y": 39,
      "z": -1,
      "name": "Wood_Goldenwood_Planks_Half",
      "rotation": 8
    },
    {
      "x": -9,
      "y": 43,
      "z": -1,
      "name": "Furniture_Crude_Platform",
      "rotation": 1
    },
    {
      "x": -9,
      "y": 60,
      "z": -1,
      "name": "Wood_Sallow_Branch_Corner",
      "support": 15,
      "rotation": 24
    },
    {
      "x": -9,
      "y": 62,
      "z": -1,
      "name": "Wood_Sallow_Branch_Long",
      "support": 15,
      "rotation": 5
    },
    {
      "x": -9,
      "y": 64,
      "z": -1,
      "name": "Plant_Leaves_Beech",
      "support": 15
    },
    {
      "x": -9,
      "y": 5,
      "z": 0,
      "name": "Wood_Sallow_Roots"
    },
    {
      "x": -9,
      "y": 6,
      "z": 0,
      "name": "Wood_Sallow_Trunk_Full",
      "support": 15
    },
    {
      "x": -9,
      "y": 7,
      "z": 0,
      "name": "Wood_Sallow_Trunk",
      "support": 15
    },
    {
      "x": -9,
      "y": 8,
      "z": 0,
      "name": "Wood_Sallow_Trunk",
      "support": 15
    },
    {
      "x": -9,
      "y": 9,
      "z": 0,
      "name": "Wood_Sallow_Trunk",
      "support": 15
    },
    {
      "x": -9,
      "y": 10,
      "z": 0,
      "name": "Wood_Sallow_Trunk",
      "support": 15
    },
    {
      "x": -9,
      "y": 11,
      "z": 0,
      "name": "Wood_Sallow_Trunk",
      "support": 15
    },
    {
      "x": -9,
      "y": 12,
      "z": 0,
      "name": "Wood_Sallow_Trunk_Full",
      "support": 15
    },
    {
      "x": -9,
      "y": 13,
      "z": 0,
      "name": "Plant_Moss_Rug_Green_Dark",
      "support": 15
    },
    {
      "x": -9,
      "y": 27,
      "z": 0,
      "name": "Wood_Goldenwood_Planks_Half",
      "rotation": 8
    },
    {
      "x": -9,
      "y": 31,
      "z": 0,
      "name": "Wood_Goldenwood_Planks_Half",
      "rotation": 8
    },
    {
      "x": -9,
      "y": 39,
      "z": 0,
      "name": "Wood_Goldenwood_Planks_Half",
      "rotation": 8
    },
    {
      "x": -9,
      "y": 43,
      "z": 0,
      "name": "Furniture_Crude_Platform",
      "rotation": 1
    },
    {
      "x": -9,
      "y": 47,
      "z": 0,
      "name": "Furniture_Crude_Platform",
      "rotation": 1
    },
    {
      "x": -9,
      "y": 48,
      "z": 0,
      "name": "Wood_Hardwood_Fence",
      "rotation": 2
    },
    {
      "x": -9,
      "y": 51,
      "z": 0,
      "name": "Wood_Tropicalwood_Roof_Hollow",
      "rotation": 2
    },
    {
      "x": -9,
      "y": 60,
      "z": 0,
      "name": "Wood_Sallow_Branch_Long",
      "support": 15,
      "rotation": 4
    },
    {
      "x": -9,
      "y": 6,
      "z": 1,
      "name": "Wood_Sallow_Trunk_Full",
      "support": 15
    },
    {
      "x": -9,
      "y": 7,
      "z": 1,
      "name": "Wood_Sallow_Trunk",
      "support": 15
    },
    {
      "x": -9,
      "y": 8,
      "z": 1,
      "name": "Wood_Sallow_Trunk",
      "support": 15
    },
    {
      "x": -9,
      "y": 9,
      "z": 1,
      "name": "Wood_Sallow_Trunk",
      "support": 15
    },
    {
      "x": -9,
      "y": 10,
      "z": 1,
      "name": "Wood_Sallow_Trunk",
      "support": 15
    },
    {
      "x": -9,
      "y": 11,
      "z": 1,
      "name": "Wood_Sallow_Trunk_Full",
      "support": 15
    },
    {
      "x": -9,
      "y": 12,
      "z": 1,
      "name": "Plant_Moss_Rug_Green_Dark",
      "support": 15
    },
    {
      "x": -9,
      "y": 27,
      "z": 1,
      "name": "Wood_Goldenwood_Planks_Half",
      "rotation": 8
    },
    {
      "x": -9,
      "y": 31,
      "z": 1,
      "name": "Wood_Goldenwood_Planks_Half",
      "rotation": 8
    },
    {
      "x": -9,
      "y": 39,
      "z": 1,
      "name": "Wood_Goldenwood_Planks_Half",
      "rotation": 8
    },
    {
      "x": -9,
      "y": 43,
      "z": 1,
      "name": "Wood_Goldenwood_Planks_Half",
      "rotation": 8
    },
    {
      "x": -9,
      "y": 44,
      "z": 1,
      "name": "*Wood_Softwood_Fence_State_Definitions_Corner"
    },
    {
      "x": -9,
      "y": 45,
      "z": 1,
      "name": "*Wood_Softwood_Fence_State_Definitions_Corner"
    },
    {
      "x": -9,
      "y": 46,
      "z": 1,
      "name": "*Wood_Softwood_Fence_State_Definitions_Corner"
    },
    {
      "x": -9,
      "y": 47,
      "z": 1,
      "name": "Wood_Goldenwood_Stairs",
      "rotation": 8
    },
    {
      "x": -9,
      "y": 52,
      "z": 1,
      "name": "Wood_Tropicalwood_Roof_Flat"
    },
    {
      "x": -9,
      "y": 60,
      "z": 1,
      "name": "Wood_Sallow_Branch_Corner",
      "support": 15,
      "rotation": 26
    },
    {
      "x": -9,
      "y": 62,
      "z": 1,
      "name": "Wood_Sallow_Branch_Corner",
      "support": 15,
      "rotation": 25
    },
    {
      "x": -9,
      "y": 63,
      "z": 1,
      "name": "Plant_Leaves_Beech",
      "support": 15
    },
    {
      "x": -9,
      "y": 64,
      "z": 1,
      "name": "Plant_Leaves_Beech",
      "support": 15
    },
    {
      "x": -9,
      "y": 6,
      "z": 2,
      "name": "Wood_Sallow_Trunk_Full",
      "support": 15
    },
    {
      "x": -9,
      "y": 7,
      "z": 2,
      "name": "Wood_Sallow_Trunk",
      "support": 15
    },
    {
      "x": -9,
      "y": 8,
      "z": 2,
      "name": "Wood_Sallow_Trunk",
      "support": 15
    },
    {
      "x": -9,
      "y": 9,
      "z": 2,
      "name": "Wood_Sallow_Trunk",
      "support": 15
    },
    {
      "x": -9,
      "y": 10,
      "z": 2,
      "name": "Wood_Sallow_Trunk_Full",
      "support": 15
    },
    {
      "x": -9,
      "y": 27,
      "z": 2,
      "name": "Wood_Goldenwood_Planks_Half",
      "rotation": 8
    },
    {
      "x": -9,
      "y": 31,
      "z": 2,
      "name": "Wood_Goldenwood_Planks_Half"
    },
    {
      "x": -9,
      "y": 34,
      "z": 2,
      "name": "Wood_Sallow_Branch_Short",
      "support": 15,
      "rotation": 3
    },
    {
      "x": -9,
      "y": 39,
      "z": 2,
      "name": "Wood_Goldenwood_Planks_Half"
    },
    {
      "x": -9,
      "y": 42,
      "z": 2,
      "name": "Wood_Sallow_Branch_Short",
      "support": 15,
      "rotation": 3
    },
    {
      "x": -9,
      "y": 43,
      "z": 2,
      "name": "Wood_Goldenwood_Planks_Half",
      "rotation": 8
    },
    {
      "x": -9,
      "y": 44,
      "z": 2,
      "name": "Wood_Softwood_Fence",
      "rotation": 1
    },
    {
      "x": -9,
      "y": 45,
      "z": 2,
      "name": "Wood_Softwood_Fence",
      "rotation": 1
    },
    {
      "x": -9,
      "y": 46,
      "z": 2,
      "name": "Wood_Softwood_Fence",
      "rotation": 1
    },
    {
      "x": -9,
      "y": 47,
      "z": 2,
      "name": "Wood_Goldenwood_Planks_Half",
      "rotation": 8
    },
    {
      "x": -9,
      "y": 52,
      "z": 2,
      "name": "Wood_Tropicalwood_Roof_Flat"
    },
    {
      "x": -9,
      "y": 55,
      "z": 2,
      "name": "Wood_Sallow_Trunk_Full",
      "support": 15
    },
    {
      "x": -9,
      "y": 62,
      "z": 2,
      "name": "Wood_Sallow_Branch_Corner",
      "support": 15
    },
    {
      "x": -9,
      "y": 63,
      "z": 2,
      "name": "Wood_Sallow_Branch_Long",
      "support": 15
    },
    {
      "x": -9,
      "y": 64,
      "z": 2,
      "name": "Wood_Sallow_Branch_Long",
      "support": 15
    },
    {
      "x": -9,
      "y": 65,
      "z": 2,
      "name": "Plant_Leaves_Beech",
      "support": 15
    },
    {
      "x": -9,
      "y": 6,
      "z": 3,
      "name": "Wood_Sallow_Roots"
    },
    {
      "x": -9,
      "y": 7,
      "z": 3,
      "name": "Wood_Sallow_Trunk_Full",
      "support": 15
    },
    {
      "x": -9,
      "y": 8,
      "z": 3,
      "name": "Wood_Sallow_Trunk",
      "support": 15
    },
    {
      "x": -9,
      "y": 9,
      "z": 3,
      "name": "Wood_Sallow_Trunk",
      "support": 15
    },
    {
      "x": -9,
      "y": 10,
      "z": 3,
      "name": "Wood_Sallow_Trunk",
      "support": 15
    },
    {
      "x": -9,
      "y": 11,
      "z": 3,
      "name": "Wood_Sallow_Trunk",
      "support": 15
    },
    {
      "x": -9,
      "y": 12,
      "z": 3,
      "name": "Wood_Sallow_Trunk_Full",
      "support": 15
    },
    {
      "x": -9,
      "y": 13,
      "z": 3,
      "name": "Plant_Moss_Rug_Green_Dark",
      "support": 15
    },
    {
      "x": -9,
      "y": 23,
      "z": 3,
      "name": "Wood_Sallow_Trunk_Half",
      "rotation": 7
    },
    {
      "x": -9,
      "y": 24,
      "z": 3,
      "name": "Wood_Sallow_Trunk",
      "support": 1,
      "rotation": 7
    },
    {
      "x": -9,
      "y": 25,
      "z": 3,
      "name": "Wood_Sallow_Trunk_Half",
      "rotation": 5
    },
    {
      "x": -9,
      "y": 27,
      "z": 3,
      "name": "Wood_Goldenwood_Planks_Half",
      "rotation": 8
    },
    {
      "x": -9,
      "y": 30,
      "z": 3,
      "name": "Wood_Goldenwood_Planks_Half",
      "rotation": 8
    },
    {
      "x": -9,
      "y": 32,
      "z": 3,
      "name": "Wood_Torch_Wall",
      "rotation": 3
    },
    {
      "x": -9,
      "y": 38,
      "z": 3,
      "name": "Wood_Goldenwood_Planks_Half",
      "rotation": 8
    },
    {
      "x": -9,
      "y": 40,
      "z": 3,
      "name": "Wood_Torch_Wall",
      "rotation": 3
    },
    {
      "x": -9,
      "y": 43,
      "z": 3,
      "name": "Wood_Goldenwood_Planks_Half",
      "rotation": 8
    },
    {
      "x": -9,
      "y": 45,
