{
  "version": 8,
  "blockIdVersion": 11,
  "anchorX": 0,
  "anchorY": 0,
  "anchorZ": 0,
  "blocks": [
    {
      "x": -13,
      "y": 12,
      "z": -11,
      "name": "Rock_Shale_Brick_Smooth_Half",
      "rotation": 7
    },
    {
      "x": -13,
      "y": 13,
      "z": -11,
      "name": "Rock_Shale_Brick_Smooth_Half",
      "rotation": 7
    },
    {
      "x": -13,
      "y": 14,
      "z": -11,
      "name": "Rock_Shale_Brick_Smooth_Half",
      "rotation": 7
    },
    {
      "x": -13,
      "y": 31,
      "z": -11,
      "name": "Rock_Shale_Brick_Smooth_Half",
      "rotation": 7
    },
    {
      "x": -13,
      "y": 32,
      "z": -11,
      "name": "Rock_Shale_Brick_Smooth_Half",
      "rotation": 7
    },
    {
      "x": -13,
      "y": 33,
      "z": -11,
      "name": "Rock_Shale_Brick_Smooth_Half",
      "rotation": 7
    },
    {
      "x": -13,
      "y": 11,
      "z": -10,
      "name": "Rock_Shale_Brick_Smooth_Half",
      "rotation": 7
    },
    {
      "x": -13,
      "y": 12,
      "z": -10,
      "name": "Rock_Shale_Brick_Smooth_Half",
      "rotation": 7
    },
    {
      "x": -13,
      "y": 13,
      "z": -10,
      "name": "Rock_Shale_Brick_Smooth_Half",
      "rotation": 7
    },
    {
      "x": -13,
      "y": 30,
      "z": -10,
      "name": "Rock_Shale_Brick_Smooth_Half",
      "rotation": 7
    },
    {
      "x": -13,
      "y": 31,
      "z": -10,
      "name": "Rock_Shale_Brick_Smooth_Half",
      "rotation": 7
    },
    {
      "x": -13,
      "y": 32,
      "z": -10,
      "name": "Rock_Shale_Brick_Smooth_Half",
      "rotation": 7
    },
    {
      "x": -13,
      "y": 10,
      "z": -9,
      "name": "Rock_Shale_Brick_Smooth_Half",
      "rotation": 7
    },
    {
      "x": -13,
      "y": 11,
      "z": -9,
      "name": "Rock_Shale_Brick_Smooth_Half",
      "rotation": 7
    },
    {
      "x": -13,
      "y": 12,
      "z": -9,
      "name": "Rock_Shale_Brick_Smooth_Half",
      "rotation": 7
    },
    {
      "x": -13,
      "y": 29,
      "z": -9,
      "name": "Rock_Shale_Brick_Smooth_Half",
      "rotation": 7
    },
    {
      "x": -13,
      "y": 30,
      "z": -9,
      "name": "Rock_Shale_Brick_Smooth_Half",
      "rotation": 7
    },
    {
      "x": -13,
      "y": 31,
      "z": -9,
      "name": "Rock_Shale_Brick_Smooth_Half",
      "rotation": 7
    },
    {
      "x": -13,
      "y": 10,
      "z": -8,
      "name": "Rock_Shale_Brick_Smooth_Half",
      "rotation": 7
    },
    {
      "x": -13,
      "y": 11,
      "z": -8,
      "name": "Rock_Shale_Brick_Smooth_Half",
      "rotation": 7
    },
    {
      "x": -13,
      "y": 29,
      "z": -8,
      "name": "Rock_Shale_Brick_Smooth_Half",
      "rotation": 7
    },
    {
      "x": -13,
      "y": 30,
      "z": -8,
      "name": "Rock_Shale_Brick_Smooth_Half",
      "rotation": 7
    },
    {
      "x": -13,
      "y": 10,
      "z": -7,
      "name": "Rock_Shale_Brick_Smooth_Half",
      "rotation": 7
    },
    {
      "x": -13,
      "y": 29,
      "z": -7,
      "name": "Rock_Shale_Brick_Smooth_Half",
      "rotation": 7
    },
    {
      "x": -13,
      "y": 10,
      "z": 8,
      "name": "Rock_Shale_Brick_Smooth_Half",
      "rotation": 7
    },
    {
      "x": -13,
      "y": 29,
      "z": 8,
      "name": "Rock_Shale_Brick_Smooth_Half",
      "rotation": 7
    },
    {
      "x": -13,
      "y": 10,
      "z": 9,
      "name": "Rock_Shale_Brick_Smooth_Half",
      "rotation": 7
    },
    {
      "x": -13,
      "y": 11,
      "z": 9,
      "name": "Rock_Shale_Brick_Smooth_Half",
      "rotation": 7
    },
    {
      "x": -13,
      "y": 29,
      "z": 9,
      "name": "Rock_Shale_Brick_Smooth_Half",
      "rotation": 7
    },
    {
      "x": -13,
      "y": 30,
      "z": 9,
      "name": "Rock_Shale_Brick_Smooth_Half",
      "rotation": 7
    },
    {
      "x": -13,
      "y": 10,
      "z": 10,
      "name": "Rock_Shale_Brick_Smooth_Half",
      "rotation": 7
    },
    {
      "x": -13,
      "y": 11,
      "z": 10,
      "name": "Rock_Shale_Brick_Smooth_Half",
      "rotation": 7
    },
    {
      "x": -13,
      "y": 12,
      "z": 10,
      "name": "Rock_Shale_Brick_Smooth_Half",
      "rotation": 7
    },
    {
      "x": -13,
      "y": 29,
      "z": 10,
      "name": "Rock_Shale_Brick_Smooth_Half",
      "rotation": 7
    },
    {
      "x": -13,
      "y": 30,
      "z": 10,
      "name": "Rock_Shale_Brick_Smooth_Half",
      "rotation": 7
    },
    {
      "x": -13,
      "y": 31,
      "z": 10,
      "name": "Rock_Shale_Brick_Smooth_Half",
      "rotation": 7
    },
    {
      "x": -13,
      "y": 11,
      "z": 11,
      "name": "Rock_Shale_Brick_Smooth_Half",
      "rotation": 7
    },
    {
      "x": -13,
      "y": 12,
      "z": 11,
      "name": "Rock_Shale_Brick_Smooth_Half",
      "rotation": 7
    },
    {
      "x": -13,
      "y": 13,
      "z": 11,
      "name": "Rock_Shale_Brick_Smooth_Half",
      "rotation": 7
    },
    {
      "x": -13,
      "y": 30,
      "z": 11,
      "name": "Rock_Shale_Brick_Smooth_Half",
      "rotation": 7
    },
    {
      "x": -13,
      "y": 31,
      "z": 11,
      "name": "Rock_Shale_Brick_Smooth_Half",
      "rotation": 7
    },
    {
      "x": -13,
      "y": 32,
      "z": 11,
      "name": "Rock_Shale_Brick_Smooth_Half",
      "rotation": 7
    },
    {
      "x": -13,
      "y": 12,
      "z": 12,
      "name": "Rock_Shale_Brick_Smooth_Half",
      "rotation": 7
    },
    {
      "x": -13,
      "y": 13,
      "z": 12,
      "name": "Rock_Shale_Brick_Smooth_Half",
      "rotation": 7
    },
    {
      "x": -13,
      "y": 14,
      "z": 12,
      "name": "Rock_Shale_Brick_Smooth_Half",
      "rotation": 7
    },
    {
      "x": -13,
      "y": 31,
      "z": 12,
      "name": "Rock_Shale_Brick_Smooth_Half",
      "rotation": 7
    },
    {
      "x": -13,
      "y": 32,
      "z": 12,
      "name": "Rock_Shale_Brick_Smooth_Half",
      "rotation": 7
    },
    {
      "x": -13,
      "y": 33,
      "z": 12,
      "name": "Rock_Shale_Brick_Smooth_Half",
      "rotation": 7
    },
    {
      "x": -12,
      "y": 12,
      "z": -12,
      "name": "Rock_Shale_Brick_Stairs",
      "rotation": 50
    },
    {
      "x": -12,
      "y": 13,
      "z": -12,
      "name": "Rock_Shale_Brick_Stairs",
      "rotation": 50
    },
    {
      "x": -12,
      "y": 14,
      "z": -12,
      "name": "Rock_Shale_Brick_Stairs",
      "rotation": 50
    },
    {
      "x": -12,
      "y": 15,
      "z": -12,
      "name": "Rock_Shale_Brick_Stairs",
      "rotation": 50
    },
    {
      "x": -12,
      "y": 16,
      "z": -12,
      "name": "Rock_Shale_Brick_Stairs",
      "rotation": 50
    },
    {
      "x": -12,
      "y": 31,
      "z": -12,
      "name": "Rock_Shale_Brick_Stairs",
      "rotation": 50
    },
    {
      "x": -12,
      "y": 32,
      "z": -12,
      "name": "Rock_Shale_Brick_Stairs",
      "rotation": 50
    },
    {
      "x": -12,
      "y": 33,
      "z": -12,
      "name": "Rock_Shale_Brick_Stairs",
      "rotation": 50
    },
    {
      "x": -12,
      "y": 34,
      "z": -12,
      "name": "Rock_Shale_Brick_Stairs",
      "rotation": 50
    },
    {
      "x": -12,
      "y": 35,
      "z": -12,
      "name": "Rock_Shale_Brick_Stairs",
      "rotation": 50
    },
    {
      "x": -12,
      "y": 11,
      "z": -11,
      "name": "Rock_Shale_Brick_Smooth_Half",
      "rotation": 6
    },
    {
      "x": -12,
      "y": 12,
      "z": -11,
      "name": "Rock_Runic_Teal_Brick_Stairs",
      "rotation": 35
    },
    {
      "x": -12,
      "y": 13,
      "z": -11,
      "name": "Rock_Shale_Brick_Smooth_Half",
      "rotation": 4
    },
    {
      "x": -12,
      "y": 14,
      "z": -11,
      "name": "Rock_Shale_Brick_Smooth_Half",
      "rotation": 4
    },
    {
      "x": -12,
      "y": 15,
      "z": -11,
      "name": "Rock_Shale_Brick_Smooth_Half",
      "rotation": 4
    },
    {
      "x": -12,
      "y": 30,
      "z": -11,
      "name": "Rock_Shale_Brick_Smooth_Half",
      "rotation": 6
    },
    {
      "x": -12,
      "y": 31,
      "z": -11,
      "name": "Rock_Runic_Teal_Brick_Stairs",
      "rotation": 35
    },
    {
      "x": -12,
      "y": 32,
      "z": -11,
      "name": "Rock_Shale_Brick_Smooth_Half",
      "rotation": 4
    },
    {
      "x": -12,
      "y": 33,
      "z": -11,
      "name": "Rock_Shale_Brick_Smooth_Half",
      "rotation": 4
    },
    {
      "x": -12,
      "y": 34,
      "z": -11,
      "name": "Rock_Shale_Brick_Smooth_Half",
      "rotation": 4
    },
    {
      "x": -12,
      "y": 10,
      "z": -10,
      "name": "Rock_Shale_Brick_Smooth_Half",
      "rotation": 6
    },
    {
      "x": -12,
      "y": 11,
      "z": -10,
      "name": "Rock_Runic_Teal_Brick_Stairs",
      "rotation": 35
    },
    {
      "x": -12,
      "y": 12,
      "z": -10,
      "name": "Rock_Shale_Brick_Smooth_Half",
      "rotation": 4
    },
    {
      "x": -12,
      "y": 29,
      "z": -10,
      "name": "Rock_Shale_Brick_Smooth_Half",
      "rotation": 6
    },
    {
      "x": -12,
      "y": 30,
      "z": -10,
      "name": "Rock_Runic_Teal_Brick_Stairs",
      "rotation": 35
    },
    {
      "x": -12,
      "y": 31,
      "z": -10,
      "name": "Rock_Shale_Brick_Smooth_Half",
      "rotation": 4
    },
    {
      "x": -12,
      "y": 8,
      "z": -9,
      "name": "Rock_Shale_Brick_Smooth_Half",
      "rotation": 7
    },
    {
      "x": -12,
      "y": 9,
      "z": -9,
      "name": "Rock_Shale_Brick_Smooth_Half",
      "rotation": 7
    },
    {
      "x": -12,
      "y": 10,
      "z": -9,
      "name": "Rock_Runic_Teal_Brick_Stairs",
      "rotation": 35
    },
    {
      "x": -12,
      "y": 11,
      "z": -9,
      "name": "Rock_Shale_Brick_Smooth_Half",
      "rotation": 4
    },
    {
      "x": -12,
      "y": 27,
      "z": -9,
      "name": "Rock_Shale_Brick_Smooth_Half",
      "rotation": 7
    },
    {
      "x": -12,
      "y": 28,
      "z": -9,
      "name": "Rock_Shale_Brick_Smooth_Half",
      "rotation": 7
    },
    {
      "x": -12,
      "y": 29,
      "z": -9,
      "name": "Rock_Runic_Teal_Brick_Stairs",
      "rotation": 35
    },
    {
      "x": -12,
      "y": 30,
      "z": -9,
      "name": "Rock_Shale_Brick_Smooth_Half",
      "rotation": 4
    },
    {
      "x": -12,
      "y": 8,
      "z": -8,
      "name": "Rock_Shale_Brick_Smooth_Half",
      "rotation": 7
    },
    {
      "x": -12,
      "y": 9,
      "z": -8,
      "name": "Rock_Shale_Brick_Smooth_Half",
      "rotation": 7
    },
    {
      "x": -12,
      "y": 10,
      "z": -8,
      "name": "Rock_Shale_Brick_Smooth_Half",
      "rotation": 4
    },
    {
      "x": -12,
      "y": 27,
      "z": -8,
      "name": "Rock_Shale_Brick_Smooth_Half",
      "rotation": 7
    },
    {
      "x": -12,
      "y": 28,
      "z": -8,
      "name": "Rock_Shale_Brick_Smooth_Half",
      "rotation": 7
    },
    {
      "x": -12,
      "y": 29,
      "z": -8,
      "name": "Rock_Shale_Brick_Smooth_Half",
      "rotation": 4
    },
    {
      "x": -12,
      "y": 8,
      "z": -7,
      "name": "Rock_Shale_Brick_Smooth_Half",
      "rotation": 7
    },
    {
      "x": -12,
      "y": 9,
      "z": -7,
      "name": "Rock_Shale_Brick_Smooth_Half",
      "rotation": 7
    },
    {
      "x": -12,
      "y": 10,
      "z": -7,
      "name": "Rock_Shale_Brick_Smooth_Half",
      "rotation": 7
    },
    {
      "x": -12,
      "y": 27,
      "z": -7,
      "name": "Rock_Shale_Brick_Smooth_Half",
      "rotation": 7
    },
    {
      "x": -12,
      "y": 28,
      "z": -7,
      "name": "Rock_Shale_Brick_Smooth_Half",
      "rotation": 7
    },
    {
      "x": -12,
      "y": 29,
      "z": -7,
      "name": "Rock_Shale_Brick_Smooth_Half",
      "rotation": 7
    },
    {
      "x": -12,
      "y": 7,
      "z": -6,
      "name": "Rock_Shale_Brick_Smooth_Half",
      "rotation": 7
    },
    {
      "x": -12,
      "y": 8,
      "z": -6,
      "name": "Rock_Shale_Brick_Smooth_Half",
      "rotation": 7
    },
    {
      "x": -12,
      "y": 9,
      "z": -6,
      "name": "Rock_Shale_Brick_Smooth_Half",
      "rotation": 7
    },
    {
      "x": -12,
      "y": 10,
      "z": -6,
      "name": "Rock_Shale_Brick_Smooth_Half",
      "rotation": 7
    },
    {
      "x": -12,
      "y": 26,
      "z": -6,
      "name": "Rock_Shale_Brick_Smooth_Half",
      "rotation": 7
    },
    {
      "x": -12,
      "y": 27,
      "z": -6,
      "name": "Rock_Shale_Brick_Smooth_Half",
      "rotation": 7
    },
    {
      "x": -12,
      "y": 28,
      "z": -6,
      "name": "Rock_Shale_Brick_Smooth_Half",
      "rotation": 7
    },
    {
      "x": -12,
      "y": 29,
      "z": -6,
      "name": "Rock_Shale_Brick_Smooth_Half",
      "rotation": 7
    },
    {
      "x": -12,
      "y": 7,
      "z": 7,
      "name": "Rock_Shale_Brick_Smooth_Half",
      "rotation": 7
    },
    {
      "x": -12,
      "y": 8,
      "z": 7,
      "name": "Rock_Shale_Brick_Smooth_Half",
      "rotation": 7
    },
    {
      "x": -12,
      "y": 9,
      "z": 7,
      "name": "Rock_Shale_Brick_Smooth_Half",
      "rotation": 7
    },
    {
      "x": -12,
      "y": 10,
      "z": 7,
      "name": "Rock_Shale_Brick_Smooth_Half",
      "rotation": 7
    },
    {
      "x": -12,
      "y": 26,
      "z": 7,
      "name": "Rock_Shale_Brick_Smooth_Half",
      "rotation": 7
    },
    {
      "x": -12,
      "y": 27,
      "z": 7,
      "name": "Rock_Shale_Brick_Smooth_Half",
      "rotation": 7
    },
    {
      "x": -12,
      "y": 28,
      "z": 7,
      "name": "Rock_Shale_Brick_Smooth_Half",
      "rotation": 7
    },
    {
      "x": -12,
      "y": 29,
      "z": 7,
      "name": "Rock_Shale_Brick_Smooth_Half",
      "rotation": 7
    },
    {
      "x": -12,
      "y": 8,
      "z": 8,
      "name": "Rock_Shale_Brick_Smooth_Half",
      "rotation": 7
    },
    {
      "x": -12,
      "y": 9,
      "z": 8,
      "name": "Rock_Shale_Brick_Smooth_Half",
      "rotation": 7
    },
    {
      "x": -12,
      "y": 10,
      "z": 8,
      "name": "Rock_Shale_Brick_Smooth_Half",
      "rotation": 7
    },
    {
      "x": -12,
      "y": 27,
      "z": 8,
      "name": "Rock_Shale_Brick_Smooth_Half",
      "rotation": 7
    },
    {
      "x": -12,
      "y": 28,
      "z": 8,
      "name": "Rock_Shale_Brick_Smooth_Half",
      "rotation": 7
    },
    {
      "x": -12,
      "y": 29,
      "z": 8,
      "name": "Rock_Shale_Brick_Smooth_Half",
      "rotation": 7
    },
    {
      "x": -12,
      "y": 8,
      "z": 9,
      "name": "Rock_Shale_Brick_Smooth_Half",
      "rotation": 7
    },
    {
      "x": -12,
      "y": 9,
      "z": 9,
      "name": "Rock_Shale_Brick_Smooth_Half",
      "rotation": 7
    },
    {
      "x": -12,
      "y": 10,
      "z": 9,
      "name": "Rock_Shale_Brick_Smooth_Half",
      "rotation": 6
    },
    {
      "x": -12,
      "y": 27,
      "z": 9,
      "name": "Rock_Shale_Brick_Smooth_Half",
      "rotation": 7
    },
    {
      "x": -12,
      "y": 28,
      "z": 9,
      "name": "Rock_Shale_Brick_Smooth_Half",
      "rotation": 7
    },
    {
      "x": -12,
      "y": 29,
      "z": 9,
      "name": "Rock_Shale_Brick_Smooth_Half",
      "rotation": 6
    },
    {
      "x": -12,
      "y": 8,
      "z": 10,
      "name": "Rock_Shale_Brick_Smooth_Half",
      "rotation": 7
    },
    {
      "x": -12,
      "y": 9,
      "z": 10,
      "name": "Rock_Shale_Brick_Smooth_Half",
      "rotation": 7
    },
    {
      "x": -12,
      "y": 10,
      "z": 10,
      "name": "Rock_Runic_Teal_Brick_Stairs",
      "rotation": 9
    },
    {
      "x": -12,
      "y": 11,
      "z": 10,
      "name": "Rock_Shale_Brick_Smooth_Half",
      "rotation": 6
    },
    {
      "x": -12,
      "y": 27,
      "z": 10,
      "name": "Rock_Shale_Brick_Smooth_Half",
      "rotation": 7
    },
    {
      "x": -12,
      "y": 28,
      "z": 10,
      "name": "Rock_Shale_Brick_Smooth_Half",
      "rotation": 7
    },
    {
      "x": -12,
      "y": 29,
      "z": 10,
      "name": "Rock_Runic_Teal_Brick_Stairs",
      "rotation": 9
    },
    {
      "x": -12,
      "y": 30,
      "z": 10,
      "name": "Rock_Shale_Brick_Smooth_Half",
      "rotation": 6
    },
    {
      "x": -12,
      "y": 10,
      "z": 11,
      "name": "Rock_Shale_Brick_Smooth_Half",
      "rotation": 4
    },
    {
      "x": -12,
      "y": 11,
      "z": 11,
      "name": "Rock_Runic_Teal_Brick_Stairs",
      "rotation": 9
    },
    {
      "x": -12,
      "y": 12,
      "z": 11,
      "name": "Rock_Shale_Brick_Smooth_Half",
      "rotation": 6
    },
    {
      "x": -12,
      "y": 29,
      "z": 11,
      "name": "Rock_Shale_Brick_Smooth_Half",
      "rotation": 4
    },
    {
      "x": -12,
      "y": 30,
      "z": 11,
      "name": "Rock_Runic_Teal_Brick_Stairs",
      "rotation": 9
    },
    {
      "x": -12,
      "y": 31,
      "z": 11,
      "name": "Rock_Shale_Brick_Smooth_Half",
      "rotation": 6
    },
    {
      "x": -12,
      "y": 11,
      "z": 12,
      "name": "Rock_Shale_Brick_Smooth_Half",
      "rotation": 4
    },
    {
      "x": -12,
      "y": 12,
      "z": 12,
      "name": "Rock_Runic_Teal_Brick_Stairs",
      "rotation": 9
    },
    {
      "x": -12,
      "y": 13,
      "z": 12,
      "name": "Rock_Shale_Brick_Smooth_Half",
      "rotation": 6
    },
    {
      "x": -12,
      "y": 14,
      "z": 12,
      "name": "Rock_Shale_Brick_Smooth_Half",
      "rotation": 6
    },
    {
      "x": -12,
      "y": 15,
      "z": 12,
      "name": "Rock_Shale_Brick_Smooth_Half",
      "rotation": 6
    },
    {
      "x": -12,
      "y": 30,
      "z": 12,
      "name": "Rock_Shale_Brick_Smooth_Half",
      "rotation": 4
    },
    {
      "x": -12,
      "y": 31,
      "z": 12,
      "name": "Rock_Runic_Teal_Brick_Stairs",
      "rotation": 9
    },
    {
      "x": -12,
      "y": 32,
      "z": 12,
      "name": "Rock_Shale_Brick_Smooth_Half",
      "rotation": 6
    },
    {
      "x": -12,
      "y": 33,
      "z": 12,
      "name": "Rock_Shale_Brick_Smooth_Half",
      "rotation": 6
    },
    {
      "x": -12,
      "y": 34,
      "z": 12,
      "name": "Rock_Shale_Brick_Smooth_Half",
      "rotation": 6
    },
    {
      "x": -12,
      "y": 12,
      "z": 13,
      "name": "Rock_Shale_Brick_Stairs",
      "rotation": 25
    },
    {
      "x": -12,
      "y": 13,
      "z": 13,
      "name": "Rock_Shale_Brick_Stairs",
      "rotation": 25
    },
    {
      "x": -12,
      "y": 14,
      "z": 13,
      "name": "Rock_Shale_Brick_Stairs",
      "rotation": 25
    },
    {
      "x": -12,
      "y": 15,
      "z": 13,
      "name": "Rock_Shale_Brick_Stairs",
      "rotation": 25
    },
    {
      "x": -12,
      "y": 16,
      "z": 13,
      "name": "Rock_Shale_Brick_Stairs",
      "rotation": 25
    },
    {
      "x": -12,
      "y": 31,
      "z": 13,
      "name": "Rock_Shale_Brick_Stairs",
      "rotation": 25
    },
    {
      "x": -12,
      "y": 32,
      "z": 13,
      "name": "Rock_Shale_Brick_Stairs",
      "rotation": 25
    },
    {
      "x": -12,
      "y": 33,
      "z": 13,
      "name": "Rock_Shale_Brick_Stairs",
      "rotation": 25
    },
    {
      "x": -12,
      "y": 34,
      "z": 13,
      "name": "Rock_Shale_Brick_Stairs",
      "rotation": 25
    },
    {
      "x": -12,
      "y": 35,
      "z": 13,
      "name": "Rock_Shale_Brick_Stairs",
      "rotation": 25
    },
    {
      "x": -11,
      "y": 12,
      "z": -13,
      "name": "Rock_Shale_Brick_Smooth_Half",
      "rotation": 6
    },
    {
      "x": -11,
      "y": 13,
      "z": -13,
      "name": "Rock_Shale_Brick_Smooth_Half",
      "rotation": 6
    },
    {
      "x": -11,
      "y": 14,
      "z": -13,
      "name": "Rock_Shale_Brick_Smooth_Half",
      "rotation": 6
    },
    {
      "x": -11,
      "y": 31,
      "z": -13,
      "name": "Rock_Shale_Brick_Smooth_Half",
      "rotation": 6
    },
    {
      "x": -11,
      "y": 32,
      "z": -13,
      "name": "Rock_Shale_Brick_Smooth_Half",
      "rotation": 6
    },
    {
      "x": -11,
      "y": 33,
      "z": -13,
      "name": "Rock_Shale_Brick_Smooth_Half",
      "rotation": 6
    },
    {
      "x": -11,
      "y": 11,
      "z": -12,
      "name": "Rock_Shale_Brick_Smooth_Half",
      "rotation": 7
    },
    {
      "x": -11,
      "y": 12,
      "z": -12,
      "name": "Rock_Runic_Teal_Brick_Stairs",
      "rotation": 34
    },
    {
      "x": -11,
      "y": 13,
      "z": -12,
      "name": "Rock_Shale_Brick_Smooth_Half",
      "rotation": 5
    },
    {
      "x": -11,
      "y": 14,
      "z": -12,
      "name": "Rock_Shale_Brick_Smooth_Half",
      "rotation": 5
    },
    {
      "x": -11,
      "y": 15,
      "z": -12,
      "name": "Rock_Shale_Brick_Smooth_Half",
      "rotation": 5
    },
    {
      "x": -11,
      "y": 30,
      "z": -12,
      "name": "Rock_Shale_Brick_Smooth_Half",
      "rotation": 7
    },
    {
      "x": -11,
      "y": 31,
      "z": -12,
      "name": "Rock_Runic_Teal_Brick_Stairs",
      "rotation": 34
    },
    {
      "x": -11,
      "y": 32,
      "z": -12,
      "name": "Rock_Shale_Brick_Smooth_Half",
      "rotation": 5
    },
    {
      "x": -11,
      "y": 33,
      "z": -12,
      "name": "Rock_Shale_Brick_Smooth_Half",
      "rotation": 5
    },
    {
      "x": -11,
      "y": 34,
      "z": -12,
      "name": "Rock_Shale_Brick_Smooth_Half",
      "rotation": 5
    },
    {
      "x": -11,
      "y": 12,
      "z": -11,
      "name": "Rock_Shale_Brick_Smooth"
    },
    {
      "x": -11,
      "y": 31,
      "z": -11,
      "name": "Rock_Shale_Brick_Smooth"
    },
    {
      "x": -11,
      "y": 8,
      "z": -10,
      "name": "Rock_Shale_Brick_Smooth_Half",
      "rotation": 6
    },
    {
      "x": -11,
      "y": 9,
      "z": -10,
      "name": "Rock_Shale_Brick_Smooth_Half",
      "rotation": 7
    },
    {
      "x": -11,
      "y": 10,
      "z": -10,
      "name": "Rock_Shale_Brick_Smooth_Half",
      "rotation": 7
    },
    {
      "x": -11,
      "y": 11,
      "z": -10,
      "name": "Rock_Shale_Brick_Smooth"
    },
    {
      "x": -11,
      "y": 27,
      "z": -10,
      "name": "Rock_Shale_Brick_Smooth_Half",
      "rotation": 6
    },
    {
      "x": -11,
      "y": 28,
      "z": -10,
      "name": "Rock_Shale_Brick_Smooth_Half",
      "rotation": 7
    },
    {
      "x": -11,
      "y": 29,
      "z": -10,
      "name": "Rock_Shale_Brick_Smooth_Half",
      "rotation": 7
    },
    {
      "x": -11,
      "y": 30,
      "z": -10,
      "name": "Rock_Shale_Brick_Smooth"
    },
    {
      "x": -11,
      "y": 0,
      "z": -9,
      "name": "Rock_Shale_Brick_Smooth"
    },
    {
      "x": -11,
      "y": 1,
      "z": -9,
      "name": "Rock_Shale_Brick_Smooth"
    },
    {
      "x": -11,
      "y": 2,
      "z": -9,
      "name": "Rock_Shale_Brick_Smooth"
    },
    {
      "x": -11,
      "y": 3,
      "z": -9,
      "name": "Rock_Shale_Brick_Smooth"
    },
    {
      "x": -11,
      "y": 4,
      "z": -9,
      "name": "Rock_Shale_Brick_Smooth"
    },
    {
      "x": -11,
      "y": 5,
      "z": -9,
      "name": "Rock_Shale_Brick_Smooth"
    },
    {
      "x": -11,
      "y": 6,
      "z": -9,
      "name": "Rock_Shale_Brick_Smooth"
    },
    {
      "x": -11,
      "y": 7,
      "z": -9,
      "name": "Rock_Shale_Brick_Smooth_Half",
      "rotation": 7
    },
    {
      "x": -11,
      "y": 8,
      "z": -9,
      "name": "Rock_Runic_Teal_Brick_Stairs",
      "rotation": 35
    },
    {
      "x": -11,
      "y": 9,
      "z": -9,
      "name": "Rock_Shale_Brick_Smooth_Half",
      "rotation": 4
    },
    {
      "x": -11,
      "y": 10,
      "z": -9,
      "name": "Rock_Shale_Brick_Smooth_Half",
      "rotation": 5
    },
    {
      "x": -11,
      "y": 11,
      "z": -9,
      "name": "Rock_Shale_Brick_Smooth_Half",
      "rotation": 7
    },
    {
      "x": -11,
      "y": 12,
      "z": -9,
      "name": "Rock_Shale_Brick_Smooth_Half",
      "rotation": 7
    },
    {
      "x": -11,
      "y": 13,
      "z": -9,
      "name": "Rock_Shale_Brick_Smooth_Half",
      "rotation": 7
    },
    {
      "x": -11,
      "y": 14,
      "z": -9,
      "name": "Rock_Shale_Brick_Smooth_Half",
      "rotation": 7
    },
    {
      "x": -11,
      "y": 26,
      "z": -9,
      "name": "Rock_Shale_Brick_Smooth_Half",
      "rotation": 7
    },
    {
      "x": -11,
      "y": 27,
      "z": -9,
      "name": "Rock_Runic_Teal_Brick_Stairs",
      "rotation": 35
    },
    {
      "x": -11,
      "y": 28,
      "z": -9,
      "name": "Rock_Shale_Brick_Smooth_Half",
      "rotation": 4
    },
    {
      "x": -11,
      "y": 29,
      "z": -9,
      "name": "Rock_Shale_Brick_Smooth_Half",
      "rotation": 5
    },
    {
      "x": -11,
      "y": 30,
      "z": -9,
      "name": "Rock_Shale_Brick_Smooth_Half",
      "rotation": 7
    },
    {
      "x": -11,
      "y": 31,
      "z": -9,
      "name": "Rock_Shale_Brick_Smooth_Half",
      "rotation": 7
    },
    {
      "x": -11,
      "y": 32,
      "z": -9,
      "name": "Rock_Shale_Brick_Smooth_Half",
      "rotation": 7
    },
    {
      "x": -11,
      "y": 33,
      "z": -9,
      "name": "Rock_Shale_Brick_Smooth_Half",
      "rotation": 7
    },
    {
      "x": -11,
      "y": 0,
      "z": -8,
      "name": "Rock_Shale_Brick_Smooth"
    },
    {
      "x": -11,
      "y": 1,
      "z": -8,
      "name": "Rock_Shale_Brick_Smooth"
    },
    {
      "x": -11,
      "y": 2,
      "z": -8,
      "name": "Rock_Shale_Brick_Smooth"
    },
    {
      "x": -11,
      "y": 3,
      "z": -8,
      "name": "Rock_Shale_Brick_Smooth"
    },
    {
      "x": -11,
      "y": 4,
      "z": -8,
      "name": "Rock_Shale_Brick_Smooth"
    },
    {
      "x": -11,
      "y": 5,
      "z": -8,
      "name": "Rock_Shale_Brick_Smooth_Half",
      "rotation": 7
    },
    {
      "x": -11,
      "y": 6,
      "z": -8,
      "name": "Rock_Shale_Brick_Smooth_Half",
      "rotation": 7
    },
    {
      "x": -11,
      "y": 7,
      "z": -8,
      "name": "Rock_Shale_Brick_Smooth_Half",
      "rotation": 7
    },
    {
      "x": -11,
      "y": 8,
      "z": -8,
      "name": "Rock_Runic_Teal_Brick_Stairs",
      "rotation": 35
    },
    {
      "x": -11,
      "y": 10,
      "z": -8,
      "name": "Rock_Shale_Brick_Smooth_Half",
      "rotation": 7
    },
    {
      "x": -11,
      "y": 11,
      "z": -8,
      "name": "Rock_Shale_Brick_Smooth_Half",
      "rotation": 7
    },
    {
      "x": -11,
      "y": 24,
      "z": -8,
      "name": "Rock_Shale_Brick_Smooth_Half",
      "rotation": 7
    },
    {
      "x": -11,
      "y": 25,
      "z": -8,
      "name": "Rock_Shale_Brick_Smooth_Half",
      "rotation": 7
    },
    {
      "x": -11,
      "y": 26,
      "z": -8,
      "name": "Rock_Shale_Brick_Smooth_Half",
      "rotation": 7
    },
    {
      "x": -11,
      "y": 27,
      "z": -8,
      "name": "Rock_Runic_Teal_Brick_Stairs",
      "rotation": 35
    },
    {
      "x": -11,
      "y": 29,
      "z": -8,
      "name": "Rock_Shale_Brick_Smooth_Half",
      "rotation": 7
    },
    {
      "x": -11,
      "y": 30,
      "z": -8,
      "name": "Rock_Shale_Brick_Smooth_Half",
      "rotation": 7
    },
    {
      "x": -11,
      "y": 0,
      "z": -7,
      "name": "Rock_Shale_Brick_Smooth"
    },
    {
      "x": -11,
      "y": 1,
      "z": -7,
      "name": "Rock_Shale_Brick_Smooth"
    },
    {
      "x": -11,
      "y": 2,
      "z": -7,
      "name": "Rock_Shale_Brick_Smooth_Half",
      "rotation": 7
    },
    {
      "x": -11,
      "y": 3,
      "z": -7,
      "name": "Rock_Shale_Brick_Smooth_Half",
      "rotation": 7
    },
    {
      "x": -11,
      "y": 4,
      "z": -7,
      "name": "Rock_Shale_Brick_Smooth_Half",
      "rotation": 7
    },
    {
      "x": -11,
      "y": 5,
      "z": -7,
      "name": "Rock_Shale_Brick_Smooth_Half",
      "rotation": 7
    },
    {
      "x": -11,
      "y": 6,
      "z": -7,
      "name": "Rock_Shale_Brick_Smooth_Half",
      "rotation": 7
    },
    {
      "x": -11,
      "y": 7,
      "z": -7,
      "name": "Rock_Shale_Brick_Smooth_Half",
      "rotation": 7
    },
    {
      "x": -11,
      "y": 8,
      "z": -7,
      "name": "Rock_Runic_Teal_Brick_Stairs",
      "rotation": 35
    },
    {
      "x": -11,
      "y": 21,
      "z": -7,
      "name": "Rock_Shale_Brick_Smooth_Half",
      "rotation": 7
    },
    {
      "x": -11,
      "y": 22,
      "z": -7,
      "name": "Rock_Shale_Brick_Smooth_Half",
      "rotation": 7
    },
    {
      "x": -11,
      "y": 23,
      "z": -7,
      "name": "Rock_Shale_Brick_Smooth_Half",
      "rotation": 7
    },
    {
      "x": -11,
      "y": 24,
      "z": -7,
      "name": "Rock_Shale_Brick_Smooth_Half",
      "rotation": 7
    },
    {
      "x": -11,
      "y": 25,
      "z": -7,
      "name": "Rock_Shale_Brick_Smooth_Half",
      "rotation": 7
    },
    {
      "x": -11,
      "y": 26,
      "z": -7,
      "name": "Rock_Shale_Brick_Smooth_Half",
      "rotation": 7
    },
    {
      "x": -11,
      "y": 27,
      "z": -7,
      "name": "Rock_Runic_Teal_Brick_Stairs",
      "rotation": 35
    },
    {
      "x": -11,
      "y": 7,
      "z": -6,
      "name": "Rock_Runic_Teal_Brick_Stairs",
      "rotation": 32
    },
    {
      "x": -11,
      "y": 8,
      "z": -6,
      "name": "Rock_Shale_Brick_Smooth_Half",
      "rotation": 6
    },
    {
      "x": -11,
      "y": 9,
      "z": -6,
      "name": "Rock_Shale_Brick_Smooth_Half",
      "rotation": 6
    },
    {
      "x": -11,
      "y": 10,
      "z": -6,
      "name": "Rock_Shale_Brick_Smooth_Half",
      "rotation": 6
    },
    {
      "x": -11,
      "y": 26,
      "z": -6,
      "name": "Rock_Runic_Teal_Brick_Stairs",
      "rotation": 32
    },
    {
      "x": -11,
      "y": 27,
      "z": -6,
      "name": "Rock_Shale_Brick_Smooth_Half",
      "rotation": 6
    },
    {
      "x": -11,
      "y": 28,
      "z": -6,
      "name": "Rock_Shale_Brick_Smooth_Half",
      "rotation": 6
    },
    {
      "x": -11,
      "y": 29,
      "z": -6,
      "name": "Rock_Shale_Brick_Smooth_Half",
      "rotation": 6
    },
    {
      "x": -11,
      "y": 7,
      "z": -5,
      "name": "Rock_Shale_Brick_Smooth_Half",
      "rotation": 7
    },
    {
      "x": -11,
      "y": 8,
      "z": -5,
      "name": "Rock_Shale_Brick_Smooth_Half",
      "rotation": 7
    },
    {
      "x": -11,
      "y": 9,
      "z": -5,
      "name": "Rock_Shale_Brick_Smooth_Half",
      "rotation": 7
    },
    {
      "x": -11,
      "y": 26,
      "z": -5,
      "name": "Rock_Shale_Brick_Smooth_Half",
      "rotation": 7
    },
    {
      "x": -11,
      "y": 27,
      "z": -5,
      "name": "Rock_Shale_Brick_Smooth_Half",
      "rotation": 7
    },
    {
      "x": -11,
      "y": 28,
      "z": -5,
      "name": "Rock_Shale_Brick_Smooth_Half",
      "rotation": 7
    },
    {
      "x": -11,
      "y": 7,
      "z": 6,
      "name": "Rock_Shale_Brick_Smooth_Half",
      "rotation": 7
    },
    {
      "x": -11,
      "y": 8,
      "z": 6,
      "name": "Rock_Shale_Brick_Smooth_Half",
      "rotation": 7
    },
    {
      "x": -11,
      "y": 9,
      "z": 6,
      "name": "Rock_Shale_Brick_Smooth_Half",
      "rotation": 7
    },
    {
      "x": -11,
      "y": 26,
      "z": 6,
      "name": "Rock_Shale_Brick_Smooth_Half",
      "rotation": 7
    },
    {
      "x": -11,
      "y": 27,
      "z": 6,
      "name": "Rock_Shale_Brick_Smooth_Half",
      "rotation": 7
    },
    {
      "x": -11,
      "y": 28,
      "z": 6,
      "name": "Rock_Shale_Brick_Smooth_Half",
      "rotation": 7
    },
    {
      "x": -11,
      "y": 7,
      "z": 7,
      "name": "Rock_Runic_Teal_Brick_Stairs",
      "rotation": 8
    },
    {
      "x": -11,
      "y": 8,
      "z": 7,
      "name": "Rock_Shale_Brick_Smooth_Half",
      "rotation": 4
    },
    {
      "x": -11,
      "y": 9,
      "z": 7,
      "name": "Rock_Shale_Brick_Smooth_Half",
      "rotation": 4
    },
    {
      "x": -11,
      "y": 10,
      "z": 7,
      "name": "Rock_Shale_Brick_Smooth_Half",
      "rotation": 4
    },
    {
      "x": -11,
      "y": 26,
      "z": 7,
      "name": "Rock_Runic_Teal_Brick_Stairs",
      "rotation": 8
    },
    {
      "x": -11,
      "y": 27,
      "z": 7,
      "name": "Rock_Shale_Brick_Smooth_Half",
      "rotation": 4
    },
    {
      "x": -11,
      "y": 28,
      "z": 7,
      "name": "Rock_Shale_Brick_Smooth_Half",
      "rotation": 4
    },
    {
      "x": -11,
      "y": 29,
      "z": 7,
      "name": "Rock_Shale_Brick_Smooth_Half",
      "rotation": 4
    },
    {
      "x": -11,
      "y": 2,
      "z": 8,
      "name": "Rock_Shale_Brick_Smooth_Half",
      "rotation": 7
    },
    {
      "x": -11,
      "y": 3,
      "z": 8,
      "name": "Rock_Shale_Brick_Smooth_Half",
      "rotation": 7
    },
    {
      "x": -11,
      "y": 4,
      "z": 8,
      "name": "Rock_Shale_Brick_Smooth_Half",
      "rotation": 7
    },
    {
      "x": -11,
      "y": 5,
      "z": 8,
      "name": "Rock_Shale_Brick_Smooth_Half",
      "rotation": 7
    },
    {
      "x": -11,
      "y": 6,
      "z": 8,
      "name": "Rock_Shale_Brick_Smooth_Half",
      "rotation": 7
    },
    {
      "x": -11,
      "y": 7,
      "z": 8,
      "name": "Rock_Shale_Brick_Smooth_Half",
      "rotation": 7
    },
    {
      "x": -11,
      "y": 8,
      "z": 8,
      "name": "Rock_Runic_Teal_Brick_Stairs",
      "rotation": 9
    },
    {
      "x": -11,
      "y": 21,
      "z": 8,
      "name": "Rock_Shale_Brick_Smooth_Half",
      "rotation": 7
    },
    {
      "x": -11,
      "y": 22,
      "z": 8,
      "name": "Rock_Shale_Brick_Smooth_Half",
      "rotation": 7
    },
    {
      "x": -11,
      "y": 23,
      "z": 8,
      "name": "Rock_Shale_Brick_Smooth_Half",
      "rotation": 7
    },
    {
      "x": -11,
      "y": 24,
      "z": 8,
      "name": "Rock_Shale_Brick_Smooth_Half",
      "rotation": 7
    },
    {
      "x": -11,
      "y": 25,
      "z": 8,
      "name": "Rock_Shale_Brick_Smooth_Half",
      "rotation": 7
    },
    {
      "x": -11,
      "y": 26,
      "z": 8,
      "name": "Rock_Shale_Brick_Smooth_Half",
      "rotation": 7
    },
    {
      "x": -11,
      "y": 27,
      "z": 8,
      "name": "Rock_Runic_Teal_Brick_Stairs",
      "rotation": 9
    },
    {
      "x": -11,
      "y": 5,
      "z": 9,
      "name": "Rock_Shale_Brick_Smooth_Half",
      "rotation": 7
    },
    {
      "x": -11,
      "y": 6,
      "z": 9,
      "name": "Rock_Shale_Brick_Smooth_Half",
      "rotation": 7
    },
    {
      "x": -11,
      "y": 7,
      "z": 9,
      "name": "Rock_Shale_Brick_Smooth_Half",
      "rotation": 7
    },
    {
      "x": -11,
      "y": 8,
      "z": 9,
      "name": "Rock_Runic_Teal_Brick_Stairs",
      "rotation": 9
    },
    {
      "x": -11,
      "y": 11,
      "z": 9,
      "name": "Rock_Shale_Brick_Smooth_Half",
      "rotation": 7
    },
    {
      "x": -11,
      "y": 24,
      "z": 9,
      "name": "Rock_Shale_Brick_Smooth_Half",
      "rotation": 7
    },
    {
      "x": -11,
      "y": 25,
      "z": 9,
      "name": "Rock_Shale_Brick_Smooth_Half",
      "rotation": 7
    },
    {
      "x": -11,
      "y": 26,
      "z": 9,
      "name": "Rock_Shale_Brick_Smooth_Half",
      "rotation": 7
    },
    {
      "x": -11,
      "y": 27,
      "z": 9,
      "name": "Rock_Runic_Teal_Brick_Stairs",
      "rotation": 9
    },
    {
      "x": -11,
      "y": 30,
      "z": 9,
      "name": "Rock_Shale_Brick_Smooth_Half",
      "rotation": 7
    },
    {
      "x": -11,
      "y": 7,
      "z": 10,
      "name": "Rock_Shale_Brick_Smooth_Half",
      "rotation": 7
    },
    {
      "x": -11,
      "y": 8,
      "z": 10,
      "name": "Rock_Runic_Teal_Brick_Stairs",
      "rotation": 9
    },
    {
      "x": -11,
      "y": 9,
      "z": 10,
      "name": "Rock_Shale_Brick_Smooth_Half",
      "rotation": 6
    },
    {
      "x": -11,
      "y": 10,
      "z": 10,
      "name": "Rock_Shale_Brick_Smooth_Half",
      "rotation": 5
    },
    {
      "x": -11,
      "y": 11,
      "z": 10,
      "name": "Rock_Shale_Brick_Smooth_Half",
      "rotation": 7
    },
    {
      "x": -11,
      "y": 12,
      "z": 10,
      "name": "Rock_Shale_Brick_Smooth_Half",
      "rotation": 7
    },
    {
      "x": -11,
      "y": 13,
      "z": 10,
      "name": "Rock_Shale_Brick_Smooth_Half",
      "rotation": 7
    },
    {
      "x": -11,
      "y": 14,
      "z": 10,
      "name": "Rock_Shale_Brick_Smooth_Half",
      "rotation": 7
    },
    {
      "x": -11,
      "y": 26,
      "z": 10,
      "name": "Rock_Shale_Brick_Smooth_Half",
      "rotation": 7
    },
    {
      "x": -11,
      "y": 27,
      "z": 10,
      "name": "Rock_Runic_Teal_Brick_Stairs",
      "rotation": 9
    },
    {
      "x": -11,
      "y": 28,
      "z": 10,
      "name": "Rock_Shale_Brick_Smooth_Half",
      "rotation": 6
    },
    {
      "x": -11,
      "y": 29,
      "z": 10,
      "name": "Rock_Shale_Brick_Smooth_Half",
      "rotation": 5
    },
    {
      "x": -11,
      "y": 30,
      "z": 10,
      "name": "Rock_Shale_Brick_Smooth_Half",
      "rotation": 7
    },
    {
      "x": -11,
      "y": 31,
      "z": 10,
      "name": "Rock_Shale_Brick_Smooth_Half",
      "rotation": 7
    },
    {
      "x": -11,
      "y": 32,
      "z": 10,
      "name": "Rock_Shale_Brick_Smooth_Half",
      "rotation": 7
    },
    {
      "x": -11,
      "y": 33,
      "z": 10,
      "name": "Rock_Shale_Brick_Smooth_Half",
      "rotation": 7
    },
    {
      "x": -11,
      "y": 8,
      "z": 11,
      "name": "Rock_Shale_Brick_Smooth_Half",
      "rotation": 4
    },
    {
      "x": -11,
      "y": 9,
      "z": 11,
      "name": "Rock_Shale_Brick_Smooth_Half",
      "rotation": 7
    },
    {
      "x": -11,
      "y": 10,
      "z": 11,
      "name": "Rock_Shale_Brick_Smooth_Half",
      "rotation": 7
    },
    {
      "x": -11,
      "y": 11,
      "z": 11,
      "name": "Rock_Shale_Brick_Smooth"
    },
    {
      "x": -11,
      "y": 27,
      "z": 11,
      "name": "Rock_Shale_Brick_Smooth_Half",
      "rotation": 4
    },
    {
      "x": -11,
      "y": 28,
      "z": 11,
      "name": "Rock_Shale_Brick_Smooth_Half",
      "rotation": 7
    },
    {
      "x": -11,
      "y": 29,
      "z": 11,
      "name": "Rock_Shale_Brick_Smooth_Half",
      "rotation": 7
    },
    {
      "x": -11,
      "y": 30,
      "z": 11,
      "name": "Rock_Shale_Brick_Smooth"
    },
    {
      "x": -11,
      "y": 12,
      "z": 12,
      "name": "Rock_Shale_Brick_Smooth"
    },
    {
      "x": -11,
      "y": 31,
      "z": 12,
      "name": "Rock_Shale_Brick_Smooth"
    },
    {
      "x": -11,
      "y": 11,
      "z": 13,
      "name": "Rock_Shale_Brick_Smooth_Half",
      "rotation": 7
    },
    {
      "x": -11,
      "y": 12,
      "z": 13,
      "name": "Rock_Runic_Teal_Brick_Stairs",
      "rotation": 10
    },
    {
      "x": -11,
      "y": 13,
      "z": 13,
      "name": "Rock_Shale_Brick_Smooth_Half",
      "rotation": 5
    },
    {
      "x": -11,
      "y": 14,
      "z": 13,
      "name": "Rock_Shale_Brick_Smooth_Half",
      "rotation": 5
    },
    {
      "x": -11,
      "y": 15,
      "z": 13,
      "name": "Rock_Shale_Brick_Smooth_Half",
      "rotation": 5
    },
    {
      "x": -11,
      "y": 30,
      "z": 13,
      "name": "Rock_Shale_Brick_Smooth_Half",
      "rotation": 7
    },
    {
      "x": -11,
      "y": 31,
      "z": 13,
      "name": "Rock_Runic_Teal_Brick_Stairs",
      "rotation": 10
    },
    {
      "x": -11,
      "y": 32,
      "z": 13,
      "name": "Rock_Shale_Brick_Smooth_Half",
      "rotation": 5
    },
    {
      "x": -11,
      "y": 33,
      "z": 13,
      "name": "Rock_Shale_Brick_Smooth_Half",
      "rotation": 5
    },
    {
      "x": -11,
      "y": 34,
      "z": 13,
      "name": "Rock_Shale_Brick_Smooth_Half",
      "rotation": 5
    },
    {
      "x": -11,
      "y": 12,
      "z": 14,
      "name": "Rock_Shale_Brick_Smooth_Half",
      "rotation": 4
    },
    {
      "x": -11,
      "y": 13,
      "z": 14,
      "name": "Rock_Shale_Brick_Smooth_Half",
      "rotation": 4
    },
    {
      "x": -11,
      "y": 14,
      "z": 14,
      "name": "Rock_Shale_Brick_Smooth_Half",
      "rotation": 4
    },
    {
      "x": -11,
      "y": 31,
      "z": 14,
      "name": "Rock_Shale_Brick_Smooth_Half",
      "rotation": 4
    },
    {
      "x": -11,
      "y": 32,
      "z": 14,
      "name": "Rock_Shale_Brick_Smooth_Half",
      "rotation": 4
    },
    {
      "x": -11,
      "y": 33,
      "z": 14,
      "name": "Rock_Shale_Brick_Smooth_Half",
      "rotation": 4
    },
    {
      "x": -10,
      "y": 11,
      "z": -13,
      "name": "Rock_Shale_Brick_Smooth_Half",
      "rotation": 6
    },
    {
      "x": -10,
      "y": 12,
      "z": -13,
      "name": "Rock_Shale_Brick_Smooth_Half",
      "rotation": 6
    },
    {
      "x": -10,
      "y": 13,
      "z": -13,
      "name": "Rock_Shale_Brick_Smooth_Half",
      "rotation": 6
    },
    {
      "x": -10,
      "y": 30,
      "z": -13,
      "name": "Rock_Shale_Brick_Smooth_Half",
      "rotation": 6
    },
    {
      "x": -10,
      "y": 31,
      "z": -13,
      "name": "Rock_Shale_Brick_Smooth_Half",
      "rotation": 6
    },
    {
      "x": -10,
      "y": 32,
      "z": -13,
      "name": "Rock_Shale_Brick_Smooth_Half",
      "rotation": 6
    },
    {
      "x": -10,
      "y": 10,
      "z": -12,
      "name": "Rock_Shale_Brick_Smooth_Half",
      "rotation": 7
    },
    {
      "x": -10,
      "y": 11,
      "z": -12,
      "name": "Rock_Runic_Teal_Brick_Stairs",
      "rotation": 34
    },
    {
      "x": -10,
      "y": 12,
      "z": -12,
      "name": "Rock_Shale_Brick_Smooth_Half",
      "rotation": 5
    },
    {
      "x": -10,
      "y": 29,
      "z": -12,
      "name": "Rock_Shale_Brick_Smooth_Half",
      "rotation": 7
    },
    {
      "x": -10,
      "y": 30,
      "z": -12,
      "name": "Rock_Runic_Teal_Brick_Stairs",
      "rotation": 34
    },
    {
      "x": -10,
      "y": 31,
      "z": -12,
      "name": "Rock_Shale_Brick_Smooth_Half",
      "rotation": 5
    },
    {
      "x": -10,
      "y": 8,
      "z": -11,
      "name": "Rock_Shale_Brick_Smooth_Half",
      "rotation": 7
    },
    {
      "x": -10,
      "y": 9,
      "z": -11,
      "name": "Rock_Shale_Brick_Smooth_Half",
      "rotation": 6
    },
    {
      "x": -10,
      "y": 10,
      "z": -11,
      "name": "Rock_Shale_Brick_Smooth_Half",
      "rotation": 6
    },
    {
      "x": -10,
      "y": 11,
      "z": -11,
      "name": "Rock_Shale_Brick_Smooth"
    },
    {
      "x": -10,
      "y": 27,
      "z": -11,
      "name": "Rock_Shale_Brick_Smooth_Half",
      "rotation": 7
    },
    {
      "x": -10,
      "y": 28,
      "z": -11,
      "name": "Rock_Shale_Brick_Smooth_Half",
      "rotation": 6
    },
    {
      "x": -10,
      "y": 29,
      "z": -11,
      "name": "Rock_Shale_Brick_Smooth_Half",
      "rotation": 6
    },
    {
      "x": -10,
      "y": 30,
      "z": -11,
      "name": "Rock_Shale_Brick_Smooth"
    },
    {
      "x": -10,
      "y": 0,
      "z": -10,
      "name": "Rock_Shale_Brick_Smooth"
    },
    {
      "x": -10,
      "y": 1,
      "z": -10,
      "name": "Rock_Shale_Brick_Smooth"
    },
    {
      "x": -10,
      "y": 2,
      "z": -10,
      "name": "Rock_Shale_Brick_Smooth"
    },
    {
      "x": -10,
      "y": 3,
      "z": -10,
      "name": "Rock_Shale_Brick_Smooth"
    },
    {
      "x": -10,
      "y": 4,
      "z": -10,
      "name": "Rock_Shale_Brick_Smooth"
    },
    {
      "x": -10,
      "y": 5,
      "z": -10,
      "name": "Rock_Shale_Brick_Smooth"
    },
    {
      "x": -10,
      "y": 6,
      "z": -10,
      "name": "Rock_Shale_Brick_Smooth"
    },
    {
      "x": -10,
      "y": 8,
      "z": -10,
      "name": "Rock_Shale_Brick_Smooth_Half",
      "rotation": 33
    },
    {
      "x": -10,
      "y": 9,
      "z": -10,
      "name": "Rock_Runic_Teal_Brick_Stairs",
      "rotation": 34
    },
    {
      "x": -10,
      "y": 13,
      "z": -10,
      "name": "Rock_Shale_Brick_Stairs",
      "rotation": 50
    },
    {
      "x": -10,
      "y": 14,
      "z": -10,
      "name": "Rock_Shale_Brick_Stairs",
      "rotation": 50
    },
    {
      "x": -10,
      "y": 15,
      "z": -10,
      "name": "Rock_Shale_Brick_Stairs",
      "rotation": 50
    },
    {
      "x": -10,
      "y": 16,
      "z": -10,
      "name": "Rock_Shale_Brick_Stairs",
      "rotation": 50
    },
    {
      "x": -10,
      "y": 17,
      "z": -10,
      "name": "Rock_Shale_Brick_Stairs",
      "rotation": 50
    },
    {
      "x": -10,
      "y": 27,
      "z": -10,
      "name": "Rock_Shale_Brick_Smooth_Half",
      "rotation": 33
    },
    {
      "x": -10,
      "y": 28,
      "z": -10,
      "name": "Rock_Runic_Teal_Brick_Stairs",
      "rotation": 34
    },
    {
      "x": -10,
      "y": 32,
      "z": -10,
      "name": "Rock_Shale_Brick_Stairs",
      "rotation": 50
    },
    {
      "x": -10,
      "y": 33,
      "z": -10,
      "name": "Rock_Shale_Brick_Stairs",
      "rotation": 50
    },
    {
      "x": -10,
      "y": 34,
      "z": -10,
      "name": "Rock_Shale_Brick_Stairs",
      "rotation": 50
    },
    {
      "x": -10,
      "y": 35,
      "z": -10,
      "name": "Rock_Shale_Brick_Stairs",
      "rotation": 50
    },
    {
      "x": -10,
      "y": 36,
      "z": -10,
      "name": "Rock_Shale_Brick_Stairs",
      "rotation": 50
    },
    {
      "x": -10,
      "y": 0,
      "z": -9,
      "name": "Rock_Shale_Brick_Smooth"
    },
    {
      "x": -10,
      "y": 1,
      "z": -9,
      "name": "Rock_Shale_Brick_Smooth"
    },
    {
      "x": -10,
      "y": 2,
      "z": -9,
      "name": "Rock_Shale_Brick_Smooth"
    },
    {
      "x": -10,
      "y": 3,
      "z": -9,
      "name": "Rock_Shale_Brick_Smooth"
    },
    {
      "x": -10,
      "y": 4,
      "z": -9,
      "name": "Rock_Shale_Brick_Smooth"
    },
    {
      "x": -10,
      "y": 5,
      "z": -9,
      "name": "Rock_Shale_Brick_Smooth"
    },
    {
      "x": -10,
      "y": 6,
      "z": -9,
      "name": "Rock_Shale_Brick_Smooth"
    },
    {
      "x": -10,
      "y": 7,
      "z": -9,
      "name": "Rock_Shale_Brick_Smooth"
    },
    {
      "x": -10,
      "y": 8,
      "z": -9,
      "name": "Rock_Shale_Brick_Smooth"
    },
    {
      "x": -10,
      "y": 9,
      "z": -9,
      "name": "Rock_Shale_Brick_Smooth"
    },
    {
      "x": -10,
      "y": 10,
      "z": -9,
      "name": "Rock_Shale_Brick_Smooth"
    },
    {
      "x": -10,
      "y": 11,
      "z": -9,
      "name": "Rock_Shale_Brick_Smooth"
    },
    {
      "x": -10,
      "y": 12,
      "z": -9,
      "name": "Rock_Shale_Brick_Smooth"
    },
    {
      "x": -10,
      "y": 13,
      "z": -9,
      "name": "Rock_Shale_Brick_Smooth"
    },
    {
      "x": -10,
      "y": 14,
      "z": -9,
      "name": "Rock_Shale_Brick_Ornate",
      "rotation": 3
    },
    {
      "x": -10,
      "y": 15,
      "z": -9,
      "name": "Rock_Shale_Brick_Smooth"
    },
    {
      "x": -10,
      "y": 16,
      "z": -9,
      "name": "Rock_Shale_Brick_Smooth"
    },
    {
      "x": -10,
      "y": 17,
      "z": -9,
      "name": "Rock_Shale_Brick_Smooth"
    },
    {
      "x": -10,
      "y": 18,
      "z": -9,
      "name": "Rock_Shale_Brick_Smooth"
    },
    {
      "x": -10,
      "y": 19,
      "z": -9,
      "name": "Rock_Shale_Brick_Smooth"
    },
    {
      "x": -10,
      "y": 20,
      "z": -9,
      "name": "Rock_Shale_Brick_Smooth"
    },
    {
      "x": -10,
      "y": 21,
      "z": -9,
      "name": "Rock_Shale_Brick_Smooth"
    },
    {
      "x": -10,
      "y": 22,
      "z": -9,
      "name": "Rock_Shale_Brick_Smooth"
    },
    {
      "x": -10,
      "y": 23,
      "z": -9,
      "name": "Rock_Shale_Brick_Smooth"
    },
    {
      "x": -10,
      "y": 24,
      "z": -9,
      "name": "Rock_Shale_Brick_Smooth"
    },
    {
      "x": -10,
      "y": 25,
      "z": -9,
      "name": "Rock_Shale_Brick_Smooth"
    },
    {
      "x": -10,
      "y": 26,
      "z": -9,
      "name": "Rock_Shale_Brick_Smooth"
    },
    {
      "x": -10,
      "y": 27,
      "z": -9,
      "name": "Rock_Shale_Brick_Smooth"
    },
    {
      "x": -10,
      "y": 28,
      "z": -9,
      "name": "Rock_Shale_Brick_Smooth"
    },
    {
      "x": -10,
      "y": 29,
      "z": -9,
      "name": "Rock_Shale_Brick_Smooth"
    },
    {
      "x": -10,
      "y": 30,
      "z": -9,
      "name": "Rock_Shale_Brick_Smooth"
    },
    {
      "x": -10,
      "y": 31,
      "z": -9,
      "name": "Rock_Shale_Brick_Smooth"
    },
    {
      "x": -10,
      "y": 32,
      "z": -9,
      "name": "Rock_Shale_Brick_Smooth"
    },
    {
      "x": -10,
      "y": 33,
      "z": -9,
      "name": "Rock_Shale_Brick_Ornate",
      "rotation": 3
    },
    {
      "x": -10,
      "y": 34,
      "z": -9,
      "name": "Rock_Shale_Brick_Smooth"
    },
    {
      "x": -10,
      "y": 35,
      "z": -9,
      "name": "Rock_Shale_Brick_Smooth"
    },
    {
      "x": -10,
      "y": 36,
      "z": -9,
      "name": "Rock_Shale_Brick_Smooth"
    },
    {
      "x": -10,
      "y": 37,
      "z": -9,
      "name": "Rock_Shale_Brick_Smooth"
    },
    {
      "x": -10,
      "y": 0,
      "z": -8,
      "name": "Rock_Shale_Brick_Smooth"
    },
    {
      "x": -10,
      "y": 1,
      "z": -8,
      "name": "Rock_Shale_Brick_Smooth"
    },
    {
      "x": -10,
      "y": 2,
      "z": -8,
      "name": "Rock_Shale_Brick_Smooth"
    },
    {
      "x": -10,
      "y": 3,
      "z": -8,
      "name": "Rock_Shale_Brick_Smooth"
    },
    {
      "x": -10,
      "y": 4,
      "z": -8,
      "name": "Rock_Shale_Brick_Smooth"
    },
    {
      "x": -10,
      "y": 5,
      "z": -8,
      "name": "Rock_Shale_Brick_Smooth"
    },
    {
      "x": -10,
      "y": 6,
      "z": -8,
      "name": "Rock_Shale_Brick_Smooth"
    },
    {
      "x": -10,
      "y": 7,
      "z": -8,
      "name": "Rock_Shale_Brick_Smooth"
    },
    {
      "x": -10,
      "y": 8,
      "z": -8,
      "name": "Rock_Shale_Brick_Smooth"
    },
    {
      "x": -10,
      "y": 9,
      "z": -8,
      "name": "Rock_Shale_Brick_Smooth"
    },
    {
      "x": -10,
      "y": 10,
      "z": -8,
      "name": "Rock_Shale_Brick_Smooth"
    },
    {
      "x": -10,
      "y": 11,
      "z": -8,
      "name": "Rock_Shale_Brick_Smooth"
    },
    {
      "x": -10,
      "y": 14,
      "z": -8,
      "name": "Rock_Shale_Brick_Ornate",
      "rotation": 3
    },
    {
      "x": -10,
      "y": 15,
      "z": -8,
      "name": "Rock_Shale_Brick_Smooth"
    },
    {
      "x": -10,
      "y": 16,
      "z": -8,
      "name": "Rock_Shale_Brick_Smooth_Half",
      "rotation": 7
    },
    {
      "x": -10,
      "y": 17,
      "z": -8,
      "name": "Rock_Shale_Brick_Smooth_Half",
      "rotation": 7
    },
    {
      "x": -10,
      "y": 18,
      "z": -8,
      "name": "Rock_Shale_Brick_Smooth"
    },
    {
      "x": -10,
      "y": 19,
      "z": -8,
      "name": "Rock_Shale_Brick_Smooth"
    },
    {
      "x": -10,
      "y": 20,
      "z": -8,
      "name": "Rock_Shale_Brick_Smooth"
    },
    {
      "x": -10,
      "y": 21,
      "z": -8,
      "name": "Rock_Shale_Brick_Smooth"
    },
    {
      "x": -10,
      "y": 22,
      "z": -8,
      "name": "Rock_Shale_Brick_Smooth"
    },
    {
      "x": -10,
      "y": 23,
      "z": -8,
      "name": "Rock_Shale_Brick_Smooth"
    },
    {
      "x": -10,
      "y": 24,
      "z": -8,
      "name": "Rock_Shale_Brick_Smooth"
    },
    {
      "x": -10,
      "y": 25,
      "z": -8,
      "name": "Rock_Shale_Brick_Smooth"
    },
    {
      "x": -10,
      "y": 26,
      "z": -8,
      "name": "Rock_Shale_Brick_Smooth"
    },
    {
      "x": -10,
      "y": 27,
      "z": -8,
      "name": "Rock_Shale_Brick_Smooth"
    },
    {
      "x": -10,
      "y": 28,
      "z": -8,
      "name": "Rock_Shale_Brick_Smooth"
    },
    {
      "x": -10,
      "y": 29,
      "z": -8,
      "name": "Rock_Shale_Brick_Smooth"
    },
    {
      "x": -10,
      "y": 30,
      "z": -8,
      "name": "Rock_Shale_Brick_Smooth"
    },
    {
      "x": -10,
      "y": 33,
      "z": -8,
      "name": "Rock_Shale_Brick_Ornate",
      "rotation": 3
    },
    {
      "x": -10,
      "y": 34,
      "z": -8,
      "name": "Rock_Shale_Brick_Smooth"
    },
    {
      "x": -10,
      "y": 35,
      "z": -8,
      "name": "Rock_Shale_Brick_Smooth_Half",
      "rotation": 7
    },
    {
      "x": -10,
      "y": 36,
      "z": -8,
      "name": "Rock_Shale_Brick_Smooth_Half",
      "rotation": 7
    },
    {
      "x": -10,
      "y": 37,
      "z": -8,
      "name": "Rock_Shale_Brick_Smooth"
    },
    {
      "x": -10,
      "y": 0,
      "z": -7,
      "name": "Rock_Shale_Brick_Smooth"
    },
    {
      "x": -10,
      "y": 1,
      "z": -7,
      "name": "Rock_Shale_Brick_Smooth"
    },
    {
      "x": -10,
      "y": 2,
      "z": -7,
      "name": "Rock_Shale_Brick_Smooth"
    },
    {
      "x": -10,
      "y": 3,
      "z": -7,
      "name": "Rock_Shale_Brick_Smooth"
    },
    {
      "x": -10,
      "y": 4,
      "z": -7,
      "name": "Rock_Shale_Brick_Smooth"
    },
    {
      "x": -10,
      "y": 5,
      "z": -7,
      "name": "Rock_Shale_Brick_Smooth"
    },
    {
      "x": -10,
      "y": 6,
      "z": -7,
      "name": "Rock_Shale_Brick_Smooth"
    },
    {
      "x": -10,
      "y": 7,
      "z": -7,
      "name": "Rock_Shale_Brick_Smooth"
    },
    {
      "x": -10,
      "y": 8,
      "z": -7,
      "name": "Rock_Shale_Brick_Smooth"
    },
    {
      "x": -10,
      "y": 9,
      "z": -7,
      "name": "Rock_Shale_Brick_Smooth"
    },
    {
      "x": -10,
      "y": 10,
      "z": -7,
      "name": "Rock_Shale_Brick_Smooth"
    },
    {
      "x": -10,
      "y": 11,
      "z": -7,
      "name": "Rock_Shale_Brick_Smooth"
    },
    {
      "x": -10,
      "y": 12,
      "z": -7,
      "name": "Rock_Shale_Brick_Smooth"
    },
    {
      "x": -10,
      "y": 13,
      "z": -7,
      "name": "Rock_Shale_Brick_Smooth"
    },
    {
      "x": -10,
      "y": 14,
      "z": -7,
      "name": "Rock_Shale_Brick_Ornate",
      "rotation": 3
    },
    {
      "x": -10,
      "y": 15,
      "z": -7,
      "name": "Rock_Shale_Brick_Smooth"
    },
    {
      "x": -10,
      "y": 16,
      "z": -7,
      "name": "Rock_Shale_Brick_Smooth"
    },
    {
      "x": -10,
      "y": 17,
      "z": -7,
      "name": "Rock_Shale_Brick_Smooth"
    },
    {
      "x": -10,
      "y": 18,
      "z": -7,
      "name": "Rock_Shale_Brick_Smooth"
    },
    {
      "x": -10,
      "y": 19,
      "z": -7,
      "name": "Rock_Shale_Brick_Smooth"
    },
    {
      "x": -10,
      "y": 20,
      "z": -7,
      "name": "Rock_Shale_Brick_Smooth"
    },
    {
      "x": -10,
      "y": 21,
      "z": -7,
      "name": "Rock_Shale_Brick_Smooth"
    },
    {
      "x": -10,
      "y": 22,
      "z": -7,
      "name": "Rock_Shale_Brick_Smooth"
    },
    {
      "x": -10,
      "y": 23,
      "z": -7,
      "name": "Rock_Shale_Brick_Smooth"
    },
    {
      "x": -10,
      "y": 24,
      "z": -7,
      "name": "Rock_Shale_Brick_Smooth"
    },
    {
      "x": -10,
      "y": 25,
      "z": -7,
      "name": "Rock_Shale_Brick_Smooth"
    },
    {
      "x": -10,
      "y": 26,
      "z": -7,
      "name": "Rock_Shale_Brick_Smooth"
    },
    {
      "x": -10,
      "y": 27,
      "z": -7,
      "name": "Rock_Shale_Brick_Smooth"
    },
    {
      "x": -10,
      "y": 28,
      "z": -7,
      "name": "Rock_Shale_Brick_Smooth"
    },
    {
      "x": -10,
      "y": 29,
      "z": -7,
      "name": "Rock_Shale_Brick_Smooth"
    },
    {
      "x": -10,
      "y": 30,
      "z": -7,
      "name": "Rock_Shale_Brick_Smooth"
    },
    {
      "x": -10,
      "y": 31,
      "z": -7,
      "name": "Rock_Shale_Brick_Smooth"
    },
    {
      "x": -10,
      "y": 32,
      "z": -7,
      "name": "Rock_Shale_Brick_Smooth"
    },
    {
      "x": -10,
      "y": 33,
      "z": -7,
      "name": "Rock_Shale_Brick_Ornate",
      "rotation": 3
    },
    {
      "x": -10,
      "y": 34,
      "z": -7,
      "name": "Rock_Shale_Brick_Smooth"
    },
    {
      "x": -10,
      "y": 35,
      "z": -7,
      "name": "Rock_Shale_Brick_Smooth"
    },
    {
      "x": -10,
      "y": 36,
      "z": -7,
      "name": "Rock_Shale_Brick_Smooth"
    },
    {
      "x": -10,
      "y": 37,
      "z": -7,
      "name": "Rock_Shale_Brick_Smooth"
    },
    {
      "x": -10,
      "y": 0,
      "z": -6,
      "name": "Rock_Shale_Brick_Smooth_Half",
      "rotation": 4
    },
    {
      "x": -10,
      "y": 1,
      "z": -6,
      "name": "Rock_Shale_Brick_Smooth_Half",
      "rotation": 4
    },
    {
      "x": -10,
      "y": 2,
      "z": -6,
      "name": "Rock_Shale_Brick_Smooth_Half",
      "rotation": 4
    },
    {
      "x": -10,
      "y": 3,
      "z": -6,
      "name": "Rock_Shale_Brick_Smooth_Half",
      "rotation": 4
    },
    {
      "x": -10,
      "y": 4,
      "z": -6,
      "name": "Rock_Shale_Brick_Smooth_Half",
      "rotation": 4
    },
    {
      "x": -10,
      "y": 5,
      "z": -6,
      "name": "Rock_Shale_Brick_Smooth_Half",
      "rotation": 4
    },
    {
      "x": -10,
      "y": 6,
      "z": -6,
      "name": "Rock_Shale_Brick_Smooth_Half",
      "rotation": 4
    },
    {
      "x": -10,
      "y": 7,
      "z": -6,
      "name": "*Rock_Runic_Teal_Brick_Stairs_State_Definitions_Inverted_Corner_Right",
      "rotation": 35
    },
    {
      "x": -10,
      "y": 19,
      "z": -6,
      "name": "Rock_Shale_Brick_Smooth_Half",
      "rotation": 4
    },
    {
      "x": -10,
      "y": 20,
      "z": -6,
      "name": "Rock_Shale_Brick_Smooth_Half",
      "rotation": 4
    },
    {
      "x": -10,
      "y": 21,
      "z": -6,
      "name": "Rock_Shale_Brick_Smooth_Half",
      "rotation": 4
    },
    {
      "x": -10,
      "y": 22,
      "z": -6,
      "name": "Rock_Shale_Brick_Smooth_Half",
      "rotation": 4
    },
    {
      "x": -10,
      "y": 23,
      "z": -6,
      "name": "Rock_Shale_Brick_Smooth_Half",
      "rotation": 4
    },
    {
      "x": -10,
      "y": 24,
      "z": -6,
      "name": "Rock_Shale_Brick_Smooth_Half",
      "rotation": 4
    },
    {
      "x": -10,
      "y": 25,
      "z": -6,
      "name": "Rock_Shale_Brick_Smooth_Half",
      "rotation": 4
    },
    {
      "x": -10,
      "y": 26,
      "z": -6,
      "name": "*Rock_Runic_Teal_Brick_Stairs_State_Definitions_Inverted_Corner_Right",
      "rotation": 35
    },
    {
      "x": -10,
      "y": 7,
      "z": -5,
      "name": "*Rock_Runic_Teal_Brick_Stairs_State_Definitions_Corner_Left",
      "rotation": 32
    },
    {
      "x": -10,
      "y": 26,
      "z": -5,
      "name": "*Rock_Runic_Teal_Brick_Stairs_State_Definitions_Corner_Left",
      "rotation": 32
    },
    {
      "x": -10,
      "y": 7,
      "z": -4,
      "name": "Rock_Shale_Brick_Smooth_Half",
      "rotation": 4
    },
    {
      "x": -10,
      "y": 8,
      "z": -4,
      "name": "Rock_Shale_Brick_Smooth_Half",
      "rotation": 4
    },
    {
      "x": -10,
      "y": 9,
      "z": -4,
      "name": "Rock_Shale_Brick_Smooth_Half",
      "rotation": 4
    },
    {
      "x": -10,
      "y": 26,
      "z": -4,
      "name": "Rock_Shale_Brick_Smooth_Half",
      "rotation": 4
    },
    {
      "x": -10,
      "y": 27,
      "z": -4,
      "name": "Rock_Shale_Brick_Smooth_Half",
      "rotation": 4
    },
    {
      "x": -10,
      "y": 28,
      "z": -4,
      "name": "Rock_Shale_Brick_Smooth_Half",
      "rotation": 4
    },
    {
      "x": -10,
      "y": 7,
      "z": 5,
      "name": "Rock_Shale_Brick_Smooth_Half",
      "rotation": 6
    },
    {
      "x": -10,
      "y": 8,
      "z": 5,
      "name": "Rock_Shale_Brick_Smooth_Half",
      "rotation": 6
    },
    {
      "x": -10,
      "y": 9,
      "z": 5,
      "name": "Rock_Shale_Brick_Smooth_Half",
      "rotation": 6
    },
    {
      "x": -10,
      "y": 26,
      "z": 5,
      "name": "Rock_Shale_Brick_Smooth_Half",
      "rotation": 6
    },
    {
      "x": -10,
      "y": 27,
      "z": 5,
      "name": "Rock_Shale_Brick_Smooth_Half",
      "rotation": 6
    },
    {
      "x": -10,
      "y": 28,
      "z": 5,
      "name": "Rock_Shale_Brick_Smooth_Half",
      "rotation": 6
    },
    {
      "x": -10,
      "y": 7,
      "z": 6,
      "name": "*Rock_Runic_Teal_Brick_Stairs_State_Definitions_Corner_Right",
      "rotation": 8
    },
    {
      "x": -10,
      "y": 26,
      "z": 6,
      "name": "*Rock_Runic_Teal_Brick_Stairs_State_Definitions_Corner_Right",
      "rotation": 8
    },
    {
      "x": -10,
      "y": 0,
      "z": 7,
      "name": "Rock_Shale_Brick_Smooth_Half",
      "rotation": 6
    },
    {
      "x": -10,
      "y": 1,
      "z": 7,
      "name": "Rock_Shale_Brick_Smooth_Half",
      "rotation": 6
    },
    {
      "x": -10,
      "y": 2,
      "z": 7,
      "name": "Rock_Shale_Brick_Smooth_Half",
      "rotation": 6
    },
    {
      "x": -10,
      "y": 3,
      "z": 7,
      "name": "Rock_Shale_Brick_Smooth_Half",
      "rotation": 6
    },
    {
      "x": -10,
      "y": 4,
      "z": 7,
      "name": "Rock_Shale_Brick_Smooth_Half",
      "rotation": 6
    },
    {
      "x": -10,
      "y": 5,
      "z": 7,
      "name": "Rock_Shale_Brick_Smooth_Half",
      "rotation": 6
    },
    {
      "x": -10,
      "y": 6,
      "z": 7,
      "name": "Rock_Shale_Brick_Smooth_Half",
      "rotation": 6
    },
    {
      "x": -10,
      "y": 7,
      "z": 7,
      "name": "*Rock_Runic_Teal_Brick_Stairs_State_Definitions_Inverted_Corner_Left",
      "rotation": 9
    },
    {
      "x": -10,
      "y": 19,
      "z": 7,
      "name": "Rock_Shale_Brick_Smooth_Half",
      "rotation": 6
    },
    {
      "x": -10,
      "y": 20,
      "z": 7,
      "name": "Rock_Shale_Brick_Smooth_Half",
      "rotation": 6
    },
    {
      "x": -10,
      "y": 21,
      "z": 7,
      "name": "Rock_Shale_Brick_Smooth_Half",
      "rotation": 6
    },
    {
      "x": -10,
      "y": 22,
      "z": 7,
      "name": "Rock_Shale_Brick_Smooth_Half",
      "rotation": 6
    },
    {
      "x": -10,
      "y": 23,
      "z": 7,
      "name": "Rock_Shale_Brick_Smooth_Half",
      "rotation": 6
    },
    {
      "x": -10,
      "y": 24,
      "z": 7,
      "name": "Rock_Shale_Brick_Smooth_Half",
      "rotation": 6
    },
    {
      "x": -10,
      "y": 25,
      "z": 7,
      "name": "Rock_Shale_Brick_Smooth_Half",
      "rotation": 6
    },
    {
      "x": -10,
      "y": 26,
      "z": 7,
      "name": "*Rock_Runic_Teal_Brick_Stairs_State_Definitions_Inverted_Corner_Left",
      "rotation": 9
    },
    {
      "x": -10,
      "y": 0,
      "z": 8,
      "name": "Rock_Shale_Brick_Smooth"
    },
    {
      "x": -10,
      "y": 1,
      "z": 8,
      "name": "Rock_Shale_Brick_Smooth"
    },
    {
      "x": -10,
      "y": 2,
      "z": 8,
      "name": "Rock_Shale_Brick_Smooth"
    },
    {
      "x": -10,
      "y": 3,
      "z": 8,
      "name": "Rock_Shale_Brick_Smooth"
    },
    {
      "x": -10,
      "y": 4,
      "z": 8,
      "name": "Rock_Shale_Brick_Smooth"
    },
    {
      "x": -10,
      "y": 5,
      "z": 8,
      "name": "Rock_Shale_Brick_Smooth"
    },
    {
      "x": -10,
      "y": 6,
      "z": 8,
      "name": "Rock_Shale_Brick_Smooth"
    },
    {
      "x": -10,
      "y": 7,
      "z": 8,
      "name": "Rock_Shale_Brick_Smooth"
    },
    {
      "x": -10,
      "y": 8,
      "z": 8,
      "name": "Rock_Shale_Brick_Smooth"
    },
    {
      "x": -10,
      "y": 9,
      "z": 8,
      "name": "Rock_Shale_Brick_Smooth"
    },
    {
      "x": -10,
      "y": 10,
      "z": 8,
      "name": "Rock_Shale_Brick_Smooth"
    },
    {
      "x": -10,
      "y": 11,
      "z": 8,
      "name": "Rock_Shale_Brick_Smooth"
    },
    {
      "x": -10,
      "y": 12,
      "z": 8,
      "name": "Rock_Shale_Brick_Smooth"
    },
    {
      "x": -10,
      "y": 13,
      "z": 8,
      "name": "Rock_Shale_Brick_Smooth"
    },
    {
      "x": -10,
      "y": 14,
      "z": 8,
      "name": "Rock_Shale_Brick_Ornate"
    },
    {
      "x": -10,
      "y": 15,
      "z": 8,
      "name": "Rock_Shale_Brick_Smooth"
    },
    {
      "x": -10,
      "y": 16,
      "z": 8,
      "name": "Rock_Shale_Brick_Smooth"
    },
    {
      "x": -10,
      "y": 17,
      "z": 8,
      "name": "Rock_Shale_Brick_Smooth"
    },
    {
      "x": -10,
      "y": 18,
      "z": 8,
      "name": "Rock_Shale_Brick_Smooth"
    },
    {
      "x": -10,
      "y": 19,
      "z": 8,
      "name": "Rock_Shale_Brick_Smooth"
    },
    {
      "x": -10,
      "y": 20,
      "z": 8,
      "name": "Rock_Shale_Brick_Smooth"
    },
    {
      "x": -10,
      "y": 21,
      "z": 8,
      "name": "Rock_Shale_Brick_Smooth"
    },
    {
      "x": -10,
      "y": 22,
      "z": 8,
      "name": "Rock_Shale_Brick_Smooth"
    },
    {
      "x": -10,
      "y": 23,
      "z": 8,
      "name": "Rock_Shale_Brick_Smooth"
    },
    {
      "x": -10,
      "y": 24,
      "z": 8,
      "name": "Rock_Shale_Brick_Smooth"
    },
    {
      "x": -10,
      "y": 25,
      "z": 8,
      "name": "Rock_Shale_Brick_Smooth"
    },
    {
      "x": -10,
      "y": 26,
      "z": 8,
      "name": "Rock_Shale_Brick_Smooth"
    },
    {
      "x": -10,
      "y": 27,
      "z": 8,
      "name": "Rock_Shale_Brick_Smooth"
    },
    {
      "x": -10,
      "y": 28,
      "z": 8,
      "name": "Rock_Shale_Brick_Smooth"
    },
    {
      "x": -10,
      "y": 29,
      "z": 8,
      "name": "Rock_Shale_Brick_Smooth"
    },
    {
      "x": -10,
      "y": 30,
      "z": 8,
      "name": "Rock_Shale_Brick_Smooth"
    },
    {
      "x": -10,
      "y": 31,
      "z": 8,
      "name": "Rock_Shale_Brick_Smooth"
    },
    {
      "x": -10,
      "y": 32,
      "z": 8,
      "name": "Rock_Shale_Brick_Smooth"
    },
    {
      "x": -10,
      "y": 33,
      "z": 8,
      "name": "Rock_Shale_Brick_Ornate"
    },
    {
      "x": -10,
      "y": 34,
      "z": 8,
      "name": "Rock_Shale_Brick_Smooth"
    },
    {
      "x": -10,
      "y": 35,
      "z": 8,
      "name": "Rock_Shale_Brick_Smooth"
    },
    {
      "x": -10,
      "y": 36,
      "z": 8,
      "name": "Rock_Shale_Brick_Smooth"
    },
    {
      "x": -10,
      "y": 37,
      "z": 8,
      "name": "Rock_Shale_Brick_Smooth"
    },
    {
      "x": -10,
      "y": 0,
      "z": 9,
      "name": "Rock_Shale_Brick_Smooth"
    },
    {
      "x": -10,
      "y": 1,
      "z": 9,
      "name": "Rock_Shale_Brick_Smooth"
    },
    {
      "x": -10,
      "y": 2,
      "z": 9,
      "name": "Rock_Shale_Brick_Smooth"
    },
    {
      "x": -10,
      "y": 3,
      "z": 9,
      "name": "Rock_Shale_Brick_Smooth"
    },
    {
      "x": -10,
      "y": 4,
      "z": 9,
      "name": "Rock_Shale_Brick_Smooth"
    },
    {
      "x": -10,
      "y": 5,
      "z": 9,
      "name": "Rock_Shale_Brick_Smooth"
    },
    {
      "x": -10,
      "y": 6,
      "z": 9,
      "name": "Rock_Shale_Brick_Smooth"
    },
    {
      "x": -10,
      "y": 7,
      "z": 9,
      "name": "Rock_Shale_Brick_Smooth"
    },
    {
      "x": -10,
      "y": 8,
      "z": 9,
      "name": "Rock_Shale_Brick_Smooth"
    },
    {
      "x": -10,
      "y": 9,
      "z": 9,
      "name": "Rock_Shale_Brick_Smooth"
    },
    {
      "x": -10,
      "y": 10,
      "z": 9,
      "name": "Rock_Shale_Brick_Smooth"
    },
    {
      "x": -10,
      "y": 11,
      "z": 9,
      "name": "Rock_Shale_Brick_Smooth"
    },
    {
      "x": -10,
      "y": 14,
      "z": 9,
      "name": "Rock_Shale_Brick_Ornate"
    },
    {
      "x": -10,
      "y": 15,
      "z": 9,
      "name": "Rock_Shale_Brick_Smooth"
    },
    {
      "x": -10,
      "y": 16,
      "z": 9,
      "name": "Rock_Shale_Brick_Smooth_Half",
      "rotation": 7
    },
    {
      "x": -10,
      "y": 17,
      "z": 9,
      "name": "Rock_Shale_Brick_Smooth_Half",
      "rotation": 7
    },
    {
      "x": -10,
      "y": 18,
      "z": 9,
      "name": "Rock_Shale_Brick_Smooth"
    },
    {
      "x": -10,
      "y": 19,
      "z": 9,
      "name": "Rock_Shale_Brick_Smooth"
    },
    {
      "x": -10,
      "y": 20,
      "z": 9,
      "name": "Rock_Shale_Brick_Smooth"
    },
    {
      "x": -10,
      "y": 21,
      "z": 9,
      "name": "Rock_Shale_Brick_Smooth"
    },
    {
      "x": -10,
      "y": 22,
      "z": 9,
      "name": "Rock_Shale_Brick_Smooth"
    },
    {
      "x": -10,
      "y": 23,
      "z": 9,
      "name": "Rock_Shale_Brick_Smooth"
    },
    {
      "x": -10,
      "y": 24,
      "z": 9,
      "name": "Rock_Shale_Brick_Smooth"
    },
    {
      "x": -10,
      "y": 25,
      "z": 9,
      "name": "Rock_Shale_Brick_Smooth"
    },
    {
      "x": -10,
      "y": 26,
      "z": 9,
      "name": "Rock_Shale_Brick_Smooth"
    },
    {
      "x": -10,
      "y": 27,
      "z": 9,
      "name": "Rock_Shale_Brick_Smooth"
    },
    {
      "x": -10,
      "y": 28,
      "z": 9,
      "name": "Rock_Shale_Brick_Smooth"
    },
    {
      "x": -10,
      "y": 29,
      "z": 9,
      "name": "Rock_Shale_Brick_Smooth"
    },
    {
      "x": -10,
      "y": 30,
      "z": 9,
      "name": "Rock_Shale_Brick_Smooth"
    },
    {
      "x": -10,
      "y": 33,
      "z": 9,
      "name": "Rock_Shale_Brick_Ornate"
    },
    {
      "x": -10,
      "y": 34,
      "z": 9,
      "name": "Rock_Shale_Brick_Smooth"
    },
    {
      "x": -10,
      "y": 35,
      "z": 9,
      "name": "Rock_Shale_Brick_Smooth_Half",
      "rotation": 7
    },
    {
      "x": -10,
      "y": 36,
      "z": 9,
      "name": "Rock_Shale_Brick_Smooth_Half",
      "rotation": 7
    },
    {
      "x": -10,
      "y": 37,
      "z": 9,
      "name": "Rock_Shale_Brick_Smooth"
    },
    {
      "x": -10,
      "y": 0,
      "z": 10,
      "name": "Rock_Shale_Brick_Smooth"
    },
    {
      "x": -10,
      "y": 1,
      "z": 10,
      "name": "Rock_Shale_Brick_Smooth"
    },
    {
      "x": -10,
      "y": 2,
      "z": 10,
      "name": "Rock_Shale_Brick_Smooth"
    },
    {
      "x": -10,
      "y": 3,
      "z": 10,
      "name": "Rock_Shale_Brick_Smooth"
    },
    {
      "x": -10,
      "y": 4,
      "z": 10,
      "name": "Rock_Shale_Brick_Smooth"
    },
    {
      "x": -10,
      "y": 5,
      "z": 10,
      "name": "Rock_Shale_Brick_Smooth"
    },
    {
      "x": -10,
      "y": 6,
      "z": 10,
      "name": "Rock_Shale_Brick_Smooth"
    },
    {
      "x": -10,
      "y": 7,
      "z": 10,
      "name": "Rock_Shale_Brick_Smooth"
    },
    {
      "x": -10,
      "y": 8,
      "z": 10,
      "name": "Rock_Shale_Brick_Smooth"
    },
    {
      "x": -10,
      "y": 9,
      "z": 10,
      "name": "Rock_Shale_Brick_Smooth"
    },
    {
      "x": -10,
      "y": 10,
      "z": 10,
      "name": "Rock_Shale_Brick_Smooth"
    },
    {
      "x": -10,
      "y": 11,
      "z": 10,
      "name": "Rock_Shale_Brick_Smooth"
    },
    {
      "x": -10,
      "y": 12,
      "z": 10,
      "name": "Rock_Shale_Brick_Smooth"
    },
    {
      "x": -10,
      "y": 13,
      "z": 10,
      "name": "Rock_Shale_Brick_Smooth"
    },
    {
      "x": -10,
      "y": 14,
      "z": 10,
      "name": "Rock_Shale_Brick_Ornate"
    },
    {
      "x": -10,
      "y": 15,
      "z": 10,
      "name": "Rock_Shale_Brick_Smooth"
    },
    {
      "x": -10,
      "y": 16,
      "z": 10,
      "name": "Rock_Shale_Brick_Smooth"
    },
    {
      "x": -10,
      "y": 17,
      "z": 10,
      "name": "Rock_Shale_Brick_Smooth"
    },
    {
      "x": -10,
      "y": 18,
      "z": 10,
      "name": "Rock_Shale_Brick_Smooth"
    },
    {
      "x": -10,
      "y": 19,
      "z": 10,
      "name": "Rock_Shale_Brick_Smooth"
    },
    {
      "x": -10,
      "y": 20,
      "z": 10,
      "name": "Rock_Shale_Brick_Smooth"
    },
    {
      "x": -10,
      "y": 21,
      "z": 10,
      "name": "Rock_Shale_Brick_Smooth"
    },
    {
      "x": -10,
      "y": 22,
      "z": 10,
      "name": "Rock_Shale_Brick_Smooth"
    },
    {
      "x": -10,
      "y": 23,
      "z": 10,
      "name": "Rock_Shale_Brick_Smooth"
    },
    {
      "x": -10,
      "y": 24,
      "z": 10,
      "name": "Rock_Shale_Brick_Smooth"
    },
    {
      "x": -10,
      "y": 25,
      "z": 10,
      "name": "Rock_Shale_Brick_Smooth"
    },
    {
      "x": -10,
      "y": 26,
      "z": 10,
      "name": "Rock_Shale_Brick_Smooth"
    },
    {
      "x": -10,
      "y": 27,
      "z": 10,
      "name": "Rock_Shale_Brick_Smooth"
    },
    {
      "x": -10,
      "y": 28,
      "z": 10,
      "name": "Rock_Shale_Brick_Smooth"
    },
    {
      "x": -10,
      "y": 29,
      "z": 10,
      "name": "Rock_Shale_Brick_Smooth"
    },
    {
      "x": -10,
      "y": 30,
      "z": 10,
      "name": "Rock_Shale_Brick_Smooth"
    },
    {
      "x": -10,
      "y": 31,
      "z": 10,
      "name": "Rock_Shale_Brick_Smooth"
    },
    {
      "x": -10,
      "y": 32,
      "z": 10,
      "name": "Rock_Shale_Brick_Smooth"
    },
    {
      "x": -10,
      "y": 33,
      "z": 10,
      "name": "Rock_Shale_Brick_Ornate"
    },
    {
      "x": -10,
      "y": 34,
      "z": 10,
      "name": "Rock_Shale_Brick_Smooth"
    },
    {
      "x": -10,
      "y": 35,
      "z": 10,
      "name": "Rock_Shale_Brick_Smooth"
    },
    {
      "x": -10,
      "y": 36,
      "z": 10,
      "name": "Rock_Shale_Brick_Smooth"
    },
    {
      "x": -10,
      "y": 37,
      "z": 10,
      "name": "Rock_Shale_Brick_Smooth"
    },
    {
      "x": -10,
      "y": 8,
      "z": 11,
      "name": "Rock_Shale_Brick_Smooth_Half",
      "rotation": 8
    },
    {
      "x": -10,
      "y": 9,
      "z": 11,
      "name": "Rock_Runic_Teal_Brick_Stairs",
      "rotation": 9
    },
    {
      "x": -10,
      "y": 13,
      "z": 11,
      "name": "Rock_Shale_Brick_Stairs",
      "rotation": 25
    },
    {
      "x": -10,
      "y": 14,
      "z": 11,
      "name": "Rock_Shale_Brick_Stairs",
      "rotation": 25
    },
    {
      "x": -10,
      "y": 15,
      "z": 11,
      "name": "Rock_Shale_Brick_Stairs",
      "rotation": 25
    },
    {
      "x": -10,
      "y": 16,
      "z": 11,
      "name": "Rock_Shale_Brick_Stairs",
      "rotation": 25
    },
    {
      "x": -10,
      "y": 17,
      "z": 11,
      "name": "Rock_Shale_Brick_Stairs",
      "rotation": 25
    },
    {
      "x": -10,
      "y": 27,
      "z": 11,
      "name": "Rock_Shale_Brick_Smooth_Half",
      "rotation": 8
    },
    {
      "x": -10,
      "y": 28,
      "z": 11,
      "name": "Rock_Runic_Teal_Brick_Stairs",
      "rotation": 9
    },
    {
      "x": -10,
      "y": 32,
      "z": 11,
      "name": "Rock_Shale_Brick_Stairs",
      "rotation": 25
    },
    {
      "x": -10,
      "y": 33,
      "z": 11,
      "name": "Rock_Shale_Brick_Stairs",
      "rotation": 25
    },
    {
      "x": -10,
      "y": 34,
      "z": 11,
      "name": "Rock_Shale_Brick_Stairs",
      "rotation": 25
    },
    {
      "x": -10,
      "y": 35,
      "z": 11,
      "name": "Rock_Shale_Brick_Stairs",
      "rotation": 25
    },
    {
      "x": -10,
      "y": 36,
      "z": 11,
      "name": "Rock_Shale_Brick_Stairs",
      "rotation": 25
    },
    {
      "x": -10,
      "y": 8,
      "z": 12,
      "name": "Rock_Shale_Brick_Smooth_Half",
      "rotation": 7
    },
    {
      "x": -10,
      "y": 9,
      "z": 12,
      "name": "Rock_Shale_Brick_Smooth_Half",
      "rotation": 4
    },
    {
      "x": -10,
      "y": 10,
      "z": 12,
      "name": "Rock_Shale_Brick_Smooth_Half",
      "rotation": 4
    },
    {
      "x": -10,
      "y": 11,
      "z": 12,
      "name": "Rock_Shale_Brick_Smooth"
    },
    {
      "x": -10,
      "y": 27,
      "z": 12,
      "name": "Rock_Shale_Brick_Smooth_Half",
      "rotation": 7
    },
    {
      "x": -10,
      "y": 28,
      "z": 12,
      "name": "Rock_Shale_Brick_Smooth_Half",
      "rotation": 4
    },
    {
      "x": -10,
      "y": 29,
      "z": 12,
      "name": "Rock_Shale_Brick_Smooth_Half",
      "rotation": 4
    },
    {
      "x": -10,
      "y": 30,
      "z": 12,
      "name": "Rock_Shale_Brick_Smooth"
    },
    {
      "x": -10,
      "y": 10,
      "z": 13,
      "name": "Rock_Shale_Brick_Smooth_Half",
      "rotation": 7
    },
    {
      "x": -10,
      "y": 11,
      "z": 13,
      "name": "Rock_Runic_Teal_Brick_Stairs",
      "rotation": 10
    },
    {
      "x": -10,
      "y": 12,
      "z": 13,
      "name": "Rock_Shale_Brick_Smooth_Half",
      "rotation": 5
    },
    {
      "x": -10,
      "y": 29,
      "z": 13,
      "name": "Rock_Shale_Brick_Smooth_Half",
      "rotation": 7
    },
    {
      "x": -10,
      "y": 30,
      "z": 13,
      "name": "Rock_Runic_Teal_Brick_Stairs",
      "rotation": 10
    },
    {
      "x": -10,
      "y": 31,
      "z": 13,
      "name": "Rock_Shale_Brick_Smooth_Half",
      "rotation": 5
    },
    {
      "x": -10,
      "y": 11,
      "z": 14,
      "name": "Rock_Shale_Brick_Smooth_Half",
      "rotation": 4
    },
    {
      "x": -10,
      "y": 12,
      "z": 14,
      "name": "Rock_Shale_Brick_Smooth_Half",
      "rotation": 4
    },
    {
      "x": -10,
      "y": 13,
      "z": 14,
      "name": "Rock_Shale_Brick_Smooth_Half",
      "rotation": 4
    },
    {
      "x": -10,
      "y": 30,
      "z": 14,
      "name": "Rock_Shale_Brick_Smooth_Half",
      "rotation": 4
    },
    {
      "x": -10,
      "y": 31,
      "z": 14,
      "name": "Rock_Shale_Brick_Smooth_Half",
      "rotation": 4
    },
    {
      "x": -10,
      "y": 32,
      "z": 14,
      "name": "Rock_Shale_Brick_Smooth_Half",
      "rotation": 4
    },
    {
      "x": -9,
      "y": 10,
      "z": -13,
      "name": "Rock_Shale_Brick_Smooth_Half",
      "rotation": 6
    },
    {
      "x": -9,
      "y": 11,
      "z": -13,
      "name": "Rock_Shale_Brick_Smooth_Half",
      "rotation": 6
    },
    {
      "x": -9,
      "y": 12,
      "z": -13,
      "name": "Rock_Shale_Brick_Smooth_Half",
      "rotation": 6
    },
    {
      "x": -9,
      "y": 29,
      "z": -13,
      "name": "Rock_Shale_Brick_Smooth_Half",
      "rotation": 6
    },
    {
      "x": -9,
      "y": 30,
      "z": -13,
      "name": "Rock_Shale_Brick_Smooth_Half",
      "rotation": 6
    },
    {
      "x": -9,
      "y": 31,
      "z": -13,
      "name": "Rock_Shale_Brick_Smooth_Half",
      "rotation": 6
    },
    {
      "x": -9,
      "y": 8,
      "z": -12,
      "name": "Rock_Shale_Brick_Smooth_Half",
      "rotation": 6
    },
    {
      "x": -9,
      "y": 9,
      "z": -12,
      "name": "Rock_Shale_Brick_Smooth_Half",
      "rotation": 6
    },
    {
      "x": -9,
      "y": 10,
      "z": -12,
      "name": "Rock_Runic_Teal_Brick_Stairs",
      "rotation": 34
    },
    {
      "x": -9,
      "y": 11,
      "z": -12,
      "name": "Rock_Shale_Brick_Smooth_Half",
      "rotation": 5
    },
    {
      "x": -9,
      "y": 27,
      "z": -12,
      "name": "Rock_Shale_Brick_Smooth_Half",
      "rotation": 6
    },
    {
      "x": -9,
      "y": 28,
      "z": -12,
      "name": "Rock_Shale_Brick_Smooth_Half",
      "rotation": 6
    },
    {
      "x": -9,
      "y": 29,
      "z": -12,
      "name": "Rock_Runic_Teal_Brick_Stairs",
      "rotation": 34
    },
    {
      "x": -9,
      "y": 30,
      "z": -12,
      "name": "Rock_Shale_Brick_Smooth_Half",
      "rotation": 5
    },
    {
      "x": -9,
      "y": 7,
      "z": -11,
      "name": "Rock_Shale_Brick_Smooth_Half",
      "rotation": 6
    },
    {
      "x": -9,
      "y": 8,
      "z": -11,
      "name": "Rock_Runic_Teal_Brick_Stairs",
      "rotation": 34
    },
    {
      "x": -9,
      "y": 9,
      "z": -11,
      "name": "Rock_Shale_Brick_Smooth_Half",
      "rotation": 5
    },
    {
      "x": -9,
      "y": 10,
      "z": -11,
      "name": "Rock_Shale_Brick_Smooth_Half",
      "rotation": 4
    },
    {
      "x": -9,
      "y": 11,
      "z": -11,
      "name": "Rock_Shale_Brick_Smooth_Half",
      "rotation": 6
    },
    {
      "x": -9,
      "y": 12,
      "z": -11,
      "name": "Rock_Shale_Brick_Smooth_Half",
      "rotation": 6
    },
    {
      "x": -9,
      "y": 13,
      "z": -11,
      "name": "Rock_Shale_Brick_Smooth_Half",
      "rotation": 6
    },
    {
      "x": -9,
      "y": 14,
      "z": -11,
      "name": "Rock_Shale_Brick_Smooth_Half",
      "rotation": 6
    },
    {
      "x": -9,
      "y": 26,
      "z": -11,
      "name": "Rock_Shale_Brick_Smooth_Half",
      "rotation": 6
    },
    {
      "x": -9,
      "y": 27,
      "z": -11,
      "name": "Rock_Runic_Teal_Brick_Stairs",
      "rotation": 34
    },
    {
      "x": -9,
      "y": 28,
      "z": -11,
      "name": "Rock_Shale_Brick_Smooth_Half",
      "rotation": 5
    },
    {
      "x": -9,
      "y": 29,
      "z": -11,
      "name": "Rock_Shale_Brick_Smooth_Half",
      "rotation": 4
    },
    {
      "x": -9,
      "y": 30,
      "z": -11,
      "name": "Rock_Shale_Brick_Smooth_Half",
      "rotation": 6
    },
    {
      "x": -9,
      "y": 31,
      "z": -11,
      "name": "Rock_Shale_Brick_Smooth_Half",
      "rotation": 6
    },
    {
      "x": -9,
      "y": 32,
      "z": -11,
      "name": "Rock_Shale_Brick_Smooth_Half",
      "rotation": 6
    },
    {
      "x": -9,
      "y": 33,
      "z": -11,
      "name": "Rock_Shale_Brick_Smooth_Half",
      "rotation": 6
    },
    {
      "x": -9,
      "y": 0,
      "z": -10,
      "name": "Rock_Shale_Brick_Smooth"
    },
    {
      "x": -9,
      "y": 1,
      "z": -10,
      "name": "Rock_Shale_Brick_Smooth"
    },
    {
      "x": -9,
      "y": 2,
      "z": -10,
      "name": "Rock_Shale_Brick_Smooth"
    },
    {
      "x": -9,
      "y": 3,
      "z": -10,
      "name": "Rock_Shale_Brick_Smooth"
    },
    {
      "x": -9,
      "y": 4,
      "z": -10,
      "name": "Rock_Shale_Brick_Smooth"
    },
    {
      "x": -9,
      "y": 5,
      "z": -10,
      "name": "Rock_Shale_Brick_Smooth"
    },
    {
      "x": -9,
      "y": 6,
      "z": -10,
      "name": "Rock_Shale_Brick_Smooth"
    },
    {
      "x": -9,
      "y": 7,
      "z": -10,
      "name": "Rock_Shale_Brick_Smooth"
    },
    {
      "x": -9,
      "y": 8,
      "z": -10,
      "name": "Rock_Shale_Brick_Smooth"
    },
    {
      "x": -9,
      "y": 9,
      "z": -10,
      "name": "Rock_Shale_Brick_Smooth"
    },
    {
      "x": -9,
      "y": 10,
      "z": -10,
      "name": "Rock_Shale_Brick_Smooth"
    },
    {
      "x": -9,
      "y": 11,
      "z": -10,
      "name": "Rock_Shale_Brick_Smooth"
    },
    {
      "x": -9,
      "y": 12,
      "z": -10,
      "name": "Rock_Shale_Brick_Smooth"
    },
    {
      "x": -9,
      "y": 13,
      "z": -10,
      "name": "Rock_Shale_Brick_Smooth"
    },
    {
      "x": -9,
      "y": 14,
      "z": -10,
      "name": "Rock_Shale_Brick_Ornate",
      "rotation": 3
    },
    {
      "x": -9,
      "y": 15,
      "z": -10,
      "name": "Rock_Shale_Brick_Smooth"
    },
    {
      "x": -9,
      "y": 16,
      "z": -10,
      "name": "Rock_Shale_Brick_Smooth"
    },
    {
      "x": -9,
      "y": 17,
      "z": -10,
      "name": "Rock_Shale_Brick_Smooth"
    },
    {
      "x": -9,
      "y": 18,
      "z": -10,
      "name": "Rock_Shale_Brick_Smooth"
    },
    {
      "x": -9,
      "y": 19,
      "z": -10,
      "name": "Rock_Shale_Brick_Smooth"
    },
    {
      "x": -9,
      "y": 20,
      "z": -10,
      "name": "Rock_Shale_Brick_Smooth"
    },
    {
      "x": -9,
      "y": 21,
      "z": -10,
      "name": "Rock_Shale_Brick_Smooth"
    },
    {
      "x": -9,
      "y": 22,
      "z": -10,
      "name": "Rock_Shale_Brick_Smooth"
    },
    {
      "x": -9,
      "y": 23,
      "z": -10,
      "name": "Rock_Shale_Brick_Smooth"
    },
    {
      "x": -9,
      "y": 24,
      "z": -10,
      "name": "Rock_Shale_Brick_Smooth"
    },
    {
      "x": -9,
      "y": 25,
      "z": -10,
      "name": "Rock_Shale_Brick_Smooth"
    },
    {
      "x": -9,
      "y": 26,
      "z": -10,
      "name": "Rock_Shale_Brick_Smooth"
    },
    {
      "x": -9,
      "y": 27,
      "z": -10,
      "name": "Rock_Shale_Brick_Smooth"
    },
    {
      "x": -9,
      "y": 28,
      "z": -10,
      "name": "Rock_Shale_Brick_Smooth"
    },
    {
      "x": -9,
      "y": 29,
      "z": -10,
      "name": "Rock_Shale_Brick_Smooth"
    },
    {
      "x": -9,
      "y": 30,
      "z": -10,
      "name": "Rock_Shale_Brick_Smooth"
    },
    {
      "x": -9,
      "y": 31,
      "z": -10,
      "name": "Rock_Shale_Brick_Smooth"
    },
    {
      "x": -9,
      "y": 32,
      "z": -10,
      "name": "Rock_Shale_Brick_Smooth"
    },
    {
      "x": -9,
      "y": 33,
      "z": -10,
      "name": "Rock_Shale_Brick_Ornate",
      "rotation": 3
    },
    {
      "x": -9,
      "y": 34,
      "z": -10,
      "name": "Rock_Shale_Brick_Smooth"
    },
    {
      "x": -9,
      "y": 35,
      "z": -10,
      "name": "Rock_Shale_Brick_Smooth"
    },
    {
      "x": -9,
      "y": 36,
      "z": -10,
      "name": "Rock_Shale_Brick_Smooth"
    },
    {
      "x": -9,
      "y": 37,
      "z": -10,
      "name": "Rock_Shale_Brick_Smooth"
    },
    {
      "x": -9,
      "y": 0,
      "z": -6,
      "name": "Rock_Shale_Brick_Smooth"
    },
    {
      "x": -9,
      "y": 1,
      "z": -6,
      "name": "Rock_Shale_Brick_Smooth"
    },
    {
      "x": -9,
      "y": 2,
      "z": -6,
      "name": "Rock_Shale_Brick_Smooth"
    },
    {
      "x": -9,
      "y": 3,
      "z": -6,
      "name": "Rock_Shale_Brick_Smooth"
    },
    {
      "x": -9,
      "y": 4,
      "z": -6,
      "name": "Rock_Shale_Brick_Smooth"
    },
    {
      "x": -9,
      "y": 5,
      "z": -6,
      "name": "Rock_Shale_Brick_Smooth"
    },
    {
      "x": -9,
      "y": 6,
      "z": -6,
      "name": "Rock_Shale_Brick_Smooth"
    },
    {
      "x": -9,
      "y": 7,
      "z": -6,
      "name": "Rock_Shale_Brick_Smooth"
    },
    {
      "x": -9,
      "y": 8,
      "z": -6,
      "name": "Rock_Shale_Brick_Smooth"
    },
    {
      "x": -9,
      "y": 9,
      "z": -6,
      "name": "Rock_Shale_Brick_Smooth"
    },
    {
      "x": -9,
      "y": 10,
      "z": -6,
      "name": "Rock_Shale_Brick_Smooth"
    },
    {
      "x": -9,
      "y": 11,
      "z": -6,
      "name": "Rock_Shale_Brick_Smooth"
    },
    {
      "x": -9,
      "y": 12,
      "z": -6,
      "name": "Rock_Shale_Brick_Smooth"
    },
    {
      "x": -9,
      "y": 13,
      "z": -6,
      "name": "Rock_Shale_Brick_Smooth"
    },
    {
      "x": -9,
      "y": 14,
      "z": -6,
      "name": "Rock_Shale_Brick_Ornate",
      "rotation": 3
    },
    {
      "x": -9,
      "y": 15,
      "z": -6,
      "name": "Rock_Shale_Brick_Smooth"
    },
    {
      "x": -9,
      "y": 16,
      "z": -6,
      "name": "Rock_Shale_Brick_Smooth"
    },
    {
      "x": -9,
      "y": 17,
      "z": -6,
      "name": "Rock_Shale_Brick_Smooth"
    },
    {
      "x": -9,
      "y": 18,
      "z": -6,
      "name": "Rock_Shale_Brick_Smooth"
    },
    {
      "x": -9,
      "y": 19,
      "z": -6,
      "name": "Rock_Shale_Brick_Smooth"
    },
    {
      "x": -9,
      "y": 20,
      "z": -6,
      "name": "Rock_Shale_Brick_Smooth"
    },
    {
      "x": -9,
      "y": 21,
      "z": -6,
      "name": "Rock_Shale_Brick_Smooth"
    },
    {
      "x": -9,
      "y": 22,
      "z": -6,
      "name": "Rock_Shale_Brick_Smooth"
    },
    {
      "x": -9,
      "y": 23,
      "z": -6,
      "name": "Rock_Shale_Brick_Smooth"
    },
    {
      "x": -9,
      "y": 24,
      "z": -6,
      "name": "Rock_Shale_Brick_Smooth"
    },
    {
      "x": -9,
      "y": 25,
      "z": -6,
      "name": "Rock_Shale_Brick_Smooth"
    },
    {
      "x": -9,
      "y": 26,
      "z": -6,
      "name": "Rock_Shale_Brick_Smooth"
    },
    {
      "x": -9,
      "y": 27,
      "z": -6,
      "name": "Rock_Shale_Brick_Smooth"
    },
    {
      "x": -9,
      "y": 28,
      "z": -6,
      "name": "Rock_Shale_Brick_Smooth"
    },
    {
      "x": -9,
      "y": 29,
      "z": -6,
      "name": "Rock_Shale_Brick_Smooth"
    },
    {
      "x": -9,
      "y": 30,
      "z": -6,
      "name": "Rock_Shale_Brick_Smooth"
    },
    {
      "x": -9,
      "y": 31,
      "z": -6,
      "name": "Rock_Shale_Brick_Smooth"
    },
    {
      "x": -9,
      "y": 32,
      "z": -6,
      "name": "Rock_Shale_Brick_Smooth"
    },
    {
      "x": -9,
      "y": 33,
      "z": -6,
      "name": "Rock_Shale_Brick_Ornate",
      "rotation": 3
    },
    {
      "x": -9,
      "y": 34,
      "z": -6,
      "name": "Rock_Shale_Brick_Smooth"
    },
    {
      "x": -9,
      "y": 35,
      "z": -6,
      "name": "Rock_Shale_Brick_Smooth"
    },
    {
      "x": -9,
      "y": 36,
      "z": -6,
      "name": "Rock_Shale_Brick_Smooth"
    },
    {
      "x": -9,
      "y": 37,
      "z": -6,
      "name": "Rock_Shale_Brick_Smooth"
    },
    {
      "x": -9,
      "y": 0,
      "z": -5,
      "name": "Rock_Shale_Brick_Smooth_Half",
      "rotation": 4
    },
    {
      "x": -9,
      "y": 1,
      "z": -5,
      "name": "Rock_Shale_Brick_Smooth_Half",
      "rotation": 4
    },
    {
      "x": -9,
      "y": 2,
      "z": -5,
      "name": "Rock_Shale_Brick_Smooth_Half",
      "rotation": 4
    },
    {
      "x": -9,
      "y": 3,
      "z": -5,
      "name": "Rock_Shale_Brick_Smooth_Half",
      "rotation": 4
    },
    {
      "x": -9,
      "y": 4,
      "z": -5,
      "name": "Rock_Shale_Brick_Smooth_Half",
      "rotation": 4
    },
    {
      "x": -9,
      "y": 5,
      "z": -5,
      "name": "Rock_Shale_Brick_Smooth_Half",
      "rotation": 4
    },
    {
      "x": -9,
      "y": 6,
      "z": -5,
      "name": "Rock_Shale_Brick_Smooth_Half",
      "rotation": 4
    },
    {
      "x": -9,
      "y": 7,
      "z": -5,
      "name": "Rock_Runic_Teal_Brick_Stairs",
      "rotation": 32
    },
    {
      "x": -9,
      "y": 19,
      "z": -5,
      "name": "Rock_Shale_Brick_Smooth_Half",
      "rotation": 4
    },
    {
      "x": -9,
      "y": 20,
      "z": -5,
      "name": "Rock_Shale_Brick_Smooth_Half",
      "rotation": 4
    },
    {
      "x": -9,
      "y": 21,
      "z": -5,
      "name": "Rock_Shale_Brick_Smooth_Half",
      "rotation": 4
    },
    {
      "x": -9,
      "y": 22,
      "z": -5,
      "name": "Rock_Shale_Brick_Smooth_Half",
      "rotation": 4
    },
    {
      "x": -9,
      "y": 23,
      "z": -5,
      "name": "Rock_Shale_Brick_Smooth_Half",
      "rotation": 4
    },
    {
      "x": -9,
      "y": 24,
      "z": -5,
      "name": "Rock_Shale_Brick_Smooth_Half",
      "rotation": 4
    },
    {
      "x": -9,
      "y": 25,
      "z": -5,
      "name": "Rock_Shale_Brick_Smooth_Half",
      "rotation": 4
    },
    {
      "x": -9,
      "y": 26,
      "z": -5,
      "name": "Rock_Runic_Teal_Brick_Stairs",
      "rotation": 32
    },
    {
      "x": -9,
      "y": 7,
      "z": -4,
      "name": "Rock_Shale_Brick_Smooth_Half",
      "rotation": 4
    },
    {
      "x": -9,
      "y": 8,
      "z": -4,
      "name": "Rock_Shale_Brick_Smooth_Half",
      "rotation": 4
    },
    {
      "x": -9,
      "y": 26,
      "z": -4,
      "name": "Rock_Shale_Brick_Smooth_Half",
      "rotation": 4
    },
    {
      "x": -9,
      "y": 27,
      "z": -4,
      "name": "Rock_Shale_Brick_Smooth_Half",
      "rotation": 4
    },
    {
      "x": -9,
      "y": 7,
      "z": 5,
      "name": "Rock_Shale_Brick_Smooth_Half",
      "rotation": 6
    },
    {
      "x": -9,
      "y": 8,
      "z": 5,
      "name": "Rock_Shale_Brick_Smooth_Half",
      "rotation": 6
    },
    {
      "x": -9,
      "y": 26,
      "z": 5,
      "name": "Rock_Shale_Brick_Smooth_Half",
      "rotation": 6
    },
    {
      "x": -9,
      "y": 27,
      "z": 5,
      "name": "Rock_Shale_Brick_Smooth_Half",
      "rotation": 6
    },
    {
      "x": -9,
      "y": 0,
      "z": 6,
      "name": "Rock_Shale_Brick_Smooth_Half",
      "rotation": 6
    },
    {
      "x": -9,
      "y": 1,
      "z": 6,
      "name": "Rock_Shale_Brick_Smooth_Half",
      "rotation": 6
    },
    {
      "x": -9,
      "y": 2,
      "z": 6,
      "name": "Rock_Shale_Brick_Smooth_Half",
      "rotation": 6
    },
    {
      "x": -9,
      "y": 3,
      "z": 6,
      "name": "Rock_Shale_Brick_Smooth_Half",
      "rotation": 6
    },
    {
      "x": -9,
      "y": 4,
      "z": 6,
      "name": "Rock_Shale_Brick_Smooth_Half",
      "rotation": 6
    },
    {
      "x": -9,
      "y": 5,
      "z": 6,
      "name": "Rock_Shale_Brick_Smooth_Half",
      "rotation": 6
    },
    {
      "x": -9,
      "y": 6,
      "z": 6,
      "name": "Rock_Shale_Brick_Smooth_Half",
      "rotation": 6
    },
    {
      "x": -9,
      "y": 7,
      "z": 6,
      "name": "Rock_Runic_Teal_Brick_Stairs",
      "rotation": 8
    },
    {
      "x": -9,
      "y": 19,
      "z": 6,
      "name": "Rock_Shale_Brick_Smooth_Half",
      "rotation": 6
    },
    {
      "x": -9,
      "y": 20,
      "z": 6,
      "name": "Rock_Shale_Brick_Smooth_Half",
      "rotation": 6
    },
    {
      "x": -9,
      "y": 21,
      "z": 6,
      "name": "Rock_Shale_Brick_Smooth_Half",
      "rotation": 6
    },
    {
      "x": -9,
      "y": 22,
      "z": 6,
      "name": "Rock_Shale_Brick_Smooth_Half",
      "rotation": 6
    },
    {
      "x": -9,
      "y": 23,
      "z": 6,
      "name": "Rock_Shale_Brick_Smooth_Half",
      "rotation": 6
    },
    {
      "x": -9,
      "y": 24,
      "z": 6,
      "name": "Rock_Shale_Brick_Smooth_Half",
      "rotation": 6
    },
    {
      "x": -9,
      "y": 25,
      "z": 6,
      "name": "Rock_Shale_Brick_Smooth_Half",
      "rotation": 6
    },
    {
      "x": -9,
      "y": 26,
      "z": 6,
      "name": "Rock_Runic_Teal_Brick_Stairs",
      "rotation": 8
    },
    {
      "x": -9,
      "y": 0,
      "z": 7,
      "name": "Rock_Shale_Brick_Smooth"
    },
    {
      "x": -9,
      "y": 1,
      "z": 7,
      "name": "Rock_Shale_Brick_Smooth"
    },
    {
      "x": -9,
      "y": 2,
      "z": 7,
      "name": "Rock_Shale_Brick_Smooth"
    },
    {
      "x": -9,
      "y": 3,
      "z": 7,
      "name": "Rock_Shale_Brick_Smooth"
    },
    {
      "x": -9,
      "y": 4,
      "z": 7,
      "name": "Rock_Shale_Brick_Smooth"
    },
    {
      "x": -9,
      "y": 5,
      "z": 7,
      "name": "Rock_Shale_Brick_Smooth"
    },
    {
      "x": -9,
      "y": 6,
      "z": 7,
      "name": "Rock_Shale_Brick_Smooth"
    },
    {
      "x": -9,
      "y": 7,
      "z": 7,
      "name": "Rock_Shale_Brick_Smooth"
    },
    {
      "x": -9,
      "y": 8,
      "z": 7,
      "name": "Rock_Shale_Brick_Smooth"
    },
    {
      "x": -9,
      "y": 9,
      "z": 7,
      "name": "Rock_Shale_Brick_Smooth"
    },
    {
      "x": -9,
      "y": 10,
      "z": 7,
      "name": "Rock_Shale_Brick_Smooth"
    },
    {
      "x": -9,
      "y": 11,
      "z": 7,
      "name": "Rock_Shale_Brick_Smooth"
    },
    {
      "x": -9,
      "y": 12,
      "z": 7,
      "name": "Rock_Shale_Brick_Smooth"
    },
    {
      "x": -9,
      "y": 13,
      "z": 7,
      "name": "Rock_Shale_Brick_Smooth"
    },
    {
      "x": -9,
      "y": 14,
      "z": 7,
      "name": "Rock_Shale_Brick_Ornate"
    },
    {
      "x": -9,
      "y": 15,
      "z": 7,
      "name": "Rock_Shale_Brick_Smooth"
    },
    {
      "x": -9,
      "y": 16,
      "z": 7,
      "name": "Rock_Shale_Brick_Smooth"
    },
    {
      "x": -9,
      "y": 17,
      "z": 7,
      "name": "Rock_Shale_Brick_Smooth"
    },
    {
      "x": -9,
      "y": 18,
      "z": 7,
      "name": "Rock_Shale_Brick_Smooth"
    },
    {
      "x": -9,
      "y": 19,
      "z": 7,
      "name": "Rock_Shale_Brick_Smooth"
    },
    {
      "x": -9,
      "y": 20,
      "z": 7,
      "name": "Rock_Shale_Brick_Smooth"
    },
    {
      "x": -9,
      "y": 21,
      "z": 7,
      "name": "Rock_Shale_Brick_Smooth"
    },
    {
      "x": -9,
      "y": 22,
      "z": 7,
      "name": "Rock_Shale_Brick_Smooth"
    },
    {
      "x": -9,
      "y": 23,
      "z": 7,
      "name": "Rock_Shale_Brick_Smooth"
    },
    {
      "x": -9,
      "y": 24,
      "z": 7,
      "name": "Rock_Shale_Brick_Smooth"
    },
    {
      "x": -9,
      "y": 25,
      "z": 7,
      "name": "Rock_Shale_Brick_Smooth"
    },
    {
      "x": -9,
      "y": 26,
      "z": 7,
      "name": "Rock_Shale_Brick_Smooth"
    },
    {
      "x": -9,
      "y": 27,
      "z": 7,
      "name": "Rock_Shale_Brick_Smooth"
    },
    {
      "x": -9,
      "y": 28,
      "z": 7,
      "name": "Rock_Shale_Brick_Smooth"
    },
    {
      "x": -9,
      "y": 29,
      "z": 7,
      "name": "Rock_Shale_Brick_Smooth"
    },
    {
      "x": -9,
      "y": 30,
      "z": 7,
      "name": "Rock_Shale_Brick_Smooth"
    },
    {
      "x": -9,
      "y": 31,
      "z": 7,
      "name": "Rock_Shale_Brick_Smooth"
    },
    {
      "x": -9,
      "y": 32,
      "z": 7,
      "name": "Rock_Shale_Brick_Smooth"
    },
    {
      "x": -9,
      "y": 33,
      "z": 7,
      "name": "Rock_Shale_Brick_Ornate"
    },
    {
      "x": -9,
      "y": 34,
      "z": 7,
      "name": "Rock_Shale_Brick_Smooth"
    },
    {
      "x": -9,
      "y": 35,
      "z": 7,
      "name": "Rock_Shale_Brick_Smooth"
    },
    {
      "x": -9,
      "y": 36,
      "z": 7,
      "name": "Rock_Shale_Brick_Smooth"
    },
    {
      "x": -9,
      "y": 37,
      "z": 7,
      "name": "Rock_Shale_Brick_Smooth"
    },
    {
      "x": -9,
      "y": 0,
      "z": 11,
      "name": "Rock_Shale_Brick_Smooth"
    },
    {
      "x": -9,
      "y": 1,
      "z": 11,
      "name": "Rock_Shale_Brick_Smooth"
    },
    {
      "x": -9,
      "y": 2,
      "z": 11,
      "name": "Rock_Shale_Brick_Smooth"
    },
    {
      "x": -9,
      "y": 3,
      "z": 11,
      "name": "Rock_Shale_Brick_Smooth"
    },
    {
      "x": -9,
      "y": 4,
      "z": 11,
      "name": "Rock_Shale_Brick_Smooth"
    },
    {
      "x": -9,
      "y": 5,
      "z": 11,
      "name": "Rock_Shale_Brick_Smooth"
    },
    {
      "x": -9,
      "y": 6,
      "z": 11,
      "name": "Rock_Shale_Brick_Smooth"
    },
    {
      "x": -9,
      "y": 7,
      "z": 11,
      "name": "Rock_Shale_Brick_Smooth"
    },
    {
      "x": -9,
      "y": 8,
      "z": 11,
      "name": "Rock_Shale_Brick_Smooth"
    },
    {
      "x": -9,
      "y": 9,
      "z": 11,
      "name": "Rock_Shale_Brick_Smooth"
    },
    {
      "x": -9,
      "y": 10,
      "z": 11,
      "name": "Rock_Shale_Brick_Smooth"
    },
    {
      "x": -9,
      "y": 11,
      "z": 11,
      "name": "Rock_Shale_Brick_Smooth"
    },
    {
      "x": -9,
      "y": 12,
      "z": 11,
      "name": "Rock_Shale_Brick_Smooth"
    },
    {
      "x": -9,
      "y": 13,
      "z": 11,
      "name": "Rock_Shale_Brick_Smooth"
    },
    {
      "x": -9,
      "y": 14,
      "z": 11,
      "name": "Rock_Shale_Brick_Ornate"
    },
    {
      "x": -9,
      "y": 15,
      "z": 11,
      "name": "Rock_Shale_Brick_Smooth"
    },
    {
      "x": -9,
      "y": 16,
      "z": 11,
      "name": "Rock_Shale_Brick_Smooth"
    },
    {
      "x": -9,
      "y": 17,
      "z": 11,
      "name": "Rock_Shale_Brick_Smooth"
    },
    {
      "x": -9,
      "y": 18,
      "z": 11,
      "name": "Rock_Shale_Brick_Smooth"
    },
    {
      "x": -9,
      "y": 19,
      "z": 11,
