{
  "version": 8,
  "blockIdVersion": 11,
  "anchorX": 0,
  "anchorY": 0,
  "anchorZ": 0,
  "blocks": [
    {
      "x": -21,
      "y": 4,
      "z": -4,
      "name": "Rock_Shale_Cobble"
    },
    {
      "x": -21,
      "y": 5,
      "z": -4,
      "name": "Rock_Shale_Brick",
      "rotation": 1
    },
    {
      "x": -21,
      "y": 6,
      "z": -4,
      "name": "Rock_Shale_Brick",
      "rotation": 1
    },
    {
      "x": -21,
      "y": 7,
      "z": -4,
      "name": "Rock_Shale_Brick",
      "rotation": 1
    },
    {
      "x": -21,
      "y": 8,
      "z": -4,
      "name": "Rock_Shale_Brick",
      "rotation": 1
    },
    {
      "x": -21,
      "y": 9,
      "z": -4,
      "name": "Rock_Shale_Brick_Ornate",
      "rotation": 3
    },
    {
      "x": -21,
      "y": 10,
      "z": -4,
      "name": "Rock_Shale_Cobble"
    },
    {
      "x": -21,
      "y": 11,
      "z": -4,
      "name": "Rock_Shale_Brick",
      "rotation": 1
    },
    {
      "x": -21,
      "y": 12,
      "z": -4,
      "name": "Rock_Shale_Brick",
      "rotation": 1
    },
    {
      "x": -21,
      "y": 13,
      "z": -4,
      "name": "Rock_Shale_Brick",
      "rotation": 1
    },
    {
      "x": -21,
      "y": 14,
      "z": -4,
      "name": "Rock_Shale_Brick",
      "rotation": 1
    },
    {
      "x": -21,
      "y": 15,
      "z": -4,
      "name": "Rock_Shale_Brick_Ornate",
      "rotation": 3
    },
    {
      "x": -21,
      "y": 16,
      "z": -4,
      "name": "Rock_Shale_Cobble"
    },
    {
      "x": -21,
      "y": 17,
      "z": -4,
      "name": "Rock_Shale_Brick",
      "rotation": 1
    },
    {
      "x": -21,
      "y": 18,
      "z": -4,
      "name": "Rock_Shale_Brick",
      "rotation": 1
    },
    {
      "x": -21,
      "y": 19,
      "z": -4,
      "name": "Rock_Shale_Brick",
      "rotation": 1
    },
    {
      "x": -21,
      "y": 20,
      "z": -4,
      "name": "Rock_Shale_Brick",
      "rotation": 1
    },
    {
      "x": -21,
      "y": 21,
      "z": -4,
      "name": "Rock_Shale_Brick_Ornate",
      "rotation": 3
    },
    {
      "x": -21,
      "y": 4,
      "z": -3,
      "name": "Rock_Shale_Brick_Smooth"
    },
    {
      "x": -21,
      "y": 5,
      "z": -3,
      "name": "Rock_Shale_Brick_Smooth"
    },
    {
      "x": -21,
      "y": 6,
      "z": -3,
      "name": "Rock_Shale_Brick_Smooth"
    },
    {
      "x": -21,
      "y": 7,
      "z": -3,
      "name": "Rock_Shale_Brick_Smooth"
    },
    {
      "x": -21,
      "y": 8,
      "z": -3,
      "name": "Rock_Shale_Brick_Smooth"
    },
    {
      "x": -21,
      "y": 9,
      "z": -3,
      "name": "Rock_Shale_Brick_Ornate"
    },
    {
      "x": -21,
      "y": 10,
      "z": -3,
      "name": "Rock_Shale_Brick_Smooth"
    },
    {
      "x": -21,
      "y": 11,
      "z": -3,
      "name": "Rock_Shale_Brick_Smooth"
    },
    {
      "x": -21,
      "y": 12,
      "z": -3,
      "name": "Rock_Shale_Brick_Smooth"
    },
    {
      "x": -21,
      "y": 13,
      "z": -3,
      "name": "Rock_Shale_Brick_Smooth"
    },
    {
      "x": -21,
      "y": 14,
      "z": -3,
      "name": "Rock_Shale_Brick_Smooth"
    },
    {
      "x": -21,
      "y": 15,
      "z": -3,
      "name": "Rock_Shale_Brick_Ornate"
    },
    {
      "x": -21,
      "y": 16,
      "z": -3,
      "name": "Rock_Shale_Brick_Smooth"
    },
    {
      "x": -21,
      "y": 17,
      "z": -3,
      "name": "Rock_Shale_Brick_Smooth"
    },
    {
      "x": -21,
      "y": 18,
      "z": -3,
      "name": "Rock_Shale_Brick_Smooth"
    },
    {
      "x": -21,
      "y": 19,
      "z": -3,
      "name": "Rock_Shale_Brick_Smooth"
    },
    {
      "x": -21,
      "y": 20,
      "z": -3,
      "name": "Rock_Shale_Brick_Smooth"
    },
    {
      "x": -21,
      "y": 21,
      "z": -3,
      "name": "Rock_Shale_Brick_Ornate"
    },
    {
      "x": -21,
      "y": 4,
      "z": -2,
      "name": "Rock_Shale_Cobble"
    },
    {
      "x": -21,
      "y": 5,
      "z": -2,
      "name": "Rock_Shale_Brick",
      "rotation": 1
    },
    {
      "x": -21,
      "y": 6,
      "z": -2,
      "name": "Rock_Shale_Brick",
      "rotation": 1
    },
    {
      "x": -21,
      "y": 7,
      "z": -2,
      "name": "Rock_Shale_Brick",
      "rotation": 1
    },
    {
      "x": -21,
      "y": 8,
      "z": -2,
      "name": "Rock_Shale_Brick",
      "rotation": 1
    },
    {
      "x": -21,
      "y": 9,
      "z": -2,
      "name": "Rock_Shale_Brick_Ornate",
      "rotation": 3
    },
    {
      "x": -21,
      "y": 10,
      "z": -2,
      "name": "Rock_Shale_Cobble"
    },
    {
      "x": -21,
      "y": 11,
      "z": -2,
      "name": "Rock_Shale_Brick",
      "rotation": 1
    },
    {
      "x": -21,
      "y": 12,
      "z": -2,
      "name": "Rock_Shale_Brick",
      "rotation": 1
    },
    {
      "x": -21,
      "y": 13,
      "z": -2,
      "name": "Rock_Shale_Brick",
      "rotation": 1
    },
    {
      "x": -21,
      "y": 14,
      "z": -2,
      "name": "Rock_Shale_Brick",
      "rotation": 1
    },
    {
      "x": -21,
      "y": 15,
      "z": -2,
      "name": "Rock_Shale_Brick_Ornate",
      "rotation": 3
    },
    {
      "x": -21,
      "y": 16,
      "z": -2,
      "name": "Rock_Shale_Cobble"
    },
    {
      "x": -21,
      "y": 17,
      "z": -2,
      "name": "Rock_Shale_Brick",
      "rotation": 1
    },
    {
      "x": -21,
      "y": 18,
      "z": -2,
      "name": "Rock_Shale_Brick",
      "rotation": 1
    },
    {
      "x": -21,
      "y": 19,
      "z": -2,
      "name": "Rock_Shale_Brick",
      "rotation": 1
    },
    {
      "x": -21,
      "y": 20,
      "z": -2,
      "name": "Rock_Shale_Brick",
      "rotation": 1
    },
    {
      "x": -21,
      "y": 21,
      "z": -2,
      "name": "Rock_Shale_Brick_Ornate",
      "rotation": 3
    },
    {
      "x": -21,
      "y": 4,
      "z": -1,
      "name": "Rock_Shale_Cobble"
    },
    {
      "x": -21,
      "y": 5,
      "z": -1,
      "name": "Rock_Shale_Brick_Smooth"
    },
    {
      "x": -21,
      "y": 6,
      "z": -1,
      "name": "Rock_Shale_Brick_Smooth"
    },
    {
      "x": -21,
      "y": 7,
      "z": -1,
      "name": "Rock_Shale_Brick_Smooth"
    },
    {
      "x": -21,
      "y": 8,
      "z": -1,
      "name": "Rock_Shale_Brick_Smooth"
    },
    {
      "x": -21,
      "y": 9,
      "z": -1,
      "name": "Rock_Shale_Brick_Ornate"
    },
    {
      "x": -21,
      "y": 10,
      "z": -1,
      "name": "Rock_Shale_Cobble"
    },
    {
      "x": -21,
      "y": 11,
      "z": -1,
      "name": "Rock_Shale_Brick_Smooth"
    },
    {
      "x": -21,
      "y": 12,
      "z": -1,
      "name": "Rock_Shale_Brick_Smooth"
    },
    {
      "x": -21,
      "y": 13,
      "z": -1,
      "name": "Rock_Shale_Brick_Smooth"
    },
    {
      "x": -21,
      "y": 14,
      "z": -1,
      "name": "Rock_Shale_Brick_Smooth"
    },
    {
      "x": -21,
      "y": 15,
      "z": -1,
      "name": "Rock_Shale_Brick_Ornate"
    },
    {
      "x": -21,
      "y": 16,
      "z": -1,
      "name": "Rock_Shale_Cobble"
    },
    {
      "x": -21,
      "y": 17,
      "z": -1,
      "name": "Rock_Shale_Brick_Smooth"
    },
    {
      "x": -21,
      "y": 18,
      "z": -1,
      "name": "Rock_Shale_Brick_Smooth"
    },
    {
      "x": -21,
      "y": 19,
      "z": -1,
      "name": "Rock_Shale_Brick_Smooth"
    },
    {
      "x": -21,
      "y": 20,
      "z": -1,
      "name": "Rock_Shale_Brick_Smooth"
    },
    {
      "x": -21,
      "y": 21,
      "z": -1,
      "name": "Rock_Shale_Brick_Ornate"
    },
    {
      "x": -21,
      "y": 4,
      "z": 0,
      "name": "Rock_Shale_Cobble",
      "rotation": 1
    },
    {
      "x": -21,
      "y": 5,
      "z": 0,
      "name": "Rock_Shale_Brick",
      "rotation": 2
    },
    {
      "x": -21,
      "y": 6,
      "z": 0,
      "name": "Rock_Shale_Brick",
      "rotation": 2
    },
    {
      "x": -21,
      "y": 7,
      "z": 0,
      "name": "Rock_Shale_Brick",
      "rotation": 2
    },
    {
      "x": -21,
      "y": 8,
      "z": 0,
      "name": "Rock_Shale_Brick",
      "rotation": 2
    },
    {
      "x": -21,
      "y": 9,
      "z": 0,
      "name": "Rock_Shale_Brick_Ornate"
    },
    {
      "x": -21,
      "y": 10,
      "z": 0,
      "name": "Rock_Shale_Cobble",
      "rotation": 1
    },
    {
      "x": -21,
      "y": 11,
      "z": 0,
      "name": "Rock_Shale_Brick",
      "rotation": 2
    },
    {
      "x": -21,
      "y": 12,
      "z": 0,
      "name": "Rock_Shale_Brick",
      "rotation": 2
    },
    {
      "x": -21,
      "y": 13,
      "z": 0,
      "name": "Rock_Shale_Brick",
      "rotation": 2
    },
    {
      "x": -21,
      "y": 14,
      "z": 0,
      "name": "Rock_Shale_Brick",
      "rotation": 2
    },
    {
      "x": -21,
      "y": 15,
      "z": 0,
      "name": "Rock_Shale_Brick_Ornate"
    },
    {
      "x": -21,
      "y": 16,
      "z": 0,
      "name": "Rock_Shale_Cobble",
      "rotation": 1
    },
    {
      "x": -21,
      "y": 17,
      "z": 0,
      "name": "Rock_Shale_Brick",
      "rotation": 2
    },
    {
      "x": -21,
      "y": 18,
      "z": 0,
      "name": "Rock_Shale_Brick",
      "rotation": 2
    },
    {
      "x": -21,
      "y": 19,
      "z": 0,
      "name": "Rock_Shale_Brick",
      "rotation": 2
    },
    {
      "x": -21,
      "y": 20,
      "z": 0,
      "name": "Rock_Shale_Brick",
      "rotation": 2
    },
    {
      "x": -21,
      "y": 21,
      "z": 0,
      "name": "Rock_Shale_Brick_Ornate"
    },
    {
      "x": -21,
      "y": 4,
      "z": 1,
      "name": "Rock_Shale_Cobble",
      "rotation": 1
    },
    {
      "x": -21,
      "y": 5,
      "z": 1,
      "name": "Rock_Shale_Brick_Smooth",
      "rotation": 1
    },
    {
      "x": -21,
      "y": 6,
      "z": 1,
      "name": "Rock_Shale_Brick_Smooth",
      "rotation": 1
    },
    {
      "x": -21,
      "y": 7,
      "z": 1,
      "name": "Rock_Shale_Brick_Smooth",
      "rotation": 1
    },
    {
      "x": -21,
      "y": 8,
      "z": 1,
      "name": "Rock_Shale_Brick_Smooth",
      "rotation": 1
    },
    {
      "x": -21,
      "y": 9,
      "z": 1,
      "name": "Rock_Shale_Brick_Ornate",
      "rotation": 1
    },
    {
      "x": -21,
      "y": 10,
      "z": 1,
      "name": "Rock_Shale_Cobble",
      "rotation": 1
    },
    {
      "x": -21,
      "y": 11,
      "z": 1,
      "name": "Rock_Shale_Brick_Smooth",
      "rotation": 1
    },
    {
      "x": -21,
      "y": 12,
      "z": 1,
      "name": "Rock_Shale_Brick_Smooth",
      "rotation": 1
    },
    {
      "x": -21,
      "y": 13,
      "z": 1,
      "name": "Rock_Shale_Brick_Smooth",
      "rotation": 1
    },
    {
      "x": -21,
      "y": 14,
      "z": 1,
      "name": "Rock_Shale_Brick_Smooth",
      "rotation": 1
    },
    {
      "x": -21,
      "y": 15,
      "z": 1,
      "name": "Rock_Shale_Brick_Ornate",
      "rotation": 1
    },
    {
      "x": -21,
      "y": 16,
      "z": 1,
      "name": "Rock_Shale_Cobble",
      "rotation": 1
    },
    {
      "x": -21,
      "y": 17,
      "z": 1,
      "name": "Rock_Shale_Brick_Smooth",
      "rotation": 1
    },
    {
      "x": -21,
      "y": 18,
      "z": 1,
      "name": "Rock_Shale_Brick_Smooth",
      "rotation": 1
    },
    {
      "x": -21,
      "y": 19,
      "z": 1,
      "name": "Rock_Shale_Brick_Smooth",
      "rotation": 1
    },
    {
      "x": -21,
      "y": 20,
      "z": 1,
      "name": "Rock_Shale_Brick_Smooth",
      "rotation": 1
    },
    {
      "x": -21,
      "y": 21,
      "z": 1,
      "name": "Rock_Shale_Brick_Ornate",
      "rotation": 1
    },
    {
      "x": -21,
      "y": 4,
      "z": 2,
      "name": "Rock_Shale_Cobble",
      "rotation": 1
    },
    {
      "x": -21,
      "y": 5,
      "z": 2,
      "name": "Rock_Shale_Brick",
      "rotation": 2
    },
    {
      "x": -21,
      "y": 6,
      "z": 2,
      "name": "Rock_Shale_Brick",
      "rotation": 2
    },
    {
      "x": -21,
      "y": 7,
      "z": 2,
      "name": "Rock_Shale_Brick",
      "rotation": 2
    },
    {
      "x": -21,
      "y": 8,
      "z": 2,
      "name": "Rock_Shale_Brick",
      "rotation": 2
    },
    {
      "x": -21,
      "y": 9,
      "z": 2,
      "name": "Rock_Shale_Brick_Ornate"
    },
    {
      "x": -21,
      "y": 10,
      "z": 2,
      "name": "Rock_Shale_Cobble",
      "rotation": 1
    },
    {
      "x": -21,
      "y": 11,
      "z": 2,
      "name": "Rock_Shale_Brick",
      "rotation": 2
    },
    {
      "x": -21,
      "y": 12,
      "z": 2,
      "name": "Rock_Shale_Brick",
      "rotation": 2
    },
    {
      "x": -21,
      "y": 13,
      "z": 2,
      "name": "Rock_Shale_Brick",
      "rotation": 2
    },
    {
      "x": -21,
      "y": 14,
      "z": 2,
      "name": "Rock_Shale_Brick",
      "rotation": 2
    },
    {
      "x": -21,
      "y": 15,
      "z": 2,
      "name": "Rock_Shale_Brick_Ornate"
    },
    {
      "x": -21,
      "y": 16,
      "z": 2,
      "name": "Rock_Shale_Cobble",
      "rotation": 1
    },
    {
      "x": -21,
      "y": 17,
      "z": 2,
      "name": "Rock_Shale_Brick",
      "rotation": 2
    },
    {
      "x": -21,
      "y": 18,
      "z": 2,
      "name": "Rock_Shale_Brick",
      "rotation": 2
    },
    {
      "x": -21,
      "y": 19,
      "z": 2,
      "name": "Rock_Shale_Brick",
      "rotation": 2
    },
    {
      "x": -21,
      "y": 20,
      "z": 2,
      "name": "Rock_Shale_Brick",
      "rotation": 2
    },
    {
      "x": -21,
      "y": 21,
      "z": 2,
      "name": "Rock_Shale_Brick_Ornate"
    },
    {
      "x": -21,
      "y": 4,
      "z": 3,
      "name": "Rock_Shale_Brick_Smooth",
      "rotation": 1
    },
    {
      "x": -21,
      "y": 5,
      "z": 3,
      "name": "Rock_Shale_Brick_Smooth",
      "rotation": 1
    },
    {
      "x": -21,
      "y": 6,
      "z": 3,
      "name": "Rock_Shale_Brick_Smooth",
      "rotation": 1
    },
    {
      "x": -21,
      "y": 7,
      "z": 3,
      "name": "Rock_Shale_Brick_Smooth",
      "rotation": 1
    },
    {
      "x": -21,
      "y": 8,
      "z": 3,
      "name": "Rock_Shale_Brick_Smooth",
      "rotation": 1
    },
    {
      "x": -21,
      "y": 9,
      "z": 3,
      "name": "Rock_Shale_Brick_Ornate",
      "rotation": 1
    },
    {
      "x": -21,
      "y": 10,
      "z": 3,
      "name": "Rock_Shale_Brick_Smooth",
      "rotation": 1
    },
    {
      "x": -21,
      "y": 11,
      "z": 3,
      "name": "Rock_Shale_Brick_Smooth",
      "rotation": 1
    },
    {
      "x": -21,
      "y": 12,
      "z": 3,
      "name": "Rock_Shale_Brick_Smooth",
      "rotation": 1
    },
    {
      "x": -21,
      "y": 13,
      "z": 3,
      "name": "Rock_Shale_Brick_Smooth",
      "rotation": 1
    },
    {
      "x": -21,
      "y": 14,
      "z": 3,
      "name": "Rock_Shale_Brick_Smooth",
      "rotation": 1
    },
    {
      "x": -21,
      "y": 15,
      "z": 3,
      "name": "Rock_Shale_Brick_Ornate",
      "rotation": 1
    },
    {
      "x": -21,
      "y": 16,
      "z": 3,
      "name": "Rock_Shale_Brick_Smooth",
      "rotation": 1
    },
    {
      "x": -21,
      "y": 17,
      "z": 3,
      "name": "Rock_Shale_Brick_Smooth",
      "rotation": 1
    },
    {
      "x": -21,
      "y": 18,
      "z": 3,
      "name": "Rock_Shale_Brick_Smooth",
      "rotation": 1
    },
    {
      "x": -21,
      "y": 19,
      "z": 3,
      "name": "Rock_Shale_Brick_Smooth",
      "rotation": 1
    },
    {
      "x": -21,
      "y": 20,
      "z": 3,
      "name": "Rock_Shale_Brick_Smooth",
      "rotation": 1
    },
    {
      "x": -21,
      "y": 21,
      "z": 3,
      "name": "Rock_Shale_Brick_Ornate",
      "rotation": 1
    },
    {
      "x": -21,
      "y": 4,
      "z": 4,
      "name": "Rock_Shale_Cobble",
      "rotation": 1
    },
    {
      "x": -21,
      "y": 5,
      "z": 4,
      "name": "Rock_Shale_Brick",
      "rotation": 2
    },
    {
      "x": -21,
      "y": 6,
      "z": 4,
      "name": "Rock_Shale_Brick",
      "rotation": 2
    },
    {
      "x": -21,
      "y": 7,
      "z": 4,
      "name": "Rock_Shale_Brick",
      "rotation": 2
    },
    {
      "x": -21,
      "y": 8,
      "z": 4,
      "name": "Rock_Shale_Brick",
      "rotation": 2
    },
    {
      "x": -21,
      "y": 9,
      "z": 4,
      "name": "Rock_Shale_Brick_Ornate"
    },
    {
      "x": -21,
      "y": 10,
      "z": 4,
      "name": "Rock_Shale_Cobble",
      "rotation": 1
    },
    {
      "x": -21,
      "y": 11,
      "z": 4,
      "name": "Rock_Shale_Brick",
      "rotation": 2
    },
    {
      "x": -21,
      "y": 12,
      "z": 4,
      "name": "Rock_Shale_Brick",
      "rotation": 2
    },
    {
      "x": -21,
      "y": 13,
      "z": 4,
      "name": "Rock_Shale_Brick",
      "rotation": 2
    },
    {
      "x": -21,
      "y": 14,
      "z": 4,
      "name": "Rock_Shale_Brick",
      "rotation": 2
    },
    {
      "x": -21,
      "y": 15,
      "z": 4,
      "name": "Rock_Shale_Brick_Ornate"
    },
    {
      "x": -21,
      "y": 16,
      "z": 4,
      "name": "Rock_Shale_Cobble",
      "rotation": 1
    },
    {
      "x": -21,
      "y": 17,
      "z": 4,
      "name": "Rock_Shale_Brick",
      "rotation": 2
    },
    {
      "x": -21,
      "y": 18,
      "z": 4,
      "name": "Rock_Shale_Brick",
      "rotation": 2
    },
    {
      "x": -21,
      "y": 19,
      "z": 4,
      "name": "Rock_Shale_Brick",
      "rotation": 2
    },
    {
      "x": -21,
      "y": 20,
      "z": 4,
      "name": "Rock_Shale_Brick",
      "rotation": 2
    },
    {
      "x": -21,
      "y": 21,
      "z": 4,
      "name": "Rock_Shale_Brick_Ornate"
    },
    {
      "x": -20,
      "y": 4,
      "z": -7,
      "name": "Rock_Shale_Cobble"
    },
    {
      "x": -20,
      "y": 5,
      "z": -7,
      "name": "Rock_Shale_Brick_Smooth"
    },
    {
      "x": -20,
      "y": 6,
      "z": -7,
      "name": "Rock_Shale_Brick_Smooth"
    },
    {
      "x": -20,
      "y": 7,
      "z": -7,
      "name": "Rock_Shale_Brick_Smooth"
    },
    {
      "x": -20,
      "y": 8,
      "z": -7,
      "name": "Rock_Shale_Brick_Smooth"
    },
    {
      "x": -20,
      "y": 9,
      "z": -7,
      "name": "Rock_Shale_Brick_Ornate"
    },
    {
      "x": -20,
      "y": 10,
      "z": -7,
      "name": "Rock_Shale_Cobble"
    },
    {
      "x": -20,
      "y": 11,
      "z": -7,
      "name": "Rock_Shale_Brick_Smooth"
    },
    {
      "x": -20,
      "y": 12,
      "z": -7,
      "name": "Rock_Shale_Brick_Smooth"
    },
    {
      "x": -20,
      "y": 13,
      "z": -7,
      "name": "Rock_Shale_Brick_Smooth"
    },
    {
      "x": -20,
      "y": 14,
      "z": -7,
      "name": "Rock_Shale_Brick_Smooth"
    },
    {
      "x": -20,
      "y": 15,
      "z": -7,
      "name": "Rock_Shale_Brick_Ornate"
    },
    {
      "x": -20,
      "y": 16,
      "z": -7,
      "name": "Rock_Shale_Cobble"
    },
    {
      "x": -20,
      "y": 17,
      "z": -7,
      "name": "Rock_Shale_Brick_Smooth"
    },
    {
      "x": -20,
      "y": 18,
      "z": -7,
      "name": "Rock_Shale_Brick_Smooth"
    },
    {
      "x": -20,
      "y": 19,
      "z": -7,
      "name": "Rock_Shale_Brick_Smooth"
    },
    {
      "x": -20,
      "y": 20,
      "z": -7,
      "name": "Rock_Shale_Brick_Smooth"
    },
    {
      "x": -20,
      "y": 21,
      "z": -7,
      "name": "Rock_Shale_Brick_Ornate"
    },
    {
      "x": -20,
      "y": 4,
      "z": -6,
      "name": "Rock_Shale_Cobble"
    },
    {
      "x": -20,
      "y": 5,
      "z": -6,
      "name": "Rock_Shale_Brick",
      "rotation": 1
    },
    {
      "x": -20,
      "y": 6,
      "z": -6,
      "name": "Rock_Shale_Brick",
      "rotation": 1
    },
    {
      "x": -20,
      "y": 7,
      "z": -6,
      "name": "Rock_Shale_Brick",
      "rotation": 1
    },
    {
      "x": -20,
      "y": 8,
      "z": -6,
      "name": "Rock_Shale_Brick",
      "rotation": 1
    },
    {
      "x": -20,
      "y": 9,
      "z": -6,
      "name": "Rock_Shale_Brick_Ornate",
      "rotation": 3
    },
    {
      "x": -20,
      "y": 10,
      "z": -6,
      "name": "Rock_Shale_Cobble"
    },
    {
      "x": -20,
      "y": 11,
      "z": -6,
      "name": "Rock_Shale_Brick",
      "rotation": 1
    },
    {
      "x": -20,
      "y": 12,
      "z": -6,
      "name": "Rock_Shale_Brick",
      "rotation": 1
    },
    {
      "x": -20,
      "y": 13,
      "z": -6,
      "name": "Rock_Shale_Brick",
      "rotation": 1
    },
    {
      "x": -20,
      "y": 14,
      "z": -6,
      "name": "Rock_Shale_Brick",
      "rotation": 1
    },
    {
      "x": -20,
      "y": 15,
      "z": -6,
      "name": "Rock_Shale_Brick_Ornate",
      "rotation": 3
    },
    {
      "x": -20,
      "y": 16,
      "z": -6,
      "name": "Rock_Shale_Cobble"
    },
    {
      "x": -20,
      "y": 17,
      "z": -6,
      "name": "Rock_Shale_Brick",
      "rotation": 1
    },
    {
      "x": -20,
      "y": 18,
      "z": -6,
      "name": "Rock_Shale_Brick",
      "rotation": 1
    },
    {
      "x": -20,
      "y": 19,
      "z": -6,
      "name": "Rock_Shale_Brick",
      "rotation": 1
    },
    {
      "x": -20,
      "y": 20,
      "z": -6,
      "name": "Rock_Shale_Brick",
      "rotation": 1
    },
    {
      "x": -20,
      "y": 21,
      "z": -6,
      "name": "Rock_Shale_Brick_Ornate",
      "rotation": 3
    },
    {
      "x": -20,
      "y": 4,
      "z": -5,
      "name": "Rock_Shale_Cobble"
    },
    {
      "x": -20,
      "y": 5,
      "z": -5,
      "name": "Rock_Shale_Brick_Smooth"
    },
    {
      "x": -20,
      "y": 6,
      "z": -5,
      "name": "Rock_Shale_Brick_Smooth"
    },
    {
      "x": -20,
      "y": 7,
      "z": -5,
      "name": "Rock_Shale_Brick_Smooth"
    },
    {
      "x": -20,
      "y": 8,
      "z": -5,
      "name": "Rock_Shale_Brick_Smooth"
    },
    {
      "x": -20,
      "y": 9,
      "z": -5,
      "name": "Rock_Shale_Brick_Ornate"
    },
    {
      "x": -20,
      "y": 10,
      "z": -5,
      "name": "Rock_Shale_Cobble"
    },
    {
      "x": -20,
      "y": 11,
      "z": -5,
      "name": "Rock_Shale_Brick_Smooth"
    },
    {
      "x": -20,
      "y": 12,
      "z": -5,
      "name": "Rock_Shale_Brick_Smooth"
    },
    {
      "x": -20,
      "y": 13,
      "z": -5,
      "name": "Rock_Shale_Brick_Smooth"
    },
    {
      "x": -20,
      "y": 14,
      "z": -5,
      "name": "Rock_Shale_Brick_Smooth"
    },
    {
      "x": -20,
      "y": 15,
      "z": -5,
      "name": "Rock_Shale_Brick_Ornate"
    },
    {
      "x": -20,
      "y": 16,
      "z": -5,
      "name": "Rock_Shale_Cobble"
    },
    {
      "x": -20,
      "y": 17,
      "z": -5,
      "name": "Rock_Shale_Brick_Smooth"
    },
    {
      "x": -20,
      "y": 18,
      "z": -5,
      "name": "Rock_Shale_Brick_Smooth"
    },
    {
      "x": -20,
      "y": 19,
      "z": -5,
      "name": "Rock_Shale_Brick_Smooth"
    },
    {
      "x": -20,
      "y": 20,
      "z": -5,
      "name": "Rock_Shale_Brick_Smooth"
    },
    {
      "x": -20,
      "y": 21,
      "z": -5,
      "name": "Rock_Shale_Brick_Ornate"
    },
    {
      "x": -20,
      "y": 4,
      "z": -4,
      "name": "Rock_Shale_Cobble"
    },
    {
      "x": -20,
      "y": 10,
      "z": -4,
      "name": "Rock_Shale_Cobble"
    },
    {
      "x": -20,
      "y": 16,
      "z": -4,
      "name": "Rock_Shale_Cobble"
    },
    {
      "x": -20,
      "y": 4,
      "z": -3,
      "name": "Rock_Shale_Brick_Smooth"
    },
    {
      "x": -20,
      "y": 5,
      "z": -3,
      "name": "Rock_Shale_Brick_Pillar_Base"
    },
    {
      "x": -20,
      "y": 6,
      "z": -3,
      "name": "Rock_Shale_Brick_Pillar_Middle"
    },
    {
      "x": -20,
      "y": 7,
      "z": -3,
      "name": "Rock_Shale_Brick_Pillar_Middle"
    },
    {
      "x": -20,
      "y": 8,
      "z": -3,
      "name": "Rock_Shale_Brick_Pillar_Middle"
    },
    {
      "x": -20,
      "y": 9,
      "z": -3,
      "name": "Rock_Shale_Brick_Pillar_Base",
      "rotation": 8
    },
    {
      "x": -20,
      "y": 10,
      "z": -3,
      "name": "Rock_Shale_Brick_Smooth"
    },
    {
      "x": -20,
      "y": 11,
      "z": -3,
      "name": "Rock_Shale_Brick_Pillar_Base"
    },
    {
      "x": -20,
      "y": 12,
      "z": -3,
      "name": "Rock_Shale_Brick_Pillar_Middle"
    },
    {
      "x": -20,
      "y": 13,
      "z": -3,
      "name": "Rock_Shale_Brick_Pillar_Middle"
    },
    {
      "x": -20,
      "y": 14,
      "z": -3,
      "name": "Rock_Shale_Brick_Pillar_Middle"
    },
    {
      "x": -20,
      "y": 15,
      "z": -3,
      "name": "Rock_Shale_Brick_Pillar_Base",
      "rotation": 34
    },
    {
      "x": -20,
      "y": 16,
      "z": -3,
      "name": "Rock_Shale_Brick_Smooth"
    },
    {
      "x": -20,
      "y": 17,
      "z": -3,
      "name": "Rock_Shale_Brick_Pillar_Base"
    },
    {
      "x": -20,
      "y": 18,
      "z": -3,
      "name": "Rock_Shale_Brick_Pillar_Middle"
    },
    {
      "x": -20,
      "y": 19,
      "z": -3,
      "name": "Rock_Shale_Brick_Pillar_Middle"
    },
    {
      "x": -20,
      "y": 20,
      "z": -3,
      "name": "Rock_Shale_Brick_Pillar_Middle"
    },
    {
      "x": -20,
      "y": 21,
      "z": -3,
      "name": "Rock_Shale_Brick_Pillar_Base",
      "rotation": 8
    },
    {
      "x": -20,
      "y": 4,
      "z": -2,
      "name": "Rock_Shale_Cobble"
    },
    {
      "x": -20,
      "y": 10,
      "z": -2,
      "name": "Rock_Shale_Cobble"
    },
    {
      "x": -20,
      "y": 16,
      "z": -2,
      "name": "Rock_Shale_Cobble"
    },
    {
      "x": -20,
      "y": 4,
      "z": -1,
      "name": "Rock_Shale_Cobble"
    },
    {
      "x": -20,
      "y": 10,
      "z": -1,
      "name": "Rock_Shale_Cobble"
    },
    {
      "x": -20,
      "y": 16,
      "z": -1,
      "name": "Rock_Shale_Cobble"
    },
    {
      "x": -20,
      "y": 4,
      "z": 0,
      "name": "Rock_Shale_Cobble",
      "rotation": 1
    },
    {
      "x": -20,
      "y": 5,
      "z": 0,
      "name": "Rock_Shale_Brick_Pillar_Base",
      "rotation": 1
    },
    {
      "x": -20,
      "y": 6,
      "z": 0,
      "name": "Rock_Shale_Brick_Pillar_Middle",
      "rotation": 1
    },
    {
      "x": -20,
      "y": 7,
      "z": 0,
      "name": "Rock_Shale_Brick_Pillar_Middle",
      "rotation": 1
    },
    {
      "x": -20,
      "y": 8,
      "z": 0,
      "name": "Rock_Shale_Brick_Pillar_Middle",
      "rotation": 1
    },
    {
      "x": -20,
      "y": 9,
      "z": 0,
      "name": "Rock_Shale_Brick_Pillar_Base",
      "rotation": 9
    },
    {
      "x": -20,
      "y": 10,
      "z": 0,
      "name": "Rock_Shale_Cobble",
      "rotation": 1
    },
    {
      "x": -20,
      "y": 11,
      "z": 0,
      "name": "Rock_Shale_Brick_Pillar_Base",
      "rotation": 1
    },
    {
      "x": -20,
      "y": 12,
      "z": 0,
      "name": "Rock_Shale_Brick_Pillar_Middle",
      "rotation": 1
    },
    {
      "x": -20,
      "y": 13,
      "z": 0,
      "name": "Rock_Shale_Brick_Pillar_Middle",
      "rotation": 1
    },
    {
      "x": -20,
      "y": 14,
      "z": 0,
      "name": "Rock_Shale_Brick_Pillar_Middle",
      "rotation": 1
    },
    {
      "x": -20,
      "y": 15,
      "z": 0,
      "name": "Rock_Shale_Brick_Pillar_Base",
      "rotation": 35
    },
    {
      "x": -20,
      "y": 16,
      "z": 0,
      "name": "Rock_Shale_Cobble",
      "rotation": 1
    },
    {
      "x": -20,
      "y": 17,
      "z": 0,
      "name": "Rock_Shale_Brick_Pillar_Base",
      "rotation": 1
    },
    {
      "x": -20,
      "y": 18,
      "z": 0,
      "name": "Rock_Shale_Brick_Pillar_Middle",
      "rotation": 1
    },
    {
      "x": -20,
      "y": 19,
      "z": 0,
      "name": "Rock_Shale_Brick_Pillar_Middle",
      "rotation": 1
    },
    {
      "x": -20,
      "y": 20,
      "z": 0,
      "name": "Rock_Shale_Brick_Pillar_Middle",
      "rotation": 1
    },
    {
      "x": -20,
      "y": 21,
      "z": 0,
      "name": "Rock_Shale_Brick_Pillar_Base",
      "rotation": 9
    },
    {
      "x": -20,
      "y": 4,
      "z": 1,
      "name": "Rock_Shale_Cobble",
      "rotation": 1
    },
    {
      "x": -20,
      "y": 10,
      "z": 1,
      "name": "Rock_Shale_Cobble",
      "rotation": 1
    },
    {
      "x": -20,
      "y": 16,
      "z": 1,
      "name": "Rock_Shale_Cobble",
      "rotation": 1
    },
    {
      "x": -20,
      "y": 4,
      "z": 2,
      "name": "Rock_Shale_Cobble",
      "rotation": 1
    },
    {
      "x": -20,
      "y": 5,
      "z": 2,
      "name": "Rubble_Shale_Medium"
    },
    {
      "x": -20,
      "y": 10,
      "z": 2,
      "name": "Rock_Shale_Cobble",
      "rotation": 1
    },
    {
      "x": -20,
      "y": 11,
      "z": 2,
      "name": "Furniture_SK_Monument_Chest_Small",
      "components": {
        "Components": {
          "ItemContainerBlock": {
            "ItemContainer": {
              "Capacity": 18,
              "Items": {
                "14": {
                  "Id": "Plant_Seeds_Wheat",
                  "Quantity": 2,
                  "Durability": 0.0,
                  "MaxDurability": 0.0,
                  "OverrideDroppedItemAnimation": false
                },
                "1": {
                  "Id": "Ingredient_Hide_Light",
                  "Quantity": 3,
                  "Durability": 0.0,
                  "MaxDurability": 0.0,
                  "OverrideDroppedItemAnimation": false
                },
                "3": {
                  "Id": "Ore_Cobalt",
                  "Quantity": 3,
                  "Durability": 0.0,
                  "MaxDurability": 0.0,
                  "OverrideDroppedItemAnimation": false
                },
                "2": {
                  "Id": "Wood_Birch_Trunk",
                  "Quantity": 9,
                  "Durability": 0.0,
                  "MaxDurability": 0.0,
                  "OverrideDroppedItemAnimation": false
                },
                "7": {
                  "Id": "Plant_Fruit_Apple",
                  "Quantity": 4,
                  "Durability": 0.0,
                  "MaxDurability": 0.0,
                  "OverrideDroppedItemAnimation": false
                },
                "9": {
                  "Id": "Ore_Copper",
                  "Quantity": 3,
                  "Durability": 0.0,
                  "MaxDurability": 0.0,
                  "OverrideDroppedItemAnimation": false
                }
              }
            },
            "Capacity": 20
          }
        }
      },
      "rotation": 1
    },
    {
      "x": -20,
      "y": 14,
      "z": 2,
      "name": "Deco_SpiderWeb_Full",
      "rotation": 2
    },
    {
      "x": -20,
      "y": 16,
      "z": 2,
      "name": "Rock_Shale_Cobble",
      "rotation": 1
    },
    {
      "x": -20,
      "y": 17,
      "z": 2,
      "name": "Rubble_Shale_Medium"
    },
    {
      "x": -20,
      "y": 4,
      "z": 3,
      "name": "Rock_Shale_Brick_Smooth",
      "rotation": 1
    },
    {
      "x": -20,
      "y": 5,
      "z": 3,
      "name": "Rock_Shale_Brick_Pillar_Base",
      "rotation": 1
    },
    {
      "x": -20,
      "y": 6,
      "z": 3,
      "name": "Rock_Shale_Brick_Pillar_Middle",
      "rotation": 1
    },
    {
      "x": -20,
      "y": 7,
      "z": 3,
      "name": "Rock_Shale_Brick_Pillar_Middle",
      "rotation": 1
    },
    {
      "x": -20,
      "y": 8,
      "z": 3,
      "name": "Rock_Shale_Brick_Pillar_Middle",
      "rotation": 1
    },
    {
      "x": -20,
      "y": 9,
      "z": 3,
      "name": "Rock_Shale_Brick_Pillar_Base",
      "rotation": 9
    },
    {
      "x": -20,
      "y": 10,
      "z": 3,
      "name": "Rock_Shale_Brick_Smooth",
      "rotation": 1
    },
    {
      "x": -20,
      "y": 11,
      "z": 3,
      "name": "Rock_Shale_Brick_Pillar_Base",
      "rotation": 1
    },
    {
      "x": -20,
      "y": 12,
      "z": 3,
      "name": "Rock_Shale_Brick_Pillar_Middle",
      "rotation": 1
    },
    {
      "x": -20,
      "y": 13,
      "z": 3,
      "name": "Rock_Shale_Brick_Pillar_Middle",
      "rotation": 1
    },
    {
      "x": -20,
      "y": 14,
      "z": 3,
      "name": "Rock_Shale_Brick_Pillar_Middle",
      "rotation": 1
    },
    {
      "x": -20,
      "y": 15,
      "z": 3,
      "name": "Rock_Shale_Brick_Pillar_Base",
      "rotation": 35
    },
    {
      "x": -20,
      "y": 16,
      "z": 3,
      "name": "Rock_Shale_Brick_Smooth",
      "rotation": 1
    },
    {
      "x": -20,
      "y": 17,
      "z": 3,
      "name": "Rock_Shale_Brick_Pillar_Base",
      "rotation": 1
    },
    {
      "x": -20,
      "y": 18,
      "z": 3,
      "name": "Rock_Shale_Brick_Pillar_Middle",
      "rotation": 1
    },
    {
      "x": -20,
      "y": 19,
      "z": 3,
      "name": "Rock_Shale_Brick_Pillar_Middle",
      "rotation": 1
    },
    {
      "x": -20,
      "y": 20,
      "z": 3,
      "name": "Rock_Shale_Brick_Pillar_Middle",
      "rotation": 1
    },
    {
      "x": -20,
      "y": 21,
      "z": 3,
      "name": "Rock_Shale_Brick_Pillar_Base",
      "rotation": 9
    },
    {
      "x": -20,
      "y": 4,
      "z": 4,
      "name": "Rock_Shale_Cobble",
      "rotation": 1
    },
    {
      "x": -20,
      "y": 5,
      "z": 4,
      "name": "Plant_Moss_Rug_Green_Dark"
    },
    {
      "x": -20,
      "y": 10,
      "z": 4,
      "name": "Rock_Shale_Cobble",
      "rotation": 1
    },
    {
      "x": -20,
      "y": 16,
      "z": 4,
      "name": "Rock_Shale_Cobble",
      "rotation": 1
    },
    {
      "x": -20,
      "y": 17,
      "z": 4,
      "name": "Plant_Moss_Rug_Green_Dark"
    },
    {
      "x": -20,
      "y": 4,
      "z": 5,
      "name": "Rock_Shale_Cobble",
      "rotation": 1
    },
    {
      "x": -20,
      "y": 5,
      "z": 5,
      "name": "Rock_Shale_Brick_Smooth",
      "rotation": 1
    },
    {
      "x": -20,
      "y": 6,
      "z": 5,
      "name": "Rock_Shale_Brick_Smooth",
      "rotation": 1
    },
    {
      "x": -20,
      "y": 7,
      "z": 5,
      "name": "Rock_Shale_Brick_Smooth",
      "rotation": 1
    },
    {
      "x": -20,
      "y": 8,
      "z": 5,
      "name": "Rock_Shale_Brick_Smooth",
      "rotation": 1
    },
    {
      "x": -20,
      "y": 9,
      "z": 5,
      "name": "Rock_Shale_Brick_Ornate",
      "rotation": 1
    },
    {
      "x": -20,
      "y": 10,
      "z": 5,
      "name": "Rock_Shale_Cobble",
      "rotation": 1
    },
    {
      "x": -20,
      "y": 11,
      "z": 5,
      "name": "Rock_Shale_Brick_Smooth",
      "rotation": 1
    },
    {
      "x": -20,
      "y": 12,
      "z": 5,
      "name": "Rock_Shale_Brick_Smooth",
      "rotation": 1
    },
    {
      "x": -20,
      "y": 13,
      "z": 5,
      "name": "Rock_Shale_Brick_Smooth",
      "rotation": 1
    },
    {
      "x": -20,
      "y": 14,
      "z": 5,
      "name": "Rock_Shale_Brick_Smooth",
      "rotation": 1
    },
    {
      "x": -20,
      "y": 15,
      "z": 5,
      "name": "Rock_Shale_Brick_Ornate",
      "rotation": 1
    },
    {
      "x": -20,
      "y": 16,
      "z": 5,
      "name": "Rock_Shale_Cobble",
      "rotation": 1
    },
    {
      "x": -20,
      "y": 17,
      "z": 5,
      "name": "Rock_Shale_Brick_Smooth",
      "rotation": 1
    },
    {
      "x": -20,
      "y": 18,
      "z": 5,
      "name": "Rock_Shale_Brick_Smooth",
      "rotation": 1
    },
    {
      "x": -20,
      "y": 19,
      "z": 5,
      "name": "Rock_Shale_Brick_Smooth",
      "rotation": 1
    },
    {
      "x": -20,
      "y": 20,
      "z": 5,
      "name": "Rock_Shale_Brick_Smooth",
      "rotation": 1
    },
    {
      "x": -20,
      "y": 21,
      "z": 5,
      "name": "Rock_Shale_Brick_Ornate",
      "rotation": 1
    },
    {
      "x": -20,
      "y": 4,
      "z": 6,
      "name": "Rock_Shale_Cobble",
      "rotation": 1
    },
    {
      "x": -20,
      "y": 5,
      "z": 6,
      "name": "Rock_Shale_Brick",
      "rotation": 2
    },
    {
      "x": -20,
      "y": 6,
      "z": 6,
      "name": "Rock_Shale_Brick",
      "rotation": 2
    },
    {
      "x": -20,
      "y": 7,
      "z": 6,
      "name": "Rock_Shale_Brick",
      "rotation": 2
    },
    {
      "x": -20,
      "y": 8,
      "z": 6,
      "name": "Rock_Shale_Brick",
      "rotation": 2
    },
    {
      "x": -20,
      "y": 9,
      "z": 6,
      "name": "Rock_Shale_Brick_Ornate"
    },
    {
      "x": -20,
      "y": 10,
      "z": 6,
      "name": "Rock_Shale_Cobble",
      "rotation": 1
    },
    {
      "x": -20,
      "y": 11,
      "z": 6,
      "name": "Rock_Shale_Brick",
      "rotation": 2
    },
    {
      "x": -20,
      "y": 12,
      "z": 6,
      "name": "Rock_Shale_Brick",
      "rotation": 2
    },
    {
      "x": -20,
      "y": 13,
      "z": 6,
      "name": "Rock_Shale_Brick",
      "rotation": 2
    },
    {
      "x": -20,
      "y": 14,
      "z": 6,
      "name": "Rock_Shale_Brick",
      "rotation": 2
    },
    {
      "x": -20,
      "y": 15,
      "z": 6,
      "name": "Rock_Shale_Brick_Ornate"
    },
    {
      "x": -20,
      "y": 16,
      "z": 6,
      "name": "Rock_Shale_Cobble",
      "rotation": 1
    },
    {
      "x": -20,
      "y": 17,
      "z": 6,
      "name": "Rock_Shale_Brick",
      "rotation": 2
    },
    {
      "x": -20,
      "y": 18,
      "z": 6,
      "name": "Rock_Shale_Brick",
      "rotation": 2
    },
    {
      "x": -20,
      "y": 19,
      "z": 6,
      "name": "Rock_Shale_Brick",
      "rotation": 2
    },
    {
      "x": -20,
      "y": 20,
      "z": 6,
      "name": "Rock_Shale_Brick",
      "rotation": 2
    },
    {
      "x": -20,
      "y": 21,
      "z": 6,
      "name": "Rock_Shale_Brick_Ornate"
    },
    {
      "x": -20,
      "y": 4,
      "z": 7,
      "name": "Rock_Shale_Cobble",
      "rotation": 1
    },
    {
      "x": -20,
      "y": 5,
      "z": 7,
      "name": "Rock_Shale_Brick_Smooth",
      "rotation": 1
    },
    {
      "x": -20,
      "y": 6,
      "z": 7,
      "name": "Rock_Shale_Brick_Smooth",
      "rotation": 1
    },
    {
      "x": -20,
      "y": 7,
      "z": 7,
      "name": "Rock_Shale_Brick_Smooth",
      "rotation": 1
    },
    {
      "x": -20,
      "y": 8,
      "z": 7,
      "name": "Rock_Shale_Brick_Smooth",
      "rotation": 1
    },
    {
      "x": -20,
      "y": 9,
      "z": 7,
      "name": "Rock_Shale_Brick_Ornate",
      "rotation": 1
    },
    {
      "x": -20,
      "y": 10,
      "z": 7,
      "name": "Rock_Shale_Cobble",
      "rotation": 1
    },
    {
      "x": -20,
      "y": 11,
      "z": 7,
      "name": "Rock_Shale_Brick_Smooth",
      "rotation": 1
    },
    {
      "x": -20,
      "y": 12,
      "z": 7,
      "name": "Rock_Shale_Brick_Smooth",
      "rotation": 1
    },
    {
      "x": -20,
      "y": 13,
      "z": 7,
      "name": "Rock_Shale_Brick_Smooth",
      "rotation": 1
    },
    {
      "x": -20,
      "y": 14,
      "z": 7,
      "name": "Rock_Shale_Brick_Smooth",
      "rotation": 1
    },
    {
      "x": -20,
      "y": 15,
      "z": 7,
      "name": "Rock_Shale_Brick_Ornate",
      "rotation": 1
    },
    {
      "x": -20,
      "y": 16,
      "z": 7,
      "name": "Rock_Shale_Cobble",
      "rotation": 1
    },
    {
      "x": -20,
      "y": 17,
      "z": 7,
      "name": "Rock_Shale_Brick_Smooth",
      "rotation": 1
    },
    {
      "x": -20,
      "y": 18,
      "z": 7,
      "name": "Rock_Shale_Brick_Smooth",
      "rotation": 1
    },
    {
      "x": -20,
      "y": 19,
      "z": 7,
      "name": "Rock_Shale_Brick_Smooth",
      "rotation": 1
    },
    {
      "x": -20,
      "y": 20,
      "z": 7,
      "name": "Rock_Shale_Brick_Smooth",
      "rotation": 1
    },
    {
      "x": -20,
      "y": 21,
      "z": 7,
      "name": "Rock_Shale_Brick_Ornate",
      "rotation": 1
    },
    {
      "x": -19,
      "y": 4,
      "z": -18,
      "name": "Rock_Shale_Cobble",
      "rotation": 2
    },
    {
      "x": -19,
      "y": 5,
      "z": -18,
      "name": "Rock_Shale_Brick",
      "rotation": 1
    },
    {
      "x": -19,
      "y": 6,
      "z": -18,
      "name": "Rock_Shale_Brick",
      "rotation": 1
    },
    {
      "x": -19,
      "y": 7,
      "z": -18,
      "name": "Rock_Shale_Brick",
      "rotation": 1
    },
    {
      "x": -19,
      "y": 8,
      "z": -18,
      "name": "Rock_Shale_Brick",
      "rotation": 1
    },
    {
      "x": -19,
      "y": 9,
      "z": -18,
      "name": "Rock_Shale_Brick_Ornate",
      "rotation": 3
    },
    {
      "x": -19,
      "y": 10,
      "z": -18,
      "name": "Rock_Shale_Cobble",
      "rotation": 2
    },
    {
      "x": -19,
      "y": 11,
      "z": -18,
      "name": "Rock_Shale_Brick",
      "rotation": 1
    },
    {
      "x": -19,
      "y": 12,
      "z": -18,
      "name": "Rock_Shale_Brick",
      "rotation": 1
    },
    {
      "x": -19,
      "y": 13,
      "z": -18,
      "name": "Rock_Shale_Brick",
      "rotation": 1
    },
    {
      "x": -19,
      "y": 14,
      "z": -18,
      "name": "Rock_Shale_Brick",
      "rotation": 1
    },
    {
      "x": -19,
      "y": 15,
      "z": -18,
      "name": "Rock_Shale_Brick_Ornate",
      "rotation": 3
    },
    {
      "x": -19,
      "y": 16,
      "z": -18,
      "name": "Rock_Shale_Cobble",
      "rotation": 2
    },
    {
      "x": -19,
      "y": 17,
      "z": -18,
      "name": "Rock_Shale_Brick",
      "rotation": 1
    },
    {
      "x": -19,
      "y": 18,
      "z": -18,
      "name": "Rock_Shale_Brick",
      "rotation": 1
    },
    {
      "x": -19,
      "y": 19,
      "z": -18,
      "name": "Rock_Shale_Brick",
      "rotation": 1
    },
    {
      "x": -19,
      "y": 20,
      "z": -18,
      "name": "Rock_Shale_Brick",
      "rotation": 1
    },
    {
      "x": -19,
      "y": 21,
      "z": -18,
      "name": "Rock_Shale_Brick_Ornate",
      "rotation": 3
    },
    {
      "x": -19,
      "y": 4,
      "z": -17,
      "name": "Rock_Shale_Cobble",
      "rotation": 2
    },
    {
      "x": -19,
      "y": 5,
      "z": -17,
      "name": "Rock_Shale_Brick",
      "rotation": 1
    },
    {
      "x": -19,
      "y": 6,
      "z": -17,
      "name": "Rock_Shale_Brick",
      "rotation": 1
    },
    {
      "x": -19,
      "y": 7,
      "z": -17,
      "name": "Rock_Shale_Brick",
      "rotation": 1
    },
    {
      "x": -19,
      "y": 8,
      "z": -17,
      "name": "Rock_Shale_Brick",
      "rotation": 1
    },
    {
      "x": -19,
      "y": 9,
      "z": -17,
      "name": "Rock_Shale_Brick_Ornate",
      "rotation": 3
    },
    {
      "x": -19,
      "y": 10,
      "z": -17,
      "name": "Rock_Shale_Cobble",
      "rotation": 2
    },
    {
      "x": -19,
      "y": 11,
      "z": -17,
      "name": "Rock_Shale_Brick",
      "rotation": 1
    },
    {
      "x": -19,
      "y": 12,
      "z": -17,
      "name": "Rock_Shale_Brick",
      "rotation": 1
    },
    {
      "x": -19,
      "y": 13,
      "z": -17,
      "name": "Rock_Shale_Brick",
      "rotation": 1
    },
    {
      "x": -19,
      "y": 14,
      "z": -17,
      "name": "Rock_Shale_Brick",
      "rotation": 1
    },
    {
      "x": -19,
      "y": 15,
      "z": -17,
      "name": "Rock_Shale_Brick_Ornate",
      "rotation": 3
    },
    {
      "x": -19,
      "y": 16,
      "z": -17,
      "name": "Rock_Shale_Cobble",
      "rotation": 2
    },
    {
      "x": -19,
      "y": 17,
      "z": -17,
      "name": "Rock_Shale_Brick",
      "rotation": 1
    },
    {
      "x": -19,
      "y": 18,
      "z": -17,
      "name": "Rock_Shale_Brick",
      "rotation": 1
    },
    {
      "x": -19,
      "y": 19,
      "z": -17,
      "name": "Rock_Shale_Brick",
      "rotation": 1
    },
    {
      "x": -19,
      "y": 20,
      "z": -17,
      "name": "Rock_Shale_Brick",
      "rotation": 1
    },
    {
      "x": -19,
      "y": 21,
      "z": -17,
      "name": "Rock_Shale_Brick_Ornate",
      "rotation": 3
    },
    {
      "x": -19,
      "y": 4,
      "z": -16,
      "name": "Rock_Shale_Cobble",
      "rotation": 2
    },
    {
      "x": -19,
      "y": 5,
      "z": -16,
      "name": "Rock_Shale_Brick",
      "rotation": 1
    },
    {
      "x": -19,
      "y": 6,
      "z": -16,
      "name": "Rock_Shale_Brick",
      "rotation": 1
    },
    {
      "x": -19,
      "y": 7,
      "z": -16,
      "name": "Rock_Shale_Brick",
      "rotation": 1
    },
    {
      "x": -19,
      "y": 8,
      "z": -16,
      "name": "Rock_Shale_Brick",
      "rotation": 1
    },
    {
      "x": -19,
      "y": 9,
      "z": -16,
      "name": "Rock_Shale_Brick_Ornate",
      "rotation": 3
    },
    {
      "x": -19,
      "y": 10,
      "z": -16,
      "name": "Rock_Shale_Cobble",
      "rotation": 2
    },
    {
      "x": -19,
      "y": 11,
      "z": -16,
      "name": "Rock_Shale_Brick",
      "rotation": 1
    },
    {
      "x": -19,
      "y": 12,
      "z": -16,
      "name": "Rock_Shale_Brick",
      "rotation": 1
    },
    {
      "x": -19,
      "y": 13,
      "z": -16,
      "name": "Rock_Shale_Brick",
      "rotation": 1
    },
    {
      "x": -19,
      "y": 14,
      "z": -16,
      "name": "Rock_Shale_Brick",
      "rotation": 1
    },
    {
      "x": -19,
      "y": 15,
      "z": -16,
      "name": "Rock_Shale_Brick_Ornate",
      "rotation": 3
    },
    {
      "x": -19,
      "y": 16,
      "z": -16,
      "name": "Rock_Shale_Cobble",
      "rotation": 2
    },
    {
      "x": -19,
      "y": 17,
      "z": -16,
      "name": "Rock_Shale_Brick",
      "rotation": 1
    },
    {
      "x": -19,
      "y": 18,
      "z": -16,
      "name": "Rock_Shale_Brick",
      "rotation": 1
    },
    {
      "x": -19,
      "y": 19,
      "z": -16,
      "name": "Rock_Shale_Brick",
      "rotation": 1
    },
    {
      "x": -19,
      "y": 20,
      "z": -16,
      "name": "Rock_Shale_Brick",
      "rotation": 1
    },
    {
      "x": -19,
      "y": 21,
      "z": -16,
      "name": "Rock_Shale_Brick_Ornate",
      "rotation": 3
    },
    {
      "x": -19,
      "y": 4,
      "z": -15,
      "name": "Rock_Shale_Cobble",
      "rotation": 2
    },
    {
      "x": -19,
      "y": 5,
      "z": -15,
      "name": "Rock_Shale_Brick",
      "rotation": 1
    },
    {
      "x": -19,
      "y": 6,
      "z": -15,
      "name": "Rock_Shale_Brick",
      "rotation": 1
    },
    {
      "x": -19,
      "y": 7,
      "z": -15,
      "name": "Rock_Shale_Brick",
      "rotation": 1
    },
    {
      "x": -19,
      "y": 8,
      "z": -15,
      "name": "Rock_Shale_Brick",
      "rotation": 1
    },
    {
      "x": -19,
      "y": 9,
      "z": -15,
      "name": "Rock_Shale_Brick_Ornate",
      "rotation": 3
    },
    {
      "x": -19,
      "y": 10,
      "z": -15,
      "name": "Rock_Shale_Cobble",
      "rotation": 2
    },
    {
      "x": -19,
      "y": 11,
      "z": -15,
      "name": "Rock_Shale_Brick",
      "rotation": 1
    },
    {
      "x": -19,
      "y": 12,
      "z": -15,
      "name": "Rock_Shale_Brick",
      "rotation": 1
    },
    {
      "x": -19,
      "y": 13,
      "z": -15,
      "name": "Rock_Shale_Brick",
      "rotation": 1
    },
    {
      "x": -19,
      "y": 14,
      "z": -15,
      "name": "Rock_Shale_Brick",
      "rotation": 1
    },
    {
      "x": -19,
      "y": 15,
      "z": -15,
      "name": "Rock_Shale_Brick_Ornate",
      "rotation": 3
    },
    {
      "x": -19,
      "y": 16,
      "z": -15,
      "name": "Rock_Shale_Cobble",
      "rotation": 2
    },
    {
      "x": -19,
      "y": 17,
      "z": -15,
      "name": "Rock_Shale_Brick",
      "rotation": 1
    },
    {
      "x": -19,
      "y": 18,
      "z": -15,
      "name": "Rock_Shale_Brick",
      "rotation": 1
    },
    {
      "x": -19,
      "y": 19,
      "z": -15,
      "name": "Rock_Shale_Brick",
      "rotation": 1
    },
    {
      "x": -19,
      "y": 20,
      "z": -15,
      "name": "Rock_Shale_Brick",
      "rotation": 1
    },
    {
      "x": -19,
      "y": 21,
      "z": -15,
      "name": "Rock_Shale_Brick_Ornate",
      "rotation": 3
    },
    {
      "x": -19,
      "y": 4,
      "z": -9,
      "name": "Rock_Shale_Cobble"
    },
    {
      "x": -19,
      "y": 5,
      "z": -9,
      "name": "Rock_Shale_Brick_Smooth"
    },
    {
      "x": -19,
      "y": 6,
      "z": -9,
      "name": "Rock_Shale_Brick_Smooth"
    },
    {
      "x": -19,
      "y": 7,
      "z": -9,
      "name": "Rock_Shale_Brick_Smooth"
    },
    {
      "x": -19,
      "y": 8,
      "z": -9,
      "name": "Rock_Shale_Brick_Smooth"
    },
    {
      "x": -19,
      "y": 9,
      "z": -9,
      "name": "Rock_Shale_Brick_Ornate"
    },
    {
      "x": -19,
      "y": 10,
      "z": -9,
      "name": "Rock_Shale_Cobble"
    },
    {
      "x": -19,
      "y": 11,
      "z": -9,
      "name": "Rock_Shale_Brick_Smooth"
    },
    {
      "x": -19,
      "y": 12,
      "z": -9,
      "name": "Rock_Shale_Brick_Smooth"
    },
    {
      "x": -19,
      "y": 13,
      "z": -9,
      "name": "Rock_Shale_Brick_Smooth"
    },
    {
      "x": -19,
      "y": 14,
      "z": -9,
      "name": "Rock_Shale_Brick_Smooth"
    },
    {
      "x": -19,
      "y": 15,
      "z": -9,
      "name": "Rock_Shale_Brick_Ornate"
    },
    {
      "x": -19,
      "y": 16,
      "z": -9,
      "name": "Rock_Shale_Cobble"
    },
    {
      "x": -19,
      "y": 17,
      "z": -9,
      "name": "Rock_Shale_Brick_Smooth"
    },
    {
      "x": -19,
      "y": 18,
      "z": -9,
      "name": "Rock_Shale_Brick_Smooth"
    },
    {
      "x": -19,
      "y": 19,
      "z": -9,
      "name": "Rock_Shale_Brick_Smooth"
    },
    {
      "x": -19,
      "y": 20,
      "z": -9,
      "name": "Rock_Shale_Brick_Smooth"
    },
    {
      "x": -19,
      "y": 21,
      "z": -9,
      "name": "Rock_Shale_Brick_Ornate"
    },
    {
      "x": -19,
      "y": 4,
      "z": -8,
      "name": "Rock_Shale_Cobble"
    },
    {
      "x": -19,
      "y": 5,
      "z": -8,
      "name": "Rock_Shale_Brick",
      "rotation": 1
    },
    {
      "x": -19,
      "y": 6,
      "z": -8,
      "name": "Rock_Shale_Brick",
      "rotation": 1
    },
    {
      "x": -19,
      "y": 7,
      "z": -8,
      "name": "Rock_Shale_Brick",
      "rotation": 1
    },
    {
      "x": -19,
      "y": 8,
      "z": -8,
      "name": "Rock_Shale_Brick",
      "rotation": 1
    },
    {
      "x": -19,
      "y": 9,
      "z": -8,
      "name": "Rock_Shale_Brick_Ornate",
      "rotation": 3
    },
    {
      "x": -19,
      "y": 10,
      "z": -8,
      "name": "Rock_Shale_Cobble"
    },
    {
      "x": -19,
      "y": 11,
      "z": -8,
      "name": "Rock_Shale_Brick",
      "rotation": 1
    },
    {
      "x": -19,
      "y": 12,
      "z": -8,
      "name": "Rock_Shale_Brick",
      "rotation": 1
    },
    {
      "x": -19,
      "y": 13,
      "z": -8,
      "name": "Rock_Shale_Brick",
      "rotation": 1
    },
    {
      "x": -19,
      "y": 14,
      "z": -8,
      "name": "Rock_Shale_Brick",
      "rotation": 1
    },
    {
      "x": -19,
      "y": 15,
      "z": -8,
      "name": "Rock_Shale_Brick_Ornate",
      "rotation": 3
    },
    {
      "x": -19,
      "y": 16,
      "z": -8,
      "name": "Rock_Shale_Cobble"
    },
    {
      "x": -19,
      "y": 17,
      "z": -8,
      "name": "Rock_Shale_Brick",
      "rotation": 1
    },
    {
      "x": -19,
      "y": 18,
      "z": -8,
      "name": "Rock_Shale_Brick",
      "rotation": 1
    },
    {
      "x": -19,
      "y": 19,
      "z": -8,
      "name": "Rock_Shale_Brick",
      "rotation": 1
    },
    {
      "x": -19,
      "y": 20,
      "z": -8,
      "name": "Rock_Shale_Brick",
      "rotation": 1
    },
    {
      "x": -19,
      "y": 21,
      "z": -8,
      "name": "Rock_Shale_Brick_Ornate",
      "rotation": 3
    },
    {
      "x": -19,
      "y": 4,
      "z": -7,
      "name": "Rock_Shale_Cobble"
    },
    {
      "x": -19,
      "y": 5,
      "z": -7,
      "name": "Rubble_Shale"
    },
    {
      "x": -19,
      "y": 8,
      "z": -7,
      "name": "Deco_SpiderWeb_Full"
    },
    {
      "x": -19,
      "y": 9,
      "z": -7,
      "name": "Deco_SpiderWeb_Full"
    },
    {
      "x": -19,
      "y": 10,
      "z": -7,
      "name": "Rock_Shale_Cobble"
    },
    {
      "x": -19,
      "y": 16,
      "z": -7,
      "name": "Rock_Shale_Cobble"
    },
    {
      "x": -19,
      "y": 17,
      "z": -7,
      "name": "Rubble_Shale"
    },
    {
      "x": -19,
      "y": 20,
      "z": -7,
      "name": "Deco_SpiderWeb_Full"
    },
    {
      "x": -19,
      "y": 21,
      "z": -7,
      "name": "Deco_SpiderWeb_Full"
    },
    {
      "x": -19,
      "y": 4,
      "z": -6,
      "name": "Rock_Shale_Cobble"
    },
    {
      "x": -19,
      "y": 10,
      "z": -6,
      "name": "Rock_Shale_Cobble"
    },
    {
      "x": -19,
      "y": 16,
      "z": -6,
      "name": "Rock_Shale_Cobble"
    },
    {
      "x": -19,
      "y": 4,
      "z": -5,
      "name": "Rock_Shale_Cobble"
    },
    {
      "x": -19,
      "y": 10,
      "z": -5,
      "name": "Rock_Shale_Cobble"
    },
    {
      "x": -19,
      "y": 16,
      "z": -5,
      "name": "Rock_Shale_Cobble"
    },
    {
      "x": -19,
      "y": 4,
      "z": -4,
      "name": "Rock_Shale_Cobble"
    },
    {
      "x": -19,
      "y": 10,
      "z": -4,
      "name": "Rock_Shale_Cobble"
    },
    {
      "x": -19,
      "y": 11,
      "z": -4,
      "name": "Rubble_Shale_Medium",
      "rotation": 2
    },
    {
      "x": -19,
      "y": 16,
      "z": -4,
      "name": "Rock_Shale_Cobble"
    },
    {
      "x": -19,
      "y": 4,
      "z": -3,
      "name": "Rock_Shale_Brick_Smooth"
    },
    {
      "x": -19,
      "y": 10,
      "z": -3,
      "name": "Rock_Shale_Brick_Smooth"
    },
    {
      "x": -19,
      "y": 16,
      "z": -3,
      "name": "Rock_Shale_Brick_Smooth"
    },
    {
      "x": -19,
      "y": 4,
      "z": -2,
      "name": "Rock_Shale_Cobble"
    },
    {
      "x": -19,
      "y": 10,
      "z": -2,
      "name": "Rock_Shale_Cobble"
    },
    {
      "x": -19,
      "y": 16,
      "z": -2,
      "name": "Rock_Shale_Cobble"
    },
    {
      "x": -19,
      "y": 4,
      "z": -1,
      "name": "Rock_Shale_Cobble"
    },
    {
      "x": -19,
      "y": 10,
      "z": -1,
      "name": "Rock_Shale_Cobble"
    },
    {
      "x": -19,
      "y": 16,
      "z": -1,
      "name": "Rock_Shale_Cobble"
    },
    {
      "x": -19,
      "y": 4,
      "z": 0,
      "name": "Rock_Shale_Cobble",
      "rotation": 1
    },
    {
      "x": -19,
      "y": 10,
      "z": 0,
      "name": "Rock_Shale_Cobble",
      "rotation": 1
    },
    {
      "x": -19,
      "y": 16,
      "z": 0,
      "name": "Rock_Shale_Cobble",
      "rotation": 1
    },
    {
      "x": -19,
      "y": 4,
      "z": 1,
      "name": "Rock_Shale_Cobble",
      "rotation": 1
    },
    {
      "x": -19,
      "y": 5,
      "z": 1,
      "name": "Rubble_Shale"
    },
    {
      "x": -19,
      "y": 10,
      "z": 1,
      "name": "Rock_Shale_Cobble",
      "rotation": 1
    },
    {
      "x": -19,
      "y": 16,
      "z": 1,
      "name": "Rock_Shale_Cobble",
      "rotation": 1
    },
    {
      "x": -19,
      "y": 17,
      "z": 1,
      "name": "Rubble_Shale"
    },
    {
      "x": -19,
      "y": 4,
      "z": 2,
      "name": "Rock_Shale_Cobble",
      "rotation": 1
    },
    {
      "x": -19,
      "y": 10,
      "z": 2,
      "name": "Rock_Shale_Cobble",
      "rotation": 1
    },
    {
      "x": -19,
      "y": 16,
      "z": 2,
      "name": "Rock_Shale_Cobble",
      "rotation": 1
    },
    {
      "x": -19,
      "y": 4,
      "z": 3,
      "name": "Rock_Shale_Brick_Smooth",
      "rotation": 1
    },
    {
      "x": -19,
      "y": 10,
      "z": 3,
      "name": "Rock_Shale_Brick_Smooth",
      "rotation": 1
    },
    {
      "x": -19,
      "y": 16,
      "z": 3,
      "name": "Rock_Shale_Brick_Smooth",
      "rotation": 1
    },
    {
      "x": -19,
      "y": 4,
      "z": 4,
      "name": "Rock_Shale_Cobble",
      "rotation": 1
    },
    {
      "x": -19,
      "y": 10,
      "z": 4,
      "name": "Rock_Shale_Cobble",
      "rotation": 1
    },
    {
      "x": -19,
      "y": 16,
      "z": 4,
      "name": "Rock_Shale_Cobble",
      "rotation": 1
    },
    {
      "x": -19,
      "y": 4,
      "z": 5,
      "name": "Rock_Shale_Cobble",
      "rotation": 1
    },
    {
      "x": -19,
      "y": 5,
      "z": 5,
      "name": "Plant_Moss_Rug_Green_Dark"
    },
    {
      "x": -19,
      "y": 10,
      "z": 5,
      "name": "Rock_Shale_Cobble",
      "rotation": 1
    },
    {
      "x": -19,
      "y": 15,
      "z": 5,
      "name": "Plant_Moss_Wall_Green_Dark",
      "rotation": 1
    },
    {
      "x": -19,
      "y": 16,
      "z": 5,
      "name": "Rock_Shale_Cobble",
      "rotation": 1
    },
    {
      "x": -19,
      "y": 17,
      "z": 5,
      "name": "Plant_Moss_Rug_Green_Dark"
    },
    {
      "x": -19,
      "y": 4,
      "z": 6,
      "name": "Rock_Shale_Cobble",
      "rotation": 1
    },
    {
      "x": -19,
      "y": 8,
      "z": 6,
      "name": "Plant_Moss_Wall_Green_Dark",
      "rotation": 1
    },
    {
      "x": -19,
      "y": 9,
      "z": 6,
      "name": "Plant_Moss_Wall_Green_Dark",
      "rotation": 1
    },
    {
      "x": -19,
      "y": 10,
      "z": 6,
      "name": "Rock_Shale_Cobble",
      "rotation": 1
    },
    {
      "x": -19,
      "y": 16,
      "z": 6,
      "name": "Rock_Shale_Cobble",
      "rotation": 1
    },
    {
      "x": -19,
      "y": 20,
      "z": 6,
      "name": "Plant_Moss_Wall_Green_Dark",
      "rotation": 1
    },
    {
      "x": -19,
      "y": 21,
      "z": 6,
      "name": "Plant_Moss_Wall_Green_Dark",
      "rotation": 1
    },
    {
      "x": -19,
      "y": 4,
      "z": 7,
      "name": "Rock_Shale_Cobble",
      "rotation": 1
    },
    {
      "x": -19,
      "y": 5,
      "z": 7,
      "name": "Furniture_Temple_Light_Pot"
    },
    {
      "x": -19,
      "y": 10,
      "z": 7,
      "name": "Rock_Shale_Cobble",
      "rotation": 1
    },
    {
      "x": -19,
      "y": 15,
      "z": 7,
      "name": "Deco_SpiderWeb_Full",
      "rotation": 2
    },
    {
      "x": -19,
      "y": 16,
      "z": 7,
      "name": "Rock_Shale_Cobble",
      "rotation": 1
    },
    {
      "x": -19,
      "y": 17,
      "z": 7,
      "name": "Furniture_Temple_Light_Pot"
    },
    {
      "x": -19,
      "y": 4,
      "z": 8,
      "name": "Rock_Shale_Cobble",
      "rotation": 1
    },
    {
      "x": -19,
      "y": 5,
      "z": 8,
      "name": "Rock_Shale_Brick",
      "rotation": 2
    },
    {
      "x": -19,
      "y": 6,
      "z": 8,
      "name": "Rock_Shale_Brick",
      "rotation": 2
    },
    {
      "x": -19,
      "y": 7,
      "z": 8,
      "name": "Rock_Shale_Brick",
      "rotation": 2
    },
    {
      "x": -19,
      "y": 8,
      "z": 8,
      "name": "Rock_Shale_Brick",
      "rotation": 2
    },
    {
      "x": -19,
      "y": 9,
      "z": 8,
      "name": "Rock_Shale_Brick_Ornate"
    },
    {
      "x": -19,
      "y": 10,
      "z": 8,
      "name": "Rock_Shale_Cobble",
      "rotation": 1
    },
    {
      "x": -19,
      "y": 11,
      "z": 8,
      "name": "Rock_Shale_Brick",
      "rotation": 2
    },
    {
      "x": -19,
      "y": 12,
      "z": 8,
      "name": "Rock_Shale_Brick",
      "rotation": 2
    },
    {
      "x": -19,
      "y": 13,
      "z": 8,
      "name": "Rock_Shale_Brick",
      "rotation": 2
    },
    {
      "x": -19,
      "y": 14,
      "z": 8,
      "name": "Rock_Shale_Brick",
      "rotation": 2
    },
    {
      "x": -19,
      "y": 15,
      "z": 8,
      "name": "Rock_Shale_Brick_Ornate"
    },
    {
      "x": -19,
      "y": 16,
      "z": 8,
      "name": "Rock_Shale_Cobble",
      "rotation": 1
    },
    {
      "x": -19,
      "y": 17,
      "z": 8,
      "name": "Rock_Shale_Brick",
      "rotation": 2
    },
    {
      "x": -19,
      "y": 18,
      "z": 8,
      "name": "Rock_Shale_Brick",
      "rotation": 2
    },
    {
      "x": -19,
      "y": 19,
      "z": 8,
      "name": "Rock_Shale_Brick",
      "rotation": 2
    },
    {
      "x": -19,
      "y": 20,
      "z": 8,
      "name": "Rock_Shale_Brick",
      "rotation": 2
    },
    {
      "x": -19,
      "y": 21,
      "z": 8,
      "name": "Rock_Shale_Brick_Ornate"
    },
    {
      "x": -19,
      "y": 4,
      "z": 9,
      "name": "Rock_Shale_Cobble",
      "rotation": 1
    },
    {
      "x": -19,
      "y": 5,
      "z": 9,
      "name": "Rock_Shale_Brick_Smooth",
      "rotation": 1
    },
    {
      "x": -19,
      "y": 6,
      "z": 9,
      "name": "Rock_Shale_Brick_Smooth",
      "rotation": 1
    },
    {
      "x": -19,
      "y": 7,
      "z": 9,
      "name": "Rock_Shale_Brick_Smooth",
      "rotation": 1
    },
    {
      "x": -19,
      "y": 8,
      "z": 9,
      "name": "Rock_Shale_Brick_Smooth",
      "rotation": 1
    },
    {
      "x": -19,
      "y": 9,
      "z": 9,
      "name": "Rock_Shale_Brick_Ornate",
      "rotation": 1
    },
    {
      "x": -19,
      "y": 10,
      "z": 9,
      "name": "Rock_Shale_Cobble",
      "rotation": 1
    },
    {
      "x": -19,
      "y": 11,
      "z": 9,
      "name": "Rock_Shale_Brick_Smooth",
      "rotation": 1
    },
    {
      "x": -19,
      "y": 12,
      "z": 9,
      "name": "Rock_Shale_Brick_Smooth",
      "rotation": 1
    },
    {
      "x": -19,
      "y": 13,
      "z": 9,
      "name": "Rock_Shale_Brick_Smooth",
      "rotation": 1
    },
    {
      "x": -19,
      "y": 14,
      "z": 9,
      "name": "Rock_Shale_Brick_Smooth",
      "rotation": 1
    },
    {
      "x": -19,
      "y": 15,
      "z": 9,
      "name": "Rock_Shale_Brick_Ornate",
      "rotation": 1
    },
    {
      "x": -19,
      "y": 16,
      "z": 9,
      "name": "Rock_Shale_Cobble",
      "rotation": 1
    },
    {
      "x": -19,
      "y": 17,
      "z": 9,
      "name": "Rock_Shale_Brick_Smooth",
      "rotation": 1
    },
    {
      "x": -19,
      "y": 18,
      "z": 9,
      "name": "Rock_Shale_Brick_Smooth",
      "rotation": 1
    },
    {
      "x": -19,
      "y": 19,
      "z": 9,
      "name": "Rock_Shale_Brick_Smooth",
      "rotation": 1
    },
    {
      "x": -19,
      "y": 20,
      "z": 9,
      "name": "Rock_Shale_Brick_Smooth",
      "rotation": 1
    },
    {
      "x": -19,
      "y": 21,
      "z": 9,
      "name": "Rock_Shale_Brick_Ornate",
      "rotation": 1
    },
    {
      "x": -19,
      "y": 4,
      "z": 15,
      "name": "Rock_Shale_Cobble",
      "rotation": 3
    },
    {
      "x": -19,
      "y": 5,
      "z": 15,
      "name": "Rock_Shale_Brick",
      "rotation": 2
    },
    {
      "x": -19,
      "y": 6,
      "z": 15,
      "name": "Rock_Shale_Brick",
      "rotation": 2
    },
    {
      "x": -19,
      "y": 7,
      "z": 15,
      "name": "Rock_Shale_Brick",
      "rotation": 2
    },
    {
      "x": -19,
      "y": 8,
      "z": 15,
      "name": "Rock_Shale_Brick",
      "rotation": 2
    },
    {
      "x": -19,
      "y": 9,
      "z": 15,
      "name": "Rock_Shale_Brick_Ornate"
    },
    {
      "x": -19,
      "y": 10,
      "z": 15,
      "name": "Rock_Shale_Cobble",
      "rotation": 3
    },
    {
      "x": -19,
      "y": 11,
      "z": 15,
      "name": "Rock_Shale_Brick",
      "rotation": 2
    },
    {
      "x": -19,
      "y": 12,
      "z": 15,
      "name": "Rock_Shale_Brick",
      "rotation": 2
    },
    {
      "x": -19,
      "y": 13,
      "z": 15,
      "name": "Rock_Shale_Brick",
      "rotation": 2
    },
    {
      "x": -19,
      "y": 14,
      "z": 15,
      "name": "Rock_Shale_Brick",
      "rotation": 2
    },
    {
      "x": -19,
      "y": 15,
      "z": 15,
      "name": "Rock_Shale_Brick_Ornate"
    },
    {
      "x": -19,
      "y": 16,
      "z": 15,
      "name": "Rock_Shale_Cobble",
      "rotation": 3
    },
    {
      "x": -19,
      "y": 17,
      "z": 15,
      "name": "Rock_Shale_Brick",
      "rotation": 2
    },
    {
      "x": -19,
      "y": 18,
      "z": 15,
      "name": "Rock_Shale_Brick",
      "rotation": 2
    },
    {
      "x": -19,
      "y": 19,
      "z": 15,
      "name": "Rock_Shale_Brick",
      "rotation": 2
    },
    {
      "x": -19,
      "y": 20,
      "z": 15,
      "name": "Rock_Shale_Brick",
      "rotation": 2
    },
    {
      "x": -19,
      "y": 21,
      "z": 15,
      "name": "Rock_Shale_Brick_Ornate"
    },
    {
      "x": -19,
      "y": 4,
      "z": 16,
      "name": "Rock_Shale_Cobble",
      "rotation": 3
    },
    {
      "x": -19,
      "y": 5,
      "z": 16,
      "name": "Rock_Shale_Brick",
      "rotation": 2
    },
    {
      "x": -19,
      "y": 6,
      "z": 16,
      "name": "Rock_Shale_Brick",
      "rotation": 2
    },
    {
      "x": -19,
      "y": 7,
      "z": 16,
      "name": "Rock_Shale_Brick",
      "rotation": 2
    },
    {
      "x": -19,
      "y": 8,
      "z": 16,
      "name": "Rock_Shale_Brick",
      "rotation": 2
    },
    {
      "x": -19,
      "y": 9,
      "z": 16,
      "name": "Rock_Shale_Brick_Ornate"
    },
    {
      "x": -19,
      "y": 10,
      "z": 16,
      "name": "Rock_Shale_Cobble",
      "rotation": 3
    },
    {
      "x": -19,
      "y": 11,
      "z": 16,
      "name": "Rock_Shale_Brick",
      "rotation": 2
    },
    {
      "x": -19,
      "y": 12,
      "z": 16,
      "name": "Rock_Shale_Brick",
      "rotation": 2
    },
    {
      "x": -19,
      "y": 13,
      "z": 16,
      "name": "Rock_Shale_Brick",
      "rotation": 2
    },
    {
      "x": -19,
      "y": 14,
      "z": 16,
      "name": "Rock_Shale_Brick",
      "rotation": 2
    },
    {
      "x": -19,
      "y": 15,
      "z": 16,
      "name": "Rock_Shale_Brick_Ornate"
    },
    {
      "x": -19,
      "y": 16,
      "z": 16,
      "name": "Rock_Shale_Cobble",
      "rotation": 3
    },
    {
      "x": -19,
      "y": 17,
      "z": 16,
      "name": "Rock_Shale_Brick",
      "rotation": 2
    },
    {
      "x": -19,
      "y": 18,
      "z": 16,
      "name": "Rock_Shale_Brick",
      "rotation": 2
    },
    {
      "x": -19,
      "y": 19,
      "z": 16,
      "name": "Rock_Shale_Brick",
      "rotation": 2
    },
    {
      "x": -19,
      "y": 20,
      "z": 16,
      "name": "Rock_Shale_Brick",
      "rotation": 2
    },
    {
      "x": -19,
      "y": 21,
      "z": 16,
      "name": "Rock_Shale_Brick_Ornate"
    },
    {
      "x": -19,
      "y": 4,
      "z": 17,
      "name": "Rock_Shale_Cobble",
      "rotation": 3
    },
    {
      "x": -19,
      "y": 5,
      "z": 17,
      "name": "Rock_Shale_Brick",
      "rotation": 2
    },
    {
      "x": -19,
      "y": 6,
      "z": 17,
      "name": "Rock_Shale_Brick",
      "rotation": 2
    },
    {
      "x": -19,
      "y": 7,
      "z": 17,
      "name": "Rock_Shale_Brick",
      "rotation": 2
    },
    {
      "x": -19,
      "y": 8,
      "z": 17,
      "name": "Rock_Shale_Brick",
      "rotation": 2
    },
    {
      "x": -19,
      "y": 9,
      "z": 17,
      "name": "Rock_Shale_Brick_Ornate"
    },
    {
      "x": -19,
      "y": 10,
      "z": 17,
      "name": "Rock_Shale_Cobble",
      "rotation": 3
    },
    {
      "x": -19,
      "y": 11,
      "z": 17,
      "name": "Rock_Shale_Brick",
      "rotation": 2
    },
    {
      "x": -19,
      "y": 12,
      "z": 17,
      "name": "Rock_Shale_Brick",
      "rotation": 2
    },
    {
      "x": -19,
      "y": 13,
      "z": 17,
      "name": "Rock_Shale_Brick",
      "rotation": 2
    },
    {
      "x": -19,
      "y": 14,
      "z": 17,
      "name": "Rock_Shale_Brick",
      "rotation": 2
    },
    {
      "x": -19,
      "y": 15,
      "z": 17,
      "name": "Rock_Shale_Brick_Ornate"
    },
    {
      "x": -19,
      "y": 16,
      "z": 17,
      "name": "Rock_Shale_Cobble",
      "rotation": 3
    },
    {
      "x": -19,
      "y": 17,
      "z": 17,
      "name": "Rock_Shale_Brick",
      "rotation": 2
    },
    {
      "x": -19,
      "y": 18,
      "z": 17,
      "name": "Rock_Shale_Brick",
      "rotation": 2
    },
    {
      "x": -19,
      "y": 19,
      "z": 17,
      "name": "Rock_Shale_Brick",
      "rotation": 2
    },
    {
      "x": -19,
      "y": 20,
      "z": 17,
      "name": "Rock_Shale_Brick",
      "rotation": 2
    },
    {
      "x": -19,
      "y": 21,
      "z": 17,
      "name": "Rock_Shale_Brick_Ornate"
    },
    {
      "x": -19,
      "y": 4,
      "z": 18,
      "name": "Rock_Shale_Cobble",
      "rotation": 3
    },
    {
      "x": -19,
      "y": 5,
      "z": 18,
      "name": "Rock_Shale_Brick",
      "rotation": 2
    },
    {
      "x": -19,
      "y": 6,
      "z": 18,
      "name": "Rock_Shale_Brick",
      "rotation": 2
    },
    {
      "x": -19,
      "y": 7,
      "z": 18,
      "name": "Rock_Shale_Brick",
      "rotation": 2
    },
    {
      "x": -19,
      "y": 8,
      "z": 18,
      "name": "Rock_Shale_Brick",
      "rotation": 2
    },
    {
      "x": -19,
      "y": 9,
      "z": 18,
      "name": "Rock_Shale_Brick_Ornate"
    },
    {
      "x": -19,
      "y": 10,
      "z": 18,
      "name": "Rock_Shale_Cobble",
      "rotation": 3
    },
    {
      "x": -19,
      "y": 11,
      "z": 18,
      "name": "Rock_Shale_Brick",
      "rotation": 2
    },
    {
      "x": -19,
      "y": 12,
      "z": 18,
      "name": "Rock_Shale_Brick",
      "rotation": 2
    },
    {
      "x": -19,
      "y": 13,
      "z": 18,
      "name": "Rock_Shale_Brick",
      "rotation": 2
    },
    {
      "x": -19,
      "y": 14,
      "z": 18,
      "name": "Rock_Shale_Brick",
      "rotation": 2
    },
    {
      "x": -19,
      "y": 15,
      "z": 18,
      "name": "Rock_Shale_Brick_Ornate"
    },
    {
      "x": -19,
      "y": 16,
      "z": 18,
      "name": "Rock_Shale_Cobble",
      "rotation": 3
    },
    {
      "x": -19,
      "y": 17,
      "z": 18,
      "name": "Rock_Shale_Brick",
      "rotation": 2
    },
    {
      "x": -19,
      "y": 18,
      "z": 18,
      "name": "Rock_Shale_Brick",
      "rotation": 2
    },
    {
      "x": -19,
      "y": 19,
      "z": 18,
      "name": "Rock_Shale_Brick",
      "rotation": 2
    },
    {
      "x": -19,
      "y": 20,
      "z": 18,
      "name": "Rock_Shale_Brick",
      "rotation": 2
    },
    {
      "x": -19,
      "y": 21,
      "z": 18,
      "name": "Rock_Shale_Brick_Ornate"
    },
    {
      "x": -18,
      "y": 4,
      "z": -19,
      "name": "Rock_Shale_Cobble",
      "rotation": 2
    },
    {
      "x": -18,
      "y": 5,
      "z": -19,
      "name": "Rock_Shale_Brick",
      "rotation": 1
    },
    {
      "x": -18,
      "y": 6,
      "z": -19,
      "name": "Rock_Shale_Brick",
      "rotation": 1
    },
    {
      "x": -18,
      "y": 7,
      "z": -19,
      "name": "Rock_Shale_Brick",
      "rotation": 1
    },
    {
      "x": -18,
      "y": 8,
      "z": -19,
      "name": "Rock_Shale_Brick",
      "rotation": 1
    },
    {
      "x": -18,
      "y": 9,
      "z": -19,
      "name": "Rock_Shale_Brick_Ornate",
      "rotation": 3
    },
    {
      "x": -18,
      "y": 10,
      "z": -19,
      "name": "Rock_Shale_Cobble",
      "rotation": 2
    },
    {
      "x": -18,
      "y": 11,
      "z": -19,
      "name": "Rock_Shale_Brick",
      "rotation": 1
    },
    {
      "x": -18,
      "y": 12,
      "z": -19,
      "name": "Rock_Shale_Brick",
      "rotation": 1
    },
    {
      "x": -18,
      "y": 13,
      "z": -19,
      "name": "Rock_Shale_Brick",
      "rotation": 1
    },
    {
      "x": -18,
      "y": 14,
      "z": -19,
      "name": "Rock_Shale_Brick",
      "rotation": 1
    },
    {
      "x": -18,
      "y": 15,
      "z": -19,
      "name": "Rock_Shale_Brick_Ornate",
      "rotation": 3
    },
    {
      "x": -18,
      "y": 16,
      "z": -19,
      "name": "Rock_Shale_Cobble",
      "rotation": 2
    },
    {
      "x": -18,
      "y": 17,
      "z": -19,
      "name": "Rock_Shale_Brick",
      "rotation": 1
    },
    {
      "x": -18,
      "y": 18,
      "z": -19,
      "name": "Rock_Shale_Brick",
      "rotation": 1
    },
    {
      "x": -18,
      "y": 19,
      "z": -19,
      "name": "Rock_Shale_Brick",
      "rotation": 1
    },
    {
      "x": -18,
      "y": 20,
      "z": -19,
      "name": "Rock_Shale_Brick",
      "rotation": 1
    },
    {
      "x": -18,
      "y": 21,
      "z": -19,
      "name": "Rock_Shale_Brick_Ornate",
      "rotation": 3
    },
    {
      "x": -18,
      "y": 4,
      "z": -18,
      "name": "Rock_Shale_Cobble",
      "rotation": 2
    },
    {
      "x": -18,
      "y": 5,
      "z": -18,
      "name": "Rubble_Shale_Medium"
    },
    {
      "x": -18,
      "y": 10,
      "z": -18,
      "name": "Rock_Shale_Cobble",
      "rotation": 2
    },
    {
      "x": -18,
      "y": 11,
      "z": -18,
      "name": "Furniture_Human_Ruins_Ladder",
      "rotation": 1
    },
    {
      "x": -18,
      "y": 12,
      "z": -18,
      "name": "Furniture_Human_Ruins_Ladder",
      "rotation": 1
    },
    {
      "x": -18,
      "y": 13,
      "z": -18,
      "name": "Furniture_Human_Ruins_Ladder",
      "rotation": 1
    },
    {
      "x": -18,
      "y": 14,
      "z": -18,
      "name": "Furniture_Human_Ruins_Ladder",
      "rotation": 1
    },
    {
      "x": -18,
      "y": 15,
      "z": -18,
      "name": "Furniture_Human_Ruins_Ladder",
      "rotation": 1
    },
    {
      "x": -18,
      "y": 16,
      "z": -18,
      "name": "*Furniture_Temple_Dark_Trapdoor_State_Definitions_CloseDoorOut",
      "rotation": 1
    },
    {
      "x": -18,
      "y": 4,
      "z": -17,
      "name": "Rock_Shale_Cobble",
      "rotation": 2
    },
    {
      "x": -18,
      "y": 5,
      "z": -17,
      "name": "Furniture_SK_AEA_Monument_Coffin_Stage3",
      "filler": 992,
      "rotation": 1
    },
    {
      "x": -18,
      "y": 10,
      "z": -17,
      "name": "Rock_Shale_Cobble",
      "rotation": 2
    },
    {
      "x": -18,
      "y": 16,
      "z": -17,
      "name": "Rock_Shale_Cobble",
      "rotation": 2
    },
    {
      "x": -18,
      "y": 17,
      "z": -17,
      "name": "Furniture_SK_AEA_Monument_Coffin",
      "filler": 992,
      "rotation": 1
    },
    {
      "x": -18,
      "y": 4,
      "z": -16,
      "name": "Rock_Shale_Cobble",
      "rotation": 2
    },
    {
      "x": -18,
      "y": 5,
      "z": -16,
      "name": "Furniture_SK_AEA_Monument_Coffin_Stage3",
      "rotation": 1
    },
    {
      "x": -18,
      "y": 10,
      "z": -16,
      "name": "Rock_Shale_Cobble",
      "rotation": 2
    },
    {
      "x": -18,
      "y": 14,
      "z": -16,
      "name": "Plant_Moss_Wall_Green_Dark",
      "rotation": 1
    },
    {
      "x": -18,
      "y": 15,
      "z": -16,
      "name": "Plant_Moss_Wall_Green_Dark",
      "rotation": 1
    },
    {
      "x": -18,
      "y": 16,
      "z": -16,
      "name": "Rock_Shale_Cobble",
      "rotation": 2
    },
    {
      "x": -18,
      "y": 17,
      "z": -16,
      "name": "Furniture_SK_AEA_Monument_Coffin",
      "rotation": 1
    },
    {
      "x": -18,
      "y": 4,
      "z": -15,
      "name": "Rock_Shale_Cobble",
      "rotation": 2
    },
    {
      "x": -18,
      "y": 10,
      "z": -15,
      "name": "Rock_Shale_Cobble",
      "rotation": 2
    },
    {
      "x": -18,
      "y": 11,
      "z": -15,
      "name": "Rubble_Shale_Medium",
      "rotation": 2
    },
    {
      "x": -18,
      "y": 16,
      "z": -15,
      "name": "Rock_Shale_Cobble",
      "rotation": 2
    },
    {
      "x": -18,
      "y": 4,
      "z": -14,
      "name": "Rock_Shale_Cobble",
      "rotation": 2
    },
    {
      "x": -18,
      "y": 5,
      "z": -14,
      "name": "Rock_Shale_Brick",
      "rotation": 1
    },
    {
      "x": -18,
      "y": 6,
      "z": -14,
      "name": "Rock_Shale_Brick",
      "rotation": 1
    },
    {
      "x": -18,
      "y": 7,
      "z": -14,
      "name": "Rock_Shale_Brick",
      "rotation": 1
    },
    {
      "x": -18,
      "y": 8,
      "z": -14,
      "name": "Rock_Shale_Brick",
      "rotation": 1
    },
    {
      "x": -18,
      "y": 9,
      "z": -14,
      "name": "Rock_Shale_Brick_Ornate",
      "rotation": 3
    },
    {
      "x": -18,
      "y": 10,
      "z": -14,
      "name": "Rock_Shale_Cobble",
      "rotation": 2
    },
    {
      "x": -18,
      "y": 11,
      "z": -14,
      "name": "Rock_Shale_Brick",
      "rotation": 1
    },
    {
      "x": -18,
      "y": 12,
      "z": -14,
      "name": "Rock_Shale_Brick",
      "rotation": 1
    },
    {
      "x": -18,
      "y": 13,
      "z": -14,
      "name": "Rock_Shale_Brick",
      "rotation": 1
    },
    {
      "x": -18,
      "y": 14,
      "z": -14,
      "name": "Rock_Shale_Brick",
      "rotation": 1
    },
    {
      "x": -18,
      "y": 15,
      "z": -14,
      "name": "Rock_Shale_Brick_Ornate",
      "rotation": 3
    },
    {
      "x": -18,
      "y": 16,
      "z": -14,
      "name": "Rock_Shale_Cobble",
      "rotation": 2
    },
    {
      "x": -18,
      "y": 17,
      "z": -14,
      "name": "Rock_Shale_Brick",
      "rotation": 1
    },
    {
      "x": -18,
      "y": 18,
      "z": -14,
      "name": "Rock_Shale_Brick",
      "rotation": 1
    },
    {
      "x": -18,
      "y": 19,
      "z": -14,
      "name": "Rock_Shale_Brick",
      "rotation": 1
    },
    {
      "x": -18,
      "y": 20,
      "z": -14,
      "name": "Rock_Shale_Brick",
      "rotation": 1
    },
    {
      "x": -18,
      "y": 21,
      "z": -14,
      "name": "Rock_Shale_Brick_Ornate",
      "rotation": 3
    },
    {
      "x": -18,
      "y": 4,
      "z": -11,
      "name": "Rock_Shale_Cobble"
    },
    {
      "x": -18,
      "y": 5,
      "z": -11,
      "name": "Rock_Shale_Brick_Smooth"
    },
    {
      "x": -18,
      "y": 6,
      "z": -11,
      "name": "Rock_Shale_Brick_Smooth"
    },
    {
      "x": -18,
      "y": 7,
      "z": -11,
      "name": "Rock_Shale_Brick_Smooth"
    },
    {
      "x": -18,
      "y": 8,
      "z": -11,
      "name": "Rock_Shale_Brick_Smooth"
    },
    {
      "x": -18,
      "y": 9,
      "z": -11,
      "name": "Rock_Shale_Brick_Ornate"
    },
    {
      "x": -18,
      "y": 10,
      "z": -11,
      "name": "Rock_Shale_Cobble"
    },
    {
      "x": -18,
      "y": 11,
      "z": -11,
      "name": "Rock_Shale_Brick_Smooth"
    },
    {
      "x": -18,
      "y": 12,
      "z": -11,
      "name": "Rock_Shale_Brick_Smooth"
    },
    {
      "x": -18,
      "y": 13,
      "z": -11,
      "name": "Rock_Shale_Brick_Smooth"
    },
    {
      "x": -18,
      "y": 14,
      "z": -11,
      "name": "Rock_Shale_Brick_Smooth"
    },
    {
      "x": -18,
      "y": 15,
      "z": -11,
      "name": "Rock_Shale_Brick_Ornate"
    },
    {
      "x": -18,
      "y": 16,
      "z": -11,
      "name": "Rock_Shale_Cobble"
    },
    {
      "x": -18,
      "y": 17,
      "z": -11,
      "name": "Rock_Shale_Brick_Smooth"
    },
    {
      "x": -18,
      "y": 18,
      "z": -11,
      "name": "Rock_Shale_Brick_Smooth"
    },
    {
      "x": -18,
      "y": 19,
      "z": -11,
      "name": "Rock_Shale_Brick_Smooth"
    },
    {
      "x": -18,
      "y": 20,
      "z": -11,
      "name": "Rock_Shale_Brick_Smooth"
    },
    {
      "x": -18,
      "y": 21,
      "z": -11,
      "name": "Rock_Shale_Brick_Ornate"
    },
    {
      "x": -18,
      "y": 4,
      "z": -10,
      "name": "Rock_Shale_Cobble"
    },
    {
      "x": -18,
      "y": 5,
      "z": -10,
      "name": "Rock_Shale_Brick",
      "rotation": 1
    },
    {
      "x": -18,
      "y": 6,
      "z": -10,
      "name": "Rock_Shale_Brick",
      "rotation": 1
    },
    {
      "x": -18,
      "y": 7,
      "z": -10,
      "name": "Rock_Shale_Brick",
      "rotation": 1
    },
    {
      "x": -18,
      "y": 8,
      "z": -10,
      "name": "Rock_Shale_Brick",
      "rotation": 1
    },
    {
      "x": -18,
      "y": 9,
      "z": -10,
      "name": "Rock_Shale_Brick_Ornate",
      "rotation": 3
    },
    {
      "x": -18,
      "y": 10,
      "z": -10,
      "name": "Rock_Shale_Cobble"
    },
    {
      "x": -18,
      "y": 11,
      "z": -10,
      "name": "Rock_Shale_Brick",
      "rotation": 1
    },
    {
      "x": -18,
      "y": 12,
      "z": -10,
      "name": "Rock_Shale_Brick",
      "rotation": 1
    },
    {
      "x": -18,
      "y": 13,
      "z": -10,
      "name": "Rock_Shale_Brick",
      "rotation": 1
    },
    {
      "x": -18,
      "y": 14,
      "z": -10,
      "name": "Rock_Shale_Brick",
      "rotation": 1
    },
    {
      "x": -18,
      "y": 15,
      "z": -10,
      "name": "Rock_Shale_Brick_Ornate",
      "rotation": 3
    },
    {
      "x": -18,
      "y": 16,
      "z": -10,
      "name": "Rock_Shale_Cobble"
    },
    {
      "x": -18,
      "y": 17,
      "z": -10,
      "name": "Rock_Shale_Brick",
      "rotation": 1
    },
    {
      "x": -18,
      "y": 18,
      "z": -10,
      "name": "Rock_Shale_Brick",
      "rotation": 1
    },
    {
      "x": -18,
      "y": 19,
      "z": -10,
      "name": "Rock_Shale_Brick",
      "rotation": 1
    },
    {
      "x": -18,
      "y": 20,
      "z": -10,
      "name": "Rock_Shale_Brick",
      "rotation": 1
    },
    {
      "x": -18,
      "y": 21,
      "z": -10,
      "name": "Rock_Shale_Brick_Ornate",
      "rotation": 3
    },
    {
      "x": -18,
      "y": 4,
      "z": -9,
      "name": "Rock_Shale_Cobble"
    },
    {
      "x": -18,
      "y": 9,
      "z": -9,
      "name": "Deco_SpiderWeb_Full"
    },
    {
      "x": -18,
      "y": 10,
      "z": -9,
      "name": "Rock_Shale_Cobble"
    },
    {
      "x": -18,
      "y": 16,
      "z": -9,
      "name": "Rock_Shale_Cobble"
    },
    {
      "x": -18,
      "y": 21,
      "z": -9,
      "name": "Deco_SpiderWeb_Full"
    },
    {
      "x": -18,
      "y": 4,
      "z": -8,
      "name": "Rock_Shale_Cobble"
    },
    {
      "x": -18,
      "y": 10,
      "z": -8,
      "name": "Rock_Shale_Cobble"
    },
    {
      "x": -18,
      "y": 16,
      "z": -8,
      "name": "Rock_Shale_Cobble"
    },
    {
      "x": -18,
      "y": 4,
      "z": -7,
      "name": "Rock_Shale_Cobble"
    },
    {
      "x": -18,
      "y": 10,
      "z": -7,
      "name": "Rock_Shale_Cobble"
    },
    {
      "x": -18,
      "y": 16,
      "z": -7,
      "name": "Rock_Shale_Cobble"
    },
    {
      "x": -18,
      "y": 4,
      "z": -6,
      "name": "Rock_Shale_Cobble"
    },
    {
      "x": -18,
      "y": 10,
      "z": -6,
      "name": "Rock_Shale_Cobble"
    },
    {
      "x": -18,
      "y": 16,
      "z": -6,
      "name": "Rock_Shale_Cobble"
    },
    {
      "x": -18,
      "y": 4,
      "z": -5,
      "name": "Rock_Shale_Cobble"
    },
    {
      "x": -18,
      "y": 10,
      "z": -5,
      "name": "Rock_Shale_Cobble"
    },
    {
      "x": -18,
      "y": 16,
      "z": -5,
      "name": "Rock_Shale_Cobble"
    },
    {
      "x": -18,
      "y": 4,
      "z": -4,
      "name": "Rock_Shale_Cobble"
    },
    {
      "x": -18,
      "y": 10,
      "z": -4,
      "name": "Rock_Shale_Cobble"
    },
    {
      "x": -18,
      "y": 16,
      "z": -4,
      "name": "Rock_Shale_Cobble"
    },
    {
      "x": -18,
      "y": 4,
      "z": -3,
      "name": "Rock_Shale_Brick_Smooth"
    },
    {
      "x": -18,
      "y": 10,
      "z": -3,
      "name": "Rock_Shale_Brick_Smooth"
    },
    {
      "x": -18,
      "y": 16,
      "z": -3,
      "name": "Rock_Shale_Brick_Smooth"
    },
    {
      "x": -18,
      "y": 4,
      "z": -2,
      "name": "Rock_Shale_Cobble"
    },
    {
      "x": -18,
      "y": 10,
      "z": -2,
      "name": "Rock_Shale_Cobble"
    },
    {
      "x": -18,
      "y": 16,
      "z": -2,
      "name": "Rock_Shale_Cobble"
    },
    {
      "x": -18,
      "y": 4,
      "z": -1,
      "name": "Rock_Shale_Cobble"
    },
    {
      "x": -18,
      "y": 10,
      "z": -1,
      "name": "Rock_Shale_Cobble"
    },
    {
      "x": -18,
      "y": 16,
      "z": -1,
      "name": "Rock_Shale_Cobble"
    },
    {
      "x": -18,
      "y": 4,
      "z": 0,
      "name": "Rock_Shale_Cobble",
      "rotation": 1
    },
    {
      "x": -18,
      "y": 10,
      "z": 0,
      "name": "Rock_Shale_Cobble",
      "rotation": 1
    },
    {
      "x": -18,
      "y": 16,
      "z": 0,
      "name": "Rock_Shale_Cobble",
      "rotation": 1
    },
    {
      "x": -18,
      "y": 4,
      "z": 1,
      "name": "Rock_Shale_Cobble",
      "rotation": 1
    },
    {
      "x": -18,
      "y": 10,
      "z": 1,
      "name": "Rock_Shale_Cobble",
      "rotation": 1
    },
    {
      "x": -18,
      "y": 16,
      "z": 1,
      "name": "Rock_Shale_Cobble",
      "rotation": 1
    },
    {
      "x": -18,
      "y": 4,
      "z": 2,
      "name": "Rock_Shale_Cobble",
      "rotation": 1
    },
    {
      "x": -18,
      "y": 10,
      "z": 2,
      "name": "Rock_Shale_Cobble",
      "rotation": 1
    },
    {
      "x": -18,
      "y": 16,
      "z": 2,
      "name": "Rock_Shale_Cobble",
      "rotation": 1
    },
    {
      "x": -18,
      "y": 4,
      "z": 3,
      "name": "Rock_Shale_Brick_Smooth",
      "rotation": 1
    },
    {
      "x": -18,
      "y": 10,
      "z": 3,
      "name": "Rock_Shale_Brick_Smooth",
      "rotation": 1
    },
    {
      "x": -18,
      "y": 16,
      "z": 3,
      "name": "Rock_Shale_Brick_Smooth",
      "rotation": 1
    },
    {
      "x": -18,
      "y": 4,
      "z": 4,
      "name": "Rock_Shale_Cobble",
      "rotation": 1
    },
    {
      "x": -18,
      "y": 10,
      "z": 4,
      "name": "Rock_Shale_Cobble",
      "rotation": 1
    },
    {
      "x": -18,
      "y": 16,
      "z": 4,
      "name": "Rock_Shale_Cobble",
      "rotation": 1
    },
    {
      "x": -18,
      "y": 4,
      "z": 5,
      "name": "Rock_Shale_Cobble",
      "rotation": 1
    },
    {
      "x": -18,
      "y": 10,
      "z": 5,
      "name": "Rock_Shale_Cobble",
      "rotation": 1
    },
    {
      "x": -18,
      "y": 16,
      "z": 5,
      "name": "Rock_Shale_Cobble",
      "rotation": 1
    },
    {
      "x": -18,
      "y": 4,
      "z": 6,
      "name": "Rock_Shale_Cobble",
      "rotation": 1
    },
    {
      "x": -18,
      "y": 10,
      "z": 6,
      "name": "Rock_Shale_Cobble",
      "rotation": 1
    },
    {
      "x": -18,
      "y": 16,
      "z": 6,
      "name": "Rock_Shale_Cobble",
      "rotation": 1
    },
    {
      "x": -18,
      "y": 4,
      "z": 7,
      "name": "Rock_Shale_Cobble",
      "rotation": 1
    },
    {
      "x": -18,
      "y": 10,
      "z": 7,
      "name": "Rock_Shale_Cobble",
      "rotation": 1
    },
    {
      "x": -18,
      "y": 16,
      "z": 7,
      "name": "Rock_Shale_Cobble",
      "rotation": 1
    },
    {
      "x": -18,
      "y": 4,
      "z": 8,
      "name": "Rock_Shale_Cobble",
      "rotation": 1
    },
    {
      "x": -18,
      "y": 10,
      "z": 8,
      "name": "Rock_Shale_Cobble",
      "rotation": 1
    },
    {
      "x": -18,
      "y": 16,
      "z": 8,
      "name": "Rock_Shale_Cobble",
      "rotation": 1
    },
    {
      "x": -18,
      "y": 4,
      "z": 9,
      "name": "Rock_Shale_Cobble",
      "rotation": 1
    },
    {
      "x": -18,
      "y": 9,
      "z": 9,
      "name": "Plant_Moss_Wall_Green_Dark",
      "rotation": 2
    },
    {
      "x": -18,
      "y": 10,
      "z": 9,
      "name": "Rock_Shale_Cobble",
      "rotation": 1
    },
    {
      "x": -18,
      "y": 14,
      "z": 9,
      "name": "Plant_Moss_Wall_Green_Dark",
      "rotation": 2
    },
    {
      "x": -18,
      "y": 15,
      "z": 9,
      "name": "Plant_Moss_Wall_Green_Dark",
      "rotation": 2
    },
    {
      "x": -18,
      "y": 16,
      "z": 9,
      "name": "Rock_Shale_Cobble",
      "rotation": 1
    },
    {
      "x": -18,
      "y": 21,
      "z": 9,
      "name": "Plant_Moss_Wall_Green_Dark",
      "rotation": 2
    },
    {
      "x": -18,
      "y": 4,
      "z": 10,
      "name": "Rock_Shale_Cobble",
      "rotation": 1
    },
    {
      "x": -18,
      "y": 5,
      "z": 10,
      "name": "Rock_Shale_Brick",
      "rotation": 2
    },
    {
      "x": -18,
      "y": 6,
      "z": 10,
      "name": "Rock_Shale_Brick",
      "rotation": 2
    },
    {
      "x": -18,
      "y": 7,
      "z": 10,
      "name": "Rock_Shale_Brick",
      "rotation": 2
    },
    {
      "x": -18,
      "y": 8,
      "z": 10,
      "name": "Rock_Shale_Brick",
      "rotation": 2
    },
    {
      "x": -18,
      "y": 9,
      "z": 10,
      "name": "Rock_Shale_Brick_Ornate"
    },
    {
      "x": -18,
      "y": 10,
      "z": 10,
      "name": "Rock_Shale_Cobble",
      "rotation": 1
    },
    {
      "x": -18,
      "y": 11,
      "z": 10,
      "name": "Rock_Shale_Brick",
      "rotation": 2
    },
    {
      "x": -18,
      "y": 12,
      "z": 10,
      "name": "Rock_Shale_Brick",
      "rotation": 2
    },
    {
      "x": -18,
      "y": 13,
      "z": 10,
      "name": "Rock_Shale_Brick",
      "rotation": 2
    },
    {
      "x": -18,
      "y": 14,
      "z": 10,
      "name": "Rock_Shale_Brick",
      "rotation": 2
    },
    {
      "x": -18,
      "y": 15,
      "z": 10,
      "name": "Rock_Shale_Brick_Ornate"
    },
    {
      "x": -18,
      "y": 16,
      "z": 10,
      "name": "Rock_Shale_Cobble",
      "rotation": 1
    },
    {
      "x": -18,
      "y": 17,
      "z": 10,
      "name": "Rock_Shale_Brick",
      "rotation": 2
    },
    {
      "x": -18,
      "y": 18,
      "z": 10,
      "name": "Rock_Shale_Brick",
      "rotation": 2
    },
    {
      "x": -18,
      "y": 19,
      "z": 10,
      "name": "Rock_Shale_Brick",
      "rotation": 2
    },
    {
      "x": -18,
      "y": 20,
      "z": 10,
      "name": "Rock_Shale_Brick",
      "rotation": 2
    },
    {
      "x": -18,
      "y": 21,
      "z": 10,
      "name": "Rock_Shale_Brick_Ornate"
    },
    {
      "x": -18,
      "y": 4,
      "z": 11,
      "name": "Rock_Shale_Cobble",
      "rotation": 1
    },
    {
      "x": -18,
      "y": 5,
      "z": 11,
      "name": "Rock_Shale_Brick_Smooth",
      "rotation": 1
    },
    {
      "x": -18,
      "y": 6,
      "z": 11,
      "name": "Rock_Shale_Brick_Smooth",
      "rotation": 1
    },
    {
      "x": -18,
      "y": 7,
      "z": 11,
      "name": "Rock_Shale_Brick_Smooth",
      "rotation": 1
    },
    {
      "x": -18,
      "y": 8,
      "z": 11,
      "name": "Rock_Shale_Brick_Smooth",
      "rotation": 1
    },
    {
      "x": -18,
      "y": 9,
      "z": 11,
      "name": "Rock_Shale_Brick_Ornate",
      "rotation": 1
    },
    {
      "x": -18,
      "y": 10,
      "z": 11,
      "name": "Rock_Shale_Cobble",
      "rotation": 1
    },
    {
      "x": -18,
      "y": 11,
      "z": 11,
      "name": "Rock_Shale_Brick_Smooth",
      "rotation": 1
    },
    {
      "x": -18,
      "y": 12,
      "z": 11,
      "name": "Rock_Shale_Brick_Smooth",
      "rotation": 1
    },
    {
      "x": -18,
      "y": 13,
      "z": 11,
      "name": "Rock_Shale_Brick_Smooth",
      "rotation": 1
    },
    {
      "x": -18,
      "y": 14,
      "z": 11,
      "name": "Rock_Shale_Brick_Smooth",
      "rotation": 1
    },
    {
      "x": -18,
      "y": 15,
      "z": 11,
      "name": "Rock_Shale_Brick_Ornate",
      "rotation": 1
    },
    {
      "x": -18,
      "y": 16,
      "z": 11,
      "name": "Rock_Shale_Cobble",
      "rotation": 1
    },
    {
      "x": -18,
      "y": 17,
      "z": 11,
      "name": "Rock_Shale_Brick_Smooth",
      "rotation": 1
    },
    {
      "x": -18,
      "y": 18,
      "z": 11,
      "name": "Rock_Shale_Brick_Smooth",
      "rotation": 1
    },
    {
      "x": -18,
      "y": 19,
      "z": 11,
      "name": "Rock_Shale_Brick_Smooth",
      "rotation": 1
    },
    {
      "x": -18,
      "y": 20,
      "z": 11,
      "name": "Rock_Shale_Brick_Smooth",
      "rotation": 1
    },
    {
      "x": -18,
      "y": 21,
      "z": 11,
      "name": "Rock_Shale_Brick_Ornate",
      "rotation": 1
    },
    {
      "x": -18,
      "y": 4,
      "z": 14,
      "name": "Rock_Shale_Cobble",
      "rotation": 3
    },
    {
      "x": -18,
      "y": 5,
      "z": 14,
      "name": "Rock_Shale_Brick",
      "rotation": 2
    },
    {
      "x": -18,
      "y": 6,
      "z": 14,
      "name": "Rock_Shale_Brick",
      "rotation": 2
    },
    {
      "x": -18,
      "y": 7,
      "z": 14,
      "name": "Rock_Shale_Brick",
      "rotation": 2
    },
    {
      "x": -18,
      "y": 8,
      "z": 14,
      "name": "Rock_Shale_Brick",
      "rotation": 2
    },
    {
      "x": -18,
      "y": 9,
      "z": 14,
      "name": "Rock_Shale_Brick_Ornate"
    },
    {
      "x": -18,
      "y": 10,
      "z": 14,
      "name": "Rock_Shale_Cobble",
      "rotation": 3
    },
    {
      "x": -18,
      "y": 11,
      "z": 14,
      "name": "Rock_Shale_Brick",
      "rotation": 2
    },
    {
      "x": -18,
      "y": 12,
      "z": 14,
      "name": "Rock_Shale_Brick",
      "rotation": 2
    },
    {
      "x": -18,
      "y": 13,
      "z": 14,
      "name": "Rock_Shale_Brick",
      "rotation": 2
    },
    {
      "x": -18,
      "y": 14,
      "z": 14,
      "name": "Rock_Shale_Brick",
      "rotation": 2
    },
    {
      "x": -18,
      "y": 15,
      "z": 14,
      "name": "Rock_Shale_Brick_Ornate"
    },
    {
      "x": -18,
      "y": 16,
      "z": 14,
      "name": "Rock_Shale_Cobble",
      "rotation": 3
    },
    {
      "x": -18,
      "y": 17,
      "z": 14,
      "name": "Rock_Shale_Brick",
      "rotation": 2
    },
    {
      "x": -18,
      "y": 18,
      "z": 14,
      "name": "Rock_Shale_Brick",
      "rotation": 2
    },
    {
      "x": -18,
      "y": 19,
      "z": 14,
      "name": "Rock_Shale_Brick",
      "rotation": 2
    },
    {
      "x": -18,
      "y": 20,
      "z": 14,
      "name": "Rock_Shale_Brick",
      "rotation": 2
    },
    {
      "x": -18,
      "y": 21,
      "z": 14,
      "name": "Rock_Shale_Brick_Ornate"
    },
    {
      "x": -18,
      "y": 4,
      "z": 15,
      "name": "Rock_Shale_Cobble",
      "rotation": 3
    },
    {
      "x": -18,
      "y": 5,
      "z": 15,
      "name": "Rubble_Shale_Medium"
    },
    {
      "x": -18,
      "y": 10,
      "z": 15,
      "name": "Rock_Shale_Cobble",
      "rotation": 3
    },
    {
      "x": -18,
      "y": 11,
      "z": 15,
      "name": "Rubble_Shale",
      "rotation": 2
    },
    {
      "x": -18,
      "y": 16,
      "z": 15,
      "name": "Rock_Shale_Cobble",
      "rotation": 3
    },
    {
      "x": -18,
      "y": 17,
      "z": 15,
      "name": "Rubble_Shale_Medium"
    },
    {
      "x": -18,
      "y": 4,
      "z": 16,
      "name": "Rock_Shale_Cobble",
      "rotation": 3
    },
    {
      "x": -18,
      "y": 5,
      "z": 16,
      "name": "Plant_Moss_Rug_Green_Dark"
    },
    {
      "x": -18,
      "y": 9,
      "z": 16,
      "name": "Plant_Moss_Wall_Green_Dark",
      "rotation": 1
    },
    {
      "x": -18,
      "y": 10,
      "z": 16,
      "name": "Rock_Shale_Cobble",
      "rotation": 3
    },
    {
      "x": -18,
      "y": 16,
      "z": 16,
      "name": "Rock_Shale_Cobble",
      "rotation": 3
    },
    {
      "x": -18,
      "y": 17,
      "z": 16,
      "name": "Plant_Moss_Rug_Green_Dark"
    },
    {
      "x": -18,
      "y": 21,
      "z": 16,
      "name": "Plant_Moss_Wall_Green_Dark",
      "rotation": 1
    },
    {
      "x": -18,
      "y": 4,
      "z": 17,
      "name": "Rock_Shale_Cobble",
      "rotation": 3
    },
    {
      "x": -18,
      "y": 10,
      "z": 17,
      "name": "Rock_Shale_Cobble",
      "rotation": 3
    },
    {
      "x": -18,
      "y": 16,
      "z": 17,
      "name": "Rock_Shale_Cobble",
      "rotation": 3
    },
    {
      "x": -18,
      "y": 4,
      "z": 18,
      "name": "Rock_Shale_Cobble",
      "rotation": 3
    },
    {
      "x": -18,
      "y": 8,
      "z": 18,
      "name": "Plant_Moss_Wall_Green_Dark",
      "rotation": 2
    },
    {
      "x": -18,
      "y": 9,
      "z": 18,
      "name": "Plant_Moss_Wall_Green_Dark",
      "rotation": 2
    },
    {
      "x": -18,
      "y": 10,
      "z": 18,
      "name": "Rock_Shale_Cobble",
      "rotation": 3
    },
    {
      "x": -18,
      "y": 11,
      "z": 18,
      "name": "Plant_Moss_Rug_Green_Dark",
      "rotation": 2
    },
    {
      "x": -18,
      "y": 16,
      "z": 18,
      "name": "Rock_Shale_Cobble",
      "rotation": 3
    },
    {
      "x": -18,
      "y": 20,
      "z": 18,
      "name": "Plant_Moss_Wall_Green_Dark",
      "rotation": 2
    },
    {
      "x": -18,
      "y": 21,
      "z": 18,
      "name": "Plant_Moss_Wall_Green_Dark",
      "rotation": 2
    },
    {
      "x": -18,
      "y": 4,
      "z": 19,
      "name": "Rock_Shale_Cobble",
      "rotation": 3
    },
    {
      "x": -18,
      "y": 5,
      "z": 19,
      "name": "Rock_Shale_Brick",
      "rotation": 2
    },
    {
      "x": -18,
      "y": 6,
      "z": 19,
      "name": "Rock_Shale_Brick",
      "rotation": 2
    },
    {
      "x": -18,
      "y": 7,
      "z": 19,
      "name": "Rock_Shale_Brick",
      "rotation": 2
    },
    {
      "x": -18,
      "y": 8,
      "z": 19,
      "name": "Rock_Shale_Brick",
      "rotation": 2
    },
    {
      "x": -18,
      "y": 9,
      "z": 19,
      "name": "Rock_Shale_Brick_Ornate"
    },
    {
      "x": -18,
      "y": 10,
      "z": 19,
      "name": "Rock_Shale_Cobble",
      "rotation": 3
    },
    {
      "x": -18,
      "y": 11,
      "z": 19,
      "name": "Rock_Shale_Brick",
      "rotation": 2
    },
    {
      "x": -18,
      "y": 12,
      "z": 19,
      "name": "Rock_Shale_Brick",
      "rotation": 2
    },
    {
      "x": -18,
      "y": 13,
      "z": 19,
      "name": "Rock_Shale_Brick",
      "rotation": 2
    },
    {
      "x": -18,
      "y": 14,
      "z": 19,
      "name": "Rock_Shale_Brick",
      "rotation": 2
    },
    {
      "x": -18,
      "y": 15,
      "z": 19,
      "name": "Rock_Shale_Brick_Ornate"
    },
    {
      "x": -18,
      "y": 16,
      "z": 19,
      "name": "Rock_Shale_Cobble",
      "rotation": 3
    },
    {
      "x": -18,
      "y": 17,
      "z": 19,
      "name": "Rock_Shale_Brick",
      "rotation": 2
    },
    {
      "x": -18,
      "y": 18,
      "z": 19,
      "name": "Rock_Shale_Brick",
      "rotation": 2
    },
    {
      "x": -18,
      "y": 19,
      "z": 19,
      "name": "Rock_Shale_Brick",
      "rotation": 2
    },
    {
      "x": -18,
      "y": 20,
      "z": 19,
      "name": "Rock_Shale_Brick",
      "rotation": 2
    },
    {
      "x": -18,
      "y": 21,
      "z": 19,
      "name": "Rock_Shale_Brick_Ornate"
    },
    {
      "x": -17,
      "y": 4,
      "z": -19,
      "name": "Rock_Shale_Cobble",
      "rotation": 2
    },
    {
      "x": -17,
      "y": 5,
      "z": -19,
      "name": "Rock_Shale_Brick",
      "rotation": 1
    },
    {
      "x": -17,
      "y": 6,
      "z": -19,
      "name": "Rock_Shale_Brick",
      "rotation": 1
    },
    {
      "x": -17,
      "y": 7,
      "z": -19,
      "name": "Rock_Shale_Brick",
      "rotation": 1
    },
    {
      "x": -17,
      "y": 8,
      "z": -19,
      "name": "Rock_Shale_Brick",
      "rotation": 1
    },
    {
      "x": -17,
      "y": 9,
      "z": -19,
      "name": "Rock_Shale_Brick_Ornate",
      "rotation": 3
    },
    {
      "x": -17,
      "y": 10,
      "z": -19,
