{
  "version": 8,
  "blockIdVersion": 11,
  "anchorX": 0,
  "anchorY": 0,
  "anchorZ": 0,
  "blocks": [
    {
      "x": -10,
      "y": 54,
      "z": 3,
      "name": "Plant_Leaves_Beech",
      "support": 15
    },
    {
      "x": -10,
      "y": 55,
      "z": 3,
      "name": "Plant_Leaves_Beech",
      "support": 15
    },
    {
      "x": -9,
      "y": 58,
      "z": -3,
      "name": "Plant_Leaves_Beech",
      "support": 15
    },
    {
      "x": -9,
      "y": 59,
      "z": -3,
      "name": "Plant_Leaves_Beech",
      "support": 15
    },
    {
      "x": -9,
      "y": 54,
      "z": -1,
      "name": "Plant_Leaves_Beech",
      "support": 15
    },
    {
      "x": -9,
      "y": 55,
      "z": -1,
      "name": "Plant_Leaves_Beech",
      "support": 15
    },
    {
      "x": -9,
      "y": 54,
      "z": 0,
      "name": "Plant_Leaves_Beech",
      "support": 15
    },
    {
      "x": -9,
      "y": 54,
      "z": 2,
      "name": "Plant_Leaves_Beech",
      "support": 15
    },
    {
      "x": -9,
      "y": 55,
      "z": 2,
      "name": "Plant_Leaves_Beech",
      "support": 15
    },
    {
      "x": -9,
      "y": 53,
      "z": 3,
      "name": "Plant_Leaves_Beech",
      "support": 15
    },
    {
      "x": -9,
      "y": 54,
      "z": 3,
      "name": "Wood_Sallow_Branch_Corner",
      "support": 15,
      "rotation": 3
    },
    {
      "x": -9,
      "y": 55,
      "z": 3,
      "name": "Wood_Sallow_Branch_Long",
      "support": 15
    },
    {
      "x": -9,
      "y": 56,
      "z": 3,
      "name": "Plant_Leaves_Beech",
      "support": 15
    },
    {
      "x": -9,
      "y": 54,
      "z": 4,
      "name": "Plant_Leaves_Beech",
      "support": 15
    },
    {
      "x": -9,
      "y": 55,
      "z": 4,
      "name": "Plant_Leaves_Beech",
      "support": 15
    },
    {
      "x": -8,
      "y": 58,
      "z": -4,
      "name": "Plant_Leaves_Beech",
      "support": 15
    },
    {
      "x": -8,
      "y": 59,
      "z": -4,
      "name": "Plant_Leaves_Beech",
      "support": 15
    },
    {
      "x": -8,
      "y": 58,
      "z": -3,
      "name": "Wood_Sallow_Branch_Corner",
      "support": 15,
      "rotation": 3
    },
    {
      "x": -8,
      "y": 59,
      "z": -3,
      "name": "Wood_Sallow_Branch_Long",
      "support": 15
    },
    {
      "x": -8,
      "y": 60,
      "z": -3,
      "name": "Plant_Leaves_Beech",
      "support": 15
    },
    {
      "x": -8,
      "y": 54,
      "z": -2,
      "name": "Plant_Leaves_Beech",
      "support": 15
    },
    {
      "x": -8,
      "y": 55,
      "z": -2,
      "name": "Plant_Leaves_Beech",
      "support": 15
    },
    {
      "x": -8,
      "y": 58,
      "z": -2,
      "name": "Plant_Leaves_Beech",
      "support": 15
    },
    {
      "x": -8,
      "y": 59,
      "z": -2,
      "name": "Plant_Leaves_Beech",
      "support": 15
    },
    {
      "x": -8,
      "y": 54,
      "z": -1,
      "name": "Wood_Sallow_Branch_Corner",
      "support": 15,
      "rotation": 2
    },
    {
      "x": -8,
      "y": 55,
      "z": -1,
      "name": "Wood_Sallow_Branch_Long",
      "support": 15
    },
    {
      "x": -8,
      "y": 56,
      "z": -1,
      "name": "Plant_Leaves_Beech",
      "support": 15
    },
    {
      "x": -8,
      "y": 54,
      "z": 0,
      "name": "Wood_Sallow_Branch_Corner",
      "support": 15,
      "rotation": 19
    },
    {
      "x": -8,
      "y": 55,
      "z": 0,
      "name": "Plant_Leaves_Beech",
      "support": 15
    },
    {
      "x": -8,
      "y": 54,
      "z": 3,
      "name": "Wood_Sallow_Trunk",
      "support": 15,
      "rotation": 5
    },
    {
      "x": -8,
      "y": 55,
      "z": 3,
      "name": "Plant_Leaves_Beech",
      "support": 15
    },
    {
      "x": -8,
      "y": 58,
      "z": 3,
      "name": "Plant_Leaves_Beech",
      "support": 15
    },
    {
      "x": -8,
      "y": 59,
      "z": 3,
      "name": "Plant_Leaves_Beech",
      "support": 15
    },
    {
      "x": -8,
      "y": 55,
      "z": 7,
      "name": "Plant_Leaves_Beech",
      "support": 15
    },
    {
      "x": -8,
      "y": 55,
      "z": 8,
      "name": "Plant_Leaves_Beech",
      "support": 15
    },
    {
      "x": -8,
      "y": 56,
      "z": 8,
      "name": "Plant_Leaves_Beech",
      "support": 15
    },
    {
      "x": -7,
      "y": 54,
      "z": -6,
      "name": "Plant_Leaves_Beech",
      "support": 15
    },
    {
      "x": -7,
      "y": 55,
      "z": -6,
      "name": "Plant_Leaves_Beech",
      "support": 15
    },
    {
      "x": -7,
      "y": 58,
      "z": -4,
      "name": "Plant_Leaves_Beech",
      "support": 15
    },
    {
      "x": -7,
      "y": 58,
      "z": -3,
      "name": "Wood_Sallow_Branch_Long",
      "support": 15,
      "rotation": 5
    },
    {
      "x": -7,
      "y": 59,
      "z": -3,
      "name": "Plant_Leaves_Beech",
      "support": 15
    },
    {
      "x": -7,
      "y": 60,
      "z": -3,
      "name": "Plant_Leaves_Beech",
      "support": 15
    },
    {
      "x": -7,
      "y": 58,
      "z": -2,
      "name": "Plant_Leaves_Beech",
      "support": 15
    },
    {
      "x": -7,
      "y": 54,
      "z": -1,
      "name": "Plant_Leaves_Beech",
      "support": 15
    },
    {
      "x": -7,
      "y": 55,
      "z": -1,
      "name": "Plant_Leaves_Beech",
      "support": 15
    },
    {
      "x": -7,
      "y": 2,
      "z": 0,
      "name": "Wood_Sallow_Roots"
    },
    {
      "x": -7,
      "y": 3,
      "z": 0,
      "name": "Wood_Sallow_Trunk_Full",
      "support": 15
    },
    {
      "x": -7,
      "y": 4,
      "z": 0,
      "name": "Wood_Sallow_Trunk",
      "support": 15
    },
    {
      "x": -7,
      "y": 5,
      "z": 0,
      "name": "Wood_Sallow_Trunk",
      "support": 15
    },
    {
      "x": -7,
      "y": 6,
      "z": 0,
      "name": "Wood_Sallow_Trunk",
      "support": 15
    },
    {
      "x": -7,
      "y": 7,
      "z": 0,
      "name": "Wood_Sallow_Trunk",
      "support": 15
    },
    {
      "x": -7,
      "y": 8,
      "z": 0,
      "name": "Wood_Sallow_Trunk_Full",
      "support": 15
    },
    {
      "x": -7,
      "y": 54,
      "z": 0,
      "name": "Wood_Sallow_Branch_Corner",
      "support": 15,
      "rotation": 24
    },
    {
      "x": -7,
      "y": 54,
      "z": 1,
      "name": "Wood_Sallow_Branch_Corner",
      "support": 15,
      "rotation": 19
    },
    {
      "x": -7,
      "y": 58,
      "z": 2,
      "name": "Plant_Leaves_Beech",
      "support": 15
    },
    {
      "x": -7,
      "y": 59,
      "z": 2,
      "name": "Plant_Leaves_Beech",
      "support": 15
    },
    {
      "x": -7,
      "y": 54,
      "z": 3,
      "name": "Wood_Sallow_Trunk",
      "support": 15,
      "rotation": 5
    },
    {
      "x": -7,
      "y": 55,
      "z": 3,
      "name": "Plant_Leaves_Beech",
      "support": 15
    },
    {
      "x": -7,
      "y": 56,
      "z": 3,
      "name": "Plant_Leaves_Beech",
      "support": 15
    },
    {
      "x": -7,
      "y": 57,
      "z": 3,
      "name": "Plant_Leaves_Beech",
      "support": 15
    },
    {
      "x": -7,
      "y": 58,
      "z": 3,
      "name": "Wood_Sallow_Branch_Corner",
      "support": 15,
      "rotation": 3
    },
    {
      "x": -7,
      "y": 59,
      "z": 3,
      "name": "Wood_Sallow_Branch_Long",
      "support": 15
    },
    {
      "x": -7,
      "y": 60,
      "z": 3,
      "name": "Plant_Leaves_Beech",
      "support": 15
    },
    {
      "x": -7,
      "y": 54,
      "z": 4,
      "name": "Wood_Sallow_Branch_Long",
      "support": 15,
      "rotation": 4
    },
    {
      "x": -7,
      "y": 58,
      "z": 4,
      "name": "Plant_Leaves_Beech",
      "support": 15
    },
    {
      "x": -7,
      "y": 59,
      "z": 4,
      "name": "Plant_Leaves_Beech",
      "support": 15
    },
    {
      "x": -7,
      "y": 54,
      "z": 5,
      "name": "Wood_Sallow_Branch_Long",
      "support": 15,
      "rotation": 4
    },
    {
      "x": -7,
      "y": 54,
      "z": 6,
      "name": "Wood_Sallow_Branch_Corner",
      "support": 15
    },
    {
      "x": -7,
      "y": 55,
      "z": 6,
      "name": "Wood_Sallow_Branch_Corner",
      "support": 15,
      "rotation": 8
    },
    {
      "x": -7,
      "y": 58,
      "z": 6,
      "name": "Plant_Leaves_Beech",
      "support": 15
    },
    {
      "x": -7,
      "y": 59,
      "z": 6,
      "name": "Plant_Leaves_Beech",
      "support": 15
    },
    {
      "x": -7,
      "y": 54,
      "z": 7,
      "name": "Plant_Leaves_Beech",
      "support": 15
    },
    {
      "x": -7,
      "y": 55,
      "z": 7,
      "name": "Wood_Sallow_Branch_Long",
      "support": 15,
      "rotation": 4
    },
    {
      "x": -7,
      "y": 56,
      "z": 7,
      "name": "Plant_Leaves_Beech",
      "support": 15
    },
    {
      "x": -7,
      "y": 54,
      "z": 8,
      "name": "Plant_Leaves_Beech",
      "support": 15
    },
    {
      "x": -7,
      "y": 55,
      "z": 8,
      "name": "Wood_Sallow_Branch_Corner",
      "support": 15
    },
    {
      "x": -7,
      "y": 56,
      "z": 8,
      "name": "Wood_Sallow_Branch_Long",
      "support": 15
    },
    {
      "x": -7,
      "y": 57,
      "z": 8,
      "name": "Plant_Leaves_Beech",
      "support": 15
    },
    {
      "x": -7,
      "y": 55,
      "z": 9,
      "name": "Plant_Leaves_Beech",
      "support": 15
    },
    {
      "x": -7,
      "y": 56,
      "z": 9,
      "name": "Plant_Leaves_Beech",
      "support": 15
    },
    {
      "x": -6,
      "y": 54,
      "z": -7,
      "name": "Plant_Leaves_Beech",
      "support": 15
    },
    {
      "x": -6,
      "y": 55,
      "z": -7,
      "name": "Plant_Leaves_Beech",
      "support": 15
    },
    {
      "x": -6,
      "y": 2,
      "z": -6,
      "name": "Wood_Sallow_Roots"
    },
    {
      "x": -6,
      "y": 3,
      "z": -6,
      "name": "Wood_Sallow_Trunk_Full",
      "support": 15
    },
    {
      "x": -6,
      "y": 4,
      "z": -6,
      "name": "Wood_Sallow_Trunk",
      "support": 15
    },
    {
      "x": -6,
      "y": 5,
      "z": -6,
      "name": "Wood_Sallow_Trunk",
      "support": 15
    },
    {
      "x": -6,
      "y": 6,
      "z": -6,
      "name": "Wood_Sallow_Trunk",
      "support": 15
    },
    {
      "x": -6,
      "y": 7,
      "z": -6,
      "name": "Wood_Sallow_Trunk",
      "support": 15
    },
    {
      "x": -6,
      "y": 8,
      "z": -6,
      "name": "Wood_Sallow_Trunk_Full",
      "support": 15
    },
    {
      "x": -6,
      "y": 53,
      "z": -6,
      "name": "Plant_Leaves_Beech",
      "support": 15
    },
    {
      "x": -6,
      "y": 54,
      "z": -6,
      "name": "Wood_Sallow_Branch_Corner",
      "support": 15,
      "rotation": 3
    },
    {
      "x": -6,
      "y": 55,
      "z": -6,
      "name": "Wood_Sallow_Branch_Long",
      "support": 15
    },
    {
      "x": -6,
      "y": 56,
      "z": -6,
      "name": "Plant_Leaves_Beech",
      "support": 15
    },
    {
      "x": -6,
      "y": 4,
      "z": -5,
      "name": "Wood_Sallow_Roots"
    },
    {
      "x": -6,
      "y": 5,
      "z": -5,
      "name": "Wood_Sallow_Trunk_Full",
      "support": 15
    },
    {
      "x": -6,
      "y": 6,
      "z": -5,
      "name": "Wood_Sallow_Trunk",
      "support": 15
    },
    {
      "x": -6,
      "y": 7,
      "z": -5,
      "name": "Wood_Sallow_Trunk",
      "support": 15
    },
    {
      "x": -6,
      "y": 8,
      "z": -5,
      "name": "Wood_Sallow_Trunk",
      "support": 15
    },
    {
      "x": -6,
      "y": 9,
      "z": -5,
      "name": "Wood_Sallow_Trunk_Full",
      "support": 15
    },
    {
      "x": -6,
      "y": 54,
      "z": -5,
      "name": "Plant_Leaves_Beech",
      "support": 15
    },
    {
      "x": -6,
      "y": 55,
      "z": -5,
      "name": "Plant_Leaves_Beech",
      "support": 15
    },
    {
      "x": -6,
      "y": 10,
      "z": -4,
      "name": "Plant_Moss_Wall_Green_Dark",
      "support": 15,
      "rotation": 3
    },
    {
      "x": -6,
      "y": 60,
      "z": -4,
      "name": "Plant_Leaves_Beech",
      "support": 15
    },
    {
      "x": -6,
      "y": 57,
      "z": -3,
      "name": "Wood_Sallow_Trunk_Full",
      "support": 15,
      "rotation": 5
    },
    {
      "x": -6,
      "y": 58,
      "z": -3,
      "name": "Wood_Sallow_Trunk",
      "support": 15
    },
    {
      "x": -6,
      "y": 59,
      "z": -3,
      "name": "Wood_Sallow_Branch_Long",
      "support": 15
    },
    {
      "x": -6,
      "y": 60,
      "z": -3,
      "name": "Wood_Sallow_Branch_Long",
      "support": 15
    },
    {
      "x": -6,
      "y": 61,
      "z": -3,
      "name": "Plant_Leaves_Beech",
      "support": 15
    },
    {
      "x": -6,
      "y": 60,
      "z": -2,
      "name": "Plant_Leaves_Beech",
      "support": 15
    },
    {
      "x": -6,
      "y": 4,
      "z": 0,
      "name": "Wood_Sallow_Roots"
    },
    {
      "x": -6,
      "y": 5,
      "z": 0,
      "name": "Wood_Sallow_Trunk_Full",
      "support": 15
    },
    {
      "x": -6,
      "y": 6,
      "z": 0,
      "name": "Wood_Sallow_Trunk",
      "support": 15
    },
    {
      "x": -6,
      "y": 7,
      "z": 0,
      "name": "Wood_Sallow_Trunk",
      "support": 15
    },
    {
      "x": -6,
      "y": 8,
      "z": 0,
      "name": "Wood_Sallow_Trunk",
      "support": 15
    },
    {
      "x": -6,
      "y": 9,
      "z": 0,
      "name": "Wood_Sallow_Trunk_Full",
      "support": 15
    },
    {
      "x": -6,
      "y": 10,
      "z": 1,
      "name": "Plant_Moss_Wall_Green_Dark",
      "support": 15,
      "rotation": 3
    },
    {
      "x": -6,
      "y": 54,
      "z": 1,
      "name": "Wood_Sallow_Branch_Corner",
      "support": 15,
      "rotation": 24
    },
    {
      "x": -6,
      "y": 58,
      "z": 1,
      "name": "Plant_Leaves_Beech",
      "support": 15
    },
    {
      "x": -6,
      "y": 59,
      "z": 1,
      "name": "Plant_Leaves_Beech",
      "support": 15
    },
    {
      "x": -6,
      "y": 42,
      "z": 2,
      "name": "Plant_Vine_Liana",
      "support": 15,
      "rotation": 3
    },
    {
      "x": -6,
      "y": 43,
      "z": 2,
      "name": "Plant_Vine_Liana",
      "support": 15,
      "rotation": 3
    },
    {
      "x": -6,
      "y": 44,
      "z": 2,
      "name": "Plant_Vine_Liana",
      "support": 15,
      "rotation": 3
    },
    {
      "x": -6,
      "y": 45,
      "z": 2,
      "name": "Plant_Vine_Liana",
      "support": 15,
      "rotation": 3
    },
    {
      "x": -6,
      "y": 46,
      "z": 2,
      "name": "Plant_Vine_Liana",
      "support": 15,
      "rotation": 3
    },
    {
      "x": -6,
      "y": 47,
      "z": 2,
      "name": "Plant_Vine_Liana",
      "support": 15,
      "rotation": 3
    },
    {
      "x": -6,
      "y": 48,
      "z": 2,
      "name": "Plant_Vine_Liana",
      "support": 15,
      "rotation": 3
    },
    {
      "x": -6,
      "y": 49,
      "z": 2,
      "name": "Plant_Vine_Liana",
      "support": 15,
      "rotation": 3
    },
    {
      "x": -6,
      "y": 50,
      "z": 2,
      "name": "Plant_Vine_Liana",
      "support": 15,
      "rotation": 3
    },
    {
      "x": -6,
      "y": 51,
      "z": 2,
      "name": "Plant_Vine_Liana",
      "support": 15,
      "rotation": 3
    },
    {
      "x": -6,
      "y": 52,
      "z": 2,
      "name": "Plant_Vine_Liana",
      "support": 15,
      "rotation": 3
    },
    {
      "x": -6,
      "y": 53,
      "z": 2,
      "name": "Plant_Vine_Liana_End",
      "support": 15,
      "rotation": 3
    },
    {
      "x": -6,
      "y": 54,
      "z": 2,
      "name": "Wood_Sallow_Branch_Long",
      "support": 15,
      "rotation": 4
    },
    {
      "x": -6,
      "y": 55,
      "z": 2,
      "name": "Plant_Leaves_Beech",
      "support": 15
    },
    {
      "x": -6,
      "y": 56,
      "z": 2,
      "name": "Plant_Leaves_Beech",
      "support": 15
    },
    {
      "x": -6,
      "y": 58,
      "z": 2,
      "name": "Plant_Leaves_Beech",
      "support": 15
    },
    {
      "x": -6,
      "y": 54,
      "z": 3,
      "name": "Wood_Sallow_Trunk",
      "support": 15,
      "rotation": 5
    },
    {
      "x": -6,
      "y": 55,
      "z": 3,
      "name": "Wood_Sallow_Branch_Corner",
      "support": 15,
      "rotation": 3
    },
    {
      "x": -6,
      "y": 56,
      "z": 3,
      "name": "Wood_Sallow_Branch_Long",
      "support": 15
    },
    {
      "x": -6,
      "y": 57,
      "z": 3,
      "name": "Plant_Leaves_Beech",
      "support": 15
    },
    {
      "x": -6,
      "y": 58,
      "z": 3,
      "name": "Wood_Sallow_Branch_Long",
      "support": 15,
      "rotation": 5
    },
    {
      "x": -6,
      "y": 59,
      "z": 3,
      "name": "Plant_Leaves_Beech",
      "support": 15
    },
    {
      "x": -6,
      "y": 55,
      "z": 4,
      "name": "Plant_Leaves_Beech",
      "support": 15
    },
    {
      "x": -6,
      "y": 56,
      "z": 4,
      "name": "Plant_Leaves_Beech",
      "support": 15
    },
    {
      "x": -6,
      "y": 58,
      "z": 4,
      "name": "Plant_Leaves_Beech",
      "support": 15
    },
    {
      "x": -6,
      "y": 58,
      "z": 5,
      "name": "Plant_Leaves_Beech",
      "support": 15
    },
    {
      "x": -6,
      "y": 59,
      "z": 5,
      "name": "Plant_Leaves_Beech",
      "support": 15
    },
    {
      "x": -6,
      "y": 1,
      "z": 6,
      "name": "Wood_Sallow_Roots"
    },
    {
      "x": -6,
      "y": 2,
      "z": 6,
      "name": "Wood_Sallow_Trunk_Full",
      "support": 15
    },
    {
      "x": -6,
      "y": 3,
      "z": 6,
      "name": "Wood_Sallow_Trunk",
      "support": 15
    },
    {
      "x": -6,
      "y": 4,
      "z": 6,
      "name": "Wood_Sallow_Trunk",
      "support": 15
    },
    {
      "x": -6,
      "y": 5,
      "z": 6,
      "name": "Wood_Sallow_Trunk",
      "support": 15
    },
    {
      "x": -6,
      "y": 6,
      "z": 6,
      "name": "Wood_Sallow_Trunk",
      "support": 15
    },
    {
      "x": -6,
      "y": 7,
      "z": 6,
      "name": "Wood_Sallow_Trunk",
      "support": 15
    },
    {
      "x": -6,
      "y": 8,
      "z": 6,
      "name": "Wood_Sallow_Trunk_Full",
      "support": 15
    },
    {
      "x": -6,
      "y": 9,
      "z": 6,
      "name": "Plant_Moss_Rug_Green_Dark",
      "support": 15
    },
    {
      "x": -6,
      "y": 58,
      "z": 6,
      "name": "Wood_Sallow_Branch_Corner",
      "support": 15,
      "rotation": 3
    },
    {
      "x": -6,
      "y": 59,
      "z": 6,
      "name": "Wood_Sallow_Branch_Long",
      "support": 15
    },
    {
      "x": -6,
      "y": 60,
      "z": 6,
      "name": "Plant_Leaves_Beech",
      "support": 15
    },
    {
      "x": -6,
      "y": 58,
      "z": 7,
      "name": "Plant_Leaves_Beech",
      "support": 15
    },
    {
      "x": -6,
      "y": 59,
      "z": 7,
      "name": "Plant_Leaves_Beech",
      "support": 15
    },
    {
      "x": -6,
      "y": 55,
      "z": 8,
      "name": "Plant_Leaves_Beech",
      "support": 15
    },
    {
      "x": -6,
      "y": 56,
      "z": 8,
      "name": "Plant_Leaves_Beech",
      "support": 15
    },
    {
      "x": -5,
      "y": 55,
      "z": -8,
      "name": "Plant_Leaves_Beech",
      "support": 15
    },
    {
      "x": -5,
      "y": 56,
      "z": -8,
      "name": "Plant_Leaves_Beech",
      "support": 15
    },
    {
      "x": -5,
      "y": 54,
      "z": -7,
      "name": "Plant_Leaves_Beech",
      "support": 15
    },
    {
      "x": -5,
      "y": 53,
      "z": -6,
      "name": "Plant_Leaves_Beech",
      "support": 15
    },
    {
      "x": -5,
      "y": 54,
      "z": -6,
      "name": "Wood_Sallow_Branch_Long",
      "support": 15,
      "rotation": 5
    },
    {
      "x": -5,
      "y": 55,
      "z": -6,
      "name": "Plant_Leaves_Beech",
      "support": 15
    },
    {
      "x": -5,
      "y": 54,
      "z": -5,
      "name": "Plant_Leaves_Beech",
      "support": 15
    },
    {
      "x": -5,
      "y": 57,
      "z": -5,
      "name": "Plant_Leaves_Beech",
      "support": 15
    },
    {
      "x": -5,
      "y": 58,
      "z": -5,
      "name": "Plant_Leaves_Beech",
      "support": 15
    },
    {
      "x": -5,
      "y": 4,
      "z": -4,
      "name": "Wood_Sallow_Roots"
    },
    {
      "x": -5,
      "y": 5,
      "z": -4,
      "name": "Wood_Sallow_Trunk_Full",
      "support": 15
    },
    {
      "x": -5,
      "y": 6,
      "z": -4,
      "name": "Wood_Sallow_Trunk",
      "support": 15
    },
    {
      "x": -5,
      "y": 7,
      "z": -4,
      "name": "Wood_Sallow_Trunk",
      "support": 15
    },
    {
      "x": -5,
      "y": 8,
      "z": -4,
      "name": "Wood_Sallow_Trunk",
      "support": 15
    },
    {
      "x": -5,
      "y": 9,
      "z": -4,
      "name": "Wood_Sallow_Trunk",
      "support": 15
    },
    {
      "x": -5,
      "y": 10,
      "z": -4,
      "name": "Wood_Sallow_Trunk_Full",
      "support": 15
    },
    {
      "x": -5,
      "y": 11,
      "z": -4,
      "name": "Plant_Moss_Rug_Green_Dark",
      "support": 15
    },
    {
      "x": -5,
      "y": 57,
      "z": -4,
      "name": "Plant_Leaves_Beech",
      "support": 15
    },
    {
      "x": -5,
      "y": 62,
      "z": -4,
      "name": "Plant_Leaves_Beech",
      "support": 15
    },
    {
      "x": -5,
      "y": 63,
      "z": -4,
      "name": "Plant_Leaves_Beech",
      "support": 15
    },
    {
      "x": -5,
      "y": 10,
      "z": -3,
      "name": "Plant_Moss_Wall_Green_Dark",
      "support": 15
    },
    {
      "x": -5,
      "y": 57,
      "z": -3,
      "name": "Wood_Sallow_Trunk_Full",
      "support": 15,
      "rotation": 5
    },
    {
      "x": -5,
      "y": 56,
      "z": -2,
      "name": "Wood_Sallow_Trunk_Full",
      "support": 15,
      "rotation": 5
    },
    {
      "x": -5,
      "y": 57,
      "z": -2,
      "name": "Wood_Sallow_Trunk_Full",
      "support": 15,
      "rotation": 4
    },
    {
      "x": -5,
      "y": 58,
      "z": 0,
      "name": "Plant_Leaves_Beech",
      "support": 15
    },
    {
      "x": -5,
      "y": 59,
      "z": 0,
      "name": "Plant_Leaves_Beech",
      "support": 15
    },
    {
      "x": -5,
      "y": 5,
      "z": 1,
      "name": "Wood_Sallow_Roots"
    },
    {
      "x": -5,
      "y": 6,
      "z": 1,
      "name": "Wood_Sallow_Trunk_Full",
      "support": 15
    },
    {
      "x": -5,
      "y": 7,
      "z": 1,
      "name": "Wood_Sallow_Trunk",
      "support": 15
    },
    {
      "x": -5,
      "y": 8,
      "z": 1,
      "name": "Wood_Sallow_Trunk",
      "support": 15
    },
    {
      "x": -5,
      "y": 9,
      "z": 1,
      "name": "Wood_Sallow_Trunk",
      "support": 15
    },
    {
      "x": -5,
      "y": 10,
      "z": 1,
      "name": "Wood_Sallow_Trunk_Full",
      "support": 15
    },
    {
      "x": -5,
      "y": 11,
      "z": 1,
      "name": "Plant_Moss_Rug_Green_Dark",
      "support": 15
    },
    {
      "x": -5,
      "y": 57,
      "z": 1,
      "name": "Plant_Leaves_Beech",
      "support": 15
    },
    {
      "x": -5,
      "y": 58,
      "z": 1,
      "name": "Wood_Sallow_Branch_Corner",
      "support": 15,
      "rotation": 3
    },
    {
      "x": -5,
      "y": 59,
      "z": 1,
      "name": "Wood_Sallow_Branch_Long",
      "support": 15
    },
    {
      "x": -5,
      "y": 60,
      "z": 1,
      "name": "Plant_Leaves_Beech",
      "support": 15
    },
    {
      "x": -5,
      "y": 53,
      "z": 2,
      "name": "Wood_Sallow_Trunk_Full",
      "support": 15,
      "rotation": 5
    },
    {
      "x": -5,
      "y": 55,
      "z": 2,
      "name": "Plant_Leaves_Beech",
      "support": 15
    },
    {
      "x": -5,
      "y": 58,
      "z": 2,
      "name": "Plant_Leaves_Beech",
      "support": 15
    },
    {
      "x": -5,
      "y": 59,
      "z": 2,
      "name": "Plant_Leaves_Beech",
      "support": 15
    },
    {
      "x": -5,
      "y": 53,
      "z": 3,
      "name": "Wood_Sallow_Trunk_Full",
      "support": 15,
      "rotation": 4
    },
    {
      "x": -5,
      "y": 54,
      "z": 3,
      "name": "Wood_Sallow_Trunk_Full",
      "support": 15,
      "rotation": 5
    },
    {
      "x": -5,
      "y": 55,
      "z": 3,
      "name": "Wood_Sallow_Branch_Corner",
      "support": 15,
      "rotation": 11
    },
    {
      "x": -5,
      "y": 56,
      "z": 3,
      "name": "Plant_Leaves_Beech",
      "support": 15
    },
    {
      "x": -5,
      "y": 58,
      "z": 3,
      "name": "Wood_Sallow_Branch_Long",
      "support": 15,
      "rotation": 5
    },
    {
      "x": -5,
      "y": 55,
      "z": 4,
      "name": "Plant_Leaves_Beech",
      "support": 15
    },
    {
      "x": -5,
      "y": 2,
      "z": 5,
      "name": "Wood_Sallow_Roots"
    },
    {
      "x": -5,
      "y": 3,
      "z": 5,
      "name": "Wood_Sallow_Trunk_Full",
      "support": 15
    },
    {
      "x": -5,
      "y": 4,
      "z": 5,
      "name": "Wood_Sallow_Trunk",
      "support": 15
    },
    {
      "x": -5,
      "y": 5,
      "z": 5,
      "name": "Wood_Sallow_Trunk",
      "support": 15
    },
    {
      "x": -5,
      "y": 6,
      "z": 5,
      "name": "Wood_Sallow_Trunk",
      "support": 15
    },
    {
      "x": -5,
      "y": 7,
      "z": 5,
      "name": "Wood_Sallow_Trunk",
      "support": 15
    },
    {
      "x": -5,
      "y": 8,
      "z": 5,
      "name": "Wood_Sallow_Trunk",
      "support": 15
    },
    {
      "x": -5,
      "y": 9,
      "z": 5,
      "name": "Wood_Sallow_Trunk_Full",
      "support": 15
    },
    {
      "x": -5,
      "y": 10,
      "z": 5,
      "name": "Plant_Moss_Rug_Green_Dark",
      "support": 15
    },
    {
      "x": -5,
      "y": 58,
      "z": 5,
      "name": "Plant_Leaves_Beech",
      "support": 15
    },
    {
      "x": -5,
      "y": 52,
      "z": 6,
      "name": "Plant_Leaves_Beech",
      "support": 15
    },
    {
      "x": -5,
      "y": 53,
      "z": 6,
      "name": "Plant_Leaves_Beech",
      "support": 15
    },
    {
      "x": -5,
      "y": 57,
      "z": 6,
      "name": "Plant_Leaves_Beech",
      "support": 15
    },
    {
      "x": -5,
      "y": 58,
      "z": 6,
      "name": "Wood_Sallow_Branch_Long",
      "support": 15,
      "rotation": 5
    },
    {
      "x": -5,
      "y": 59,
      "z": 6,
      "name": "Plant_Leaves_Beech",
      "support": 15
    },
    {
      "x": -5,
      "y": 58,
      "z": 7,
      "name": "Plant_Leaves_Beech",
      "support": 15
    },
    {
      "x": -4,
      "y": 55,
      "z": -9,
      "name": "Plant_Leaves_Beech",
      "support": 15
    },
    {
      "x": -4,
      "y": 56,
      "z": -9,
      "name": "Plant_Leaves_Beech",
      "support": 15
    },
    {
      "x": -4,
      "y": 54,
      "z": -8,
      "name": "Plant_Leaves_Beech",
      "support": 15
    },
    {
      "x": -4,
      "y": 55,
      "z": -8,
      "name": "Wood_Sallow_Branch_Corner",
      "support": 15,
      "rotation": 3
    },
    {
      "x": -4,
      "y": 56,
      "z": -8,
      "name": "Wood_Sallow_Branch_Long",
      "support": 15
    },
    {
      "x": -4,
      "y": 57,
      "z": -8,
      "name": "Plant_Leaves_Beech",
      "support": 15
    },
    {
      "x": -4,
      "y": 55,
      "z": -7,
      "name": "Plant_Leaves_Beech",
      "support": 15
    },
    {
      "x": -4,
      "y": 56,
      "z": -7,
      "name": "Plant_Leaves_Beech",
      "support": 15
    },
    {
      "x": -4,
      "y": 59,
      "z": -7,
      "name": "Plant_Leaves_Beech",
      "support": 15
    },
    {
      "x": -4,
      "y": 60,
      "z": -7,
      "name": "Plant_Leaves_Beech",
      "support": 15
    },
    {
      "x": -4,
      "y": 61,
      "z": -7,
      "name": "Plant_Leaves_Beech",
      "support": 15
    },
    {
      "x": -4,
      "y": 54,
      "z": -6,
      "name": "Wood_Sallow_Branch_Corner",
      "support": 15,
      "rotation": 24
    },
    {
      "x": -4,
      "y": 57,
      "z": -6,
      "name": "Plant_Leaves_Beech",
      "support": 15
    },
    {
      "x": -4,
      "y": 58,
      "z": -6,
      "name": "Plant_Leaves_Beech",
      "support": 15
    },
    {
      "x": -4,
      "y": 60,
      "z": -6,
      "name": "Plant_Leaves_Beech",
      "support": 15
    },
    {
      "x": -4,
      "y": 10,
      "z": -5,
      "name": "Plant_Moss_Wall_Green_Dark",
      "support": 15,
      "rotation": 2
    },
    {
      "x": -4,
      "y": 54,
      "z": -5,
      "name": "Wood_Sallow_Branch_Corner",
      "support": 15,
      "rotation": 19
    },
    {
      "x": -4,
      "y": 56,
      "z": -5,
      "name": "Plant_Leaves_Beech",
      "support": 15
    },
    {
      "x": -4,
      "y": 57,
      "z": -5,
      "name": "Wood_Sallow_Branch_Corner",
      "support": 15,
      "rotation": 2
    },
    {
      "x": -4,
      "y": 58,
      "z": -5,
      "name": "Wood_Sallow_Branch_Long",
      "support": 15
    },
    {
      "x": -4,
      "y": 59,
      "z": -5,
      "name": "Plant_Leaves_Beech",
      "support": 15
    },
    {
      "x": -4,
      "y": 62,
      "z": -5,
      "name": "Plant_Leaves_Beech",
      "support": 15
    },
    {
      "x": -4,
      "y": 63,
      "z": -5,
      "name": "Plant_Leaves_Beech",
      "support": 15
    },
    {
      "x": -4,
      "y": 4,
      "z": -4,
      "name": "Wood_Sallow_Roots"
    },
    {
      "x": -4,
      "y": 5,
      "z": -4,
      "name": "Wood_Sallow_Trunk_Full",
      "support": 15
    },
    {
      "x": -4,
      "y": 6,
      "z": -4,
      "name": "Wood_Sallow_Trunk",
      "support": 15
    },
    {
      "x": -4,
      "y": 7,
      "z": -4,
      "name": "Wood_Sallow_Trunk",
      "support": 15
    },
    {
      "x": -4,
      "y": 8,
      "z": -4,
      "name": "Wood_Sallow_Trunk",
      "support": 15
    },
    {
      "x": -4,
      "y": 9,
      "z": -4,
      "name": "Wood_Sallow_Trunk",
      "support": 15
    },
    {
      "x": -4,
      "y": 10,
      "z": -4,
      "name": "Wood_Sallow_Trunk_Full",
      "support": 15
    },
    {
      "x": -4,
      "y": 11,
      "z": -4,
      "name": "Plant_Moss_Rug_Green_Dark",
      "support": 15
    },
    {
      "x": -4,
      "y": 56,
      "z": -4,
      "name": "Plant_Leaves_Beech",
      "support": 15
    },
    {
      "x": -4,
      "y": 57,
      "z": -4,
      "name": "Wood_Sallow_Branch_Long",
      "support": 15,
      "rotation": 4
    },
    {
      "x": -4,
      "y": 58,
      "z": -4,
      "name": "Plant_Leaves_Beech",
      "support": 15
    },
    {
      "x": -4,
      "y": 61,
      "z": -4,
      "name": "Plant_Leaves_Beech",
      "support": 15
    },
    {
      "x": -4,
      "y": 62,
      "z": -4,
      "name": "Wood_Sallow_Branch_Corner",
      "support": 15,
      "rotation": 3
    },
    {
      "x": -4,
      "y": 63,
      "z": -4,
      "name": "Wood_Sallow_Branch_Long",
      "support": 15
    },
    {
      "x": -4,
      "y": 64,
      "z": -4,
      "name": "Plant_Leaves_Beech",
      "support": 15
    },
    {
      "x": -4,
      "y": 57,
      "z": -3,
      "name": "Wood_Sallow_Branch_Corner",
      "support": 15,
      "rotation": 27
    },
    {
      "x": -4,
      "y": 62,
      "z": -3,
      "name": "Plant_Leaves_Beech",
      "support": 15
    },
    {
      "x": -4,
      "y": 63,
      "z": -3,
      "name": "Plant_Leaves_Beech",
      "support": 15
    },
    {
      "x": -4,
      "y": 56,
      "z": -2,
      "name": "Wood_Sallow_Trunk",
      "support": 15,
      "rotation": 5
    },
    {
      "x": -4,
      "y": 56,
      "z": -1,
      "name": "Wood_Sallow_Branch_Corner",
      "support": 15
    },
    {
      "x": -4,
      "y": 57,
      "z": -1,
      "name": "Wood_Sallow_Branch_Corner",
      "support": 15,
      "rotation": 8
    },
    {
      "x": -4,
      "y": 11,
      "z": 0,
      "name": "Plant_Moss_Wall_Green_Dark",
      "support": 15,
      "rotation": 2
    },
    {
      "x": -4,
      "y": 57,
      "z": 0,
      "name": "Wood_Sallow_Branch_Long",
      "support": 15,
      "rotation": 4
    },
    {
      "x": -4,
      "y": 58,
      "z": 0,
      "name": "Plant_Leaves_Beech",
      "support": 15
    },
    {
      "x": -4,
      "y": 5,
      "z": 1,
      "name": "Wood_Sallow_Roots"
    },
    {
      "x": -4,
      "y": 6,
      "z": 1,
      "name": "Wood_Sallow_Trunk_Full",
      "support": 15
    },
    {
      "x": -4,
      "y": 7,
      "z": 1,
      "name": "Wood_Sallow_Trunk",
      "support": 15
    },
    {
      "x": -4,
      "y": 8,
      "z": 1,
      "name": "Wood_Sallow_Trunk",
      "support": 15
    },
    {
      "x": -4,
      "y": 9,
      "z": 1,
      "name": "Wood_Sallow_Trunk",
      "support": 15
    },
    {
      "x": -4,
      "y": 10,
      "z": 1,
      "name": "Wood_Sallow_Trunk",
      "support": 15
    },
    {
      "x": -4,
      "y": 11,
      "z": 1,
      "name": "Wood_Sallow_Trunk_Full",
      "support": 15
    },
    {
      "x": -4,
      "y": 12,
      "z": 1,
      "name": "Plant_Moss_Rug_Green_Dark",
      "support": 15
    },
    {
      "x": -4,
      "y": 57,
      "z": 1,
      "name": "Wood_Sallow_Branch_Corner",
      "support": 15
    },
    {
      "x": -4,
      "y": 58,
      "z": 1,
      "name": "Wood_Sallow_Branch_Corner",
      "support": 15,
      "rotation": 11
    },
    {
      "x": -4,
      "y": 59,
      "z": 1,
      "name": "Plant_Leaves_Beech",
      "support": 15
    },
    {
      "x": -4,
      "y": 60,
      "z": 1,
      "name": "Plant_Leaves_Beech",
      "support": 15
    },
    {
      "x": -4,
      "y": 61,
      "z": 1,
      "name": "Plant_Leaves_Beech",
      "support": 15
    },
    {
      "x": -4,
      "y": 11,
      "z": 2,
      "name": "Plant_Moss_Wall_Green_Dark",
      "support": 15
    },
    {
      "x": -4,
      "y": 52,
      "z": 2,
      "name": "Wood_Sallow_Trunk_Full",
      "support": 15,
      "rotation": 5
    },
    {
      "x": -4,
      "y": 53,
      "z": 2,
      "name": "Wood_Sallow_Trunk_Full",
      "support": 15,
      "rotation": 5
    },
    {
      "x": -4,
      "y": 58,
      "z": 2,
      "name": "Plant_Leaves_Beech",
      "support": 15
    },
    {
      "x": -4,
      "y": 4,
      "z": 3,
      "name": "Wood_Sallow_Roots"
    },
    {
      "x": -4,
      "y": 5,
      "z": 3,
      "name": "Wood_Sallow_Trunk_Full",
      "support": 15
    },
    {
      "x": -4,
      "y": 6,
      "z": 3,
      "name": "Wood_Sallow_Trunk",
      "support": 15
    },
    {
      "x": -4,
      "y": 7,
      "z": 3,
      "name": "Wood_Sallow_Trunk",
      "support": 15
    },
    {
      "x": -4,
      "y": 8,
      "z": 3,
      "name": "Wood_Sallow_Trunk",
      "support": 15
    },
    {
      "x": -4,
      "y": 9,
      "z": 3,
      "name": "Wood_Sallow_Trunk",
      "support": 15
    },
    {
      "x": -4,
      "y": 10,
      "z": 3,
      "name": "Wood_Sallow_Trunk_Full",
      "support": 15
    },
    {
      "x": -4,
      "y": 58,
      "z": 3,
      "name": "Wood_Sallow_Branch_Corner",
      "support": 15,
      "rotation": 24
    },
    {
      "x": -4,
      "y": 3,
      "z": 4,
      "name": "Wood_Sallow_Roots"
    },
    {
      "x": -4,
      "y": 4,
      "z": 4,
      "name": "Wood_Sallow_Trunk_Full",
      "support": 15
    },
    {
      "x": -4,
      "y": 5,
      "z": 4,
      "name": "Wood_Sallow_Trunk",
      "support": 15
    },
    {
      "x": -4,
      "y": 6,
      "z": 4,
      "name": "Wood_Sallow_Trunk",
      "support": 15
    },
    {
      "x": -4,
      "y": 7,
      "z": 4,
      "name": "Wood_Sallow_Trunk",
      "support": 15
    },
    {
      "x": -4,
      "y": 8,
      "z": 4,
      "name": "Wood_Sallow_Trunk",
      "support": 15
    },
    {
      "x": -4,
      "y": 9,
      "z": 4,
      "name": "Wood_Sallow_Trunk",
      "support": 15
    },
    {
      "x": -4,
      "y": 10,
      "z": 4,
      "name": "Wood_Sallow_Trunk_Full",
      "support": 15
    },
    {
      "x": -4,
      "y": 58,
      "z": 4,
      "name": "Wood_Sallow_Branch_Corner",
      "support": 15,
      "rotation": 19
    },
    {
      "x": -4,
      "y": 62,
      "z": 4,
      "name": "Plant_Leaves_Beech",
      "support": 15
    },
    {
      "x": -4,
      "y": 63,
      "z": 4,
      "name": "Plant_Leaves_Beech",
      "support": 15
    },
    {
      "x": -4,
      "y": 52,
      "z": 5,
      "name": "Plant_Leaves_Beech",
      "support": 15
    },
    {
      "x": -4,
      "y": 53,
      "z": 5,
      "name": "Plant_Leaves_Beech",
      "support": 15
    },
    {
      "x": -4,
      "y": 51,
      "z": 6,
      "name": "Plant_Leaves_Beech",
      "support": 15
    },
    {
      "x": -4,
      "y": 52,
      "z": 6,
      "name": "Wood_Sallow_Branch_Corner",
      "support": 15,
      "rotation": 3
    },
    {
      "x": -4,
      "y": 53,
      "z": 6,
      "name": "Wood_Sallow_Branch_Long",
      "support": 15
    },
    {
      "x": -4,
      "y": 54,
      "z": 6,
      "name": "Plant_Leaves_Beech",
      "support": 15
    },
    {
      "x": -4,
      "y": 58,
      "z": 6,
      "name": "Wood_Sallow_Trunk",
      "support": 15,
      "rotation": 5
    },
    {
      "x": -4,
      "y": 52,
      "z": 7,
      "name": "Plant_Leaves_Beech",
      "support": 15
    },
    {
      "x": -4,
      "y": 53,
      "z": 7,
      "name": "Plant_Leaves_Beech",
      "support": 15
    },
    {
      "x": -4,
      "y": 58,
      "z": 7,
      "name": "Plant_Leaves_Beech",
      "support": 15
    },
    {
      "x": -4,
      "y": 58,
      "z": 8,
      "name": "Plant_Leaves_Beech",
      "support": 15
    },
    {
      "x": -4,
      "y": 59,
      "z": 8,
      "name": "Plant_Leaves_Beech",
      "support": 15
    },
    {
      "x": -3,
      "y": 55,
      "z": -9,
      "name": "Plant_Leaves_Beech",
      "support": 15
    },
    {
      "x": -3,
      "y": 56,
      "z": -9,
      "name": "Plant_Leaves_Beech",
      "support": 15
    },
    {
      "x": -3,
      "y": 55,
      "z": -8,
      "name": "Wood_Sallow_Branch_Long",
      "support": 15,
      "rotation": 5
    },
    {
      "x": -3,
      "y": 56,
      "z": -8,
      "name": "Plant_Leaves_Beech",
      "support": 15
    },
    {
      "x": -3,
      "y": 60,
      "z": -8,
      "name": "Plant_Leaves_Beech",
      "support": 15
    },
    {
      "x": -3,
      "y": 61,
      "z": -8,
      "name": "Plant_Leaves_Beech",
      "support": 15
    },
    {
      "x": -3,
      "y": 55,
      "z": -7,
      "name": "Plant_Leaves_Beech",
      "support": 15
    },
    {
      "x": -3,
      "y": 59,
      "z": -7,
      "name": "Plant_Leaves_Beech",
      "support": 15
    },
    {
      "x": -3,
      "y": 60,
      "z": -7,
      "name": "Wood_Sallow_Branch_Corner",
      "support": 15,
      "rotation": 2
    },
    {
      "x": -3,
      "y": 61,
      "z": -7,
      "name": "Wood_Sallow_Branch_Long",
      "support": 15
    },
    {
      "x": -3,
      "y": 62,
      "z": -7,
      "name": "Plant_Leaves_Beech",
      "support": 15
    },
    {
      "x": -3,
      "y": 60,
      "z": -6,
      "name": "Wood_Sallow_Branch_Long",
      "support": 15,
      "rotation": 4
    },
    {
      "x": -3,
      "y": 61,
      "z": -6,
      "name": "Plant_Leaves_Beech",
      "support": 15
    },
    {
      "x": -3,
      "y": 54,
      "z": -5,
      "name": "Wood_Sallow_Branch_Long",
      "support": 15,
      "rotation": 5
    },
    {
      "x": -3,
      "y": 57,
      "z": -5,
      "name": "Plant_Leaves_Beech",
      "support": 15
    },
    {
      "x": -3,
      "y": 58,
      "z": -5,
      "name": "Plant_Leaves_Beech",
      "support": 15
    },
    {
      "x": -3,
      "y": 60,
      "z": -5,
      "name": "Wood_Sallow_Branch_Long",
      "support": 15,
      "rotation": 4
    },
    {
      "x": -3,
      "y": 62,
      "z": -5,
      "name": "Plant_Leaves_Beech",
      "support": 15
    },
    {
      "x": -3,
      "y": 10,
      "z": -4,
      "name": "Plant_Moss_Wall_Green_Dark",
      "support": 15,
      "rotation": 1
    },
    {
      "x": -3,
      "y": 57,
      "z": -4,
      "name": "Plant_Leaves_Beech",
      "support": 15
    },
    {
      "x": -3,
      "y": 60,
      "z": -4,
      "name": "Wood_Sallow_Branch_Corner",
      "support": 15,
      "rotation": 19
    },
    {
      "x": -3,
      "y": 62,
      "z": -4,
      "name": "Wood_Sallow_Branch_Long",
      "support": 15,
      "rotation": 5
    },
    {
      "x": -3,
      "y": 63,
      "z": -4,
      "name": "Plant_Leaves_Beech",
      "support": 15
    },
    {
      "x": -3,
      "y": 5,
      "z": -3,
      "name": "Wood_Sallow_Roots"
    },
    {
      "x": -3,
      "y": 6,
      "z": -3,
      "name": "Wood_Sallow_Trunk_Full",
      "support": 15
    },
    {
      "x": -3,
      "y": 7,
      "z": -3,
      "name": "Wood_Sallow_Trunk",
      "support": 15
    },
    {
      "x": -3,
      "y": 8,
      "z": -3,
      "name": "Wood_Sallow_Trunk",
      "support": 15
    },
    {
      "x": -3,
      "y": 9,
      "z": -3,
      "name": "Wood_Sallow_Trunk",
      "support": 15
    },
    {
      "x": -3,
      "y": 10,
      "z": -3,
      "name": "Wood_Sallow_Trunk",
      "support": 15
    },
    {
      "x": -3,
      "y": 11,
      "z": -3,
      "name": "Wood_Sallow_Trunk_Full",
      "support": 15
    },
    {
      "x": -3,
      "y": 12,
      "z": -3,
      "name": "Plant_Moss_Wall_Green_Dark",
      "support": 15,
      "rotation": 3
    },
    {
      "x": -3,
      "y": 62,
      "z": -3,
      "name": "Plant_Leaves_Beech",
      "support": 15
    },
    {
      "x": -3,
      "y": 55,
      "z": -2,
      "name": "Wood_Sallow_Trunk_Full",
      "support": 15,
      "rotation": 4
    },
    {
      "x": -3,
      "y": 56,
      "z": -2,
      "name": "Wood_Sallow_Trunk_Full",
      "support": 15,
      "rotation": 5
    },
    {
      "x": -3,
      "y": 55,
      "z": -1,
      "name": "Wood_Sallow_Trunk_Full",
      "support": 15,
      "rotation": 5
    },
    {
      "x": -3,
      "y": 63,
      "z": -1,
      "name": "Plant_Leaves_Beech",
      "support": 15
    },
    {
      "x": -3,
      "y": 64,
      "z": -1,
      "name": "Plant_Leaves_Beech",
      "support": 15
    },
    {
      "x": -3,
      "y": 7,
      "z": 0,
      "name": "Wood_Sallow_Trunk_Full",
      "support": 15
    },
    {
      "x": -3,
      "y": 8,
      "z": 0,
      "name": "Wood_Sallow_Trunk",
      "support": 15
    },
    {
      "x": -3,
      "y": 9,
      "z": 0,
      "name": "Wood_Sallow_Trunk",
      "support": 15
    },
    {
      "x": -3,
      "y": 10,
      "z": 0,
      "name": "Wood_Sallow_Trunk",
      "support": 15
    },
    {
      "x": -3,
      "y": 11,
      "z": 0,
      "name": "Wood_Sallow_Trunk_Full",
      "support": 15
    },
    {
      "x": -3,
      "y": 12,
      "z": 0,
      "name": "Plant_Moss_Wall_Green_Dark",
      "support": 15,
      "rotation": 3
    },
    {
      "x": -3,
      "y": 60,
      "z": 0,
      "name": "Plant_Leaves_Beech",
      "support": 15
    },
    {
      "x": -3,
      "y": 61,
      "z": 0,
      "name": "Plant_Leaves_Beech",
      "support": 15
    },
    {
      "x": -3,
      "y": 6,
      "z": 1,
      "name": "Wood_Sallow_Roots"
    },
    {
      "x": -3,
      "y": 7,
      "z": 1,
      "name": "Wood_Sallow_Trunk_Full",
      "support": 15
    },
    {
      "x": -3,
      "y": 8,
      "z": 1,
      "name": "Wood_Sallow_Trunk",
      "support": 15
    },
    {
      "x": -3,
      "y": 9,
      "z": 1,
      "name": "Wood_Sallow_Trunk",
      "support": 15
    },
    {
      "x": -3,
      "y": 10,
      "z": 1,
      "name": "Wood_Sallow_Trunk",
      "support": 15
    },
    {
      "x": -3,
      "y": 11,
      "z": 1,
      "name": "Wood_Sallow_Trunk",
      "support": 15
    },
    {
      "x": -3,
      "y": 12,
      "z": 1,
      "name": "Wood_Sallow_Trunk_Full",
      "support": 15
    },
    {
      "x": -3,
      "y": 13,
      "z": 1,
      "name": "Plant_Moss_Rug_Green_Dark",
      "support": 15
    },
    {
      "x": -3,
      "y": 59,
      "z": 1,
      "name": "Plant_Leaves_Beech",
      "support": 15
    },
    {
      "x": -3,
      "y": 60,
      "z": 1,
      "name": "Wood_Sallow_Branch_Corner",
      "support": 15,
      "rotation": 3
    },
    {
      "x": -3,
      "y": 61,
      "z": 1,
      "name": "Wood_Sallow_Branch_Long",
      "support": 15
    },
    {
      "x": -3,
      "y": 62,
      "z": 1,
      "name": "Plant_Leaves_Beech",
      "support": 15
    },
    {
      "x": -3,
      "y": 5,
      "z": 2,
      "name": "Wood_Sallow_Roots"
    },
    {
      "x": -3,
      "y": 6,
      "z": 2,
      "name": "Wood_Sallow_Trunk_Full",
      "support": 15
    },
    {
      "x": -3,
      "y": 7,
      "z": 2,
      "name": "Wood_Sallow_Trunk",
      "support": 15
    },
    {
      "x": -3,
      "y": 8,
      "z": 2,
      "name": "Wood_Sallow_Trunk",
      "support": 15
    },
    {
      "x": -3,
      "y": 9,
      "z": 2,
      "name": "Wood_Sallow_Trunk",
      "support": 15
    },
    {
      "x": -3,
      "y": 10,
      "z": 2,
      "name": "Wood_Sallow_Trunk",
      "support": 15
    },
    {
      "x": -3,
      "y": 11,
      "z": 2,
      "name": "Wood_Sallow_Trunk_Full",
      "support": 15
    },
    {
      "x": -3,
      "y": 12,
      "z": 2,
      "name": "Plant_Moss_Wall_Green_Dark",
      "support": 15
    },
    {
      "x": -3,
      "y": 52,
      "z": 2,
      "name": "Wood_Sallow_Trunk",
      "support": 15,
      "rotation": 5
    },
    {
      "x": -3,
      "y": 60,
      "z": 2,
      "name": "Plant_Leaves_Beech",
      "support": 15
    },
    {
      "x": -3,
      "y": 61,
      "z": 2,
      "name": "Plant_Leaves_Beech",
      "support": 15
    },
    {
      "x": -3,
      "y": 5,
      "z": 3,
      "name": "Wood_Sallow_Roots"
    },
    {
      "x": -3,
      "y": 6,
      "z": 3,
      "name": "Wood_Sallow_Trunk_Full",
      "support": 15
    },
    {
      "x": -3,
      "y": 7,
      "z": 3,
      "name": "Wood_Sallow_Trunk",
      "support": 15
    },
    {
      "x": -3,
      "y": 8,
      "z": 3,
      "name": "Wood_Sallow_Trunk",
      "support": 15
    },
    {
      "x": -3,
      "y": 9,
      "z": 3,
      "name": "Wood_Sallow_Trunk",
      "support": 15
    },
    {
      "x": -3,
      "y": 10,
      "z": 3,
      "name": "Wood_Sallow_Trunk",
      "support": 15
    },
    {
      "x": -3,
      "y": 11,
      "z": 3,
      "name": "Wood_Sallow_Trunk_Full",
      "support": 15
    },
    {
      "x": -3,
      "y": 42,
      "z": 3,
      "name": "Plant_Vine_Liana_End",
      "support": 15
    },
    {
      "x": -3,
      "y": 43,
      "z": 3,
      "name": "Plant_Vine_Liana_End",
      "support": 15
    },
    {
      "x": -3,
      "y": 44,
      "z": 3,
      "name": "Plant_Vine_Liana_End",
      "support": 15
    },
    {
      "x": -3,
      "y": 45,
      "z": 3,
      "name": "Plant_Vine_Liana_End",
      "support": 15
    },
    {
      "x": -3,
      "y": 46,
      "z": 3,
      "name": "Plant_Vine_Liana_End",
      "support": 15
    },
    {
      "x": -3,
      "y": 47,
      "z": 3,
      "name": "Plant_Vine_Liana_End",
      "support": 15
    },
    {
      "x": -3,
      "y": 48,
      "z": 3,
      "name": "Plant_Vine_Liana_End",
      "support": 15
    },
    {
      "x": -3,
      "y": 49,
      "z": 3,
      "name": "Plant_Vine_Liana_End",
      "support": 15
    },
    {
      "x": -3,
      "y": 50,
      "z": 3,
      "name": "Plant_Vine_Liana_End",
      "support": 15
    },
    {
      "x": -3,
      "y": 51,
      "z": 3,
      "name": "Plant_Vine_Liana_End",
      "support": 15
    },
    {
      "x": -3,
      "y": 52,
      "z": 3,
      "name": "Plant_Vine_Liana_End",
      "support": 15
    },
    {
      "x": -3,
      "y": 62,
      "z": 3,
      "name": "Plant_Leaves_Beech",
      "support": 15
    },
    {
      "x": -3,
      "y": 63,
      "z": 3,
      "name": "Plant_Leaves_Beech",
      "support": 15
    },
    {
      "x": -3,
      "y": 6,
      "z": 4,
      "name": "Wood_Sallow_Trunk_Full",
      "support": 15
    },
    {
      "x": -3,
      "y": 7,
      "z": 4,
      "name": "Wood_Sallow_Trunk",
      "support": 15
    },
    {
      "x": -3,
      "y": 8,
      "z": 4,
      "name": "Wood_Sallow_Trunk",
      "support": 15
    },
    {
      "x": -3,
      "y": 9,
      "z": 4,
      "name": "Wood_Sallow_Trunk",
      "support": 15
    },
    {
      "x": -3,
      "y": 10,
      "z": 4,
      "name": "Wood_Sallow_Trunk_Full",
      "support": 15
    },
    {
      "x": -3,
      "y": 11,
      "z": 4,
      "name": "Plant_Moss_Rug_Green_Dark",
      "support": 15
    },
    {
      "x": -3,
      "y": 52,
      "z": 4,
      "name": "Wood_Sallow_Branch_Corner",
      "support": 15,
      "rotation": 25
    },
    {
      "x": -3,
      "y": 58,
      "z": 4,
      "name": "Wood_Sallow_Branch_Long",
      "support": 15,
      "rotation": 5
    },
    {
      "x": -3,
      "y": 62,
      "z": 4,
      "name": "Wood_Sallow_Branch_Corner",
      "support": 15,
      "rotation": 3
    },
    {
      "x": -3,
      "y": 63,
      "z": 4,
      "name": "Wood_Sallow_Branch_Long",
      "support": 15
    },
    {
      "x": -3,
      "y": 64,
      "z": 4,
      "name": "Plant_Leaves_Beech",
      "support": 15
    },
    {
      "x": -3,
      "y": 52,
      "z": 5,
      "name": "Wood_Sallow_Branch_Long",
      "support": 15,
      "rotation": 4
    },
    {
      "x": -3,
      "y": 60,
      "z": 5,
      "name": "Plant_Leaves_Beech",
      "support": 15
    },
    {
      "x": -3,
      "y": 62,
      "z": 5,
      "name": "Plant_Leaves_Beech",
      "support": 15
    },
    {
      "x": -3,
      "y": 63,
      "z": 5,
      "name": "Plant_Leaves_Beech",
      "support": 15
    },
    {
      "x": -3,
      "y": 52,
      "z": 6,
      "name": "Wood_Sallow_Branch_Corner",
      "support": 15,
      "rotation": 16
    },
    {
      "x": -3,
      "y": 53,
      "z": 6,
      "name": "Plant_Leaves_Beech",
      "support": 15
    },
    {
      "x": -3,
      "y": 58,
      "z": 6,
      "name": "Wood_Sallow_Trunk",
      "support": 15,
      "rotation": 5
    },
    {
      "x": -3,
      "y": 52,
      "z": 7,
      "name": "Plant_Leaves_Beech",
      "support": 15
    },
    {
      "x": -3,
      "y": 57,
      "z": 7,
      "name": "Plant_Leaves_Beech",
      "support": 15
    },
    {
      "x": -3,
      "y": 58,
      "z": 7,
      "name": "Wood_Sallow_Branch_Long",
      "support": 15,
      "rotation": 4
    },
    {
      "x": -3,
      "y": 59,
      "z": 7,
      "name": "Plant_Leaves_Beech",
      "support": 15
    },
    {
      "x": -3,
      "y": 2,
      "z": 8,
      "name": "Wood_Sallow_Roots"
    },
    {
      "x": -3,
      "y": 3,
      "z": 8,
      "name": "Wood_Sallow_Trunk_Full",
      "support": 15
    },
    {
      "x": -3,
      "y": 4,
      "z": 8,
      "name": "Wood_Sallow_Trunk",
      "support": 15
    },
    {
      "x": -3,
      "y": 5,
      "z": 8,
      "name": "Wood_Sallow_Trunk",
      "support": 15
    },
    {
      "x": -3,
      "y": 6,
      "z": 8,
      "name": "Wood_Sallow_Trunk",
      "support": 15
    },
    {
      "x": -3,
      "y": 7,
      "z": 8,
      "name": "Wood_Sallow_Trunk",
      "support": 15
    },
    {
      "x": -3,
      "y": 8,
      "z": 8,
      "name": "Wood_Sallow_Trunk_Full",
      "support": 15
    },
    {
      "x": -3,
      "y": 57,
      "z": 8,
      "name": "Plant_Leaves_Beech",
      "support": 15
    },
    {
      "x": -3,
      "y": 58,
      "z": 8,
      "name": "Wood_Sallow_Branch_Corner",
      "support": 15
    },
    {
      "x": -3,
      "y": 59,
      "z": 8,
      "name": "Wood_Sallow_Branch_Long",
      "support": 15
    },
    {
      "x": -3,
      "y": 60,
      "z": 8,
      "name": "Plant_Leaves_Beech",
      "support": 15
    },
    {
      "x": -3,
      "y": 58,
      "z": 9,
      "name": "Plant_Leaves_Beech",
      "support": 15
    },
    {
      "x": -3,
      "y": 59,
      "z": 9,
      "name": "Plant_Leaves_Beech",
      "support": 15
    },
    {
      "x": -2,
      "y": 55,
      "z": -10,
      "name": "Plant_Leaves_Beech",
      "support": 15
    },
    {
      "x": -2,
      "y": 56,
      "z": -10,
      "name": "Plant_Leaves_Beech",
      "support": 15
    },
    {
      "x": -2,
      "y": 8,
      "z": -9,
      "name": "Plant_Moss_Wall_Green_Dark",
      "support": 15,
      "rotation": 2
    },
    {
      "x": -2,
      "y": 55,
      "z": -9,
      "name": "Plant_Leaves_Beech",
      "support": 15
    },
    {
      "x": -2,
      "y": 2,
      "z": -8,
      "name": "Wood_Sallow_Roots"
    },
    {
      "x": -2,
      "y": 3,
      "z": -8,
      "name": "Wood_Sallow_Trunk_Full",
      "support": 15
    },
    {
      "x": -2,
      "y": 4,
      "z": -8,
      "name": "Wood_Sallow_Trunk",
      "support": 15
    },
    {
      "x": -2,
      "y": 5,
      "z": -8,
      "name": "Wood_Sallow_Trunk",
      "support": 15
    },
    {
      "x": -2,
      "y": 6,
      "z": -8,
      "name": "Wood_Sallow_Trunk",
      "support": 15
    },
    {
      "x": -2,
      "y": 7,
      "z": -8,
      "name": "Wood_Sallow_Trunk",
      "support": 15
    },
    {
      "x": -2,
      "y": 8,
      "z": -8,
      "name": "Wood_Sallow_Trunk_Full",
      "support": 15
    },
    {
      "x": -2,
      "y": 9,
      "z": -8,
      "name": "Plant_Moss_Rug_Green_Dark",
      "support": 15
    },
    {
      "x": -2,
      "y": 55,
      "z": -8,
      "name": "Wood_Sallow_Branch_Corner",
      "support": 15,
      "rotation": 24
    },
    {
      "x": -2,
      "y": 3,
      "z": -7,
      "name": "Wood_Sallow_Roots"
    },
    {
      "x": -2,
      "y": 4,
      "z": -7,
      "name": "Wood_Sallow_Trunk_Full",
      "support": 15
    },
    {
      "x": -2,
      "y": 5,
      "z": -7,
      "name": "Wood_Sallow_Trunk",
      "support": 15
    },
    {
      "x": -2,
      "y": 6,
      "z": -7,
      "name": "Wood_Sallow_Trunk",
      "support": 15
    },
    {
      "x": -2,
      "y": 7,
      "z": -7,
      "name": "Wood_Sallow_Trunk",
      "support": 15
    },
    {
      "x": -2,
      "y": 8,
      "z": -7,
      "name": "Wood_Sallow_Trunk",
      "support": 15
    },
    {
      "x": -2,
      "y": 9,
      "z": -7,
      "name": "Wood_Sallow_Trunk_Full",
      "support": 15
    },
    {
      "x": -2,
      "y": 10,
      "z": -7,
      "name": "Plant_Moss_Rug_Green_Dark",
      "support": 15
    },
    {
      "x": -2,
      "y": 55,
      "z": -7,
      "name": "Wood_Sallow_Branch_Corner",
      "support": 15,
      "rotation": 19
    },
    {
      "x": -2,
      "y": 60,
      "z": -7,
      "name": "Plant_Leaves_Beech",
      "support": 15
    },
    {
      "x": -2,
      "y": 61,
      "z": -7,
      "name": "Plant_Leaves_Beech",
      "support": 15
    },
    {
      "x": -2,
      "y": 10,
      "z": -6,
      "name": "Plant_Moss_Wall_Green_Dark",
      "support": 15,
      "rotation": 3
    },
    {
      "x": -2,
      "y": 57,
      "z": -6,
      "name": "Plant_Leaves_Beech",
      "support": 15
    },
    {
      "x": -2,
      "y": 60,
      "z": -6,
      "name": "Plant_Leaves_Beech",
      "support": 15
    },
    {
      "x": -2,
      "y": 62,
      "z": -6,
      "name": "Plant_Leaves_Beech",
      "support": 15
    },
    {
      "x": -2,
      "y": 63,
      "z": -6,
      "name": "Plant_Leaves_Beech",
      "support": 15
    },
    {
      "x": -2,
      "y": 54,
      "z": -5,
      "name": "Wood_Sallow_Branch_Long",
      "support": 15,
      "rotation": 5
    },
    {
      "x": -2,
      "y": 62,
      "z": -5,
      "name": "Plant_Leaves_Beech",
      "support": 15
    },
    {
      "x": -2,
      "y": 60,
      "z": -4,
      "name": "Wood_Sallow_Branch_Corner",
      "support": 15,
      "rotation": 24
    },
    {
      "x": -2,
      "y": 62,
      "z": -4,
      "name": "Wood_Sallow_Branch_Long",
      "support": 15,
      "rotation": 5
    },
    {
      "x": -2,
      "y": 64,
      "z": -4,
      "name": "Plant_Leaves_Beech",
      "support": 15
    },
    {
      "x": -2,
      "y": 5,
      "z": -3,
      "name": "Wood_Sallow_Roots"
    },
    {
      "x": -2,
      "y": 6,
      "z": -3,
      "name": "Wood_Sallow_Trunk_Full",
      "support": 15
    },
    {
      "x": -2,
      "y": 7,
      "z": -3,
      "name": "Wood_Sallow_Trunk",
      "support": 15
    },
    {
      "x": -2,
      "y": 8,
      "z": -3,
      "name": "Wood_Sallow_Trunk",
      "support": 15
    },
    {
      "x": -2,
      "y": 9,
      "z": -3,
      "name": "Wood_Sallow_Trunk",
      "support": 15
    },
    {
      "x": -2,
      "y": 10,
      "z": -3,
      "name": "Wood_Sallow_Trunk",
      "support": 15
    },
    {
      "x": -2,
      "y": 11,
      "z": -3,
      "name": "Wood_Sallow_Trunk",
      "support": 15
    },
    {
      "x": -2,
      "y": 12,
      "z": -3,
      "name": "Wood_Sallow_Trunk_Full",
      "support": 15
    },
    {
      "x": -2,
      "y": 13,
      "z": -3,
      "name": "Plant_Moss_Rug_Green_Dark",
      "support": 15
    },
    {
      "x": -2,
      "y": 60,
      "z": -3,
      "name": "Wood_Sallow_Branch_Long",
      "support": 15,
      "rotation": 4
    },
    {
      "x": -2,
      "y": 6,
      "z": -2,
      "name": "Wood_Sallow_Trunk_Full",
      "support": 15
    },
    {
      "x": -2,
      "y": 7,
      "z": -2,
      "name": "Wood_Sallow_Trunk",
      "support": 15
    },
    {
      "x": -2,
      "y": 8,
      "z": -2,
      "name": "Wood_Sallow_Trunk",
      "support": 15
    },
    {
      "x": -2,
      "y": 9,
      "z": -2,
      "name": "Wood_Sallow_Trunk",
      "support": 15
    },
    {
      "x": -2,
      "y": 10,
      "z": -2,
      "name": "Wood_Sallow_Trunk",
      "support": 15
    },
    {
      "x": -2,
      "y": 11,
      "z": -2,
      "name": "Wood_Sallow_Trunk_Full",
      "support": 15
    },
    {
      "x": -2,
      "y": 12,
      "z": -2,
      "name": "Plant_Moss_Rug_Green_Dark",
      "support": 15
    },
    {
      "x": -2,
      "y": 60,
      "z": -2,
      "name": "Wood_Sallow_Branch_Corner",
      "support": 15,
      "rotation": 26
    },
    {
      "x": -2,
      "y": 62,
      "z": -2,
      "name": "Wood_Sallow_Branch_Corner",
      "support": 15,
      "rotation": 25
    },
    {
      "x": -2,
      "y": 63,
      "z": -2,
      "name": "Plant_Leaves_Beech",
      "support": 15
    },
    {
      "x": -2,
      "y": 64,
      "z": -2,
      "name": "Plant_Leaves_Beech",
      "support": 15
    },
    {
      "x": -2,
      "y": 6,
      "z": -1,
      "name": "Wood_Sallow_Trunk_Full",
      "support": 15
    },
    {
      "x": -2,
      "y": 7,
      "z": -1,
      "name": "Wood_Sallow_Trunk",
      "support": 15
    },
    {
      "x": -2,
      "y": 8,
      "z": -1,
      "name": "Wood_Sallow_Trunk",
      "support": 15
    },
    {
      "x": -2,
      "y": 9,
      "z": -1,
      "name": "Wood_Sallow_Trunk",
      "support": 15
    },
    {
      "x": -2,
      "y": 10,
      "z": -1,
      "name": "Wood_Sallow_Trunk_Full",
      "support": 15
    },
    {
      "x": -2,
      "y": 34,
      "z": -1,
      "name": "Wood_Sallow_Branch_Short",
      "support": 15,
      "rotation": 3
    },
    {
      "x": -2,
      "y": 42,
      "z": -1,
      "name": "Wood_Sallow_Branch_Short",
      "support": 15,
      "rotation": 3
    },
    {
      "x": -2,
      "y": 55,
      "z": -1,
      "name": "Wood_Sallow_Trunk_Full",
      "support": 15
    },
    {
      "x": -2,
      "y": 62,
      "z": -1,
      "name": "Wood_Sallow_Branch_Corner",
      "support": 15
    },
    {
      "x": -2,
      "y": 63,
      "z": -1,
      "name": "Wood_Sallow_Branch_Long",
      "support": 15
    },
    {
      "x": -2,
      "y": 64,
      "z": -1,
      "name": "Wood_Sallow_Branch_Long",
      "support": 15
    },
    {
      "x": -2,
      "y": 65,
      "z": -1,
      "name": "Plant_Leaves_Beech",
      "support": 15
    },
    {
      "x": -2,
      "y": 6,
      "z": 0,
      "name": "Wood_Sallow_Roots"
    },
    {
      "x": -2,
      "y": 7,
      "z": 0,
      "name": "Wood_Sallow_Trunk_Full",
      "support": 15
    },
    {
      "x": -2,
      "y": 8,
      "z": 0,
      "name": "Wood_Sallow_Trunk",
      "support": 15
    },
    {
      "x": -2,
      "y": 9,
      "z": 0,
      "name": "Wood_Sallow_Trunk",
      "support": 15
    },
    {
      "x": -2,
      "y": 10,
      "z": 0,
      "name": "Wood_Sallow_Trunk",
      "support": 15
    },
    {
      "x": -2,
      "y": 11,
      "z": 0,
      "name": "Wood_Sallow_Trunk",
      "support": 15
    },
    {
      "x": -2,
      "y": 12,
      "z": 0,
      "name": "Wood_Sallow_Trunk_Full",
      "support": 15
    },
    {
      "x": -2,
      "y": 13,
      "z": 0,
      "name": "Plant_Moss_Rug_Green_Dark",
      "support": 15
    },
    {
      "x": -2,
      "y": 47,
      "z": 0,
      "name": "Wood_Sallow_Trunk_Full",
      "support": 15
    },
    {
      "x": -2,
      "y": 48,
      "z": 0,
      "name": "Wood_Sallow_Trunk",
      "support": 15
    },
    {
      "x": -2,
      "y": 49,
      "z": 0,
      "name": "Wood_Sallow_Trunk",
      "support": 15
    },
    {
      "x": -2,
      "y": 50,
      "z": 0,
      "name": "Wood_Sallow_Trunk",
      "support": 15
    },
    {
      "x": -2,
      "y": 51,
      "z": 0,
      "name": "Wood_Sallow_Trunk",
      "support": 15
    },
    {
      "x": -2,
      "y": 52,
      "z": 0,
      "name": "Wood_Sallow_Trunk",
      "support": 15
    },
    {
      "x": -2,
      "y": 53,
      "z": 0,
      "name": "Wood_Sallow_Trunk",
      "support": 15
    },
    {
      "x": -2,
      "y": 54,
      "z": 0,
      "name": "Wood_Sallow_Trunk_Full",
      "support": 15,
      "rotation": 4
    },
    {
      "x": -2,
      "y": 60,
      "z": 0,
      "name": "Plant_Leaves_Beech",
      "support": 15
    },
    {
      "x": -2,
      "y": 63,
      "z": 0,
      "name": "Plant_Leaves_Beech",
      "support": 15
    },
    {
      "x": -2,
      "y": 64,
      "z": 0,
      "name": "Plant_Leaves_Beech",
      "support": 15
    },
    {
      "x": -2,
      "y": 7,
      "z": 1,
      "name": "Wood_Sallow_Trunk_Full",
      "support": 15
    },
    {
      "x": -2,
      "y": 8,
      "z": 1,
      "name": "Wood_Sallow_Trunk",
      "support": 15
    },
    {
      "x": -2,
      "y": 9,
      "z": 1,
      "name": "Wood_Sallow_Trunk",
      "support": 15
    },
    {
      "x": -2,
      "y": 10,
      "z": 1,
      "name": "Wood_Sallow_Trunk",
      "support": 15
    },
    {
      "x": -2,
      "y": 11,
      "z": 1,
      "name": "Wood_Sallow_Trunk",
      "support": 15
    },
    {
      "x": -2,
      "y": 12,
      "z": 1,
      "name": "Wood_Sallow_Trunk",
      "support": 15
    },
    {
      "x": -2,
      "y": 13,
      "z": 1,
      "name": "Wood_Sallow_Trunk_Full",
      "support": 15
    },
    {
      "x": -2,
      "y": 14,
      "z": 1,
      "name": "Plant_Moss_Rug_Green_Dark",
      "support": 15
    },
    {
      "x": -2,
      "y": 29,
      "z": 1,
      "name": "Wood_Sallow_Branch_Short",
      "support": 15,
      "rotation": 3
    },
    {
      "x": -2,
      "y": 33,
      "z": 1,
      "name": "Wood_Sallow_Branch_Short",
      "support": 15,
      "rotation": 3
    },
    {
      "x": -2,
      "y": 49,
      "z": 1,
      "name": "Wood_Sallow_Trunk_Full",
      "support": 15
    },
    {
      "x": -2,
      "y": 50,
      "z": 1,
      "name": "Wood_Sallow_Trunk",
      "support": 15
    },
    {
      "x": -2,
      "y": 51,
      "z": 1,
      "name": "Wood_Sallow_Trunk",
      "support": 15
    },
    {
      "x": -2,
      "y": 52,
      "z": 1,
      "name": "Wood_Sallow_Trunk",
      "support": 15
    },
    {
      "x": -2,
      "y": 53,
      "z": 1,
      "name": "Wood_Sallow_Trunk_Full",
      "support": 15
    },
    {
      "x": -2,
      "y": 59,
      "z": 1,
      "name": "Plant_Leaves_Beech",
      "support": 15
    },
    {
      "x": -2,
      "y": 60,
      "z": 1,
      "name": "Wood_Sallow_Branch_Long",
      "support": 15,
      "rotation": 5
    },
    {
      "x": -2,
      "y": 61,
      "z": 1,
      "name": "Plant_Leaves_Beech",
      "support": 15
    },
    {
      "x": -2,
      "y": 7,
      "z": 2,
      "name": "Wood_Sallow_Trunk_Full",
      "support": 15
    },
    {
      "x": -2,
      "y": 8,
      "z": 2,
      "name": "Wood_Sallow_Trunk",
      "support": 15
    },
    {
      "x": -2,
      "y": 9,
      "z": 2,
      "name": "Wood_Sallow_Trunk",
      "support": 15
    },
    {
      "x": -2,
      "y": 10,
      "z": 2,
      "name": "Wood_Sallow_Trunk",
      "support": 15
    },
    {
      "x": -2,
      "y": 11,
      "z": 2,
      "name": "Wood_Sallow_Trunk",
      "support": 15
    },
    {
      "x": -2,
      "y": 12,
      "z": 2,
      "name": "Wood_Sallow_Trunk",
      "support": 15
    },
    {
      "x": -2,
      "y": 13,
      "z": 2,
      "name": "Wood_Sallow_Trunk",
      "support": 15
    },
    {
      "x": -2,
      "y": 14,
      "z": 2,
      "name": "Wood_Sallow_Trunk",
      "support": 15
    },
    {
      "x": -2,
      "y": 15,
      "z": 2,
      "name": "Wood_Sallow_Trunk",
      "support": 15
    },
    {
      "x": -2,
      "y": 16,
      "z": 2,
      "name": "Wood_Sallow_Trunk_Full",
      "support": 15
    },
    {
      "x": -2,
      "y": 52,
      "z": 2,
      "name": "Wood_Sallow_Trunk_Full",
      "support": 15,
      "rotation": 5
    },
    {
      "x": -2,
      "y": 60,
      "z": 2,
      "name": "Plant_Leaves_Beech",
      "support": 15
    },
    {
      "x": -2,
      "y": 6,
      "z": 3,
      "name": "Wood_Sallow_Trunk_Full",
      "support": 15
    },
    {
      "x": -2,
      "y": 7,
      "z": 3,
      "name": "Wood_Sallow_Trunk",
      "support": 15
    },
    {
      "x": -2,
      "y": 8,
      "z": 3,
      "name": "Wood_Sallow_Trunk",
      "support": 15
    },
    {
      "x": -2,
      "y": 9,
      "z": 3,
      "name": "Wood_Sallow_Trunk",
      "support": 15
    },
    {
      "x": -2,
      "y": 10,
      "z": 3,
      "name": "Wood_Sallow_Trunk",
      "support": 15
    },
    {
      "x": -2,
      "y": 11,
      "z": 3,
      "name": "Wood_Sallow_Trunk_Full",
      "support": 15
    },
    {
      "x": -2,
      "y": 12,
      "z": 3,
      "name": "Plant_Moss_Rug_Green_Dark",
      "support": 15
    },
    {
      "x": -2,
      "y": 52,
      "z": 3,
      "name": "Wood_Sallow_Branch_Long",
      "support": 15,
      "rotation": 4
    },
    {
      "x": -2,
      "y": 62,
      "z": 3,
      "name": "Plant_Leaves_Beech",
      "support": 15
    },
    {
      "x": -2,
      "y": 10,
      "z": 4,
      "name": "Plant_Moss_Wall_Green_Dark",
      "support": 15,
      "rotation": 1
    },
    {
      "x": -2,
      "y": 52,
      "z": 4,
      "name": "Wood_Sallow_Branch_Corner",
      "support": 15,
      "rotation": 16
    },
    {
      "x": -2,
      "y": 58,
      "z": 4,
      "name": "Wood_Sallow_Branch_Corner",
      "support": 15,
      "rotation": 24
    },
    {
      "x": -2,
      "y": 60,
      "z": 4,
      "name": "Plant_Leaves_Beech",
      "support": 15
    },
    {
      "x": -2,
      "y": 62,
      "z": 4,
      "name": "Wood_Sallow_Branch_Long",
      "support": 15,
      "rotation": 5
    },
    {
      "x": -2,
      "y": 63,
      "z": 4,
      "name": "Plant_Leaves_Beech",
      "support": 15
    },
    {
      "x": -2,
      "y": 58,
      "z": 5,
      "name": "Wood_Sallow_Trunk_Full",
      "support": 15,
      "rotation": 4
    },
    {
      "x": -2,
      "y": 59,
      "z": 5,
      "name": "Wood_Sallow_Branch_Long",
      "support": 15
    },
    {
      "x": -2,
      "y": 60,
      "z": 5,
      "name": "Wood_Sallow_Branch_Long",
      "support": 15
    },
    {
      "x": -2,
      "y": 61,
      "z": 5,
      "name": "Plant_Leaves_Beech",
      "support": 15
    },
    {
      "x": -2,
      "y": 62,
      "z": 5,
      "name": "Plant_Leaves_Beech",
      "support": 15
    },
    {
      "x": -2,
      "y": 10,
      "z": 6,
      "name": "Plant_Moss_Wall_Green_Dark",
      "support": 15,
      "rotation": 3
    },
    {
      "x": -2,
      "y": 58,
      "z": 6,
      "name": "Wood_Sallow_Trunk_Full",
      "support": 15,
      "rotation": 5
    },
    {
      "x": -2,
      "y": 60,
      "z": 6,
      "name": "Plant_Leaves_Beech",
      "support": 15
    },
    {
      "x": -2,
      "y": 3,
      "z": 7,
      "name": "Wood_Sallow_Roots"
    },
    {
      "x": -2,
      "y": 4,
      "z": 7,
      "name": "Wood_Sallow_Trunk_Full",
      "support": 15
    },
    {
      "x": -2,
      "y": 5,
      "z": 7,
      "name": "Wood_Sallow_Trunk",
      "support": 15
    },
    {
      "x": -2,
      "y": 6,
      "z": 7,
      "name": "Wood_Sallow_Trunk",
      "support": 15
    },
    {
      "x": -2,
      "y": 7,
      "z": 7,
      "name": "Wood_Sallow_Trunk",
      "support": 15
    },
    {
      "x": -2,
      "y": 8,
      "z": 7,
      "name": "Wood_Sallow_Trunk",
      "support": 15
    },
    {
      "x": -2,
      "y": 9,
      "z": 7,
      "name": "Wood_Sallow_Trunk_Full",
      "support": 15
    },
    {
      "x": -2,
      "y": 10,
      "z": 7,
      "name": "Plant_Moss_Rug_Green_Dark",
      "support": 15
    },
    {
      "x": -2,
      "y": 58,
      "z": 7,
      "name": "Plant_Leaves_Beech",
      "support": 15
    },
    {
      "x": -2,
      "y": 9,
      "z": 8,
      "name": "Plant_Moss_Wall_Green_Dark",
      "support": 15
    },
    {
      "x": -2,
      "y": 58,
      "z": 8,
      "name": "Plant_Leaves_Beech",
      "support": 15
    },
    {
      "x": -2,
      "y": 59,
      "z": 8,
      "name": "Plant_Leaves_Beech",
      "support": 15
    },
    {
      "x": -1,
      "y": 55,
      "z": -10,
      "name": "Wood_Sallow_Branch_Corner",
      "support": 15,
      "rotation": 2
    },
    {
      "x": -1,
      "y": 56,
      "z": -10,
      "name": "Wood_Sallow_Branch_Long",
      "support": 15
    },
    {
      "x": -1,
      "y": 57,
      "z": -10,
      "name": "Plant_Leaves_Beech",
      "support": 15
    },
    {
      "x": -1,
      "y": 54,
      "z": -9,
      "name": "Plant_Leaves_Beech",
      "support": 15
    },
    {
      "x": -1,
      "y": 55,
      "z": -9,
      "name": "Wood_Sallow_Branch_Long",
      "support": 15,
      "rotation": 4
    },
    {
      "x": -1,
      "y": 56,
      "z": -9,
      "name": "Plant_Leaves_Beech",
      "support": 15
    },
    {
      "x": -1,
      "y": 8,
      "z": -8,
      "name": "Plant_Moss_Wall_Green_Dark",
      "support": 15,
      "rotation": 1
    },
    {
      "x": -1,
      "y": 55,
      "z": -8,
      "name": "Wood_Sallow_Trunk",
      "support": 15,
      "rotation": 4
    },
    {
      "x": -1,
      "y": 9,
      "z": -7,
      "name": "Plant_Moss_Wall_Green_Dark",
      "support": 15,
      "rotation": 1
    },
    {
      "x": -1,
      "y": 55,
      "z": -7,
      "name": "Wood_Sallow_Trunk",
      "support": 15,
      "rotation": 4
    },
    {
      "x": -1,
      "y": 57,
      "z": -7,
      "name": "Plant_Leaves_Beech",
      "support": 15
    },
    {
      "x": -1,
      "y": 62,
      "z": -7,
      "name": "Plant_Leaves_Beech",
      "support": 15
    },
    {
      "x": -1,
      "y": 63,
      "z": -7,
      "name": "Plant_Leaves_Beech",
      "support": 15
    },
    {
      "x": -1,
      "y": 4,
      "z": -6,
      "name": "Wood_Sallow_Roots"
    },
    {
      "x": -1,
      "y": 5,
      "z": -6,
      "name": "Wood_Sallow_Trunk_Full",
      "support": 15
    },
    {
      "x": -1,
      "y": 6,
      "z": -6,
      "name": "Wood_Sallow_Trunk",
      "support": 15
    },
    {
      "x": -1,
      "y": 7,
      "z": -6,
      "name": "Wood_Sallow_Trunk",
      "support": 15
    },
    {
      "x": -1,
      "y": 8,
      "z": -6,
      "name": "Wood_Sallow_Trunk",
      "support": 15
    },
    {
      "x": -1,
      "y": 9,
      "z": -6,
      "name": "Wood_Sallow_Trunk",
      "support": 15
    },
    {
      "x": -1,
      "y": 10,
      "z": -6,
      "name": "Wood_Sallow_Trunk_Full",
      "support": 15
    },
    {
      "x": -1,
      "y": 11,
      "z": -6,
      "name": "Plant_Moss_Rug_Green_Dark",
      "support": 15
    },
    {
      "x": -1,
      "y": 55,
      "z": -6,
      "name": "Wood_Sallow_Trunk",
      "support": 15,
      "rotation": 4
    },
    {
      "x": -1,
      "y": 56,
      "z": -6,
      "name": "Wood_Sallow_Branch_Long",
      "support": 15
    },
    {
      "x": -1,
      "y": 57,
      "z": -6,
      "name": "Wood_Sallow_Branch_Long",
      "support": 15
    },
    {
      "x": -1,
      "y": 58,
      "z": -6,
      "name": "Plant_Leaves_Beech",
      "support": 15
    },
    {
      "x": -1,
      "y": 61,
      "z": -6,
      "name": "Plant_Leaves_Beech",
      "support": 15
    },
    {
      "x": -1,
      "y": 62,
      "z": -6,
      "name": "Wood_Sallow_Branch_Corner",
      "support": 15,
      "rotation": 2
    },
    {
      "x": -1,
      "y": 63,
      "z": -6,
      "name": "Wood_Sallow_Branch_Long",
      "support": 15
    },
    {
      "x": -1,
      "y": 64,
      "z": -6,
      "name": "Plant_Leaves_Beech",
      "support": 15
    },
    {
      "x": -1,
      "y": 5,
      "z": -5,
      "name": "Wood_Sallow_Roots"
    },
    {
      "x": -1,
      "y": 6,
      "z": -5,
      "name": "Wood_Sallow_Trunk_Full",
      "support": 15
    },
    {
      "x": -1,
      "y": 7,
      "z": -5,
      "name": "Wood_Sallow_Trunk",
      "support": 15
    },
    {
      "x": -1,
      "y": 8,
      "z": -5,
      "name": "Wood_Sallow_Trunk",
      "support": 15
    },
    {
      "x": -1,
      "y": 9,
      "z": -5,
      "name": "Wood_Sallow_Trunk",
      "support": 15
    },
    {
      "x": -1,
      "y": 10,
      "z": -5,
      "name": "Wood_Sallow_Trunk",
      "support": 15
    },
    {
      "x": -1,
      "y": 11,
      "z": -5,
      "name": "Wood_Sallow_Trunk_Full",
      "support": 15
    },
    {
      "x": -1,
      "y": 54,
      "z": -5,
      "name": "Wood_Sallow_Trunk_Full",
      "support": 15,
      "rotation": 4
    },
    {
      "x": -1,
      "y": 55,
      "z": -5,
      "name": "Wood_Sallow_Trunk_Full",
      "support": 15
    },
    {
      "x": -1,
      "y": 57,
      "z": -5,
      "name": "Plant_Leaves_Beech",
      "support": 15
    },
    {
      "x": -1,
      "y": 62,
      "z": -5,
      "name": "Wood_Sallow_Branch_Long",
      "support": 15,
      "rotation": 4
    },
    {
      "x": -1,
      "y": 63,
      "z": -5,
      "name": "Plant_Leaves_Beech",
      "support": 15
    },
    {
      "x": -1,
      "y": 64,
      "z": -5,
      "name": "Plant_Leaves_Beech",
      "support": 15
    },
    {
      "x": -1,
      "y": 54,
      "z": -4,
      "name": "Wood_Sallow_Trunk",
      "support": 15,
      "rotation": 4
    },
    {
      "x": -1,
      "y": 61,
      "z": -4,
      "name": "Wood_Sallow_Trunk_Full",
      "support": 15,
      "rotation": 4
    },
    {
      "x": -1,
      "y": 62,
      "z": -4,
      "name": "Wood_Sallow_Trunk",
      "support": 15
    },
    {
      "x": -1,
      "y": 63,
      "z": -4,
      "name": "Wood_Sallow_Branch_Long",
      "support": 15
    },
    {
      "x": -1,
      "y": 64,
      "z": -4,
      "name": "Wood_Sallow_Branch_Long",
      "support": 15
    },
    {
      "x": -1,
      "y": 65,
      "z": -4,
      "name": "Plant_Leaves_Beech",
      "support": 15
    },
    {
      "x": -1,
      "y": 7,
      "z": -3,
      "name": "Wood_Sallow_Trunk_Full",
      "support": 15
    },
    {
      "x": -1,
      "y": 8,
      "z": -3,
      "name": "Wood_Sallow_Trunk",
      "support": 15
    },
    {
      "x": -1,
      "y": 9,
      "z": -3,
      "name": "Wood_Sallow_Trunk",
      "support": 15
    },
    {
      "x": -1,
      "y": 10,
      "z": -3,
      "name": "Wood_Sallow_Trunk",
      "support": 15
    },
    {
      "x": -1,
      "y": 11,
      "z": -3,
      "name": "Wood_Sallow_Trunk_Full",
      "support": 15
    },
    {
      "x": -1,
      "y": 13,
      "z": -3,
      "name": "Plant_Moss_Wall_Green_Dark",
      "support": 15,
      "rotation": 2
    },
    {
      "x": -1,
      "y": 54,
      "z": -3,
      "name": "Wood_Sallow_Trunk_Full",
      "support": 15,
      "rotation": 5
    },
    {
      "x": -1,
      "y": 61,
      "z": -3,
      "name": "Wood_Sallow_Trunk",
      "support": 15,
      "rotation": 4
    },
    {
      "x": -1,
      "y": 64,
      "z": -3,
      "name": "Plant_Leaves_Beech",
      "support": 15
    },
    {
      "x": -1,
      "y": 5,
      "z": -2,
      "name": "Wood_Sallow_Roots"
    },
    {
      "x": -1,
      "y": 6,
      "z": -2,
      "name": "Wood_Sallow_Trunk_Full",
      "support": 15
    },
    {
      "x": -1,
      "y": 7,
      "z": -2,
      "name": "Wood_Sallow_Trunk",
      "support": 15
    },
    {
      "x": -1,
      "y": 8,
      "z": -2,
      "name": "Wood_Sallow_Trunk",
      "support": 15
    },
    {
      "x": -1,
      "y": 9,
      "z": -2,
      "name": "Wood_Sallow_Trunk",
      "support": 15
    },
    {
      "x": -1,
      "y": 10,
      "z": -2,
      "name": "Wood_Sallow_Trunk",
      "support": 15
    },
    {
      "x": -1,
      "y": 11,
      "z": -2,
      "name": "Wood_Sallow_Trunk",
      "support": 15
    },
    {
      "x": -1,
      "y": 12,
      "z": -2,
      "name": "Wood_Sallow_Trunk",
      "support": 15
    },
    {
      "x": -1,
      "y": 13,
      "z": -2,
      "name": "Wood_Sallow_Trunk_Full",
      "support": 15
    },
    {
      "x": -1,
      "y": 14,
      "z": -2,
      "name": "Plant_Moss_Rug_Green_Dark",
      "support": 15
    },
    {
      "x": -1,
      "y": 17,
      "z": -2,
      "name": "Plant_Moss_Wall_Green_Dark",
      "support": 15,
      "rotation": 3
    },
    {
      "x": -1,
      "y": 38,
      "z": -2,
      "name": "Wood_Sallow_Branch_Short",
      "support": 15,
      "rotation": 2
    },
    {
      "x": -1,
      "y": 60,
      "z": -2,
      "name": "Wood_Sallow_Trunk_Full",
      "support": 15,
      "rotation": 5
    },
    {
      "x": -1,
      "y": 61,
      "z": -2,
      "name": "Wood_Sallow_Trunk_Full",
      "support": 15,
      "rotation": 4
    },
    {
      "x": -1,
      "y": 62,
      "z": -2,
      "name": "Wood_Sallow_Branch_Corner",
      "support": 15,
      "rotation": 11
    },
    {
      "x": -1,
      "y": 5,
      "z": -1,
      "name": "Wood_Sallow_Roots"
    },
    {
      "x": -1,
      "y": 6,
      "z": -1,
      "name": "Wood_Sallow_Trunk_Full",
      "support": 15
    },
    {
      "x": -1,
      "y": 7,
      "z": -1,
      "name": "Wood_Sallow_Trunk",
      "support": 15
    },
    {
      "x": -1,
      "y": 8,
      "z": -1,
      "name": "Wood_Sallow_Trunk"
    },
    {
      "x": -1,
      "y": 9,
      "z": -1,
      "name": "Wood_Sallow_Trunk"
    },
    {
      "x": -1,
      "y": 10,
      "z": -1,
      "name": "Wood_Sallow_Trunk"
    },
    {
      "x": -1,
      "y": 11,
      "z": -1,
      "name": "Wood_Sallow_Trunk"
    },
    {
      "x": -1,
      "y": 12,
      "z": -1,
      "name": "Wood_Sallow_Trunk"
    },
    {
      "x": -1,
      "y": 13,
      "z": -1,
      "name": "Wood_Sallow_Trunk"
    },
    {
      "x": -1,
      "y": 14,
      "z": -1,
      "name": "Wood_Sallow_Trunk"
    },
    {
      "x": -1,
      "y": 15,
      "z": -1,
      "name": "Wood_Sallow_Trunk"
    },
    {
      "x": -1,
      "y": 16,
      "z": -1,
      "name": "Wood_Sallow_Trunk"
    },
    {
      "x": -1,
      "y": 17,
      "z": -1,
      "name": "Wood_Sallow_Trunk"
    },
    {
      "x": -1,
      "y": 18,
      "z": -1,
      "name": "Wood_Sallow_Trunk"
    },
    {
      "x": -1,
      "y": 19,
      "z": -1,
      "name": "Wood_Sallow_Trunk"
    },
    {
      "x": -1,
      "y": 20,
      "z": -1,
      "name": "Wood_Sallow_Trunk"
    },
    {
      "x": -1,
      "y": 21,
      "z": -1,
      "name": "Wood_Sallow_Trunk"
    },
    {
      "x": -1,
      "y": 22,
      "z": -1,
      "name": "Wood_Sallow_Trunk"
    },
    {
      "x": -1,
      "y": 23,
      "z": -1,
      "name": "Wood_Sallow_Trunk"
    },
    {
      "x": -1,
      "y": 24,
      "z": -1,
      "name": "Wood_Sallow_Trunk"
    },
    {
      "x": -1,
      "y": 25,
      "z": -1,
      "name": "Wood_Sallow_Trunk"
    },
    {
      "x": -1,
      "y": 26,
      "z": -1,
      "name": "Wood_Sallow_Trunk"
    },
    {
      "x": -1,
      "y": 27,
      "z": -1,
      "name": "Wood_Sallow_Trunk"
    },
    {
      "x": -1,
      "y": 28,
      "z": -1,
      "name": "Wood_Sallow_Trunk"
    },
    {
      "x": -1,
      "y": 29,
      "z": -1,
      "name": "Wood_Sallow_Trunk"
    },
    {
      "x": -1,
      "y": 30,
      "z": -1,
      "name": "Wood_Sallow_Trunk"
    },
    {
      "x": -1,
      "y": 31,
      "z": -1,
      "name": "Wood_Sallow_Trunk"
    },
    {
      "x": -1,
      "y": 32,
      "z": -1,
      "name": "Wood_Sallow_Trunk"
    },
    {
      "x": -1,
      "y": 33,
      "z": -1,
      "name": "Wood_Sallow_Trunk"
    },
    {
      "x": -1,
      "y": 34,
      "z": -1,
      "name": "Wood_Sallow_Trunk"
    },
    {
      "x": -1,
      "y": 35,
      "z": -1,
      "name": "Wood_Sallow_Trunk"
    },
    {
      "x": -1,
      "y": 36,
      "z": -1,
      "name": "Wood_Sallow_Trunk"
    },
    {
      "x": -1,
      "y": 37,
      "z": -1,
      "name": "Wood_Sallow_Trunk"
    },
    {
      "x": -1,
      "y": 38,
      "z": -1,
      "name": "Wood_Sallow_Trunk"
    },
    {
      "x": -1,
      "y": 39,
      "z": -1,
      "name": "Wood_Sallow_Trunk"
    },
    {
      "x": -1,
      "y": 40,
      "z": -1,
      "name": "Wood_Sallow_Trunk"
    },
    {
      "x": -1,
      "y": 41,
      "z": -1,
      "name": "Wood_Sallow_Trunk"
    },
    {
      "x": -1,
      "y": 42,
      "z": -1,
      "name": "Wood_Sallow_Trunk"
    },
    {
      "x": -1,
      "y": 43,
      "z": -1,
      "name": "Wood_Sallow_Trunk"
    },
    {
      "x": -1,
      "y": 44,
      "z": -1,
      "name": "Wood_Sallow_Trunk"
    },
    {
      "x": -1,
      "y": 45,
      "z": -1,
      "name": "Wood_Sallow_Trunk"
    },
    {
      "x": -1,
      "y": 46,
      "z": -1,
      "name": "Wood_Sallow_Trunk"
    },
    {
      "x": -1,
      "y": 47,
      "z": -1,
      "name": "Wood_Sallow_Trunk"
    },
    {
      "x": -1,
      "y": 48,
      "z": -1,
      "name": "Wood_Sallow_Trunk"
    },
    {
      "x": -1,
      "y": 49,
      "z": -1,
      "name": "Wood_Sallow_Trunk"
    },
    {
      "x": -1,
      "y": 50,
      "z": -1,
      "name": "Wood_Sallow_Trunk"
    },
    {
      "x": -1,
      "y": 51,
      "z": -1,
      "name": "Wood_Sallow_Trunk"
    },
    {
      "x": -1,
      "y": 52,
      "z": -1,
      "name": "Wood_Sallow_Trunk",
      "support": 15
    },
    {
      "x": -1,
      "y": 53,
      "z": -1,
      "name": "Wood_Sallow_Trunk_Full",
      "support": 15
    },
    {
      "x": -1,
      "y": 63,
      "z": -1,
      "name": "Plant_Leaves_Beech",
      "support": 15
    },
    {
      "x": -1,
      "y": 64,
      "z": -1,
      "name": "Plant_Leaves_Beech",
      "support": 15
    },
    {
      "x": -1,
      "y": 7,
      "z": 0,
      "name": "Wood_Sallow_Roots"
    },
    {
      "x": -1,
      "y": 8,
      "z": 0,
      "name": "Wood_Sallow_Trunk_Full",
      "support": 15
    },
    {
      "x": -1,
      "y": 9,
      "z": 0,
      "name": "Wood_Sallow_Trunk"
    },
    {
      "x": -1,
      "y": 10,
      "z": 0,
      "name": "Wood_Sallow_Trunk"
    },
    {
      "x": -1,
      "y": 11,
      "z": 0,
      "name": "Wood_Sallow_Trunk"
    },
    {
      "x": -1,
      "y": 12,
      "z": 0,
      "name": "Wood_Sallow_Trunk"
    },
    {
      "x": -1,
      "y": 13,
      "z": 0,
      "name": "Wood_Sallow_Trunk"
    },
    {
      "x": -1,
      "y": 14,
      "z": 0,
      "name": "Wood_Sallow_Trunk"
    },
    {
      "x": -1,
      "y": 15,
      "z": 0,
      "name": "Wood_Sallow_Trunk"
    },
    {
      "x": -1,
      "y": 16,
      "z": 0,
      "name": "Wood_Sallow_Trunk"
    },
    {
      "x": -1,
      "y": 17,
      "z": 0,
      "name": "Wood_Sallow_Trunk"
    },
    {
      "x": -1,
      "y": 18,
      "z": 0,
      "name": "Wood_Sallow_Trunk"
    },
    {
      "x": -1,
      "y": 19,
      "z": 0,
      "name": "Wood_Sallow_Trunk"
    },
    {
      "x": -1,
      "y": 20,
      "z": 0,
      "name": "Wood_Sallow_Trunk"
    },
    {
      "x": -1,
      "y": 21,
      "z": 0,
      "name": "Wood_Sallow_Trunk"
    },
    {
      "x": -1,
      "y": 22,
      "z": 0,
      "name": "Wood_Sallow_Trunk"
    },
    {
      "x": -1,
      "y": 23,
      "z": 0,
      "name": "Wood_Sallow_Trunk"
    },
    {
      "x": -1,
      "y": 24,
      "z": 0,
      "name": "Wood_Sallow_Trunk"
    },
    {
      "x": -1,
      "y": 25,
      "z": 0,
      "name": "Wood_Sallow_Trunk"
    },
    {
      "x": -1,
      "y": 26,
      "z": 0,
      "name": "Wood_Sallow_Trunk"
    },
    {
      "x": -1,
      "y": 27,
      "z": 0,
      "name": "Wood_Sallow_Trunk"
    },
    {
      "x": -1,
      "y": 28,
      "z": 0,
      "name": "Wood_Sallow_Trunk"
    },
    {
      "x": -1,
      "y": 29,
      "z": 0,
      "name": "Wood_Sallow_Trunk"
    },
    {
      "x": -1,
      "y": 30,
      "z": 0,
      "name": "Wood_Sallow_Trunk"
    },
    {
      "x": -1,
      "y": 31,
      "z": 0,
      "name": "Wood_Sallow_Trunk"
    },
    {
      "x": -1,
      "y": 32,
      "z": 0,
      "name": "Wood_Sallow_Trunk"
    },
    {
      "x": -1,
      "y": 33,
      "z": 0,
      "name": "Wood_Sallow_Trunk"
    },
    {
      "x": -1,
      "y": 34,
      "z": 0,
      "name": "Wood_Sallow_Trunk"
    },
    {
      "x": -1,
      "y": 35,
      "z": 0,
      "name": "Wood_Sallow_Trunk"
    },
    {
      "x": -1,
      "y": 36,
      "z": 0,
      "name": "Wood_Sallow_Trunk"
    },
    {
      "x": -1,
      "y": 37,
      "z": 0,
      "name": "Wood_Sallow_Trunk"
    },
    {
      "x": -1,
      "y": 38,
      "z": 0,
      "name": "Wood_Sallow_Trunk"
    },
    {
      "x": -1,
      "y": 39,
      "z": 0,
      "name": "Wood_Sallow_Trunk"
    },
    {
      "x": -1,
      "y": 40,
      "z": 0,
      "name": "Wood_Sallow_Trunk"
    },
    {
      "x": -1,
      "y": 41,
      "z": 0,
      "name": "Wood_Sallow_Trunk"
    },
    {
      "x": -1,
      "y": 42,
      "z": 0,
      "name": "Wood_Sallow_Trunk"
    },
    {
      "x": -1,
      "y": 43,
      "z": 0,
      "name": "Wood_Sallow_Trunk"
    },
    {
      "x": -1,
      "y": 44,
      "z": 0,
      "name": "Wood_Sallow_Trunk"
    },
    {
      "x": -1,
      "y": 45,
      "z": 0,
      "name": "Wood_Sallow_Trunk"
    },
    {
      "x": -1,
      "y": 46,
      "z": 0,
      "name": "Wood_Sallow_Trunk"
    },
    {
      "x": -1,
      "y": 47,
      "z": 0,
      "name": "Wood_Sallow_Trunk"
    },
    {
      "x": -1,
      "y": 48,
      "z": 0,
      "name": "Wood_Sallow_Trunk"
    },
    {
      "x": -1,
      "y": 49,
      "z": 0,
      "name": "Wood_Sallow_Trunk"
    },
    {
      "x": -1,
      "y": 50,
      "z": 0,
      "name": "Wood_Sallow_Trunk"
    },
    {
      "x": -1,
      "y": 51,
      "z": 0,
      "name": "Wood_Sallow_Trunk"
    },
    {
      "x": -1,
      "y": 52,
      "z": 0,
      "name": "Wood_Sallow_Trunk",
      "support": 15
    },
    {
      "x": -1,
      "y": 53,
      "z": 0,
      "name": "Wood_Sallow_Trunk",
      "support": 15
    },
    {
      "x": -1,
      "y": 54,
      "z": 0,
      "name": "Wood_Sallow_Trunk",
      "support": 15,
      "rotation": 5
    },
    {
      "x": -1,
      "y": 8,
      "z": 1,
      "name": "Wood_Sallow_Trunk_Full",
      "support": 15
    },
    {
      "x": -1,
      "y": 9,
      "z": 1,
      "name": "Wood_Sallow_Trunk"
    },
    {
      "x": -1,
      "y": 10,
      "z": 1,
      "name": "Wood_Sallow_Trunk"
    },
    {
      "x": -1,
      "y": 11,
      "z": 1,
      "name": "Wood_Sallow_Trunk"
    },
    {
      "x": -1,
      "y": 12,
      "z": 1,
      "name": "Wood_Sallow_Trunk"
    },
    {
      "x": -1,
      "y": 13,
      "z": 1,
      "name": "Wood_Sallow_Trunk"
    },
    {
      "x": -1,
      "y": 14,
      "z": 1,
      "name": "Wood_Sallow_Trunk"
    },
    {
      "x": -1,
      "y": 15,
      "z": 1,
      "name": "Wood_Sallow_Trunk"
    },
    {
      "x": -1,
      "y": 16,
      "z": 1,
      "name": "Wood_Sallow_Trunk"
    },
    {
      "x": -1,
      "y": 17,
      "z": 1,
      "name": "Wood_Sallow_Trunk"
    },
    {
      "x": -1,
      "y": 18,
      "z": 1,
      "name": "Wood_Sallow_Trunk"
    },
    {
      "x": -1,
      "y": 19,
      "z": 1,
      "name": "Wood_Sallow_Trunk"
    },
    {
      "x": -1,
      "y": 20,
      "z": 1,
      "name": "Wood_Sallow_Trunk"
    },
    {
      "x": -1,
      "y": 21,
      "z": 1,
      "name": "Wood_Sallow_Trunk"
    },
    {
      "x": -1,
      "y": 22,
      "z": 1,
      "name": "Wood_Sallow_Trunk"
    },
    {
      "x": -1,
      "y": 23,
      "z": 1,
      "name": "Wood_Sallow_Trunk"
    },
    {
      "x": -1,
      "y": 24,
      "z": 1,
      "name": "Wood_Sallow_Trunk"
    },
    {
      "x": -1,
      "y": 25,
      "z": 1,
      "name": "Wood_Sallow_Trunk"
    },
    {
      "x": -1,
      "y": 26,
      "z": 1,
      "name": "Wood_Sallow_Trunk"
    },
    {
      "x": -1,
      "y": 27,
      "z": 1,
      "name": "Wood_Sallow_Trunk"
    },
    {
      "x": -1,
      "y": 28,
      "z": 1,
      "name": "Wood_Sallow_Trunk"
    },
    {
      "x": -1,
      "y": 29,
      "z": 1,
      "name": "Wood_Sallow_Trunk"
    },
    {
      "x": -1,
      "y": 30,
      "z": 1,
      "name": "Wood_Sallow_Trunk"
    },
    {
      "x": -1,
      "y": 31,
      "z": 1,
      "name": "Wood_Sallow_Trunk"
    },
    {
      "x": -1,
      "y": 32,
      "z": 1,
      "name": "Wood_Sallow_Trunk"
    },
    {
      "x": -1,
      "y": 33,
      "z": 1,
      "name": "Wood_Sallow_Trunk"
    },
    {
      "x": -1,
      "y": 34,
      "z": 1,
      "name": "Wood_Sallow_Trunk"
    },
    {
      "x": -1,
      "y": 35,
      "z": 1,
      "name": "Wood_Sallow_Trunk"
    },
    {
      "x": -1,
      "y": 36,
      "z": 1,
      "name": "Wood_Sallow_Trunk"
    },
    {
      "x": -1,
      "y": 37,
      "z": 1,
      "name": "Wood_Sallow_Trunk"
    },
    {
      "x": -1,
      "y": 38,
      "z": 1,
      "name": "Wood_Sallow_Trunk"
    },
    {
      "x": -1,
      "y": 39,
      "z": 1,
      "name": "Wood_Sallow_Trunk"
    },
    {
      "x": -1,
      "y": 40,
      "z": 1,
      "name": "Wood_Sallow_Trunk"
    },
    {
      "x": -1,
      "y": 41,
      "z": 1,
      "name": "Wood_Sallow_Trunk"
    },
    {
      "x": -1,
      "y": 42,
      "z": 1,
      "name": "Wood_Sallow_Trunk"
    },
    {
      "x": -1,
      "y": 43,
      "z": 1,
      "name": "Wood_Sallow_Trunk"
    },
    {
      "x": -1,
      "y": 44,
      "z": 1,
      "name": "Wood_Sallow_Trunk"
    },
    {
      "x": -1,
      "y": 45,
      "z": 1,
      "name": "Wood_Sallow_Trunk"
    },
    {
      "x": -1,
      "y": 46,
      "z": 1,
      "name": "Wood_Sallow_Trunk"
    },
    {
      "x": -1,
      "y": 47,
      "z": 1,
      "name": "Wood_Sallow_Trunk"
    },
    {
      "x": -1,
      "y": 48,
      "z": 1,
      "name": "Wood_Sallow_Trunk"
    },
    {
      "x": -1,
      "y": 49,
      "z": 1,
      "name": "Wood_Sallow_Trunk"
    },
    {
      "x": -1,
      "y": 50,
      "z": 1,
      "name": "Wood_Sallow_Trunk"
    },
    {
      "x": -1,
      "y": 51,
      "z": 1,
      "name": "Wood_Sallow_Trunk"
    },
    {
      "x": -1,
      "y": 52,
      "z": 1,
      "name": "Wood_Sallow_Trunk_Full",
      "support": 15
    },
    {
      "x": -1,
      "y": 60,
      "z": 1,
      "name": "Wood_Sallow_Branch_Corner",
      "support": 15,
      "rotation": 24
    },
    {
      "x": -1,
      "y": 6,
      "z": 2,
      "name": "Wood_Sallow_Roots"
    },
    {
      "x": -1,
      "y": 7,
      "z": 2,
      "name": "Wood_Sallow_Trunk_Full",
      "support": 15
    },
    {
      "x": -1,
      "y": 8,
      "z": 2,
      "name": "Wood_Sallow_Trunk",
      "support": 15
    },
    {
      "x": -1,
      "y": 9,
      "z": 2,
      "name": "Wood_Sallow_Trunk",
      "support": 15
    },
    {
      "x": -1,
      "y": 10,
      "z": 2,
      "name": "Wood_Sallow_Trunk",
      "support": 15
    },
    {
      "x": -1,
      "y": 11,
      "z": 2,
      "name": "Wood_Sallow_Trunk",
      "support": 15
    },
    {
      "x": -1,
      "y": 12,
      "z": 2,
      "name": "Wood_Sallow_Trunk",
      "support": 15
    },
    {
      "x": -1,
      "y": 13,
      "z": 2,
      "name": "Wood_Sallow_Trunk_Full",
      "support": 15
    },
    {
      "x": -1,
      "y": 14,
      "z": 2,
      "name": "Plant_Moss_Rug_Green_Dark",
      "support": 15
    },
    {
      "x": -1,
      "y": 44,
      "z": 2,
      "name": "Wood_Sallow_Branch_Short",
      "support": 15
    },
    {
      "x": -1,
      "y": 60,
      "z": 2,
      "name": "Wood_Sallow_Branch_Corner",
      "support": 15,
      "rotation": 19
    },
    {
      "x": -1,
      "y": 13,
      "z": 3,
      "name": "Plant_Moss_Wall_Green_Dark",
      "support": 15
    },
    {
      "x": -1,
      "y": 56,
      "z": 3,
      "name": "Wood_Sallow_Trunk_Full",
      "support": 15,
      "rotation": 5
    },
    {
      "x": -1,
      "y": 57,
      "z": 3,
      "name": "Wood_Sallow_Trunk_Full",
      "support": 15,
      "rotation": 4
    },
    {
      "x": -1,
      "y": 12,
      "z": 4,
      "name": "Plant_Moss_Wall_Green_Dark",
      "support": 15,
      "rotation": 3
    },
    {
      "x": -1,
      "y": 57,
      "z": 4,
      "name": "Wood_Sallow_Trunk_Full",
      "support": 15,
      "rotation": 4
    },
    {
      "x": -1,
      "y": 58,
      "z": 4,
      "name": "Wood_Sallow_Trunk_Full",
      "support": 15,
      "rotation": 4
    },
    {
      "x": -1,
      "y": 61,
      "z": 4,
      "name": "Wood_Sallow_Branch_Corner",
      "support": 15,
      "rotation": 3
    },
    {
      "x": -1,
      "y": 62,
      "z": 4,
      "name": "Wood_Sallow_Branch_Corner",
      "support": 15,
      "rotation": 11
    },
    {
      "x": -1,
      "y": 63,
      "z": 4,
      "name": "Plant_Leaves_Beech",
      "support": 15
    },
    {
      "x": -1,
      "y": 58,
      "z": 5,
      "name": "Wood_Sallow_Trunk_Full",
      "support": 15,
      "rotation": 4
    },
    {
      "x": -1,
      "y": 60,
      "z": 5,
      "name": "Plant_Leaves_Beech",
      "support": 15
    },
    {
      "x": -1,
      "y": 62,
      "z": 5,
      "name": "Plant_Leaves_Beech",
      "support": 15
    },
    {
      "x": -1,
      "y": 3,
      "z": 6,
      "name": "Wood_Sallow_Roots"
    },
    {
      "x": -1,
      "y": 4,
      "z": 6,
      "name": "Wood_Sallow_Trunk_Full",
      "support": 15
    },
    {
      "x": -1,
      "y": 5,
      "z": 6,
      "name": "Wood_Sallow_Trunk",
      "support": 15
    },
    {
      "x": -1,
      "y": 6,
      "z": 6,
      "name": "Wood_Sallow_Trunk",
      "support": 15
    },
    {
      "x": -1,
      "y": 7,
      "z": 6,
      "name": "Wood_Sallow_Trunk",
      "support": 15
    },
    {
      "x": -1,
      "y": 8,
      "z": 6,
      "name": "Wood_Sallow_Trunk",
      "support": 15
    },
    {
      "x": -1,
      "y": 9,
      "z": 6,
      "name": "Wood_Sallow_Trunk",
      "support": 15
    },
    {
      "x": -1,
      "y": 10,
      "z": 6,
      "name": "Wood_Sallow_Trunk_Full",
      "support": 15
    },
    {
      "x": -1,
      "y": 11,
      "z": 6,
      "name": "Plant_Moss_Rug_Green_Dark",
      "support": 15
    },
    {
      "x": -1,
      "y": 9,
      "z": 7,
      "name": "Plant_Moss_Wall_Green_Dark",
      "support": 15,
      "rotation": 1
    },
    {
      "x": -1,
      "y": 51,
      "z": 8,
      "name": "Plant_Leaves_Beech",
      "support": 15
    },
    {
      "x": -1,
      "y": 51,
      "z": 9,
      "name": "Plant_Leaves_Beech",
      "support": 15
    },
    {
      "x": -1,
      "y": 52,
      "z": 9,
      "name": "Plant_Leaves_Beech",
      "support": 15
    },
    {
      "x": 0,
      "y": 55,
      "z": -10,
      "name": "Plant_Leaves_Beech",
      "support": 15
    },
    {
      "x": 0,
      "y": 56,
      "z": -10,
      "name": "Plant_Leaves_Beech",
      "support": 15
    },
    {
      "x": 0,
      "y": 55,
      "z": -9,
      "name": "Plant_Leaves_Beech",
      "support": 15
    },
    {
      "x": 0,
      "y": 56,
      "z": -9,
      "name": "Plant_Leaves_Beech",
      "support": 15
    },
    {
      "x": 0,
      "y": 57,
      "z": -6,
      "name": "Plant_Leaves_Beech",
      "support": 15
    },
    {
      "x": 0,
      "y": 59,
      "z": -6,
      "name": "Plant_Leaves_Beech",
      "support": 15
    },
    {
      "x": 0,
      "y": 60,
      "z": -6,
      "name": "Plant_Leaves_Beech",
      "support": 15
    },
    {
      "x": 0,
      "y": 62,
      "z": -6,
      "name": "Plant_Leaves_Beech",
      "support": 15
    },
    {
      "x": 0,
      "y": 63,
      "z": -6,
      "name": "Plant_Leaves_Beech",
      "support": 15
    },
    {
      "x": 0,
      "y": 62,
      "z": -5,
      "name": "Plant_Leaves_Beech",
      "support": 15
    },
    {
      "x": 0,
      "y": 5,
      "z": -4,
      "name": "Wood_Sallow_Roots"
    },
    {
      "x": 0,
      "y": 6,
      "z": -4,
      "name": "Wood_Sallow_Trunk_Full",
      "support": 15
    },
    {
      "x": 0,
      "y": 7,
      "z": -4,
      "name": "Wood_Sallow_Trunk",
      "support": 15
    },
    {
      "x": 0,
      "y": 8,
      "z": -4,
      "name": "Wood_Sallow_Trunk",
      "support": 15
    },
    {
      "x": 0,
      "y": 9,
      "z": -4,
      "name": "Wood_Sallow_Trunk",
      "support": 15
    },
    {
      "x": 0,
      "y": 10,
      "z": -4,
      "name": "Wood_Sallow_Trunk",
      "support": 15
    },
    {
      "x": 0,
      "y": 11,
      "z": -4,
      "name": "Wood_Sallow_Trunk_Full",
      "support": 15
    },
    {
      "x": 0,
      "y": 43,
      "z": -4,
      "name": "Plant_Vine_Liana_End",
      "support": 15,
      "rotation": 2
    },
    {
      "x": 0,
      "y": 44,
      "z": -4,
      "name": "Plant_Vine_Liana",
      "support": 15,
      "rotation": 2
    },
    {
      "x": 0,
      "y": 45,
      "z": -4,
      "name": "Plant_Vine_Liana",
      "support": 15,
      "rotation": 2
    },
    {
      "x": 0,
      "y": 46,
      "z": -4,
      "name": "Plant_Vine_Liana",
      "support": 15,
      "rotation": 2
    },
    {
      "x": 0,
      "y": 47,
      "z": -4,
      "name": "Plant_Vine_Liana",
      "support": 15,
      "rotation": 2
    },
    {
      "x": 0,
      "y": 48,
      "z": -4,
      "name": "Plant_Vine_Liana",
      "support": 15,
      "rotation": 2
    },
    {
      "x": 0,
      "y": 49,
      "z": -4,
      "name": "Plant_Vine_Liana",
      "support": 15,
      "rotation": 2
    },
    {
      "x": 0,
      "y": 50,
      "z": -4,
      "name": "Plant_Vine_Liana",
      "support": 15,
      "rotation": 2
    },
    {
      "x": 0,
      "y": 51,
      "z": -4,
      "name": "Plant_Vine_Liana",
      "support": 15,
      "rotation": 2
    },
    {
      "x": 0,
      "y": 52,
      "z": -4,
      "name": "Plant_Vine_Liana",
      "support": 15,
      "rotation": 2
