{
  "version": 8,
  "blockIdVersion": 11,
  "anchorX": 0,
  "anchorY": 0,
  "anchorZ": 0,
  "blocks": [
    {
      "x": -7,
      "y": 2,
      "z": 0,
      "name": "Wood_Sallow_Roots"
    },
    {
      "x": -7,
      "y": 3,
      "z": 0,
      "name": "Wood_Sallow_Trunk_Full",
      "support": 15
    },
    {
      "x": -7,
      "y": 4,
      "z": 0,
      "name": "Wood_Sallow_Trunk",
      "support": 15
    },
    {
      "x": -7,
      "y": 5,
      "z": 0,
      "name": "Wood_Sallow_Trunk",
      "support": 15
    },
    {
      "x": -7,
      "y": 6,
      "z": 0,
      "name": "Wood_Sallow_Trunk",
      "support": 15
    },
    {
      "x": -7,
      "y": 7,
      "z": 0,
      "name": "Wood_Sallow_Trunk",
      "support": 15
    },
    {
      "x": -7,
      "y": 8,
      "z": 0,
      "name": "Wood_Sallow_Trunk_Full",
      "support": 15
    },
    {
      "x": -6,
      "y": 2,
      "z": -6,
      "name": "Wood_Sallow_Roots"
    },
    {
      "x": -6,
      "y": 3,
      "z": -6,
      "name": "Wood_Sallow_Trunk_Full",
      "support": 15
    },
    {
      "x": -6,
      "y": 4,
      "z": -6,
      "name": "Wood_Sallow_Trunk",
      "support": 15
    },
    {
      "x": -6,
      "y": 5,
      "z": -6,
      "name": "Wood_Sallow_Trunk",
      "support": 15
    },
    {
      "x": -6,
      "y": 6,
      "z": -6,
      "name": "Wood_Sallow_Trunk",
      "support": 15
    },
    {
      "x": -6,
      "y": 7,
      "z": -6,
      "name": "Wood_Sallow_Trunk",
      "support": 15
    },
    {
      "x": -6,
      "y": 8,
      "z": -6,
      "name": "Wood_Sallow_Trunk_Full",
      "support": 15
    },
    {
      "x": -6,
      "y": 4,
      "z": -5,
      "name": "Wood_Sallow_Roots"
    },
    {
      "x": -6,
      "y": 5,
      "z": -5,
      "name": "Wood_Sallow_Trunk_Full",
      "support": 15
    },
    {
      "x": -6,
      "y": 6,
      "z": -5,
      "name": "Wood_Sallow_Trunk",
      "support": 15
    },
    {
      "x": -6,
      "y": 7,
      "z": -5,
      "name": "Wood_Sallow_Trunk",
      "support": 15
    },
    {
      "x": -6,
      "y": 8,
      "z": -5,
      "name": "Wood_Sallow_Trunk",
      "support": 15
    },
    {
      "x": -6,
      "y": 9,
      "z": -5,
      "name": "Wood_Sallow_Trunk_Full",
      "support": 15
    },
    {
      "x": -6,
      "y": 10,
      "z": -4,
      "name": "Plant_Moss_Wall_Green_Dark",
      "support": 15,
      "rotation": 3
    },
    {
      "x": -6,
      "y": 4,
      "z": 0,
      "name": "Wood_Sallow_Roots"
    },
    {
      "x": -6,
      "y": 5,
      "z": 0,
      "name": "Wood_Sallow_Trunk_Full",
      "support": 15
    },
    {
      "x": -6,
      "y": 6,
      "z": 0,
      "name": "Wood_Sallow_Trunk",
      "support": 15
    },
    {
      "x": -6,
      "y": 7,
      "z": 0,
      "name": "Wood_Sallow_Trunk",
      "support": 15
    },
    {
      "x": -6,
      "y": 8,
      "z": 0,
      "name": "Wood_Sallow_Trunk",
      "support": 15
    },
    {
      "x": -6,
      "y": 9,
      "z": 0,
      "name": "Wood_Sallow_Trunk_Full",
      "support": 15
    },
    {
      "x": -6,
      "y": 10,
      "z": 1,
      "name": "Plant_Moss_Wall_Green_Dark",
      "support": 15,
      "rotation": 3
    },
    {
      "x": -6,
      "y": 1,
      "z": 6,
      "name": "Wood_Sallow_Roots"
    },
    {
      "x": -6,
      "y": 2,
      "z": 6,
      "name": "Wood_Sallow_Trunk_Full",
      "support": 15
    },
    {
      "x": -6,
      "y": 3,
      "z": 6,
      "name": "Wood_Sallow_Trunk",
      "support": 15
    },
    {
      "x": -6,
      "y": 4,
      "z": 6,
      "name": "Wood_Sallow_Trunk",
      "support": 15
    },
    {
      "x": -6,
      "y": 5,
      "z": 6,
      "name": "Wood_Sallow_Trunk",
      "support": 15
    },
    {
      "x": -6,
      "y": 6,
      "z": 6,
      "name": "Wood_Sallow_Trunk",
      "support": 15
    },
    {
      "x": -6,
      "y": 7,
      "z": 6,
      "name": "Wood_Sallow_Trunk",
      "support": 15
    },
    {
      "x": -6,
      "y": 8,
      "z": 6,
      "name": "Wood_Sallow_Trunk_Full",
      "support": 15
    },
    {
      "x": -6,
      "y": 9,
      "z": 6,
      "name": "Plant_Moss_Rug_Green_Dark",
      "support": 15
    },
    {
      "x": -5,
      "y": 4,
      "z": -4,
      "name": "Wood_Sallow_Roots"
    },
    {
      "x": -5,
      "y": 5,
      "z": -4,
      "name": "Wood_Sallow_Trunk_Full",
      "support": 15
    },
    {
      "x": -5,
      "y": 6,
      "z": -4,
      "name": "Wood_Sallow_Trunk",
      "support": 15
    },
    {
      "x": -5,
      "y": 7,
      "z": -4,
      "name": "Wood_Sallow_Trunk",
      "support": 15
    },
    {
      "x": -5,
      "y": 8,
      "z": -4,
      "name": "Wood_Sallow_Trunk",
      "support": 15
    },
    {
      "x": -5,
      "y": 9,
      "z": -4,
      "name": "Wood_Sallow_Trunk",
      "support": 15
    },
    {
      "x": -5,
      "y": 10,
      "z": -4,
      "name": "Wood_Sallow_Trunk_Full",
      "support": 15
    },
    {
      "x": -5,
      "y": 11,
      "z": -4,
      "name": "Plant_Moss_Rug_Green_Dark",
      "support": 15
    },
    {
      "x": -5,
      "y": 10,
      "z": -3,
      "name": "Plant_Moss_Wall_Green_Dark",
      "support": 15
    },
    {
      "x": -5,
      "y": 5,
      "z": 1,
      "name": "Wood_Sallow_Roots"
    },
    {
      "x": -5,
      "y": 6,
      "z": 1,
      "name": "Wood_Sallow_Trunk_Full",
      "support": 15
    },
    {
      "x": -5,
      "y": 7,
      "z": 1,
      "name": "Wood_Sallow_Trunk",
      "support": 15
    },
    {
      "x": -5,
      "y": 8,
      "z": 1,
      "name": "Wood_Sallow_Trunk",
      "support": 15
    },
    {
      "x": -5,
      "y": 9,
      "z": 1,
      "name": "Wood_Sallow_Trunk",
      "support": 15
    },
    {
      "x": -5,
      "y": 10,
      "z": 1,
      "name": "Wood_Sallow_Trunk_Full",
      "support": 15
    },
    {
      "x": -5,
      "y": 11,
      "z": 1,
      "name": "Plant_Moss_Rug_Green_Dark",
      "support": 15
    },
    {
      "x": -5,
      "y": 2,
      "z": 5,
      "name": "Wood_Sallow_Roots"
    },
    {
      "x": -5,
      "y": 3,
      "z": 5,
      "name": "Wood_Sallow_Trunk_Full",
      "support": 15
    },
    {
      "x": -5,
      "y": 4,
      "z": 5,
      "name": "Wood_Sallow_Trunk",
      "support": 15
    },
    {
      "x": -5,
      "y": 5,
      "z": 5,
      "name": "Wood_Sallow_Trunk",
      "support": 15
    },
    {
      "x": -5,
      "y": 6,
      "z": 5,
      "name": "Wood_Sallow_Trunk",
      "support": 15
    },
    {
      "x": -5,
      "y": 7,
      "z": 5,
      "name": "Wood_Sallow_Trunk",
      "support": 15
    },
    {
      "x": -5,
      "y": 8,
      "z": 5,
      "name": "Wood_Sallow_Trunk",
      "support": 15
    },
    {
      "x": -5,
      "y": 9,
      "z": 5,
      "name": "Wood_Sallow_Trunk_Full",
      "support": 15
    },
    {
      "x": -5,
      "y": 10,
      "z": 5,
      "name": "Plant_Moss_Rug_Green_Dark",
      "support": 15
    },
    {
      "x": -4,
      "y": 10,
      "z": -5,
      "name": "Plant_Moss_Wall_Green_Dark",
      "support": 15,
      "rotation": 2
    },
    {
      "x": -4,
      "y": 4,
      "z": -4,
      "name": "Wood_Sallow_Roots"
    },
    {
      "x": -4,
      "y": 5,
      "z": -4,
      "name": "Wood_Sallow_Trunk_Full",
      "support": 15
    },
    {
      "x": -4,
      "y": 6,
      "z": -4,
      "name": "Wood_Sallow_Trunk",
      "support": 15
    },
    {
      "x": -4,
      "y": 7,
      "z": -4,
      "name": "Wood_Sallow_Trunk",
      "support": 15
    },
    {
      "x": -4,
      "y": 8,
      "z": -4,
      "name": "Wood_Sallow_Trunk",
      "support": 15
    },
    {
      "x": -4,
      "y": 9,
      "z": -4,
      "name": "Wood_Sallow_Trunk",
      "support": 15
    },
    {
      "x": -4,
      "y": 10,
      "z": -4,
      "name": "Wood_Sallow_Trunk_Full",
      "support": 15
    },
    {
      "x": -4,
      "y": 11,
      "z": -4,
      "name": "Plant_Moss_Rug_Green_Dark",
      "support": 15
    },
    {
      "x": -4,
      "y": 11,
      "z": 0,
      "name": "Plant_Moss_Wall_Green_Dark",
      "support": 15,
      "rotation": 2
    },
    {
      "x": -4,
      "y": 5,
      "z": 1,
      "name": "Wood_Sallow_Roots"
    },
    {
      "x": -4,
      "y": 6,
      "z": 1,
      "name": "Wood_Sallow_Trunk_Full",
      "support": 15
    },
    {
      "x": -4,
      "y": 7,
      "z": 1,
      "name": "Wood_Sallow_Trunk",
      "support": 15
    },
    {
      "x": -4,
      "y": 8,
      "z": 1,
      "name": "Wood_Sallow_Trunk",
      "support": 15
    },
    {
      "x": -4,
      "y": 9,
      "z": 1,
      "name": "Wood_Sallow_Trunk",
      "support": 15
    },
    {
      "x": -4,
      "y": 10,
      "z": 1,
      "name": "Wood_Sallow_Trunk",
      "support": 15
    },
    {
      "x": -4,
      "y": 11,
      "z": 1,
      "name": "Wood_Sallow_Trunk_Full",
      "support": 15
    },
    {
      "x": -4,
      "y": 12,
      "z": 1,
      "name": "Plant_Moss_Rug_Green_Dark",
      "support": 15
    },
    {
      "x": -4,
      "y": 11,
      "z": 2,
      "name": "Plant_Moss_Wall_Green_Dark",
      "support": 15
    },
    {
      "x": -4,
      "y": 4,
      "z": 3,
      "name": "Wood_Sallow_Roots"
    },
    {
      "x": -4,
      "y": 5,
      "z": 3,
      "name": "Wood_Sallow_Trunk_Full",
      "support": 15
    },
    {
      "x": -4,
      "y": 6,
      "z": 3,
      "name": "Wood_Sallow_Trunk",
      "support": 15
    },
    {
      "x": -4,
      "y": 7,
      "z": 3,
      "name": "Wood_Sallow_Trunk",
      "support": 15
    },
    {
      "x": -4,
      "y": 8,
      "z": 3,
      "name": "Wood_Sallow_Trunk",
      "support": 15
    },
    {
      "x": -4,
      "y": 9,
      "z": 3,
      "name": "Wood_Sallow_Trunk",
      "support": 15
    },
    {
      "x": -4,
      "y": 10,
      "z": 3,
      "name": "Wood_Sallow_Trunk_Full",
      "support": 15
    },
    {
      "x": -4,
      "y": 3,
      "z": 4,
      "name": "Wood_Sallow_Roots"
    },
    {
      "x": -4,
      "y": 4,
      "z": 4,
      "name": "Wood_Sallow_Trunk_Full",
      "support": 15
    },
    {
      "x": -4,
      "y": 5,
      "z": 4,
      "name": "Wood_Sallow_Trunk",
      "support": 15
    },
    {
      "x": -4,
      "y": 6,
      "z": 4,
      "name": "Wood_Sallow_Trunk",
      "support": 15
    },
    {
      "x": -4,
      "y": 7,
      "z": 4,
      "name": "Wood_Sallow_Trunk",
      "support": 15
    },
    {
      "x": -4,
      "y": 8,
      "z": 4,
      "name": "Wood_Sallow_Trunk",
      "support": 15
    },
    {
      "x": -4,
      "y": 9,
      "z": 4,
      "name": "Wood_Sallow_Trunk",
      "support": 15
    },
    {
      "x": -4,
      "y": 10,
      "z": 4,
      "name": "Wood_Sallow_Trunk_Full",
      "support": 15
    },
    {
      "x": -3,
      "y": 10,
      "z": -4,
      "name": "Plant_Moss_Wall_Green_Dark",
      "support": 15,
      "rotation": 1
    },
    {
      "x": -3,
      "y": 5,
      "z": -3,
      "name": "Wood_Sallow_Roots"
    },
    {
      "x": -3,
      "y": 6,
      "z": -3,
      "name": "Wood_Sallow_Trunk_Full",
      "support": 15
    },
    {
      "x": -3,
      "y": 7,
      "z": -3,
      "name": "Wood_Sallow_Trunk",
      "support": 15
    },
    {
      "x": -3,
      "y": 8,
      "z": -3,
      "name": "Wood_Sallow_Trunk",
      "support": 15
    },
    {
      "x": -3,
      "y": 9,
      "z": -3,
      "name": "Wood_Sallow_Trunk",
      "support": 15
    },
    {
      "x": -3,
      "y": 10,
      "z": -3,
      "name": "Wood_Sallow_Trunk",
      "support": 15
    },
    {
      "x": -3,
      "y": 11,
      "z": -3,
      "name": "Wood_Sallow_Trunk_Full",
      "support": 15
    },
    {
      "x": -3,
      "y": 12,
      "z": -3,
      "name": "Plant_Moss_Wall_Green_Dark",
      "support": 15,
      "rotation": 3
    },
    {
      "x": -3,
      "y": 7,
      "z": 0,
      "name": "Wood_Sallow_Trunk_Full",
      "support": 15
    },
    {
      "x": -3,
      "y": 8,
      "z": 0,
      "name": "Wood_Sallow_Trunk",
      "support": 15
    },
    {
      "x": -3,
      "y": 9,
      "z": 0,
      "name": "Wood_Sallow_Trunk",
      "support": 15
    },
    {
      "x": -3,
      "y": 10,
      "z": 0,
      "name": "Wood_Sallow_Trunk",
      "support": 15
    },
    {
      "x": -3,
      "y": 11,
      "z": 0,
      "name": "Wood_Sallow_Trunk_Full",
      "support": 15
    },
    {
      "x": -3,
      "y": 12,
      "z": 0,
      "name": "Plant_Moss_Wall_Green_Dark",
      "support": 15,
      "rotation": 3
    },
    {
      "x": -3,
      "y": 6,
      "z": 1,
      "name": "Wood_Sallow_Roots"
    },
    {
      "x": -3,
      "y": 7,
      "z": 1,
      "name": "Wood_Sallow_Trunk_Full",
      "support": 15
    },
    {
      "x": -3,
      "y": 8,
      "z": 1,
      "name": "Wood_Sallow_Trunk",
      "support": 15
    },
    {
      "x": -3,
      "y": 9,
      "z": 1,
      "name": "Wood_Sallow_Trunk",
      "support": 15
    },
    {
      "x": -3,
      "y": 10,
      "z": 1,
      "name": "Wood_Sallow_Trunk",
      "support": 15
    },
    {
      "x": -3,
      "y": 11,
      "z": 1,
      "name": "Wood_Sallow_Trunk",
      "support": 15
    },
    {
      "x": -3,
      "y": 12,
      "z": 1,
      "name": "Wood_Sallow_Trunk_Full",
      "support": 15
    },
    {
      "x": -3,
      "y": 13,
      "z": 1,
      "name": "Plant_Moss_Rug_Green_Dark",
      "support": 15
    },
    {
      "x": -3,
      "y": 5,
      "z": 2,
      "name": "Wood_Sallow_Roots"
    },
    {
      "x": -3,
      "y": 6,
      "z": 2,
      "name": "Wood_Sallow_Trunk_Full",
      "support": 15
    },
    {
      "x": -3,
      "y": 7,
      "z": 2,
      "name": "Wood_Sallow_Trunk",
      "support": 15
    },
    {
      "x": -3,
      "y": 8,
      "z": 2,
      "name": "Wood_Sallow_Trunk",
      "support": 15
    },
    {
      "x": -3,
      "y": 9,
      "z": 2,
      "name": "Wood_Sallow_Trunk",
      "support": 15
    },
    {
      "x": -3,
      "y": 10,
      "z": 2,
      "name": "Wood_Sallow_Trunk",
      "support": 15
    },
    {
      "x": -3,
      "y": 11,
      "z": 2,
      "name": "Wood_Sallow_Trunk_Full",
      "support": 15
    },
    {
      "x": -3,
      "y": 12,
      "z": 2,
      "name": "Plant_Moss_Wall_Green_Dark",
      "support": 15
    },
    {
      "x": -3,
      "y": 5,
      "z": 3,
      "name": "Wood_Sallow_Roots"
    },
    {
      "x": -3,
      "y": 6,
      "z": 3,
      "name": "Wood_Sallow_Trunk_Full",
      "support": 15
    },
    {
      "x": -3,
      "y": 7,
      "z": 3,
      "name": "Wood_Sallow_Trunk",
      "support": 15
    },
    {
      "x": -3,
      "y": 8,
      "z": 3,
      "name": "Wood_Sallow_Trunk",
      "support": 15
    },
    {
      "x": -3,
      "y": 9,
      "z": 3,
      "name": "Wood_Sallow_Trunk",
      "support": 15
    },
    {
      "x": -3,
      "y": 10,
      "z": 3,
      "name": "Wood_Sallow_Trunk",
      "support": 15
    },
    {
      "x": -3,
      "y": 11,
      "z": 3,
      "name": "Wood_Sallow_Trunk_Full",
      "support": 15
    },
    {
      "x": -3,
      "y": 6,
      "z": 4,
      "name": "Wood_Sallow_Trunk_Full",
      "support": 15
    },
    {
      "x": -3,
      "y": 7,
      "z": 4,
      "name": "Wood_Sallow_Trunk",
      "support": 15
    },
    {
      "x": -3,
      "y": 8,
      "z": 4,
      "name": "Wood_Sallow_Trunk",
      "support": 15
    },
    {
      "x": -3,
      "y": 9,
      "z": 4,
      "name": "Wood_Sallow_Trunk",
      "support": 15
    },
    {
      "x": -3,
      "y": 10,
      "z": 4,
      "name": "Wood_Sallow_Trunk_Full",
      "support": 15
    },
    {
      "x": -3,
      "y": 11,
      "z": 4,
      "name": "Plant_Moss_Rug_Green_Dark",
      "support": 15
    },
    {
      "x": -3,
      "y": 2,
      "z": 8,
      "name": "Wood_Sallow_Roots"
    },
    {
      "x": -3,
      "y": 3,
      "z": 8,
      "name": "Wood_Sallow_Trunk_Full",
      "support": 15
    },
    {
      "x": -3,
      "y": 4,
      "z": 8,
      "name": "Wood_Sallow_Trunk",
      "support": 15
    },
    {
      "x": -3,
      "y": 5,
      "z": 8,
      "name": "Wood_Sallow_Trunk",
      "support": 15
    },
    {
      "x": -3,
      "y": 6,
      "z": 8,
      "name": "Wood_Sallow_Trunk",
      "support": 15
    },
    {
      "x": -3,
      "y": 7,
      "z": 8,
      "name": "Wood_Sallow_Trunk",
      "support": 15
    },
    {
      "x": -3,
      "y": 8,
      "z": 8,
      "name": "Wood_Sallow_Trunk_Full",
      "support": 15
    },
    {
      "x": -2,
      "y": 8,
      "z": -9,
      "name": "Plant_Moss_Wall_Green_Dark",
      "support": 15,
      "rotation": 2
    },
    {
      "x": -2,
      "y": 2,
      "z": -8,
      "name": "Wood_Sallow_Roots"
    },
    {
      "x": -2,
      "y": 3,
      "z": -8,
      "name": "Wood_Sallow_Trunk_Full",
      "support": 15
    },
    {
      "x": -2,
      "y": 4,
      "z": -8,
      "name": "Wood_Sallow_Trunk",
      "support": 15
    },
    {
      "x": -2,
      "y": 5,
      "z": -8,
      "name": "Wood_Sallow_Trunk",
      "support": 15
    },
    {
      "x": -2,
      "y": 6,
      "z": -8,
      "name": "Wood_Sallow_Trunk",
      "support": 15
    },
    {
      "x": -2,
      "y": 7,
      "z": -8,
      "name": "Wood_Sallow_Trunk",
      "support": 15
    },
    {
      "x": -2,
      "y": 8,
      "z": -8,
      "name": "Wood_Sallow_Trunk_Full",
      "support": 15
    },
    {
      "x": -2,
      "y": 9,
      "z": -8,
      "name": "Plant_Moss_Rug_Green_Dark",
      "support": 15
    },
    {
      "x": -2,
      "y": 3,
      "z": -7,
      "name": "Wood_Sallow_Roots"
    },
    {
      "x": -2,
      "y": 4,
      "z": -7,
      "name": "Wood_Sallow_Trunk_Full",
      "support": 15
    },
    {
      "x": -2,
      "y": 5,
      "z": -7,
      "name": "Wood_Sallow_Trunk",
      "support": 15
    },
    {
      "x": -2,
      "y": 6,
      "z": -7,
      "name": "Wood_Sallow_Trunk",
      "support": 15
    },
    {
      "x": -2,
      "y": 7,
      "z": -7,
      "name": "Wood_Sallow_Trunk",
      "support": 15
    },
    {
      "x": -2,
      "y": 8,
      "z": -7,
      "name": "Wood_Sallow_Trunk",
      "support": 15
    },
    {
      "x": -2,
      "y": 9,
      "z": -7,
      "name": "Wood_Sallow_Trunk_Full",
      "support": 15
    },
    {
      "x": -2,
      "y": 10,
      "z": -7,
      "name": "Plant_Moss_Rug_Green_Dark",
      "support": 15
    },
    {
      "x": -2,
      "y": 10,
      "z": -6,
      "name": "Plant_Moss_Wall_Green_Dark",
      "support": 15,
      "rotation": 3
    },
    {
      "x": -2,
      "y": 5,
      "z": -3,
      "name": "Wood_Sallow_Roots"
    },
    {
      "x": -2,
      "y": 6,
      "z": -3,
      "name": "Wood_Sallow_Trunk_Full",
      "support": 15
    },
    {
      "x": -2,
      "y": 7,
      "z": -3,
      "name": "Wood_Sallow_Trunk",
      "support": 15
    },
    {
      "x": -2,
      "y": 8,
      "z": -3,
      "name": "Wood_Sallow_Trunk",
      "support": 15
    },
    {
      "x": -2,
      "y": 9,
      "z": -3,
      "name": "Wood_Sallow_Trunk",
      "support": 15
    },
    {
      "x": -2,
      "y": 10,
      "z": -3,
      "name": "Wood_Sallow_Trunk",
      "support": 15
    },
    {
      "x": -2,
      "y": 11,
      "z": -3,
      "name": "Wood_Sallow_Trunk",
      "support": 15
    },
    {
      "x": -2,
      "y": 12,
      "z": -3,
      "name": "Wood_Sallow_Trunk_Full",
      "support": 15
    },
    {
      "x": -2,
      "y": 13,
      "z": -3,
      "name": "Plant_Moss_Rug_Green_Dark",
      "support": 15
    },
    {
      "x": -2,
      "y": 6,
      "z": -2,
      "name": "Wood_Sallow_Trunk_Full",
      "support": 15
    },
    {
      "x": -2,
      "y": 7,
      "z": -2,
      "name": "Wood_Sallow_Trunk",
      "support": 15
    },
    {
      "x": -2,
      "y": 8,
      "z": -2,
      "name": "Wood_Sallow_Trunk",
      "support": 15
    },
    {
      "x": -2,
      "y": 9,
      "z": -2,
      "name": "Wood_Sallow_Trunk",
      "support": 15
    },
    {
      "x": -2,
      "y": 10,
      "z": -2,
      "name": "Wood_Sallow_Trunk",
      "support": 15
    },
    {
      "x": -2,
      "y": 11,
      "z": -2,
      "name": "Wood_Sallow_Trunk_Full",
      "support": 15
    },
    {
      "x": -2,
      "y": 12,
      "z": -2,
      "name": "Plant_Moss_Rug_Green_Dark",
      "support": 15
    },
    {
      "x": -2,
      "y": 6,
      "z": -1,
      "name": "Wood_Sallow_Trunk_Full",
      "support": 15
    },
    {
      "x": -2,
      "y": 7,
      "z": -1,
      "name": "Wood_Sallow_Trunk",
      "support": 15
    },
    {
      "x": -2,
      "y": 8,
      "z": -1,
      "name": "Wood_Sallow_Trunk",
      "support": 15
    },
    {
      "x": -2,
      "y": 9,
      "z": -1,
      "name": "Wood_Sallow_Trunk",
      "support": 15
    },
    {
      "x": -2,
      "y": 10,
      "z": -1,
      "name": "Wood_Sallow_Trunk_Full",
      "support": 15
    },
    {
      "x": -2,
      "y": 6,
      "z": 0,
      "name": "Wood_Sallow_Roots"
    },
    {
      "x": -2,
      "y": 7,
      "z": 0,
      "name": "Wood_Sallow_Trunk_Full",
      "support": 15
    },
    {
      "x": -2,
      "y": 8,
      "z": 0,
      "name": "Wood_Sallow_Trunk",
      "support": 15
    },
    {
      "x": -2,
      "y": 9,
      "z": 0,
      "name": "Wood_Sallow_Trunk",
      "support": 15
    },
    {
      "x": -2,
      "y": 10,
      "z": 0,
      "name": "Wood_Sallow_Trunk",
      "support": 15
    },
    {
      "x": -2,
      "y": 11,
      "z": 0,
      "name": "Wood_Sallow_Trunk",
      "support": 15
    },
    {
      "x": -2,
      "y": 12,
      "z": 0,
      "name": "Wood_Sallow_Trunk_Full",
      "support": 15
    },
    {
      "x": -2,
      "y": 13,
      "z": 0,
      "name": "Plant_Moss_Rug_Green_Dark",
      "support": 15
    },
    {
      "x": -2,
      "y": 7,
      "z": 1,
      "name": "Wood_Sallow_Trunk_Full",
      "support": 15
    },
    {
      "x": -2,
      "y": 8,
      "z": 1,
      "name": "Wood_Sallow_Trunk",
      "support": 15
    },
    {
      "x": -2,
      "y": 9,
      "z": 1,
      "name": "Wood_Sallow_Trunk",
      "support": 15
    },
    {
      "x": -2,
      "y": 10,
      "z": 1,
      "name": "Wood_Sallow_Trunk",
      "support": 15
    },
    {
      "x": -2,
      "y": 11,
      "z": 1,
      "name": "Wood_Sallow_Trunk",
      "support": 15
    },
    {
      "x": -2,
      "y": 12,
      "z": 1,
      "name": "Wood_Sallow_Trunk",
      "support": 15
    },
    {
      "x": -2,
      "y": 13,
      "z": 1,
      "name": "Wood_Sallow_Trunk_Full",
      "support": 15
    },
    {
      "x": -2,
      "y": 14,
      "z": 1,
      "name": "Plant_Moss_Rug_Green_Dark",
      "support": 15
    },
    {
      "x": -2,
      "y": 7,
      "z": 2,
      "name": "Wood_Sallow_Trunk_Full",
      "support": 15
    },
    {
      "x": -2,
      "y": 8,
      "z": 2,
      "name": "Wood_Sallow_Trunk",
      "support": 15
    },
    {
      "x": -2,
      "y": 9,
      "z": 2,
      "name": "Wood_Sallow_Trunk",
      "support": 15
    },
    {
      "x": -2,
      "y": 10,
      "z": 2,
      "name": "Wood_Sallow_Trunk",
      "support": 15
    },
    {
      "x": -2,
      "y": 11,
      "z": 2,
      "name": "Wood_Sallow_Trunk",
      "support": 15
    },
    {
      "x": -2,
      "y": 12,
      "z": 2,
      "name": "Wood_Sallow_Trunk",
      "support": 15
    },
    {
      "x": -2,
      "y": 13,
      "z": 2,
      "name": "Wood_Sallow_Trunk",
      "support": 15
    },
    {
      "x": -2,
      "y": 14,
      "z": 2,
      "name": "Wood_Sallow_Trunk",
      "support": 15
    },
    {
      "x": -2,
      "y": 15,
      "z": 2,
      "name": "Wood_Sallow_Trunk",
      "support": 15
    },
    {
      "x": -2,
      "y": 16,
      "z": 2,
      "name": "Wood_Sallow_Trunk_Full",
      "support": 15
    },
    {
      "x": -2,
      "y": 6,
      "z": 3,
      "name": "Wood_Sallow_Trunk_Full",
      "support": 15
    },
    {
      "x": -2,
      "y": 7,
      "z": 3,
      "name": "Wood_Sallow_Trunk",
      "support": 15
    },
    {
      "x": -2,
      "y": 8,
      "z": 3,
      "name": "Wood_Sallow_Trunk",
      "support": 15
    },
    {
      "x": -2,
      "y": 9,
      "z": 3,
      "name": "Wood_Sallow_Trunk",
      "support": 15
    },
    {
      "x": -2,
      "y": 10,
      "z": 3,
      "name": "Wood_Sallow_Trunk",
      "support": 15
    },
    {
      "x": -2,
      "y": 11,
      "z": 3,
      "name": "Wood_Sallow_Trunk_Full",
      "support": 15
    },
    {
      "x": -2,
      "y": 12,
      "z": 3,
      "name": "Plant_Moss_Rug_Green_Dark",
      "support": 15
    },
    {
      "x": -2,
      "y": 10,
      "z": 4,
      "name": "Plant_Moss_Wall_Green_Dark",
      "support": 15,
      "rotation": 1
    },
    {
      "x": -2,
      "y": 10,
      "z": 6,
      "name": "Plant_Moss_Wall_Green_Dark",
      "support": 15,
      "rotation": 3
    },
    {
      "x": -2,
      "y": 3,
      "z": 7,
      "name": "Wood_Sallow_Roots"
    },
    {
      "x": -2,
      "y": 4,
      "z": 7,
      "name": "Wood_Sallow_Trunk_Full",
      "support": 15
    },
    {
      "x": -2,
      "y": 5,
      "z": 7,
      "name": "Wood_Sallow_Trunk",
      "support": 15
    },
    {
      "x": -2,
      "y": 6,
      "z": 7,
      "name": "Wood_Sallow_Trunk",
      "support": 15
    },
    {
      "x": -2,
      "y": 7,
      "z": 7,
      "name": "Wood_Sallow_Trunk",
      "support": 15
    },
    {
      "x": -2,
      "y": 8,
      "z": 7,
      "name": "Wood_Sallow_Trunk",
      "support": 15
    },
    {
      "x": -2,
      "y": 9,
      "z": 7,
      "name": "Wood_Sallow_Trunk_Full",
      "support": 15
    },
    {
      "x": -2,
      "y": 10,
      "z": 7,
      "name": "Plant_Moss_Rug_Green_Dark",
      "support": 15
    },
    {
      "x": -2,
      "y": 9,
      "z": 8,
      "name": "Plant_Moss_Wall_Green_Dark",
      "support": 15
    },
    {
      "x": -1,
      "y": 8,
      "z": -8,
      "name": "Plant_Moss_Wall_Green_Dark",
      "support": 15,
      "rotation": 1
    },
    {
      "x": -1,
      "y": 9,
      "z": -7,
      "name": "Plant_Moss_Wall_Green_Dark",
      "support": 15,
      "rotation": 1
    },
    {
      "x": -1,
      "y": 4,
      "z": -6,
      "name": "Wood_Sallow_Roots"
    },
    {
      "x": -1,
      "y": 5,
      "z": -6,
      "name": "Wood_Sallow_Trunk_Full",
      "support": 15
    },
    {
      "x": -1,
      "y": 6,
      "z": -6,
      "name": "Wood_Sallow_Trunk",
      "support": 15
    },
    {
      "x": -1,
      "y": 7,
      "z": -6,
      "name": "Wood_Sallow_Trunk",
      "support": 15
    },
    {
      "x": -1,
      "y": 8,
      "z": -6,
      "name": "Wood_Sallow_Trunk",
      "support": 15
    },
    {
      "x": -1,
      "y": 9,
      "z": -6,
      "name": "Wood_Sallow_Trunk",
      "support": 15
    },
    {
      "x": -1,
      "y": 10,
      "z": -6,
      "name": "Wood_Sallow_Trunk_Full",
      "support": 15
    },
    {
      "x": -1,
      "y": 11,
      "z": -6,
      "name": "Plant_Moss_Rug_Green_Dark",
      "support": 15
    },
    {
      "x": -1,
      "y": 5,
      "z": -5,
      "name": "Wood_Sallow_Roots"
    },
    {
      "x": -1,
      "y": 6,
      "z": -5,
      "name": "Wood_Sallow_Trunk_Full",
      "support": 15
    },
    {
      "x": -1,
      "y": 7,
      "z": -5,
      "name": "Wood_Sallow_Trunk",
      "support": 15
    },
    {
      "x": -1,
      "y": 8,
      "z": -5,
      "name": "Wood_Sallow_Trunk",
      "support": 15
    },
    {
      "x": -1,
      "y": 9,
      "z": -5,
      "name": "Wood_Sallow_Trunk",
      "support": 15
    },
    {
      "x": -1,
      "y": 10,
      "z": -5,
      "name": "Wood_Sallow_Trunk",
      "support": 15
    },
    {
      "x": -1,
      "y": 11,
      "z": -5,
      "name": "Wood_Sallow_Trunk_Full",
      "support": 15
    },
    {
      "x": -1,
      "y": 7,
      "z": -3,
      "name": "Wood_Sallow_Trunk_Full",
      "support": 15
    },
    {
      "x": -1,
      "y": 8,
      "z": -3,
      "name": "Wood_Sallow_Trunk",
      "support": 15
    },
    {
      "x": -1,
      "y": 9,
      "z": -3,
      "name": "Wood_Sallow_Trunk",
      "support": 15
    },
    {
      "x": -1,
      "y": 10,
      "z": -3,
      "name": "Wood_Sallow_Trunk",
      "support": 15
    },
    {
      "x": -1,
      "y": 11,
      "z": -3,
      "name": "Wood_Sallow_Trunk_Full",
      "support": 15
    },
    {
      "x": -1,
      "y": 13,
      "z": -3,
      "name": "Plant_Moss_Wall_Green_Dark",
      "support": 15,
      "rotation": 2
    },
    {
      "x": -1,
      "y": 5,
      "z": -2,
      "name": "Wood_Sallow_Roots"
    },
    {
      "x": -1,
      "y": 6,
      "z": -2,
      "name": "Wood_Sallow_Trunk_Full",
      "support": 15
    },
    {
      "x": -1,
      "y": 7,
      "z": -2,
      "name": "Wood_Sallow_Trunk",
      "support": 15
    },
    {
      "x": -1,
      "y": 8,
      "z": -2,
      "name": "Wood_Sallow_Trunk",
      "support": 15
    },
    {
      "x": -1,
      "y": 9,
      "z": -2,
      "name": "Wood_Sallow_Trunk",
      "support": 15
    },
    {
      "x": -1,
      "y": 10,
      "z": -2,
      "name": "Wood_Sallow_Trunk",
      "support": 15
    },
    {
      "x": -1,
      "y": 11,
      "z": -2,
      "name": "Wood_Sallow_Trunk",
      "support": 15
    },
    {
      "x": -1,
      "y": 12,
      "z": -2,
      "name": "Wood_Sallow_Trunk",
      "support": 15
    },
    {
      "x": -1,
      "y": 13,
      "z": -2,
      "name": "Wood_Sallow_Trunk_Full",
      "support": 15
    },
    {
      "x": -1,
      "y": 14,
      "z": -2,
      "name": "Plant_Moss_Rug_Green_Dark",
      "support": 15
    },
    {
      "x": -1,
      "y": 5,
      "z": -1,
      "name": "Wood_Sallow_Roots"
    },
    {
      "x": -1,
      "y": 6,
      "z": -1,
      "name": "Wood_Sallow_Trunk_Full",
      "support": 15
    },
    {
      "x": -1,
      "y": 7,
      "z": -1,
      "name": "Wood_Sallow_Trunk",
      "support": 15
    },
    {
      "x": -1,
      "y": 8,
      "z": -1,
      "name": "Wood_Sallow_Trunk"
    },
    {
      "x": -1,
      "y": 9,
      "z": -1,
      "name": "Wood_Sallow_Trunk"
    },
    {
      "x": -1,
      "y": 10,
      "z": -1,
      "name": "Wood_Sallow_Trunk"
    },
    {
      "x": -1,
      "y": 11,
      "z": -1,
      "name": "Wood_Sallow_Trunk"
    },
    {
      "x": -1,
      "y": 12,
      "z": -1,
      "name": "Wood_Sallow_Trunk"
    },
    {
      "x": -1,
      "y": 13,
      "z": -1,
      "name": "Wood_Sallow_Trunk"
    },
    {
      "x": -1,
      "y": 14,
      "z": -1,
      "name": "Wood_Sallow_Trunk"
    },
    {
      "x": -1,
      "y": 15,
      "z": -1,
      "name": "Wood_Sallow_Trunk"
    },
    {
      "x": -1,
      "y": 16,
      "z": -1,
      "name": "Wood_Sallow_Trunk"
    },
    {
      "x": -1,
      "y": 7,
      "z": 0,
      "name": "Wood_Sallow_Roots"
    },
    {
      "x": -1,
      "y": 8,
      "z": 0,
      "name": "Wood_Sallow_Trunk_Full",
      "support": 15
    },
    {
      "x": -1,
      "y": 9,
      "z": 0,
      "name": "Wood_Sallow_Trunk"
    },
    {
      "x": -1,
      "y": 10,
      "z": 0,
      "name": "Wood_Sallow_Trunk"
    },
    {
      "x": -1,
      "y": 11,
      "z": 0,
      "name": "Wood_Sallow_Trunk"
    },
    {
      "x": -1,
      "y": 12,
      "z": 0,
      "name": "Wood_Sallow_Trunk"
    },
    {
      "x": -1,
      "y": 13,
      "z": 0,
      "name": "Wood_Sallow_Trunk"
    },
    {
      "x": -1,
      "y": 14,
      "z": 0,
      "name": "Wood_Sallow_Trunk"
    },
    {
      "x": -1,
      "y": 15,
      "z": 0,
      "name": "Wood_Sallow_Trunk"
    },
    {
      "x": -1,
      "y": 16,
      "z": 0,
      "name": "Wood_Sallow_Trunk"
    },
    {
      "x": -1,
      "y": 8,
      "z": 1,
      "name": "Wood_Sallow_Trunk_Full",
      "support": 15
    },
    {
      "x": -1,
      "y": 9,
      "z": 1,
      "name": "Wood_Sallow_Trunk"
    },
    {
      "x": -1,
      "y": 10,
      "z": 1,
      "name": "Wood_Sallow_Trunk"
    },
    {
      "x": -1,
      "y": 11,
      "z": 1,
      "name": "Wood_Sallow_Trunk"
    },
    {
      "x": -1,
      "y": 12,
      "z": 1,
      "name": "Wood_Sallow_Trunk"
    },
    {
      "x": -1,
      "y": 13,
      "z": 1,
      "name": "Wood_Sallow_Trunk"
    },
    {
      "x": -1,
      "y": 14,
      "z": 1,
      "name": "Wood_Sallow_Trunk"
    },
    {
      "x": -1,
      "y": 15,
      "z": 1,
      "name": "Wood_Sallow_Trunk"
    },
    {
      "x": -1,
      "y": 16,
      "z": 1,
      "name": "Wood_Sallow_Trunk"
    },
    {
      "x": -1,
      "y": 6,
      "z": 2,
      "name": "Wood_Sallow_Roots"
    },
    {
      "x": -1,
      "y": 7,
      "z": 2,
      "name": "Wood_Sallow_Trunk_Full",
      "support": 15
    },
    {
      "x": -1,
      "y": 8,
      "z": 2,
      "name": "Wood_Sallow_Trunk",
      "support": 15
    },
    {
      "x": -1,
      "y": 9,
      "z": 2,
      "name": "Wood_Sallow_Trunk",
      "support": 15
    },
    {
      "x": -1,
      "y": 10,
      "z": 2,
      "name": "Wood_Sallow_Trunk",
      "support": 15
    },
    {
      "x": -1,
      "y": 11,
      "z": 2,
      "name": "Wood_Sallow_Trunk",
      "support": 15
    },
    {
      "x": -1,
      "y": 12,
      "z": 2,
      "name": "Wood_Sallow_Trunk",
      "support": 15
    },
    {
      "x": -1,
      "y": 13,
      "z": 2,
      "name": "Wood_Sallow_Trunk_Full",
      "support": 15
    },
    {
      "x": -1,
      "y": 14,
      "z": 2,
      "name": "Plant_Moss_Rug_Green_Dark",
      "support": 15
    },
    {
      "x": -1,
      "y": 13,
      "z": 3,
      "name": "Plant_Moss_Wall_Green_Dark",
      "support": 15
    },
    {
      "x": -1,
      "y": 12,
      "z": 4,
      "name": "Plant_Moss_Wall_Green_Dark",
      "support": 15,
      "rotation": 3
    },
    {
      "x": -1,
      "y": 3,
      "z": 6,
      "name": "Wood_Sallow_Roots"
    },
    {
      "x": -1,
      "y": 4,
      "z": 6,
      "name": "Wood_Sallow_Trunk_Full",
      "support": 15
    },
    {
      "x": -1,
      "y": 5,
      "z": 6,
      "name": "Wood_Sallow_Trunk",
      "support": 15
    },
    {
      "x": -1,
      "y": 6,
      "z": 6,
      "name": "Wood_Sallow_Trunk",
      "support": 15
    },
    {
      "x": -1,
      "y": 7,
      "z": 6,
      "name": "Wood_Sallow_Trunk",
      "support": 15
    },
    {
      "x": -1,
      "y": 8,
      "z": 6,
      "name": "Wood_Sallow_Trunk",
      "support": 15
    },
    {
      "x": -1,
      "y": 9,
      "z": 6,
      "name": "Wood_Sallow_Trunk",
      "support": 15
    },
    {
      "x": -1,
      "y": 10,
      "z": 6,
      "name": "Wood_Sallow_Trunk_Full",
      "support": 15
    },
    {
      "x": -1,
      "y": 11,
      "z": 6,
      "name": "Plant_Moss_Rug_Green_Dark",
      "support": 15
    },
    {
      "x": -1,
      "y": 9,
      "z": 7,
      "name": "Plant_Moss_Wall_Green_Dark",
      "support": 15,
      "rotation": 1
    },
    {
      "x": 0,
      "y": 5,
      "z": -4,
      "name": "Wood_Sallow_Roots"
    },
    {
      "x": 0,
      "y": 6,
      "z": -4,
      "name": "Wood_Sallow_Trunk_Full",
      "support": 15
    },
    {
      "x": 0,
      "y": 7,
      "z": -4,
      "name": "Wood_Sallow_Trunk",
      "support": 15
    },
    {
      "x": 0,
      "y": 8,
      "z": -4,
      "name": "Wood_Sallow_Trunk",
      "support": 15
    },
    {
      "x": 0,
      "y": 9,
      "z": -4,
      "name": "Wood_Sallow_Trunk",
      "support": 15
    },
    {
      "x": 0,
      "y": 10,
      "z": -4,
      "name": "Wood_Sallow_Trunk",
      "support": 15
    },
    {
      "x": 0,
      "y": 11,
      "z": -4,
      "name": "Wood_Sallow_Trunk_Full",
      "support": 15
    },
    {
      "x": 0,
      "y": 6,
      "z": -3,
      "name": "Wood_Sallow_Roots"
    },
    {
      "x": 0,
      "y": 7,
      "z": -3,
      "name": "Wood_Sallow_Trunk_Full",
      "support": 15
    },
    {
      "x": 0,
      "y": 8,
      "z": -3,
      "name": "Wood_Sallow_Trunk",
      "support": 15
    },
    {
      "x": 0,
      "y": 9,
      "z": -3,
      "name": "Wood_Sallow_Trunk",
      "support": 15
    },
    {
      "x": 0,
      "y": 10,
      "z": -3,
      "name": "Wood_Sallow_Trunk",
      "support": 15
    },
    {
      "x": 0,
      "y": 11,
      "z": -3,
      "name": "Wood_Sallow_Trunk",
      "support": 15
    },
    {
      "x": 0,
      "y": 12,
      "z": -3,
      "name": "Wood_Sallow_Trunk_Full",
      "support": 15
    },
    {
      "x": 0,
      "y": 6,
      "z": -2,
      "name": "Wood_Sallow_Roots"
    },
    {
      "x": 0,
      "y": 7,
      "z": -2,
      "name": "Wood_Sallow_Trunk_Full",
      "support": 15
    },
    {
      "x": 0,
      "y": 8,
      "z": -2,
      "name": "Wood_Sallow_Trunk",
      "support": 15
    },
    {
      "x": 0,
      "y": 9,
      "z": -2,
      "name": "Wood_Sallow_Trunk",
      "support": 15
    },
    {
      "x": 0,
      "y": 10,
      "z": -2,
      "name": "Wood_Sallow_Trunk",
      "support": 15
    },
    {
      "x": 0,
      "y": 11,
      "z": -2,
      "name": "Wood_Sallow_Trunk",
      "support": 15
    },
    {
      "x": 0,
      "y": 12,
      "z": -2,
      "name": "Wood_Sallow_Trunk",
      "support": 15
    },
    {
      "x": 0,
      "y": 13,
      "z": -2,
      "name": "Wood_Sallow_Trunk",
      "support": 15
    },
    {
      "x": 0,
      "y": 14,
      "z": -2,
      "name": "Wood_Sallow_Trunk",
      "support": 15
    },
    {
      "x": 0,
      "y": 15,
      "z": -2,
      "name": "Wood_Sallow_Trunk_Full",
      "support": 15
    },
    {
      "x": 0,
      "y": 16,
      "z": -2,
      "name": "Wood_Sallow_Trunk_Full",
      "support": 15
    },
    {
      "x": 0,
      "y": 6,
      "z": -1,
      "name": "Wood_Sallow_Roots"
    },
    {
      "x": 0,
      "y": 7,
      "z": -1,
      "name": "Wood_Sallow_Trunk_Full",
      "support": 15
    },
    {
      "x": 0,
      "y": 8,
      "z": -1,
      "name": "Wood_Sallow_Trunk"
    },
    {
      "x": 0,
      "y": 9,
      "z": -1,
      "name": "Wood_Sallow_Trunk"
    },
    {
      "x": 0,
      "y": 10,
      "z": -1,
      "name": "Wood_Sallow_Trunk"
    },
    {
      "x": 0,
      "y": 11,
      "z": -1,
      "name": "Wood_Sallow_Trunk"
    },
    {
      "x": 0,
      "y": 12,
      "z": -1,
      "name": "Wood_Sallow_Trunk"
    },
    {
      "x": 0,
      "y": 13,
      "z": -1,
      "name": "Wood_Sallow_Trunk"
    },
    {
      "x": 0,
      "y": 14,
      "z": -1,
      "name": "Wood_Sallow_Trunk"
    },
    {
      "x": 0,
      "y": 15,
      "z": -1,
      "name": "Wood_Sallow_Trunk"
    },
    {
      "x": 0,
      "y": 16,
      "z": -1,
      "name": "Wood_Sallow_Trunk"
    },
    {
      "x": 0,
      "y": 8,
      "z": 0,
      "name": "Wood_Sallow_Trunk_Full",
      "support": 15
    },
    {
      "x": 0,
      "y": 9,
      "z": 0,
      "name": "Wood_Sallow_Trunk"
    },
    {
      "x": 0,
      "y": 10,
      "z": 0,
      "name": "Wood_Sallow_Trunk"
    },
    {
      "x": 0,
      "y": 11,
      "z": 0,
      "name": "Wood_Sallow_Trunk"
    },
    {
      "x": 0,
      "y": 12,
      "z": 0,
      "name": "Wood_Sallow_Trunk"
    },
    {
      "x": 0,
      "y": 13,
      "z": 0,
      "name": "Wood_Sallow_Trunk"
    },
    {
      "x": 0,
      "y": 14,
      "z": 0,
      "name": "Wood_Sallow_Trunk"
    },
    {
      "x": 0,
      "y": 15,
      "z": 0,
      "name": "Wood_Sallow_Trunk"
    },
    {
      "x": 0,
      "y": 16,
      "z": 0,
      "name": "Wood_Sallow_Trunk"
    },
    {
      "x": 0,
      "y": 7,
      "z": 1,
      "name": "Wood_Sallow_Roots"
    },
    {
      "x": 0,
      "y": 8,
      "z": 1,
      "name": "Wood_Sallow_Trunk_Full",
      "support": 15
    },
    {
      "x": 0,
      "y": 9,
      "z": 1,
      "name": "Wood_Sallow_Trunk"
    },
    {
      "x": 0,
      "y": 10,
      "z": 1,
      "name": "Wood_Sallow_Trunk"
    },
    {
      "x": 0,
      "y": 11,
      "z": 1,
      "name": "Wood_Sallow_Trunk"
    },
    {
      "x": 0,
      "y": 12,
      "z": 1,
      "name": "Wood_Sallow_Trunk"
    },
    {
      "x": 0,
      "y": 13,
      "z": 1,
      "name": "Wood_Sallow_Trunk"
    },
    {
      "x": 0,
      "y": 14,
      "z": 1,
      "name": "Wood_Sallow_Trunk"
    },
    {
      "x": 0,
      "y": 15,
      "z": 1,
      "name": "Wood_Sallow_Trunk"
    },
    {
      "x": 0,
      "y": 16,
      "z": 1,
      "name": "Wood_Sallow_Trunk"
    },
    {
      "x": 0,
      "y": 7,
      "z": 2,
      "name": "Wood_Sallow_Trunk_Full",
      "support": 15
    },
    {
      "x": 0,
      "y": 8,
      "z": 2,
      "name": "Wood_Sallow_Trunk",
      "support": 15
    },
    {
      "x": 0,
      "y": 9,
      "z": 2,
      "name": "Wood_Sallow_Trunk",
      "support": 15
    },
    {
      "x": 0,
      "y": 10,
      "z": 2,
      "name": "Wood_Sallow_Trunk",
      "support": 15
    },
    {
      "x": 0,
      "y": 11,
      "z": 2,
      "name": "Wood_Sallow_Trunk",
      "support": 15
    },
    {
      "x": 0,
      "y": 12,
      "z": 2,
      "name": "Wood_Sallow_Trunk",
      "support": 15
    },
    {
      "x": 0,
      "y": 13,
      "z": 2,
      "name": "Wood_Sallow_Trunk",
      "support": 15
    },
    {
      "x": 0,
      "y": 14,
      "z": 2,
      "name": "Wood_Sallow_Trunk",
      "support": 15
    },
    {
      "x": 0,
      "y": 15,
      "z": 2,
      "name": "Wood_Sallow_Trunk",
      "support": 15
    },
    {
      "x": 0,
      "y": 16,
      "z": 2,
      "name": "Wood_Sallow_Trunk",
      "support": 15
    },
    {
      "x": 0,
      "y": 6,
      "z": 3,
      "name": "Wood_Sallow_Roots"
    },
    {
      "x": 0,
      "y": 7,
      "z": 3,
      "name": "Wood_Sallow_Trunk_Full",
      "support": 15
    },
    {
      "x": 0,
      "y": 8,
      "z": 3,
      "name": "Wood_Sallow_Trunk",
      "support": 15
    },
    {
      "x": 0,
      "y": 9,
      "z": 3,
      "name": "Wood_Sallow_Trunk",
      "support": 15
    },
    {
      "x": 0,
      "y": 10,
      "z": 3,
      "name": "Wood_Sallow_Trunk",
      "support": 15
    },
    {
      "x": 0,
      "y": 11,
      "z": 3,
      "name": "Wood_Sallow_Trunk",
      "support": 15
    },
    {
      "x": 0,
      "y": 12,
      "z": 3,
      "name": "Wood_Sallow_Trunk",
      "support": 15
    },
    {
      "x": 0,
      "y": 13,
      "z": 3,
      "name": "Wood_Sallow_Trunk_Full",
      "support": 15
    },
    {
      "x": 0,
      "y": 14,
      "z": 3,
      "name": "Plant_Moss_Rug_Green_Dark",
      "support": 15
    },
    {
      "x": 0,
      "y": 5,
      "z": 4,
      "name": "Wood_Sallow_Roots"
    },
    {
      "x": 0,
      "y": 6,
      "z": 4,
      "name": "Wood_Sallow_Trunk_Full",
      "support": 15
    },
    {
      "x": 0,
      "y": 7,
      "z": 4,
      "name": "Wood_Sallow_Trunk",
      "support": 15
    },
    {
      "x": 0,
      "y": 8,
      "z": 4,
      "name": "Wood_Sallow_Trunk",
      "support": 15
    },
    {
      "x": 0,
      "y": 9,
      "z": 4,
      "name": "Wood_Sallow_Trunk",
      "support": 15
    },
    {
      "x": 0,
      "y": 10,
      "z": 4,
      "name": "Wood_Sallow_Trunk",
      "support": 15
    },
    {
      "x": 0,
      "y": 11,
      "z": 4,
      "name": "Wood_Sallow_Trunk",
      "support": 15
    },
    {
      "x": 0,
      "y": 12,
      "z": 4,
      "name": "Wood_Sallow_Trunk_Full",
      "support": 15
    },
    {
      "x": 0,
      "y": 13,
      "z": 4,
      "name": "Plant_Moss_Rug_Green_Dark",
      "support": 15
    },
    {
      "x": 0,
      "y": 4,
      "z": 5,
      "name": "Wood_Sallow_Roots"
    },
    {
      "x": 0,
      "y": 5,
      "z": 5,
      "name": "Wood_Sallow_Trunk_Full",
      "support": 15
    },
    {
      "x": 0,
      "y": 6,
      "z": 5,
      "name": "Wood_Sallow_Trunk",
      "support": 15
    },
    {
      "x": 0,
      "y": 7,
      "z": 5,
      "name": "Wood_Sallow_Trunk",
      "support": 15
    },
    {
      "x": 0,
      "y": 8,
      "z": 5,
      "name": "Wood_Sallow_Trunk",
      "support": 15
    },
    {
      "x": 0,
      "y": 9,
      "z": 5,
      "name": "Wood_Sallow_Trunk",
      "support": 15
    },
    {
      "x": 0,
      "y": 10,
      "z": 5,
      "name": "Wood_Sallow_Trunk",
      "support": 15
    },
    {
      "x": 0,
      "y": 11,
      "z": 5,
      "name": "Wood_Sallow_Trunk_Full",
      "support": 15
    },
    {
      "x": 0,
      "y": 12,
      "z": 5,
      "name": "Plant_Moss_Wall_Green_Dark",
      "support": 15
    },
    {
      "x": 0,
      "y": 9,
      "z": 7,
      "name": "Plant_Moss_Wall_Green_Dark",
      "support": 15,
      "rotation": 3
    },
    {
      "x": 1,
      "y": 6,
      "z": -2,
      "name": "Wood_Sallow_Roots"
    },
    {
      "x": 1,
      "y": 7,
      "z": -2,
      "name": "Wood_Sallow_Trunk_Full",
      "support": 15
    },
    {
      "x": 1,
      "y": 8,
      "z": -2,
      "name": "Wood_Sallow_Trunk",
      "support": 15
    },
    {
      "x": 1,
      "y": 9,
      "z": -2,
      "name": "Wood_Sallow_Trunk",
      "support": 15
    },
    {
      "x": 1,
      "y": 10,
      "z": -2,
      "name": "Wood_Sallow_Trunk",
      "support": 15
    },
    {
      "x": 1,
      "y": 11,
      "z": -2,
      "name": "Wood_Sallow_Trunk",
      "support": 15
    },
    {
      "x": 1,
      "y": 12,
      "z": -2,
      "name": "Wood_Sallow_Trunk",
      "support": 15
    },
    {
      "x": 1,
      "y": 13,
      "z": -2,
      "name": "Wood_Sallow_Trunk_Full",
      "support": 15
    },
    {
      "x": 1,
      "y": 7,
      "z": -1,
      "name": "Wood_Sallow_Trunk_Full",
      "support": 15
    },
    {
      "x": 1,
      "y": 8,
      "z": -1,
      "name": "Wood_Sallow_Trunk"
    },
    {
      "x": 1,
      "y": 9,
      "z": -1,
      "name": "Wood_Sallow_Trunk"
    },
    {
      "x": 1,
      "y": 10,
      "z": -1,
      "name": "Wood_Sallow_Trunk"
    },
    {
      "x": 1,
      "y": 11,
      "z": -1,
      "name": "Wood_Sallow_Trunk"
    },
    {
      "x": 1,
      "y": 12,
      "z": -1,
      "name": "Wood_Sallow_Trunk"
    },
    {
      "x": 1,
      "y": 13,
      "z": -1,
      "name": "Wood_Sallow_Trunk"
    },
    {
      "x": 1,
      "y": 14,
      "z": -1,
      "name": "Wood_Sallow_Trunk"
    },
    {
      "x": 1,
      "y": 15,
      "z": -1,
      "name": "Wood_Sallow_Trunk"
    },
    {
      "x": 1,
      "y": 16,
      "z": -1,
      "name": "Wood_Sallow_Trunk"
    },
    {
      "x": 1,
      "y": 6,
      "z": 0,
      "name": "Wood_Sallow_Roots"
    },
    {
      "x": 1,
      "y": 7,
      "z": 0,
      "name": "Wood_Sallow_Trunk_Full",
      "support": 15
    },
    {
      "x": 1,
      "y": 8,
      "z": 0,
      "name": "Wood_Sallow_Trunk",
      "support": 15
    },
    {
      "x": 1,
      "y": 9,
      "z": 0,
      "name": "Wood_Sallow_Trunk"
    },
    {
      "x": 1,
      "y": 10,
      "z": 0,
      "name": "Wood_Sallow_Trunk"
    },
    {
      "x": 1,
      "y": 11,
      "z": 0,
      "name": "Wood_Sallow_Trunk"
    },
    {
      "x": 1,
      "y": 12,
      "z": 0,
      "name": "Wood_Sallow_Trunk"
    },
    {
      "x": 1,
      "y": 13,
      "z": 0,
      "name": "Wood_Sallow_Trunk"
    },
    {
      "x": 1,
      "y": 14,
      "z": 0,
      "name": "Wood_Sallow_Trunk"
    },
    {
      "x": 1,
      "y": 15,
      "z": 0,
      "name": "Wood_Sallow_Trunk"
    },
    {
      "x": 1,
      "y": 16,
      "z": 0,
      "name": "Wood_Sallow_Trunk"
    },
    {
      "x": 1,
      "y": 6,
      "z": 1,
      "name": "Wood_Sallow_Roots"
    },
    {
      "x": 1,
      "y": 7,
      "z": 1,
      "name": "Wood_Sallow_Trunk_Full",
      "support": 15
    },
    {
      "x": 1,
      "y": 8,
      "z": 1,
      "name": "Wood_Sallow_Trunk"
    },
    {
      "x": 1,
      "y": 9,
      "z": 1,
      "name": "Wood_Sallow_Trunk"
    },
    {
      "x": 1,
      "y": 10,
      "z": 1,
      "name": "Wood_Sallow_Trunk"
    },
    {
      "x": 1,
      "y": 11,
      "z": 1,
      "name": "Wood_Sallow_Trunk"
    },
    {
      "x": 1,
      "y": 12,
      "z": 1,
      "name": "Wood_Sallow_Trunk"
    },
    {
      "x": 1,
      "y": 13,
      "z": 1,
      "name": "Wood_Sallow_Trunk"
    },
    {
      "x": 1,
      "y": 14,
      "z": 1,
      "name": "Wood_Sallow_Trunk"
    },
    {
      "x": 1,
      "y": 15,
      "z": 1,
      "name": "Wood_Sallow_Trunk"
    },
    {
      "x": 1,
      "y": 16,
      "z": 1,
      "name": "Wood_Sallow_Trunk"
    },
    {
      "x": 1,
      "y": 7,
      "z": 2,
      "name": "Wood_Sallow_Trunk_Full",
      "support": 15
    },
    {
      "x": 1,
      "y": 8,
      "z": 2,
      "name": "Wood_Sallow_Trunk",
      "support": 15
    },
    {
      "x": 1,
      "y": 9,
      "z": 2,
      "name": "Wood_Sallow_Trunk",
      "support": 15
    },
    {
      "x": 1,
      "y": 10,
      "z": 2,
      "name": "Wood_Sallow_Trunk",
      "support": 15
    },
    {
      "x": 1,
      "y": 11,
      "z": 2,
      "name": "Wood_Sallow_Trunk",
      "support": 15
    },
    {
      "x": 1,
      "y": 12,
      "z": 2,
      "name": "Wood_Sallow_Trunk_Full",
      "support": 15
    },
    {
      "x": 1,
      "y": 4,
      "z": 6,
      "name": "Wood_Sallow_Roots"
    },
    {
      "x": 1,
      "y": 5,
      "z": 6,
      "name": "Wood_Sallow_Trunk_Full",
      "support": 15
    },
    {
      "x": 1,
      "y": 6,
      "z": 6,
      "name": "Wood_Sallow_Trunk",
      "support": 15
    },
    {
      "x": 1,
      "y": 7,
      "z": 6,
      "name": "Wood_Sallow_Trunk",
      "support": 15
    },
    {
      "x": 1,
      "y": 8,
      "z": 6,
      "name": "Wood_Sallow_Trunk",
      "support": 15
    },
    {
      "x": 1,
      "y": 9,
      "z": 6,
      "name": "Wood_Sallow_Trunk",
      "support": 15
    },
    {
      "x": 1,
      "y": 10,
      "z": 6,
      "name": "Wood_Sallow_Trunk_Full",
      "support": 15
    },
    {
      "x": 1,
      "y": 3,
      "z": 7,
      "name": "Wood_Sallow_Roots"
    },
    {
      "x": 1,
      "y": 4,
      "z": 7,
      "name": "Wood_Sallow_Trunk_Full",
      "support": 15
    },
    {
      "x": 1,
      "y": 5,
      "z": 7,
      "name": "Wood_Sallow_Trunk",
      "support": 15
    },
    {
      "x": 1,
      "y": 6,
      "z": 7,
      "name": "Wood_Sallow_Trunk",
      "support": 15
    },
    {
      "x": 1,
      "y": 7,
      "z": 7,
      "name": "Wood_Sallow_Trunk",
      "support": 15
    },
    {
      "x": 1,
      "y": 8,
      "z": 7,
      "name": "Wood_Sallow_Trunk",
      "support": 15
    },
    {
      "x": 1,
      "y": 9,
      "z": 7,
      "name": "Wood_Sallow_Trunk_Full",
      "support": 15
    },
    {
      "x": 1,
      "y": 10,
      "z": 7,
      "name": "Plant_Moss_Rug_Green_Dark",
      "support": 15
    },
    {
      "x": 1,
      "y": 2,
      "z": 8,
      "name": "Wood_Sallow_Roots"
    },
    {
      "x": 1,
      "y": 3,
      "z": 8,
      "name": "Wood_Sallow_Trunk_Full",
      "support": 15
    },
    {
      "x": 1,
      "y": 4,
      "z": 8,
      "name": "Wood_Sallow_Trunk",
      "support": 15
    },
    {
      "x": 1,
      "y": 5,
      "z": 8,
      "name": "Wood_Sallow_Trunk",
      "support": 15
    },
    {
      "x": 1,
      "y": 6,
      "z": 8,
      "name": "Wood_Sallow_Trunk",
      "support": 15
    },
    {
      "x": 1,
      "y": 7,
      "z": 8,
      "name": "Wood_Sallow_Trunk",
      "support": 15
    },
    {
      "x": 1,
      "y": 8,
      "z": 8,
      "name": "Wood_Sallow_Trunk_Full",
      "support": 15
    },
    {
      "x": 1,
      "y": 9,
      "z": 8,
      "name": "Plant_Moss_Rug_Green_Dark",
      "support": 15
    },
    {
      "x": 2,
      "y": 6,
      "z": -2,
      "name": "Wood_Sallow_Roots"
    },
    {
      "x": 2,
      "y": 7,
      "z": -2,
      "name": "Wood_Sallow_Trunk_Full",
      "support": 15
    },
    {
      "x": 2,
      "y": 8,
      "z": -2,
      "name": "Wood_Sallow_Trunk",
      "support": 15
    },
    {
      "x": 2,
      "y": 9,
      "z": -2,
      "name": "Wood_Sallow_Trunk",
      "support": 15
    },
    {
      "x": 2,
      "y": 10,
      "z": -2,
      "name": "Wood_Sallow_Trunk",
      "support": 15
    },
    {
      "x": 2,
      "y": 11,
      "z": -2,
      "name": "Wood_Sallow_Trunk",
      "support": 15
    },
    {
      "x": 2,
      "y": 12,
      "z": -2,
      "name": "Wood_Sallow_Trunk",
      "support": 15
    },
    {
      "x": 2,
      "y": 13,
      "z": -2,
      "name": "Wood_Sallow_Trunk",
      "support": 15
    },
    {
      "x": 2,
      "y": 14,
      "z": -2,
      "name": "Wood_Sallow_Trunk",
      "support": 15
    },
    {
      "x": 2,
      "y": 15,
      "z": -2,
      "name": "Wood_Sallow_Trunk_Full",
      "support": 15
    },
    {
      "x": 2,
      "y": 6,
      "z": -1,
      "name": "Wood_Sallow_Roots"
    },
    {
      "x": 2,
      "y": 7,
      "z": -1,
      "name": "Wood_Sallow_Trunk_Full",
      "support": 15
    },
    {
      "x": 2,
      "y": 8,
      "z": -1,
      "name": "Wood_Sallow_Trunk",
      "support": 15
    },
    {
      "x": 2,
      "y": 9,
      "z": -1,
      "name": "Wood_Sallow_Trunk",
      "support": 15
    },
    {
      "x": 2,
      "y": 10,
      "z": -1,
      "name": "Wood_Sallow_Trunk",
      "support": 15
    },
    {
      "x": 2,
      "y": 11,
      "z": -1,
      "name": "Wood_Sallow_Trunk",
      "support": 15
    },
    {
      "x": 2,
      "y": 12,
      "z": -1,
      "name": "Wood_Sallow_Trunk",
      "support": 15
    },
    {
      "x": 2,
      "y": 13,
      "z": -1,
      "name": "Wood_Sallow_Trunk",
      "support": 15
    },
    {
      "x": 2,
      "y": 14,
      "z": -1,
      "name": "Wood_Sallow_Trunk_Full",
      "support": 15
    },
    {
      "x": 2,
      "y": 15,
      "z": -1,
      "name": "Plant_Moss_Rug_Green_Dark",
      "support": 15
    },
    {
      "x": 2,
      "y": 7,
      "z": 0,
      "name": "Wood_Sallow_Trunk_Full",
      "support": 15
    },
    {
      "x": 2,
      "y": 8,
      "z": 0,
      "name": "Wood_Sallow_Trunk",
      "support": 15
    },
    {
      "x": 2,
      "y": 9,
      "z": 0,
      "name": "Wood_Sallow_Trunk",
      "support": 15
    },
    {
      "x": 2,
      "y": 10,
      "z": 0,
      "name": "Wood_Sallow_Trunk",
      "support": 15
    },
    {
      "x": 2,
      "y": 11,
      "z": 0,
      "name": "Wood_Sallow_Trunk",
      "support": 15
    },
    {
      "x": 2,
      "y": 12,
      "z": 0,
      "name": "Wood_Sallow_Trunk",
      "support": 15
    },
    {
      "x": 2,
      "y": 13,
      "z": 0,
      "name": "Wood_Sallow_Trunk",
      "support": 15
    },
    {
      "x": 2,
      "y": 14,
      "z": 0,
      "name": "Wood_Sallow_Trunk",
      "support": 15
    },
    {
      "x": 2,
      "y": 15,
      "z": 0,
      "name": "Wood_Sallow_Trunk",
      "support": 15
    },
    {
      "x": 2,
      "y": 16,
      "z": 0,
      "name": "Wood_Sallow_Trunk",
      "support": 15
    },
    {
      "x": 2,
      "y": 6,
      "z": 1,
      "name": "Wood_Sallow_Roots"
    },
    {
      "x": 2,
      "y": 7,
      "z": 1,
      "name": "Wood_Sallow_Trunk_Full",
      "support": 15
    },
    {
      "x": 2,
      "y": 8,
      "z": 1,
      "name": "Wood_Sallow_Trunk",
      "support": 15
    },
    {
      "x": 2,
      "y": 9,
      "z": 1,
      "name": "Wood_Sallow_Trunk",
      "support": 15
    },
    {
      "x": 2,
      "y": 10,
      "z": 1,
      "name": "Wood_Sallow_Trunk",
      "support": 15
    },
    {
      "x": 2,
      "y": 11,
      "z": 1,
      "name": "Wood_Sallow_Trunk",
      "support": 15
    },
    {
      "x": 2,
      "y": 12,
      "z": 1,
      "name": "Wood_Sallow_Trunk",
      "support": 15
    },
    {
      "x": 2,
      "y": 13,
      "z": 1,
      "name": "Wood_Sallow_Trunk",
      "support": 15
    },
    {
      "x": 2,
      "y": 14,
      "z": 1,
      "name": "Wood_Sallow_Trunk",
      "support": 15
    },
    {
      "x": 2,
      "y": 15,
      "z": 1,
      "name": "Wood_Sallow_Trunk",
      "support": 15
    },
    {
      "x": 2,
      "y": 16,
      "z": 1,
      "name": "Wood_Sallow_Trunk",
      "support": 15
    },
    {
      "x": 2,
      "y": 6,
      "z": 2,
      "name": "Wood_Sallow_Roots"
    },
    {
      "x": 2,
      "y": 7,
      "z": 2,
      "name": "Wood_Sallow_Trunk_Full",
      "support": 15,
      "rotation": 5
    },
    {
      "x": 2,
      "y": 8,
      "z": 2,
      "name": "Wood_Sallow_Trunk",
      "support": 15
    },
    {
      "x": 2,
      "y": 9,
      "z": 2,
      "name": "Wood_Sallow_Trunk",
      "support": 15
    },
    {
      "x": 2,
      "y": 10,
      "z": 2,
      "name": "Wood_Sallow_Trunk",
      "support": 15
    },
    {
      "x": 2,
      "y": 11,
      "z": 2,
      "name": "Wood_Sallow_Trunk",
      "support": 15
    },
    {
      "x": 2,
      "y": 12,
      "z": 2,
      "name": "Wood_Sallow_Trunk",
      "support": 15
    },
    {
      "x": 2,
      "y": 13,
      "z": 2,
      "name": "Wood_Sallow_Trunk",
      "support": 15
    },
    {
      "x": 2,
      "y": 14,
      "z": 2,
      "name": "Wood_Sallow_Trunk",
      "support": 15
    },
    {
      "x": 2,
      "y": 15,
      "z": 2,
      "name": "Wood_Sallow_Trunk_Full",
      "support": 15
    },
    {
      "x": 2,
      "y": 16,
      "z": 2,
      "name": "Plant_Moss_Rug_Green_Dark",
      "support": 15
    },
    {
      "x": 2,
      "y": 7,
      "z": 3,
      "name": "Wood_Sallow_Trunk_Full",
      "support": 15
    },
    {
      "x": 2,
      "y": 8,
      "z": 3,
      "name": "Wood_Sallow_Trunk",
      "support": 15
    },
    {
      "x": 2,
      "y": 9,
      "z": 3,
      "name": "Wood_Sallow_Trunk",
      "support": 15
    },
    {
      "x": 2,
      "y": 10,
      "z": 3,
      "name": "Wood_Sallow_Trunk",
      "support": 15
    },
    {
      "x": 2,
      "y": 11,
      "z": 3,
      "name": "Wood_Sallow_Trunk",
      "support": 15
    },
    {
      "x": 2,
      "y": 12,
      "z": 3,
      "name": "Wood_Sallow_Trunk",
      "support": 15
    },
    {
      "x": 2,
      "y": 13,
      "z": 3,
      "name": "Wood_Sallow_Trunk_Full",
      "support": 15
    },
    {
      "x": 2,
      "y": 15,
      "z": 3,
      "name": "Plant_Moss_Wall_Green_Dark",
      "support": 15
    },
    {
      "x": 2,
      "y": 9,
      "z": 7,
      "name": "Plant_Moss_Wall_Green_Dark",
      "support": 15,
      "rotation": 1
    },
    {
      "x": 2,
      "y": 8,
      "z": 8,
      "name": "Plant_Moss_Wall_Green_Dark",
      "support": 15,
      "rotation": 1
    },
    {
      "x": 3,
      "y": 5,
      "z": -4,
      "name": "Wood_Sallow_Roots"
    },
    {
      "x": 3,
      "y": 6,
      "z": -4,
      "name": "Wood_Sallow_Trunk_Full",
      "support": 15
    },
    {
      "x": 3,
      "y": 7,
      "z": -4,
      "name": "Wood_Sallow_Trunk",
      "support": 15
    },
    {
      "x": 3,
      "y": 8,
      "z": -4,
      "name": "Wood_Sallow_Trunk",
      "support": 15
    },
    {
      "x": 3,
      "y": 9,
      "z": -4,
      "name": "Wood_Sallow_Trunk",
      "support": 15
    },
    {
      "x": 3,
      "y": 10,
      "z": -4,
      "name": "Wood_Sallow_Trunk_Full",
      "support": 15
    },
    {
      "x": 3,
      "y": 11,
      "z": -4,
      "name": "Plant_Moss_Rug_Green_Dark",
      "support": 15
    },
    {
      "x": 3,
      "y": 5,
      "z": -3,
      "name": "Wood_Sallow_Roots"
    },
    {
      "x": 3,
      "y": 6,
      "z": -3,
      "name": "Wood_Sallow_Trunk_Full",
      "support": 15
    },
    {
      "x": 3,
      "y": 7,
      "z": -3,
      "name": "Wood_Sallow_Trunk",
      "support": 15
    },
    {
      "x": 3,
      "y": 8,
      "z": -3,
      "name": "Wood_Sallow_Trunk",
      "support": 15
    },
    {
      "x": 3,
      "y": 9,
      "z": -3,
      "name": "Wood_Sallow_Trunk",
      "support": 15
    },
    {
      "x": 3,
      "y": 10,
      "z": -3,
      "name": "Wood_Sallow_Trunk",
      "support": 15
    },
    {
      "x": 3,
      "y": 11,
      "z": -3,
      "name": "Wood_Sallow_Trunk",
      "support": 15
    },
    {
      "x": 3,
      "y": 12,
      "z": -3,
      "name": "Wood_Sallow_Trunk_Full",
      "support": 15
    },
    {
      "x": 3,
      "y": 7,
      "z": -2,
      "name": "Wood_Sallow_Trunk_Full",
      "support": 15
    },
    {
      "x": 3,
      "y": 8,
      "z": -2,
      "name": "Wood_Sallow_Trunk",
      "support": 15
    },
    {
      "x": 3,
      "y": 9,
      "z": -2,
      "name": "Wood_Sallow_Trunk",
      "support": 15
    },
    {
      "x": 3,
      "y": 10,
      "z": -2,
      "name": "Wood_Sallow_Trunk",
      "support": 15
    },
    {
      "x": 3,
      "y": 11,
      "z": -2,
      "name": "Wood_Sallow_Trunk",
      "support": 15
    },
    {
      "x": 3,
      "y": 12,
      "z": -2,
      "name": "Wood_Sallow_Trunk",
      "support": 15
    },
    {
      "x": 3,
      "y": 13,
      "z": -2,
      "name": "Wood_Sallow_Trunk_Full",
      "support": 15
    },
    {
      "x": 3,
      "y": 14,
      "z": -2,
      "name": "Plant_Moss_Rug_Green_Dark",
      "support": 15
    },
    {
      "x": 3,
      "y": 14,
      "z": -1,
      "name": "Plant_Moss_Wall_Green_Dark",
      "support": 15,
      "rotation": 1
    },
    {
      "x": 3,
      "y": 6,
      "z": 0,
      "name": "Wood_Sallow_Roots"
    },
    {
      "x": 3,
      "y": 7,
      "z": 0,
      "name": "Wood_Sallow_Trunk_Full",
      "support": 15
    },
    {
      "x": 3,
      "y": 8,
      "z": 0,
      "name": "Wood_Sallow_Trunk",
      "support": 15
    },
    {
      "x": 3,
      "y": 9,
      "z": 0,
      "name": "Wood_Sallow_Trunk",
      "support": 15
    },
    {
      "x": 3,
      "y": 10,
      "z": 0,
      "name": "Wood_Sallow_Trunk",
      "support": 15
    },
    {
      "x": 3,
      "y": 11,
      "z": 0,
      "name": "Wood_Sallow_Trunk",
      "support": 15
    },
    {
      "x": 3,
      "y": 12,
      "z": 0,
      "name": "Wood_Sallow_Trunk_Full",
      "support": 15
    },
    {
      "x": 3,
      "y": 13,
      "z": 0,
      "name": "Plant_Moss_Rug_Green_Dark",
      "support": 15
    },
    {
      "x": 3,
      "y": 7,
      "z": 2,
      "name": "Wood_Sallow_Trunk_Full",
      "support": 15
    },
    {
      "x": 3,
      "y": 8,
      "z": 2,
      "name": "Wood_Sallow_Trunk",
      "support": 15
    },
    {
      "x": 3,
      "y": 9,
      "z": 2,
      "name": "Wood_Sallow_Trunk",
      "support": 15
    },
    {
      "x": 3,
      "y": 10,
      "z": 2,
      "name": "Wood_Sallow_Trunk",
      "support": 15
    },
    {
      "x": 3,
      "y": 11,
      "z": 2,
      "name": "Wood_Sallow_Trunk",
      "support": 15
    },
    {
      "x": 3,
      "y": 12,
      "z": 2,
      "name": "Wood_Sallow_Trunk",
      "support": 15
    },
    {
      "x": 3,
      "y": 13,
      "z": 2,
      "name": "Wood_Sallow_Trunk",
      "support": 15
    },
    {
      "x": 3,
      "y": 14,
      "z": 2,
      "name": "Wood_Sallow_Trunk_Full",
      "support": 15
    },
    {
      "x": 3,
      "y": 15,
      "z": 2,
      "name": "Plant_Moss_Wall_Green_Dark",
      "support": 15,
      "rotation": 1
    },
    {
      "x": 3,
      "y": 6,
      "z": 3,
      "name": "Wood_Sallow_Roots"
    },
    {
      "x": 3,
      "y": 7,
      "z": 3,
      "name": "Wood_Sallow_Trunk_Full",
      "support": 15
    },
    {
      "x": 3,
      "y": 8,
      "z": 3,
      "name": "Wood_Sallow_Trunk",
      "support": 15
    },
    {
      "x": 3,
      "y": 9,
      "z": 3,
      "name": "Wood_Sallow_Trunk",
      "support": 15
    },
    {
      "x": 3,
      "y": 10,
      "z": 3,
      "name": "Wood_Sallow_Trunk",
      "support": 15
    },
    {
      "x": 3,
      "y": 11,
      "z": 3,
      "name": "Wood_Sallow_Trunk",
      "support": 15
    },
    {
      "x": 3,
      "y": 12,
      "z": 3,
      "name": "Wood_Sallow_Trunk_Full",
      "support": 15
    },
    {
      "x": 3,
      "y": 6,
      "z": 4,
      "name": "Wood_Sallow_Roots"
    },
    {
      "x": 3,
      "y": 7,
      "z": 4,
      "name": "Wood_Sallow_Trunk_Full",
      "support": 15
    },
    {
      "x": 3,
      "y": 8,
      "z": 4,
      "name": "Wood_Sallow_Trunk",
      "support": 15
    },
    {
      "x": 3,
      "y": 9,
      "z": 4,
      "name": "Wood_Sallow_Trunk",
      "support": 15
    },
    {
      "x": 3,
      "y": 10,
      "z": 4,
      "name": "Wood_Sallow_Trunk",
      "support": 15
    },
    {
      "x": 3,
      "y": 11,
      "z": 4,
      "name": "Wood_Sallow_Trunk_Full",
      "support": 15
    },
    {
      "x": 3,
      "y": 12,
      "z": 4,
      "name": "Plant_Moss_Rug_Green_Dark",
      "support": 15
    },
    {
      "x": 3,
      "y": 5,
      "z": 5,
      "name": "Wood_Sallow_Roots"
    },
    {
      "x": 3,
      "y": 6,
      "z": 5,
      "name": "Wood_Sallow_Trunk_Full",
      "support": 15
    },
    {
      "x": 3,
      "y": 7,
      "z": 5,
      "name": "Wood_Sallow_Trunk",
      "support": 15
    },
    {
      "x": 3,
      "y": 8,
      "z": 5,
      "name": "Wood_Sallow_Trunk",
      "support": 15
    },
    {
      "x": 3,
      "y": 9,
      "z": 5,
      "name": "Wood_Sallow_Trunk",
      "support": 15
    },
    {
      "x": 3,
      "y": 10,
      "z": 5,
      "name": "Wood_Sallow_Trunk_Full",
      "support": 15
    },
    {
      "x": 3,
      "y": 11,
      "z": 5,
      "name": "Plant_Moss_Rug_Green_Dark",
      "support": 15
    },
    {
      "x": 3,
      "y": 10,
      "z": 6,
      "name": "Plant_Moss_Wall_Green_Dark",
      "support": 15
    },
    {
      "x": 4,
      "y": 9,
      "z": -6,
      "name": "Plant_Moss_Wall_Green_Dark",
      "support": 15,
      "rotation": 2
    },
    {
      "x": 4,
      "y": 3,
      "z": -5,
      "name": "Wood_Sallow_Roots"
    },
    {
      "x": 4,
      "y": 4,
      "z": -5,
      "name": "Wood_Sallow_Trunk_Full",
      "support": 15
    },
    {
      "x": 4,
      "y": 5,
      "z": -5,
      "name": "Wood_Sallow_Trunk",
      "support": 15
    },
    {
      "x": 4,
      "y": 6,
      "z": -5,
      "name": "Wood_Sallow_Trunk",
      "support": 15
    },
    {
      "x": 4,
      "y": 7,
      "z": -5,
      "name": "Wood_Sallow_Trunk",
      "support": 15
    },
    {
      "x": 4,
      "y": 8,
      "z": -5,
      "name": "Wood_Sallow_Trunk",
      "support": 15
    },
    {
      "x": 4,
      "y": 9,
      "z": -5,
      "name": "Wood_Sallow_Trunk_Full",
      "support": 15
    },
    {
      "x": 4,
      "y": 10,
      "z": -5,
      "name": "Plant_Moss_Rug_Green_Dark",
      "support": 15
    },
    {
      "x": 4,
      "y": 10,
      "z": -4,
      "name": "Plant_Moss_Wall_Green_Dark",
      "support": 15,
      "rotation": 1
    },
    {
      "x": 4,
      "y": 5,
      "z": 0,
      "name": "Wood_Sallow_Roots"
    },
    {
      "x": 4,
      "y": 6,
      "z": 0,
      "name": "Wood_Sallow_Trunk_Full",
      "support": 15
    },
    {
      "x": 4,
      "y": 7,
      "z": 0,
      "name": "Wood_Sallow_Trunk",
      "support": 15
    },
    {
      "x": 4,
      "y": 8,
      "z": 0,
      "name": "Wood_Sallow_Trunk",
      "support": 15
    },
    {
      "x": 4,
      "y": 9,
      "z": 0,
      "name": "Wood_Sallow_Trunk",
      "support": 15
    },
    {
      "x": 4,
      "y": 10,
      "z": 0,
      "name": "Wood_Sallow_Trunk",
      "support": 15
    },
    {
      "x": 4,
      "y": 11,
      "z": 0,
      "name": "Wood_Sallow_Trunk_Full",
      "support": 15
    },
    {
      "x": 4,
      "y": 5,
      "z": 3,
      "name": "Wood_Sallow_Roots"
    },
    {
      "x": 4,
      "y": 6,
      "z": 3,
      "name": "Wood_Sallow_Trunk_Full",
      "support": 15
    },
    {
      "x": 4,
      "y": 7,
      "z": 3,
      "name": "Wood_Sallow_Trunk",
      "support": 15
    },
    {
      "x": 4,
      "y": 8,
      "z": 3,
      "name": "Wood_Sallow_Trunk",
      "support": 15
    },
    {
      "x": 4,
      "y": 9,
      "z": 3,
      "name": "Wood_Sallow_Trunk",
      "support": 15
    },
    {
      "x": 4,
      "y": 10,
      "z": 3,
      "name": "Wood_Sallow_Trunk",
      "support": 15
    },
    {
      "x": 4,
      "y": 11,
      "z": 3,
      "name": "Wood_Sallow_Trunk_Full",
      "support": 15
    },
    {
      "x": 4,
      "y": 11,
      "z": 4,
      "name": "Plant_Moss_Wall_Green_Dark",
      "support": 15,
      "rotation": 1
    },
    {
      "x": 4,
      "y": 4,
      "z": 6,
      "name": "Wood_Sallow_Roots"
    },
    {
      "x": 4,
      "y": 5,
      "z": 6,
      "name": "Wood_Sallow_Trunk_Full",
      "support": 15
    },
    {
      "x": 4,
      "y": 6,
      "z": 6,
      "name": "Wood_Sallow_Trunk",
      "support": 15
    },
    {
      "x": 4,
      "y": 7,
      "z": 6,
      "name": "Wood_Sallow_Trunk",
      "support": 15
    },
    {
      "x": 4,
      "y": 8,
      "z": 6,
      "name": "Wood_Sallow_Trunk",
      "support": 15
    },
    {
      "x": 4,
      "y": 9,
      "z": 6,
      "name": "Wood_Sallow_Trunk_Full",
      "support": 15
    },
    {
      "x": 4,
      "y": 8,
      "z": 7,
      "name": "Plant_Moss_Wall_Green_Dark",
      "support": 15,
      "rotation": 3
    },
    {
      "x": 5,
      "y": 10,
      "z": -2,
      "name": "Plant_Moss_Wall_Green_Dark",
      "support": 15,
      "rotation": 2
    },
    {
      "x": 5,
      "y": 5,
      "z": -1,
      "name": "Wood_Sallow_Roots"
    },
    {
      "x": 5,
      "y": 6,
      "z": -1,
      "name": "Wood_Sallow_Trunk_Full",
      "support": 15
    },
    {
      "x": 5,
      "y": 7,
      "z": -1,
      "name": "Wood_Sallow_Trunk",
      "support": 15
    },
    {
      "x": 5,
      "y": 8,
      "z": -1,
      "name": "Wood_Sallow_Trunk",
      "support": 15
    },
    {
      "x": 5,
      "y": 9,
      "z": -1,
      "name": "Wood_Sallow_Trunk",
      "support": 15
    },
    {
      "x": 5,
      "y": 10,
      "z": -1,
      "name": "Wood_Sallow_Trunk_Full",
      "support": 15
    },
    {
      "x": 5,
      "y": 11,
      "z": -1,
      "name": "Plant_Moss_Rug_Green_Dark",
      "support": 15
    },
    {
      "x": 5,
      "y": 5,
      "z": 3,
      "name": "Wood_Sallow_Roots"
    },
    {
      "x": 5,
      "y": 6,
      "z": 3,
      "name": "Wood_Sallow_Trunk_Full",
      "support": 15
    },
    {
      "x": 5,
      "y": 7,
      "z": 3,
      "name": "Wood_Sallow_Trunk",
      "support": 15
    },
    {
      "x": 5,
      "y": 8,
      "z": 3,
      "name": "Wood_Sallow_Trunk",
      "support": 15
    },
    {
      "x": 5,
      "y": 9,
      "z": 3,
      "name": "Wood_Sallow_Trunk",
      "support": 15
    },
    {
      "x": 5,
      "y": 10,
      "z": 3,
      "name": "Wood_Sallow_Trunk_Full",
      "support": 15
    },
    {
      "x": 5,
      "y": 3,
      "z": 7,
      "name": "Wood_Sallow_Roots"
    },
    {
      "x": 5,
      "y": 4,
      "z": 7,
      "name": "Wood_Sallow_Trunk_Full",
      "support": 15
    },
    {
      "x": 5,
      "y": 5,
      "z": 7,
      "name": "Wood_Sallow_Trunk",
      "support": 15
    },
    {
      "x": 5,
      "y": 6,
      "z": 7,
      "name": "Wood_Sallow_Trunk",
      "support": 15
    },
    {
      "x": 5,
      "y": 7,
      "z": 7,
      "name": "Wood_Sallow_Trunk",
      "support": 15
    },
    {
      "x": 5,
      "y": 8,
      "z": 7,
      "name": "Wood_Sallow_Trunk_Full",
      "support": 15
    },
    {
      "x": 5,
      "y": 9,
      "z": 7,
      "name": "Plant_Moss_Rug_Green_Dark",
      "support": 15
    },
    {
      "x": 6,
      "y": 9,
      "z": -2,
      "name": "Plant_Moss_Wall_Green_Dark",
      "support": 15,
      "rotation": 2
    },
    {
      "x": 6,
      "y": 4,
      "z": -1,
      "name": "Wood_Sallow_Roots"
    },
    {
      "x": 6,
      "y": 5,
      "z": -1,
      "name": "Wood_Sallow_Trunk_Full",
      "support": 15
    },
    {
      "x": 6,
      "y": 6,
      "z": -1,
      "name": "Wood_Sallow_Trunk",
      "support": 15
    },
    {
      "x": 6,
      "y": 7,
      "z": -1,
      "name": "Wood_Sallow_Trunk",
      "support": 15
    },
    {
      "x": 6,
      "y": 8,
      "z": -1,
      "name": "Wood_Sallow_Trunk",
      "support": 15
    },
    {
      "x": 6,
      "y": 9,
      "z": -1,
      "name": "Wood_Sallow_Trunk_Full",
      "support": 15
    },
    {
      "x": 6,
      "y": 10,
      "z": -1,
      "name": "Plant_Moss_Rug_Green_Dark",
      "support": 15
    },
    {
      "x": 6,
      "y": 9,
      "z": 0,
      "name": "Plant_Moss_Wall_Green_Dark",
      "support": 15
    },
    {
      "x": 6,
      "y": 4,
      "z": 2,
      "name": "Wood_Sallow_Roots"
    },
    {
      "x": 6,
      "y": 5,
      "z": 2,
      "name": "Wood_Sallow_Trunk_Full",
      "support": 15
    },
    {
      "x": 6,
      "y": 6,
      "z": 2,
      "name": "Wood_Sallow_Trunk",
      "support": 15
    },
    {
      "x": 6,
      "y": 7,
      "z": 2,
      "name": "Wood_Sallow_Trunk",
      "support": 15
    },
    {
      "x": 6,
      "y": 8,
      "z": 2,
      "name": "Wood_Sallow_Trunk",
      "support": 15
    },
    {
      "x": 6,
      "y": 9,
      "z": 2,
      "name": "Wood_Sallow_Trunk_Full",
      "support": 15
    },
    {
      "x": 6,
      "y": 10,
      "z": 2,
      "name": "Plant_Moss_Rug_Green_Dark",
      "support": 15
    },
    {
      "x": 7,
      "y": 2,
      "z": -1,
      "name": "Wood_Sallow_Roots"
    },
    {
      "x": 7,
      "y": 3,
      "z": -1,
      "name": "Wood_Sallow_Trunk_Full",
      "support": 15
    },
    {
      "x": 7,
      "y": 4,
      "z": -1,
      "name": "Wood_Sallow_Trunk",
      "support": 15
    },
    {
      "x": 7,
      "y": 5,
      "z": -1,
      "name": "Wood_Sallow_Trunk",
      "support": 15
    },
    {
      "x": 7,
      "y": 6,
      "z": -1,
      "name": "Wood_Sallow_Trunk",
      "support": 15
    },
    {
      "x": 7,
      "y": 7,
      "z": -1,
      "name": "Wood_Sallow_Trunk",
      "support": 15
    },
    {
      "x": 7,
      "y": 8,
      "z": -1,
      "name": "Wood_Sallow_Trunk_Full",
      "support": 15
    },
    {
      "x": 7,
      "y": 9,
      "z": -1,
      "name": "Plant_Moss_Rug_Green_Dark",
      "support": 15
    },
    {
      "x": 7,
      "y": 3,
      "z": 2,
      "name": "Wood_Sallow_Roots"
    },
    {
      "x": 7,
      "y": 4,
      "z": 2,
      "name": "Wood_Sallow_Trunk_Full",
      "support": 15
    },
    {
      "x": 7,
      "y": 5,
      "z": 2,
      "name": "Wood_Sallow_Trunk",
      "support": 15
    },
    {
      "x": 7,
      "y": 6,
      "z": 2,
      "name": "Wood_Sallow_Trunk",
      "support": 15
    },
    {
      "x": 7,
      "y": 7,
      "z": 2,
      "name": "Wood_Sallow_Trunk",
      "support": 15
    },
    {
      "x": 7,
      "y": 8,
      "z": 2,
      "name": "Wood_Sallow_Trunk_Full",
      "support": 15
    },
    {
      "x": 7,
      "y": 9,
      "z": 2,
      "name": "Plant_Moss_Rug_Green_Dark",
      "support": 15
    },
    {
      "x": 8,
      "y": 8,
      "z": -1,
      "name": "Plant_Moss_Wall_Green_Dark",
      "support": 15,
      "rotation": 1
    }
  ],
  "fluids": [
    {
      "x": -7,
      "y": 2,
      "z": 0,
      "name": "Empty",
      "level": 0
    },
    {
      "x": -7,
      "y": 3,
      "z": 0,
      "name": "Empty",
      "level": 0
    },
    {
      "x": -7,
      "y": 4,
      "z": 0,
      "name": "Empty",
      "level": 0
    },
    {
      "x": -7,
      "y": 5,
      "z": 0,
      "name": "Empty",
      "level": 0
    },
    {
      "x": -7,
      "y": 6,
      "z": 0,
      "name": "Empty",
      "level": 0
    },
    {
      "x": -7,
      "y": 7,
      "z": 0,
      "name": "Empty",
      "level": 0
    },
    {
      "x": -7,
      "y": 8,
      "z": 0,
      "name": "Empty",
      "level": 0
    },
    {
      "x": -6,
      "y": 2,
      "z": -6,
      "name": "Empty",
      "level": 0
    },
    {
      "x": -6,
      "y": 3,
      "z": -6,
      "name": "Empty",
      "level": 0
    },
    {
      "x": -6,
      "y": 4,
      "z": -6,
      "name": "Empty",
      "level": 0
    },
    {
      "x": -6,
      "y": 5,
      "z": -6,
      "name": "Empty",
      "level": 0
    },
    {
      "x": -6,
      "y": 6,
      "z": -6,
      "name": "Empty",
      "level": 0
    },
    {
      "x": -6,
      "y": 7,
      "z": -6,
      "name": "Empty",
      "level": 0
    },
    {
      "x": -6,
      "y": 8,
      "z": -6,
      "name": "Empty",
      "level": 0
    },
    {
      "x": -6,
      "y": 4,
      "z": -5,
      "name": "Empty",
      "level": 0
    },
    {
      "x": -6,
      "y": 5,
      "z": -5,
      "name": "Empty",
      "level": 0
    },
    {
      "x": -6,
      "y": 6,
      "z": -5,
      "name": "Empty",
      "level": 0
    },
    {
      "x": -6,
      "y": 7,
      "z": -5,
      "name": "Empty",
      "level": 0
    },
    {
      "x": -6,
      "y": 8,
      "z": -5,
      "name": "Empty",
      "level": 0
    },
    {
      "x": -6,
      "y": 9,
      "z": -5,
      "name": "Empty",
      "level": 0
    },
    {
      "x": -6,
      "y": 10,
      "z": -4,
      "name": "Empty",
      "level": 0
    },
    {
      "x": -6,
      "y": 4,
      "z": 0,
      "name": "Empty",
      "level": 0
    },
    {
      "x": -6,
      "y": 5,
      "z": 0,
      "name": "Empty",
      "level": 0
    },
    {
      "x": -6,
      "y": 6,
      "z": 0,
      "name": "Empty",
      "level": 0
    },
    {
      "x": -6,
      "y": 7,
      "z": 0,
      "name": "Empty",
      "level": 0
    },
    {
      "x": -6,
      "y": 8,
      "z": 0,
      "name": "Empty",
      "level": 0
    },
    {
      "x": -6,
      "y": 9,
      "z": 0,
      "name": "Empty",
      "level": 0
    },
    {
      "x": -6,
      "y": 10,
      "z": 1,
      "name": "Empty",
      "level": 0
    },
    {
      "x": -6,
      "y": 1,
      "z": 6,
      "name": "Empty",
      "level": 0
    },
    {
      "x": -6,
      "y": 2,
      "z": 6,
      "name": "Empty",
      "level": 0
    },
    {
      "x": -6,
      "y": 3,
      "z": 6,
      "name": "Empty",
      "level": 0
    },
    {
      "x": -6,
      "y": 4,
      "z": 6,
      "name": "Empty",
      "level": 0
    },
    {
      "x": -6,
      "y": 5,
      "z": 6,
      "name": "Empty",
      "level": 0
    },
    {
      "x": -6,
      "y": 6,
      "z": 6,
      "name": "Empty",
      "level": 0
    },
    {
      "x": -6,
      "y": 7,
      "z": 6,
      "name": "Empty",
      "level": 0
    },
    {
      "x": -6,
      "y": 8,
      "z": 6,
      "name": "Empty",
      "level": 0
    },
    {
      "x": -6,
      "y": 9,
      "z": 6,
      "name": "Empty",
      "level": 0
    },
    {
      "x": -5,
      "y": 4,
      "z": -4,
      "name": "Empty",
      "level": 0
    },
    {
      "x": -5,
      "y": 5,
      "z": -4,
      "name": "Empty",
      "level": 0
    },
    {
      "x": -5,
      "y": 6,
      "z": -4,
      "name": "Empty",
      "level": 0
    },
    {
      "x": -5,
      "y": 7,
      "z": -4,
      "name": "Empty",
      "level": 0
    },
    {
      "x": -5,
      "y": 8,
      "z": -4,
      "name": "Empty",
      "level": 0
    },
    {
      "x": -5,
      "y": 9,
      "z": -4,
      "name": "Empty",
      "level": 0
    },
    {
      "x": -5,
      "y": 10,
      "z": -4,
      "name": "Empty",
      "level": 0
    },
    {
      "x": -5,
      "y": 11,
      "z": -4,
      "name": "Empty",
      "level": 0
    },
    {
      "x": -5,
      "y": 10,
      "z": -3,
      "name": "Empty",
      "level": 0
    },
    {
      "x": -5,
      "y": 5,
      "z": 1,
      "name": "Empty",
      "level": 0
    },
    {
      "x": -5,
      "y": 6,
      "z": 1,
      "name": "Empty",
      "level": 0
    },
    {
      "x": -5,
      "y": 7,
      "z": 1,
      "name": "Empty",
      "level": 0
    },
    {
      "x": -5,
      "y": 8,
      "z": 1,
      "name": "Empty",
      "level": 0
    },
    {
      "x": -5,
      "y": 9,
      "z": 1,
      "name": "Empty",
      "level": 0
    },
    {
      "x": -5,
      "y": 10,
      "z": 1,
      "name": "Empty",
      "level": 0
    },
    {
      "x": -5,
      "y": 11,
      "z": 1,
      "name": "Empty",
      "level": 0
    },
    {
      "x": -5,
      "y": 2,
      "z": 5,
      "name": "Empty",
      "level": 0
    },
    {
      "x": -5,
      "y": 3,
      "z": 5,
      "name": "Empty",
      "level": 0
    },
    {
      "x": -5,
      "y": 4,
      "z": 5,
      "name": "Empty",
      "level": 0
    },
    {
      "x": -5,
      "y": 5,
      "z": 5,
      "name": "Empty",
      "level": 0
    },
    {
      "x": -5,
      "y": 6,
      "z": 5,
      "name": "Empty",
      "level": 0
    },
    {
      "x": -5,
      "y": 7,
      "z": 5,
      "name": "Empty",
      "level": 0
    },
    {
      "x": -5,
      "y": 8,
      "z": 5,
      "name": "Empty",
      "level": 0
    },
    {
      "x": -5,
      "y": 9,
      "z": 5,
      "name": "Empty",
      "level": 0
    },
    {
      "x": -5,
      "y": 10,
      "z": 5,
      "name": "Empty",
      "level": 0
    },
    {
      "x": -4,
      "y": 10,
      "z": -5,
      "name": "Empty",
      "level": 0
    },
    {
      "x": -4,
      "y": 4,
      "z": -4,
      "name": "Empty",
      "level": 0
    },
    {
      "x": -4,
      "y": 5,
      "z": -4,
      "name": "Empty",
      "level": 0
    },
    {
      "x": -4,
      "y": 6,
      "z": -4,
      "name": "Empty",
      "level": 0
    },
    {
      "x": -4,
      "y": 7,
      "z": -4,
      "name": "Empty",
      "level": 0
    },
    {
      "x": -4,
      "y": 8,
      "z": -4,
      "name": "Empty",
      "level": 0
    },
    {
      "x": -4,
      "y": 9,
      "z": -4,
      "name": "Empty",
      "level": 0
    },
    {
      "x": -4,
      "y": 10,
      "z": -4,
      "name": "Empty",
      "level": 0
    },
    {
      "x": -4,
      "y": 11,
      "z": -4,
      "name": "Empty",
      "level": 0
    },
    {
      "x": -4,
      "y": 11,
      "z": 0,
      "name": "Empty",
      "level": 0
    },
    {
      "x": -4,
      "y": 5,
      "z": 1,
      "name": "Empty",
      "level": 0
    },
    {
      "x": -4,
      "y": 6,
      "z": 1,
      "name": "Empty",
      "level": 0
    },
    {
      "x": -4,
      "y": 7,
      "z": 1,
      "name": "Empty",
      "level": 0
    },
    {
      "x": -4,
      "y": 8,
      "z": 1,
      "name": "Empty",
      "level": 0
    },
    {
      "x": -4,
      "y": 9,
      "z": 1,
      "name": "Empty",
      "level": 0
    },
    {
      "x": -4,
      "y": 10,
      "z": 1,
      "name": "Empty",
      "level": 0
    },
    {
      "x": -4,
      "y": 11,
      "z": 1,
      "name": "Empty",
      "level": 0
    },
    {
      "x": -4,
      "y": 12,
      "z": 1,
      "name": "Empty",
      "level": 0
    },
    {
      "x": -4,
      "y": 11,
      "z": 2,
      "name": "Empty",
      "level": 0
    },
    {
      "x": -4,
      "y": 4,
      "z": 3,
      "name": "Empty",
      "level": 0
    },
    {
      "x": -4,
      "y": 5,
      "z": 3,
      "name": "Empty",
      "level": 0
    },
    {
      "x": -4,
      "y": 6,
      "z": 3,
      "name": "Empty",
      "level": 0
    },
    {
      "x": -4,
      "y": 7,
      "z": 3,
      "name": "Empty",
      "level": 0
    },
    {
      "x": -4,
      "y": 8,
      "z": 3,
      "name": "Empty",
      "level": 0
    },
    {
      "x": -4,
      "y": 9,
      "z": 3,
      "name": "Empty",
      "level": 0
    },
    {
      "x": -4,
      "y": 10,
      "z": 3,
      "name": "Empty",
      "level": 0
    },
    {
      "x": -4,
      "y": 3,
      "z": 4,
      "name": "Empty",
      "level": 0
    },
    {
      "x": -4,
      "y": 4,
      "z": 4,
      "name": "Empty",
      "level": 0
    },
    {
      "x": -4,
      "y": 5,
      "z": 4,
      "name": "Empty",
      "level": 0
    },
    {
      "x": -4,
      "y": 6,
      "z": 4,
      "name": "Empty",
      "level": 0
    },
    {
      "x": -4,
      "y": 7,
      "z": 4,
      "name": "Empty",
      "level": 0
    },
    {
      "x": -4,
      "y": 8,
      "z": 4,
      "name": "Empty",
      "level": 0
    },
    {
      "x": -4,
      "y": 9,
      "z": 4,
      "name": "Empty",
      "level": 0
    },
    {
      "x": -4,
      "y": 10,
      "z": 4,
      "name": "Empty",
      "level": 0
    },
    {
      "x": -3,
      "y": 10,
      "z": -4,
      "name": "Empty",
      "level": 0
    },
    {
      "x": -3,
      "y": 5,
      "z": -3,
      "name": "Empty",
      "level": 0
    },
    {
      "x": -3,
      "y": 6,
      "z": -3,
      "name": "Empty",
      "level": 0
    },
    {
      "x": -3,
      "y": 7,
      "z": -3,
      "name": "Empty",
      "level": 0
    },
    {
      "x": -3,
      "y": 8,
      "z": -3,
      "name": "Empty",
      "level": 0
    },
    {
      "x": -3,
      "y": 9,
      "z": -3,
      "name": "Empty",
      "level": 0
    },
    {
      "x": -3,
      "y": 10,
      "z": -3,
      "name": "Empty",
      "level": 0
    },
    {
      "x": -3,
      "y": 11,
      "z": -3,
      "name": "Empty",
      "level": 0
    },
    {
      "x": -3,
      "y": 12,
      "z": -3,
      "name": "Empty",
      "level": 0
    },
    {
      "x": -3,
      "y": 7,
      "z": 0,
      "name": "Empty",
      "level": 0
    },
    {
      "x": -3,
      "y": 8,
      "z": 0,
      "name": "Empty",
      "level": 0
    },
    {
      "x": -3,
      "y": 9,
      "z": 0,
      "name": "Empty",
      "level": 0
    },
    {
      "x": -3,
      "y": 10,
      "z": 0,
      "name": "Empty",
      "level": 0
    },
    {
      "x": -3,
      "y": 11,
      "z": 0,
      "name": "Empty",
      "level": 0
    },
    {
      "x": -3,
      "y": 12,
      "z": 0,
      "name": "Empty",
      "level": 0
    },
    {
      "x": -3,
      "y": 6,
      "z": 1,
      "name": "Empty",
      "level": 0
    },
    {
      "x": -3,
      "y": 7,
      "z": 1,
      "name": "Empty",
      "level": 0
    },
    {
      "x": -3,
      "y": 8,
      "z": 1,
      "name": "Empty",
      "level": 0
    },
    {
      "x": -3,
      "y": 9,
      "z": 1,
      "name": "Empty",
      "level": 0
    },
    {
      "x": -3,
      "y": 10,
      "z": 1,
      "name": "Empty",
      "level": 0
    },
    {
      "x": -3,
      "y": 11,
      "z": 1,
      "name": "Empty",
      "level": 0
    },
    {
      "x": -3,
      "y": 12,
      "z": 1,
      "name": "Empty",
      "level": 0
    },
    {
      "x": -3,
      "y": 13,
      "z": 1,
      "name": "Empty",
      "level": 0
    },
    {
      "x": -3,
      "y": 5,
      "z": 2,
      "name": "Empty",
      "level": 0
    },
    {
      "x": -3,
      "y": 6,
      "z": 2,
      "name": "Empty",
      "level": 0
    },
    {
      "x": -3,
      "y": 7,
      "z": 2,
      "name": "Empty",
      "level": 0
    },
    {
      "x": -3,
      "y": 8,
      "z": 2,
      "name": "Empty",
      "level": 0
    },
    {
      "x": -3,
      "y": 9,
      "z": 2,
      "name": "Empty",
      "level": 0
    },
    {
      "x": -3,
      "y": 10,
      "z": 2,
      "name": "Empty",
      "level": 0
    },
    {
      "x": -3,
      "y": 11,
      "z": 2,
      "name": "Empty",
      "level": 0
    },
    {
      "x": -3,
      "y": 12,
      "z": 2,
      "name": "Empty",
      "level": 0
    },
    {
      "x": -3,
      "y": 5,
      "z": 3,
      "name": "Empty",
      "level": 0
    },
    {
      "x": -3,
      "y": 6,
      "z": 3,
      "name": "Empty",
      "level": 0
    },
    {
      "x": -3,
      "y": 7,
      "z": 3,
      "name": "Empty",
      "level": 0
    },
    {
      "x": -3,
      "y": 8,
      "z": 3,
      "name": "Empty",
      "level": 0
    },
    {
      "x": -3,
      "y": 9,
      "z": 3,
      "name": "Empty",
      "level": 0
    },
    {
      "x": -3,
      "y": 10,
      "z": 3,
      "name": "Empty",
      "level": 0
    },
    {
      "x": -3,
      "y": 11,
      "z": 3,
      "name": "Empty",
      "level": 0
    },
    {
      "x": -3,
      "y": 6,
      "z": 4,
      "name": "Empty",
      "level": 0
    },
    {
      "x": -3,
      "y": 7,
      "z": 4,
      "name": "Empty",
      "level": 0
    },
    {
      "x": -3,
      "y": 8,
      "z": 4,
      "name": "Empty",
      "level": 0
    },
    {
      "x": -3,
      "y": 9,
      "z": 4,
      "name": "Empty",
      "level": 0
    },
    {
      "x": -3,
      "y": 10,
      "z": 4,
      "name": "Empty",
      "level": 0
    },
    {
      "x": -3,
      "y": 11,
      "z": 4,
      "name": "Empty",
      "level": 0
    },
    {
      "x": -3,
      "y": 2,
      "z": 8,
      "name": "Empty",
      "level": 0
    },
    {
      "x": -3,
      "y": 3,
      "z": 8,
      "name": "Empty",
      "level": 0
    },
    {
      "x": -3,
      "y": 4,
      "z": 8,
      "name": "Empty",
      "level": 0
    },
    {
      "x": -3,
      "y": 5,
      "z": 8,
      "name": "Empty",
      "level": 0
    },
    {
      "x": -3,
      "y": 6,
      "z": 8,
      "name": "Empty",
      "level": 0
    },
    {
      "x": -3,
      "y": 7,
      "z": 8,
      "name": "Empty",
      "level": 0
    },
    {
      "x": -3,
      "y": 8,
      "z": 8,
      "name": "Empty",
      "level": 0
    },
    {
      "x": -2,
      "y": 8,
      "z": -9,
      "name": "Empty",
      "level": 0
    },
    {
      "x": -2,
      "y": 2,
      "z": -8,
      "name": "Empty",
      "level": 0
    },
    {
      "x": -2,
      "y": 3,
      "z": -8,
      "name": "Empty",
      "level": 0
    },
    {
      "x": -2,
      "y": 4,
      "z": -8,
      "name": "Empty",
      "level": 0
    },
    {
      "x": -2,
      "y": 5,
      "z": -8,
      "name": "Empty",
      "level": 0
    },
    {
      "x": -2,
      "y": 6,
      "z": -8,
      "name": "Empty",
      "level": 0
    },
    {
      "x": -2,
      "y": 7,
      "z": -8,
      "name": "Empty",
      "level": 0
    },
    {
      "x": -2,
      "y": 8,
      "z": -8,
      "name": "Empty",
      "level": 0
    },
    {
      "x": -2,
      "y": 9,
      "z": -8,
      "name": "Empty",
      "level": 0
    },
    {
      "x": -2,
      "y": 3,
      "z": -7,
      "name": "Empty",
      "level": 0
    },
    {
      "x": -2,
      "y": 4,
      "z": -7,
      "name": "Empty",
      "level": 0
    },
    {
      "x": -2,
      "y": 5,
      "z": -7,
      "name": "Empty",
      "level": 0
    },
    {
      "x": -2,
      "y": 6,
      "z": -7,
      "name": "Empty",
      "level": 0
    },
    {
      "x": -2,
      "y": 7,
      "z": -7,
      "name": "Empty",
      "level": 0
    },
    {
      "x": -2,
      "y": 8,
      "z": -7,
      "name": "Empty",
      "level": 0
    },
    {
      "x": -2,
      "y": 9,
      "z": -7,
      "name": "Empty",
      "level": 0
    },
    {
      "x": -2,
      "y": 10,
      "z": -7,
      "name": "Empty",
      "level": 0
    },
    {
      "x": -2,
      "y": 10,
      "z": -6,
      "name": "Empty",
      "level": 0
    },
    {
      "x": -2,
      "y": 5,
      "z": -3,
      "name": "Empty",
      "level": 0
    },
    {
      "x": -2,
      "y": 6,
      "z": -3,
      "name": "Empty",
      "level": 0
    },
    {
      "x": -2,
      "y": 7,
      "z": -3,
      "name": "Empty",
      "level": 0
    },
    {
      "x": -2,
      "y": 8,
      "z": -3,
      "name": "Empty",
      "level": 0
    },
    {
      "x": -2,
      "y": 9,
      "z": -3,
      "name": "Empty",
      "level": 0
    },
    {
      "x": -2,
      "y": 10,
      "z": -3,
      "name": "Empty",
      "level": 0
    },
    {
      "x": -2,
      "y": 11,
      "z": -3,
      "name": "Empty",
      "level": 0
    },
    {
      "x": -2,
      "y": 12,
      "z": -3,
      "name": "Empty",
      "level": 0
    },
    {
      "x": -2,
      "y": 13,
      "z": -3,
      "name": "Empty",
      "level": 0
    },
    {
      "x": -2,
      "y": 6,
      "z": -2,
      "name": "Empty",
      "level": 0
    },
    {
      "x": -2,
      "y": 7,
      "z": -2,
      "name": "Empty",
      "level": 0
    },
    {
      "x": -2,
      "y": 8,
      "z": -2,
      "name": "Empty",
      "level": 0
    },
    {
      "x": -2,
      "y": 9,
      "z": -2,
      "name": "Empty",
      "level": 0
    },
    {
      "x": -2,
      "y": 10,
      "z": -2,
      "name": "Empty",
      "level": 0
    },
    {
      "x": -2,
      "y": 11,
      "z": -2,
      "name": "Empty",
      "level": 0
    },
    {
      "x": -2,
      "y": 12,
      "z": -2,
      "name": "Empty",
      "level": 0
    },
    {
      "x": -2,
      "y": 6,
      "z": -1,
      "name": "Empty",
      "level": 0
    },
    {
      "x": -2,
      "y": 7,
      "z": -1,
      "name": "Empty",
      "level": 0
    },
    {
      "x": -2,
      "y": 8,
      "z": -1,
      "name": "Empty",
      "level": 0
    },
    {
      "x": -2,
      "y": 9,
      "z": -1,
      "name": "Empty",
      "level": 0
    },
    {
      "x": -2,
      "y": 10,
      "z": -1,
      "name": "Empty",
      "level": 0
    },
    {
      "x": -2,
      "y": 6,
      "z": 0,
      "name": "Empty",
      "level": 0
    },
    {
      "x": -2,
      "y": 7,
      "z": 0,
      "name": "Empty",
      "level": 0
    },
    {
      "x": -2,
      "y": 8,
      "z": 0,
      "name": "Empty",
      "level": 0
    },
    {
      "x": -2,
      "y": 9,
      "z": 0,
      "name": "Empty",
      "level": 0
    },
    {
      "x": -2,
      "y": 10,
      "z": 0,
      "name": "Empty",
      "level": 0
    },
    {
      "x": -2,
      "y": 11,
      "z": 0,
      "name": "Empty",
      "level": 0
    },
    {
      "x": -2,
      "y": 12,
      "z": 0,
      "name": "Empty",
      "level": 0
    },
    {
      "x": -2,
      "y": 13,
      "z": 0,
      "name": "Empty",
      "level": 0
    },
    {
      "x": -2,
      "y": 7,
      "z": 1,
      "name": "Empty",
      "level": 0
    },
    {
      "x": -2,
      "y": 8,
      "z": 1,
      "name": "Empty",
      "level": 0
    },
    {
      "x": -2,
      "y": 9,
      "z": 1,
      "name": "Empty",
      "level": 0
    },
    {
      "x": -2,
      "y": 10,
      "z": 1,
      "name": "Empty",
      "level": 0
    },
    {
      "x": -2,
      "y": 11,
      "z": 1,
      "name": "Empty",
      "level": 0
    },
    {
      "x": -2,
      "y": 12,
      "z": 1,
      "name": "Empty",
      "level": 0
    },
    {
      "x": -2,
      "y": 13,
      "z": 1,
      "name": "Empty",
      "level": 0
    },
    {
      "x": -2,
      "y": 14,
      "z": 1,
      "name": "Empty",
      "level": 0
    },
    {
      "x": -2,
      "y": 7,
      "z": 2,
      "name": "Empty",
      "level": 0
    },
    {
      "x": -2,
      "y": 8,
      "z": 2,
      "name": "Empty",
      "level": 0
    },
    {
      "x": -2,
      "y": 9,
      "z": 2,
      "name": "Empty",
      "level": 0
    },
    {
      "x": -2,
      "y": 10,
      "z": 2,
      "name": "Empty",
      "level": 0
    },
    {
      "x": -2,
      "y": 11,
      "z": 2,
      "name": "Empty",
      "level": 0
    },
    {
      "x": -2,
      "y": 12,
      "z": 2,
      "name": "Empty",
      "level": 0
    },
    {
      "x": -2,
      "y": 13,
      "z": 2,
      "name": "Empty",
      "level": 0
    },
    {
      "x": -2,
      "y": 14,
      "z": 2,
      "name": "Empty",
      "level": 0
    },
    {
      "x": -2,
      "y": 15,
      "z": 2,
      "name": "Empty",
      "level": 0
    },
    {
      "x": -2,
      "y": 16,
      "z": 2,
      "name": "Empty",
      "level": 0
    },
    {
      "x": -2,
      "y": 6,
      "z": 3,
      "name": "Empty",
      "level": 0
    },
    {
      "x": -2,
      "y": 7,
      "z": 3,
      "name": "Empty",
      "level": 0
    },
    {
      "x": -2,
      "y": 8,
      "z": 3,
      "name": "Empty",
      "level": 0
    },
    {
      "x": -2,
      "y": 9,
      "z": 3,
      "name": "Empty",
      "level": 0
    },
    {
      "x": -2,
      "y": 10,
      "z": 3,
      "name": "Empty",
      "level": 0
    },
    {
      "x": -2,
      "y": 11,
      "z": 3,
      "name": "Empty",
      "level": 0
    },
    {
      "x": -2,
      "y": 12,
      "z": 3,
      "name": "Empty",
      "level": 0
    },
    {
      "x": -2,
      "y": 10,
      "z": 4,
      "name": "Empty",
      "level": 0
    },
    {
      "x": -2,
      "y": 10,
      "z": 6,
      "name": "Empty",
      "level": 0
    },
    {
      "x": -2,
      "y": 3,
      "z": 7,
      "name": "Empty",
      "level": 0
    },
    {
      "x": -2,
      "y": 4,
      "z": 7,
      "name": "Empty",
      "level": 0
    },
    {
      "x": -2,
      "y": 5,
      "z": 7,
      "name": "Empty",
      "level": 0
    },
    {
      "x": -2,
      "y": 6,
      "z": 7,
      "name": "Empty",
      "level": 0
    },
    {
      "x": -2,
      "y": 7,
      "z": 7,
      "name": "Empty",
      "level": 0
    },
    {
      "x": -2,
      "y": 8,
      "z": 7,
      "name": "Empty",
      "level": 0
    },
    {
      "x": -2,
      "y": 9,
      "z": 7,
      "name": "Empty",
      "level": 0
    },
    {
      "x": -2,
      "y": 10,
      "z": 7,
      "name": "Empty",
      "level": 0
    },
    {
      "x": -2,
      "y": 9,
      "z": 8,
      "name": "Empty",
      "level": 0
    },
    {
      "x": -1,
      "y": 8,
      "z": -8,
      "name": "Empty",
      "level": 0
    },
    {
      "x": -1,
      "y": 9,
      "z": -7,
      "name": "Empty",
      "level": 0
    },
    {
      "x": -1,
      "y": 4,
      "z": -6,
      "name": "Empty",
      "level": 0
    },
    {
      "x": -1,
      "y": 5,
      "z": -6,
      "name": "Empty",
      "level": 0
    },
    {
      "x": -1,
      "y": 6,
      "z": -6,
      "name": "Empty",
      "level": 0
    },
    {
      "x": -1,
      "y": 7,
      "z": -6,
      "name": "Empty",
      "level": 0
    },
    {
      "x": -1,
      "y": 8,
      "z": -6,
      "name": "Empty",
      "level": 0
    },
    {
      "x": -1,
      "y": 9,
      "z": -6,
      "name": "Empty",
      "level": 0
    },
    {
      "x": -1,
      "y": 10,
      "z": -6,
      "name": "Empty",
      "level": 0
    },
    {
      "x": -1,
      "y": 11,
      "z": -6,
      "name": "Empty",
      "level": 0
    },
    {
      "x": -1,
      "y": 5,
      "z": -5,
      "name": "Empty",
      "level": 0
    },
    {
      "x": -1,
      "y": 6,
      "z": -5,
      "name": "Empty",
      "level": 0
    },
    {
      "x": -1,
      "y": 7,
      "z": -5,
      "name": "Empty",
      "level": 0
    },
    {
      "x": -1,
      "y": 8,
      "z": -5,
      "name": "Empty",
      "level": 0
    },
    {
      "x": -1,
      "y": 9,
      "z": -5,
      "name": "Empty",
      "level": 0
    },
    {
      "x": -1,
      "y": 10,
      "z": -5,
      "name": "Empty",
      "level": 0
    },
    {
      "x": -1,
      "y": 11,
      "z": -5,
      "name": "Empty",
      "level": 0
    },
    {
      "x": -1,
      "y": 7,
      "z": -3,
      "name": "Empty",
      "level": 0
    },
    {
      "x": -1,
      "y": 8,
      "z": -3,
      "name": "Empty",
      "level": 0
    },
    {
      "x": -1,
      "y": 9,
      "z": -3,
      "name": "Empty",
      "level": 0
    },
    {
      "x": -1,
      "y": 10,
      "z": -3,
      "name": "Empty",
      "level": 0
    },
    {
      "x": -1,
      "y": 11,
      "z": -3,
      "name": "Empty",
      "level": 0
    },
    {
      "x": -1,
