{
  "version": 8,
  "blockIdVersion": 11,
  "anchorX": 0,
  "anchorY": 0,
  "anchorZ": 0,
  "blocks": [
    {
      "x": -22,
      "y": 10,
      "z": -9,
      "name": "Rock_Shale_Brick_Stairs",
      "rotation": 3
    },
    {
      "x": -22,
      "y": 10,
      "z": -8,
      "name": "Rock_Shale_Brick_Stairs",
      "rotation": 3
    },
    {
      "x": -22,
      "y": 10,
      "z": -7,
      "name": "Rock_Shale_Brick_Stairs",
      "rotation": 3
    },
    {
      "x": -22,
      "y": 10,
      "z": -6,
      "name": "Rock_Shale_Brick_Stairs",
      "rotation": 3
    },
    {
      "x": -22,
      "y": 10,
      "z": -5,
      "name": "Rock_Shale_Brick_Stairs",
      "rotation": 3
    },
    {
      "x": -22,
      "y": 10,
      "z": -4,
      "name": "Rock_Shale_Brick_Stairs",
      "rotation": 3
    },
    {
      "x": -22,
      "y": 10,
      "z": -3,
      "name": "Rock_Shale_Brick_Stairs",
      "rotation": 3
    },
    {
      "x": -22,
      "y": 10,
      "z": -2,
      "name": "Rock_Shale_Brick_Stairs",
      "rotation": 3
    },
    {
      "x": -22,
      "y": 10,
      "z": -1,
      "name": "Rock_Shale_Brick_Stairs",
      "rotation": 3
    },
    {
      "x": -22,
      "y": 10,
      "z": 0,
      "name": "Rock_Shale_Brick_Stairs",
      "rotation": 3
    },
    {
      "x": -22,
      "y": 10,
      "z": 1,
      "name": "Rock_Shale_Brick_Stairs",
      "rotation": 3
    },
    {
      "x": -22,
      "y": 10,
      "z": 2,
      "name": "Rock_Shale_Brick_Stairs",
      "rotation": 3
    },
    {
      "x": -22,
      "y": 10,
      "z": 3,
      "name": "Rock_Shale_Brick_Stairs",
      "rotation": 3
    },
    {
      "x": -22,
      "y": 10,
      "z": 4,
      "name": "Rock_Shale_Brick_Stairs",
      "rotation": 3
    },
    {
      "x": -22,
      "y": 10,
      "z": 5,
      "name": "Rock_Shale_Brick_Stairs",
      "rotation": 3
    },
    {
      "x": -22,
      "y": 10,
      "z": 6,
      "name": "Rock_Shale_Brick_Stairs",
      "rotation": 3
    },
    {
      "x": -22,
      "y": 10,
      "z": 7,
      "name": "Rock_Shale_Brick_Stairs",
      "rotation": 3
    },
    {
      "x": -22,
      "y": 10,
      "z": 8,
      "name": "Rock_Shale_Brick_Stairs",
      "rotation": 3
    },
    {
      "x": -22,
      "y": 10,
      "z": 9,
      "name": "Rock_Shale_Brick_Stairs",
      "rotation": 3
    },
    {
      "x": -21,
      "y": 10,
      "z": -21,
      "name": "Rock_Shale_Cobble"
    },
    {
      "x": -21,
      "y": 11,
      "z": -21,
      "name": "*Rock_Shale_Cobble_Stairs_State_Definitions_Corner_Left",
      "rotation": 2
    },
    {
      "x": -21,
      "y": 10,
      "z": -20,
      "name": "Rock_Shale_Cobble"
    },
    {
      "x": -21,
      "y": 11,
      "z": -20,
      "name": "Rock_Shale_Cobble_Stairs",
      "rotation": 3
    },
    {
      "x": -21,
      "y": 10,
      "z": -19,
      "name": "Rock_Shale_Cobble"
    },
    {
      "x": -21,
      "y": 11,
      "z": -19,
      "name": "Rock_Shale_Cobble_Stairs",
      "rotation": 3
    },
    {
      "x": -21,
      "y": 10,
      "z": -18,
      "name": "Rock_Shale_Cobble"
    },
    {
      "x": -21,
      "y": 11,
      "z": -18,
      "name": "Rock_Shale_Cobble_Stairs",
      "rotation": 3
    },
    {
      "x": -21,
      "y": 10,
      "z": -17,
      "name": "Rock_Shale_Cobble"
    },
    {
      "x": -21,
      "y": 11,
      "z": -17,
      "name": "Rock_Shale_Cobble_Stairs",
      "rotation": 3
    },
    {
      "x": -21,
      "y": 10,
      "z": -16,
      "name": "Rock_Shale_Cobble"
    },
    {
      "x": -21,
      "y": 11,
      "z": -16,
      "name": "Rock_Shale_Cobble_Stairs",
      "rotation": 3
    },
    {
      "x": -21,
      "y": 10,
      "z": -15,
      "name": "Rock_Shale_Cobble"
    },
    {
      "x": -21,
      "y": 11,
      "z": -15,
      "name": "Rock_Shale_Cobble_Stairs",
      "rotation": 3
    },
    {
      "x": -21,
      "y": 10,
      "z": -14,
      "name": "Rock_Shale_Cobble"
    },
    {
      "x": -21,
      "y": 11,
      "z": -14,
      "name": "Rock_Shale_Cobble_Stairs",
      "rotation": 3
    },
    {
      "x": -21,
      "y": 10,
      "z": -13,
      "name": "Rock_Shale_Cobble"
    },
    {
      "x": -21,
      "y": 11,
      "z": -13,
      "name": "Rock_Shale_Cobble_Stairs",
      "rotation": 3
    },
    {
      "x": -21,
      "y": 10,
      "z": -12,
      "name": "Rock_Shale_Cobble"
    },
    {
      "x": -21,
      "y": 11,
      "z": -12,
      "name": "Rock_Shale_Cobble_Stairs",
      "rotation": 3
    },
    {
      "x": -21,
      "y": 10,
      "z": -11,
      "name": "Rock_Shale_Cobble"
    },
    {
      "x": -21,
      "y": 11,
      "z": -11,
      "name": "Rock_Shale_Cobble_Stairs",
      "rotation": 3
    },
    {
      "x": -21,
      "y": 10,
      "z": -10,
      "name": "Rock_Shale_Cobble"
    },
    {
      "x": -21,
      "y": 11,
      "z": -10,
      "name": "Rock_Shale_Cobble_Stairs",
      "rotation": 3
    },
    {
      "x": -21,
      "y": 10,
      "z": -9,
      "name": "Rock_Shale_Cobble"
    },
    {
      "x": -21,
      "y": 11,
      "z": -9,
      "name": "Rock_Shale_Cobble_Stairs",
      "rotation": 3
    },
    {
      "x": -21,
      "y": 10,
      "z": -8,
      "name": "Rock_Shale_Cobble"
    },
    {
      "x": -21,
      "y": 11,
      "z": -8,
      "name": "Rock_Shale_Cobble_Stairs",
      "rotation": 3
    },
    {
      "x": -21,
      "y": 10,
      "z": -7,
      "name": "Rock_Shale_Cobble"
    },
    {
      "x": -21,
      "y": 11,
      "z": -7,
      "name": "Rock_Shale_Cobble_Stairs",
      "rotation": 3
    },
    {
      "x": -21,
      "y": 10,
      "z": -6,
      "name": "Rock_Shale_Cobble"
    },
    {
      "x": -21,
      "y": 11,
      "z": -6,
      "name": "Rock_Shale_Cobble_Stairs",
      "rotation": 3
    },
    {
      "x": -21,
      "y": 10,
      "z": -5,
      "name": "Rock_Shale_Cobble"
    },
    {
      "x": -21,
      "y": 11,
      "z": -5,
      "name": "Rock_Shale_Cobble_Stairs",
      "rotation": 3
    },
    {
      "x": -21,
      "y": 4,
      "z": -4,
      "name": "Rock_Shale_Cobble"
    },
    {
      "x": -21,
      "y": 5,
      "z": -4,
      "name": "Rock_Shale_Brick",
      "rotation": 1
    },
    {
      "x": -21,
      "y": 6,
      "z": -4,
      "name": "Rock_Shale_Brick",
      "rotation": 1
    },
    {
      "x": -21,
      "y": 7,
      "z": -4,
      "name": "Rock_Shale_Brick",
      "rotation": 1
    },
    {
      "x": -21,
      "y": 8,
      "z": -4,
      "name": "Rock_Shale_Brick",
      "rotation": 1
    },
    {
      "x": -21,
      "y": 9,
      "z": -4,
      "name": "Rock_Shale_Brick_Ornate",
      "rotation": 3
    },
    {
      "x": -21,
      "y": 10,
      "z": -4,
      "name": "Rock_Shale_Cobble"
    },
    {
      "x": -21,
      "y": 11,
      "z": -4,
      "name": "Rock_Shale_Cobble_Stairs",
      "rotation": 3
    },
    {
      "x": -21,
      "y": 4,
      "z": -3,
      "name": "Rock_Shale_Brick_Smooth"
    },
    {
      "x": -21,
      "y": 5,
      "z": -3,
      "name": "Rock_Shale_Brick_Smooth"
    },
    {
      "x": -21,
      "y": 6,
      "z": -3,
      "name": "Rock_Shale_Brick_Smooth"
    },
    {
      "x": -21,
      "y": 7,
      "z": -3,
      "name": "Rock_Shale_Brick_Smooth"
    },
    {
      "x": -21,
      "y": 8,
      "z": -3,
      "name": "Rock_Shale_Brick_Smooth"
    },
    {
      "x": -21,
      "y": 9,
      "z": -3,
      "name": "Rock_Shale_Brick_Ornate"
    },
    {
      "x": -21,
      "y": 10,
      "z": -3,
      "name": "Rock_Shale_Cobble"
    },
    {
      "x": -21,
      "y": 11,
      "z": -3,
      "name": "Rock_Shale_Cobble_Stairs",
      "rotation": 3
    },
    {
      "x": -21,
      "y": 4,
      "z": -2,
      "name": "Rock_Shale_Cobble"
    },
    {
      "x": -21,
      "y": 5,
      "z": -2,
      "name": "Rock_Shale_Brick",
      "rotation": 1
    },
    {
      "x": -21,
      "y": 6,
      "z": -2,
      "name": "Rock_Shale_Brick",
      "rotation": 1
    },
    {
      "x": -21,
      "y": 7,
      "z": -2,
      "name": "Rock_Shale_Brick",
      "rotation": 1
    },
    {
      "x": -21,
      "y": 8,
      "z": -2,
      "name": "Rock_Shale_Brick",
      "rotation": 1
    },
    {
      "x": -21,
      "y": 9,
      "z": -2,
      "name": "Rock_Shale_Brick_Ornate",
      "rotation": 3
    },
    {
      "x": -21,
      "y": 10,
      "z": -2,
      "name": "Rock_Shale_Cobble"
    },
    {
      "x": -21,
      "y": 11,
      "z": -2,
      "name": "Rock_Shale_Cobble_Stairs",
      "rotation": 3
    },
    {
      "x": -21,
      "y": 4,
      "z": -1,
      "name": "Rock_Shale_Cobble"
    },
    {
      "x": -21,
      "y": 5,
      "z": -1,
      "name": "Rock_Shale_Brick_Smooth"
    },
    {
      "x": -21,
      "y": 6,
      "z": -1,
      "name": "Rock_Shale_Brick_Smooth"
    },
    {
      "x": -21,
      "y": 7,
      "z": -1,
      "name": "Rock_Shale_Brick_Smooth"
    },
    {
      "x": -21,
      "y": 8,
      "z": -1,
      "name": "Rock_Shale_Brick_Smooth"
    },
    {
      "x": -21,
      "y": 9,
      "z": -1,
      "name": "Rock_Shale_Brick_Ornate"
    },
    {
      "x": -21,
      "y": 10,
      "z": -1,
      "name": "Rock_Shale_Cobble"
    },
    {
      "x": -21,
      "y": 11,
      "z": -1,
      "name": "Rock_Shale_Cobble_Stairs",
      "rotation": 3
    },
    {
      "x": -21,
      "y": 4,
      "z": 0,
      "name": "Rock_Shale_Cobble",
      "rotation": 1
    },
    {
      "x": -21,
      "y": 5,
      "z": 0,
      "name": "Rock_Shale_Brick",
      "rotation": 2
    },
    {
      "x": -21,
      "y": 6,
      "z": 0,
      "name": "Rock_Shale_Brick",
      "rotation": 2
    },
    {
      "x": -21,
      "y": 7,
      "z": 0,
      "name": "Rock_Shale_Brick",
      "rotation": 2
    },
    {
      "x": -21,
      "y": 8,
      "z": 0,
      "name": "Rock_Shale_Brick",
      "rotation": 2
    },
    {
      "x": -21,
      "y": 9,
      "z": 0,
      "name": "Rock_Shale_Brick_Ornate"
    },
    {
      "x": -21,
      "y": 10,
      "z": 0,
      "name": "Rock_Shale_Cobble"
    },
    {
      "x": -21,
      "y": 11,
      "z": 0,
      "name": "Rock_Shale_Cobble_Stairs",
      "rotation": 3
    },
    {
      "x": -21,
      "y": 4,
      "z": 1,
      "name": "Rock_Shale_Cobble",
      "rotation": 1
    },
    {
      "x": -21,
      "y": 5,
      "z": 1,
      "name": "Rock_Shale_Brick_Smooth",
      "rotation": 1
    },
    {
      "x": -21,
      "y": 6,
      "z": 1,
      "name": "Rock_Shale_Brick_Smooth",
      "rotation": 1
    },
    {
      "x": -21,
      "y": 7,
      "z": 1,
      "name": "Rock_Shale_Brick_Smooth",
      "rotation": 1
    },
    {
      "x": -21,
      "y": 8,
      "z": 1,
      "name": "Rock_Shale_Brick_Smooth",
      "rotation": 1
    },
    {
      "x": -21,
      "y": 9,
      "z": 1,
      "name": "Rock_Shale_Brick_Ornate",
      "rotation": 1
    },
    {
      "x": -21,
      "y": 10,
      "z": 1,
      "name": "Rock_Shale_Cobble"
    },
    {
      "x": -21,
      "y": 11,
      "z": 1,
      "name": "Rock_Shale_Cobble_Stairs",
      "rotation": 3
    },
    {
      "x": -21,
      "y": 4,
      "z": 2,
      "name": "Rock_Shale_Cobble",
      "rotation": 1
    },
    {
      "x": -21,
      "y": 5,
      "z": 2,
      "name": "Rock_Shale_Brick",
      "rotation": 2
    },
    {
      "x": -21,
      "y": 6,
      "z": 2,
      "name": "Rock_Shale_Brick",
      "rotation": 2
    },
    {
      "x": -21,
      "y": 7,
      "z": 2,
      "name": "Rock_Shale_Brick",
      "rotation": 2
    },
    {
      "x": -21,
      "y": 8,
      "z": 2,
      "name": "Rock_Shale_Brick",
      "rotation": 2
    },
    {
      "x": -21,
      "y": 9,
      "z": 2,
      "name": "Rock_Shale_Brick_Ornate"
    },
    {
      "x": -21,
      "y": 10,
      "z": 2,
      "name": "Rock_Shale_Cobble"
    },
    {
      "x": -21,
      "y": 11,
      "z": 2,
      "name": "Rock_Shale_Cobble_Stairs",
      "rotation": 3
    },
    {
      "x": -21,
      "y": 4,
      "z": 3,
      "name": "Rock_Shale_Brick_Smooth",
      "rotation": 1
    },
    {
      "x": -21,
      "y": 5,
      "z": 3,
      "name": "Rock_Shale_Brick_Smooth",
      "rotation": 1
    },
    {
      "x": -21,
      "y": 6,
      "z": 3,
      "name": "Rock_Shale_Brick_Smooth",
      "rotation": 1
    },
    {
      "x": -21,
      "y": 7,
      "z": 3,
      "name": "Rock_Shale_Brick_Smooth",
      "rotation": 1
    },
    {
      "x": -21,
      "y": 8,
      "z": 3,
      "name": "Rock_Shale_Brick_Smooth",
      "rotation": 1
    },
    {
      "x": -21,
      "y": 9,
      "z": 3,
      "name": "Rock_Shale_Brick_Ornate",
      "rotation": 1
    },
    {
      "x": -21,
      "y": 10,
      "z": 3,
      "name": "Rock_Shale_Cobble"
    },
    {
      "x": -21,
      "y": 11,
      "z": 3,
      "name": "Rock_Shale_Cobble_Stairs",
      "rotation": 3
    },
    {
      "x": -21,
      "y": 4,
      "z": 4,
      "name": "Rock_Shale_Cobble",
      "rotation": 1
    },
    {
      "x": -21,
      "y": 5,
      "z": 4,
      "name": "Rock_Shale_Brick",
      "rotation": 2
    },
    {
      "x": -21,
      "y": 6,
      "z": 4,
      "name": "Rock_Shale_Brick",
      "rotation": 2
    },
    {
      "x": -21,
      "y": 7,
      "z": 4,
      "name": "Rock_Shale_Brick",
      "rotation": 2
    },
    {
      "x": -21,
      "y": 8,
      "z": 4,
      "name": "Rock_Shale_Brick",
      "rotation": 2
    },
    {
      "x": -21,
      "y": 9,
      "z": 4,
      "name": "Rock_Shale_Brick_Ornate"
    },
    {
      "x": -21,
      "y": 10,
      "z": 4,
      "name": "Rock_Shale_Cobble"
    },
    {
      "x": -21,
      "y": 11,
      "z": 4,
      "name": "Rock_Shale_Cobble_Stairs",
      "rotation": 3
    },
    {
      "x": -21,
      "y": 10,
      "z": 5,
      "name": "Rock_Shale_Cobble"
    },
    {
      "x": -21,
      "y": 11,
      "z": 5,
      "name": "Rock_Shale_Cobble_Stairs",
      "rotation": 3
    },
    {
      "x": -21,
      "y": 10,
      "z": 6,
      "name": "Rock_Shale_Cobble"
    },
    {
      "x": -21,
      "y": 11,
      "z": 6,
      "name": "Rock_Shale_Cobble_Stairs",
      "rotation": 3
    },
    {
      "x": -21,
      "y": 10,
      "z": 7,
      "name": "Rock_Shale_Cobble"
    },
    {
      "x": -21,
      "y": 11,
      "z": 7,
      "name": "Rock_Shale_Cobble_Stairs",
      "rotation": 3
    },
    {
      "x": -21,
      "y": 10,
      "z": 8,
      "name": "Rock_Shale_Cobble"
    },
    {
      "x": -21,
      "y": 11,
      "z": 8,
      "name": "Rock_Shale_Cobble_Stairs",
      "rotation": 3
    },
    {
      "x": -21,
      "y": 10,
      "z": 9,
      "name": "Rock_Shale_Cobble"
    },
    {
      "x": -21,
      "y": 11,
      "z": 9,
      "name": "Rock_Shale_Cobble_Stairs",
      "rotation": 3
    },
    {
      "x": -21,
      "y": 10,
      "z": 10,
      "name": "Rock_Shale_Cobble"
    },
    {
      "x": -21,
      "y": 11,
      "z": 10,
      "name": "Rock_Shale_Cobble_Stairs",
      "rotation": 3
    },
    {
      "x": -21,
      "y": 10,
      "z": 11,
      "name": "Rock_Shale_Cobble"
    },
    {
      "x": -21,
      "y": 11,
      "z": 11,
      "name": "Rock_Shale_Cobble_Stairs",
      "rotation": 3
    },
    {
      "x": -21,
      "y": 10,
      "z": 12,
      "name": "Rock_Shale_Cobble"
    },
    {
      "x": -21,
      "y": 11,
      "z": 12,
      "name": "Rock_Shale_Cobble_Stairs",
      "rotation": 3
    },
    {
      "x": -21,
      "y": 10,
      "z": 13,
      "name": "Rock_Shale_Cobble"
    },
    {
      "x": -21,
      "y": 11,
      "z": 13,
      "name": "Rock_Shale_Cobble_Stairs",
      "rotation": 3
    },
    {
      "x": -21,
      "y": 10,
      "z": 14,
      "name": "Rock_Shale_Cobble"
    },
    {
      "x": -21,
      "y": 11,
      "z": 14,
      "name": "Rock_Shale_Cobble_Stairs",
      "rotation": 3
    },
    {
      "x": -21,
      "y": 10,
      "z": 15,
      "name": "Rock_Shale_Cobble"
    },
    {
      "x": -21,
      "y": 11,
      "z": 15,
      "name": "Rock_Shale_Cobble_Stairs",
      "rotation": 3
    },
    {
      "x": -21,
      "y": 10,
      "z": 16,
      "name": "Rock_Shale_Cobble"
    },
    {
      "x": -21,
      "y": 11,
      "z": 16,
      "name": "Rock_Shale_Cobble_Stairs",
      "rotation": 3
    },
    {
      "x": -21,
      "y": 10,
      "z": 17,
      "name": "Rock_Shale_Cobble"
    },
    {
      "x": -21,
      "y": 11,
      "z": 17,
      "name": "Rock_Shale_Cobble_Stairs",
      "rotation": 3
    },
    {
      "x": -21,
      "y": 10,
      "z": 18,
      "name": "Rock_Shale_Cobble"
    },
    {
      "x": -21,
      "y": 11,
      "z": 18,
      "name": "Rock_Shale_Cobble_Stairs",
      "rotation": 3
    },
    {
      "x": -21,
      "y": 10,
      "z": 19,
      "name": "Rock_Shale_Cobble"
    },
    {
      "x": -21,
      "y": 11,
      "z": 19,
      "name": "Rock_Shale_Cobble_Stairs",
      "rotation": 3
    },
    {
      "x": -21,
      "y": 10,
      "z": 20,
      "name": "Rock_Shale_Cobble"
    },
    {
      "x": -21,
      "y": 11,
      "z": 20,
      "name": "Rock_Shale_Cobble_Stairs",
      "rotation": 3
    },
    {
      "x": -21,
      "y": 10,
      "z": 21,
      "name": "Rock_Shale_Cobble"
    },
    {
      "x": -21,
      "y": 11,
      "z": 21,
      "name": "*Rock_Shale_Cobble_Stairs_State_Definitions_Corner_Left",
      "rotation": 3
    },
    {
      "x": -20,
      "y": 10,
      "z": -21,
      "name": "Rock_Shale_Cobble"
    },
    {
      "x": -20,
      "y": 11,
      "z": -21,
      "name": "Rock_Shale_Cobble_Stairs",
      "rotation": 2
    },
    {
      "x": -20,
      "y": 10,
      "z": -20,
      "name": "Rock_Shale_Cobble"
    },
    {
      "x": -20,
      "y": 11,
      "z": -20,
      "name": "Rock_Shale_Cobble"
    },
    {
      "x": -20,
      "y": 12,
      "z": -20,
      "name": "*Rock_Shale_Cobble_Stairs_State_Definitions_Corner_Left",
      "rotation": 2
    },
    {
      "x": -20,
      "y": 10,
      "z": -19,
      "name": "Rock_Shale_Cobble"
    },
    {
      "x": -20,
      "y": 11,
      "z": -19,
      "name": "Rock_Shale_Cobble"
    },
    {
      "x": -20,
      "y": 12,
      "z": -19,
      "name": "Rock_Shale_Cobble_Stairs",
      "rotation": 3
    },
    {
      "x": -20,
      "y": 10,
      "z": -18,
      "name": "Rock_Shale_Cobble"
    },
    {
      "x": -20,
      "y": 11,
      "z": -18,
      "name": "Rock_Shale_Cobble"
    },
    {
      "x": -20,
      "y": 12,
      "z": -18,
      "name": "Rock_Shale_Cobble_Stairs",
      "rotation": 3
    },
    {
      "x": -20,
      "y": 10,
      "z": -17,
      "name": "Rock_Shale_Cobble"
    },
    {
      "x": -20,
      "y": 11,
      "z": -17,
      "name": "Rock_Shale_Cobble"
    },
    {
      "x": -20,
      "y": 12,
      "z": -17,
      "name": "Rock_Shale_Cobble_Stairs",
      "rotation": 3
    },
    {
      "x": -20,
      "y": 10,
      "z": -16,
      "name": "Rock_Shale_Cobble"
    },
    {
      "x": -20,
      "y": 11,
      "z": -16,
      "name": "Rock_Shale_Cobble"
    },
    {
      "x": -20,
      "y": 12,
      "z": -16,
      "name": "Rock_Shale_Cobble_Stairs",
      "rotation": 3
    },
    {
      "x": -20,
      "y": 10,
      "z": -15,
      "name": "Rock_Shale_Cobble"
    },
    {
      "x": -20,
      "y": 11,
      "z": -15,
      "name": "Rock_Shale_Cobble"
    },
    {
      "x": -20,
      "y": 12,
      "z": -15,
      "name": "Rock_Shale_Cobble_Stairs",
      "rotation": 3
    },
    {
      "x": -20,
      "y": 10,
      "z": -14,
      "name": "Rock_Shale_Cobble"
    },
    {
      "x": -20,
      "y": 11,
      "z": -14,
      "name": "Rock_Shale_Cobble"
    },
    {
      "x": -20,
      "y": 12,
      "z": -14,
      "name": "Rock_Shale_Cobble_Stairs",
      "rotation": 3
    },
    {
      "x": -20,
      "y": 10,
      "z": -13,
      "name": "Rock_Shale_Cobble"
    },
    {
      "x": -20,
      "y": 11,
      "z": -13,
      "name": "Rock_Shale_Cobble"
    },
    {
      "x": -20,
      "y": 12,
      "z": -13,
      "name": "Rock_Shale_Cobble_Stairs",
      "rotation": 3
    },
    {
      "x": -20,
      "y": 10,
      "z": -12,
      "name": "Rock_Shale_Cobble"
    },
    {
      "x": -20,
      "y": 11,
      "z": -12,
      "name": "Rock_Shale_Cobble"
    },
    {
      "x": -20,
      "y": 12,
      "z": -12,
      "name": "Rock_Shale_Cobble_Stairs",
      "rotation": 3
    },
    {
      "x": -20,
      "y": 10,
      "z": -11,
      "name": "Rock_Shale_Cobble"
    },
    {
      "x": -20,
      "y": 11,
      "z": -11,
      "name": "Rock_Shale_Cobble"
    },
    {
      "x": -20,
      "y": 12,
      "z": -11,
      "name": "Rock_Shale_Cobble_Stairs",
      "rotation": 3
    },
    {
      "x": -20,
      "y": 10,
      "z": -10,
      "name": "Rock_Shale_Cobble"
    },
    {
      "x": -20,
      "y": 11,
      "z": -10,
      "name": "Rock_Shale_Cobble"
    },
    {
      "x": -20,
      "y": 12,
      "z": -10,
      "name": "*Rock_Shale_Cobble_Stairs_State_Definitions_Corner_Left",
      "rotation": 3
    },
    {
      "x": -20,
      "y": 10,
      "z": -9,
      "name": "Rock_Shale_Cobble"
    },
    {
      "x": -20,
      "y": 11,
      "z": -9,
      "name": "Rock_Shale_Cobble"
    },
    {
      "x": -20,
      "y": 10,
      "z": -8,
      "name": "Rock_Shale_Cobble"
    },
    {
      "x": -20,
      "y": 11,
      "z": -8,
      "name": "Rock_Shale_Cobble"
    },
    {
      "x": -20,
      "y": 4,
      "z": -7,
      "name": "Rock_Shale_Cobble"
    },
    {
      "x": -20,
      "y": 5,
      "z": -7,
      "name": "Rock_Shale_Brick_Smooth"
    },
    {
      "x": -20,
      "y": 6,
      "z": -7,
      "name": "Rock_Shale_Brick_Smooth"
    },
    {
      "x": -20,
      "y": 7,
      "z": -7,
      "name": "Rock_Shale_Brick_Smooth"
    },
    {
      "x": -20,
      "y": 8,
      "z": -7,
      "name": "Rock_Shale_Brick_Smooth"
    },
    {
      "x": -20,
      "y": 9,
      "z": -7,
      "name": "Rock_Shale_Brick_Ornate"
    },
    {
      "x": -20,
      "y": 10,
      "z": -7,
      "name": "Rock_Shale_Cobble"
    },
    {
      "x": -20,
      "y": 11,
      "z": -7,
      "name": "Rock_Shale_Cobble"
    },
    {
      "x": -20,
      "y": 4,
      "z": -6,
      "name": "Rock_Shale_Cobble"
    },
    {
      "x": -20,
      "y": 5,
      "z": -6,
      "name": "Rock_Shale_Brick",
      "rotation": 1
    },
    {
      "x": -20,
      "y": 6,
      "z": -6,
      "name": "Rock_Shale_Brick",
      "rotation": 1
    },
    {
      "x": -20,
      "y": 7,
      "z": -6,
      "name": "Rock_Shale_Brick",
      "rotation": 1
    },
    {
      "x": -20,
      "y": 8,
      "z": -6,
      "name": "Rock_Shale_Brick",
      "rotation": 1
    },
    {
      "x": -20,
      "y": 9,
      "z": -6,
      "name": "Rock_Shale_Brick_Ornate",
      "rotation": 3
    },
    {
      "x": -20,
      "y": 10,
      "z": -6,
      "name": "Rock_Shale_Cobble"
    },
    {
      "x": -20,
      "y": 11,
      "z": -6,
      "name": "Rock_Shale_Cobble"
    },
    {
      "x": -20,
      "y": 4,
      "z": -5,
      "name": "Rock_Shale_Cobble"
    },
    {
      "x": -20,
      "y": 5,
      "z": -5,
      "name": "Rock_Shale_Brick_Smooth"
    },
    {
      "x": -20,
      "y": 6,
      "z": -5,
      "name": "Rock_Shale_Brick_Smooth"
    },
    {
      "x": -20,
      "y": 7,
      "z": -5,
      "name": "Rock_Shale_Brick_Smooth"
    },
    {
      "x": -20,
      "y": 8,
      "z": -5,
      "name": "Rock_Shale_Brick_Smooth"
    },
    {
      "x": -20,
      "y": 9,
      "z": -5,
      "name": "Rock_Shale_Brick_Ornate"
    },
    {
      "x": -20,
      "y": 10,
      "z": -5,
      "name": "Rock_Shale_Cobble"
    },
    {
      "x": -20,
      "y": 11,
      "z": -5,
      "name": "Rock_Shale_Cobble"
    },
    {
      "x": -20,
      "y": 4,
      "z": -4,
      "name": "Rock_Shale_Cobble"
    },
    {
      "x": -20,
      "y": 10,
      "z": -4,
      "name": "Rock_Shale_Cobble"
    },
    {
      "x": -20,
      "y": 11,
      "z": -4,
      "name": "Rock_Shale_Cobble"
    },
    {
      "x": -20,
      "y": 4,
      "z": -3,
      "name": "Rock_Shale_Brick_Smooth"
    },
    {
      "x": -20,
      "y": 5,
      "z": -3,
      "name": "Rock_Shale_Brick_Pillar_Base"
    },
    {
      "x": -20,
      "y": 6,
      "z": -3,
      "name": "Rock_Shale_Brick_Pillar_Middle"
    },
    {
      "x": -20,
      "y": 7,
      "z": -3,
      "name": "Rock_Shale_Brick_Pillar_Middle"
    },
    {
      "x": -20,
      "y": 8,
      "z": -3,
      "name": "Rock_Shale_Brick_Pillar_Middle"
    },
    {
      "x": -20,
      "y": 9,
      "z": -3,
      "name": "Rock_Shale_Brick_Pillar_Base",
      "rotation": 8
    },
    {
      "x": -20,
      "y": 10,
      "z": -3,
      "name": "Rock_Shale_Cobble"
    },
    {
      "x": -20,
      "y": 11,
      "z": -3,
      "name": "Rock_Shale_Cobble"
    },
    {
      "x": -20,
      "y": 4,
      "z": -2,
      "name": "Rock_Shale_Cobble"
    },
    {
      "x": -20,
      "y": 10,
      "z": -2,
      "name": "Rock_Shale_Cobble"
    },
    {
      "x": -20,
      "y": 11,
      "z": -2,
      "name": "Rock_Shale_Cobble"
    },
    {
      "x": -20,
      "y": 4,
      "z": -1,
      "name": "Rock_Shale_Cobble"
    },
    {
      "x": -20,
      "y": 10,
      "z": -1,
      "name": "Rock_Shale_Cobble"
    },
    {
      "x": -20,
      "y": 11,
      "z": -1,
      "name": "Rock_Shale_Cobble"
    },
    {
      "x": -20,
      "y": 4,
      "z": 0,
      "name": "Rock_Shale_Cobble",
      "rotation": 1
    },
    {
      "x": -20,
      "y": 5,
      "z": 0,
      "name": "Rock_Shale_Brick_Pillar_Base",
      "rotation": 1
    },
    {
      "x": -20,
      "y": 6,
      "z": 0,
      "name": "Rock_Shale_Brick_Pillar_Middle",
      "rotation": 1
    },
    {
      "x": -20,
      "y": 7,
      "z": 0,
      "name": "Rock_Shale_Brick_Pillar_Middle",
      "rotation": 1
    },
    {
      "x": -20,
      "y": 8,
      "z": 0,
      "name": "Rock_Shale_Brick_Pillar_Middle",
      "rotation": 1
    },
    {
      "x": -20,
      "y": 9,
      "z": 0,
      "name": "Rock_Shale_Brick_Pillar_Base",
      "rotation": 9
    },
    {
      "x": -20,
      "y": 10,
      "z": 0,
      "name": "Rock_Shale_Cobble"
    },
    {
      "x": -20,
      "y": 11,
      "z": 0,
      "name": "Rock_Shale_Cobble"
    },
    {
      "x": -20,
      "y": 4,
      "z": 1,
      "name": "Rock_Shale_Cobble",
      "rotation": 1
    },
    {
      "x": -20,
      "y": 10,
      "z": 1,
      "name": "Rock_Shale_Cobble"
    },
    {
      "x": -20,
      "y": 11,
      "z": 1,
      "name": "Rock_Shale_Cobble"
    },
    {
      "x": -20,
      "y": 4,
      "z": 2,
      "name": "Rock_Shale_Cobble",
      "rotation": 1
    },
    {
      "x": -20,
      "y": 10,
      "z": 2,
      "name": "Rock_Shale_Cobble"
    },
    {
      "x": -20,
      "y": 11,
      "z": 2,
      "name": "Rock_Shale_Cobble"
    },
    {
      "x": -20,
      "y": 4,
      "z": 3,
      "name": "Rock_Shale_Brick_Smooth",
      "rotation": 1
    },
    {
      "x": -20,
      "y": 5,
      "z": 3,
      "name": "Rock_Shale_Brick_Pillar_Base",
      "rotation": 1
    },
    {
      "x": -20,
      "y": 6,
      "z": 3,
      "name": "Rock_Shale_Brick_Pillar_Middle",
      "rotation": 1
    },
    {
      "x": -20,
      "y": 7,
      "z": 3,
      "name": "Rock_Shale_Brick_Pillar_Middle",
      "rotation": 1
    },
    {
      "x": -20,
      "y": 8,
      "z": 3,
      "name": "Rock_Shale_Brick_Pillar_Middle",
      "rotation": 1
    },
    {
      "x": -20,
      "y": 9,
      "z": 3,
      "name": "Rock_Shale_Brick_Pillar_Base",
      "rotation": 9
    },
    {
      "x": -20,
      "y": 10,
      "z": 3,
      "name": "Rock_Shale_Cobble"
    },
    {
      "x": -20,
      "y": 11,
      "z": 3,
      "name": "Rock_Shale_Cobble"
    },
    {
      "x": -20,
      "y": 4,
      "z": 4,
      "name": "Rock_Shale_Cobble",
      "rotation": 1
    },
    {
      "x": -20,
      "y": 10,
      "z": 4,
      "name": "Rock_Shale_Cobble"
    },
    {
      "x": -20,
      "y": 11,
      "z": 4,
      "name": "Rock_Shale_Cobble"
    },
    {
      "x": -20,
      "y": 4,
      "z": 5,
      "name": "Rock_Shale_Cobble",
      "rotation": 1
    },
    {
      "x": -20,
      "y": 5,
      "z": 5,
      "name": "Rock_Shale_Brick_Smooth",
      "rotation": 1
    },
    {
      "x": -20,
      "y": 6,
      "z": 5,
      "name": "Rock_Shale_Brick_Smooth",
      "rotation": 1
    },
    {
      "x": -20,
      "y": 7,
      "z": 5,
      "name": "Rock_Shale_Brick_Smooth",
      "rotation": 1
    },
    {
      "x": -20,
      "y": 8,
      "z": 5,
      "name": "Rock_Shale_Brick_Smooth",
      "rotation": 1
    },
    {
      "x": -20,
      "y": 9,
      "z": 5,
      "name": "Rock_Shale_Brick_Ornate",
      "rotation": 1
    },
    {
      "x": -20,
      "y": 10,
      "z": 5,
      "name": "Rock_Shale_Cobble"
    },
    {
      "x": -20,
      "y": 11,
      "z": 5,
      "name": "Rock_Shale_Cobble"
    },
    {
      "x": -20,
      "y": 4,
      "z": 6,
      "name": "Rock_Shale_Cobble",
      "rotation": 1
    },
    {
      "x": -20,
      "y": 5,
      "z": 6,
      "name": "Rock_Shale_Brick",
      "rotation": 2
    },
    {
      "x": -20,
      "y": 6,
      "z": 6,
      "name": "Rock_Shale_Brick",
      "rotation": 2
    },
    {
      "x": -20,
      "y": 7,
      "z": 6,
      "name": "Rock_Shale_Brick",
      "rotation": 2
    },
    {
      "x": -20,
      "y": 8,
      "z": 6,
      "name": "Rock_Shale_Brick",
      "rotation": 2
    },
    {
      "x": -20,
      "y": 9,
      "z": 6,
      "name": "Rock_Shale_Brick_Ornate"
    },
    {
      "x": -20,
      "y": 10,
      "z": 6,
      "name": "Rock_Shale_Cobble"
    },
    {
      "x": -20,
      "y": 11,
      "z": 6,
      "name": "Rock_Shale_Cobble"
    },
    {
      "x": -20,
      "y": 4,
      "z": 7,
      "name": "Rock_Shale_Cobble",
      "rotation": 1
    },
    {
      "x": -20,
      "y": 5,
      "z": 7,
      "name": "Rock_Shale_Brick_Smooth",
      "rotation": 1
    },
    {
      "x": -20,
      "y": 6,
      "z": 7,
      "name": "Rock_Shale_Brick_Smooth",
      "rotation": 1
    },
    {
      "x": -20,
      "y": 7,
      "z": 7,
      "name": "Rock_Shale_Brick_Smooth",
      "rotation": 1
    },
    {
      "x": -20,
      "y": 8,
      "z": 7,
      "name": "Rock_Shale_Brick_Smooth",
      "rotation": 1
    },
    {
      "x": -20,
      "y": 9,
      "z": 7,
      "name": "Rock_Shale_Brick_Ornate",
      "rotation": 1
    },
    {
      "x": -20,
      "y": 10,
      "z": 7,
      "name": "Rock_Shale_Cobble"
    },
    {
      "x": -20,
      "y": 11,
      "z": 7,
      "name": "Rock_Shale_Cobble"
    },
    {
      "x": -20,
      "y": 10,
      "z": 8,
      "name": "Rock_Shale_Cobble"
    },
    {
      "x": -20,
      "y": 11,
      "z": 8,
      "name": "Rock_Shale_Cobble"
    },
    {
      "x": -20,
      "y": 10,
      "z": 9,
      "name": "Rock_Shale_Cobble"
    },
    {
      "x": -20,
      "y": 11,
      "z": 9,
      "name": "Rock_Shale_Cobble"
    },
    {
      "x": -20,
      "y": 10,
      "z": 10,
      "name": "Rock_Shale_Cobble"
    },
    {
      "x": -20,
      "y": 11,
      "z": 10,
      "name": "Rock_Shale_Cobble"
    },
    {
      "x": -20,
      "y": 12,
      "z": 10,
      "name": "*Rock_Shale_Cobble_Stairs_State_Definitions_Corner_Left",
      "rotation": 2
    },
    {
      "x": -20,
      "y": 10,
      "z": 11,
      "name": "Rock_Shale_Cobble"
    },
    {
      "x": -20,
      "y": 11,
      "z": 11,
      "name": "Rock_Shale_Cobble"
    },
    {
      "x": -20,
      "y": 12,
      "z": 11,
      "name": "Rock_Shale_Cobble_Stairs",
      "rotation": 3
    },
    {
      "x": -20,
      "y": 10,
      "z": 12,
      "name": "Rock_Shale_Cobble"
    },
    {
      "x": -20,
      "y": 11,
      "z": 12,
      "name": "Rock_Shale_Cobble"
    },
    {
      "x": -20,
      "y": 12,
      "z": 12,
      "name": "Rock_Shale_Cobble_Stairs",
      "rotation": 3
    },
    {
      "x": -20,
      "y": 10,
      "z": 13,
      "name": "Rock_Shale_Cobble"
    },
    {
      "x": -20,
      "y": 11,
      "z": 13,
      "name": "Rock_Shale_Cobble"
    },
    {
      "x": -20,
      "y": 12,
      "z": 13,
      "name": "Rock_Shale_Cobble_Stairs",
      "rotation": 3
    },
    {
      "x": -20,
      "y": 10,
      "z": 14,
      "name": "Rock_Shale_Cobble"
    },
    {
      "x": -20,
      "y": 11,
      "z": 14,
      "name": "Rock_Shale_Cobble"
    },
    {
      "x": -20,
      "y": 12,
      "z": 14,
      "name": "Rock_Shale_Cobble_Stairs",
      "rotation": 3
    },
    {
      "x": -20,
      "y": 10,
      "z": 15,
      "name": "Rock_Shale_Cobble"
    },
    {
      "x": -20,
      "y": 11,
      "z": 15,
      "name": "Rock_Shale_Cobble"
    },
    {
      "x": -20,
      "y": 12,
      "z": 15,
      "name": "Rock_Shale_Cobble_Stairs",
      "rotation": 3
    },
    {
      "x": -20,
      "y": 10,
      "z": 16,
      "name": "Rock_Shale_Cobble"
    },
    {
      "x": -20,
      "y": 11,
      "z": 16,
      "name": "Rock_Shale_Cobble"
    },
    {
      "x": -20,
      "y": 12,
      "z": 16,
      "name": "Rock_Shale_Cobble_Stairs",
      "rotation": 3
    },
    {
      "x": -20,
      "y": 10,
      "z": 17,
      "name": "Rock_Shale_Cobble"
    },
    {
      "x": -20,
      "y": 11,
      "z": 17,
      "name": "Rock_Shale_Cobble"
    },
    {
      "x": -20,
      "y": 12,
      "z": 17,
      "name": "Rock_Shale_Cobble_Stairs",
      "rotation": 3
    },
    {
      "x": -20,
      "y": 10,
      "z": 18,
      "name": "Rock_Shale_Cobble"
    },
    {
      "x": -20,
      "y": 11,
      "z": 18,
      "name": "Rock_Shale_Cobble"
    },
    {
      "x": -20,
      "y": 12,
      "z": 18,
      "name": "Rock_Shale_Cobble_Stairs",
      "rotation": 3
    },
    {
      "x": -20,
      "y": 10,
      "z": 19,
      "name": "Rock_Shale_Cobble"
    },
    {
      "x": -20,
      "y": 11,
      "z": 19,
      "name": "Rock_Shale_Cobble"
    },
    {
      "x": -20,
      "y": 12,
      "z": 19,
      "name": "Rock_Shale_Cobble_Stairs",
      "rotation": 3
    },
    {
      "x": -20,
      "y": 10,
      "z": 20,
      "name": "Rock_Shale_Cobble"
    },
    {
      "x": -20,
      "y": 11,
      "z": 20,
      "name": "Rock_Shale_Cobble"
    },
    {
      "x": -20,
      "y": 12,
      "z": 20,
      "name": "*Rock_Shale_Cobble_Stairs_State_Definitions_Corner_Left",
      "rotation": 3
    },
    {
      "x": -20,
      "y": 10,
      "z": 21,
      "name": "Rock_Shale_Cobble"
    },
    {
      "x": -20,
      "y": 11,
      "z": 21,
      "name": "Rock_Shale_Cobble_Stairs"
    },
    {
      "x": -19,
      "y": 10,
      "z": -21,
      "name": "Rock_Shale_Cobble"
    },
    {
      "x": -19,
      "y": 11,
      "z": -21,
      "name": "Rock_Shale_Cobble_Stairs",
      "rotation": 2
    },
    {
      "x": -19,
      "y": 10,
      "z": -20,
      "name": "Rock_Shale_Cobble"
    },
    {
      "x": -19,
      "y": 11,
      "z": -20,
      "name": "Rock_Shale_Cobble"
    },
    {
      "x": -19,
      "y": 12,
      "z": -20,
      "name": "Rock_Shale_Cobble_Stairs",
      "rotation": 2
    },
    {
      "x": -19,
      "y": 10,
      "z": -19,
      "name": "Rock_Shale_Cobble"
    },
    {
      "x": -19,
      "y": 11,
      "z": -19,
      "name": "Rock_Shale_Cobble"
    },
    {
      "x": -19,
      "y": 12,
      "z": -19,
      "name": "Rock_Shale_Cobble",
      "rotation": 3
    },
    {
      "x": -19,
      "y": 13,
      "z": -19,
      "name": "Rock_Shale_Brick",
      "rotation": 3
    },
    {
      "x": -19,
      "y": 14,
      "z": -19,
      "name": "Rock_Shale_Brick",
      "rotation": 3
    },
    {
      "x": -19,
      "y": 15,
      "z": -19,
      "name": "Rock_Shale_Brick_Smooth",
      "rotation": 3
    },
    {
      "x": -19,
      "y": 4,
      "z": -18,
      "name": "Rock_Shale_Cobble",
      "rotation": 2
    },
    {
      "x": -19,
      "y": 5,
      "z": -18,
      "name": "Rock_Shale_Brick",
      "rotation": 1
    },
    {
      "x": -19,
      "y": 6,
      "z": -18,
      "name": "Rock_Shale_Brick",
      "rotation": 1
    },
    {
      "x": -19,
      "y": 7,
      "z": -18,
      "name": "Rock_Shale_Brick",
      "rotation": 1
    },
    {
      "x": -19,
      "y": 8,
      "z": -18,
      "name": "Rock_Shale_Brick",
      "rotation": 1
    },
    {
      "x": -19,
      "y": 9,
      "z": -18,
      "name": "Rock_Shale_Brick_Ornate",
      "rotation": 3
    },
    {
      "x": -19,
      "y": 10,
      "z": -18,
      "name": "Rock_Shale_Cobble"
    },
    {
      "x": -19,
      "y": 11,
      "z": -18,
      "name": "Rock_Shale_Cobble"
    },
    {
      "x": -19,
      "y": 12,
      "z": -18,
      "name": "Rock_Shale_Cobble",
      "rotation": 3
    },
    {
      "x": -19,
      "y": 13,
      "z": -18,
      "name": "Rock_Shale_Brick",
      "rotation": 3
    },
    {
      "x": -19,
      "y": 14,
      "z": -18,
      "name": "Rock_Shale_Brick",
      "rotation": 3
    },
    {
      "x": -19,
      "y": 4,
      "z": -17,
      "name": "Rock_Shale_Cobble",
      "rotation": 2
    },
    {
      "x": -19,
      "y": 5,
      "z": -17,
      "name": "Rock_Shale_Brick",
      "rotation": 1
    },
    {
      "x": -19,
      "y": 6,
      "z": -17,
      "name": "Rock_Shale_Brick",
      "rotation": 1
    },
    {
      "x": -19,
      "y": 7,
      "z": -17,
      "name": "Rock_Shale_Brick",
      "rotation": 1
    },
    {
      "x": -19,
      "y": 8,
      "z": -17,
      "name": "Rock_Shale_Brick",
      "rotation": 1
    },
    {
      "x": -19,
      "y": 9,
      "z": -17,
      "name": "Rock_Shale_Brick_Ornate",
      "rotation": 3
    },
    {
      "x": -19,
      "y": 10,
      "z": -17,
      "name": "Rock_Shale_Cobble"
    },
    {
      "x": -19,
      "y": 11,
      "z": -17,
      "name": "Rock_Shale_Cobble"
    },
    {
      "x": -19,
      "y": 12,
      "z": -17,
      "name": "Rock_Shale_Cobble",
      "rotation": 3
    },
    {
      "x": -19,
      "y": 13,
      "z": -17,
      "name": "Rock_Shale_Brick",
      "rotation": 3
    },
    {
      "x": -19,
      "y": 14,
      "z": -17,
      "name": "Rock_Shale_Brick",
      "rotation": 3
    },
    {
      "x": -19,
      "y": 15,
      "z": -17,
      "name": "Rock_Shale_Brick_Smooth",
      "rotation": 3
    },
    {
      "x": -19,
      "y": 4,
      "z": -16,
      "name": "Rock_Shale_Cobble",
      "rotation": 2
    },
    {
      "x": -19,
      "y": 5,
      "z": -16,
      "name": "Rock_Shale_Brick",
      "rotation": 1
    },
    {
      "x": -19,
      "y": 6,
      "z": -16,
      "name": "Rock_Shale_Brick",
      "rotation": 1
    },
    {
      "x": -19,
      "y": 7,
      "z": -16,
      "name": "Rock_Shale_Brick",
      "rotation": 1
    },
    {
      "x": -19,
      "y": 8,
      "z": -16,
      "name": "Rock_Shale_Brick",
      "rotation": 1
    },
    {
      "x": -19,
      "y": 9,
      "z": -16,
      "name": "Rock_Shale_Brick_Ornate",
      "rotation": 3
    },
    {
      "x": -19,
      "y": 10,
      "z": -16,
      "name": "Rock_Shale_Cobble"
    },
    {
      "x": -19,
      "y": 11,
      "z": -16,
      "name": "Rock_Shale_Cobble"
    },
    {
      "x": -19,
      "y": 12,
      "z": -16,
      "name": "Rock_Shale_Cobble",
      "rotation": 3
    },
    {
      "x": -19,
      "y": 13,
      "z": -16,
      "name": "Rock_Shale_Brick",
      "rotation": 3
    },
    {
      "x": -19,
      "y": 14,
      "z": -16,
      "name": "Rock_Shale_Brick",
      "rotation": 3
    },
    {
      "x": -19,
      "y": 4,
      "z": -15,
      "name": "Rock_Shale_Cobble",
      "rotation": 2
    },
    {
      "x": -19,
      "y": 5,
      "z": -15,
      "name": "Rock_Shale_Brick",
      "rotation": 1
    },
    {
      "x": -19,
      "y": 6,
      "z": -15,
      "name": "Rock_Shale_Brick",
      "rotation": 1
    },
    {
      "x": -19,
      "y": 7,
      "z": -15,
      "name": "Rock_Shale_Brick",
      "rotation": 1
    },
    {
      "x": -19,
      "y": 8,
      "z": -15,
      "name": "Rock_Shale_Brick",
      "rotation": 1
    },
    {
      "x": -19,
      "y": 9,
      "z": -15,
      "name": "Rock_Shale_Brick_Ornate",
      "rotation": 3
    },
    {
      "x": -19,
      "y": 10,
      "z": -15,
      "name": "Rock_Shale_Cobble"
    },
    {
      "x": -19,
      "y": 11,
      "z": -15,
      "name": "Rock_Shale_Cobble"
    },
    {
      "x": -19,
      "y": 12,
      "z": -15,
      "name": "Rock_Shale_Cobble",
      "rotation": 3
    },
    {
      "x": -19,
      "y": 13,
      "z": -15,
      "name": "Rock_Shale_Brick",
      "rotation": 3
    },
    {
      "x": -19,
      "y": 14,
      "z": -15,
      "name": "Rock_Shale_Brick",
      "rotation": 3
    },
    {
      "x": -19,
      "y": 15,
      "z": -15,
      "name": "Rock_Shale_Brick_Smooth",
      "rotation": 3
    },
    {
      "x": -19,
      "y": 10,
      "z": -14,
      "name": "Rock_Shale_Cobble"
    },
    {
      "x": -19,
      "y": 11,
      "z": -14,
      "name": "Rock_Shale_Cobble"
    },
    {
      "x": -19,
      "y": 12,
      "z": -14,
      "name": "Rock_Shale_Cobble",
      "rotation": 3
    },
    {
      "x": -19,
      "y": 13,
      "z": -14,
      "name": "Rock_Shale_Brick",
      "rotation": 3
    },
    {
      "x": -19,
      "y": 14,
      "z": -14,
      "name": "Rock_Shale_Brick",
      "rotation": 3
    },
    {
      "x": -19,
      "y": 10,
      "z": -13,
      "name": "Rock_Shale_Cobble"
    },
    {
      "x": -19,
      "y": 11,
      "z": -13,
      "name": "Rock_Shale_Cobble"
    },
    {
      "x": -19,
      "y": 12,
      "z": -13,
      "name": "Rock_Shale_Cobble",
      "rotation": 3
    },
    {
      "x": -19,
      "y": 13,
      "z": -13,
      "name": "Rock_Shale_Brick",
      "rotation": 3
    },
    {
      "x": -19,
      "y": 14,
      "z": -13,
      "name": "Rock_Shale_Brick",
      "rotation": 3
    },
    {
      "x": -19,
      "y": 15,
      "z": -13,
      "name": "Rock_Shale_Brick_Smooth",
      "rotation": 3
    },
    {
      "x": -19,
      "y": 10,
      "z": -12,
      "name": "Rock_Shale_Cobble"
    },
    {
      "x": -19,
      "y": 11,
      "z": -12,
      "name": "Rock_Shale_Cobble"
    },
    {
      "x": -19,
      "y": 12,
      "z": -12,
      "name": "Rock_Shale_Cobble",
      "rotation": 3
    },
    {
      "x": -19,
      "y": 13,
      "z": -12,
      "name": "Rock_Shale_Brick",
      "rotation": 3
    },
    {
      "x": -19,
      "y": 14,
      "z": -12,
      "name": "Rock_Shale_Brick",
      "rotation": 3
    },
    {
      "x": -19,
      "y": 10,
      "z": -11,
      "name": "Rock_Shale_Cobble"
    },
    {
      "x": -19,
      "y": 11,
      "z": -11,
      "name": "Rock_Shale_Cobble"
    },
    {
      "x": -19,
      "y": 12,
      "z": -11,
      "name": "Rock_Shale_Cobble",
      "rotation": 3
    },
    {
      "x": -19,
      "y": 13,
      "z": -11,
      "name": "Rock_Shale_Brick",
      "rotation": 3
    },
    {
      "x": -19,
      "y": 14,
      "z": -11,
      "name": "Rock_Shale_Brick",
      "rotation": 3
    },
    {
      "x": -19,
      "y": 15,
      "z": -11,
      "name": "Rock_Shale_Brick_Smooth",
      "rotation": 3
    },
    {
      "x": -19,
      "y": 10,
      "z": -10,
      "name": "Rock_Shale_Cobble"
    },
    {
      "x": -19,
      "y": 11,
      "z": -10,
      "name": "Rock_Shale_Cobble"
    },
    {
      "x": -19,
      "y": 12,
      "z": -10,
      "name": "Rock_Shale_Cobble_Stairs"
    },
    {
      "x": -19,
      "y": 4,
      "z": -9,
      "name": "Rock_Shale_Cobble"
    },
    {
      "x": -19,
      "y": 5,
      "z": -9,
      "name": "Rock_Shale_Brick_Smooth"
    },
    {
      "x": -19,
      "y": 6,
      "z": -9,
      "name": "Rock_Shale_Brick_Smooth"
    },
    {
      "x": -19,
      "y": 7,
      "z": -9,
      "name": "Rock_Shale_Brick_Smooth"
    },
    {
      "x": -19,
      "y": 8,
      "z": -9,
      "name": "Rock_Shale_Brick_Smooth"
    },
    {
      "x": -19,
      "y": 9,
      "z": -9,
      "name": "Rock_Shale_Brick_Ornate"
    },
    {
      "x": -19,
      "y": 10,
      "z": -9,
      "name": "Rock_Shale_Cobble"
    },
    {
      "x": -19,
      "y": 11,
      "z": -9,
      "name": "Rock_Shale_Cobble"
    },
    {
      "x": -19,
      "y": 4,
      "z": -8,
      "name": "Rock_Shale_Cobble"
    },
    {
      "x": -19,
      "y": 5,
      "z": -8,
      "name": "Rock_Shale_Brick",
      "rotation": 1
    },
    {
      "x": -19,
      "y": 6,
      "z": -8,
      "name": "Rock_Shale_Brick",
      "rotation": 1
    },
    {
      "x": -19,
      "y": 7,
      "z": -8,
      "name": "Rock_Shale_Brick",
      "rotation": 1
    },
    {
      "x": -19,
      "y": 8,
      "z": -8,
      "name": "Rock_Shale_Brick",
      "rotation": 1
    },
    {
      "x": -19,
      "y": 9,
      "z": -8,
      "name": "Rock_Shale_Brick_Ornate",
      "rotation": 3
    },
    {
      "x": -19,
      "y": 10,
      "z": -8,
      "name": "Rock_Shale_Cobble"
    },
    {
      "x": -19,
      "y": 11,
      "z": -8,
      "name": "Rock_Shale_Cobble"
    },
    {
      "x": -19,
      "y": 4,
      "z": -7,
      "name": "Rock_Shale_Cobble"
    },
    {
      "x": -19,
      "y": 8,
      "z": -7,
      "name": "Deco_SpiderWeb_Full",
      "support": 15
    },
    {
      "x": -19,
      "y": 9,
      "z": -7,
      "name": "Deco_SpiderWeb_Full",
      "support": 15
    },
    {
      "x": -19,
      "y": 10,
      "z": -7,
      "name": "Rock_Shale_Cobble"
    },
    {
      "x": -19,
      "y": 11,
      "z": -7,
      "name": "Rock_Shale_Cobble"
    },
    {
      "x": -19,
      "y": 4,
      "z": -6,
      "name": "Rock_Shale_Cobble"
    },
    {
      "x": -19,
      "y": 10,
      "z": -6,
      "name": "Rock_Shale_Cobble"
    },
    {
      "x": -19,
      "y": 11,
      "z": -6,
      "name": "Rock_Shale_Cobble"
    },
    {
      "x": -19,
      "y": 4,
      "z": -5,
      "name": "Rock_Shale_Cobble"
    },
    {
      "x": -19,
      "y": 10,
      "z": -5,
      "name": "Rock_Shale_Cobble"
    },
    {
      "x": -19,
      "y": 11,
      "z": -5,
      "name": "Rock_Shale_Cobble"
    },
    {
      "x": -19,
      "y": 4,
      "z": -4,
      "name": "Rock_Shale_Cobble"
    },
    {
      "x": -19,
      "y": 10,
      "z": -4,
      "name": "Rock_Shale_Cobble"
    },
    {
      "x": -19,
      "y": 11,
      "z": -4,
      "name": "Rock_Shale_Cobble"
    },
    {
      "x": -19,
      "y": 4,
      "z": -3,
      "name": "Rock_Shale_Brick_Smooth"
    },
    {
      "x": -19,
      "y": 10,
      "z": -3,
      "name": "Rock_Shale_Cobble"
    },
    {
      "x": -19,
      "y": 11,
      "z": -3,
      "name": "Rock_Shale_Cobble"
    },
    {
      "x": -19,
      "y": 4,
      "z": -2,
      "name": "Rock_Shale_Cobble"
    },
    {
      "x": -19,
      "y": 10,
      "z": -2,
      "name": "Rock_Shale_Cobble"
    },
    {
      "x": -19,
      "y": 11,
      "z": -2,
      "name": "Rock_Shale_Cobble"
    },
    {
      "x": -19,
      "y": 4,
      "z": -1,
      "name": "Rock_Shale_Cobble"
    },
    {
      "x": -19,
      "y": 10,
      "z": -1,
      "name": "Rock_Shale_Cobble"
    },
    {
      "x": -19,
      "y": 11,
      "z": -1,
      "name": "Rock_Shale_Cobble"
    },
    {
      "x": -19,
      "y": 4,
      "z": 0,
      "name": "Rock_Shale_Cobble",
      "rotation": 1
    },
    {
      "x": -19,
      "y": 10,
      "z": 0,
      "name": "Rock_Shale_Cobble"
    },
    {
      "x": -19,
      "y": 11,
      "z": 0,
      "name": "Rock_Shale_Cobble"
    },
    {
      "x": -19,
      "y": 4,
      "z": 1,
      "name": "Rock_Shale_Cobble",
      "rotation": 1
    },
    {
      "x": -19,
      "y": 10,
      "z": 1,
      "name": "Rock_Shale_Cobble"
    },
    {
      "x": -19,
      "y": 11,
      "z": 1,
      "name": "Rock_Shale_Cobble"
    },
    {
      "x": -19,
      "y": 4,
      "z": 2,
      "name": "Rock_Shale_Cobble",
      "rotation": 1
    },
    {
      "x": -19,
      "y": 10,
      "z": 2,
      "name": "Rock_Shale_Cobble"
    },
    {
      "x": -19,
      "y": 11,
      "z": 2,
      "name": "Rock_Shale_Cobble"
    },
    {
      "x": -19,
      "y": 4,
      "z": 3,
      "name": "Rock_Shale_Brick_Smooth",
      "rotation": 1
    },
    {
      "x": -19,
      "y": 10,
      "z": 3,
      "name": "Rock_Shale_Cobble"
    },
    {
      "x": -19,
      "y": 11,
      "z": 3,
      "name": "Rock_Shale_Cobble"
    },
    {
      "x": -19,
      "y": 4,
      "z": 4,
      "name": "Rock_Shale_Cobble",
      "rotation": 1
    },
    {
      "x": -19,
      "y": 10,
      "z": 4,
      "name": "Rock_Shale_Cobble"
    },
    {
      "x": -19,
      "y": 11,
      "z": 4,
      "name": "Rock_Shale_Cobble"
    },
    {
      "x": -19,
      "y": 4,
      "z": 5,
      "name": "Rock_Shale_Cobble",
      "rotation": 1
    },
    {
      "x": -19,
      "y": 10,
      "z": 5,
      "name": "Rock_Shale_Cobble"
    },
    {
      "x": -19,
      "y": 11,
      "z": 5,
      "name": "Rock_Shale_Cobble"
    },
    {
      "x": -19,
      "y": 4,
      "z": 6,
      "name": "Rock_Shale_Cobble",
      "rotation": 1
    },
    {
      "x": -19,
      "y": 10,
      "z": 6,
      "name": "Rock_Shale_Cobble"
    },
    {
      "x": -19,
      "y": 11,
      "z": 6,
      "name": "Rock_Shale_Cobble"
    },
    {
      "x": -19,
      "y": 4,
      "z": 7,
      "name": "Rock_Shale_Cobble",
      "rotation": 1
    },
    {
      "x": -19,
      "y": 10,
      "z": 7,
      "name": "Rock_Shale_Cobble"
    },
    {
      "x": -19,
      "y": 11,
      "z": 7,
      "name": "Rock_Shale_Cobble"
    },
    {
      "x": -19,
      "y": 4,
      "z": 8,
      "name": "Rock_Shale_Cobble",
      "rotation": 1
    },
    {
      "x": -19,
      "y": 5,
      "z": 8,
      "name": "Rock_Shale_Brick",
      "rotation": 2
    },
    {
      "x": -19,
      "y": 6,
      "z": 8,
      "name": "Rock_Shale_Brick",
      "rotation": 2
    },
    {
      "x": -19,
      "y": 7,
      "z": 8,
      "name": "Rock_Shale_Brick",
      "rotation": 2
    },
    {
      "x": -19,
      "y": 8,
      "z": 8,
      "name": "Rock_Shale_Brick",
      "rotation": 2
    },
    {
      "x": -19,
      "y": 9,
      "z": 8,
      "name": "Rock_Shale_Brick_Ornate"
    },
    {
      "x": -19,
      "y": 10,
      "z": 8,
      "name": "Rock_Shale_Cobble"
    },
    {
      "x": -19,
      "y": 11,
      "z": 8,
      "name": "Rock_Shale_Cobble"
    },
    {
      "x": -19,
      "y": 4,
      "z": 9,
      "name": "Rock_Shale_Cobble",
      "rotation": 1
    },
    {
      "x": -19,
      "y": 5,
      "z": 9,
      "name": "Rock_Shale_Brick_Smooth",
      "rotation": 1
    },
    {
      "x": -19,
      "y": 6,
      "z": 9,
      "name": "Rock_Shale_Brick_Smooth",
      "rotation": 1
    },
    {
      "x": -19,
      "y": 7,
      "z": 9,
      "name": "Rock_Shale_Brick_Smooth",
      "rotation": 1
    },
    {
      "x": -19,
      "y": 8,
      "z": 9,
      "name": "Rock_Shale_Brick_Smooth",
      "rotation": 1
    },
    {
      "x": -19,
      "y": 9,
      "z": 9,
      "name": "Rock_Shale_Brick_Ornate",
      "rotation": 1
    },
    {
      "x": -19,
      "y": 10,
      "z": 9,
      "name": "Rock_Shale_Cobble"
    },
    {
      "x": -19,
      "y": 11,
      "z": 9,
      "name": "Rock_Shale_Cobble"
    },
    {
      "x": -19,
      "y": 10,
      "z": 10,
      "name": "Rock_Shale_Cobble"
    },
    {
      "x": -19,
      "y": 11,
      "z": 10,
      "name": "Rock_Shale_Cobble"
    },
    {
      "x": -19,
      "y": 12,
      "z": 10,
      "name": "Rock_Shale_Cobble_Stairs",
      "rotation": 2
    },
    {
      "x": -19,
      "y": 10,
      "z": 11,
      "name": "Rock_Shale_Cobble"
    },
    {
      "x": -19,
      "y": 11,
      "z": 11,
      "name": "Rock_Shale_Cobble"
    },
    {
      "x": -19,
      "y": 12,
      "z": 11,
      "name": "Rock_Shale_Cobble"
    },
    {
      "x": -19,
      "y": 13,
      "z": 11,
      "name": "Rock_Shale_Brick"
    },
    {
      "x": -19,
      "y": 14,
      "z": 11,
      "name": "Rock_Shale_Brick"
    },
    {
      "x": -19,
      "y": 15,
      "z": 11,
      "name": "Rock_Shale_Brick_Smooth"
    },
    {
      "x": -19,
      "y": 10,
      "z": 12,
      "name": "Rock_Shale_Cobble"
    },
    {
      "x": -19,
      "y": 11,
      "z": 12,
      "name": "Rock_Shale_Cobble"
    },
    {
      "x": -19,
      "y": 12,
      "z": 12,
      "name": "Rock_Shale_Cobble"
    },
    {
      "x": -19,
      "y": 13,
      "z": 12,
      "name": "Rock_Shale_Brick"
    },
    {
      "x": -19,
      "y": 14,
      "z": 12,
      "name": "Rock_Shale_Brick"
    },
    {
      "x": -19,
      "y": 10,
      "z": 13,
      "name": "Rock_Shale_Cobble"
    },
    {
      "x": -19,
      "y": 11,
      "z": 13,
      "name": "Rock_Shale_Cobble"
    },
    {
      "x": -19,
      "y": 12,
      "z": 13,
      "name": "Rock_Shale_Cobble"
    },
    {
      "x": -19,
      "y": 13,
      "z": 13,
      "name": "Rock_Shale_Brick"
    },
    {
      "x": -19,
      "y": 14,
      "z": 13,
      "name": "Rock_Shale_Brick"
    },
    {
      "x": -19,
      "y": 15,
      "z": 13,
      "name": "Rock_Shale_Brick_Smooth"
    },
    {
      "x": -19,
      "y": 10,
      "z": 14,
      "name": "Rock_Shale_Cobble"
    },
    {
      "x": -19,
      "y": 11,
      "z": 14,
      "name": "Rock_Shale_Cobble"
    },
    {
      "x": -19,
      "y": 12,
      "z": 14,
      "name": "Rock_Shale_Cobble"
    },
    {
      "x": -19,
      "y": 13,
      "z": 14,
      "name": "Rock_Shale_Brick"
    },
    {
      "x": -19,
      "y": 14,
      "z": 14,
      "name": "Rock_Shale_Brick"
    },
    {
      "x": -19,
      "y": 4,
      "z": 15,
      "name": "Rock_Shale_Cobble",
      "rotation": 3
    },
    {
      "x": -19,
      "y": 5,
      "z": 15,
      "name": "Rock_Shale_Brick",
      "rotation": 2
    },
    {
      "x": -19,
      "y": 6,
      "z": 15,
      "name": "Rock_Shale_Brick",
      "rotation": 2
    },
    {
      "x": -19,
      "y": 7,
      "z": 15,
      "name": "Rock_Shale_Brick",
      "rotation": 2
    },
    {
      "x": -19,
      "y": 8,
      "z": 15,
      "name": "Rock_Shale_Brick",
      "rotation": 2
    },
    {
      "x": -19,
      "y": 9,
      "z": 15,
      "name": "Rock_Shale_Brick_Ornate"
    },
    {
      "x": -19,
      "y": 10,
      "z": 15,
      "name": "Rock_Shale_Cobble"
    },
    {
      "x": -19,
      "y": 11,
      "z": 15,
      "name": "Rock_Shale_Cobble"
    },
    {
      "x": -19,
      "y": 12,
      "z": 15,
      "name": "Rock_Shale_Cobble"
    },
    {
      "x": -19,
      "y": 13,
      "z": 15,
      "name": "Rock_Shale_Brick"
    },
    {
      "x": -19,
      "y": 14,
      "z": 15,
      "name": "Rock_Shale_Brick"
    },
    {
      "x": -19,
      "y": 15,
      "z": 15,
      "name": "Rock_Shale_Brick_Smooth"
    },
    {
      "x": -19,
      "y": 4,
      "z": 16,
      "name": "Rock_Shale_Cobble",
      "rotation": 3
    },
    {
      "x": -19,
      "y": 5,
      "z": 16,
      "name": "Rock_Shale_Brick",
      "rotation": 2
    },
    {
      "x": -19,
      "y": 6,
      "z": 16,
      "name": "Rock_Shale_Brick",
      "rotation": 2
    },
    {
      "x": -19,
      "y": 7,
      "z": 16,
      "name": "Rock_Shale_Brick",
      "rotation": 2
    },
    {
      "x": -19,
      "y": 8,
      "z": 16,
      "name": "Rock_Shale_Brick",
      "rotation": 2
    },
    {
      "x": -19,
      "y": 9,
      "z": 16,
      "name": "Rock_Shale_Brick_Ornate"
    },
    {
      "x": -19,
      "y": 10,
      "z": 16,
      "name": "Rock_Shale_Cobble"
    },
    {
      "x": -19,
      "y": 11,
      "z": 16,
      "name": "Rock_Shale_Cobble"
    },
    {
      "x": -19,
      "y": 12,
      "z": 16,
      "name": "Rock_Shale_Cobble"
    },
    {
      "x": -19,
      "y": 13,
      "z": 16,
      "name": "Rock_Shale_Brick"
    },
    {
      "x": -19,
      "y": 14,
      "z": 16,
      "name": "Rock_Shale_Brick"
    },
    {
      "x": -19,
      "y": 4,
      "z": 17,
      "name": "Rock_Shale_Cobble",
      "rotation": 3
    },
    {
      "x": -19,
      "y": 5,
      "z": 17,
      "name": "Rock_Shale_Brick",
      "rotation": 2
    },
    {
      "x": -19,
      "y": 6,
      "z": 17,
      "name": "Rock_Shale_Brick",
      "rotation": 2
    },
    {
      "x": -19,
      "y": 7,
      "z": 17,
      "name": "Rock_Shale_Brick",
      "rotation": 2
    },
    {
      "x": -19,
      "y": 8,
      "z": 17,
      "name": "Rock_Shale_Brick",
      "rotation": 2
    },
    {
      "x": -19,
      "y": 9,
      "z": 17,
      "name": "Rock_Shale_Brick_Ornate"
    },
    {
      "x": -19,
      "y": 10,
      "z": 17,
      "name": "Rock_Shale_Cobble"
    },
    {
      "x": -19,
      "y": 11,
      "z": 17,
      "name": "Rock_Shale_Cobble"
    },
    {
      "x": -19,
      "y": 12,
      "z": 17,
      "name": "Rock_Shale_Cobble"
    },
    {
      "x": -19,
      "y": 13,
      "z": 17,
      "name": "Rock_Shale_Brick"
    },
    {
      "x": -19,
      "y": 14,
      "z": 17,
      "name": "Rock_Shale_Brick"
    },
    {
      "x": -19,
      "y": 15,
      "z": 17,
      "name": "Rock_Shale_Brick_Smooth"
    },
    {
      "x": -19,
      "y": 4,
      "z": 18,
      "name": "Rock_Shale_Cobble",
      "rotation": 3
    },
    {
      "x": -19,
      "y": 5,
      "z": 18,
      "name": "Rock_Shale_Brick",
      "rotation": 2
    },
    {
      "x": -19,
      "y": 6,
      "z": 18,
      "name": "Rock_Shale_Brick",
      "rotation": 2
    },
    {
      "x": -19,
      "y": 7,
      "z": 18,
      "name": "Rock_Shale_Brick",
      "rotation": 2
    },
    {
      "x": -19,
      "y": 8,
      "z": 18,
      "name": "Rock_Shale_Brick",
      "rotation": 2
    },
    {
      "x": -19,
      "y": 9,
      "z": 18,
      "name": "Rock_Shale_Brick_Ornate"
    },
    {
      "x": -19,
      "y": 10,
      "z": 18,
      "name": "Rock_Shale_Cobble"
    },
    {
      "x": -19,
      "y": 11,
      "z": 18,
      "name": "Rock_Shale_Cobble"
    },
    {
      "x": -19,
      "y": 12,
      "z": 18,
      "name": "Rock_Shale_Cobble"
    },
    {
      "x": -19,
      "y": 13,
      "z": 18,
      "name": "Rock_Shale_Brick"
    },
    {
      "x": -19,
      "y": 14,
      "z": 18,
      "name": "Rock_Shale_Brick"
    },
    {
      "x": -19,
      "y": 10,
      "z": 19,
      "name": "Rock_Shale_Cobble"
    },
    {
      "x": -19,
      "y": 11,
      "z": 19,
      "name": "Rock_Shale_Cobble"
    },
    {
      "x": -19,
      "y": 12,
      "z": 19,
      "name": "Rock_Shale_Cobble"
    },
    {
      "x": -19,
      "y": 13,
      "z": 19,
      "name": "Rock_Shale_Brick"
    },
    {
      "x": -19,
      "y": 14,
      "z": 19,
      "name": "Rock_Shale_Brick"
    },
    {
      "x": -19,
      "y": 15,
      "z": 19,
      "name": "Rock_Shale_Brick_Smooth"
    },
    {
      "x": -19,
      "y": 10,
      "z": 20,
      "name": "Rock_Shale_Cobble"
    },
    {
      "x": -19,
      "y": 11,
      "z": 20,
      "name": "Rock_Shale_Cobble"
    },
    {
      "x": -19,
      "y": 12,
      "z": 20,
      "name": "Rock_Shale_Cobble_Stairs"
    },
    {
      "x": -19,
      "y": 10,
      "z": 21,
      "name": "Rock_Shale_Cobble"
    },
    {
      "x": -19,
      "y": 11,
      "z": 21,
      "name": "Rock_Shale_Cobble_Stairs"
    },
    {
      "x": -18,
      "y": 10,
      "z": -21,
      "name": "Rock_Shale_Cobble"
    },
    {
      "x": -18,
      "y": 11,
      "z": -21,
      "name": "Rock_Shale_Cobble_Stairs",
      "rotation": 2
    },
    {
      "x": -18,
      "y": 10,
      "z": -20,
      "name": "Rock_Shale_Cobble"
    },
    {
      "x": -18,
      "y": 11,
      "z": -20,
      "name": "Rock_Shale_Cobble"
    },
    {
      "x": -18,
      "y": 12,
      "z": -20,
      "name": "Rock_Shale_Cobble_Stairs",
      "rotation": 2
    },
    {
      "x": -18,
      "y": 4,
      "z": -19,
      "name": "Rock_Shale_Cobble",
      "rotation": 2
    },
    {
      "x": -18,
      "y": 5,
      "z": -19,
      "name": "Rock_Shale_Brick",
      "rotation": 1
    },
    {
      "x": -18,
      "y": 6,
      "z": -19,
      "name": "Rock_Shale_Brick",
      "rotation": 1
    },
    {
      "x": -18,
      "y": 7,
      "z": -19,
      "name": "Rock_Shale_Brick",
      "rotation": 1
    },
    {
      "x": -18,
      "y": 8,
      "z": -19,
      "name": "Rock_Shale_Brick",
      "rotation": 1
    },
    {
      "x": -18,
      "y": 9,
      "z": -19,
      "name": "Rock_Shale_Brick_Ornate",
      "rotation": 3
    },
    {
      "x": -18,
      "y": 10,
      "z": -19,
      "name": "Rock_Shale_Cobble"
    },
    {
      "x": -18,
      "y": 11,
      "z": -19,
      "name": "Rock_Shale_Cobble"
    },
    {
      "x": -18,
      "y": 12,
      "z": -19,
      "name": "Rock_Shale_Cobble",
      "rotation": 3
    },
    {
      "x": -18,
      "y": 13,
      "z": -19,
      "name": "Rock_Shale_Brick",
      "rotation": 3
    },
    {
      "x": -18,
      "y": 14,
      "z": -19,
      "name": "Rock_Shale_Brick",
      "rotation": 3
    },
    {
      "x": -18,
      "y": 4,
      "z": -18,
      "name": "Rock_Shale_Cobble",
      "rotation": 2
    },
    {
      "x": -18,
      "y": 10,
      "z": -18,
      "name": "Rock_Shale_Cobble"
    },
    {
      "x": -18,
      "y": 11,
      "z": -18,
      "name": "Rock_Shale_Cobble"
    },
    {
      "x": -18,
      "y": 12,
      "z": -18,
      "name": "Rock_Shale_Cobble",
      "rotation": 3
    },
    {
      "x": -18,
      "y": 4,
      "z": -17,
      "name": "Rock_Shale_Cobble",
      "rotation": 2
    },
    {
      "x": -18,
      "y": 10,
      "z": -17,
      "name": "Rock_Shale_Cobble"
    },
    {
      "x": -18,
      "y": 11,
      "z": -17,
      "name": "Rock_Shale_Cobble"
    },
    {
      "x": -18,
      "y": 12,
      "z": -17,
      "name": "Rock_Shale_Cobble",
      "rotation": 3
    },
    {
      "x": -18,
      "y": 4,
      "z": -16,
      "name": "Rock_Shale_Cobble",
      "rotation": 2
    },
    {
      "x": -18,
      "y": 10,
      "z": -16,
      "name": "Rock_Shale_Cobble"
    },
    {
      "x": -18,
      "y": 11,
      "z": -16,
      "name": "Rock_Shale_Cobble"
    },
    {
      "x": -18,
      "y": 12,
      "z": -16,
      "name": "Rock_Shale_Cobble",
      "rotation": 3
    },
    {
      "x": -18,
      "y": 4,
      "z": -15,
      "name": "Rock_Shale_Cobble",
      "rotation": 2
    },
    {
      "x": -18,
      "y": 10,
      "z": -15,
      "name": "Rock_Shale_Cobble"
    },
    {
      "x": -18,
      "y": 11,
      "z": -15,
      "name": "Rock_Shale_Cobble"
    },
    {
      "x": -18,
      "y": 12,
      "z": -15,
      "name": "Rock_Shale_Cobble",
      "rotation": 3
    },
    {
      "x": -18,
      "y": 4,
      "z": -14,
      "name": "Rock_Shale_Cobble",
      "rotation": 2
    },
    {
      "x": -18,
      "y": 5,
      "z": -14,
      "name": "Rock_Shale_Brick",
      "rotation": 1
    },
    {
      "x": -18,
      "y": 6,
      "z": -14,
      "name": "Rock_Shale_Brick",
      "rotation": 1
    },
    {
      "x": -18,
      "y": 7,
      "z": -14,
      "name": "Rock_Shale_Brick",
      "rotation": 1
    },
    {
      "x": -18,
      "y": 8,
      "z": -14,
      "name": "Rock_Shale_Brick",
      "rotation": 1
    },
    {
      "x": -18,
      "y": 9,
      "z": -14,
      "name": "Rock_Shale_Brick_Ornate",
      "rotation": 3
    },
    {
      "x": -18,
      "y": 10,
      "z": -14,
      "name": "Rock_Shale_Cobble"
    },
    {
      "x": -18,
      "y": 11,
      "z": -14,
      "name": "Rock_Shale_Cobble"
    },
    {
      "x": -18,
      "y": 12,
      "z": -14,
      "name": "Rock_Shale_Cobble",
      "rotation": 3
    },
    {
      "x": -18,
      "y": 10,
      "z": -13,
      "name": "Rock_Shale_Cobble"
    },
    {
      "x": -18,
      "y": 11,
      "z": -13,
      "name": "Rock_Shale_Cobble"
    },
    {
      "x": -18,
      "y": 12,
      "z": -13,
      "name": "Rock_Shale_Cobble",
      "rotation": 3
    },
    {
      "x": -18,
      "y": 10,
      "z": -12,
      "name": "Rock_Shale_Cobble"
    },
    {
      "x": -18,
      "y": 11,
      "z": -12,
      "name": "Rock_Shale_Cobble"
    },
    {
      "x": -18,
      "y": 12,
      "z": -12,
      "name": "Rock_Shale_Cobble",
      "rotation": 3
    },
    {
      "x": -18,
      "y": 4,
      "z": -11,
      "name": "Rock_Shale_Cobble"
    },
    {
      "x": -18,
      "y": 5,
      "z": -11,
      "name": "Rock_Shale_Brick_Smooth"
    },
    {
      "x": -18,
      "y": 6,
      "z": -11,
      "name": "Rock_Shale_Brick_Smooth"
    },
    {
      "x": -18,
      "y": 7,
      "z": -11,
      "name": "Rock_Shale_Brick_Smooth"
    },
    {
      "x": -18,
      "y": 8,
      "z": -11,
      "name": "Rock_Shale_Brick_Smooth"
    },
    {
      "x": -18,
      "y": 9,
      "z": -11,
      "name": "Rock_Shale_Brick_Ornate"
    },
    {
      "x": -18,
      "y": 10,
      "z": -11,
      "name": "Rock_Shale_Cobble"
    },
    {
      "x": -18,
      "y": 11,
      "z": -11,
      "name": "Rock_Shale_Cobble"
    },
    {
      "x": -18,
      "y": 12,
      "z": -11,
      "name": "Rock_Shale_Cobble",
      "rotation": 3
    },
    {
      "x": -18,
      "y": 13,
      "z": -11,
      "name": "Rock_Shale_Brick",
      "rotation": 3
    },
    {
      "x": -18,
      "y": 14,
      "z": -11,
      "name": "Rock_Shale_Brick",
      "rotation": 3
    },
    {
      "x": -18,
      "y": 4,
      "z": -10,
      "name": "Rock_Shale_Cobble"
    },
    {
      "x": -18,
      "y": 5,
      "z": -10,
      "name": "Rock_Shale_Brick",
      "rotation": 1
    },
    {
      "x": -18,
      "y": 6,
      "z": -10,
      "name": "Rock_Shale_Brick",
      "rotation": 1
    },
    {
      "x": -18,
      "y": 7,
      "z": -10,
      "name": "Rock_Shale_Brick",
      "rotation": 1
    },
    {
      "x": -18,
      "y": 8,
      "z": -10,
      "name": "Rock_Shale_Brick",
      "rotation": 1
    },
    {
      "x": -18,
      "y": 9,
      "z": -10,
      "name": "Rock_Shale_Brick_Ornate",
      "rotation": 3
    },
    {
      "x": -18,
      "y": 10,
      "z": -10,
      "name": "Rock_Shale_Cobble"
    },
    {
      "x": -18,
      "y": 11,
      "z": -10,
      "name": "Rock_Shale_Cobble"
    },
    {
      "x": -18,
      "y": 12,
      "z": -10,
      "name": "Rock_Shale_Cobble_Stairs"
    },
    {
      "x": -18,
      "y": 4,
      "z": -9,
      "name": "Rock_Shale_Cobble"
    },
    {
      "x": -18,
      "y": 9,
      "z": -9,
      "name": "Deco_SpiderWeb_Full",
      "support": 15
    },
    {
      "x": -18,
      "y": 10,
      "z": -9,
      "name": "Rock_Shale_Cobble"
    },
    {
      "x": -18,
      "y": 11,
      "z": -9,
      "name": "Rock_Shale_Cobble"
    },
    {
      "x": -18,
      "y": 4,
      "z": -8,
      "name": "Rock_Shale_Cobble"
    },
    {
      "x": -18,
      "y": 10,
      "z": -8,
      "name": "Rock_Shale_Cobble"
    },
    {
      "x": -18,
      "y": 11,
      "z": -8,
      "name": "Rock_Shale_Cobble"
    },
    {
      "x": -18,
      "y": 4,
      "z": -7,
      "name": "Rock_Shale_Cobble"
    },
    {
      "x": -18,
      "y": 10,
      "z": -7,
      "name": "Rock_Shale_Cobble"
    },
    {
      "x": -18,
      "y": 11,
      "z": -7,
      "name": "Rock_Shale_Cobble"
    },
    {
      "x": -18,
      "y": 4,
      "z": -6,
      "name": "Rock_Shale_Cobble"
    },
    {
      "x": -18,
      "y": 10,
      "z": -6,
      "name": "Rock_Shale_Cobble"
    },
    {
      "x": -18,
      "y": 11,
      "z": -6,
      "name": "Rock_Shale_Cobble"
    },
    {
      "x": -18,
      "y": 4,
      "z": -5,
      "name": "Rock_Shale_Cobble"
    },
    {
      "x": -18,
      "y": 10,
      "z": -5,
      "name": "Rock_Shale_Cobble"
    },
    {
      "x": -18,
      "y": 11,
      "z": -5,
      "name": "Rock_Shale_Cobble"
    },
    {
      "x": -18,
      "y": 4,
      "z": -4,
      "name": "Rock_Shale_Cobble"
    },
    {
      "x": -18,
      "y": 10,
      "z": -4,
      "name": "Rock_Shale_Cobble"
    },
    {
      "x": -18,
      "y": 11,
      "z": -4,
      "name": "Rock_Shale_Cobble"
    },
    {
      "x": -18,
      "y": 4,
      "z": -3,
      "name": "Rock_Shale_Brick_Smooth"
    },
    {
      "x": -18,
      "y": 10,
      "z": -3,
      "name": "Rock_Shale_Cobble"
    },
    {
      "x": -18,
      "y": 11,
      "z": -3,
      "name": "Rock_Shale_Cobble"
    },
    {
      "x": -18,
      "y": 4,
      "z": -2,
      "name": "Rock_Shale_Cobble"
    },
    {
      "x": -18,
      "y": 10,
      "z": -2,
      "name": "Rock_Shale_Cobble"
    },
    {
      "x": -18,
      "y": 11,
      "z": -2,
      "name": "Rock_Shale_Cobble"
    },
    {
      "x": -18,
      "y": 4,
      "z": -1,
      "name": "Rock_Shale_Cobble"
    },
    {
      "x": -18,
      "y": 10,
      "z": -1,
      "name": "Rock_Shale_Cobble"
    },
    {
      "x": -18,
      "y": 11,
      "z": -1,
      "name": "Rock_Shale_Cobble"
    },
    {
      "x": -18,
      "y": 4,
      "z": 0,
      "name": "Rock_Shale_Cobble",
      "rotation": 1
    },
    {
      "x": -18,
      "y": 10,
      "z": 0,
      "name": "Rock_Shale_Cobble"
    },
    {
      "x": -18,
      "y": 11,
      "z": 0,
      "name": "Rock_Shale_Cobble"
    },
    {
      "x": -18,
      "y": 4,
      "z": 1,
      "name": "Rock_Shale_Cobble",
      "rotation": 1
    },
    {
      "x": -18,
      "y": 10,
      "z": 1,
      "name": "Rock_Shale_Cobble"
    },
    {
      "x": -18,
      "y": 11,
      "z": 1,
      "name": "Rock_Shale_Cobble"
    },
    {
      "x": -18,
      "y": 4,
      "z": 2,
      "name": "Rock_Shale_Cobble",
      "rotation": 1
    },
    {
      "x": -18,
      "y": 10,
      "z": 2,
      "name": "Rock_Shale_Cobble"
    },
    {
      "x": -18,
      "y": 11,
      "z": 2,
      "name": "Rock_Shale_Cobble"
    },
    {
      "x": -18,
      "y": 4,
      "z": 3,
      "name": "Rock_Shale_Brick_Smooth",
      "rotation": 1
    },
    {
      "x": -18,
      "y": 10,
      "z": 3,
      "name": "Rock_Shale_Cobble"
    },
    {
      "x": -18,
      "y": 11,
      "z": 3,
      "name": "Rock_Shale_Cobble"
    },
    {
      "x": -18,
      "y": 4,
      "z": 4,
      "name": "Rock_Shale_Cobble",
      "rotation": 1
    },
    {
      "x": -18,
      "y": 10,
      "z": 4,
      "name": "Rock_Shale_Cobble"
    },
    {
      "x": -18,
      "y": 11,
      "z": 4,
      "name": "Rock_Shale_Cobble"
    },
    {
      "x": -18,
      "y": 4,
      "z": 5,
      "name": "Rock_Shale_Cobble",
      "rotation": 1
    },
    {
      "x": -18,
      "y": 10,
      "z": 5,
      "name": "Rock_Shale_Cobble"
    },
    {
      "x": -18,
      "y": 11,
      "z": 5,
      "name": "Rock_Shale_Cobble"
    },
    {
      "x": -18,
      "y": 4,
      "z": 6,
      "name": "Rock_Shale_Cobble",
      "rotation": 1
    },
    {
      "x": -18,
      "y": 10,
      "z": 6,
      "name": "Rock_Shale_Cobble"
    },
    {
      "x": -18,
      "y": 11,
      "z": 6,
      "name": "Rock_Shale_Cobble"
    },
    {
      "x": -18,
      "y": 4,
      "z": 7,
      "name": "Rock_Shale_Cobble",
      "rotation": 1
    },
    {
      "x": -18,
      "y": 10,
      "z": 7,
      "name": "Rock_Shale_Cobble"
    },
    {
      "x": -18,
      "y": 11,
      "z": 7,
      "name": "Rock_Shale_Cobble"
    },
    {
      "x": -18,
      "y": 4,
      "z": 8,
      "name": "Rock_Shale_Cobble",
      "rotation": 1
    },
    {
      "x": -18,
      "y": 10,
      "z": 8,
      "name": "Rock_Shale_Cobble"
    },
    {
      "x": -18,
      "y": 11,
      "z": 8,
      "name": "Rock_Shale_Cobble"
    },
    {
      "x": -18,
      "y": 4,
      "z": 9,
      "name": "Rock_Shale_Cobble",
      "rotation": 1
    },
    {
      "x": -18,
      "y": 10,
      "z": 9,
      "name": "Rock_Shale_Cobble"
    },
    {
      "x": -18,
      "y": 11,
      "z": 9,
      "name": "Rock_Shale_Cobble"
    },
    {
      "x": -18,
      "y": 4,
      "z": 10,
      "name": "Rock_Shale_Cobble",
      "rotation": 1
    },
    {
      "x": -18,
      "y": 5,
      "z": 10,
      "name": "Rock_Shale_Brick",
      "rotation": 2
    },
    {
      "x": -18,
      "y": 6,
      "z": 10,
      "name": "Rock_Shale_Brick",
      "rotation": 2
    },
    {
      "x": -18,
      "y": 7,
      "z": 10,
      "name": "Rock_Shale_Brick",
      "rotation": 2
    },
    {
      "x": -18,
      "y": 8,
      "z": 10,
      "name": "Rock_Shale_Brick",
      "rotation": 2
    },
    {
      "x": -18,
      "y": 9,
      "z": 10,
      "name": "Rock_Shale_Brick_Ornate"
    },
    {
      "x": -18,
      "y": 10,
      "z": 10,
      "name": "Rock_Shale_Cobble"
    },
    {
      "x": -18,
      "y": 11,
      "z": 10,
      "name": "Rock_Shale_Cobble"
    },
    {
      "x": -18,
      "y": 12,
      "z": 10,
      "name": "Rock_Shale_Cobble_Stairs",
      "rotation": 2
    },
    {
      "x": -18,
      "y": 4,
      "z": 11,
      "name": "Rock_Shale_Cobble",
      "rotation": 1
    },
    {
      "x": -18,
      "y": 5,
      "z": 11,
      "name": "Rock_Shale_Brick_Smooth",
      "rotation": 1
    },
    {
      "x": -18,
      "y": 6,
      "z": 11,
      "name": "Rock_Shale_Brick_Smooth",
      "rotation": 1
    },
    {
      "x": -18,
      "y": 7,
      "z": 11,
      "name": "Rock_Shale_Brick_Smooth",
      "rotation": 1
    },
    {
      "x": -18,
      "y": 8,
      "z": 11,
      "name": "Rock_Shale_Brick_Smooth",
      "rotation": 1
    },
    {
      "x": -18,
      "y": 9,
      "z": 11,
      "name": "Rock_Shale_Brick_Ornate",
      "rotation": 1
    },
    {
      "x": -18,
      "y": 10,
      "z": 11,
      "name": "Rock_Shale_Cobble"
    },
    {
      "x": -18,
      "y": 11,
      "z": 11,
      "name": "Rock_Shale_Cobble"
    },
    {
      "x": -18,
      "y": 12,
      "z": 11,
      "name": "Rock_Shale_Cobble"
    },
    {
      "x": -18,
      "y": 13,
      "z": 11,
      "name": "Rock_Shale_Brick"
    },
    {
      "x": -18,
      "y": 14,
      "z": 11,
      "name": "Rock_Shale_Brick"
    },
    {
      "x": -18,
      "y": 10,
      "z": 12,
      "name": "Rock_Shale_Cobble"
    },
    {
      "x": -18,
      "y": 11,
      "z": 12,
      "name": "Rock_Shale_Cobble"
    },
    {
      "x": -18,
      "y": 12,
      "z": 12,
      "name": "Rock_Shale_Cobble"
    },
    {
      "x": -18,
      "y": 10,
      "z": 13,
      "name": "Rock_Shale_Cobble"
    },
    {
      "x": -18,
      "y": 11,
      "z": 13,
      "name": "Rock_Shale_Cobble"
    },
    {
      "x": -18,
      "y": 12,
      "z": 13,
      "name": "Rock_Shale_Cobble"
    },
    {
      "x": -18,
      "y": 4,
      "z": 14,
      "name": "Rock_Shale_Cobble",
      "rotation": 3
    },
    {
      "x": -18,
      "y": 5,
      "z": 14,
      "name": "Rock_Shale_Brick",
      "rotation": 2
    },
    {
      "x": -18,
      "y": 6,
      "z": 14,
      "name": "Rock_Shale_Brick",
      "rotation": 2
    },
    {
      "x": -18,
      "y": 7,
      "z": 14,
      "name": "Rock_Shale_Brick",
      "rotation": 2
    },
    {
      "x": -18,
      "y": 8,
      "z": 14,
      "name": "Rock_Shale_Brick",
      "rotation": 2
    },
    {
      "x": -18,
      "y": 9,
      "z": 14,
      "name": "Rock_Shale_Brick_Ornate"
    },
    {
      "x": -18,
      "y": 10,
      "z": 14,
      "name": "Rock_Shale_Cobble"
    },
    {
      "x": -18,
      "y": 11,
      "z": 14,
      "name": "Rock_Shale_Cobble"
    },
    {
      "x": -18,
      "y": 12,
      "z": 14,
      "name": "Rock_Shale_Cobble"
    },
    {
      "x": -18,
      "y": 4,
      "z": 15,
      "name": "Rock_Shale_Cobble",
      "rotation": 3
    },
    {
      "x": -18,
      "y": 10,
      "z": 15,
      "name": "Rock_Shale_Cobble"
    },
    {
      "x": -18,
      "y": 11,
      "z": 15,
      "name": "Rock_Shale_Cobble"
    },
    {
      "x": -18,
      "y": 12,
      "z": 15,
      "name": "Rock_Shale_Cobble"
    },
    {
      "x": -18,
      "y": 4,
      "z": 16,
      "name": "Rock_Shale_Cobble",
      "rotation": 3
    },
    {
      "x": -18,
      "y": 10,
      "z": 16,
      "name": "Rock_Shale_Cobble"
    },
    {
      "x": -18,
      "y": 11,
      "z": 16,
      "name": "Rock_Shale_Cobble"
    },
    {
      "x": -18,
      "y": 12,
      "z": 16,
      "name": "Rock_Shale_Cobble"
    },
    {
      "x": -18,
      "y": 4,
      "z": 17,
      "name": "Rock_Shale_Cobble",
      "rotation": 3
    },
    {
      "x": -18,
      "y": 10,
      "z": 17,
      "name": "Rock_Shale_Cobble"
    },
    {
      "x": -18,
      "y": 11,
      "z": 17,
      "name": "Rock_Shale_Cobble"
    },
    {
      "x": -18,
      "y": 12,
      "z": 17,
      "name": "Rock_Shale_Cobble"
    },
    {
      "x": -18,
      "y": 4,
      "z": 18,
      "name": "Rock_Shale_Cobble",
      "rotation": 3
    },
    {
      "x": -18,
      "y": 10,
      "z": 18,
      "name": "Rock_Shale_Cobble"
    },
    {
      "x": -18,
      "y": 11,
      "z": 18,
      "name": "Rock_Shale_Cobble"
    },
    {
      "x": -18,
      "y": 12,
      "z": 18,
      "name": "Rock_Shale_Cobble"
    },
    {
      "x": -18,
      "y": 4,
      "z": 19,
      "name": "Rock_Shale_Cobble",
      "rotation": 3
    },
    {
      "x": -18,
      "y": 5,
      "z": 19,
      "name": "Rock_Shale_Brick",
      "rotation": 2
    },
    {
      "x": -18,
      "y": 6,
      "z": 19,
      "name": "Rock_Shale_Brick",
      "rotation": 2
    },
    {
      "x": -18,
      "y": 7,
      "z": 19,
      "name": "Rock_Shale_Brick",
      "rotation": 2
    },
    {
      "x": -18,
      "y": 8,
      "z": 19,
      "name": "Rock_Shale_Brick",
      "rotation": 2
    },
    {
      "x": -18,
      "y": 9,
      "z": 19,
      "name": "Rock_Shale_Brick_Ornate"
    },
    {
      "x": -18,
      "y": 10,
      "z": 19,
      "name": "Rock_Shale_Cobble"
    },
    {
      "x": -18,
      "y": 11,
      "z": 19,
      "name": "Rock_Shale_Cobble"
    },
    {
      "x": -18,
      "y": 12,
      "z": 19,
      "name": "Rock_Shale_Cobble"
    },
    {
      "x": -18,
      "y": 13,
      "z": 19,
      "name": "Rock_Shale_Brick"
    },
    {
      "x": -18,
      "y": 14,
      "z": 19,
      "name": "Rock_Shale_Brick"
    },
    {
      "x": -18,
      "y": 10,
      "z": 20,
      "name": "Rock_Shale_Cobble"
    },
    {
      "x": -18,
      "y": 11,
      "z": 20,
      "name": "Rock_Shale_Cobble"
    },
    {
      "x": -18,
      "y": 12,
      "z": 20,
      "name": "Rock_Shale_Cobble_Stairs"
    },
    {
      "x": -18,
      "y": 10,
      "z": 21,
      "name": "Rock_Shale_Cobble"
    },
    {
      "x": -18,
      "y": 11,
      "z": 21,
      "name": "Rock_Shale_Cobble_Stairs"
    },
    {
      "x": -17,
      "y": 10,
      "z": -21,
      "name": "Rock_Shale_Cobble"
    },
    {
      "x": -17,
      "y": 11,
      "z": -21,
      "name": "Rock_Shale_Cobble_Stairs",
      "rotation": 2
    },
    {
      "x": -17,
      "y": 10,
      "z": -20,
      "name": "Rock_Shale_Cobble"
    },
    {
      "x": -17,
      "y": 11,
      "z": -20,
      "name": "Rock_Shale_Cobble"
    },
    {
      "x": -17,
      "y": 12,
      "z": -20,
      "name": "Rock_Shale_Cobble_Stairs",
      "rotation": 2
    },
    {
      "x": -17,
      "y": 4,
      "z": -19,
      "name": "Rock_Shale_Cobble",
      "rotation": 2
    },
    {
      "x": -17,
      "y": 5,
      "z": -19,
      "name": "Rock_Shale_Brick",
      "rotation": 1
    },
    {
      "x": -17,
      "y": 6,
      "z": -19,
      "name": "Rock_Shale_Brick",
      "rotation": 1
    },
    {
      "x": -17,
      "y": 7,
      "z": -19,
      "name": "Rock_Shale_Brick",
      "rotation": 1
    },
    {
      "x": -17,
      "y": 8,
      "z": -19,
      "name": "Rock_Shale_Brick",
      "rotation": 1
    },
    {
      "x": -17,
      "y": 9,
      "z": -19,
      "name": "Rock_Shale_Brick_Ornate",
      "rotation": 3
    },
    {
      "x": -17,
      "y": 10,
      "z": -19,
      "name": "Rock_Shale_Cobble"
    },
    {
      "x": -17,
      "y": 11,
      "z": -19,
      "name": "Rock_Shale_Cobble"
    },
    {
      "x": -17,
      "y": 12,
      "z": -19,
      "name": "Rock_Shale_Cobble",
      "rotation": 3
    },
    {
      "x": -17,
      "y": 13,
      "z": -19,
      "name": "Rock_Shale_Brick",
      "rotation": 3
    },
    {
      "x": -17,
      "y": 14,
      "z": -19,
      "name": "Rock_Shale_Brick",
      "rotation": 3
    },
    {
      "x": -17,
      "y": 15,
      "z": -19,
      "name": "Rock_Shale_Brick_Smooth",
      "rotation": 3
    },
    {
      "x": -17,
      "y": 4,
      "z": -18,
      "name": "Rock_Shale_Cobble",
      "rotation": 2
    },
    {
      "x": -17,
      "y": 10,
      "z": -18,
      "name": "Rock_Shale_Cobble"
    },
    {
      "x": -17,
      "y": 11,
      "z": -18,
      "name": "Rock_Shale_Cobble"
    },
    {
      "x": -17,
      "y": 12,
      "z": -18,
      "name": "Rock_Shale_Cobble",
      "rotation": 3
    },
    {
      "x": -17,
      "y": 4,
      "z": -17,
      "name": "Rock_Shale_Cobble",
      "rotation": 2
    },
    {
      "x": -17,
      "y": 10,
      "z": -17,
      "name": "Rock_Shale_Cobble"
    },
    {
      "x": -17,
      "y": 11,
      "z": -17,
      "name": "Rock_Shale_Cobble"
    },
    {
      "x": -17,
      "y": 12,
      "z": -17,
      "name": "Rock_Shale_Cobble",
      "rotation": 3
    },
    {
      "x": -17,
      "y": 4,
      "z": -16,
      "name": "Rock_Shale_Cobble",
      "rotation": 2
    },
    {
      "x": -17,
      "y": 10,
      "z": -16,
      "name": "Rock_Shale_Cobble"
    },
    {
      "x": -17,
      "y": 11,
      "z": -16,
      "name": "Rock_Shale_Cobble"
    },
    {
      "x": -17,
      "y": 12,
      "z": -16,
      "name": "Rock_Shale_Cobble",
      "rotation": 3
    },
    {
      "x": -17,
      "y": 4,
      "z": -15,
      "name": "Rock_Shale_Cobble",
      "rotation": 2
    },
    {
      "x": -17,
      "y": 10,
      "z": -15,
      "name": "Rock_Shale_Cobble"
    },
    {
      "x": -17,
      "y": 11,
      "z": -15,
      "name": "Rock_Shale_Cobble"
    },
    {
      "x": -17,
      "y": 12,
      "z": -15,
      "name": "Rock_Shale_Cobble",
      "rotation": 3
    },
    {
      "x": -17,
      "y": 4,
      "z": -14,
      "name": "Rock_Shale_Cobble",
      "rotation": 2
    },
    {
      "x": -17,
      "y": 9,
      "z": -14,
      "name": "Deco_SpiderWeb_Full",
      "rotation": 2
    },
    {
      "x": -17,
      "y": 10,
      "z": -14,
      "name": "Rock_Shale_Cobble"
    },
    {
      "x": -17,
      "y": 11,
      "z": -14,
      "name": "Rock_Shale_Cobble"
    },
    {
      "x": -17,
      "y": 12,
      "z": -14,
      "name": "Rock_Shale_Cobble",
      "rotation": 3
    },
    {
      "x": -17,
      "y": 4,
      "z": -13,
      "name": "Rock_Shale_Cobble",
      "rotation": 2
    },
    {
      "x": -17,
      "y": 5,
      "z": -13,
      "name": "Rock_Shale_Brick",
      "rotation": 1
    },
    {
      "x": -17,
      "y": 6,
      "z": -13,
      "name": "Rock_Shale_Brick",
      "rotation": 1
    },
    {
      "x": -17,
      "y": 7,
      "z": -13,
      "name": "Rock_Shale_Brick",
      "rotation": 1
    },
    {
      "x": -17,
      "y": 8,
      "z": -13,
      "name": "Rock_Shale_Brick",
      "rotation": 1
    },
    {
      "x": -17,
      "y": 9,
      "z": -13,
      "name": "Rock_Shale_Brick_Ornate",
      "rotation": 3
    },
    {
      "x": -17,
      "y": 10,
      "z": -13,
      "name": "Rock_Shale_Cobble"
    },
    {
      "x": -17,
      "y": 11,
      "z": -13,
      "name": "Rock_Shale_Cobble"
    },
    {
      "x": -17,
      "y": 12,
      "z": -13,
      "name": "Rock_Shale_Cobble",
      "rotation": 3
    },
    {
      "x": -17,
      "y": 4,
      "z": -12,
      "name": "Rock_Shale_Brick_Smooth"
    },
    {
      "x": -17,
      "y": 5,
      "z": -12,
      "name": "Rock_Shale_Brick_Smooth"
    },
    {
      "x": -17,
      "y": 6,
      "z": -12,
      "name": "Rock_Shale_Brick_Smooth"
    },
    {
      "x": -17,
      "y": 7,
      "z": -12,
      "name": "Rock_Shale_Brick_Smooth"
    },
    {
      "x": -17,
      "y": 8,
      "z": -12,
      "name": "Rock_Shale_Brick_Smooth"
    },
    {
      "x": -17,
      "y": 9,
      "z": -12,
      "name": "Rock_Shale_Brick_Ornate"
    },
    {
      "x": -17,
      "y": 10,
      "z": -12,
      "name": "Rock_Shale_Cobble"
    },
    {
      "x": -17,
      "y": 11,
      "z": -12,
      "name": "Rock_Shale_Cobble"
    },
    {
      "x": -17,
      "y": 12,
      "z": -12,
      "name": "Rock_Shale_Cobble",
      "rotation": 3
    },
    {
      "x": -17,
      "y": 4,
      "z": -11,
      "name": "Rock_Shale_Brick_Smooth"
    },
    {
      "x": -17,
      "y": 5,
      "z": -11,
      "name": "Rock_Shale_Brick_Pillar_Base"
    },
    {
      "x": -17,
      "y": 6,
      "z": -11,
      "name": "Rock_Shale_Brick_Pillar_Middle"
    },
    {
      "x": -17,
      "y": 7,
      "z": -11,
      "name": "Rock_Shale_Brick_Pillar_Middle"
    },
    {
      "x": -17,
      "y": 8,
      "z": -11,
      "name": "Rock_Shale_Brick_Pillar_Middle"
    },
    {
      "x": -17,
      "y": 9,
      "z": -11,
      "name": "Rock_Shale_Brick_Pillar_Base",
      "rotation": 8
    },
    {
      "x": -17,
      "y": 10,
      "z": -11,
      "name": "Rock_Shale_Cobble"
    },
    {
      "x": -17,
      "y": 11,
      "z": -11,
      "name": "Rock_Shale_Cobble"
    },
    {
      "x": -17,
      "y": 12,
      "z": -11,
      "name": "Rock_Shale_Cobble",
      "rotation": 3
    },
    {
      "x": -17,
      "y": 13,
      "z": -11,
      "name": "Rock_Shale_Brick",
      "rotation": 3
    },
    {
      "x": -17,
      "y": 14,
      "z": -11,
      "name": "Rock_Shale_Brick",
      "rotation": 3
    },
    {
      "x": -17,
      "y": 15,
      "z": -11,
      "name": "Rock_Shale_Brick_Smooth",
      "rotation": 3
    },
    {
      "x": -17,
      "y": 4,
      "z": -10,
      "name": "Rock_Shale_Brick_Smooth"
    },
    {
      "x": -17,
      "y": 10,
      "z": -10,
      "name": "Rock_Shale_Cobble"
    },
    {
      "x": -17,
      "y": 11,
      "z": -10,
      "name": "Rock_Shale_Cobble"
    },
    {
      "x": -17,
      "y": 12,
      "z": -10,
      "name": "Rock_Shale_Cobble_Stairs"
    },
    {
      "x": -17,
      "y": 4,
      "z": -9,
      "name": "Rock_Shale_Brick_Smooth"
    },
    {
      "x": -17,
      "y": 10,
      "z": -9,
      "name": "Rock_Shale_Cobble"
    },
    {
      "x": -17,
      "y": 11,
      "z": -9,
      "name": "Rock_Shale_Cobble"
    },
    {
      "x": -17,
      "y": 4,
      "z": -8,
      "name": "Rock_Shale_Brick_Smooth"
    },
    {
      "x": -17,
      "y": 10,
      "z": -8,
      "name": "Rock_Shale_Cobble"
    },
    {
      "x": -17,
      "y": 11,
      "z": -8,
      "name": "Rock_Shale_Cobble"
    },
    {
      "x": -17,
      "y": 4,
      "z": -7,
      "name": "Rock_Shale_Brick_Smooth"
    },
    {
      "x": -17,
      "y": 10,
      "z": -7,
      "name": "Rock_Shale_Cobble"
    },
    {
      "x": -17,
      "y": 11,
      "z": -7,
      "name": "Rock_Shale_Cobble"
    },
    {
      "x": -17,
      "y": 4,
      "z": -6,
      "name": "Rock_Shale_Brick_Smooth"
    },
    {
      "x": -17,
      "y": 10,
      "z": -6,
      "name": "Rock_Shale_Cobble"
    },
    {
      "x": -17,
      "y": 11,
      "z": -6,
      "name": "Rock_Shale_Cobble"
    },
    {
      "x": -17,
      "y": 4,
      "z": -5,
      "name": "Rock_Shale_Cobble"
    },
    {
      "x": -17,
      "y": 10,
      "z": -5,
      "name": "Rock_Shale_Cobble"
    },
    {
      "x": -17,
      "y": 11,
      "z": -5,
      "name": "Rock_Shale_Cobble"
    },
    {
      "x": -17,
      "y": 4,
      "z": -4,
      "name": "Rock_Shale_Cobble"
    },
    {
      "x": -17,
      "y": 10,
      "z": -4,
      "name": "Rock_Shale_Cobble"
    },
    {
      "x": -17,
      "y": 11,
      "z": -4,
      "name": "Rock_Shale_Cobble"
    },
    {
      "x": -17,
      "y": 4,
      "z": -3,
      "name": "Rock_Shale_Brick_Smooth"
    },
    {
      "x": -17,
      "y": 10,
      "z": -3,
      "name": "Rock_Shale_Cobble"
    },
    {
      "x": -17,
      "y": 11,
      "z": -3,
      "name": "Rock_Shale_Cobble"
    },
    {
      "x": -17,
      "y": 4,
      "z": -2,
      "name": "Rock_Shale_Cobble"
    },
    {
      "x": -17,
      "y": 10,
      "z": -2,
      "name": "Rock_Shale_Cobble"
    },
    {
      "x": -17,
      "y": 11,
      "z": -2,
      "name": "Rock_Shale_Cobble"
    },
    {
      "x": -17,
      "y": 4,
      "z": -1,
      "name": "Rock_Shale_Cobble"
    },
    {
      "x": -17,
      "y": 10,
      "z": -1,
      "name": "Rock_Shale_Cobble"
    },
    {
      "x": -17,
      "y": 11,
      "z": -1,
      "name": "Rock_Shale_Cobble"
    },
    {
      "x": -17,
      "y": 4,
      "z": 0,
      "name": "Rock_Shale_Cobble",
      "rotation": 1
    },
    {
      "x": -17,
      "y": 10,
      "z": 0,
      "name": "Rock_Shale_Cobble"
    },
    {
      "x": -17,
      "y": 11,
      "z": 0,
      "name": "Rock_Shale_Cobble"
    },
    {
      "x": -17,
      "y": 4,
      "z": 1,
      "name": "Rock_Shale_Cobble",
      "rotation": 1
    },
    {
      "x": -17,
      "y": 10,
      "z": 1,
      "name": "Rock_Shale_Cobble"
    },
    {
      "x": -17,
      "y": 11,
      "z": 1,
      "name": "Rock_Shale_Cobble"
    },
    {
      "x": -17,
      "y": 4,
      "z": 2,
      "name": "Rock_Shale_Cobble",
      "rotation": 1
    },
    {
      "x": -17,
      "y": 10,
      "z": 2,
      "name": "Rock_Shale_Cobble"
    },
    {
      "x": -17,
      "y": 11,
      "z": 2,
      "name": "Rock_Shale_Cobble"
    },
    {
      "x": -17,
      "y": 4,
      "z": 3,
      "name": "Rock_Shale_Brick_Smooth",
      "rotation": 1
    },
    {
      "x": -17,
      "y": 10,
      "z": 3,
      "name": "Rock_Shale_Cobble"
    },
    {
      "x": -17,
      "y": 11,
      "z": 3,
      "name": "Rock_Shale_Cobble"
    },
    {
      "x": -17,
      "y": 4,
      "z": 4,
      "name": "Rock_Shale_Cobble",
      "rotation": 1
    },
    {
      "x": -17,
      "y": 10,
      "z": 4,
      "name": "Rock_Shale_Cobble"
    },
    {
      "x": -17,
      "y": 11,
      "z": 4,
      "name": "Rock_Shale_Cobble"
    },
    {
      "x": -17,
      "y": 4,
      "z": 5,
      "name": "Rock_Shale_Cobble",
      "rotation": 1
    },
    {
      "x": -17,
      "y": 10,
      "z": 5,
      "name": "Rock_Shale_Cobble"
    },
    {
      "x": -17,
      "y": 11,
      "z": 5,
      "name": "Rock_Shale_Cobble"
    },
    {
      "x": -17,
      "y": 4,
      "z": 6,
      "name": "Rock_Shale_Brick_Smooth",
      "rotation": 1
    },
    {
      "x": -17,
      "y": 10,
      "z": 6,
      "name": "Rock_Shale_Cobble"
    },
    {
      "x": -17,
      "y": 11,
      "z": 6,
      "name": "Rock_Shale_Cobble"
    },
    {
      "x": -17,
      "y": 4,
      "z": 7,
      "name": "Rock_Shale_Brick_Smooth",
      "rotation": 1
    },
    {
      "x": -17,
      "y": 10,
      "z": 7,
      "name": "Rock_Shale_Cobble"
    },
    {
      "x": -17,
      "y": 11,
      "z": 7,
      "name": "Rock_Shale_Cobble"
    },
    {
      "x": -17,
      "y": 4,
      "z": 8,
      "name": "Rock_Shale_Brick_Smooth",
      "rotation": 1
    },
    {
      "x": -17,
      "y": 10,
      "z": 8,
      "name": "Rock_Shale_Cobble"
    },
    {
      "x": -17,
      "y": 11,
      "z": 8,
      "name": "Rock_Shale_Cobble"
    },
    {
      "x": -17,
      "y": 4,
      "z": 9,
      "name": "Rock_Shale_Brick_Smooth",
      "rotation": 1
    },
    {
      "x": -17,
      "y": 10,
      "z": 9,
      "name": "Rock_Shale_Cobble"
    },
    {
      "x": -17,
      "y": 11,
      "z": 9,
      "name": "Rock_Shale_Cobble"
    },
    {
      "x": -17,
      "y": 4,
      "z": 10,
      "name": "Rock_Shale_Brick_Smooth",
      "rotation": 1
    },
    {
      "x": -17,
      "y": 10,
      "z": 10,
      "name": "Rock_Shale_Cobble"
    },
    {
      "x": -17,
      "y": 11,
      "z": 10,
      "name": "Rock_Shale_Cobble"
    },
    {
      "x": -17,
      "y": 12,
      "z": 10,
      "name": "Rock_Shale_Cobble_Stairs",
      "rotation": 2
    },
    {
      "x": -17,
      "y": 4,
      "z": 11,
      "name": "Rock_Shale_Brick_Smooth",
      "rotation": 1
    },
    {
      "x": -17,
      "y": 5,
      "z": 11,
      "name": "Rock_Shale_Brick_Pillar_Base",
      "rotation": 1
    },
    {
      "x": -17,
      "y": 6,
      "z": 11,
      "name": "Rock_Shale_Brick_Pillar_Middle",
      "rotation": 1
    },
    {
      "x": -17,
      "y": 7,
      "z": 11,
      "name": "Rock_Shale_Brick_Pillar_Middle",
      "rotation": 1
    },
    {
      "x": -17,
      "y": 8,
      "z": 11,
      "name": "Rock_Shale_Brick_Pillar_Middle",
      "rotation": 1
    },
    {
      "x": -17,
      "y": 9,
      "z": 11,
      "name": "Rock_Shale_Brick_Pillar_Base",
      "rotation": 9
    },
    {
      "x": -17,
      "y": 10,
      "z": 11,
      "name": "Rock_Shale_Cobble"
    },
    {
      "x": -17,
      "y": 11,
      "z": 11,
      "name": "Rock_Shale_Cobble"
    },
    {
      "x": -17,
      "y": 12,
      "z": 11,
      "name": "Rock_Shale_Cobble"
    },
    {
      "x": -17,
      "y": 13,
      "z": 11,
      "name": "Rock_Shale_Brick"
    },
    {
      "x": -17,
      "y": 14,
      "z": 11,
      "name": "Rock_Shale_Brick"
    },
    {
      "x": -17,
      "y": 15,
      "z": 11,
      "name": "Rock_Shale_Brick_Smooth"
    },
    {
      "x": -17,
      "y": 4,
      "z": 12,
      "name": "Rock_Shale_Brick_Smooth",
      "rotation": 1
    },
    {
      "x": -17,
      "y": 5,
      "z": 12,
      "name": "Rock_Shale_Brick_Smooth",
      "rotation": 1
    },
    {
      "x": -17,
      "y": 6,
      "z": 12,
      "name": "Rock_Shale_Brick_Smooth",
      "rotation": 1
    },
    {
      "x": -17,
      "y": 7,
      "z": 12,
      "name": "Rock_Shale_Brick_Smooth",
      "rotation": 1
    },
    {
      "x": -17,
      "y": 8,
      "z": 12,
      "name": "Rock_Shale_Brick_Smooth",
      "rotation": 1
    },
    {
      "x": -17,
      "y": 9,
      "z": 12,
      "name": "Rock_Shale_Brick_Ornate",
      "rotation": 1
    },
    {
      "x": -17,
      "y": 10,
      "z": 12,
      "name": "Rock_Shale_Cobble"
    },
    {
      "x": -17,
      "y": 11,
      "z": 12,
      "name": "Rock_Shale_Cobble"
    },
    {
      "x": -17,
      "y": 12,
      "z": 12,
      "name": "Rock_Shale_Cobble"
    },
    {
      "x": -17,
      "y": 4,
      "z": 13,
      "name": "Rock_Shale_Cobble",
      "rotation": 3
    },
    {
      "x": -17,
      "y": 5,
      "z": 13,
      "name": "Rock_Shale_Brick",
      "rotation": 2
    },
    {
      "x": -17,
      "y": 6,
      "z": 13,
      "name": "Rock_Shale_Brick",
      "rotation": 2
    },
    {
      "x": -17,
      "y": 7,
      "z": 13,
      "name": "Rock_Shale_Brick",
      "rotation": 2
    },
    {
      "x": -17,
      "y": 8,
      "z": 13,
      "name": "Rock_Shale_Brick",
      "rotation": 2
    },
    {
      "x": -17,
      "y": 9,
      "z": 13,
      "name": "Rock_Shale_Brick_Ornate"
    },
    {
      "x": -17,
      "y": 10,
      "z": 13,
      "name": "Rock_Shale_Cobble"
    },
    {
      "x": -17,
      "y": 11,
      "z": 13,
      "name": "Rock_Shale_Cobble"
    },
    {
      "x": -17,
      "y": 12,
      "z": 13,
      "name": "Rock_Shale_Cobble"
    },
    {
      "x": -17,
      "y": 4,
      "z": 14,
      "name": "Rock_Shale_Cobble",
      "rotation": 3
    },
    {
      "x": -17,
      "y": 10,
      "z": 14,
      "name": "Rock_Shale_Cobble"
    },
    {
      "x": -17,
      "y": 11,
      "z": 14,
      "name": "Rock_Shale_Cobble"
    },
    {
      "x": -17,
      "y": 12,
      "z": 14,
      "name": "Rock_Shale_Cobble"
    },
    {
      "x": -17,
      "y": 4,
      "z": 15,
      "name": "Rock_Shale_Cobble",
      "rotation": 3
    },
    {
      "x": -17,
      "y": 10,
      "z": 15,
      "name": "Rock_Shale_Cobble"
    },
    {
      "x": -17,
      "y": 11,
      "z": 15,
      "name": "Rock_Shale_Cobble"
    },
    {
      "x": -17,
      "y": 12,
      "z": 15,
      "name": "Rock_Shale_Cobble"
    },
    {
      "x": -17,
      "y": 4,
      "z": 16,
      "name": "Rock_Shale_Cobble",
      "rotation": 3
    },
    {
      "x": -17,
      "y": 10,
      "z": 16,
      "name": "Rock_Shale_Cobble"
    },
    {
      "x": -17,
      "y": 11,
      "z": 16,
      "name": "Rock_Shale_Cobble"
    },
    {
      "x": -17,
      "y": 12,
      "z": 16,
      "name": "Rock_Shale_Cobble"
    },
    {
      "x": -17,
      "y": 4,
      "z": 17,
      "name": "Rock_Shale_Cobble",
      "rotation": 3
    },
    {
      "x": -17,
      "y": 10,
      "z": 17,
      "name": "Rock_Shale_Cobble"
    },
    {
      "x": -17,
      "y": 11,
      "z": 17,
      "name": "Rock_Shale_Cobble"
    },
    {
      "x": -17,
      "y": 12,
      "z": 17,
      "name": "Rock_Shale_Cobble"
    },
    {
      "x": -17,
      "y": 4,
      "z": 18,
      "name": "Rock_Shale_Cobble",
      "rotation": 3
    },
    {
      "x": -17,
      "y": 10,
      "z": 18,
      "name": "Rock_Shale_Cobble"
    },
    {
      "x": -17,
      "y": 11,
      "z": 18,
      "name": "Rock_Shale_Cobble"
    },
    {
      "x": -17,
      "y": 12,
      "z": 18,
      "name": "Rock_Shale_Cobble"
    },
    {
      "x": -17,
      "y": 4,
      "z": 19,
      "name": "Rock_Shale_Cobble",
      "rotation": 3
    },
    {
      "x": -17,
      "y": 5,
      "z": 19,
      "name": "Rock_Shale_Brick",
      "rotation": 2
    },
    {
      "x": -17,
      "y": 6,
      "z": 19,
      "name": "Rock_Shale_Brick",
      "rotation": 2
    },
    {
      "x": -17,
      "y": 7,
      "z": 19,
      "name": "Rock_Shale_Brick",
      "rotation": 2
    },
    {
      "x": -17,
      "y": 8,
      "z": 19,
      "name": "Rock_Shale_Brick",
      "rotation": 2
    },
    {
      "x": -17,
      "y": 9,
      "z": 19,
      "name": "Rock_Shale_Brick_Ornate"
    },
    {
      "x": -17,
      "y": 10,
      "z": 19,
      "name": "Rock_Shale_Cobble"
    },
    {
      "x": -17,
      "y": 11,
      "z": 19,
      "name": "Rock_Shale_Cobble"
    },
    {
      "x": -17,
      "y": 12,
      "z": 19,
      "name": "Rock_Shale_Cobble"
    },
    {
      "x": -17,
      "y": 13,
      "z": 19,
      "name": "Rock_Shale_Brick"
    },
    {
      "x": -17,
      "y": 14,
      "z": 19,
      "name": "Rock_Shale_Brick"
    },
    {
      "x": -17,
      "y": 15,
      "z": 19,
      "name": "Rock_Shale_Brick_Smooth"
    },
    {
      "x": -17,
      "y": 10,
      "z": 20,
      "name": "Rock_Shale_Cobble"
    },
    {
      "x": -17,
      "y": 11,
      "z": 20,
      "name": "Rock_Shale_Cobble"
    },
    {
      "x": -17,
      "y": 12,
      "z": 20,
      "name": "Rock_Shale_Cobble_Stairs"
    },
    {
      "x": -17,
      "y": 10,
      "z": 21,
      "name": "Rock_Shale_Cobble"
    },
    {
      "x": -17,
      "y": 11,
      "z": 21,
      "name": "Rock_Shale_Cobble_Stairs"
    },
    {
      "x": -16,
      "y": 10,
      "z": -21,
      "name": "Rock_Shale_Cobble"
    },
    {
      "x": -16,
      "y": 11,
      "z": -21,
      "name": "Rock_Shale_Cobble_Stairs",
