{
  "version": 8,
  "blockIdVersion": 11,
  "anchorX": 0,
  "anchorY": 0,
  "anchorZ": 0,
  "blocks": [
    {
      "x": -21,
      "y": 4,
      "z": -4,
      "name": "Rock_Shale_Cobble"
    },
    {
      "x": -21,
      "y": 5,
      "z": -4,
      "name": "Rock_Shale_Brick",
      "rotation": 1
    },
    {
      "x": -21,
      "y": 6,
      "z": -4,
      "name": "Rock_Shale_Brick",
      "rotation": 1
    },
    {
      "x": -21,
      "y": 7,
      "z": -4,
      "name": "Rock_Shale_Brick",
      "rotation": 1
    },
    {
      "x": -21,
      "y": 8,
      "z": -4,
      "name": "Rock_Shale_Brick",
      "rotation": 1
    },
    {
      "x": -21,
      "y": 9,
      "z": -4,
      "name": "Rock_Shale_Brick_Ornate",
      "rotation": 3
    },
    {
      "x": -21,
      "y": 4,
      "z": -3,
      "name": "Rock_Shale_Brick_Smooth"
    },
    {
      "x": -21,
      "y": 5,
      "z": -3,
      "name": "Rock_Shale_Brick_Smooth"
    },
    {
      "x": -21,
      "y": 6,
      "z": -3,
      "name": "Rock_Shale_Brick_Smooth"
    },
    {
      "x": -21,
      "y": 7,
      "z": -3,
      "name": "Rock_Shale_Brick_Smooth"
    },
    {
      "x": -21,
      "y": 8,
      "z": -3,
      "name": "Rock_Shale_Brick_Smooth"
    },
    {
      "x": -21,
      "y": 9,
      "z": -3,
      "name": "Rock_Shale_Brick_Ornate"
    },
    {
      "x": -21,
      "y": 4,
      "z": -2,
      "name": "Rock_Shale_Cobble"
    },
    {
      "x": -21,
      "y": 5,
      "z": -2,
      "name": "Rock_Shale_Brick",
      "rotation": 1
    },
    {
      "x": -21,
      "y": 6,
      "z": -2,
      "name": "Rock_Shale_Brick",
      "rotation": 1
    },
    {
      "x": -21,
      "y": 7,
      "z": -2,
      "name": "Rock_Shale_Brick",
      "rotation": 1
    },
    {
      "x": -21,
      "y": 8,
      "z": -2,
      "name": "Rock_Shale_Brick",
      "rotation": 1
    },
    {
      "x": -21,
      "y": 9,
      "z": -2,
      "name": "Rock_Shale_Brick_Ornate",
      "rotation": 3
    },
    {
      "x": -21,
      "y": 4,
      "z": -1,
      "name": "Rock_Shale_Cobble"
    },
    {
      "x": -21,
      "y": 5,
      "z": -1,
      "name": "Rock_Shale_Brick_Smooth"
    },
    {
      "x": -21,
      "y": 6,
      "z": -1,
      "name": "Rock_Shale_Brick_Smooth"
    },
    {
      "x": -21,
      "y": 7,
      "z": -1,
      "name": "Rock_Shale_Brick_Smooth"
    },
    {
      "x": -21,
      "y": 8,
      "z": -1,
      "name": "Rock_Shale_Brick_Smooth"
    },
    {
      "x": -21,
      "y": 9,
      "z": -1,
      "name": "Rock_Shale_Brick_Ornate"
    },
    {
      "x": -21,
      "y": 4,
      "z": 0,
      "name": "Rock_Shale_Cobble",
      "rotation": 1
    },
    {
      "x": -21,
      "y": 5,
      "z": 0,
      "name": "Rock_Shale_Brick",
      "rotation": 2
    },
    {
      "x": -21,
      "y": 6,
      "z": 0,
      "name": "Rock_Shale_Brick",
      "rotation": 2
    },
    {
      "x": -21,
      "y": 7,
      "z": 0,
      "name": "Rock_Shale_Brick",
      "rotation": 2
    },
    {
      "x": -21,
      "y": 8,
      "z": 0,
      "name": "Rock_Shale_Brick",
      "rotation": 2
    },
    {
      "x": -21,
      "y": 9,
      "z": 0,
      "name": "Rock_Shale_Brick_Ornate"
    },
    {
      "x": -21,
      "y": 4,
      "z": 1,
      "name": "Rock_Shale_Cobble",
      "rotation": 1
    },
    {
      "x": -21,
      "y": 5,
      "z": 1,
      "name": "Rock_Shale_Brick_Smooth",
      "rotation": 1
    },
    {
      "x": -21,
      "y": 6,
      "z": 1,
      "name": "Rock_Shale_Brick_Smooth",
      "rotation": 1
    },
    {
      "x": -21,
      "y": 7,
      "z": 1,
      "name": "Rock_Shale_Brick_Smooth",
      "rotation": 1
    },
    {
      "x": -21,
      "y": 8,
      "z": 1,
      "name": "Rock_Shale_Brick_Smooth",
      "rotation": 1
    },
    {
      "x": -21,
      "y": 9,
      "z": 1,
      "name": "Rock_Shale_Brick_Ornate",
      "rotation": 1
    },
    {
      "x": -21,
      "y": 4,
      "z": 2,
      "name": "Rock_Shale_Cobble",
      "rotation": 1
    },
    {
      "x": -21,
      "y": 5,
      "z": 2,
      "name": "Rock_Shale_Brick",
      "rotation": 2
    },
    {
      "x": -21,
      "y": 6,
      "z": 2,
      "name": "Rock_Shale_Brick",
      "rotation": 2
    },
    {
      "x": -21,
      "y": 7,
      "z": 2,
      "name": "Rock_Shale_Brick",
      "rotation": 2
    },
    {
      "x": -21,
      "y": 8,
      "z": 2,
      "name": "Rock_Shale_Brick",
      "rotation": 2
    },
    {
      "x": -21,
      "y": 9,
      "z": 2,
      "name": "Rock_Shale_Brick_Ornate"
    },
    {
      "x": -21,
      "y": 4,
      "z": 3,
      "name": "Rock_Shale_Brick_Smooth",
      "rotation": 1
    },
    {
      "x": -21,
      "y": 5,
      "z": 3,
      "name": "Rock_Shale_Brick_Smooth",
      "rotation": 1
    },
    {
      "x": -21,
      "y": 6,
      "z": 3,
      "name": "Rock_Shale_Brick_Smooth",
      "rotation": 1
    },
    {
      "x": -21,
      "y": 7,
      "z": 3,
      "name": "Rock_Shale_Brick_Smooth",
      "rotation": 1
    },
    {
      "x": -21,
      "y": 8,
      "z": 3,
      "name": "Rock_Shale_Brick_Smooth",
      "rotation": 1
    },
    {
      "x": -21,
      "y": 9,
      "z": 3,
      "name": "Rock_Shale_Brick_Ornate",
      "rotation": 1
    },
    {
      "x": -21,
      "y": 4,
      "z": 4,
      "name": "Rock_Shale_Cobble",
      "rotation": 1
    },
    {
      "x": -21,
      "y": 5,
      "z": 4,
      "name": "Rock_Shale_Brick",
      "rotation": 2
    },
    {
      "x": -21,
      "y": 6,
      "z": 4,
      "name": "Rock_Shale_Brick",
      "rotation": 2
    },
    {
      "x": -21,
      "y": 7,
      "z": 4,
      "name": "Rock_Shale_Brick",
      "rotation": 2
    },
    {
      "x": -21,
      "y": 8,
      "z": 4,
      "name": "Rock_Shale_Brick",
      "rotation": 2
    },
    {
      "x": -21,
      "y": 9,
      "z": 4,
      "name": "Rock_Shale_Brick_Ornate"
    },
    {
      "x": -20,
      "y": 4,
      "z": -7,
      "name": "Rock_Shale_Cobble"
    },
    {
      "x": -20,
      "y": 5,
      "z": -7,
      "name": "Rock_Shale_Brick_Smooth"
    },
    {
      "x": -20,
      "y": 6,
      "z": -7,
      "name": "Rock_Shale_Brick_Smooth"
    },
    {
      "x": -20,
      "y": 7,
      "z": -7,
      "name": "Rock_Shale_Brick_Smooth"
    },
    {
      "x": -20,
      "y": 8,
      "z": -7,
      "name": "Rock_Shale_Brick_Smooth"
    },
    {
      "x": -20,
      "y": 9,
      "z": -7,
      "name": "Rock_Shale_Brick_Ornate"
    },
    {
      "x": -20,
      "y": 4,
      "z": -6,
      "name": "Rock_Shale_Cobble"
    },
    {
      "x": -20,
      "y": 5,
      "z": -6,
      "name": "Rock_Shale_Brick",
      "rotation": 1
    },
    {
      "x": -20,
      "y": 6,
      "z": -6,
      "name": "Rock_Shale_Brick",
      "rotation": 1
    },
    {
      "x": -20,
      "y": 7,
      "z": -6,
      "name": "Rock_Shale_Brick",
      "rotation": 1
    },
    {
      "x": -20,
      "y": 8,
      "z": -6,
      "name": "Rock_Shale_Brick",
      "rotation": 1
    },
    {
      "x": -20,
      "y": 9,
      "z": -6,
      "name": "Rock_Shale_Brick_Ornate",
      "rotation": 3
    },
    {
      "x": -20,
      "y": 4,
      "z": -5,
      "name": "Rock_Shale_Cobble"
    },
    {
      "x": -20,
      "y": 5,
      "z": -5,
      "name": "Rock_Shale_Brick_Smooth"
    },
    {
      "x": -20,
      "y": 6,
      "z": -5,
      "name": "Rock_Shale_Brick_Smooth"
    },
    {
      "x": -20,
      "y": 7,
      "z": -5,
      "name": "Rock_Shale_Brick_Smooth"
    },
    {
      "x": -20,
      "y": 8,
      "z": -5,
      "name": "Rock_Shale_Brick_Smooth"
    },
    {
      "x": -20,
      "y": 9,
      "z": -5,
      "name": "Rock_Shale_Brick_Ornate"
    },
    {
      "x": -20,
      "y": 4,
      "z": -4,
      "name": "Rock_Shale_Cobble"
    },
    {
      "x": -20,
      "y": 4,
      "z": -3,
      "name": "Rock_Shale_Brick_Smooth"
    },
    {
      "x": -20,
      "y": 5,
      "z": -3,
      "name": "Rock_Shale_Brick_Pillar_Base"
    },
    {
      "x": -20,
      "y": 6,
      "z": -3,
      "name": "Rock_Shale_Brick_Pillar_Middle"
    },
    {
      "x": -20,
      "y": 7,
      "z": -3,
      "name": "Rock_Shale_Brick_Pillar_Middle"
    },
    {
      "x": -20,
      "y": 8,
      "z": -3,
      "name": "Rock_Shale_Brick_Pillar_Middle"
    },
    {
      "x": -20,
      "y": 9,
      "z": -3,
      "name": "Rock_Shale_Brick_Pillar_Base",
      "rotation": 8
    },
    {
      "x": -20,
      "y": 4,
      "z": -2,
      "name": "Rock_Shale_Cobble"
    },
    {
      "x": -20,
      "y": 4,
      "z": -1,
      "name": "Rock_Shale_Cobble"
    },
    {
      "x": -20,
      "y": 4,
      "z": 0,
      "name": "Rock_Shale_Cobble",
      "rotation": 1
    },
    {
      "x": -20,
      "y": 5,
      "z": 0,
      "name": "Rock_Shale_Brick_Pillar_Base",
      "rotation": 1
    },
    {
      "x": -20,
      "y": 6,
      "z": 0,
      "name": "Rock_Shale_Brick_Pillar_Middle",
      "rotation": 1
    },
    {
      "x": -20,
      "y": 7,
      "z": 0,
      "name": "Rock_Shale_Brick_Pillar_Middle",
      "rotation": 1
    },
    {
      "x": -20,
      "y": 8,
      "z": 0,
      "name": "Rock_Shale_Brick_Pillar_Middle",
      "rotation": 1
    },
    {
      "x": -20,
      "y": 9,
      "z": 0,
      "name": "Rock_Shale_Brick_Pillar_Base",
      "rotation": 9
    },
    {
      "x": -20,
      "y": 4,
      "z": 1,
      "name": "Rock_Shale_Cobble",
      "rotation": 1
    },
    {
      "x": -20,
      "y": 4,
      "z": 2,
      "name": "Rock_Shale_Cobble",
      "rotation": 1
    },
    {
      "x": -20,
      "y": 5,
      "z": 2,
      "name": "Rubble_Shale_Medium",
      "support": 15
    },
    {
      "x": -20,
      "y": 4,
      "z": 3,
      "name": "Rock_Shale_Brick_Smooth",
      "rotation": 1
    },
    {
      "x": -20,
      "y": 5,
      "z": 3,
      "name": "Rock_Shale_Brick_Pillar_Base",
      "rotation": 1
    },
    {
      "x": -20,
      "y": 6,
      "z": 3,
      "name": "Rock_Shale_Brick_Pillar_Middle",
      "rotation": 1
    },
    {
      "x": -20,
      "y": 7,
      "z": 3,
      "name": "Rock_Shale_Brick_Pillar_Middle",
      "rotation": 1
    },
    {
      "x": -20,
      "y": 8,
      "z": 3,
      "name": "Rock_Shale_Brick_Pillar_Middle",
      "rotation": 1
    },
    {
      "x": -20,
      "y": 9,
      "z": 3,
      "name": "Rock_Shale_Brick_Pillar_Base",
      "rotation": 9
    },
    {
      "x": -20,
      "y": 4,
      "z": 4,
      "name": "Rock_Shale_Cobble",
      "rotation": 1
    },
    {
      "x": -20,
      "y": 4,
      "z": 5,
      "name": "Rock_Shale_Cobble",
      "rotation": 1
    },
    {
      "x": -20,
      "y": 5,
      "z": 5,
      "name": "Rock_Shale_Brick_Smooth",
      "rotation": 1
    },
    {
      "x": -20,
      "y": 6,
      "z": 5,
      "name": "Rock_Shale_Brick_Smooth",
      "rotation": 1
    },
    {
      "x": -20,
      "y": 7,
      "z": 5,
      "name": "Rock_Shale_Brick_Smooth",
      "rotation": 1
    },
    {
      "x": -20,
      "y": 8,
      "z": 5,
      "name": "Rock_Shale_Brick_Smooth",
      "rotation": 1
    },
    {
      "x": -20,
      "y": 9,
      "z": 5,
      "name": "Rock_Shale_Brick_Ornate",
      "rotation": 1
    },
    {
      "x": -20,
      "y": 4,
      "z": 6,
      "name": "Rock_Shale_Cobble",
      "rotation": 1
    },
    {
      "x": -20,
      "y": 5,
      "z": 6,
      "name": "Rock_Shale_Brick",
      "rotation": 2
    },
    {
      "x": -20,
      "y": 6,
      "z": 6,
      "name": "Rock_Shale_Brick",
      "rotation": 2
    },
    {
      "x": -20,
      "y": 7,
      "z": 6,
      "name": "Rock_Shale_Brick",
      "rotation": 2
    },
    {
      "x": -20,
      "y": 8,
      "z": 6,
      "name": "Rock_Shale_Brick",
      "rotation": 2
    },
    {
      "x": -20,
      "y": 9,
      "z": 6,
      "name": "Rock_Shale_Brick_Ornate"
    },
    {
      "x": -20,
      "y": 4,
      "z": 7,
      "name": "Rock_Shale_Cobble",
      "rotation": 1
    },
    {
      "x": -20,
      "y": 5,
      "z": 7,
      "name": "Rock_Shale_Brick_Smooth",
      "rotation": 1
    },
    {
      "x": -20,
      "y": 6,
      "z": 7,
      "name": "Rock_Shale_Brick_Smooth",
      "rotation": 1
    },
    {
      "x": -20,
      "y": 7,
      "z": 7,
      "name": "Rock_Shale_Brick_Smooth",
      "rotation": 1
    },
    {
      "x": -20,
      "y": 8,
      "z": 7,
      "name": "Rock_Shale_Brick_Smooth",
      "rotation": 1
    },
    {
      "x": -20,
      "y": 9,
      "z": 7,
      "name": "Rock_Shale_Brick_Ornate",
      "rotation": 1
    },
    {
      "x": -19,
      "y": 4,
      "z": -18,
      "name": "Rock_Shale_Cobble",
      "rotation": 2
    },
    {
      "x": -19,
      "y": 5,
      "z": -18,
      "name": "Rock_Shale_Brick",
      "rotation": 1
    },
    {
      "x": -19,
      "y": 6,
      "z": -18,
      "name": "Rock_Shale_Brick",
      "rotation": 1
    },
    {
      "x": -19,
      "y": 7,
      "z": -18,
      "name": "Rock_Shale_Brick",
      "rotation": 1
    },
    {
      "x": -19,
      "y": 8,
      "z": -18,
      "name": "Rock_Shale_Brick",
      "rotation": 1
    },
    {
      "x": -19,
      "y": 9,
      "z": -18,
      "name": "Rock_Shale_Brick_Ornate",
      "rotation": 3
    },
    {
      "x": -19,
      "y": 4,
      "z": -17,
      "name": "Rock_Shale_Cobble",
      "rotation": 2
    },
    {
      "x": -19,
      "y": 5,
      "z": -17,
      "name": "Rock_Shale_Brick",
      "rotation": 1
    },
    {
      "x": -19,
      "y": 6,
      "z": -17,
      "name": "Rock_Shale_Brick",
      "rotation": 1
    },
    {
      "x": -19,
      "y": 7,
      "z": -17,
      "name": "Rock_Shale_Brick",
      "rotation": 1
    },
    {
      "x": -19,
      "y": 8,
      "z": -17,
      "name": "Rock_Shale_Brick",
      "rotation": 1
    },
    {
      "x": -19,
      "y": 9,
      "z": -17,
      "name": "Rock_Shale_Brick_Ornate",
      "rotation": 3
    },
    {
      "x": -19,
      "y": 4,
      "z": -16,
      "name": "Rock_Shale_Cobble",
      "rotation": 2
    },
    {
      "x": -19,
      "y": 5,
      "z": -16,
      "name": "Rock_Shale_Brick",
      "rotation": 1
    },
    {
      "x": -19,
      "y": 6,
      "z": -16,
      "name": "Rock_Shale_Brick",
      "rotation": 1
    },
    {
      "x": -19,
      "y": 7,
      "z": -16,
      "name": "Rock_Shale_Brick",
      "rotation": 1
    },
    {
      "x": -19,
      "y": 8,
      "z": -16,
      "name": "Rock_Shale_Brick",
      "rotation": 1
    },
    {
      "x": -19,
      "y": 9,
      "z": -16,
      "name": "Rock_Shale_Brick_Ornate",
      "rotation": 3
    },
    {
      "x": -19,
      "y": 4,
      "z": -15,
      "name": "Rock_Shale_Cobble",
      "rotation": 2
    },
    {
      "x": -19,
      "y": 5,
      "z": -15,
      "name": "Rock_Shale_Brick",
      "rotation": 1
    },
    {
      "x": -19,
      "y": 6,
      "z": -15,
      "name": "Rock_Shale_Brick",
      "rotation": 1
    },
    {
      "x": -19,
      "y": 7,
      "z": -15,
      "name": "Rock_Shale_Brick",
      "rotation": 1
    },
    {
      "x": -19,
      "y": 8,
      "z": -15,
      "name": "Rock_Shale_Brick",
      "rotation": 1
    },
    {
      "x": -19,
      "y": 9,
      "z": -15,
      "name": "Rock_Shale_Brick_Ornate",
      "rotation": 3
    },
    {
      "x": -19,
      "y": 4,
      "z": -9,
      "name": "Rock_Shale_Cobble"
    },
    {
      "x": -19,
      "y": 5,
      "z": -9,
      "name": "Rock_Shale_Brick_Smooth"
    },
    {
      "x": -19,
      "y": 6,
      "z": -9,
      "name": "Rock_Shale_Brick_Smooth"
    },
    {
      "x": -19,
      "y": 7,
      "z": -9,
      "name": "Rock_Shale_Brick_Smooth"
    },
    {
      "x": -19,
      "y": 8,
      "z": -9,
      "name": "Rock_Shale_Brick_Smooth"
    },
    {
      "x": -19,
      "y": 9,
      "z": -9,
      "name": "Rock_Shale_Brick_Ornate"
    },
    {
      "x": -19,
      "y": 4,
      "z": -8,
      "name": "Rock_Shale_Cobble"
    },
    {
      "x": -19,
      "y": 5,
      "z": -8,
      "name": "Rock_Shale_Brick",
      "rotation": 1
    },
    {
      "x": -19,
      "y": 6,
      "z": -8,
      "name": "Rock_Shale_Brick",
      "rotation": 1
    },
    {
      "x": -19,
      "y": 7,
      "z": -8,
      "name": "Rock_Shale_Brick",
      "rotation": 1
    },
    {
      "x": -19,
      "y": 8,
      "z": -8,
      "name": "Rock_Shale_Brick",
      "rotation": 1
    },
    {
      "x": -19,
      "y": 9,
      "z": -8,
      "name": "Rock_Shale_Brick_Ornate",
      "rotation": 3
    },
    {
      "x": -19,
      "y": 4,
      "z": -7,
      "name": "Rock_Shale_Cobble"
    },
    {
      "x": -19,
      "y": 5,
      "z": -7,
      "name": "Rubble_Shale",
      "support": 15
    },
    {
      "x": -19,
      "y": 8,
      "z": -7,
      "name": "Deco_SpiderWeb_Full",
      "support": 15
    },
    {
      "x": -19,
      "y": 9,
      "z": -7,
      "name": "Deco_SpiderWeb_Full",
      "support": 15
    },
    {
      "x": -19,
      "y": 4,
      "z": -6,
      "name": "Rock_Shale_Cobble"
    },
    {
      "x": -19,
      "y": 4,
      "z": -5,
      "name": "Rock_Shale_Cobble"
    },
    {
      "x": -19,
      "y": 4,
      "z": -4,
      "name": "Rock_Shale_Cobble"
    },
    {
      "x": -19,
      "y": 4,
      "z": -3,
      "name": "Rock_Shale_Brick_Smooth"
    },
    {
      "x": -19,
      "y": 4,
      "z": -2,
      "name": "Rock_Shale_Cobble"
    },
    {
      "x": -19,
      "y": 4,
      "z": -1,
      "name": "Rock_Shale_Cobble"
    },
    {
      "x": -19,
      "y": 4,
      "z": 0,
      "name": "Rock_Shale_Cobble",
      "rotation": 1
    },
    {
      "x": -19,
      "y": 4,
      "z": 1,
      "name": "Rock_Shale_Cobble",
      "rotation": 1
    },
    {
      "x": -19,
      "y": 5,
      "z": 1,
      "name": "Rubble_Shale",
      "support": 15
    },
    {
      "x": -19,
      "y": 4,
      "z": 2,
      "name": "Rock_Shale_Cobble",
      "rotation": 1
    },
    {
      "x": -19,
      "y": 4,
      "z": 3,
      "name": "Rock_Shale_Brick_Smooth",
      "rotation": 1
    },
    {
      "x": -19,
      "y": 4,
      "z": 4,
      "name": "Rock_Shale_Cobble",
      "rotation": 1
    },
    {
      "x": -19,
      "y": 4,
      "z": 5,
      "name": "Rock_Shale_Cobble",
      "rotation": 1
    },
    {
      "x": -19,
      "y": 4,
      "z": 6,
      "name": "Rock_Shale_Cobble",
      "rotation": 1
    },
    {
      "x": -19,
      "y": 4,
      "z": 7,
      "name": "Rock_Shale_Cobble",
      "rotation": 1
    },
    {
      "x": -19,
      "y": 5,
      "z": 7,
      "name": "Furniture_Temple_Light_Pot"
    },
    {
      "x": -19,
      "y": 4,
      "z": 8,
      "name": "Rock_Shale_Cobble",
      "rotation": 1
    },
    {
      "x": -19,
      "y": 5,
      "z": 8,
      "name": "Rock_Shale_Brick",
      "rotation": 2
    },
    {
      "x": -19,
      "y": 6,
      "z": 8,
      "name": "Rock_Shale_Brick",
      "rotation": 2
    },
    {
      "x": -19,
      "y": 7,
      "z": 8,
      "name": "Rock_Shale_Brick",
      "rotation": 2
    },
    {
      "x": -19,
      "y": 8,
      "z": 8,
      "name": "Rock_Shale_Brick",
      "rotation": 2
    },
    {
      "x": -19,
      "y": 9,
      "z": 8,
      "name": "Rock_Shale_Brick_Ornate"
    },
    {
      "x": -19,
      "y": 4,
      "z": 9,
      "name": "Rock_Shale_Cobble",
      "rotation": 1
    },
    {
      "x": -19,
      "y": 5,
      "z": 9,
      "name": "Rock_Shale_Brick_Smooth",
      "rotation": 1
    },
    {
      "x": -19,
      "y": 6,
      "z": 9,
      "name": "Rock_Shale_Brick_Smooth",
      "rotation": 1
    },
    {
      "x": -19,
      "y": 7,
      "z": 9,
      "name": "Rock_Shale_Brick_Smooth",
      "rotation": 1
    },
    {
      "x": -19,
      "y": 8,
      "z": 9,
      "name": "Rock_Shale_Brick_Smooth",
      "rotation": 1
    },
    {
      "x": -19,
      "y": 9,
      "z": 9,
      "name": "Rock_Shale_Brick_Ornate",
      "rotation": 1
    },
    {
      "x": -19,
      "y": 4,
      "z": 15,
      "name": "Rock_Shale_Cobble",
      "rotation": 3
    },
    {
      "x": -19,
      "y": 5,
      "z": 15,
      "name": "Rock_Shale_Brick",
      "rotation": 2
    },
    {
      "x": -19,
      "y": 6,
      "z": 15,
      "name": "Rock_Shale_Brick",
      "rotation": 2
    },
    {
      "x": -19,
      "y": 7,
      "z": 15,
      "name": "Rock_Shale_Brick",
      "rotation": 2
    },
    {
      "x": -19,
      "y": 8,
      "z": 15,
      "name": "Rock_Shale_Brick",
      "rotation": 2
    },
    {
      "x": -19,
      "y": 9,
      "z": 15,
      "name": "Rock_Shale_Brick_Ornate"
    },
    {
      "x": -19,
      "y": 4,
      "z": 16,
      "name": "Rock_Shale_Cobble",
      "rotation": 3
    },
    {
      "x": -19,
      "y": 5,
      "z": 16,
      "name": "Rock_Shale_Brick",
      "rotation": 2
    },
    {
      "x": -19,
      "y": 6,
      "z": 16,
      "name": "Rock_Shale_Brick",
      "rotation": 2
    },
    {
      "x": -19,
      "y": 7,
      "z": 16,
      "name": "Rock_Shale_Brick",
      "rotation": 2
    },
    {
      "x": -19,
      "y": 8,
      "z": 16,
      "name": "Rock_Shale_Brick",
      "rotation": 2
    },
    {
      "x": -19,
      "y": 9,
      "z": 16,
      "name": "Rock_Shale_Brick_Ornate"
    },
    {
      "x": -19,
      "y": 4,
      "z": 17,
      "name": "Rock_Shale_Cobble",
      "rotation": 3
    },
    {
      "x": -19,
      "y": 5,
      "z": 17,
      "name": "Rock_Shale_Brick",
      "rotation": 2
    },
    {
      "x": -19,
      "y": 6,
      "z": 17,
      "name": "Rock_Shale_Brick",
      "rotation": 2
    },
    {
      "x": -19,
      "y": 7,
      "z": 17,
      "name": "Rock_Shale_Brick",
      "rotation": 2
    },
    {
      "x": -19,
      "y": 8,
      "z": 17,
      "name": "Rock_Shale_Brick",
      "rotation": 2
    },
    {
      "x": -19,
      "y": 9,
      "z": 17,
      "name": "Rock_Shale_Brick_Ornate"
    },
    {
      "x": -19,
      "y": 4,
      "z": 18,
      "name": "Rock_Shale_Cobble",
      "rotation": 3
    },
    {
      "x": -19,
      "y": 5,
      "z": 18,
      "name": "Rock_Shale_Brick",
      "rotation": 2
    },
    {
      "x": -19,
      "y": 6,
      "z": 18,
      "name": "Rock_Shale_Brick",
      "rotation": 2
    },
    {
      "x": -19,
      "y": 7,
      "z": 18,
      "name": "Rock_Shale_Brick",
      "rotation": 2
    },
    {
      "x": -19,
      "y": 8,
      "z": 18,
      "name": "Rock_Shale_Brick",
      "rotation": 2
    },
    {
      "x": -19,
      "y": 9,
      "z": 18,
      "name": "Rock_Shale_Brick_Ornate"
    },
    {
      "x": -18,
      "y": 4,
      "z": -19,
      "name": "Rock_Shale_Cobble",
      "rotation": 2
    },
    {
      "x": -18,
      "y": 5,
      "z": -19,
      "name": "Rock_Shale_Brick",
      "rotation": 1
    },
    {
      "x": -18,
      "y": 6,
      "z": -19,
      "name": "Rock_Shale_Brick",
      "rotation": 1
    },
    {
      "x": -18,
      "y": 7,
      "z": -19,
      "name": "Rock_Shale_Brick",
      "rotation": 1
    },
    {
      "x": -18,
      "y": 8,
      "z": -19,
      "name": "Rock_Shale_Brick",
      "rotation": 1
    },
    {
      "x": -18,
      "y": 9,
      "z": -19,
      "name": "Rock_Shale_Brick_Ornate",
      "rotation": 3
    },
    {
      "x": -18,
      "y": 4,
      "z": -18,
      "name": "Rock_Shale_Cobble",
      "rotation": 2
    },
    {
      "x": -18,
      "y": 5,
      "z": -18,
      "name": "Rubble_Shale_Medium",
      "support": 15
    },
    {
      "x": -18,
      "y": 4,
      "z": -17,
      "name": "Rock_Shale_Cobble",
      "rotation": 2
    },
    {
      "x": -18,
      "y": 5,
      "z": -17,
      "name": "*Furniture_SK_AEA_Monument_Coffin_State_Definitions_Open",
      "filler": 992,
      "rotation": 1
    },
    {
      "x": -18,
      "y": 4,
      "z": -16,
      "name": "Rock_Shale_Cobble",
      "rotation": 2
    },
    {
      "x": -18,
      "y": 5,
      "z": -16,
      "name": "*Furniture_SK_AEA_Monument_Coffin_State_Definitions_Open",
      "rotation": 1
    },
    {
      "x": -18,
      "y": 4,
      "z": -15,
      "name": "Rock_Shale_Cobble",
      "rotation": 2
    },
    {
      "x": -18,
      "y": 4,
      "z": -14,
      "name": "Rock_Shale_Cobble",
      "rotation": 2
    },
    {
      "x": -18,
      "y": 5,
      "z": -14,
      "name": "Rock_Shale_Brick",
      "rotation": 1
    },
    {
      "x": -18,
      "y": 6,
      "z": -14,
      "name": "Rock_Shale_Brick",
      "rotation": 1
    },
    {
      "x": -18,
      "y": 7,
      "z": -14,
      "name": "Rock_Shale_Brick",
      "rotation": 1
    },
    {
      "x": -18,
      "y": 8,
      "z": -14,
      "name": "Rock_Shale_Brick",
      "rotation": 1
    },
    {
      "x": -18,
      "y": 9,
      "z": -14,
      "name": "Rock_Shale_Brick_Ornate",
      "rotation": 3
    },
    {
      "x": -18,
      "y": 4,
      "z": -11,
      "name": "Rock_Shale_Cobble"
    },
    {
      "x": -18,
      "y": 5,
      "z": -11,
      "name": "Rock_Shale_Brick_Smooth"
    },
    {
      "x": -18,
      "y": 6,
      "z": -11,
      "name": "Rock_Shale_Brick_Smooth"
    },
    {
      "x": -18,
      "y": 7,
      "z": -11,
      "name": "Rock_Shale_Brick_Smooth"
    },
    {
      "x": -18,
      "y": 8,
      "z": -11,
      "name": "Rock_Shale_Brick_Smooth"
    },
    {
      "x": -18,
      "y": 9,
      "z": -11,
      "name": "Rock_Shale_Brick_Ornate"
    },
    {
      "x": -18,
      "y": 4,
      "z": -10,
      "name": "Rock_Shale_Cobble"
    },
    {
      "x": -18,
      "y": 5,
      "z": -10,
      "name": "Rock_Shale_Brick",
      "rotation": 1
    },
    {
      "x": -18,
      "y": 6,
      "z": -10,
      "name": "Rock_Shale_Brick",
      "rotation": 1
    },
    {
      "x": -18,
      "y": 7,
      "z": -10,
      "name": "Rock_Shale_Brick",
      "rotation": 1
    },
    {
      "x": -18,
      "y": 8,
      "z": -10,
      "name": "Rock_Shale_Brick",
      "rotation": 1
    },
    {
      "x": -18,
      "y": 9,
      "z": -10,
      "name": "Rock_Shale_Brick_Ornate",
      "rotation": 3
    },
    {
      "x": -18,
      "y": 4,
      "z": -9,
      "name": "Rock_Shale_Cobble"
    },
    {
      "x": -18,
      "y": 9,
      "z": -9,
      "name": "Deco_SpiderWeb_Full",
      "support": 15
    },
    {
      "x": -18,
      "y": 4,
      "z": -8,
      "name": "Rock_Shale_Cobble"
    },
    {
      "x": -18,
      "y": 4,
      "z": -7,
      "name": "Rock_Shale_Cobble"
    },
    {
      "x": -18,
      "y": 4,
      "z": -6,
      "name": "Rock_Shale_Cobble"
    },
    {
      "x": -18,
      "y": 4,
      "z": -5,
      "name": "Rock_Shale_Cobble"
    },
    {
      "x": -18,
      "y": 4,
      "z": -4,
      "name": "Rock_Shale_Cobble"
    },
    {
      "x": -18,
      "y": 4,
      "z": -3,
      "name": "Rock_Shale_Brick_Smooth"
    },
    {
      "x": -18,
      "y": 4,
      "z": -2,
      "name": "Rock_Shale_Cobble"
    },
    {
      "x": -18,
      "y": 4,
      "z": -1,
      "name": "Rock_Shale_Cobble"
    },
    {
      "x": -18,
      "y": 4,
      "z": 0,
      "name": "Rock_Shale_Cobble",
      "rotation": 1
    },
    {
      "x": -18,
      "y": 4,
      "z": 1,
      "name": "Rock_Shale_Cobble",
      "rotation": 1
    },
    {
      "x": -18,
      "y": 4,
      "z": 2,
      "name": "Rock_Shale_Cobble",
      "rotation": 1
    },
    {
      "x": -18,
      "y": 4,
      "z": 3,
      "name": "Rock_Shale_Brick_Smooth",
      "rotation": 1
    },
    {
      "x": -18,
      "y": 4,
      "z": 4,
      "name": "Rock_Shale_Cobble",
      "rotation": 1
    },
    {
      "x": -18,
      "y": 4,
      "z": 5,
      "name": "Rock_Shale_Cobble",
      "rotation": 1
    },
    {
      "x": -18,
      "y": 4,
      "z": 6,
      "name": "Rock_Shale_Cobble",
      "rotation": 1
    },
    {
      "x": -18,
      "y": 4,
      "z": 7,
      "name": "Rock_Shale_Cobble",
      "rotation": 1
    },
    {
      "x": -18,
      "y": 4,
      "z": 8,
      "name": "Rock_Shale_Cobble",
      "rotation": 1
    },
    {
      "x": -18,
      "y": 4,
      "z": 9,
      "name": "Rock_Shale_Cobble",
      "rotation": 1
    },
    {
      "x": -18,
      "y": 4,
      "z": 10,
      "name": "Rock_Shale_Cobble",
      "rotation": 1
    },
    {
      "x": -18,
      "y": 5,
      "z": 10,
      "name": "Rock_Shale_Brick",
      "rotation": 2
    },
    {
      "x": -18,
      "y": 6,
      "z": 10,
      "name": "Rock_Shale_Brick",
      "rotation": 2
    },
    {
      "x": -18,
      "y": 7,
      "z": 10,
      "name": "Rock_Shale_Brick",
      "rotation": 2
    },
    {
      "x": -18,
      "y": 8,
      "z": 10,
      "name": "Rock_Shale_Brick",
      "rotation": 2
    },
    {
      "x": -18,
      "y": 9,
      "z": 10,
      "name": "Rock_Shale_Brick_Ornate"
    },
    {
      "x": -18,
      "y": 4,
      "z": 11,
      "name": "Rock_Shale_Cobble",
      "rotation": 1
    },
    {
      "x": -18,
      "y": 5,
      "z": 11,
      "name": "Rock_Shale_Brick_Smooth",
      "rotation": 1
    },
    {
      "x": -18,
      "y": 6,
      "z": 11,
      "name": "Rock_Shale_Brick_Smooth",
      "rotation": 1
    },
    {
      "x": -18,
      "y": 7,
      "z": 11,
      "name": "Rock_Shale_Brick_Smooth",
      "rotation": 1
    },
    {
      "x": -18,
      "y": 8,
      "z": 11,
      "name": "Rock_Shale_Brick_Smooth",
      "rotation": 1
    },
    {
      "x": -18,
      "y": 9,
      "z": 11,
      "name": "Rock_Shale_Brick_Ornate",
      "rotation": 1
    },
    {
      "x": -18,
      "y": 4,
      "z": 14,
      "name": "Rock_Shale_Cobble",
      "rotation": 3
    },
    {
      "x": -18,
      "y": 5,
      "z": 14,
      "name": "Rock_Shale_Brick",
      "rotation": 2
    },
    {
      "x": -18,
      "y": 6,
      "z": 14,
      "name": "Rock_Shale_Brick",
      "rotation": 2
    },
    {
      "x": -18,
      "y": 7,
      "z": 14,
      "name": "Rock_Shale_Brick",
      "rotation": 2
    },
    {
      "x": -18,
      "y": 8,
      "z": 14,
      "name": "Rock_Shale_Brick",
      "rotation": 2
    },
    {
      "x": -18,
      "y": 9,
      "z": 14,
      "name": "Rock_Shale_Brick_Ornate"
    },
    {
      "x": -18,
      "y": 4,
      "z": 15,
      "name": "Rock_Shale_Cobble",
      "rotation": 3
    },
    {
      "x": -18,
      "y": 5,
      "z": 15,
      "name": "Rubble_Shale_Medium",
      "support": 15
    },
    {
      "x": -18,
      "y": 4,
      "z": 16,
      "name": "Rock_Shale_Cobble",
      "rotation": 3
    },
    {
      "x": -18,
      "y": 4,
      "z": 17,
      "name": "Rock_Shale_Cobble",
      "rotation": 3
    },
    {
      "x": -18,
      "y": 4,
      "z": 18,
      "name": "Rock_Shale_Cobble",
      "rotation": 3
    },
    {
      "x": -18,
      "y": 4,
      "z": 19,
      "name": "Rock_Shale_Cobble",
      "rotation": 3
    },
    {
      "x": -18,
      "y": 5,
      "z": 19,
      "name": "Rock_Shale_Brick",
      "rotation": 2
    },
    {
      "x": -18,
      "y": 6,
      "z": 19,
      "name": "Rock_Shale_Brick",
      "rotation": 2
    },
    {
      "x": -18,
      "y": 7,
      "z": 19,
      "name": "Rock_Shale_Brick",
      "rotation": 2
    },
    {
      "x": -18,
      "y": 8,
      "z": 19,
      "name": "Rock_Shale_Brick",
      "rotation": 2
    },
    {
      "x": -18,
      "y": 9,
      "z": 19,
      "name": "Rock_Shale_Brick_Ornate"
    },
    {
      "x": -17,
      "y": 4,
      "z": -19,
      "name": "Rock_Shale_Cobble",
      "rotation": 2
    },
    {
      "x": -17,
      "y": 5,
      "z": -19,
      "name": "Rock_Shale_Brick",
      "rotation": 1
    },
    {
      "x": -17,
      "y": 6,
      "z": -19,
      "name": "Rock_Shale_Brick",
      "rotation": 1
    },
    {
      "x": -17,
      "y": 7,
      "z": -19,
      "name": "Rock_Shale_Brick",
      "rotation": 1
    },
    {
      "x": -17,
      "y": 8,
      "z": -19,
      "name": "Rock_Shale_Brick",
      "rotation": 1
    },
    {
      "x": -17,
      "y": 9,
      "z": -19,
      "name": "Rock_Shale_Brick_Ornate",
      "rotation": 3
    },
    {
      "x": -17,
      "y": 4,
      "z": -18,
      "name": "Rock_Shale_Cobble",
      "rotation": 2
    },
    {
      "x": -17,
      "y": 5,
      "z": -18,
      "name": "Rubble_Shale",
      "support": 15
    },
    {
      "x": -17,
      "y": 4,
      "z": -17,
      "name": "Rock_Shale_Cobble",
      "rotation": 2
    },
    {
      "x": -17,
      "y": 4,
      "z": -16,
      "name": "Rock_Shale_Cobble",
      "rotation": 2
    },
    {
      "x": -17,
      "y": 4,
      "z": -15,
      "name": "Rock_Shale_Cobble",
      "rotation": 2
    },
    {
      "x": -17,
      "y": 5,
      "z": -15,
      "name": "Rubble_Shale",
      "support": 15
    },
    {
      "x": -17,
      "y": 4,
      "z": -14,
      "name": "Rock_Shale_Cobble",
      "rotation": 2
    },
    {
      "x": -17,
      "y": 9,
      "z": -14,
      "name": "Deco_SpiderWeb_Full",
      "rotation": 2
    },
    {
      "x": -17,
      "y": 4,
      "z": -13,
      "name": "Rock_Shale_Cobble",
      "rotation": 2
    },
    {
      "x": -17,
      "y": 5,
      "z": -13,
      "name": "Rock_Shale_Brick",
      "rotation": 1
    },
    {
      "x": -17,
      "y": 6,
      "z": -13,
      "name": "Rock_Shale_Brick",
      "rotation": 1
    },
    {
      "x": -17,
      "y": 7,
      "z": -13,
      "name": "Rock_Shale_Brick",
      "rotation": 1
    },
    {
      "x": -17,
      "y": 8,
      "z": -13,
      "name": "Rock_Shale_Brick",
      "rotation": 1
    },
    {
      "x": -17,
      "y": 9,
      "z": -13,
      "name": "Rock_Shale_Brick_Ornate",
      "rotation": 3
    },
    {
      "x": -17,
      "y": 4,
      "z": -12,
      "name": "Rock_Shale_Brick_Smooth"
    },
    {
      "x": -17,
      "y": 5,
      "z": -12,
      "name": "Rock_Shale_Brick_Smooth"
    },
    {
      "x": -17,
      "y": 6,
      "z": -12,
      "name": "Rock_Shale_Brick_Smooth"
    },
    {
      "x": -17,
      "y": 7,
      "z": -12,
      "name": "Rock_Shale_Brick_Smooth"
    },
    {
      "x": -17,
      "y": 8,
      "z": -12,
      "name": "Rock_Shale_Brick_Smooth"
    },
    {
      "x": -17,
      "y": 9,
      "z": -12,
      "name": "Rock_Shale_Brick_Ornate"
    },
    {
      "x": -17,
      "y": 4,
      "z": -11,
      "name": "Rock_Shale_Brick_Smooth"
    },
    {
      "x": -17,
      "y": 5,
      "z": -11,
      "name": "Rock_Shale_Brick_Pillar_Base"
    },
    {
      "x": -17,
      "y": 6,
      "z": -11,
      "name": "Rock_Shale_Brick_Pillar_Middle"
    },
    {
      "x": -17,
      "y": 7,
      "z": -11,
      "name": "Rock_Shale_Brick_Pillar_Middle"
    },
    {
      "x": -17,
      "y": 8,
      "z": -11,
      "name": "Rock_Shale_Brick_Pillar_Middle"
    },
    {
      "x": -17,
      "y": 9,
      "z": -11,
      "name": "Rock_Shale_Brick_Pillar_Base",
      "rotation": 8
    },
    {
      "x": -17,
      "y": 4,
      "z": -10,
      "name": "Rock_Shale_Brick_Smooth"
    },
    {
      "x": -17,
      "y": 4,
      "z": -9,
      "name": "Rock_Shale_Brick_Smooth"
    },
    {
      "x": -17,
      "y": 4,
      "z": -8,
      "name": "Rock_Shale_Brick_Smooth"
    },
    {
      "x": -17,
      "y": 4,
      "z": -7,
      "name": "Rock_Shale_Brick_Smooth"
    },
    {
      "x": -17,
      "y": 4,
      "z": -6,
      "name": "Rock_Shale_Brick_Smooth"
    },
    {
      "x": -17,
      "y": 4,
      "z": -5,
      "name": "Rock_Shale_Cobble"
    },
    {
      "x": -17,
      "y": 4,
      "z": -4,
      "name": "Rock_Shale_Cobble"
    },
    {
      "x": -17,
      "y": 4,
      "z": -3,
      "name": "Rock_Shale_Brick_Smooth"
    },
    {
      "x": -17,
      "y": 4,
      "z": -2,
      "name": "Rock_Shale_Cobble"
    },
    {
      "x": -17,
      "y": 4,
      "z": -1,
      "name": "Rock_Shale_Cobble"
    },
    {
      "x": -17,
      "y": 4,
      "z": 0,
      "name": "Rock_Shale_Cobble",
      "rotation": 1
    },
    {
      "x": -17,
      "y": 4,
      "z": 1,
      "name": "Rock_Shale_Cobble",
      "rotation": 1
    },
    {
      "x": -17,
      "y": 4,
      "z": 2,
      "name": "Rock_Shale_Cobble",
      "rotation": 1
    },
    {
      "x": -17,
      "y": 4,
      "z": 3,
      "name": "Rock_Shale_Brick_Smooth",
      "rotation": 1
    },
    {
      "x": -17,
      "y": 4,
      "z": 4,
      "name": "Rock_Shale_Cobble",
      "rotation": 1
    },
    {
      "x": -17,
      "y": 4,
      "z": 5,
      "name": "Rock_Shale_Cobble",
      "rotation": 1
    },
    {
      "x": -17,
      "y": 4,
      "z": 6,
      "name": "Rock_Shale_Brick_Smooth",
      "rotation": 1
    },
    {
      "x": -17,
      "y": 4,
      "z": 7,
      "name": "Rock_Shale_Brick_Smooth",
      "rotation": 1
    },
    {
      "x": -17,
      "y": 4,
      "z": 8,
      "name": "Rock_Shale_Brick_Smooth",
      "rotation": 1
    },
    {
      "x": -17,
      "y": 4,
      "z": 9,
      "name": "Rock_Shale_Brick_Smooth",
      "rotation": 1
    },
    {
      "x": -17,
      "y": 4,
      "z": 10,
      "name": "Rock_Shale_Brick_Smooth",
      "rotation": 1
    },
    {
      "x": -17,
      "y": 5,
      "z": 10,
      "name": "Rubble_Shale",
      "support": 15
    },
    {
      "x": -17,
      "y": 4,
      "z": 11,
      "name": "Rock_Shale_Brick_Smooth",
      "rotation": 1
    },
    {
      "x": -17,
      "y": 5,
      "z": 11,
      "name": "Rock_Shale_Brick_Pillar_Base",
      "rotation": 1
    },
    {
      "x": -17,
      "y": 6,
      "z": 11,
      "name": "Rock_Shale_Brick_Pillar_Middle",
      "rotation": 1
    },
    {
      "x": -17,
      "y": 7,
      "z": 11,
      "name": "Rock_Shale_Brick_Pillar_Middle",
      "rotation": 1
    },
    {
      "x": -17,
      "y": 8,
      "z": 11,
      "name": "Rock_Shale_Brick_Pillar_Middle",
      "rotation": 1
    },
    {
      "x": -17,
      "y": 9,
      "z": 11,
      "name": "Rock_Shale_Brick_Pillar_Base",
      "rotation": 9
    },
    {
      "x": -17,
      "y": 4,
      "z": 12,
      "name": "Rock_Shale_Brick_Smooth",
      "rotation": 1
    },
    {
      "x": -17,
      "y": 5,
      "z": 12,
      "name": "Rock_Shale_Brick_Smooth",
      "rotation": 1
    },
    {
      "x": -17,
      "y": 6,
      "z": 12,
      "name": "Rock_Shale_Brick_Smooth",
      "rotation": 1
    },
    {
      "x": -17,
      "y": 7,
      "z": 12,
      "name": "Rock_Shale_Brick_Smooth",
      "rotation": 1
    },
    {
      "x": -17,
      "y": 8,
      "z": 12,
      "name": "Rock_Shale_Brick_Smooth",
      "rotation": 1
    },
    {
      "x": -17,
      "y": 9,
      "z": 12,
      "name": "Rock_Shale_Brick_Ornate",
      "rotation": 1
    },
    {
      "x": -17,
      "y": 4,
      "z": 13,
      "name": "Rock_Shale_Cobble",
      "rotation": 3
    },
    {
      "x": -17,
      "y": 5,
      "z": 13,
      "name": "Rock_Shale_Brick",
      "rotation": 2
    },
    {
      "x": -17,
      "y": 6,
      "z": 13,
      "name": "Rock_Shale_Brick",
      "rotation": 2
    },
    {
      "x": -17,
      "y": 7,
      "z": 13,
      "name": "Rock_Shale_Brick",
      "rotation": 2
    },
    {
      "x": -17,
      "y": 8,
      "z": 13,
      "name": "Rock_Shale_Brick",
      "rotation": 2
    },
    {
      "x": -17,
      "y": 9,
      "z": 13,
      "name": "Rock_Shale_Brick_Ornate"
    },
    {
      "x": -17,
      "y": 4,
      "z": 14,
      "name": "Rock_Shale_Cobble",
      "rotation": 3
    },
    {
      "x": -17,
      "y": 5,
      "z": 14,
      "name": "Rubble_Shale_Medium",
      "support": 15
    },
    {
      "x": -17,
      "y": 4,
      "z": 15,
      "name": "Rock_Shale_Cobble",
      "rotation": 3
    },
    {
      "x": -17,
      "y": 4,
      "z": 16,
      "name": "Rock_Shale_Cobble",
      "rotation": 3
    },
    {
      "x": -17,
      "y": 4,
      "z": 17,
      "name": "Rock_Shale_Cobble",
      "rotation": 3
    },
    {
      "x": -17,
      "y": 4,
      "z": 18,
      "name": "Rock_Shale_Cobble",
      "rotation": 3
    },
    {
      "x": -17,
      "y": 5,
      "z": 18,
      "name": "*Furniture_SK_Monument_Loot_Coffin_State_Definitions_CloseWindow",
      "filler": 31,
      "rotation": 2
    },
    {
      "x": -17,
      "y": 4,
      "z": 19,
      "name": "Rock_Shale_Cobble",
      "rotation": 3
    },
    {
      "x": -17,
      "y": 5,
      "z": 19,
      "name": "Rock_Shale_Brick",
      "rotation": 2
    },
    {
      "x": -17,
      "y": 6,
      "z": 19,
      "name": "Rock_Shale_Brick",
      "rotation": 2
    },
    {
      "x": -17,
      "y": 7,
      "z": 19,
      "name": "Rock_Shale_Brick",
      "rotation": 2
    },
    {
      "x": -17,
      "y": 8,
      "z": 19,
      "name": "Rock_Shale_Brick",
      "rotation": 2
    },
    {
      "x": -17,
      "y": 9,
      "z": 19,
      "name": "Rock_Shale_Brick_Ornate"
    },
    {
      "x": -16,
      "y": 4,
      "z": -19,
      "name": "Rock_Shale_Cobble",
      "rotation": 2
    },
    {
      "x": -16,
      "y": 5,
      "z": -19,
      "name": "Rock_Shale_Brick",
      "rotation": 1
    },
    {
      "x": -16,
      "y": 6,
      "z": -19,
      "name": "Rock_Shale_Brick",
      "rotation": 1
    },
    {
      "x": -16,
      "y": 7,
      "z": -19,
      "name": "Rock_Shale_Brick",
      "rotation": 1
    },
    {
      "x": -16,
      "y": 8,
      "z": -19,
      "name": "Rock_Shale_Brick",
      "rotation": 1
    },
    {
      "x": -16,
      "y": 9,
      "z": -19,
      "name": "Rock_Shale_Brick_Ornate",
      "rotation": 3
    },
    {
      "x": -16,
      "y": 4,
      "z": -18,
      "name": "Rock_Shale_Cobble",
      "rotation": 2
    },
    {
      "x": -16,
      "y": 4,
      "z": -17,
      "name": "Rock_Shale_Cobble",
      "rotation": 2
    },
    {
      "x": -16,
      "y": 4,
      "z": -16,
      "name": "Rock_Shale_Cobble",
      "rotation": 2
    },
    {
      "x": -16,
      "y": 4,
      "z": -15,
      "name": "Rock_Shale_Cobble",
      "rotation": 2
    },
    {
      "x": -16,
      "y": 4,
      "z": -14,
      "name": "Rock_Shale_Cobble",
      "rotation": 2
    },
    {
      "x": -16,
      "y": 5,
      "z": -14,
      "name": "Furniture_Temple_Light_Pot"
    },
    {
      "x": -16,
      "y": 4,
      "z": -13,
      "name": "Rock_Shale_Cobble"
    },
    {
      "x": -16,
      "y": 5,
      "z": -13,
      "name": "Rock_Shale_Brick",
      "rotation": 1
    },
    {
      "x": -16,
      "y": 6,
      "z": -13,
      "name": "Rock_Shale_Brick",
      "rotation": 1
    },
    {
      "x": -16,
      "y": 7,
      "z": -13,
      "name": "Rock_Shale_Brick",
      "rotation": 1
    },
    {
      "x": -16,
      "y": 8,
      "z": -13,
      "name": "Rock_Shale_Brick",
      "rotation": 1
    },
    {
      "x": -16,
      "y": 9,
      "z": -13,
      "name": "Rock_Shale_Brick_Ornate",
      "rotation": 3
    },
    {
      "x": -16,
      "y": 4,
      "z": -12,
      "name": "Rock_Shale_Cobble"
    },
    {
      "x": -16,
      "y": 4,
      "z": -11,
      "name": "Rock_Shale_Cobble"
    },
    {
      "x": -16,
      "y": 4,
      "z": -10,
      "name": "Rock_Shale_Cobble"
    },
    {
      "x": -16,
      "y": 4,
      "z": -9,
      "name": "Rock_Shale_Cobble"
    },
    {
      "x": -16,
      "y": 4,
      "z": -8,
      "name": "Rock_Shale_Cobble"
    },
    {
      "x": -16,
      "y": 4,
      "z": -7,
      "name": "Rock_Shale_Cobble"
    },
    {
      "x": -16,
      "y": 4,
      "z": -6,
      "name": "Rock_Shale_Brick_Smooth"
    },
    {
      "x": -16,
      "y": 4,
      "z": -5,
      "name": "Rock_Shale_Brick_Smooth"
    },
    {
      "x": -16,
      "y": 4,
      "z": -4,
      "name": "Rock_Shale_Cobble"
    },
    {
      "x": -16,
      "y": 4,
      "z": -3,
      "name": "Rock_Shale_Brick_Smooth"
    },
    {
      "x": -16,
      "y": 4,
      "z": -2,
      "name": "Rock_Shale_Cobble"
    },
    {
      "x": -16,
      "y": 4,
      "z": -1,
      "name": "Rock_Shale_Cobble"
    },
    {
      "x": -16,
      "y": 4,
      "z": 0,
      "name": "Rock_Shale_Cobble",
      "rotation": 1
    },
    {
      "x": -16,
      "y": 4,
      "z": 1,
      "name": "Rock_Shale_Cobble",
      "rotation": 1
    },
    {
      "x": -16,
      "y": 4,
      "z": 2,
      "name": "Rock_Shale_Cobble",
      "rotation": 1
    },
    {
      "x": -16,
      "y": 4,
      "z": 3,
      "name": "Rock_Shale_Brick_Smooth",
      "rotation": 1
    },
    {
      "x": -16,
      "y": 4,
      "z": 4,
      "name": "Rock_Shale_Cobble",
      "rotation": 1
    },
    {
      "x": -16,
      "y": 4,
      "z": 5,
      "name": "Rock_Shale_Brick_Smooth",
      "rotation": 1
    },
    {
      "x": -16,
      "y": 4,
      "z": 6,
      "name": "Rock_Shale_Brick_Smooth",
      "rotation": 1
    },
    {
      "x": -16,
      "y": 4,
      "z": 7,
      "name": "Rock_Shale_Cobble",
      "rotation": 1
    },
    {
      "x": -16,
      "y": 4,
      "z": 8,
      "name": "Rock_Shale_Cobble",
      "rotation": 1
    },
    {
      "x": -16,
      "y": 4,
      "z": 9,
      "name": "Rock_Shale_Cobble",
      "rotation": 1
    },
    {
      "x": -16,
      "y": 4,
      "z": 10,
      "name": "Rock_Shale_Cobble",
      "rotation": 1
    },
    {
      "x": -16,
      "y": 4,
      "z": 11,
      "name": "Rock_Shale_Cobble",
      "rotation": 1
    },
    {
      "x": -16,
      "y": 4,
      "z": 12,
      "name": "Rock_Shale_Cobble",
      "rotation": 1
    },
    {
      "x": -16,
      "y": 4,
      "z": 13,
      "name": "Rock_Shale_Cobble",
      "rotation": 1
    },
    {
      "x": -16,
      "y": 5,
      "z": 13,
      "name": "Rock_Shale_Brick",
      "rotation": 2
    },
    {
      "x": -16,
      "y": 6,
      "z": 13,
      "name": "Rock_Shale_Brick",
      "rotation": 2
    },
    {
      "x": -16,
      "y": 7,
      "z": 13,
      "name": "Rock_Shale_Brick",
      "rotation": 2
    },
    {
      "x": -16,
      "y": 8,
      "z": 13,
      "name": "Rock_Shale_Brick",
      "rotation": 2
    },
    {
      "x": -16,
      "y": 9,
      "z": 13,
      "name": "Rock_Shale_Brick_Ornate"
    },
    {
      "x": -16,
      "y": 4,
      "z": 14,
      "name": "Rock_Shale_Cobble",
      "rotation": 3
    },
    {
      "x": -16,
      "y": 9,
      "z": 14,
      "name": "Deco_SpiderWeb_Full",
      "rotation": 3
    },
    {
      "x": -16,
      "y": 4,
      "z": 15,
      "name": "Rock_Shale_Cobble",
      "rotation": 3
    },
    {
      "x": -16,
      "y": 4,
      "z": 16,
      "name": "Rock_Shale_Cobble",
      "rotation": 3
    },
    {
      "x": -16,
      "y": 5,
      "z": 16,
      "name": "Rubble_Shale",
      "support": 15
    },
    {
      "x": -16,
      "y": 4,
      "z": 17,
      "name": "Rock_Shale_Cobble",
      "rotation": 3
    },
    {
      "x": -16,
      "y": 4,
      "z": 18,
      "name": "Rock_Shale_Cobble",
      "rotation": 3
    },
    {
      "x": -16,
      "y": 5,
      "z": 18,
      "name": "*Furniture_SK_Monument_Loot_Coffin_State_Definitions_CloseWindow",
      "components": {
        "Components": {
          "ItemContainerBlock": {
            "ItemContainer": {
              "Capacity": 18,
              "Items": {
                "3": {
                  "Id": "Ingredient_Hide_Light",
                  "Quantity": 2,
                  "Durability": 0.0,
                  "MaxDurability": 0.0,
                  "OverrideDroppedItemAnimation": false
                },
                "2": {
                  "Id": "Ore_Copper",
                  "Quantity": 3,
                  "Durability": 0.0,
                  "MaxDurability": 0.0,
                  "OverrideDroppedItemAnimation": false
                },
                "6": {
                  "Id": "Tool_Pickaxe_Crude",
                  "Quantity": 1,
                  "Durability": 150.0,
                  "MaxDurability": 150.0,
                  "OverrideDroppedItemAnimation": false
                },
                "15": {
                  "Id": "Wood_Aspen_Trunk",
                  "Quantity": 6,
                  "Durability": 0.0,
                  "MaxDurability": 0.0,
                  "OverrideDroppedItemAnimation": false
                },
                "5": {
                  "Id": "Ingredient_Fabric_Scrap_Linen",
                  "Quantity": 1,
                  "Durability": 0.0,
                  "MaxDurability": 0.0,
                  "OverrideDroppedItemAnimation": false
                },
                "16": {
                  "Id": "Plant_Seeds_Lettuce",
                  "Quantity": 1,
                  "Durability": 0.0,
                  "MaxDurability": 0.0,
                  "OverrideDroppedItemAnimation": false
                },
                "17": {
                  "Id": "Ingredient_Powder_Boom",
                  "Quantity": 1,
                  "Durability": 0.0,
                  "MaxDurability": 0.0,
                  "OverrideDroppedItemAnimation": false
                },
                "12": {
                  "Id": "Wood_Azure_Trunk",
                  "Quantity": 7,
                  "Durability": 0.0,
                  "MaxDurability": 0.0,
                  "OverrideDroppedItemAnimation": false
                },
                "8": {
                  "Id": "Plant_Fruit_Apple",
                  "Quantity": 4,
                  "Durability": 0.0,
                  "MaxDurability": 0.0,
                  "OverrideDroppedItemAnimation": false
                }
              }
            },
            "Capacity": 20
          }
        }
      },
      "rotation": 2
    },
    {
      "x": -16,
      "y": 4,
      "z": 19,
      "name": "Rock_Shale_Cobble",
      "rotation": 3
    },
    {
      "x": -16,
      "y": 5,
      "z": 19,
      "name": "Rock_Shale_Brick",
      "rotation": 2
    },
    {
      "x": -16,
      "y": 6,
      "z": 19,
      "name": "Rock_Shale_Brick",
      "rotation": 2
    },
    {
      "x": -16,
      "y": 7,
      "z": 19,
      "name": "Rock_Shale_Brick",
      "rotation": 2
    },
    {
      "x": -16,
      "y": 8,
      "z": 19,
      "name": "Rock_Shale_Brick",
      "rotation": 2
    },
    {
      "x": -16,
      "y": 9,
      "z": 19,
      "name": "Rock_Shale_Brick_Ornate"
    },
    {
      "x": -15,
      "y": 4,
      "z": -19,
      "name": "Rock_Shale_Cobble",
      "rotation": 2
    },
    {
      "x": -15,
      "y": 5,
      "z": -19,
      "name": "Rock_Shale_Brick",
      "rotation": 1
    },
    {
      "x": -15,
      "y": 6,
      "z": -19,
      "name": "Rock_Shale_Brick",
      "rotation": 1
    },
    {
      "x": -15,
      "y": 7,
      "z": -19,
      "name": "Rock_Shale_Brick",
      "rotation": 1
    },
    {
      "x": -15,
      "y": 8,
      "z": -19,
      "name": "Rock_Shale_Brick",
      "rotation": 1
    },
    {
      "x": -15,
      "y": 9,
      "z": -19,
      "name": "Rock_Shale_Brick_Ornate",
      "rotation": 3
    },
    {
      "x": -15,
      "y": 4,
      "z": -18,
      "name": "Rock_Shale_Cobble",
      "rotation": 2
    },
    {
      "x": -15,
      "y": 4,
      "z": -17,
      "name": "Rock_Shale_Cobble",
      "rotation": 2
    },
    {
      "x": -15,
      "y": 4,
      "z": -16,
      "name": "Rock_Shale_Cobble",
      "rotation": 2
    },
    {
      "x": -15,
      "y": 4,
      "z": -15,
      "name": "Rock_Shale_Cobble",
      "rotation": 2
    },
    {
      "x": -15,
      "y": 4,
      "z": -14,
      "name": "Rock_Shale_Cobble"
    },
    {
      "x": -15,
      "y": 9,
      "z": -14,
      "name": "Rock_Shale_Brick_Ornate"
    },
    {
      "x": -15,
      "y": 4,
      "z": -13,
      "name": "Rock_Shale_Cobble"
    },
    {
      "x": -15,
      "y": 4,
      "z": -12,
      "name": "Rock_Shale_Cobble"
    },
    {
      "x": -15,
      "y": 4,
      "z": -11,
      "name": "Rock_Shale_Cobble"
    },
    {
      "x": -15,
      "y": 4,
      "z": -10,
      "name": "Rock_Shale_Cobble"
    },
    {
      "x": -15,
      "y": 4,
      "z": -9,
      "name": "Rock_Shale_Cobble"
    },
    {
      "x": -15,
      "y": 4,
      "z": -8,
      "name": "Rock_Shale_Cobble"
    },
    {
      "x": -15,
      "y": 4,
      "z": -7,
      "name": "Rock_Shale_Cobble"
    },
    {
      "x": -15,
      "y": 4,
      "z": -6,
      "name": "Rock_Shale_Cobble"
    },
    {
      "x": -15,
      "y": 4,
      "z": -5,
      "name": "Rock_Shale_Brick_Smooth"
    },
    {
      "x": -15,
      "y": 4,
      "z": -4,
      "name": "Rock_Shale_Cobble"
    },
    {
      "x": -15,
      "y": 4,
      "z": -3,
      "name": "Rock_Shale_Brick_Smooth"
    },
    {
      "x": -15,
      "y": 4,
      "z": -2,
      "name": "Rock_Shale_Cobble"
    },
    {
      "x": -15,
      "y": 4,
      "z": -1,
      "name": "Rock_Shale_Cobble"
    },
    {
      "x": -15,
      "y": 4,
      "z": 0,
      "name": "Rock_Shale_Cobble",
      "rotation": 1
    },
    {
      "x": -15,
      "y": 4,
      "z": 1,
      "name": "Rock_Shale_Cobble",
      "rotation": 1
    },
    {
      "x": -15,
      "y": 4,
      "z": 2,
      "name": "Rock_Shale_Cobble",
      "rotation": 1
    },
    {
      "x": -15,
      "y": 4,
      "z": 3,
      "name": "Rock_Shale_Brick_Smooth",
      "rotation": 1
    },
    {
      "x": -15,
      "y": 4,
      "z": 4,
      "name": "Rock_Shale_Cobble",
      "rotation": 1
    },
    {
      "x": -15,
      "y": 4,
      "z": 5,
      "name": "Rock_Shale_Brick_Smooth",
      "rotation": 1
    },
    {
      "x": -15,
      "y": 4,
      "z": 6,
      "name": "Rock_Shale_Cobble",
      "rotation": 1
    },
    {
      "x": -15,
      "y": 4,
      "z": 7,
      "name": "Rock_Shale_Cobble",
      "rotation": 1
    },
    {
      "x": -15,
      "y": 4,
      "z": 8,
      "name": "Rock_Shale_Cobble",
      "rotation": 1
    },
    {
      "x": -15,
      "y": 4,
      "z": 9,
      "name": "Rock_Shale_Cobble",
      "rotation": 1
    },
    {
      "x": -15,
      "y": 4,
      "z": 10,
      "name": "Rock_Shale_Cobble",
      "rotation": 1
    },
    {
      "x": -15,
      "y": 4,
      "z": 11,
      "name": "Rock_Shale_Cobble",
      "rotation": 1
    },
    {
      "x": -15,
      "y": 4,
      "z": 12,
      "name": "Rock_Shale_Cobble",
      "rotation": 1
    },
    {
      "x": -15,
      "y": 4,
      "z": 13,
      "name": "Rock_Shale_Cobble",
      "rotation": 1
    },
    {
      "x": -15,
      "y": 4,
      "z": 14,
      "name": "Rock_Shale_Cobble",
      "rotation": 1
    },
    {
      "x": -15,
      "y": 9,
      "z": 14,
      "name": "Rock_Shale_Brick_Ornate",
      "rotation": 1
    },
    {
      "x": -15,
      "y": 4,
      "z": 15,
      "name": "Rock_Shale_Cobble",
      "rotation": 3
    },
    {
      "x": -15,
      "y": 4,
      "z": 16,
      "name": "Rock_Shale_Cobble",
      "rotation": 3
    },
    {
      "x": -15,
      "y": 4,
      "z": 17,
      "name": "Rock_Shale_Cobble",
      "rotation": 3
    },
    {
      "x": -15,
      "y": 4,
      "z": 18,
      "name": "Rock_Shale_Cobble",
      "rotation": 3
    },
    {
      "x": -15,
      "y": 4,
      "z": 19,
      "name": "Rock_Shale_Cobble",
      "rotation": 3
    },
    {
      "x": -15,
      "y": 5,
      "z": 19,
      "name": "Rock_Shale_Brick",
      "rotation": 2
    },
    {
      "x": -15,
      "y": 6,
      "z": 19,
      "name": "Rock_Shale_Brick",
      "rotation": 2
    },
    {
      "x": -15,
      "y": 7,
      "z": 19,
      "name": "Rock_Shale_Brick",
      "rotation": 2
    },
    {
      "x": -15,
      "y": 8,
      "z": 19,
      "name": "Rock_Shale_Brick",
      "rotation": 2
    },
    {
      "x": -15,
      "y": 9,
      "z": 19,
      "name": "Rock_Shale_Brick_Ornate"
    },
    {
      "x": -14,
      "y": 4,
      "z": -18,
      "name": "Rock_Shale_Cobble",
      "rotation": 2
    },
    {
      "x": -14,
      "y": 5,
      "z": -18,
      "name": "Rock_Shale_Brick",
      "rotation": 1
    },
    {
      "x": -14,
      "y": 6,
      "z": -18,
      "name": "Rock_Shale_Brick",
      "rotation": 1
    },
    {
      "x": -14,
      "y": 7,
      "z": -18,
      "name": "Rock_Shale_Brick",
      "rotation": 1
    },
    {
      "x": -14,
      "y": 8,
      "z": -18,
      "name": "Rock_Shale_Brick",
      "rotation": 1
    },
    {
      "x": -14,
      "y": 9,
      "z": -18,
      "name": "Rock_Shale_Brick_Ornate",
      "rotation": 3
    },
    {
      "x": -14,
      "y": 4,
      "z": -17,
      "name": "Rock_Shale_Cobble",
      "rotation": 2
    },
    {
      "x": -14,
      "y": 4,
      "z": -16,
      "name": "Rock_Shale_Cobble",
      "rotation": 2
    },
    {
      "x": -14,
      "y": 9,
      "z": -16,
      "name": "Deco_SpiderWeb_Full",
      "rotation": 2
    },
    {
      "x": -14,
      "y": 4,
      "z": -15,
      "name": "Rock_Shale_Cobble"
    },
    {
      "x": -14,
      "y": 9,
      "z": -15,
      "name": "Rock_Shale_Brick_Ornate"
    },
    {
      "x": -14,
      "y": 4,
      "z": -14,
      "name": "Rock_Shale_Cobble"
    },
    {
      "x": -14,
      "y": 5,
      "z": -14,
      "name": "Rock_Shale_Brick_Pillar_Base"
    },
    {
      "x": -14,
      "y": 6,
      "z": -14,
      "name": "Rock_Shale_Brick_Pillar_Middle"
    },
    {
      "x": -14,
      "y": 7,
      "z": -14,
      "name": "Rock_Shale_Brick_Pillar_Middle"
    },
    {
      "x": -14,
      "y": 8,
      "z": -14,
      "name": "Rock_Shale_Brick_Pillar_Middle"
    },
    {
      "x": -14,
      "y": 9,
      "z": -14,
      "name": "Rock_Shale_Brick_Pillar_Base",
      "rotation": 8
    },
    {
      "x": -14,
      "y": 4,
      "z": -13,
      "name": "Rock_Shale_Cobble"
    },
    {
      "x": -14,
      "y": 4,
      "z": -12,
      "name": "Rock_Shale_Cobble"
    },
    {
      "x": -14,
      "y": 4,
      "z": -11,
      "name": "Rock_Shale_Cobble"
    },
    {
      "x": -14,
      "y": 4,
      "z": -10,
      "name": "Rock_Shale_Cobble"
    },
    {
      "x": -14,
      "y": 4,
      "z": -9,
      "name": "Rock_Shale_Cobble"
    },
    {
      "x": -14,
      "y": 4,
      "z": -8,
      "name": "Rock_Shale_Cobble"
    },
    {
      "x": -14,
      "y": 4,
      "z": -7,
      "name": "Rock_Shale_Cobble"
    },
    {
      "x": -14,
      "y": 4,
      "z": -6,
      "name": "Rock_Shale_Cobble"
    },
    {
      "x": -14,
      "y": 4,
      "z": -5,
      "name": "Rock_Shale_Brick_Smooth"
    },
    {
      "x": -14,
      "y": 4,
      "z": -4,
      "name": "Rock_Shale_Cobble"
    },
    {
      "x": -14,
      "y": 4,
      "z": -3,
      "name": "Rock_Shale_Brick_Smooth"
    },
    {
      "x": -14,
      "y": 4,
      "z": -2,
      "name": "Rock_Shale_Cobble"
    },
    {
      "x": -14,
      "y": 4,
      "z": -1,
      "name": "Rock_Shale_Cobble"
    },
    {
      "x": -14,
      "y": 4,
      "z": 0,
      "name": "Rock_Shale_Cobble",
      "rotation": 1
    },
    {
      "x": -14,
      "y": 4,
      "z": 1,
      "name": "Rock_Shale_Cobble",
      "rotation": 1
    },
    {
      "x": -14,
      "y": 4,
      "z": 2,
      "name": "Rock_Shale_Cobble",
      "rotation": 1
    },
    {
      "x": -14,
      "y": 4,
      "z": 3,
      "name": "Rock_Shale_Brick_Smooth",
      "rotation": 1
    },
    {
      "x": -14,
      "y": 4,
      "z": 4,
      "name": "Rock_Shale_Cobble",
      "rotation": 1
    },
    {
      "x": -14,
      "y": 4,
      "z": 5,
      "name": "Rock_Shale_Brick_Smooth",
      "rotation": 1
    },
    {
      "x": -14,
      "y": 4,
      "z": 6,
      "name": "Rock_Shale_Cobble",
      "rotation": 1
    },
    {
      "x": -14,
      "y": 4,
      "z": 7,
      "name": "Rock_Shale_Cobble",
      "rotation": 1
    },
    {
      "x": -14,
      "y": 5,
      "z": 7,
      "name": "Rubble_Shale_Medium",
      "support": 15
    },
    {
      "x": -14,
      "y": 4,
      "z": 8,
      "name": "Rock_Shale_Cobble",
      "rotation": 1
    },
    {
      "x": -14,
      "y": 4,
      "z": 9,
      "name": "Rock_Shale_Cobble",
      "rotation": 1
    },
    {
      "x": -14,
      "y": 4,
      "z": 10,
      "name": "Rock_Shale_Cobble",
      "rotation": 1
    },
    {
      "x": -14,
      "y": 4,
      "z": 11,
      "name": "Rock_Shale_Cobble",
      "rotation": 1
    },
    {
      "x": -14,
      "y": 4,
      "z": 12,
      "name": "Rock_Shale_Cobble",
      "rotation": 1
    },
    {
      "x": -14,
      "y": 4,
      "z": 13,
      "name": "Rock_Shale_Cobble",
      "rotation": 1
    },
    {
      "x": -14,
      "y": 4,
      "z": 14,
      "name": "Rock_Shale_Cobble",
      "rotation": 1
    },
    {
      "x": -14,
      "y": 5,
      "z": 14,
      "name": "Rock_Shale_Brick_Pillar_Base",
      "rotation": 1
    },
    {
      "x": -14,
      "y": 6,
      "z": 14,
      "name": "Rock_Shale_Brick_Pillar_Middle",
      "rotation": 1
    },
    {
      "x": -14,
      "y": 7,
      "z": 14,
      "name": "Rock_Shale_Brick_Pillar_Middle",
      "rotation": 1
    },
    {
      "x": -14,
      "y": 8,
      "z": 14,
      "name": "Rock_Shale_Brick_Pillar_Middle",
      "rotation": 1
    },
    {
      "x": -14,
      "y": 9,
      "z": 14,
      "name": "Rock_Shale_Brick_Pillar_Base",
      "rotation": 9
    },
    {
      "x": -14,
      "y": 4,
      "z": 15,
      "name": "Rock_Shale_Cobble",
      "rotation": 1
    },
    {
      "x": -14,
      "y": 9,
      "z": 15,
      "name": "Rock_Shale_Brick_Ornate",
      "rotation": 1
    },
    {
      "x": -14,
      "y": 4,
      "z": 16,
      "name": "Rock_Shale_Cobble",
      "rotation": 3
    },
    {
      "x": -14,
      "y": 4,
      "z": 17,
      "name": "Rock_Shale_Cobble",
      "rotation": 3
    },
    {
      "x": -14,
      "y": 9,
      "z": 17,
      "name": "Deco_SpiderWeb_Full",
      "rotation": 3
    },
    {
      "x": -14,
      "y": 4,
      "z": 18,
      "name": "Rock_Shale_Cobble",
      "rotation": 3
    },
    {
      "x": -14,
      "y": 5,
      "z": 18,
      "name": "Rock_Shale_Brick",
      "rotation": 2
    },
    {
      "x": -14,
      "y": 6,
      "z": 18,
      "name": "Rock_Shale_Brick",
      "rotation": 2
    },
    {
      "x": -14,
      "y": 7,
      "z": 18,
      "name": "Rock_Shale_Brick",
      "rotation": 2
    },
    {
      "x": -14,
      "y": 8,
      "z": 18,
      "name": "Rock_Shale_Brick",
      "rotation": 2
    },
    {
      "x": -14,
      "y": 9,
      "z": 18,
      "name": "Rock_Shale_Brick_Ornate"
    },
    {
      "x": -13,
      "y": 4,
      "z": -17,
      "name": "Rock_Shale_Cobble",
      "rotation": 2
    },
    {
      "x": -13,
      "y": 5,
      "z": -17,
      "name": "Rock_Shale_Brick",
      "rotation": 1
    },
    {
      "x": -13,
      "y": 6,
      "z": -17,
      "name": "Rock_Shale_Brick",
      "rotation": 1
    },
    {
      "x": -13,
      "y": 7,
      "z": -17,
      "name": "Rock_Shale_Brick",
      "rotation": 1
    },
    {
      "x": -13,
      "y": 8,
      "z": -17,
      "name": "Rock_Shale_Brick",
      "rotation": 1
    },
    {
      "x": -13,
      "y": 9,
      "z": -17,
      "name": "Rock_Shale_Brick_Ornate",
      "rotation": 3
    },
    {
      "x": -13,
      "y": 4,
      "z": -16,
      "name": "Rock_Shale_Cobble"
    },
    {
      "x": -13,
      "y": 5,
      "z": -16,
      "name": "Rock_Shale_Brick",
      "rotation": 1
    },
    {
      "x": -13,
      "y": 6,
      "z": -16,
      "name": "Rock_Shale_Brick",
      "rotation": 1
    },
    {
      "x": -13,
      "y": 7,
      "z": -16,
      "name": "Rock_Shale_Brick",
      "rotation": 1
    },
    {
      "x": -13,
      "y": 8,
      "z": -16,
      "name": "Rock_Shale_Brick",
      "rotation": 1
    },
    {
      "x": -13,
      "y": 9,
      "z": -16,
      "name": "Rock_Shale_Brick_Ornate",
      "rotation": 3
    },
    {
      "x": -13,
      "y": 4,
      "z": -15,
      "name": "Rock_Shale_Cobble"
    },
    {
      "x": -13,
      "y": 4,
      "z": -14,
      "name": "Rock_Shale_Cobble"
    },
    {
      "x": -13,
      "y": 4,
      "z": -13,
      "name": "Rock_Shale_Cobble"
    },
    {
      "x": -13,
      "y": 4,
      "z": -12,
      "name": "Rock_Shale_Cobble"
    },
    {
      "x": -13,
      "y": 4,
      "z": -11,
      "name": "Rock_Shale_Cobble"
    },
    {
      "x": -13,
      "y": 4,
      "z": -10,
      "name": "Rock_Shale_Cobble"
    },
    {
      "x": -13,
      "y": 4,
      "z": -9,
      "name": "Rock_Shale_Cobble"
    },
    {
      "x": -13,
      "y": 4,
      "z": -8,
      "name": "Rock_Shale_Cobble"
    },
    {
      "x": -13,
      "y": 4,
      "z": -7,
      "name": "Rock_Shale_Cobble"
    },
    {
      "x": -13,
      "y": 4,
      "z": -6,
      "name": "Rock_Shale_Cobble"
    },
    {
      "x": -13,
      "y": 5,
      "z": -6,
      "name": "Furniture_Temple_Light_Pot"
    },
    {
      "x": -13,
      "y": 4,
      "z": -5,
      "name": "Rock_Shale_Brick_Smooth"
    },
    {
      "x": -13,
      "y": 5,
      "z": -5,
      "name": "Rock_Shale_Brick_Pillar_Base"
    },
    {
      "x": -13,
      "y": 6,
      "z": -5,
      "name": "*Furniture_SK_Monuments_Brazier_State_Definitions_Off"
    },
    {
      "x": -13,
      "y": 4,
      "z": -4,
      "name": "Rock_Shale_Cobble"
    },
    {
      "x": -13,
      "y": 4,
      "z": -3,
      "name": "Rock_Shale_Brick_Smooth"
    },
    {
      "x": -13,
      "y": 5,
      "z": -3,
      "name": "Rock_Shale_Brick_Pillar_Base"
    },
    {
      "x": -13,
      "y": 6,
      "z": -3,
      "name": "Rock_Shale_Brick_Pillar_Middle"
    },
    {
      "x": -13,
      "y": 7,
      "z": -3,
      "name": "Rock_Shale_Brick_Pillar_Middle"
    },
    {
      "x": -13,
      "y": 8,
      "z": -3,
      "name": "Rock_Shale_Brick_Pillar_Middle"
    },
    {
      "x": -13,
      "y": 9,
      "z": -3,
      "name": "Rock_Shale_Brick_Pillar_Base",
      "rotation": 8
    },
    {
      "x": -13,
      "y": 4,
      "z": -2,
      "name": "Rock_Shale_Cobble"
    },
    {
      "x": -13,
      "y": 4,
      "z": -1,
      "name": "Rock_Shale_Cobble"
    },
    {
      "x": -13,
      "y": 4,
      "z": 0,
      "name": "Rock_Shale_Cobble",
      "rotation": 1
    },
    {
      "x": -13,
      "y": 5,
      "z": 0,
      "name": "Furniture_SK_Monument_Chest_Small",
      "components": {
        "Components": {
          "ItemContainerBlock": {
            "ItemContainer": {
              "Capacity": 18,
              "Items": {
                "15": {
                  "Id": "Wood_Aspen_Trunk",
                  "Quantity": 4,
                  "Durability": 0.0,
                  "MaxDurability": 0.0,
                  "OverrideDroppedItemAnimation": false
                },
                "14": {
                  "Id": "Tool_Pickaxe_Crude",
                  "Quantity": 1,
                  "Durability": 150.0,
                  "MaxDurability": 150.0,
                  "OverrideDroppedItemAnimation": false
                },
                "9": {
                  "Id": "Ore_Gold",
                  "Quantity": 2,
                  "Durability": 0.0,
                  "MaxDurability": 0.0,
                  "OverrideDroppedItemAnimation": false
                },
                "1": {
                  "Id": "Ore_Copper",
                  "Quantity": 1,
                  "Durability": 0.0,
                  "MaxDurability": 0.0,
                  "OverrideDroppedItemAnimation": false
                },
                "16": {
                  "Id": "Plant_Seeds_Lettuce",
                  "Quantity": 1,
                  "Durability": 0.0,
                  "MaxDurability": 0.0,
                  "OverrideDroppedItemAnimation": false
                }
              }
            },
            "Capacity": 20
          }
        }
      },
      "rotation": 3
    },
    {
      "x": -13,
      "y": 4,
      "z": 1,
      "name": "Rock_Shale_Cobble",
      "rotation": 1
    },
    {
      "x": -13,
      "y": 5,
      "z": 1,
      "name": "Rubble_Shale",
      "support": 15
    },
    {
      "x": -13,
      "y": 4,
      "z": 2,
      "name": "Rock_Shale_Cobble",
      "rotation": 1
    },
    {
      "x": -13,
      "y": 9,
      "z": 2,
      "name": "Deco_SpiderWeb_Full",
      "support": 15
    },
    {
      "x": -13,
      "y": 4,
      "z": 3,
      "name": "Rock_Shale_Brick_Smooth",
      "rotation": 1
    },
    {
      "x": -13,
      "y": 5,
      "z": 3,
      "name": "Rock_Shale_Brick_Pillar_Base",
      "rotation": 1
    },
    {
      "x": -13,
      "y": 6,
      "z": 3,
      "name": "Rock_Shale_Brick_Pillar_Middle",
      "rotation": 1
    },
    {
      "x": -13,
      "y": 7,
      "z": 3,
      "name": "Rock_Shale_Brick_Pillar_Middle",
      "rotation": 1
    },
    {
      "x": -13,
      "y": 8,
      "z": 3,
      "name": "Rock_Shale_Brick_Pillar_Middle",
      "rotation": 1
    },
    {
      "x": -13,
      "y": 9,
      "z": 3,
      "name": "Rock_Shale_Brick_Pillar_Base",
      "rotation": 9
    },
    {
      "x": -13,
      "y": 4,
      "z": 4,
      "name": "Rock_Shale_Cobble",
      "rotation": 1
    },
    {
      "x": -13,
      "y": 4,
      "z": 5,
      "name": "Rock_Shale_Brick_Smooth",
      "rotation": 1
    },
    {
      "x": -13,
      "y": 5,
      "z": 5,
      "name": "Rock_Shale_Brick_Pillar_Base",
      "rotation": 1
    },
    {
      "x": -13,
      "y": 6,
      "z": 5,
      "name": "*Furniture_SK_Monuments_Brazier_State_Definitions_Off"
    },
    {
      "x": -13,
      "y": 4,
      "z": 6,
      "name": "Rock_Shale_Cobble",
      "rotation": 1
    },
    {
      "x": -13,
      "y": 4,
      "z": 7,
      "name": "Rock_Shale_Cobble",
      "rotation": 1
    },
    {
      "x": -13,
      "y": 4,
      "z": 8,
      "name": "Rock_Shale_Cobble",
      "rotation": 1
    },
    {
      "x": -13,
      "y": 4,
      "z": 9,
      "name": "Rock_Shale_Cobble",
      "rotation": 1
    },
    {
      "x": -13,
      "y": 4,
      "z": 10,
      "name": "Rock_Shale_Cobble",
      "rotation": 1
    },
    {
      "x": -13,
      "y": 4,
      "z": 11,
      "name": "Rock_Shale_Cobble",
      "rotation": 1
    },
    {
      "x": -13,
      "y": 4,
      "z": 12,
      "name": "Rock_Shale_Cobble",
      "rotation": 1
    },
    {
      "x": -13,
      "y": 4,
      "z": 13,
      "name": "Rock_Shale_Cobble",
      "rotation": 1
    },
    {
      "x": -13,
      "y": 4,
      "z": 14,
      "name": "Rock_Shale_Cobble",
      "rotation": 1
    },
    {
      "x": -13,
      "y": 4,
      "z": 15,
      "name": "Rock_Shale_Cobble",
      "rotation": 1
    },
    {
      "x": -13,
      "y": 4,
      "z": 16,
      "name": "Rock_Shale_Cobble",
      "rotation": 1
    },
    {
      "x": -13,
      "y": 5,
      "z": 16,
      "name": "Rock_Shale_Brick",
      "rotation": 2
    },
    {
      "x": -13,
      "y": 6,
      "z": 16,
      "name": "Rock_Shale_Brick",
      "rotation": 2
    },
    {
      "x": -13,
      "y": 7,
      "z": 16,
      "name": "Rock_Shale_Brick",
      "rotation": 2
    },
    {
      "x": -13,
      "y": 8,
      "z": 16,
      "name": "Rock_Shale_Brick",
      "rotation": 2
    },
    {
      "x": -13,
      "y": 9,
      "z": 16,
      "name": "Rock_Shale_Brick_Ornate"
    },
    {
      "x": -13,
      "y": 4,
      "z": 17,
      "name": "Rock_Shale_Cobble",
      "rotation": 3
    },
    {
      "x": -13,
      "y": 5,
      "z": 17,
      "name": "Rock_Shale_Brick",
      "rotation": 2
    },
    {
      "x": -13,
      "y": 6,
      "z": 17,
      "name": "Rock_Shale_Brick",
      "rotation": 2
    },
    {
      "x": -13,
      "y": 7,
      "z": 17,
      "name": "Rock_Shale_Brick",
      "rotation": 2
    },
    {
      "x": -13,
      "y": 8,
      "z": 17,
      "name": "Rock_Shale_Brick",
      "rotation": 2
    },
    {
      "x": -13,
      "y": 9,
      "z": 17,
      "name": "Rock_Shale_Brick_Ornate"
    },
    {
      "x": -12,
      "y": 4,
      "z": -17,
      "name": "Rock_Shale_Brick_Smooth"
    },
    {
      "x": -12,
      "y": 5,
      "z": -17,
      "name": "Rock_Shale_Brick_Smooth"
    },
    {
      "x": -12,
      "y": 6,
      "z": -17,
      "name": "Rock_Shale_Brick_Smooth"
    },
    {
      "x": -12,
      "y": 7,
      "z": -17,
      "name": "Rock_Shale_Brick_Smooth"
    },
    {
      "x": -12,
      "y": 8,
      "z": -17,
      "name": "Rock_Shale_Brick_Smooth"
    },
    {
      "x": -12,
      "y": 9,
      "z": -17,
      "name": "Rock_Shale_Brick_Ornate"
    },
    {
      "x": -12,
      "y": 4,
      "z": -16,
      "name": "Rock_Shale_Cobble"
    },
    {
      "x": -12,
      "y": 4,
      "z": -15,
      "name": "Rock_Shale_Cobble"
    },
    {
      "x": -12,
      "y": 4,
      "z": -14,
      "name": "Rock_Shale_Cobble"
    },
    {
      "x": -12,
      "y": 4,
      "z": -13,
      "name": "Rock_Shale_Cobble"
    },
    {
      "x": -12,
      "y": 4,
      "z": -12,
      "name": "Rock_Shale_Cobble"
    },
    {
      "x": -12,
      "y": 4,
      "z": -11,
      "name": "Rock_Shale_Brick_Smooth"
    },
    {
      "x": -12,
      "y": 4,
      "z": -10,
      "name": "Rock_Shale_Brick_Smooth"
    },
    {
      "x": -12,
      "y": 4,
      "z": -9,
      "name": "Rock_Shale_Brick_Smooth"
    },
    {
      "x": -12,
      "y": 4,
      "z": -8,
      "name": "Rock_Shale_Brick_Smooth"
    },
    {
      "x": -12,
      "y": 4,
      "z": -7,
      "name": "Rock_Shale_Brick_Smooth"
    },
    {
      "x": -12,
      "y": 5,
      "z": -7,
      "name": "Rock_Shale_Brick_Pillar_Base"
    },
    {
      "x": -12,
      "y": 6,
      "z": -7,
      "name": "Rock_Shale_Brick_Pillar_Middle"
    },
    {
      "x": -12,
      "y": 7,
      "z": -7,
      "name": "Rock_Shale_Brick_Pillar_Middle"
    },
    {
      "x": -12,
      "y": 8,
      "z": -7,
      "name": "Rock_Shale_Brick_Pillar_Middle"
    },
    {
      "x": -12,
      "y": 9,
      "z": -7,
      "name": "Rock_Shale_Brick_Pillar_Base",
      "rotation": 8
    },
    {
      "x": -12,
      "y": 4,
      "z": -6,
      "name": "Rock_Shale_Cobble"
    },
    {
      "x": -12,
      "y": 5,
      "z": -6,
      "name": "Rock_Shale_Brick",
      "rotation": 1
    },
    {
      "x": -12,
      "y": 6,
      "z": -6,
      "name": "Rock_Shale_Brick",
      "rotation": 1
    },
    {
      "x": -12,
      "y": 7,
      "z": -6,
      "name": "Rock_Shale_Brick",
      "rotation": 1
    },
    {
      "x": -12,
      "y": 8,
      "z": -6,
      "name": "Rock_Shale_Brick",
      "rotation": 1
    },
    {
      "x": -12,
      "y": 9,
      "z": -6,
      "name": "Rock_Shale_Brick_Ornate",
      "rotation": 3
    },
    {
      "x": -12,
      "y": 4,
      "z": -5,
      "name": "Rock_Shale_Brick_Smooth",
      "rotation": 3
    },
    {
      "x": -12,
      "y": 5,
      "z": -5,
      "name": "Rock_Shale_Brick_Smooth",
      "rotation": 3
    },
    {
      "x": -12,
      "y": 6,
      "z": -5,
      "name": "Rock_Shale_Brick_Smooth",
      "rotation": 3
    },
    {
      "x": -12,
      "y": 7,
      "z": -5,
      "name": "Rock_Shale_Brick_Smooth",
      "rotation": 3
    },
    {
      "x": -12,
      "y": 8,
      "z": -5,
      "name": "Rock_Shale_Brick_Smooth",
      "rotation": 3
    },
    {
      "x": -12,
      "y": 9,
      "z": -5,
      "name": "Rock_Shale_Brick_Ornate",
      "rotation": 3
    },
    {
      "x": -12,
      "y": 4,
      "z": -4,
      "name": "Rock_Shale_Cobble",
      "rotation": 3
    },
    {
      "x": -12,
      "y": 5,
      "z": -4,
      "name": "Rock_Shale_Brick",
      "rotation": 1
    },
    {
      "x": -12,
      "y": 6,
      "z": -4,
      "name": "Rock_Shale_Brick",
      "rotation": 1
    },
    {
      "x": -12,
      "y": 7,
      "z": -4,
      "name": "Rock_Shale_Brick",
      "rotation": 1
    },
    {
      "x": -12,
      "y": 8,
      "z": -4,
      "name": "Rock_Shale_Brick",
      "rotation": 1
    },
    {
      "x": -12,
      "y": 9,
      "z": -4,
      "name": "Rock_Shale_Brick_Ornate",
      "rotation": 3
    },
    {
      "x": -12,
      "y": 4,
      "z": -3,
      "name": "Rock_Shale_Brick_Smooth",
      "rotation": 2
    },
    {
      "x": -12,
      "y": 5,
      "z": -3,
      "name": "Rock_Shale_Brick_Smooth",
      "rotation": 2
    },
    {
      "x": -12,
      "y": 6,
      "z": -3,
      "name": "Rock_Shale_Brick_Smooth",
      "rotation": 2
    },
    {
      "x": -12,
      "y": 7,
      "z": -3,
      "name": "Rock_Shale_Brick_Smooth",
      "rotation": 2
    },
    {
      "x": -12,
      "y": 8,
      "z": -3,
      "name": "Rock_Shale_Brick_Smooth",
      "rotation": 2
    },
    {
      "x": -12,
      "y": 9,
      "z": -3,
      "name": "Rock_Shale_Brick_Smooth",
      "rotation": 2
    },
    {
      "x": -12,
      "y": 3,
      "z": -2,
      "name": "Rock_Shale_Cobble",
      "rotation": 2
    },
    {
      "x": -12,
      "y": 4,
      "z": -2,
      "name": "Rock_Shale_Cobble",
      "rotation": 2
    },
    {
      "x": -12,
      "y": 5,
      "z": -2,
      "name": "Rock_Shale_Brick",
      "rotation": 2
    },
    {
      "x": -12,
      "y": 6,
      "z": -2,
      "name": "Rock_Shale_Brick",
      "rotation": 2
    },
    {
      "x": -12,
      "y": 7,
      "z": -2,
      "name": "Rock_Shale_Brick",
      "rotation": 2
    },
    {
      "x": -12,
      "y": 8,
      "z": -2,
      "name": "Rock_Shale_Brick",
      "rotation": 2
    },
    {
      "x": -12,
      "y": 9,
      "z": -2,
      "name": "Rock_Shale_Brick_Ornate"
    },
    {
      "x": -12,
      "y": 4,
      "z": -1,
      "name": "Rock_Shale_Brick_Smooth",
      "rotation": 2
    },
    {
      "x": -12,
      "y": 5,
      "z": -1,
      "name": "Rock_Shale_Brick_Smooth",
      "rotation": 2
    },
    {
      "x": -12,
      "y": 6,
      "z": -1,
      "name": "Rock_Shale_Brick_Smooth",
      "rotation": 2
    },
    {
      "x": -12,
      "y": 7,
      "z": -1,
      "name": "Rock_Shale_Brick_Smooth",
      "rotation": 2
    },
    {
      "x": -12,
      "y": 8,
      "z": -1,
      "name": "Rock_Shale_Brick_Smooth",
      "rotation": 2
    },
    {
      "x": -12,
      "y": 9,
      "z": -1,
      "name": "Rock_Shale_Brick_Ornate"
    },
    {
      "x": -12,
      "y": 4,
      "z": 0,
      "name": "Rock_Shale_Cobble",
      "rotation": 2
    },
    {
      "x": -12,
      "y": 5,
      "z": 0,
      "name": "Rock_Shale_Brick",
      "rotation": 3
    },
    {
      "x": -12,
      "y": 6,
      "z": 0,
      "name": "Rock_Shale_Brick",
      "rotation": 3
    },
    {
      "x": -12,
      "y": 7,
      "z": 0,
      "name": "Rock_Shale_Brick",
      "rotation": 3
    },
    {
      "x": -12,
      "y": 8,
      "z": 0,
      "name": "Rock_Shale_Brick",
      "rotation": 3
    },
    {
      "x": -12,
      "y": 9,
      "z": 0,
      "name": "Rock_Shale_Brick_Ornate",
      "rotation": 1
    },
    {
      "x": -12,
      "y": 4,
      "z": 1,
      "name": "Rock_Shale_Brick_Smooth",
      "rotation": 2
    },
    {
      "x": -12,
      "y": 5,
      "z": 1,
      "name": "Rock_Shale_Brick_Smooth",
      "rotation": 2
    },
    {
      "x": -12,
      "y": 6,
      "z": 1,
      "name": "Rock_Shale_Brick_Smooth",
      "rotation": 2
    },
    {
      "x": -12,
      "y": 7,
      "z": 1,
      "name": "Rock_Shale_Brick_Smooth",
      "rotation": 2
    },
    {
      "x": -12,
      "y": 8,
      "z": 1,
      "name": "Rock_Shale_Brick_Smooth",
      "rotation": 2
    },
    {
      "x": -12,
      "y": 9,
      "z": 1,
      "name": "Rock_Shale_Brick_Ornate",
      "rotation": 1
    },
    {
      "x": -12,
      "y": 3,
      "z": 2,
      "name": "Rock_Shale_Cobble",
      "rotation": 2
    },
    {
      "x": -12,
      "y": 4,
      "z": 2,
      "name": "Rock_Shale_Cobble",
      "rotation": 2
    },
    {
      "x": -12,
      "y": 5,
      "z": 2,
      "name": "Rock_Shale_Brick",
      "rotation": 3
    },
    {
      "x": -12,
      "y": 6,
      "z": 2,
      "name": "Rock_Shale_Brick",
      "rotation": 3
    },
    {
      "x": -12,
      "y": 7,
      "z": 2,
      "name": "Rock_Shale_Brick",
      "rotation": 3
    },
    {
      "x": -12,
      "y": 8,
      "z": 2,
      "name": "Rock_Shale_Brick",
      "rotation": 3
    },
    {
      "x": -12,
      "y": 9,
      "z": 2,
      "name": "Rock_Shale_Brick_Ornate",
      "rotation": 1
    },
    {
      "x": -12,
      "y": 4,
      "z": 3,
      "name": "Rock_Shale_Brick_Smooth",
      "rotation": 2
    },
    {
      "x": -12,
      "y": 5,
      "z": 3,
      "name": "Rock_Shale_Brick_Smooth",
      "rotation": 2
    },
    {
      "x": -12,
      "y": 6,
      "z": 3,
      "name": "Rock_Shale_Brick_Smooth",
      "rotation": 2
    },
    {
      "x": -12,
      "y": 7,
      "z": 3,
      "name": "Rock_Shale_Brick_Smooth",
      "rotation": 2
    },
    {
      "x": -12,
      "y": 8,
      "z": 3,
      "name": "Rock_Shale_Brick_Smooth",
      "rotation": 2
    },
    {
      "x": -12,
      "y": 9,
      "z": 3,
      "name": "Rock_Shale_Brick_Ornate",
      "rotation": 1
    },
    {
      "x": -12,
      "y": 4,
      "z": 4,
      "name": "Rock_Shale_Cobble"
    },
    {
      "x": -12,
      "y": 5,
      "z": 4,
      "name": "Rock_Shale_Brick",
      "rotation": 2
    },
    {
      "x": -12,
      "y": 6,
      "z": 4,
      "name": "Rock_Shale_Brick",
      "rotation": 2
    },
    {
      "x": -12,
      "y": 7,
      "z": 4,
      "name": "Rock_Shale_Brick",
      "rotation": 2
    },
    {
      "x": -12,
      "y": 8,
      "z": 4,
      "name": "Rock_Shale_Brick",
      "rotation": 2
    },
    {
      "x": -12,
      "y": 9,
      "z": 4,
      "name": "Rock_Shale_Brick_Ornate"
    },
    {
      "x": -12,
      "y": 4,
      "z": 5,
      "name": "Rock_Shale_Brick_Smooth"
    },
    {
      "x": -12,
      "y": 5,
      "z": 5,
      "name": "Rock_Shale_Brick_Smooth"
    },
    {
      "x": -12,
      "y": 6,
      "z": 5,
      "name": "Rock_Shale_Brick_Smooth"
    },
    {
      "x": -12,
      "y": 7,
      "z": 5,
      "name": "Rock_Shale_Brick_Smooth"
    },
    {
      "x": -12,
      "y": 8,
      "z": 5,
      "name": "Rock_Shale_Brick_Smooth"
    },
    {
      "x": -12,
      "y": 9,
      "z": 5,
      "name": "Rock_Shale_Brick_Ornate"
    },
    {
      "x": -12,
      "y": 4,
      "z": 6,
      "name": "Rock_Shale_Cobble"
    },
    {
      "x": -12,
      "y": 5,
      "z": 6,
      "name": "Rock_Shale_Brick",
      "rotation": 2
    },
    {
      "x": -12,
      "y": 6,
      "z": 6,
      "name": "Rock_Shale_Brick",
      "rotation": 2
    },
    {
      "x": -12,
      "y": 7,
      "z": 6,
      "name": "Rock_Shale_Brick",
      "rotation": 2
    },
    {
      "x": -12,
      "y": 8,
      "z": 6,
      "name": "Rock_Shale_Brick",
      "rotation": 2
    },
    {
      "x": -12,
      "y": 9,
      "z": 6,
      "name": "Rock_Shale_Brick_Ornate"
    },
    {
      "x": -12,
      "y": 4,
      "z": 7,
      "name": "Rock_Shale_Brick_Smooth",
      "rotation": 1
    },
    {
      "x": -12,
      "y": 5,
      "z": 7,
      "name": "Rock_Shale_Brick_Pillar_Base",
      "rotation": 1
    },
    {
      "x": -12,
      "y": 6,
      "z": 7,
      "name": "Rock_Shale_Brick_Pillar_Middle",
      "rotation": 1
    },
    {
      "x": -12,
      "y": 7,
      "z": 7,
      "name": "Rock_Shale_Brick_Pillar_Middle",
      "rotation": 1
    },
    {
      "x": -12,
      "y": 8,
      "z": 7,
      "name": "Rock_Shale_Brick_Pillar_Middle",
      "rotation": 1
    },
    {
      "x": -12,
      "y": 9,
      "z": 7,
      "name": "Rock_Shale_Brick_Pillar_Base",
      "rotation": 9
    },
    {
      "x": -12,
      "y": 4,
      "z": 8,
      "name": "Rock_Shale_Brick_Smooth",
      "rotation": 1
    },
    {
      "x": -12,
      "y": 4,
      "z": 9,
      "name": "Rock_Shale_Brick_Smooth",
      "rotation": 1
    },
    {
      "x": -12,
      "y": 4,
      "z": 10,
      "name": "Rock_Shale_Brick_Smooth",
      "rotation": 1
    },
    {
      "x": -12,
      "y": 4,
      "z": 11,
      "name": "Rock_Shale_Brick_Smooth",
      "rotation": 1
    },
    {
      "x": -12,
      "y": 4,
      "z": 12,
      "name": "Rock_Shale_Cobble",
      "rotation": 1
    },
    {
      "x": -12,
      "y": 4,
      "z": 13,
      "name": "Rock_Shale_Cobble",
      "rotation": 1
    },
    {
      "x": -12,
      "y": 4,
      "z": 14,
      "name": "Rock_Shale_Cobble",
      "rotation": 1
    },
    {
      "x": -12,
      "y": 4,
      "z": 15,
      "name": "Rock_Shale_Cobble",
      "rotation": 1
    },
    {
      "x": -12,
      "y": 4,
      "z": 16,
      "name": "Rock_Shale_Cobble",
      "rotation": 1
    },
    {
      "x": -12,
      "y": 4,
      "z": 17,
      "name": "Rock_Shale_Brick_Smooth",
      "rotation": 1
    },
    {
      "x": -12,
      "y": 5,
      "z": 17,
      "name": "Rock_Shale_Brick_Smooth",
      "rotation": 1
    },
    {
      "x": -12,
      "y": 6,
      "z": 17,
      "name": "Rock_Shale_Brick_Smooth",
      "rotation": 1
    },
    {
      "x": -12,
      "y": 7,
      "z": 17,
      "name": "Rock_Shale_Brick_Smooth",
      "rotation": 1
    },
    {
      "x": -12,
      "y": 8,
      "z": 17,
      "name": "Rock_Shale_Brick_Smooth",
      "rotation": 1
    },
    {
      "x": -12,
      "y": 9,
      "z": 17,
      "name": "Rock_Shale_Brick_Ornate",
      "rotation": 1
    },
    {
      "x": -11,
      "y": 4,
      "z": -18,
      "name": "Rock_Shale_Cobble"
    },
    {
      "x": -11,
      "y": 5,
      "z": -18,
      "name": "Rock_Shale_Brick_Smooth"
    },
    {
      "x": -11,
      "y": 6,
      "z": -18,
      "name": "Rock_Shale_Brick_Smooth"
    },
    {
      "x": -11,
      "y": 7,
      "z": -18,
      "name": "Rock_Shale_Brick_Smooth"
    },
    {
      "x": -11,
      "y": 8,
      "z": -18,
      "name": "Rock_Shale_Brick_Smooth"
    },
    {
      "x": -11,
      "y": 9,
      "z": -18,
      "name": "Rock_Shale_Brick_Ornate"
    },
    {
      "x": -11,
      "y": 4,
      "z": -17,
      "name": "Rock_Shale_Brick_Smooth"
    },
    {
      "x": -11,
      "y": 5,
      "z": -17,
      "name": "Rock_Shale_Brick_Pillar_Base"
    },
    {
      "x": -11,
      "y": 6,
      "z": -17,
      "name": "Rock_Shale_Brick_Pillar_Middle"
    },
    {
      "x": -11,
      "y": 7,
      "z": -17,
      "name": "Rock_Shale_Brick_Pillar_Middle"
    },
    {
      "x": -11,
      "y": 8,
      "z": -17,
      "name": "Rock_Shale_Brick_Pillar_Middle"
    },
    {
      "x": -11,
      "y": 9,
      "z": -17,
      "name": "Rock_Shale_Brick_Pillar_Base",
      "rotation": 8
    },
    {
      "x": -11,
      "y": 4,
      "z": -16,
      "name": "Rock_Shale_Cobble"
    },
    {
      "x": -11,
      "y": 4,
      "z": -15,
      "name": "Rock_Shale_Cobble"
    },
    {
      "x": -11,
      "y": 4,
      "z": -14,
      "name": "Rock_Shale_Cobble"
    },
    {
      "x": -11,
      "y": 4,
      "z": -13,
      "name": "Rock_Shale_Cobble"
    },
    {
      "x": -11,
      "y": 4,
      "z": -12,
      "name": "Rock_Shale_Brick_Smooth"
    },
    {
      "x": -11,
      "y": 4,
      "z": -11,
      "name": "Rock_Shale_Brick_Smooth"
    },
    {
      "x": -11,
      "y": 4,
      "z": -10,
      "name": "Rock_Shale_Cobble"
    },
    {
      "x": -11,
      "y": 4,
      "z": -9,
      "name": "Rock_Shale_Cobble"
    },
    {
      "x": -11,
      "y": 4,
      "z": -8,
      "name": "Rock_Shale_Cobble",
      "rotation": 3
    },
    {
      "x": -11,
      "y": 9,
      "z": -8,
      "name": "Rock_Shale_Brick_Ornate",
      "rotation": 3
    },
    {
      "x": -11,
      "y": 4,
      "z": -7,
      "name": "Rock_Shale_Brick_Smooth",
      "rotation": 3
    },
    {
      "x": -11,
      "y": 9,
      "z": -7,
      "name": "Rock_Shale_Brick_Ornate",
      "rotation": 3
    },
    {
      "x": -11,
      "y": 4,
      "z": -6,
      "name": "Rock_Shale_Cobble",
      "rotation": 3
    },
    {
      "x": -11,
      "y": 4,
      "z": -5,
      "name": "Rock_Shale_Brick_Smooth",
      "rotation": 3
    },
    {
      "x": -11,
      "y": 4,
      "z": -4,
      "name": "Rock_Shale_Cobble",
      "rotation": 3
    },
    {
      "x": -11,
      "y": 4,
      "z": -3,
      "name": "Rock_Shale_Brick_Smooth",
      "rotation": 2
    },
    {
      "x": -11,
      "y": 5,
      "z": -3,
      "name": "Rock_Shale_Brick_Pillar_Base",
      "rotation": 2
    },
    {
      "x": -11,
      "y": 6,
      "z": -3,
      "name": "Rock_Shale_Brick_Pillar_Middle",
      "rotation": 2
    },
    {
      "x": -11,
      "y": 7,
      "z": -3,
      "name": "Rock_Shale_Brick_Pillar_Middle",
      "rotation": 2
    },
    {
      "x": -11,
      "y": 8,
      "z": -3,
      "name": "Rock_Shale_Brick_Pillar_Middle",
      "rotation": 2
    },
    {
      "x": -11,
      "y": 9,
      "z": -3,
      "name": "Rock_Shale_Brick_Pillar_Base",
      "rotation": 10
    },
    {
      "x": -11,
      "y": 3,
      "z": -2,
      "name": "Rock_Shale_Cobble",
      "rotation": 2
    },
    {
      "x": -11,
      "y": 4,
      "z": -2,
      "name": "Metal_Iron_Glowing_Pipe_Corner",
      "rotation": 3
    },
    {
      "x": -11,
      "y": 5,
      "z": -2,
      "name": "Metal_Iron_Glowing_Pipe",
      "rotation": 2
    },
    {
      "x": -11,
      "y": 6,
      "z": -2,
      "name": "Metal_Iron_Glowing_Pipe_Corner",
      "rotation": 8
    },
    {
      "x": -11,
      "y": 4,
      "z": -1,
      "name": "Rock_Shale_Brick_Smooth",
      "rotation": 2
    },
    {
      "x": -11,
      "y": 5,
      "z": -1,
      "name": "Rock_Shale_Brick_Smooth",
      "rotation": 2
    },
    {
      "x": -11,
      "y": 6,
      "z": -1,
      "name": "Rock_Shale_Brick_Decorative",
      "rotation": 2
    },
    {
      "x": -11,
      "y": 4,
      "z": 0,
      "name": "Rock_Shale_Cobble",
      "rotation": 2
    },
    {
      "x": -11,
      "y": 5,
      "z": 0,
      "name": "Build_Lightsource_Cyan",
      "rotation": 2
    },
    {
      "x": -11,
      "y": 6,
      "z": 0,
      "name": "Build_Lightsource_Cyan",
      "rotation": 2
    },
    {
      "x": -11,
      "y": 7,
      "z": 0,
      "name": "Deko_Block_Test",
      "rotation": 2
    },
    {
      "x": -11,
      "y": 4,
      "z": 1,
      "name": "Rock_Shale_Brick_Smooth",
      "rotation": 2
    },
    {
      "x": -11,
      "y": 5,
      "z": 1,
      "name": "Rock_Shale_Brick_Smooth",
      "rotation": 2
    },
    {
      "x": -11,
      "y": 6,
      "z": 1,
      "name": "Rock_Shale_Brick_Decorative",
      "rotation": 2
    },
    {
      "x": -11,
      "y": 3,
      "z": 2,
      "name": "Rock_Shale_Cobble",
      "rotation": 2
    },
    {
      "x": -11,
      "y": 4,
      "z": 2,
      "name": "Metal_Iron_Glowing_Pipe_Corner",
      "rotation": 3
    },
    {
      "x": -11,
      "y": 5,
      "z": 2,
      "name": "Metal_Iron_Glowing_Pipe",
      "rotation": 2
    },
    {
      "x": -11,
      "y": 6,
      "z": 2,
      "name": "Metal_Iron_Glowing_Pipe_Corner",
      "rotation": 12
    },
    {
      "x": -11,
      "y": 4,
      "z": 3,
      "name": "Rock_Shale_Brick_Smooth",
      "rotation": 2
    },
    {
      "x": -11,
      "y": 5,
      "z": 3,
      "name": "Rock_Shale_Brick_Pillar_Base",
      "rotation": 2
    },
    {
      "x": -11,
      "y": 6,
      "z": 3,
      "name": "Rock_Shale_Brick_Pillar_Middle",
      "rotation": 2
    },
    {
      "x": -11,
      "y": 7,
      "z": 3,
      "name": "Rock_Shale_Brick_Pillar_Middle",
      "rotation": 2
    },
    {
      "x": -11,
      "y": 8,
      "z": 3,
      "name": "Rock_Shale_Brick_Pillar_Middle",
      "rotation": 2
    },
    {
      "x": -11,
      "y": 9,
      "z": 3,
      "name": "Rock_Shale_Brick_Pillar_Base",
      "rotation": 10
    },
    {
      "x": -11,
      "y": 4,
      "z": 4,
      "name": "Rock_Shale_Cobble"
    },
    {
      "x": -11,
      "y": 5,
      "z": 4,
      "name": "*Furniture_SK_Monument_Loot_Coffin_State_Definitions_CloseWindow",
      "filler": 992,
      "rotation": 1
    },
    {
      "x": -11,
      "y": 4,
      "z": 5,
      "name": "Rock_Shale_Brick_Smooth"
    },
    {
      "x": -11,
      "y": 5,
      "z": 5,
      "name": "*Furniture_SK_Monument_Loot_Coffin_State_Definitions_CloseWindow",
      "components": {
        "Components": {
          "ItemContainerBlock": {
            "ItemContainer": {
              "Capacity": 18,
              "Items": {
                "0": {
                  "Id": "Wood_Aspen_Trunk",
                  "Quantity": 7,
                  "Durability": 0.0,
                  "MaxDurability": 0.0,
                  "OverrideDroppedItemAnimation": false
                },
                "2": {
                  "Id": "Wood_Azure_Trunk",
                  "Quantity": 6,
                  "Durability": 0.0,
                  "MaxDurability": 0.0,
                  "OverrideDroppedItemAnimation": false
                },
                "6": {
                  "Id": "Ingredient_Powder_Boom",
                  "Quantity": 1,
                  "Durability": 0.0,
                  "MaxDurability": 0.0,
                  "OverrideDroppedItemAnimation": false
                },
                "4": {
                  "Id": "Ore_Iron",
                  "Quantity": 1,
                  "Durability": 0.0,
                  "MaxDurability": 0.0,
                  "OverrideDroppedItemAnimation": false
                },
                "16": {
                  "Id": "Ore_Copper",
                  "Quantity": 2,
                  "Durability": 0.0,
                  "MaxDurability": 0.0,
                  "OverrideDroppedItemAnimation": false
                },
                "12": {
                  "Id": "Ore_Gold",
                  "Quantity": 3,
                  "Durability": 0.0,
                  "MaxDurability": 0.0,
                  "OverrideDroppedItemAnimation": false
                },
                "8": {
                  "Id": "Plant_Seeds_Wheat",
                  "Quantity": 1,
                  "Durability": 0.0,
                  "MaxDurability": 0.0,
                  "OverrideDroppedItemAnimation": false
                },
                "9": {
                  "Id": "Plant_Fruit_Berries_Red",
                  "Quantity": 3,
                  "Durability": 0.0,
                  "MaxDurability": 0.0,
                  "OverrideDroppedItemAnimation": false
                }
              }
            },
            "Capacity": 20
          }
        }
      },
      "rotation": 1
    },
    {
      "x": -11,
      "y": 4,
      "z": 6,
      "name": "Rock_Shale_Cobble"
    },
    {
      "x": -11,
      "y": 4,
      "z": 7,
      "name": "Rock_Shale_Brick_Smooth"
    },
    {
      "x": -11,
      "y": 9,
      "z": 7,
      "name": "Rock_Shale_Brick_Ornate"
    },
    {
      "x": -11,
      "y": 4,
      "z": 8,
      "name": "Rock_Shale_Cobble"
    },
    {
      "x": -11,
      "y": 9,
      "z": 8,
      "name": "Rock_Shale_Brick_Ornate"
    },
    {
      "x": -11,
      "y": 4,
      "z": 9,
      "name": "Rock_Shale_Cobble",
      "rotation": 1
    },
    {
      "x": -11,
      "y": 4,
      "z": 10,
      "name": "Rock_Shale_Cobble",
      "rotation": 1
    },
    {
      "x": -11,
      "y": 4,
      "z": 11,
      "name": "Rock_Shale_Brick_Smooth",
      "rotation": 1
    },
    {
      "x": -11,
      "y": 4,
      "z": 12,
      "name": "Rock_Shale_Brick_Smooth",
      "rotation": 1
    },
    {
      "x": -11,
      "y": 4,
      "z": 13,
      "name": "Rock_Shale_Cobble",
      "rotation": 1
    },
    {
      "x": -11,
      "y": 4,
      "z": 14,
      "name": "Rock_Shale_Cobble",
      "rotation": 1
    },
    {
      "x": -11,
      "y": 4,
      "z": 15,
      "name": "Rock_Shale_Cobble",
      "rotation": 1
    },
    {
      "x": -11,
      "y": 4,
      "z": 16,
      "name": "Rock_Shale_Cobble",
      "rotation": 1
    },
    {
      "x": -11,
      "y": 4,
      "z": 17,
      "name": "Rock_Shale_Brick_Smooth",
      "rotation": 1
    },
    {
      "x": -11,
      "y": 5,
      "z": 17,
      "name": "Rock_Shale_Brick_Pillar_Base",
      "rotation": 1
    },
    {
      "x": -11,
      "y": 6,
      "z": 17,
      "name": "Rock_Shale_Brick_Pillar_Middle",
      "rotation": 1
    },
    {
      "x": -11,
      "y": 7,
      "z": 17,
      "name": "Rock_Shale_Brick_Pillar_Middle",
      "rotation": 1
    },
    {
      "x": -11,
      "y": 8,
      "z": 17,
      "name": "Rock_Shale_Brick_Pillar_Middle",
      "rotation": 1
    },
    {
      "x": -11,
      "y": 9,
      "z": 17,
      "name": "Rock_Shale_Brick_Pillar_Base",
      "rotation": 9
    },
    {
      "x": -11,
      "y": 4,
      "z": 18,
      "name": "Rock_Shale_Cobble",
      "rotation": 1
    },
    {
      "x": -11,
      "y": 5,
      "z": 18,
      "name": "Rock_Shale_Brick_Smooth",
      "rotation": 1
    },
    {
      "x": -11,
      "y": 6,
      "z": 18,
      "name": "Rock_Shale_Brick_Smooth",
      "rotation": 1
    },
    {
      "x": -11,
      "y": 7,
      "z": 18,
      "name": "Rock_Shale_Brick_Smooth",
      "rotation": 1
    },
    {
      "x": -11,
      "y": 8,
      "z": 18,
      "name": "Rock_Shale_Brick_Smooth",
      "rotation": 1
    },
    {
      "x": -11,
      "y": 9,
      "z": 18,
      "name": "Rock_Shale_Brick_Ornate",
      "rotation": 1
    },
    {
      "x": -10,
      "y": 4,
      "z": -18,
      "name": "Rock_Shale_Cobble"
    },
    {
      "x": -10,
      "y": 5,
      "z": -18,
      "name": "Rock_Shale_Brick",
      "rotation": 1
    },
    {
      "x": -10,
      "y": 6,
      "z": -18,
      "name": "Rock_Shale_Brick",
      "rotation": 1
    },
    {
      "x": -10,
      "y": 7,
      "z": -18,
      "name": "Rock_Shale_Brick",
      "rotation": 1
    },
    {
      "x": -10,
      "y": 8,
      "z": -18,
      "name": "Rock_Shale_Brick",
      "rotation": 1
    },
    {
      "x": -10,
      "y": 9,
      "z": -18,
      "name": "Rock_Shale_Brick_Ornate",
      "rotation": 3
    },
    {
      "x": -10,
      "y": 4,
      "z": -17,
      "name": "Rock_Shale_Brick_Smooth"
    },
    {
      "x": -10,
      "y": 4,
      "z": -16,
      "name": "Rock_Shale_Cobble"
    },
    {
      "x": -10,
      "y": 4,
      "z": -15,
      "name": "Rock_Shale_Cobble"
    },
    {
      "x": -10,
      "y": 4,
      "z": -14,
      "name": "Rock_Shale_Cobble"
    },
    {
      "x": -10,
      "y": 4,
      "z": -13,
      "name": "Rock_Shale_Cobble"
    },
    {
      "x": -10,
      "y": 4,
      "z": -12,
      "name": "Rock_Shale_Brick_Smooth"
    },
    {
      "x": -10,
      "y": 4,
      "z": -11,
      "name": "Rock_Shale_Cobble"
    },
    {
      "x": -10,
      "y": 4,
      "z": -10,
      "name": "Rock_Shale_Cobble"
    },
    {
      "x": -10,
      "y": 5,
      "z": -10,
      "name": "Rock_Shale_Brick_Pillar_Base",
      "rotation": 3
    },
    {
      "x": -10,
      "y": 6,
      "z": -10,
      "name": "Rock_Shale_Brick_Pillar_Middle",
      "rotation": 3
    },
    {
      "x": -10,
      "y": 7,
      "z": -10,
      "name": "Rock_Shale_Brick_Pillar_Middle",
      "rotation": 3
    },
    {
      "x": -10,
      "y": 8,
      "z": -10,
      "name": "Rock_Shale_Brick_Pillar_Middle",
      "rotation": 3
    },
    {
      "x": -10,
      "y": 9,
      "z": -10,
      "name": "Rock_Shale_Brick_Pillar_Base",
      "rotation": 11
    },
    {
      "x": -10,
      "y": 4,
      "z": -9,
      "name": "Rock_Shale_Cobble",
      "rotation": 3
