{
  "version": 8,
  "blockIdVersion": 11,
  "anchorX": 0,
  "anchorY": 0,
  "anchorZ": 0,
  "blocks": [
    {
      "x": -33,
      "y": 13,
      "z": -23,
      "name": "Soil_Grass"
    },
    {
      "x": -33,
      "y": 13,
      "z": -22,
      "name": "Soil_Grass"
    },
    {
      "x": -33,
      "y": 13,
      "z": -21,
      "name": "Soil_Grass"
    },
    {
      "x": -33,
      "y": 14,
      "z": -21,
      "name": "Plant_Grass_Jungle_Tall",
      "support": 15
    },
    {
      "x": -33,
      "y": 13,
      "z": -20,
      "name": "Soil_Grass"
    },
    {
      "x": -33,
      "y": 14,
      "z": -20,
      "name": "Plant_Grass_Jungle_Tall",
      "support": 15
    },
    {
      "x": -33,
      "y": 13,
      "z": -19,
      "name": "Soil_Grass"
    },
    {
      "x": -33,
      "y": 13,
      "z": -18,
      "name": "Soil_Grass"
    },
    {
      "x": -33,
      "y": 13,
      "z": -17,
      "name": "Soil_Grass"
    },
    {
      "x": -33,
      "y": 14,
      "z": -17,
      "name": "Plant_Grass_Sharp_Wild",
      "support": 15
    },
    {
      "x": -33,
      "y": 15,
      "z": -17,
      "name": "Plant_Grass_Sharp_Wild",
      "filler": 1024
    },
    {
      "x": -33,
      "y": 13,
      "z": -16,
      "name": "Soil_Grass"
    },
    {
      "x": -33,
      "y": 13,
      "z": -15,
      "name": "Soil_Grass"
    },
    {
      "x": -33,
      "y": 13,
      "z": -14,
      "name": "Soil_Grass"
    },
    {
      "x": -32,
      "y": 13,
      "z": -28,
      "name": "Soil_Grass"
    },
    {
      "x": -32,
      "y": 13,
      "z": -27,
      "name": "Soil_Grass"
    },
    {
      "x": -32,
      "y": 13,
      "z": -26,
      "name": "Soil_Grass"
    },
    {
      "x": -32,
      "y": 13,
      "z": -25,
      "name": "Soil_Grass"
    },
    {
      "x": -32,
      "y": 13,
      "z": -24,
      "name": "Soil_Grass"
    },
    {
      "x": -32,
      "y": 13,
      "z": -23,
      "name": "Soil_Grass"
    },
    {
      "x": -32,
      "y": 14,
      "z": -22,
      "name": "Soil_Grass"
    },
    {
      "x": -32,
      "y": 14,
      "z": -21,
      "name": "Soil_Grass"
    },
    {
      "x": -32,
      "y": 14,
      "z": -20,
      "name": "Soil_Grass"
    },
    {
      "x": -32,
      "y": 14,
      "z": -19,
      "name": "Soil_Grass"
    },
    {
      "x": -32,
      "y": 14,
      "z": -18,
      "name": "Soil_Grass"
    },
    {
      "x": -32,
      "y": 13,
      "z": -17,
      "name": "Soil_Dirt"
    },
    {
      "x": -32,
      "y": 14,
      "z": -17,
      "name": "Soil_Grass"
    },
    {
      "x": -32,
      "y": 15,
      "z": -17,
      "name": "Plant_Grass_Sharp_Wild",
      "support": 15
    },
    {
      "x": -32,
      "y": 16,
      "z": -17,
      "name": "Plant_Grass_Sharp_Wild",
      "filler": 1024
    },
    {
      "x": -32,
      "y": 13,
      "z": -16,
      "name": "Soil_Grass"
    },
    {
      "x": -32,
      "y": 13,
      "z": -15,
      "name": "Soil_Grass"
    },
    {
      "x": -32,
      "y": 14,
      "z": -15,
      "name": "Plant_Grass_Sharp_Overgrown",
      "support": 15
    },
    {
      "x": -32,
      "y": 15,
      "z": -15,
      "name": "Plant_Grass_Sharp_Overgrown",
      "filler": 1024
    },
    {
      "x": -32,
      "y": 13,
      "z": -14,
      "name": "Soil_Grass"
    },
    {
      "x": -32,
      "y": 13,
      "z": -13,
      "name": "Soil_Grass"
    },
    {
      "x": -32,
      "y": 13,
      "z": -12,
      "name": "Soil_Grass"
    },
    {
      "x": -32,
      "y": 13,
      "z": -11,
      "name": "Soil_Grass"
    },
    {
      "x": -32,
      "y": 14,
      "z": -11,
      "name": "Plant_Grass_Sharp_Overgrown",
      "support": 15
    },
    {
      "x": -32,
      "y": 15,
      "z": -11,
      "name": "Plant_Grass_Sharp_Overgrown",
      "filler": 1024
    },
    {
      "x": -32,
      "y": 13,
      "z": -10,
      "name": "Soil_Grass"
    },
    {
      "x": -32,
      "y": 13,
      "z": -9,
      "name": "Soil_Grass"
    },
    {
      "x": -32,
      "y": 13,
      "z": -2,
      "name": "Soil_Grass"
    },
    {
      "x": -32,
      "y": 13,
      "z": -1,
      "name": "Soil_Grass"
    },
    {
      "x": -32,
      "y": 13,
      "z": 0,
      "name": "Soil_Grass"
    },
    {
      "x": -32,
      "y": 13,
      "z": 1,
      "name": "Soil_Grass"
    },
    {
      "x": -32,
      "y": 14,
      "z": 1,
      "name": "Plant_Grass_Sharp_Overgrown",
      "support": 15
    },
    {
      "x": -32,
      "y": 15,
      "z": 1,
      "name": "Plant_Grass_Sharp_Overgrown",
      "filler": 1024
    },
    {
      "x": -32,
      "y": 13,
      "z": 2,
      "name": "Soil_Grass"
    },
    {
      "x": -32,
      "y": 13,
      "z": 3,
      "name": "Soil_Grass"
    },
    {
      "x": -31,
      "y": 13,
      "z": -29,
      "name": "Soil_Grass"
    },
    {
      "x": -31,
      "y": 13,
      "z": -28,
      "name": "Soil_Grass"
    },
    {
      "x": -31,
      "y": 14,
      "z": -27,
      "name": "Soil_Grass"
    },
    {
      "x": -31,
      "y": 14,
      "z": -26,
      "name": "Soil_Grass"
    },
    {
      "x": -31,
      "y": 14,
      "z": -25,
      "name": "Soil_Grass"
    },
    {
      "x": -31,
      "y": 15,
      "z": -25,
      "name": "Plant_Grass_Jungle_Tall",
      "support": 15
    },
    {
      "x": -31,
      "y": 14,
      "z": -24,
      "name": "Soil_Grass"
    },
    {
      "x": -31,
      "y": 14,
      "z": -23,
      "name": "Soil_Grass"
    },
    {
      "x": -31,
      "y": 15,
      "z": -23,
      "name": "Plant_Grass_Sharp_Overgrown",
      "support": 15
    },
    {
      "x": -31,
      "y": 16,
      "z": -23,
      "name": "Plant_Grass_Sharp_Overgrown",
      "filler": 1024
    },
    {
      "x": -31,
      "y": 14,
      "z": -22,
      "name": "Soil_Grass"
    },
    {
      "x": -31,
      "y": 15,
      "z": -22,
      "name": "Plant_Grass_Jungle_Tall",
      "support": 15
    },
    {
      "x": -31,
      "y": 14,
      "z": -21,
      "name": "Soil_Dirt"
    },
    {
      "x": -31,
      "y": 15,
      "z": -21,
      "name": "Soil_Grass"
    },
    {
      "x": -31,
      "y": 16,
      "z": -21,
      "name": "Plant_Grass_Sharp_Overgrown",
      "support": 15
    },
    {
      "x": -31,
      "y": 17,
      "z": -21,
      "name": "Plant_Grass_Sharp_Overgrown",
      "filler": 1024
    },
    {
      "x": -31,
      "y": 14,
      "z": -20,
      "name": "Soil_Dirt"
    },
    {
      "x": -31,
      "y": 15,
      "z": -20,
      "name": "Soil_Grass"
    },
    {
      "x": -31,
      "y": 14,
      "z": -19,
      "name": "Soil_Dirt"
    },
    {
      "x": -31,
      "y": 15,
      "z": -19,
      "name": "Soil_Grass"
    },
    {
      "x": -31,
      "y": 16,
      "z": -19,
      "name": "Plant_Grass_Jungle_Tall",
      "support": 15
    },
    {
      "x": -31,
      "y": 14,
      "z": -18,
      "name": "Soil_Dirt"
    },
    {
      "x": -31,
      "y": 15,
      "z": -18,
      "name": "Soil_Grass"
    },
    {
      "x": -31,
      "y": 14,
      "z": -17,
      "name": "Soil_Dirt"
    },
    {
      "x": -31,
      "y": 15,
      "z": -17,
      "name": "Soil_Grass"
    },
    {
      "x": -31,
      "y": 14,
      "z": -16,
      "name": "Soil_Grass"
    },
    {
      "x": -31,
      "y": 14,
      "z": -15,
      "name": "Soil_Grass"
    },
    {
      "x": -31,
      "y": 14,
      "z": -14,
      "name": "Soil_Grass"
    },
    {
      "x": -31,
      "y": 14,
      "z": -13,
      "name": "Soil_Grass"
    },
    {
      "x": -31,
      "y": 15,
      "z": -13,
      "name": "Plant_Grass_Sharp_Overgrown",
      "support": 15
    },
    {
      "x": -31,
      "y": 16,
      "z": -13,
      "name": "Plant_Grass_Sharp_Overgrown",
      "filler": 1024
    },
    {
      "x": -31,
      "y": 14,
      "z": -12,
      "name": "Soil_Grass"
    },
    {
      "x": -31,
      "y": 15,
      "z": -12,
      "name": "Plant_Grass_Sharp_Overgrown",
      "support": 15
    },
    {
      "x": -31,
      "y": 16,
      "z": -12,
      "name": "Plant_Grass_Sharp_Overgrown",
      "filler": 1024
    },
    {
      "x": -31,
      "y": 14,
      "z": -11,
      "name": "Soil_Grass"
    },
    {
      "x": -31,
      "y": 14,
      "z": -10,
      "name": "Soil_Grass"
    },
    {
      "x": -31,
      "y": 13,
      "z": -9,
      "name": "Soil_Dirt"
    },
    {
      "x": -31,
      "y": 14,
      "z": -9,
      "name": "Soil_Grass"
    },
    {
      "x": -31,
      "y": 13,
      "z": -8,
      "name": "Soil_Grass"
    },
    {
      "x": -31,
      "y": 13,
      "z": -7,
      "name": "Soil_Grass"
    },
    {
      "x": -31,
      "y": 13,
      "z": -6,
      "name": "Soil_Grass"
    },
    {
      "x": -31,
      "y": 14,
      "z": -6,
      "name": "Plant_Grass_Sharp_Overgrown",
      "support": 15
    },
    {
      "x": -31,
      "y": 15,
      "z": -6,
      "name": "Plant_Grass_Sharp_Overgrown",
      "filler": 1024
    },
    {
      "x": -31,
      "y": 13,
      "z": -5,
      "name": "Soil_Grass"
    },
    {
      "x": -31,
      "y": 14,
      "z": -5,
      "name": "Plant_Grass_Sharp_Overgrown",
      "support": 15
    },
    {
      "x": -31,
      "y": 15,
      "z": -5,
      "name": "Plant_Grass_Sharp_Overgrown",
      "filler": 1024
    },
    {
      "x": -31,
      "y": 13,
      "z": -4,
      "name": "Soil_Grass"
    },
    {
      "x": -31,
      "y": 13,
      "z": -3,
      "name": "Soil_Grass"
    },
    {
      "x": -31,
      "y": 13,
      "z": -2,
      "name": "Soil_Grass"
    },
    {
      "x": -31,
      "y": 14,
      "z": -1,
      "name": "Soil_Grass"
    },
    {
      "x": -31,
      "y": 14,
      "z": 0,
      "name": "Soil_Grass"
    },
    {
      "x": -31,
      "y": 13,
      "z": 1,
      "name": "Soil_Dirt"
    },
    {
      "x": -31,
      "y": 14,
      "z": 1,
      "name": "Soil_Grass"
    },
    {
      "x": -31,
      "y": 13,
      "z": 2,
      "name": "Soil_Grass"
    },
    {
      "x": -31,
      "y": 13,
      "z": 3,
      "name": "Soil_Grass"
    },
    {
      "x": -31,
      "y": 13,
      "z": 4,
      "name": "Soil_Grass"
    },
    {
      "x": -31,
      "y": 13,
      "z": 5,
      "name": "Soil_Grass"
    },
    {
      "x": -31,
      "y": 13,
      "z": 6,
      "name": "Soil_Grass"
    },
    {
      "x": -31,
      "y": 14,
      "z": 6,
      "name": "Plant_Flower_Tall_Yellow"
    },
    {
      "x": -31,
      "y": 13,
      "z": 7,
      "name": "Soil_Grass"
    },
    {
      "x": -31,
      "y": 13,
      "z": 8,
      "name": "Soil_Grass"
    },
    {
      "x": -31,
      "y": 13,
      "z": 9,
      "name": "Soil_Grass"
    },
    {
      "x": -31,
      "y": 13,
      "z": 10,
      "name": "Soil_Grass"
    },
    {
      "x": -31,
      "y": 14,
      "z": 10,
      "name": "Plant_Grass_Sharp_Overgrown",
      "support": 15
    },
    {
      "x": -31,
      "y": 15,
      "z": 10,
      "name": "Plant_Grass_Sharp_Overgrown",
      "filler": 1024
    },
    {
      "x": -31,
      "y": 13,
      "z": 11,
      "name": "Soil_Grass"
    },
    {
      "x": -31,
      "y": 13,
      "z": 12,
      "name": "Soil_Grass"
    },
    {
      "x": -31,
      "y": 13,
      "z": 13,
      "name": "Soil_Grass"
    },
    {
      "x": -31,
      "y": 14,
      "z": 13,
      "name": "Plant_Grass_Sharp_Overgrown",
      "support": 15
    },
    {
      "x": -31,
      "y": 15,
      "z": 13,
      "name": "Plant_Grass_Sharp_Overgrown",
      "filler": 1024
    },
    {
      "x": -31,
      "y": 13,
      "z": 14,
      "name": "Soil_Grass"
    },
    {
      "x": -31,
      "y": 14,
      "z": 14,
      "name": "Plant_Grass_Sharp_Overgrown",
      "support": 15
    },
    {
      "x": -31,
      "y": 15,
      "z": 14,
      "name": "Plant_Grass_Sharp_Overgrown",
      "filler": 1024
    },
    {
      "x": -31,
      "y": 13,
      "z": 15,
      "name": "Soil_Grass"
    },
    {
      "x": -31,
      "y": 14,
      "z": 15,
      "name": "Plant_Grass_Sharp_Overgrown",
      "support": 15
    },
    {
      "x": -31,
      "y": 15,
      "z": 15,
      "name": "Plant_Grass_Sharp_Overgrown",
      "filler": 1024
    },
    {
      "x": -31,
      "y": 13,
      "z": 16,
      "name": "Soil_Grass"
    },
    {
      "x": -31,
      "y": 13,
      "z": 17,
      "name": "Soil_Grass"
    },
    {
      "x": -31,
      "y": 13,
      "z": 18,
      "name": "Soil_Grass"
    },
    {
      "x": -30,
      "y": 13,
      "z": -29,
      "name": "Soil_Dirt"
    },
    {
      "x": -30,
      "y": 14,
      "z": -29,
      "name": "Soil_Grass"
    },
    {
      "x": -30,
      "y": 14,
      "z": -28,
      "name": "Soil_Grass"
    },
    {
      "x": -30,
      "y": 14,
      "z": -27,
      "name": "Soil_Grass"
    },
    {
      "x": -30,
      "y": 15,
      "z": -26,
      "name": "Soil_Grass"
    },
    {
      "x": -30,
      "y": 15,
      "z": -25,
      "name": "Soil_Grass"
    },
    {
      "x": -30,
      "y": 16,
      "z": -25,
      "name": "Plant_Grass_Jungle_Tall",
      "support": 15
    },
    {
      "x": -30,
      "y": 15,
      "z": -24,
      "name": "Soil_Grass"
    },
    {
      "x": -30,
      "y": 16,
      "z": -24,
      "name": "Plant_Grass_Sharp_Overgrown",
      "support": 15
    },
    {
      "x": -30,
      "y": 17,
      "z": -24,
      "name": "Plant_Grass_Sharp_Overgrown",
      "filler": 1024
    },
    {
      "x": -30,
      "y": 15,
      "z": -23,
      "name": "Soil_Grass"
    },
    {
      "x": -30,
      "y": 15,
      "z": -22,
      "name": "Soil_Grass"
    },
    {
      "x": -30,
      "y": 15,
      "z": -21,
      "name": "Soil_Dirt"
    },
    {
      "x": -30,
      "y": 16,
      "z": -21,
      "name": "Soil_Grass"
    },
    {
      "x": -30,
      "y": 17,
      "z": -21,
      "name": "Plant_Grass_Sharp_Wild",
      "support": 15
    },
    {
      "x": -30,
      "y": 18,
      "z": -21,
      "name": "Plant_Grass_Sharp_Wild",
      "filler": 1024
    },
    {
      "x": -30,
      "y": 16,
      "z": -20,
      "name": "Soil_Grass"
    },
    {
      "x": -30,
      "y": 17,
      "z": -20,
      "name": "Plant_Grass_Sharp_Overgrown",
      "support": 15
    },
    {
      "x": -30,
      "y": 18,
      "z": -20,
      "name": "Plant_Grass_Sharp_Overgrown",
      "filler": 1024
    },
    {
      "x": -30,
      "y": 16,
      "z": -19,
      "name": "Soil_Grass"
    },
    {
      "x": -30,
      "y": 16,
      "z": -18,
      "name": "Soil_Grass"
    },
    {
      "x": -30,
      "y": 15,
      "z": -17,
      "name": "Soil_Grass"
    },
    {
      "x": -30,
      "y": 15,
      "z": -16,
      "name": "Soil_Grass"
    },
    {
      "x": -30,
      "y": 15,
      "z": -15,
      "name": "Soil_Grass"
    },
    {
      "x": -30,
      "y": 15,
      "z": -14,
      "name": "Soil_Grass"
    },
    {
      "x": -30,
      "y": 15,
      "z": -13,
      "name": "Soil_Grass"
    },
    {
      "x": -30,
      "y": 16,
      "z": -13,
      "name": "Plant_Grass_Sharp_Overgrown",
      "support": 15
    },
    {
      "x": -30,
      "y": 17,
      "z": -13,
      "name": "Plant_Grass_Sharp_Overgrown",
      "filler": 1024
    },
    {
      "x": -30,
      "y": 15,
      "z": -12,
      "name": "Soil_Grass"
    },
    {
      "x": -30,
      "y": 15,
      "z": -11,
      "name": "Soil_Grass"
    },
    {
      "x": -30,
      "y": 15,
      "z": -10,
      "name": "Soil_Grass"
    },
    {
      "x": -30,
      "y": 14,
      "z": -9,
      "name": "Soil_Grass"
    },
    {
      "x": -30,
      "y": 14,
      "z": -8,
      "name": "Soil_Grass"
    },
    {
      "x": -30,
      "y": 15,
      "z": -8,
      "name": "Plant_Grass_Sharp_Wild",
      "support": 15
    },
    {
      "x": -30,
      "y": 16,
      "z": -8,
      "name": "Plant_Grass_Sharp_Wild",
      "filler": 1024
    },
    {
      "x": -30,
      "y": 14,
      "z": -7,
      "name": "Soil_Grass"
    },
    {
      "x": -30,
      "y": 14,
      "z": -6,
      "name": "Soil_Grass"
    },
    {
      "x": -30,
      "y": 14,
      "z": -5,
      "name": "Soil_Grass"
    },
    {
      "x": -30,
      "y": 14,
      "z": -4,
      "name": "Soil_Grass"
    },
    {
      "x": -30,
      "y": 14,
      "z": -3,
      "name": "Soil_Grass"
    },
    {
      "x": -30,
      "y": 15,
      "z": -3,
      "name": "Plant_Grass_Sharp_Overgrown",
      "support": 15
    },
    {
      "x": -30,
      "y": 16,
      "z": -3,
      "name": "Plant_Grass_Sharp_Overgrown",
      "filler": 1024
    },
    {
      "x": -30,
      "y": 14,
      "z": -2,
      "name": "Soil_Grass"
    },
    {
      "x": -30,
      "y": 14,
      "z": -1,
      "name": "Soil_Grass"
    },
    {
      "x": -30,
      "y": 15,
      "z": -1,
      "name": "Plant_Grass_Sharp_Overgrown",
      "support": 15
    },
    {
      "x": -30,
      "y": 16,
      "z": -1,
      "name": "Plant_Grass_Sharp_Overgrown",
      "filler": 1024
    },
    {
      "x": -30,
      "y": 15,
      "z": 0,
      "name": "Soil_Grass"
    },
    {
      "x": -30,
      "y": 14,
      "z": 1,
      "name": "Soil_Dirt"
    },
    {
      "x": -30,
      "y": 15,
      "z": 1,
      "name": "Soil_Grass"
    },
    {
      "x": -30,
      "y": 14,
      "z": 2,
      "name": "Soil_Grass"
    },
    {
      "x": -30,
      "y": 14,
      "z": 3,
      "name": "Soil_Grass"
    },
    {
      "x": -30,
      "y": 15,
      "z": 3,
      "name": "Plant_Grass_Sharp_Overgrown",
      "support": 15
    },
    {
      "x": -30,
      "y": 16,
      "z": 3,
      "name": "Plant_Grass_Sharp_Overgrown",
      "filler": 1024
    },
    {
      "x": -30,
      "y": 14,
      "z": 4,
      "name": "Soil_Grass"
    },
    {
      "x": -30,
      "y": 14,
      "z": 5,
      "name": "Soil_Grass"
    },
    {
      "x": -30,
      "y": 15,
      "z": 5,
      "name": "Plant_Grass_Jungle_Tall",
      "support": 15
    },
    {
      "x": -30,
      "y": 14,
      "z": 6,
      "name": "Soil_Grass"
    },
    {
      "x": -30,
      "y": 15,
      "z": 6,
      "name": "Plant_Grass_Jungle_Tall",
      "support": 15
    },
    {
      "x": -30,
      "y": 14,
      "z": 7,
      "name": "Soil_Grass"
    },
    {
      "x": -30,
      "y": 15,
      "z": 7,
      "name": "Plant_Grass_Jungle_Tall",
      "support": 15
    },
    {
      "x": -30,
      "y": 14,
      "z": 8,
      "name": "Soil_Grass"
    },
    {
      "x": -30,
      "y": 15,
      "z": 8,
      "name": "Plant_Grass_Jungle_Tall",
      "support": 15
    },
    {
      "x": -30,
      "y": 14,
      "z": 9,
      "name": "Soil_Grass"
    },
    {
      "x": -30,
      "y": 14,
      "z": 10,
      "name": "Soil_Grass"
    },
    {
      "x": -30,
      "y": 15,
      "z": 10,
      "name": "Plant_Grass_Jungle_Tall",
      "support": 15
    },
    {
      "x": -30,
      "y": 14,
      "z": 11,
      "name": "Soil_Grass"
    },
    {
      "x": -30,
      "y": 14,
      "z": 12,
      "name": "Soil_Grass"
    },
    {
      "x": -30,
      "y": 15,
      "z": 12,
      "name": "Plant_Flower_Common_Pink"
    },
    {
      "x": -30,
      "y": 16,
      "z": 12,
      "name": "Plant_Flower_Common_Pink",
      "filler": 1024
    },
    {
      "x": -30,
      "y": 14,
      "z": 13,
      "name": "Soil_Grass"
    },
    {
      "x": -30,
      "y": 15,
      "z": 13,
      "name": "Plant_Grass_Sharp_Wild",
      "support": 15
    },
    {
      "x": -30,
      "y": 16,
      "z": 13,
      "name": "Plant_Grass_Sharp_Wild",
      "filler": 1024
    },
    {
      "x": -30,
      "y": 14,
      "z": 14,
      "name": "Soil_Grass"
    },
    {
      "x": -30,
      "y": 14,
      "z": 15,
      "name": "Soil_Grass"
    },
    {
      "x": -30,
      "y": 14,
      "z": 16,
      "name": "Soil_Grass"
    },
    {
      "x": -30,
      "y": 13,
      "z": 17,
      "name": "Soil_Dirt"
    },
    {
      "x": -30,
      "y": 14,
      "z": 17,
      "name": "Soil_Grass"
    },
    {
      "x": -30,
      "y": 15,
      "z": 17,
      "name": "Plant_Grass_Jungle_Tall",
      "support": 15
    },
    {
      "x": -30,
      "y": 13,
      "z": 18,
      "name": "Soil_Grass"
    },
    {
      "x": -30,
      "y": 13,
      "z": 19,
      "name": "Soil_Grass"
    },
    {
      "x": -29,
      "y": 13,
      "z": -30,
      "name": "Soil_Grass"
    },
    {
      "x": -29,
      "y": 14,
      "z": -29,
      "name": "Soil_Grass"
    },
    {
      "x": -29,
      "y": 14,
      "z": -28,
      "name": "Soil_Grass"
    },
    {
      "x": -29,
      "y": 15,
      "z": -27,
      "name": "Soil_Grass"
    },
    {
      "x": -29,
      "y": 15,
      "z": -26,
      "name": "Soil_Grass"
    },
    {
      "x": -29,
      "y": 16,
      "z": -25,
      "name": "Soil_Dirt"
    },
    {
      "x": -29,
      "y": 17,
      "z": -25,
      "name": "Soil_Grass"
    },
    {
      "x": -29,
      "y": 16,
      "z": -24,
      "name": "Soil_Dirt"
    },
    {
      "x": -29,
      "y": 17,
      "z": -24,
      "name": "Soil_Grass"
    },
    {
      "x": -29,
      "y": 18,
      "z": -24,
      "name": "Plant_Grass_Jungle_Tall",
      "support": 15
    },
    {
      "x": -29,
      "y": 16,
      "z": -23,
      "name": "Soil_Dirt"
    },
    {
      "x": -29,
      "y": 17,
      "z": -23,
      "name": "Soil_Grass"
    },
    {
      "x": -29,
      "y": 18,
      "z": -23,
      "name": "Plant_Grass_Jungle_Tall",
      "support": 15
    },
    {
      "x": -29,
      "y": 16,
      "z": -22,
      "name": "Soil_Grass"
    },
    {
      "x": -29,
      "y": 17,
      "z": -22,
      "name": "Plant_Grass_Jungle_Tall",
      "support": 15
    },
    {
      "x": -29,
      "y": 16,
      "z": -21,
      "name": "Soil_Dirt"
    },
    {
      "x": -29,
      "y": 17,
      "z": -21,
      "name": "Soil_Grass"
    },
    {
      "x": -29,
      "y": 16,
      "z": -20,
      "name": "Soil_Dirt"
    },
    {
      "x": -29,
      "y": 17,
      "z": -20,
      "name": "Soil_Grass"
    },
    {
      "x": -29,
      "y": 16,
      "z": -19,
      "name": "Soil_Dirt"
    },
    {
      "x": -29,
      "y": 17,
      "z": -19,
      "name": "Soil_Grass"
    },
    {
      "x": -29,
      "y": 16,
      "z": -18,
      "name": "Soil_Dirt"
    },
    {
      "x": -29,
      "y": 17,
      "z": -18,
      "name": "Soil_Grass"
    },
    {
      "x": -29,
      "y": 16,
      "z": -17,
      "name": "Soil_Dirt"
    },
    {
      "x": -29,
      "y": 17,
      "z": -17,
      "name": "Soil_Grass"
    },
    {
      "x": -29,
      "y": 16,
      "z": -16,
      "name": "Soil_Grass"
    },
    {
      "x": -29,
      "y": 17,
      "z": -16,
      "name": "Plant_Grass_Jungle_Tall",
      "support": 15
    },
    {
      "x": -29,
      "y": 16,
      "z": -15,
      "name": "Soil_Grass"
    },
    {
      "x": -29,
      "y": 16,
      "z": -14,
      "name": "Soil_Grass"
    },
    {
      "x": -29,
      "y": 16,
      "z": -13,
      "name": "Soil_Grass"
    },
    {
      "x": -29,
      "y": 16,
      "z": -12,
      "name": "Soil_Grass"
    },
    {
      "x": -29,
      "y": 16,
      "z": -11,
      "name": "Soil_Grass"
    },
    {
      "x": -29,
      "y": 17,
      "z": -11,
      "name": "Plant_Grass_Sharp_Overgrown",
      "support": 15
    },
    {
      "x": -29,
      "y": 18,
      "z": -11,
      "name": "Plant_Grass_Sharp_Overgrown",
      "filler": 1024
    },
    {
      "x": -29,
      "y": 15,
      "z": -10,
      "name": "Soil_Grass"
    },
    {
      "x": -29,
      "y": 16,
      "z": -10,
      "name": "Plant_Grass_Sharp_Overgrown",
      "support": 15
    },
    {
      "x": -29,
      "y": 17,
      "z": -10,
      "name": "Plant_Grass_Sharp_Overgrown",
      "filler": 1024
    },
    {
      "x": -29,
      "y": 15,
      "z": -9,
      "name": "Soil_Grass"
    },
    {
      "x": -29,
      "y": 16,
      "z": -9,
      "name": "Plant_Grass_Sharp_Overgrown",
      "support": 15
    },
    {
      "x": -29,
      "y": 17,
      "z": -9,
      "name": "Plant_Grass_Sharp_Overgrown",
      "filler": 1024
    },
    {
      "x": -29,
      "y": 15,
      "z": -8,
      "name": "Soil_Grass"
    },
    {
      "x": -29,
      "y": 16,
      "z": -8,
      "name": "Plant_Grass_Sharp_Overgrown",
      "support": 15
    },
    {
      "x": -29,
      "y": 17,
      "z": -8,
      "name": "Plant_Grass_Sharp_Overgrown",
      "filler": 1024
    },
    {
      "x": -29,
      "y": 15,
      "z": -7,
      "name": "Soil_Grass"
    },
    {
      "x": -29,
      "y": 15,
      "z": -6,
      "name": "Soil_Grass"
    },
    {
      "x": -29,
      "y": 16,
      "z": -6,
      "name": "Plant_Grass_Sharp_Overgrown",
      "support": 15
    },
    {
      "x": -29,
      "y": 17,
      "z": -6,
      "name": "Plant_Grass_Sharp_Overgrown",
      "filler": 1024
    },
    {
      "x": -29,
      "y": 15,
      "z": -5,
      "name": "Soil_Grass"
    },
    {
      "x": -29,
      "y": 15,
      "z": -4,
      "name": "Soil_Grass"
    },
    {
      "x": -29,
      "y": 15,
      "z": -3,
      "name": "Soil_Grass"
    },
    {
      "x": -29,
      "y": 15,
      "z": -2,
      "name": "Soil_Grass"
    },
    {
      "x": -29,
      "y": 15,
      "z": -1,
      "name": "Soil_Grass"
    },
    {
      "x": -29,
      "y": 15,
      "z": 0,
      "name": "Soil_Dirt"
    },
    {
      "x": -29,
      "y": 16,
      "z": 0,
      "name": "Soil_Grass"
    },
    {
      "x": -29,
      "y": 17,
      "z": 0,
      "name": "Plant_Flower_Tall_Yellow"
    },
    {
      "x": -29,
      "y": 14,
      "z": 1,
      "name": "Soil_Dirt"
    },
    {
      "x": -29,
      "y": 15,
      "z": 1,
      "name": "Soil_Dirt"
    },
    {
      "x": -29,
      "y": 16,
      "z": 1,
      "name": "Soil_Grass"
    },
    {
      "x": -29,
      "y": 14,
      "z": 2,
      "name": "Soil_Dirt"
    },
    {
      "x": -29,
      "y": 15,
      "z": 2,
      "name": "Soil_Dirt"
    },
    {
      "x": -29,
      "y": 16,
      "z": 2,
      "name": "Soil_Grass"
    },
    {
      "x": -29,
      "y": 14,
      "z": 3,
      "name": "Soil_Dirt"
    },
    {
      "x": -29,
      "y": 15,
      "z": 3,
      "name": "Soil_Grass"
    },
    {
      "x": -29,
      "y": 14,
      "z": 4,
      "name": "Soil_Dirt"
    },
    {
      "x": -29,
      "y": 15,
      "z": 4,
      "name": "Soil_Grass"
    },
    {
      "x": -29,
      "y": 14,
      "z": 5,
      "name": "Soil_Dirt"
    },
    {
      "x": -29,
      "y": 15,
      "z": 5,
      "name": "Soil_Grass"
    },
    {
      "x": -29,
      "y": 16,
      "z": 5,
      "name": "Plant_Grass_Sharp_Overgrown",
      "support": 15
    },
    {
      "x": -29,
      "y": 17,
      "z": 5,
      "name": "Plant_Grass_Sharp_Overgrown",
      "filler": 1024
    },
    {
      "x": -29,
      "y": 14,
      "z": 6,
      "name": "Soil_Dirt"
    },
    {
      "x": -29,
      "y": 15,
      "z": 6,
      "name": "Soil_Grass"
    },
    {
      "x": -29,
      "y": 14,
      "z": 7,
      "name": "Soil_Dirt"
    },
    {
      "x": -29,
      "y": 15,
      "z": 7,
      "name": "Soil_Grass"
    },
    {
      "x": -29,
      "y": 14,
      "z": 8,
      "name": "Soil_Dirt"
    },
    {
      "x": -29,
      "y": 15,
      "z": 8,
      "name": "Soil_Grass"
    },
    {
      "x": -29,
      "y": 16,
      "z": 8,
      "name": "Plant_Grass_Sharp_Overgrown",
      "support": 15
    },
    {
      "x": -29,
      "y": 17,
      "z": 8,
      "name": "Plant_Grass_Sharp_Overgrown",
      "filler": 1024
    },
    {
      "x": -29,
      "y": 14,
      "z": 9,
      "name": "Soil_Dirt"
    },
    {
      "x": -29,
      "y": 15,
      "z": 9,
      "name": "Soil_Grass"
    },
    {
      "x": -29,
      "y": 16,
      "z": 9,
      "name": "Plant_Grass_Sharp_Overgrown",
      "support": 15
    },
    {
      "x": -29,
      "y": 17,
      "z": 9,
      "name": "Plant_Grass_Sharp_Overgrown",
      "filler": 1024
    },
    {
      "x": -29,
      "y": 14,
      "z": 10,
      "name": "Soil_Dirt"
    },
    {
      "x": -29,
      "y": 15,
      "z": 10,
      "name": "Soil_Grass"
    },
    {
      "x": -29,
      "y": 14,
      "z": 11,
      "name": "Soil_Dirt"
    },
    {
      "x": -29,
      "y": 15,
      "z": 11,
      "name": "Soil_Grass"
    },
    {
      "x": -29,
      "y": 14,
      "z": 12,
      "name": "Soil_Dirt"
    },
    {
      "x": -29,
      "y": 15,
      "z": 12,
      "name": "Soil_Grass"
    },
    {
      "x": -29,
      "y": 14,
      "z": 13,
      "name": "Soil_Dirt"
    },
    {
      "x": -29,
      "y": 15,
      "z": 13,
      "name": "Soil_Grass"
    },
    {
      "x": -29,
      "y": 14,
      "z": 14,
      "name": "Soil_Dirt"
    },
    {
      "x": -29,
      "y": 15,
      "z": 14,
      "name": "Soil_Grass"
    },
    {
      "x": -29,
      "y": 14,
      "z": 15,
      "name": "Soil_Dirt"
    },
    {
      "x": -29,
      "y": 15,
      "z": 15,
      "name": "Soil_Grass"
    },
    {
      "x": -29,
      "y": 16,
      "z": 15,
      "name": "Plant_Grass_Jungle_Tall",
      "support": 15
    },
    {
      "x": -29,
      "y": 14,
      "z": 16,
      "name": "Soil_Dirt"
    },
    {
      "x": -29,
      "y": 15,
      "z": 16,
      "name": "Soil_Grass"
    },
    {
      "x": -29,
      "y": 16,
      "z": 16,
      "name": "Plant_Grass_Sharp_Overgrown",
      "support": 15
    },
    {
      "x": -29,
      "y": 17,
      "z": 16,
      "name": "Plant_Grass_Sharp_Overgrown",
      "filler": 1024
    },
    {
      "x": -29,
      "y": 13,
      "z": 17,
      "name": "Soil_Dirt"
    },
    {
      "x": -29,
      "y": 14,
      "z": 17,
      "name": "Soil_Grass"
    },
    {
      "x": -29,
      "y": 13,
      "z": 18,
      "name": "Soil_Grass"
    },
    {
      "x": -29,
      "y": 14,
      "z": 18,
      "name": "Plant_Grass_Jungle_Tall",
      "support": 15
    },
    {
      "x": -29,
      "y": 13,
      "z": 19,
      "name": "Soil_Grass"
    },
    {
      "x": -29,
      "y": 14,
      "z": 19,
      "name": "Plant_Grass_Sharp_Wild",
      "support": 15
    },
    {
      "x": -29,
      "y": 15,
      "z": 19,
      "name": "Plant_Grass_Sharp_Wild",
      "filler": 1024
    },
    {
      "x": -29,
      "y": 13,
      "z": 20,
      "name": "Soil_Grass"
    },
    {
      "x": -29,
      "y": 13,
      "z": 21,
      "name": "Soil_Grass"
    },
    {
      "x": -28,
      "y": 13,
      "z": -30,
      "name": "Soil_Grass"
    },
    {
      "x": -28,
      "y": 14,
      "z": -29,
      "name": "Soil_Grass"
    },
    {
      "x": -28,
      "y": 14,
      "z": -28,
      "name": "Soil_Grass"
    },
    {
      "x": -28,
      "y": 15,
      "z": -27,
      "name": "Soil_Grass"
    },
    {
      "x": -28,
      "y": 16,
      "z": -27,
      "name": "Plant_Flower_Common_Pink"
    },
    {
      "x": -28,
      "y": 17,
      "z": -27,
      "name": "Plant_Flower_Common_Pink",
      "filler": 1024
    },
    {
      "x": -28,
      "y": 16,
      "z": -26,
      "name": "Soil_Dirt"
    },
    {
      "x": -28,
      "y": 17,
      "z": -26,
      "name": "Soil_Grass"
    },
    {
      "x": -28,
      "y": 16,
      "z": -25,
      "name": "Soil_Dirt"
    },
    {
      "x": -28,
      "y": 17,
      "z": -25,
      "name": "Soil_Dirt"
    },
    {
      "x": -28,
      "y": 18,
      "z": -25,
      "name": "Soil_Grass"
    },
    {
      "x": -28,
      "y": 16,
      "z": -24,
      "name": "Soil_Dirt"
    },
    {
      "x": -28,
      "y": 17,
      "z": -24,
      "name": "Soil_Dirt"
    },
    {
      "x": -28,
      "y": 18,
      "z": -24,
      "name": "Soil_Grass"
    },
    {
      "x": -28,
      "y": 16,
      "z": -23,
      "name": "Soil_Dirt"
    },
    {
      "x": -28,
      "y": 17,
      "z": -23,
      "name": "Soil_Dirt"
    },
    {
      "x": -28,
      "y": 18,
      "z": -23,
      "name": "Soil_Grass"
    },
    {
      "x": -28,
      "y": 15,
      "z": -22,
      "name": "Soil_Dirt"
    },
    {
      "x": -28,
      "y": 16,
      "z": -22,
      "name": "Soil_Dirt"
    },
    {
      "x": -28,
      "y": 17,
      "z": -22,
      "name": "Soil_Dirt"
    },
    {
      "x": -28,
      "y": 18,
      "z": -22,
      "name": "Soil_Grass"
    },
    {
      "x": -28,
      "y": 19,
      "z": -22,
      "name": "Plant_Grass_Jungle_Tall",
      "support": 15
    },
    {
      "x": -28,
      "y": 15,
      "z": -21,
      "name": "Soil_Dirt"
    },
    {
      "x": -28,
      "y": 16,
      "z": -21,
      "name": "Soil_Dirt"
    },
    {
      "x": -28,
      "y": 17,
      "z": -21,
      "name": "Soil_Dirt"
    },
    {
      "x": -28,
      "y": 18,
      "z": -21,
      "name": "Soil_Grass"
    },
    {
      "x": -28,
      "y": 19,
      "z": -21,
      "name": "Plant_Grass_Jungle_Tall",
      "support": 15
    },
    {
      "x": -28,
      "y": 15,
      "z": -20,
      "name": "Soil_Dirt"
    },
    {
      "x": -28,
      "y": 16,
      "z": -20,
      "name": "Soil_Dirt"
    },
    {
      "x": -28,
      "y": 17,
      "z": -20,
      "name": "Soil_Dirt"
    },
    {
      "x": -28,
      "y": 18,
      "z": -20,
      "name": "Soil_Grass"
    },
    {
      "x": -28,
      "y": 19,
      "z": -20,
      "name": "Plant_Flower_Tall_Yellow"
    },
    {
      "x": -28,
      "y": 14,
      "z": -19,
      "name": "Soil_Grass"
    },
    {
      "x": -28,
      "y": 16,
      "z": -19,
      "name": "Soil_Dirt"
    },
    {
      "x": -28,
      "y": 17,
      "z": -19,
      "name": "Soil_Dirt"
    },
    {
      "x": -28,
      "y": 18,
      "z": -19,
      "name": "Soil_Grass"
    },
    {
      "x": -28,
      "y": 14,
      "z": -18,
      "name": "Soil_Grass"
    },
    {
      "x": -28,
      "y": 16,
      "z": -18,
      "name": "Soil_Dirt"
    },
    {
      "x": -28,
      "y": 17,
      "z": -18,
      "name": "Soil_Dirt"
    },
    {
      "x": -28,
      "y": 18,
      "z": -18,
      "name": "Soil_Grass"
    },
    {
      "x": -28,
      "y": 14,
      "z": -17,
      "name": "Soil_Grass"
    },
    {
      "x": -28,
      "y": 16,
      "z": -17,
      "name": "Soil_Dirt"
    },
    {
      "x": -28,
      "y": 17,
      "z": -17,
      "name": "Soil_Dirt"
    },
    {
      "x": -28,
      "y": 18,
      "z": -17,
      "name": "Soil_Grass"
    },
    {
      "x": -28,
      "y": 14,
      "z": -16,
      "name": "Soil_Grass"
    },
    {
      "x": -28,
      "y": 17,
      "z": -16,
      "name": "Soil_Dirt"
    },
    {
      "x": -28,
      "y": 18,
      "z": -16,
      "name": "Soil_Grass"
    },
    {
      "x": -28,
      "y": 14,
      "z": -15,
      "name": "Soil_Grass"
    },
    {
      "x": -28,
      "y": 17,
      "z": -15,
      "name": "Soil_Grass"
    },
    {
      "x": -28,
      "y": 14,
      "z": -14,
      "name": "Soil_Grass"
    },
    {
      "x": -28,
      "y": 17,
      "z": -14,
      "name": "Soil_Grass"
    },
    {
      "x": -28,
      "y": 18,
      "z": -14,
      "name": "Plant_Grass_Jungle_Tall",
      "support": 15
    },
    {
      "x": -28,
      "y": 14,
      "z": -13,
      "name": "Soil_Grass"
    },
    {
      "x": -28,
      "y": 17,
      "z": -13,
      "name": "Soil_Grass"
    },
    {
      "x": -28,
      "y": 14,
      "z": -12,
      "name": "Soil_Grass"
    },
    {
      "x": -28,
      "y": 17,
      "z": -12,
      "name": "Soil_Grass"
    },
    {
      "x": -28,
      "y": 18,
      "z": -12,
      "name": "Plant_Flower_Common_Pink"
    },
    {
      "x": -28,
      "y": 19,
      "z": -12,
      "name": "Plant_Flower_Common_Pink",
      "filler": 1024
    },
    {
      "x": -28,
      "y": 14,
      "z": -11,
      "name": "Soil_Grass"
    },
    {
      "x": -28,
      "y": 16,
      "z": -11,
      "name": "Soil_Dirt"
    },
    {
      "x": -28,
      "y": 17,
      "z": -11,
      "name": "Soil_Grass"
    },
    {
      "x": -28,
      "y": 14,
      "z": -10,
      "name": "Soil_Grass"
    },
    {
      "x": -28,
      "y": 16,
      "z": -10,
      "name": "Soil_Dirt"
    },
    {
      "x": -28,
      "y": 17,
      "z": -10,
      "name": "Soil_Grass"
    },
    {
      "x": -28,
      "y": 18,
      "z": -10,
      "name": "Plant_Grass_Jungle_Tall",
      "support": 15
    },
    {
      "x": -28,
      "y": 14,
      "z": -9,
      "name": "Soil_Grass"
    },
    {
      "x": -28,
      "y": 16,
      "z": -9,
      "name": "Soil_Dirt"
    },
    {
      "x": -28,
      "y": 17,
      "z": -9,
      "name": "Soil_Grass"
    },
    {
      "x": -28,
      "y": 14,
      "z": -8,
      "name": "Soil_Grass"
    },
    {
      "x": -28,
      "y": 16,
      "z": -8,
      "name": "Soil_Dirt"
    },
    {
      "x": -28,
      "y": 17,
      "z": -8,
      "name": "Soil_Dirt"
    },
    {
      "x": -28,
      "y": 18,
      "z": -8,
      "name": "Soil_Grass"
    },
    {
      "x": -28,
      "y": 14,
      "z": -7,
      "name": "Soil_Grass"
    },
    {
      "x": -28,
      "y": 16,
      "z": -7,
      "name": "Soil_Dirt"
    },
    {
      "x": -28,
      "y": 17,
      "z": -7,
      "name": "Soil_Grass"
    },
    {
      "x": -28,
      "y": 14,
      "z": -6,
      "name": "Soil_Grass"
    },
    {
      "x": -28,
      "y": 16,
      "z": -6,
      "name": "Soil_Dirt"
    },
    {
      "x": -28,
      "y": 17,
      "z": -6,
      "name": "Soil_Grass"
    },
    {
      "x": -28,
      "y": 14,
      "z": -5,
      "name": "Soil_Grass"
    },
    {
      "x": -28,
      "y": 16,
      "z": -5,
      "name": "Soil_Dirt"
    },
    {
      "x": -28,
      "y": 17,
      "z": -5,
      "name": "Soil_Grass"
    },
    {
      "x": -28,
      "y": 14,
      "z": -4,
      "name": "Soil_Grass"
    },
    {
      "x": -28,
      "y": 16,
      "z": -4,
      "name": "Soil_Dirt"
    },
    {
      "x": -28,
      "y": 17,
      "z": -4,
      "name": "Soil_Grass"
    },
    {
      "x": -28,
      "y": 14,
      "z": -3,
      "name": "Soil_Grass"
    },
    {
      "x": -28,
      "y": 16,
      "z": -3,
      "name": "Soil_Grass"
    },
    {
      "x": -28,
      "y": 17,
      "z": -3,
      "name": "Plant_Grass_Sharp_Overgrown",
      "support": 15
    },
    {
      "x": -28,
      "y": 18,
      "z": -3,
      "name": "Plant_Grass_Sharp_Overgrown",
      "filler": 1024
    },
    {
      "x": -28,
      "y": 16,
      "z": -2,
      "name": "Soil_Dirt"
    },
    {
      "x": -28,
      "y": 17,
      "z": -2,
      "name": "Soil_Grass"
    },
    {
      "x": -28,
      "y": 16,
      "z": -1,
      "name": "Soil_Grass"
    },
    {
      "x": -28,
      "y": 16,
      "z": 0,
      "name": "Soil_Grass"
    },
    {
      "x": -28,
      "y": 14,
      "z": 1,
      "name": "Soil_Grass"
    },
    {
      "x": -28,
      "y": 16,
      "z": 1,
      "name": "Soil_Dirt"
    },
    {
      "x": -28,
      "y": 17,
      "z": 1,
      "name": "Soil_Grass"
    },
    {
      "x": -28,
      "y": 14,
      "z": 2,
      "name": "Soil_Dirt"
    },
    {
      "x": -28,
      "y": 15,
      "z": 2,
      "name": "Soil_Dirt"
    },
    {
      "x": -28,
      "y": 16,
      "z": 2,
      "name": "Soil_Grass"
    },
    {
      "x": -28,
      "y": 14,
      "z": 3,
      "name": "Soil_Dirt"
    },
    {
      "x": -28,
      "y": 15,
      "z": 3,
      "name": "Soil_Dirt"
    },
    {
      "x": -28,
      "y": 16,
      "z": 3,
      "name": "Soil_Grass"
    },
    {
      "x": -28,
      "y": 14,
      "z": 4,
      "name": "Soil_Dirt"
    },
    {
      "x": -28,
      "y": 15,
      "z": 4,
      "name": "Soil_Dirt"
    },
    {
      "x": -28,
      "y": 16,
      "z": 4,
      "name": "Soil_Grass"
    },
    {
      "x": -28,
      "y": 14,
      "z": 5,
      "name": "Soil_Dirt"
    },
    {
      "x": -28,
      "y": 15,
      "z": 5,
      "name": "Soil_Dirt"
    },
    {
      "x": -28,
      "y": 16,
      "z": 5,
      "name": "Soil_Grass"
    },
    {
      "x": -28,
      "y": 14,
      "z": 6,
      "name": "Soil_Dirt"
    },
    {
      "x": -28,
      "y": 15,
      "z": 6,
      "name": "Soil_Dirt"
    },
    {
      "x": -28,
      "y": 16,
      "z": 6,
      "name": "Soil_Grass"
    },
    {
      "x": -28,
      "y": 14,
      "z": 7,
      "name": "Soil_Dirt"
    },
    {
      "x": -28,
      "y": 15,
      "z": 7,
      "name": "Soil_Dirt"
    },
    {
      "x": -28,
      "y": 16,
      "z": 7,
      "name": "Soil_Grass"
    },
    {
      "x": -28,
      "y": 14,
      "z": 8,
      "name": "Soil_Dirt"
    },
    {
      "x": -28,
      "y": 15,
      "z": 8,
      "name": "Soil_Dirt"
    },
    {
      "x": -28,
      "y": 16,
      "z": 8,
      "name": "Soil_Grass"
    },
    {
      "x": -28,
      "y": 17,
      "z": 8,
      "name": "Plant_Grass_Sharp_Overgrown",
      "support": 15
    },
    {
      "x": -28,
      "y": 18,
      "z": 8,
      "name": "Plant_Grass_Sharp_Overgrown",
      "filler": 1024
    },
    {
      "x": -28,
      "y": 14,
      "z": 9,
      "name": "Soil_Dirt"
    },
    {
      "x": -28,
      "y": 15,
      "z": 9,
      "name": "Soil_Dirt"
    },
    {
      "x": -28,
      "y": 16,
      "z": 9,
      "name": "Soil_Grass"
    },
    {
      "x": -28,
      "y": 14,
      "z": 10,
      "name": "Soil_Dirt"
    },
    {
      "x": -28,
      "y": 15,
      "z": 10,
      "name": "Soil_Dirt"
    },
    {
      "x": -28,
      "y": 16,
      "z": 10,
      "name": "Soil_Grass"
    },
    {
      "x": -28,
      "y": 17,
      "z": 10,
      "name": "Plant_Grass_Jungle_Tall",
      "support": 15
    },
    {
      "x": -28,
      "y": 14,
      "z": 11,
      "name": "Soil_Dirt"
    },
    {
      "x": -28,
      "y": 15,
      "z": 11,
      "name": "Soil_Dirt"
    },
    {
      "x": -28,
      "y": 16,
      "z": 11,
      "name": "Soil_Grass"
    },
    {
      "x": -28,
      "y": 17,
      "z": 11,
      "name": "Plant_Grass_Sharp_Wild",
      "support": 15
    },
    {
      "x": -28,
      "y": 18,
      "z": 11,
      "name": "Plant_Grass_Sharp_Wild",
      "filler": 1024
    },
    {
      "x": -28,
      "y": 14,
      "z": 12,
      "name": "Soil_Dirt"
    },
    {
      "x": -28,
      "y": 15,
      "z": 12,
      "name": "Soil_Dirt"
    },
    {
      "x": -28,
      "y": 16,
      "z": 12,
      "name": "Soil_Grass"
    },
    {
      "x": -28,
      "y": 14,
      "z": 13,
      "name": "Soil_Dirt"
    },
    {
      "x": -28,
      "y": 15,
      "z": 13,
      "name": "Soil_Dirt"
    },
    {
      "x": -28,
      "y": 16,
      "z": 13,
      "name": "Soil_Grass"
    },
    {
      "x": -28,
      "y": 14,
      "z": 14,
      "name": "Soil_Dirt"
    },
    {
      "x": -28,
      "y": 15,
      "z": 14,
      "name": "Soil_Dirt"
    },
    {
      "x": -28,
      "y": 16,
      "z": 14,
      "name": "Soil_Grass"
    },
    {
      "x": -28,
      "y": 14,
      "z": 15,
      "name": "Soil_Dirt"
    },
    {
      "x": -28,
      "y": 15,
      "z": 15,
      "name": "Soil_Dirt"
    },
    {
      "x": -28,
      "y": 16,
      "z": 15,
      "name": "Soil_Grass"
    },
    {
      "x": -28,
      "y": 14,
      "z": 16,
      "name": "Soil_Dirt"
    },
    {
      "x": -28,
      "y": 15,
      "z": 16,
      "name": "Soil_Grass"
    },
    {
      "x": -28,
      "y": 14,
      "z": 17,
      "name": "Soil_Dirt"
    },
    {
      "x": -28,
      "y": 15,
      "z": 17,
      "name": "Soil_Grass"
    },
    {
      "x": -28,
      "y": 14,
      "z": 18,
      "name": "Soil_Dirt"
    },
    {
      "x": -28,
      "y": 15,
      "z": 18,
      "name": "Soil_Grass"
    },
    {
      "x": -28,
      "y": 16,
      "z": 18,
      "name": "Plant_Flower_Bushy_Purple"
    },
    {
      "x": -28,
      "y": 14,
      "z": 19,
      "name": "Soil_Grass"
    },
    {
      "x": -28,
      "y": 13,
      "z": 20,
      "name": "Soil_Dirt"
    },
    {
      "x": -28,
      "y": 14,
      "z": 20,
      "name": "Soil_Grass"
    },
    {
      "x": -28,
      "y": 15,
      "z": 20,
      "name": "Plant_Grass_Sharp_Overgrown",
      "support": 15
    },
    {
      "x": -28,
      "y": 16,
      "z": 20,
      "name": "Plant_Grass_Sharp_Overgrown",
      "filler": 1024
    },
    {
      "x": -28,
      "y": 13,
      "z": 21,
      "name": "Soil_Grass"
    },
    {
      "x": -28,
      "y": 13,
      "z": 22,
      "name": "Soil_Grass"
    },
    {
      "x": -28,
      "y": 13,
      "z": 23,
      "name": "Soil_Grass"
    },
    {
      "x": -28,
      "y": 13,
      "z": 24,
      "name": "Soil_Grass"
    },
    {
      "x": -28,
      "y": 13,
      "z": 25,
      "name": "Soil_Grass"
    },
    {
      "x": -27,
      "y": 13,
      "z": -31,
      "name": "Soil_Grass"
    },
    {
      "x": -27,
      "y": 14,
      "z": -31,
      "name": "Plant_Grass_Jungle_Tall",
      "support": 15
    },
    {
      "x": -27,
      "y": 13,
      "z": -30,
      "name": "Soil_Grass"
    },
    {
      "x": -27,
      "y": 14,
      "z": -30,
      "name": "Plant_Grass_Jungle_Tall",
      "support": 15
    },
    {
      "x": -27,
      "y": 14,
      "z": -29,
      "name": "Soil_Grass"
    },
    {
      "x": -27,
      "y": 14,
      "z": -28,
      "name": "Soil_Grass"
    },
    {
      "x": -27,
      "y": 15,
      "z": -27,
      "name": "Soil_Grass"
    },
    {
      "x": -27,
      "y": 16,
      "z": -26,
      "name": "Soil_Dirt"
    },
    {
      "x": -27,
      "y": 17,
      "z": -26,
      "name": "Soil_Dirt"
    },
    {
      "x": -27,
      "y": 18,
      "z": -26,
      "name": "Soil_Grass"
    },
    {
      "x": -27,
      "y": 16,
      "z": -25,
      "name": "Soil_Dirt"
    },
    {
      "x": -27,
      "y": 17,
      "z": -25,
      "name": "Soil_Dirt"
    },
    {
      "x": -27,
      "y": 18,
      "z": -25,
      "name": "Soil_Dirt"
    },
    {
      "x": -27,
      "y": 19,
      "z": -25,
      "name": "Soil_Grass"
    },
    {
      "x": -27,
      "y": 20,
      "z": -25,
      "name": "Plant_Grass_Sharp_Overgrown",
      "support": 15
    },
    {
      "x": -27,
      "y": 21,
      "z": -25,
      "name": "Plant_Grass_Sharp_Overgrown",
      "filler": 1024
    },
    {
      "x": -27,
      "y": 15,
      "z": -24,
      "name": "Soil_Dirt"
    },
    {
      "x": -27,
      "y": 16,
      "z": -24,
      "name": "Soil_Dirt"
    },
    {
      "x": -27,
      "y": 17,
      "z": -24,
      "name": "Soil_Dirt"
    },
    {
      "x": -27,
      "y": 18,
      "z": -24,
      "name": "Soil_Dirt"
    },
    {
      "x": -27,
      "y": 19,
      "z": -24,
      "name": "Soil_Grass"
    },
    {
      "x": -27,
      "y": 15,
      "z": -23,
      "name": "Soil_Dirt"
    },
    {
      "x": -27,
      "y": 16,
      "z": -23,
      "name": "Soil_Dirt"
    },
    {
      "x": -27,
      "y": 17,
      "z": -23,
      "name": "Soil_Dirt"
    },
    {
      "x": -27,
      "y": 18,
      "z": -23,
      "name": "Soil_Dirt"
    },
    {
      "x": -27,
      "y": 19,
      "z": -23,
      "name": "Soil_Grass"
    },
    {
      "x": -27,
      "y": 15,
      "z": -22,
      "name": "Soil_Dirt"
    },
    {
      "x": -27,
      "y": 16,
      "z": -22,
      "name": "Soil_Dirt"
    },
    {
      "x": -27,
      "y": 17,
      "z": -22,
      "name": "Soil_Dirt"
    },
    {
      "x": -27,
      "y": 18,
      "z": -22,
      "name": "Soil_Dirt"
    },
    {
      "x": -27,
      "y": 19,
      "z": -22,
      "name": "Soil_Grass"
    },
    {
      "x": -27,
      "y": 20,
      "z": -22,
      "name": "Plant_Grass_Jungle_Tall",
      "support": 15
    },
    {
      "x": -27,
      "y": 15,
      "z": -21,
      "name": "Soil_Dirt"
    },
    {
      "x": -27,
      "y": 16,
      "z": -21,
      "name": "Soil_Dirt"
    },
    {
      "x": -27,
      "y": 17,
      "z": -21,
      "name": "Soil_Dirt"
    },
    {
      "x": -27,
      "y": 18,
      "z": -21,
      "name": "Soil_Dirt"
    },
    {
      "x": -27,
      "y": 19,
      "z": -21,
      "name": "Soil_Grass"
    },
    {
      "x": -27,
      "y": 15,
      "z": -20,
      "name": "Soil_Dirt"
    },
    {
      "x": -27,
      "y": 16,
      "z": -20,
      "name": "Soil_Dirt"
    },
    {
      "x": -27,
      "y": 17,
      "z": -20,
      "name": "Soil_Dirt"
    },
    {
      "x": -27,
      "y": 18,
      "z": -20,
      "name": "Soil_Dirt"
    },
    {
      "x": -27,
      "y": 19,
      "z": -20,
      "name": "Soil_Grass"
    },
    {
      "x": -27,
      "y": 14,
      "z": -19,
      "name": "Soil_Dirt"
    },
    {
      "x": -27,
      "y": 15,
      "z": -19,
      "name": "Soil_Dirt"
    },
    {
      "x": -27,
      "y": 16,
      "z": -19,
      "name": "Soil_Dirt"
    },
    {
      "x": -27,
      "y": 17,
      "z": -19,
      "name": "Soil_Dirt"
    },
    {
      "x": -27,
      "y": 18,
      "z": -19,
      "name": "Soil_Dirt"
    },
    {
      "x": -27,
      "y": 19,
      "z": -19,
      "name": "Soil_Grass"
    },
    {
      "x": -27,
      "y": 14,
      "z": -18,
      "name": "Soil_Dirt"
    },
    {
      "x": -27,
      "y": 15,
      "z": -18,
      "name": "Soil_Dirt"
    },
    {
      "x": -27,
      "y": 16,
      "z": -18,
      "name": "Soil_Dirt"
    },
    {
      "x": -27,
      "y": 17,
      "z": -18,
      "name": "Soil_Dirt"
    },
    {
      "x": -27,
      "y": 18,
      "z": -18,
      "name": "Soil_Dirt"
    },
    {
      "x": -27,
      "y": 19,
      "z": -18,
      "name": "Soil_Grass"
    },
    {
      "x": -27,
      "y": 14,
      "z": -17,
      "name": "Soil_Dirt"
    },
    {
      "x": -27,
      "y": 15,
      "z": -17,
      "name": "Soil_Dirt"
    },
    {
      "x": -27,
      "y": 16,
      "z": -17,
      "name": "Soil_Dirt"
    },
    {
      "x": -27,
      "y": 17,
      "z": -17,
      "name": "Soil_Dirt"
    },
    {
      "x": -27,
      "y": 18,
      "z": -17,
      "name": "Soil_Dirt"
    },
    {
      "x": -27,
      "y": 19,
      "z": -17,
      "name": "Soil_Grass"
    },
    {
      "x": -27,
      "y": 14,
      "z": -16,
      "name": "Soil_Dirt"
    },
    {
      "x": -27,
      "y": 15,
      "z": -16,
      "name": "Soil_Dirt"
    },
    {
      "x": -27,
      "y": 16,
      "z": -16,
      "name": "Soil_Dirt"
    },
    {
      "x": -27,
      "y": 17,
      "z": -16,
      "name": "Soil_Dirt"
    },
    {
      "x": -27,
      "y": 18,
      "z": -16,
      "name": "Soil_Dirt"
    },
    {
      "x": -27,
      "y": 19,
      "z": -16,
      "name": "Soil_Grass"
    },
    {
      "x": -27,
      "y": 14,
      "z": -15,
      "name": "Soil_Dirt"
    },
    {
      "x": -27,
      "y": 15,
      "z": -15,
      "name": "Soil_Grass"
    },
    {
      "x": -27,
      "y": 17,
      "z": -15,
      "name": "Soil_Dirt"
    },
    {
      "x": -27,
      "y": 18,
      "z": -15,
      "name": "Soil_Dirt"
    },
    {
      "x": -27,
      "y": 19,
      "z": -15,
      "name": "Soil_Grass"
    },
    {
      "x": -27,
      "y": 14,
      "z": -14,
      "name": "Soil_Dirt"
    },
    {
      "x": -27,
      "y": 15,
      "z": -14,
      "name": "Soil_Grass"
    },
    {
      "x": -27,
      "y": 18,
      "z": -14,
      "name": "Soil_Grass"
    },
    {
      "x": -27,
      "y": 14,
      "z": -13,
      "name": "Soil_Dirt"
    },
    {
      "x": -27,
      "y": 15,
      "z": -13,
      "name": "Soil_Grass"
    },
    {
      "x": -27,
      "y": 18,
      "z": -13,
      "name": "Soil_Grass"
    },
    {
      "x": -27,
      "y": 14,
      "z": -12,
      "name": "Soil_Dirt"
    },
    {
      "x": -27,
      "y": 15,
      "z": -12,
      "name": "Soil_Grass"
    },
    {
      "x": -27,
      "y": 18,
      "z": -12,
      "name": "Soil_Grass"
    },
    {
      "x": -27,
      "y": 14,
      "z": -11,
      "name": "Soil_Dirt"
    },
    {
      "x": -27,
      "y": 15,
      "z": -11,
      "name": "Soil_Grass"
    },
    {
      "x": -27,
      "y": 18,
      "z": -11,
      "name": "Soil_Grass"
    },
    {
      "x": -27,
      "y": 14,
      "z": -10,
      "name": "Soil_Dirt"
    },
    {
      "x": -27,
      "y": 15,
      "z": -10,
      "name": "Soil_Grass"
    },
    {
      "x": -27,
      "y": 17,
      "z": -10,
      "name": "Soil_Dirt"
    },
    {
      "x": -27,
      "y": 18,
      "z": -10,
      "name": "Soil_Dirt"
    },
    {
      "x": -27,
      "y": 19,
      "z": -10,
      "name": "Soil_Grass"
    },
    {
      "x": -27,
      "y": 14,
      "z": -9,
      "name": "Soil_Dirt"
    },
    {
      "x": -27,
      "y": 15,
      "z": -9,
      "name": "Soil_Grass"
    },
    {
      "x": -27,
      "y": 17,
      "z": -9,
      "name": "Soil_Dirt"
    },
    {
      "x": -27,
      "y": 18,
      "z": -9,
      "name": "Soil_Dirt"
    },
    {
      "x": -27,
      "y": 19,
      "z": -9,
      "name": "Soil_Grass"
    },
    {
      "x": -27,
      "y": 14,
      "z": -8,
      "name": "Soil_Dirt"
    },
    {
      "x": -27,
      "y": 15,
      "z": -8,
      "name": "Soil_Dirt"
    },
    {
      "x": -27,
      "y": 16,
      "z": -8,
      "name": "Soil_Dirt"
    },
    {
      "x": -27,
      "y": 17,
      "z": -8,
      "name": "Soil_Dirt"
    },
    {
      "x": -27,
      "y": 18,
      "z": -8,
      "name": "Soil_Dirt"
    },
    {
      "x": -27,
      "y": 19,
      "z": -8,
      "name": "Soil_Dirt"
    },
    {
      "x": -27,
      "y": 20,
      "z": -8,
      "name": "Soil_Grass"
    },
    {
      "x": -27,
      "y": 14,
      "z": -7,
      "name": "Soil_Dirt"
    },
    {
      "x": -27,
      "y": 15,
      "z": -7,
      "name": "Soil_Dirt"
    },
    {
      "x": -27,
      "y": 16,
      "z": -7,
      "name": "Soil_Dirt"
    },
    {
      "x": -27,
      "y": 17,
      "z": -7,
      "name": "Soil_Dirt"
    },
    {
      "x": -27,
      "y": 18,
      "z": -7,
      "name": "Soil_Dirt"
    },
    {
      "x": -27,
      "y": 19,
      "z": -7,
      "name": "Soil_Dirt"
    },
    {
      "x": -27,
      "y": 20,
      "z": -7,
      "name": "Soil_Grass"
    },
    {
      "x": -27,
      "y": 21,
      "z": -7,
      "name": "Plant_Grass_Jungle_Tall",
      "support": 15
    },
    {
      "x": -27,
      "y": 14,
      "z": -6,
      "name": "Soil_Dirt"
    },
    {
      "x": -27,
      "y": 15,
      "z": -6,
      "name": "Soil_Dirt"
    },
    {
      "x": -27,
      "y": 16,
      "z": -6,
      "name": "Soil_Dirt"
    },
    {
      "x": -27,
      "y": 17,
      "z": -6,
      "name": "Soil_Dirt"
    },
    {
      "x": -27,
      "y": 18,
      "z": -6,
      "name": "Soil_Dirt"
    },
    {
      "x": -27,
      "y": 19,
      "z": -6,
      "name": "Soil_Dirt"
    },
    {
      "x": -27,
      "y": 20,
      "z": -6,
      "name": "Soil_Grass"
    },
    {
      "x": -27,
      "y": 14,
      "z": -5,
      "name": "Soil_Dirt"
    },
    {
      "x": -27,
      "y": 15,
      "z": -5,
      "name": "Soil_Dirt"
    },
    {
      "x": -27,
      "y": 16,
      "z": -5,
      "name": "Soil_Dirt"
    },
    {
      "x": -27,
      "y": 17,
      "z": -5,
      "name": "Soil_Dirt"
    },
    {
      "x": -27,
      "y": 18,
      "z": -5,
      "name": "Soil_Dirt"
    },
    {
      "x": -27,
      "y": 19,
      "z": -5,
      "name": "Soil_Dirt"
    },
    {
      "x": -27,
      "y": 20,
      "z": -5,
      "name": "Soil_Grass"
    },
    {
      "x": -27,
      "y": 14,
      "z": -4,
      "name": "Soil_Dirt"
    },
    {
      "x": -27,
      "y": 15,
      "z": -4,
      "name": "Soil_Dirt"
    },
    {
      "x": -27,
      "y": 16,
      "z": -4,
      "name": "Soil_Dirt"
    },
    {
      "x": -27,
      "y": 17,
      "z": -4,
      "name": "Soil_Dirt"
    },
    {
      "x": -27,
      "y": 18,
      "z": -4,
      "name": "Soil_Dirt"
    },
    {
      "x": -27,
      "y": 19,
      "z": -4,
      "name": "Soil_Dirt"
    },
    {
      "x": -27,
      "y": 20,
      "z": -4,
      "name": "Soil_Grass"
    },
    {
      "x": -27,
      "y": 14,
      "z": -3,
      "name": "Soil_Grass"
    },
    {
      "x": -27,
      "y": 17,
      "z": -3,
      "name": "Soil_Dirt"
    },
    {
      "x": -27,
      "y": 18,
      "z": -3,
      "name": "Soil_Dirt"
    },
    {
      "x": -27,
      "y": 19,
      "z": -3,
      "name": "Soil_Grass"
    },
    {
      "x": -27,
      "y": 20,
      "z": -3,
      "name": "Plant_Grass_Sharp_Overgrown",
      "support": 15
    },
    {
      "x": -27,
      "y": 21,
      "z": -3,
      "name": "Plant_Grass_Sharp_Overgrown",
      "filler": 1024
    },
    {
      "x": -27,
      "y": 17,
      "z": -2,
      "name": "Soil_Dirt"
    },
    {
      "x": -27,
      "y": 18,
      "z": -2,
      "name": "Soil_Dirt"
    },
    {
      "x": -27,
      "y": 19,
      "z": -2,
      "name": "Soil_Grass"
    },
    {
      "x": -27,
      "y": 17,
      "z": -1,
      "name": "Soil_Grass"
    },
    {
      "x": -27,
      "y": 17,
      "z": 0,
      "name": "Soil_Grass"
    },
    {
      "x": -27,
      "y": 14,
      "z": 1,
      "name": "Soil_Grass"
    },
    {
      "x": -27,
      "y": 17,
      "z": 1,
      "name": "Soil_Grass"
    },
    {
      "x": -27,
      "y": 14,
      "z": 2,
      "name": "Soil_Dirt"
    },
    {
      "x": -27,
      "y": 15,
      "z": 2,
      "name": "Soil_Grass"
    },
    {
      "x": -27,
      "y": 17,
      "z": 2,
      "name": "Soil_Grass"
    },
    {
      "x": -27,
      "y": 14,
      "z": 3,
      "name": "Soil_Dirt"
    },
    {
      "x": -27,
      "y": 15,
      "z": 3,
      "name": "Soil_Dirt"
    },
    {
      "x": -27,
      "y": 16,
      "z": 3,
      "name": "Soil_Dirt"
    },
    {
      "x": -27,
      "y": 17,
      "z": 3,
      "name": "Soil_Grass"
    },
    {
      "x": -27,
      "y": 14,
      "z": 4,
      "name": "Soil_Dirt"
    },
    {
      "x": -27,
      "y": 15,
      "z": 4,
      "name": "Soil_Dirt"
    },
    {
      "x": -27,
      "y": 16,
      "z": 4,
      "name": "Soil_Dirt"
    },
    {
      "x": -27,
      "y": 17,
      "z": 4,
      "name": "Soil_Grass"
    },
    {
      "x": -27,
      "y": 18,
      "z": 4,
      "name": "Plant_Grass_Sharp_Overgrown",
      "support": 15
    },
    {
      "x": -27,
      "y": 19,
      "z": 4,
      "name": "Plant_Grass_Sharp_Overgrown",
      "filler": 1024
    },
    {
      "x": -27,
      "y": 14,
      "z": 5,
      "name": "Soil_Dirt"
    },
    {
      "x": -27,
      "y": 15,
      "z": 5,
      "name": "Soil_Dirt"
    },
    {
      "x": -27,
      "y": 16,
      "z": 5,
      "name": "Soil_Dirt"
    },
    {
      "x": -27,
      "y": 17,
      "z": 5,
      "name": "Soil_Grass"
    },
    {
      "x": -27,
      "y": 18,
      "z": 5,
      "name": "Plant_Grass_Sharp_Overgrown",
      "support": 15
    },
    {
      "x": -27,
      "y": 19,
      "z": 5,
      "name": "Plant_Grass_Sharp_Overgrown",
      "filler": 1024
    },
    {
      "x": -27,
      "y": 14,
      "z": 6,
      "name": "Soil_Dirt"
    },
    {
      "x": -27,
      "y": 15,
      "z": 6,
      "name": "Soil_Dirt"
    },
    {
      "x": -27,
      "y": 16,
      "z": 6,
      "name": "Soil_Dirt"
    },
    {
      "x": -27,
      "y": 17,
      "z": 6,
      "name": "Soil_Grass"
    },
    {
      "x": -27,
      "y": 18,
      "z": 6,
      "name": "Plant_Grass_Sharp_Overgrown",
      "support": 15
    },
    {
      "x": -27,
      "y": 19,
      "z": 6,
      "name": "Plant_Grass_Sharp_Overgrown",
      "filler": 1024
    },
    {
      "x": -27,
      "y": 14,
      "z": 7,
      "name": "Soil_Dirt"
    },
    {
      "x": -27,
      "y": 15,
      "z": 7,
      "name": "Soil_Dirt"
    },
    {
      "x": -27,
      "y": 16,
      "z": 7,
      "name": "Soil_Dirt"
    },
    {
      "x": -27,
      "y": 17,
      "z": 7,
      "name": "Soil_Grass"
    },
    {
      "x": -27,
      "y": 14,
      "z": 8,
      "name": "Soil_Dirt"
    },
    {
      "x": -27,
      "y": 15,
      "z": 8,
      "name": "Soil_Dirt"
    },
    {
      "x": -27,
      "y": 16,
      "z": 8,
      "name": "Soil_Dirt"
    },
    {
      "x": -27,
      "y": 17,
      "z": 8,
      "name": "Soil_Grass"
    },
    {
      "x": -27,
      "y": 14,
      "z": 9,
      "name": "Soil_Dirt"
    },
    {
      "x": -27,
      "y": 15,
      "z": 9,
      "name": "Soil_Dirt"
    },
    {
      "x": -27,
      "y": 16,
      "z": 9,
      "name": "Soil_Dirt"
    },
    {
      "x": -27,
      "y": 17,
      "z": 9,
      "name": "Soil_Grass"
    },
    {
      "x": -27,
      "y": 18,
      "z": 9,
      "name": "Plant_Grass_Sharp_Overgrown",
      "support": 15
    },
    {
      "x": -27,
      "y": 19,
      "z": 9,
      "name": "Plant_Grass_Sharp_Overgrown",
      "filler": 1024
    },
    {
      "x": -27,
      "y": 14,
      "z": 10,
      "name": "Soil_Dirt"
    },
    {
      "x": -27,
      "y": 15,
      "z": 10,
      "name": "Soil_Dirt"
    },
    {
      "x": -27,
      "y": 16,
      "z": 10,
      "name": "Soil_Dirt"
    },
    {
      "x": -27,
      "y": 17,
      "z": 10,
      "name": "Soil_Grass"
    },
    {
      "x": -27,
      "y": 14,
      "z": 11,
      "name": "Soil_Dirt"
    },
    {
      "x": -27,
      "y": 15,
      "z": 11,
      "name": "Soil_Dirt"
    },
    {
      "x": -27,
      "y": 16,
      "z": 11,
      "name": "Soil_Dirt"
    },
    {
      "x": -27,
      "y": 17,
      "z": 11,
      "name": "Soil_Grass"
    },
    {
      "x": -27,
      "y": 14,
      "z": 12,
      "name": "Soil_Dirt"
    },
    {
      "x": -27,
      "y": 15,
      "z": 12,
      "name": "Soil_Dirt"
    },
    {
      "x": -27,
      "y": 16,
      "z": 12,
      "name": "Soil_Dirt"
    },
    {
      "x": -27,
      "y": 17,
      "z": 12,
      "name": "Soil_Grass"
    },
    {
      "x": -27,
      "y": 18,
      "z": 12,
      "name": "Plant_Grass_Sharp_Overgrown",
      "support": 15
    },
    {
      "x": -27,
      "y": 19,
      "z": 12,
      "name": "Plant_Grass_Sharp_Overgrown",
      "filler": 1024
    },
    {
      "x": -27,
      "y": 14,
      "z": 13,
      "name": "Soil_Dirt"
    },
    {
      "x": -27,
      "y": 15,
      "z": 13,
      "name": "Soil_Dirt"
    },
    {
      "x": -27,
      "y": 16,
      "z": 13,
      "name": "Soil_Dirt"
    },
    {
      "x": -27,
      "y": 17,
      "z": 13,
      "name": "Soil_Grass"
    },
    {
      "x": -27,
      "y": 14,
      "z": 14,
      "name": "Soil_Dirt"
    },
    {
      "x": -27,
      "y": 15,
      "z": 14,
      "name": "Soil_Dirt"
    },
    {
      "x": -27,
      "y": 16,
      "z": 14,
      "name": "Soil_Dirt"
    },
    {
      "x": -27,
      "y": 17,
      "z": 14,
      "name": "Soil_Grass"
    },
    {
      "x": -27,
      "y": 14,
      "z": 15,
      "name": "Soil_Dirt"
    },
    {
      "x": -27,
      "y": 15,
      "z": 15,
      "name": "Soil_Dirt"
    },
    {
      "x": -27,
      "y": 16,
      "z": 15,
      "name": "Soil_Grass"
    },
    {
      "x": -27,
      "y": 17,
      "z": 15,
      "name": "Plant_Grass_Sharp_Overgrown",
      "support": 15
    },
    {
      "x": -27,
      "y": 18,
      "z": 15,
      "name": "Plant_Grass_Sharp_Overgrown",
      "filler": 1024
    },
    {
      "x": -27,
      "y": 14,
      "z": 16,
      "name": "Soil_Dirt"
    },
    {
      "x": -27,
      "y": 15,
      "z": 16,
      "name": "Soil_Dirt"
    },
    {
      "x": -27,
      "y": 16,
      "z": 16,
      "name": "Soil_Grass"
    },
    {
      "x": -27,
      "y": 17,
      "z": 16,
      "name": "Plant_Grass_Jungle_Tall",
      "support": 15
    },
    {
      "x": -27,
      "y": 14,
      "z": 17,
      "name": "Soil_Grass"
    },
    {
      "x": -27,
      "y": 16,
      "z": 17,
      "name": "Soil_Grass"
    },
    {
      "x": -27,
      "y": 17,
      "z": 17,
      "name": "Plant_Grass_Jungle_Tall",
      "support": 15
    },
    {
      "x": -27,
      "y": 14,
      "z": 18,
      "name": "Soil_Grass"
    },
    {
      "x": -27,
      "y": 16,
      "z": 18,
      "name": "Soil_Grass"
    },
    {
      "x": -27,
      "y": 14,
      "z": 19,
      "name": "Soil_Dirt"
    },
    {
      "x": -27,
      "y": 15,
      "z": 19,
      "name": "Soil_Grass"
    },
    {
      "x": -27,
      "y": 14,
      "z": 20,
      "name": "Soil_Dirt"
    },
    {
      "x": -27,
      "y": 15,
      "z": 20,
      "name": "Soil_Grass"
    },
    {
      "x": -27,
      "y": 14,
      "z": 21,
      "name": "Soil_Grass"
    },
    {
      "x": -27,
      "y": 15,
      "z": 21,
      "name": "Plant_Grass_Sharp_Overgrown",
      "support": 15
    },
    {
      "x": -27,
      "y": 16,
      "z": 21,
      "name": "Plant_Grass_Sharp_Overgrown",
      "filler": 1024
    },
    {
      "x": -27,
      "y": 14,
      "z": 22,
      "name": "Soil_Grass"
    },
    {
      "x": -27,
      "y": 14,
      "z": 23,
      "name": "Soil_Grass"
    },
    {
      "x": -27,
      "y": 13,
      "z": 24,
      "name": "Soil_Dirt"
    },
    {
      "x": -27,
      "y": 14,
      "z": 24,
      "name": "Soil_Grass"
    },
    {
      "x": -27,
      "y": 13,
      "z": 25,
      "name": "Soil_Grass"
    },
    {
      "x": -27,
      "y": 13,
      "z": 26,
      "name": "Soil_Grass"
    },
    {
      "x": -27,
      "y": 13,
      "z": 27,
      "name": "Soil_Grass"
    },
    {
      "x": -26,
      "y": 13,
      "z": -32,
      "name": "Soil_Grass"
    },
    {
      "x": -26,
      "y": 13,
      "z": -31,
      "name": "Soil_Grass"
    },
    {
      "x": -26,
      "y": 14,
      "z": -30,
      "name": "Soil_Grass"
    },
    {
      "x": -26,
      "y": 15,
      "z": -30,
      "name": "Plant_Grass_Jungle_Tall",
      "support": 15
    },
    {
      "x": -26,
      "y": 14,
      "z": -29,
      "name": "Soil_Grass"
    },
    {
      "x": -26,
      "y": 15,
      "z": -28,
      "name": "Soil_Grass"
    },
    {
      "x": -26,
      "y": 15,
      "z": -27,
      "name": "Soil_Dirt"
    },
    {
      "x": -26,
      "y": 16,
      "z": -27,
      "name": "Soil_Grass"
    },
    {
      "x": -26,
      "y": 16,
      "z": -26,
      "name": "Soil_Dirt"
    },
    {
      "x": -26,
      "y": 17,
      "z": -26,
      "name": "Soil_Dirt"
    },
    {
      "x": -26,
      "y": 18,
      "z": -26,
      "name": "Soil_Grass"
    },
    {
      "x": -26,
      "y": 15,
      "z": -25,
      "name": "Soil_Dirt"
    },
    {
      "x": -26,
      "y": 16,
      "z": -25,
      "name": "Soil_Dirt"
    },
    {
      "x": -26,
      "y": 17,
      "z": -25,
      "name": "Soil_Dirt"
    },
    {
      "x": -26,
      "y": 18,
      "z": -25,
      "name": "Soil_Dirt"
    },
    {
      "x": -26,
      "y": 19,
      "z": -25,
      "name": "Soil_Grass"
    },
    {
      "x": -26,
      "y": 15,
      "z": -24,
      "name": "Soil_Dirt"
    },
    {
      "x": -26,
      "y": 16,
      "z": -24,
      "name": "Soil_Dirt"
    },
    {
      "x": -26,
      "y": 17,
      "z": -24,
      "name": "Soil_Dirt"
    },
    {
      "x": -26,
      "y": 18,
      "z": -24,
      "name": "Soil_Dirt"
    },
    {
      "x": -26,
      "y": 19,
      "z": -24,
      "name": "Soil_Dirt"
    },
    {
      "x": -26,
      "y": 20,
      "z": -24,
      "name": "Soil_Grass"
    },
    {
      "x": -26,
      "y": 15,
      "z": -23,
      "name": "Soil_Dirt"
    },
    {
      "x": -26,
      "y": 16,
      "z": -23,
      "name": "Soil_Dirt"
    },
    {
      "x": -26,
      "y": 17,
      "z": -23,
      "name": "Soil_Dirt"
    },
    {
      "x": -26,
      "y": 18,
      "z": -23,
      "name": "Soil_Dirt"
    },
    {
      "x": -26,
      "y": 19,
      "z": -23,
      "name": "Soil_Dirt"
    },
    {
      "x": -26,
      "y": 20,
      "z": -23,
      "name": "Soil_Grass"
    },
    {
      "x": -26,
      "y": 15,
      "z": -22,
      "name": "Soil_Dirt"
    },
    {
      "x": -26,
      "y": 16,
      "z": -22,
      "name": "Soil_Dirt"
    },
    {
      "x": -26,
      "y": 17,
      "z": -22,
      "name": "Soil_Dirt"
    },
    {
      "x": -26,
      "y": 18,
      "z": -22,
      "name": "Soil_Dirt"
    },
    {
      "x": -26,
      "y": 19,
      "z": -22,
      "name": "Soil_Dirt"
    },
    {
      "x": -26,
      "y": 20,
      "z": -22,
      "name": "Soil_Grass"
    },
    {
      "x": -26,
      "y": 15,
      "z": -21,
      "name": "Soil_Dirt"
    },
    {
      "x": -26,
      "y": 16,
      "z": -21,
      "name": "Soil_Dirt"
    },
    {
      "x": -26,
      "y": 17,
      "z": -21,
      "name": "Soil_Dirt"
    },
    {
      "x": -26,
      "y": 18,
      "z": -21,
      "name": "Soil_Dirt"
    },
    {
      "x": -26,
      "y": 19,
      "z": -21,
      "name": "Soil_Dirt"
    },
    {
      "x": -26,
      "y": 20,
      "z": -21,
      "name": "Soil_Grass"
    },
    {
      "x": -26,
      "y": 21,
      "z": -21,
      "name": "Plant_Grass_Sharp_Wild",
      "support": 15
    },
    {
      "x": -26,
      "y": 22,
      "z": -21,
      "name": "Plant_Grass_Sharp_Wild",
      "filler": 1024
    },
    {
      "x": -26,
      "y": 15,
      "z": -20,
      "name": "Soil_Dirt"
    },
    {
      "x": -26,
      "y": 16,
      "z": -20,
      "name": "Soil_Dirt"
    },
    {
      "x": -26,
      "y": 17,
      "z": -20,
      "name": "Soil_Dirt"
    },
    {
      "x": -26,
      "y": 18,
      "z": -20,
      "name": "Soil_Dirt"
    },
    {
      "x": -26,
      "y": 19,
      "z": -20,
      "name": "Soil_Dirt"
    },
    {
      "x": -26,
      "y": 20,
      "z": -20,
      "name": "Soil_Grass"
    },
    {
      "x": -26,
      "y": 14,
      "z": -19,
      "name": "Soil_Dirt"
    },
    {
      "x": -26,
      "y": 15,
      "z": -19,
      "name": "Soil_Dirt"
    },
    {
      "x": -26,
      "y": 16,
      "z": -19,
      "name": "Soil_Dirt"
    },
    {
      "x": -26,
      "y": 17,
      "z": -19,
      "name": "Soil_Dirt"
    },
    {
      "x": -26,
      "y": 18,
      "z": -19,
      "name": "Soil_Dirt"
    },
    {
      "x": -26,
      "y": 19,
      "z": -19,
      "name": "Soil_Dirt"
    },
    {
      "x": -26,
      "y": 20,
      "z": -19,
      "name": "Soil_Grass"
    },
    {
      "x": -26,
      "y": 14,
      "z": -18,
      "name": "Soil_Dirt"
    },
    {
      "x": -26,
      "y": 15,
      "z": -18,
      "name": "Soil_Dirt"
    },
    {
      "x": -26,
      "y": 16,
      "z": -18,
      "name": "Soil_Dirt"
    },
    {
      "x": -26,
      "y": 17,
      "z": -18,
      "name": "Soil_Dirt"
    },
    {
      "x": -26,
      "y": 18,
      "z": -18,
      "name": "Soil_Dirt"
    },
    {
      "x": -26,
      "y": 19,
      "z": -18,
      "name": "Soil_Dirt"
    },
    {
      "x": -26,
      "y": 20,
      "z": -18,
      "name": "Soil_Grass"
    },
    {
      "x": -26,
      "y": 14,
      "z": -17,
      "name": "Soil_Dirt"
    },
    {
      "x": -26,
      "y": 15,
      "z": -17,
      "name": "Soil_Dirt"
    },
    {
      "x": -26,
      "y": 16,
      "z": -17,
      "name": "Soil_Dirt"
    },
    {
      "x": -26,
      "y": 17,
      "z": -17,
      "name": "Soil_Dirt"
    },
    {
      "x": -26,
      "y": 18,
      "z": -17,
      "name": "Soil_Dirt"
    },
    {
      "x": -26,
      "y": 19,
      "z": -17,
      "name": "Soil_Dirt"
    },
    {
      "x": -26,
      "y": 20,
      "z": -17,
      "name": "Soil_Grass"
    },
    {
      "x": -26,
      "y": 21,
      "z": -17,
      "name": "Plant_Grass_Sharp_Overgrown",
      "support": 15
    },
    {
      "x": -26,
      "y": 22,
      "z": -17,
      "name": "Plant_Grass_Sharp_Overgrown",
      "filler": 1024
    },
    {
      "x": -26,
      "y": 14,
      "z": -16,
      "name": "Soil_Dirt"
    },
    {
      "x": -26,
      "y": 15,
      "z": -16,
      "name": "Soil_Dirt"
    },
    {
      "x": -26,
      "y": 16,
      "z": -16,
      "name": "Soil_Dirt"
    },
    {
      "x": -26,
      "y": 17,
      "z": -16,
      "name": "Soil_Dirt"
    },
    {
      "x": -26,
      "y": 18,
      "z": -16,
      "name": "Soil_Dirt"
    },
    {
      "x": -26,
      "y": 19,
      "z": -16,
      "name": "Soil_Dirt"
    },
    {
      "x": -26,
      "y": 20,
      "z": -16,
      "name": "Soil_Grass"
    },
    {
      "x": -26,
      "y": 14,
      "z": -15,
      "name": "Soil_Dirt"
    },
    {
      "x": -26,
      "y": 15,
      "z": -15,
      "name": "Soil_Dirt"
    },
    {
      "x": -26,
      "y": 16,
      "z": -15,
      "name": "Soil_Dirt"
    },
    {
      "x": -26,
      "y": 17,
      "z": -15,
      "name": "Soil_Dirt"
    },
    {
      "x": -26,
      "y": 18,
      "z": -15,
      "name": "Soil_Dirt"
    },
    {
      "x": -26,
      "y": 19,
      "z": -15,
      "name": "Soil_Dirt"
    },
    {
      "x": -26,
      "y": 20,
      "z": -15,
      "name": "Soil_Grass"
    },
    {
      "x": -26,
      "y": 14,
      "z": -14,
      "name": "Soil_Dirt"
    },
    {
      "x": -26,
      "y": 15,
      "z": -14,
      "name": "Soil_Dirt"
    },
    {
      "x": -26,
      "y": 16,
      "z": -14,
      "name": "Soil_Dirt"
    },
    {
      "x": -26,
      "y": 17,
      "z": -14,
      "name": "Soil_Dirt"
    },
    {
      "x": -26,
      "y": 18,
      "z": -14,
      "name": "Soil_Dirt"
    },
    {
      "x": -26,
      "y": 19,
      "z": -14,
      "name": "Soil_Grass"
    },
    {
      "x": -26,
      "y": 14,
      "z": -13,
      "name": "Soil_Dirt"
    },
    {
      "x": -26,
      "y": 15,
      "z": -13,
      "name": "Soil_Dirt"
    },
    {
      "x": -26,
      "y": 16,
      "z": -13,
      "name": "Soil_Grass"
    },
    {
      "x": -26,
      "y": 19,
      "z": -13,
      "name": "Soil_Grass"
    },
    {
      "x": -26,
      "y": 14,
      "z": -12,
      "name": "Soil_Dirt"
    },
    {
      "x": -26,
      "y": 15,
      "z": -12,
      "name": "Soil_Dirt"
    },
    {
      "x": -26,
      "y": 16,
      "z": -12,
      "name": "Soil_Grass"
    },
    {
      "x": -26,
      "y": 19,
      "z": -12,
      "name": "Soil_Grass"
    },
    {
      "x": -26,
      "y": 14,
      "z": -11,
      "name": "Soil_Dirt"
    },
    {
      "x": -26,
      "y": 15,
      "z": -11,
      "name": "Soil_Dirt"
    },
    {
      "x": -26,
      "y": 16,
      "z": -11,
      "name": "Soil_Dirt"
    },
    {
      "x": -26,
      "y": 17,
      "z": -11,
      "name": "Soil_Dirt"
    },
    {
      "x": -26,
      "y": 18,
      "z": -11,
      "name": "Soil_Dirt"
    },
    {
      "x": -26,
      "y": 19,
      "z": -11,
      "name": "Soil_Grass"
    },
    {
      "x": -26,
      "y": 14,
      "z": -10,
      "name": "Soil_Dirt"
    },
    {
      "x": -26,
      "y": 15,
      "z": -10,
      "name": "Soil_Dirt"
    },
    {
      "x": -26,
      "y": 16,
      "z": -10,
      "name": "Soil_Dirt"
    },
    {
      "x": -26,
      "y": 17,
      "z": -10,
      "name": "Soil_Dirt"
    },
    {
      "x": -26,
      "y": 18,
      "z": -10,
      "name": "Soil_Dirt"
    },
    {
      "x": -26,
      "y": 19,
      "z": -10,
      "name": "Soil_Dirt"
    },
    {
      "x": -26,
      "y": 20,
      "z": -10,
      "name": "Soil_Grass"
    },
    {
      "x": -26,
      "y": 14,
      "z": -9,
      "name": "Soil_Dirt"
    },
    {
      "x": -26,
      "y": 15,
      "z": -9,
      "name": "Soil_Dirt"
    },
    {
      "x": -26,
      "y": 16,
      "z": -9,
      "name": "Soil_Dirt"
    },
    {
      "x": -26,
      "y": 17,
      "z": -9,
      "name": "Soil_Dirt"
    },
    {
      "x": -26,
      "y": 18,
      "z": -9,
      "name": "Soil_Dirt"
    },
    {
      "x": -26,
      "y": 19,
      "z": -9,
      "name": "Soil_Dirt"
    },
    {
      "x": -26,
      "y": 20,
      "z": -9,
      "name": "Soil_Grass"
    },
    {
      "x": -26,
      "y": 14,
      "z": -8,
      "name": "Soil_Dirt"
    },
    {
      "x": -26,
      "y": 15,
      "z": -8,
      "name": "Soil_Dirt"
    },
    {
      "x": -26,
      "y": 16,
      "z": -8,
      "name": "Soil_Dirt"
    },
    {
      "x": -26,
      "y": 17,
      "z": -8,
      "name": "Soil_Dirt"
    },
    {
      "x": -26,
      "y": 18,
      "z": -8,
      "name": "Soil_Dirt"
    },
    {
      "x": -26,
      "y": 19,
      "z": -8,
      "name": "Soil_Dirt"
    },
    {
      "x": -26,
      "y": 20,
      "z": -8,
      "name": "Soil_Grass"
    },
    {
      "x": -26,
      "y": 14,
      "z": -7,
      "name": "Soil_Dirt"
    },
    {
      "x": -26,
      "y": 15,
      "z": -7,
      "name": "Soil_Dirt"
    },
    {
      "x": -26,
      "y": 16,
      "z": -7,
      "name": "Soil_Dirt"
    },
    {
      "x": -26,
      "y": 17,
      "z": -7,
      "name": "Soil_Dirt"
    },
    {
      "x": -26,
      "y": 18,
      "z": -7,
      "name": "Soil_Dirt"
    },
    {
      "x": -26,
      "y": 19,
      "z": -7,
      "name": "Soil_Dirt"
    },
    {
      "x": -26,
      "y": 20,
      "z": -7,
      "name": "Soil_Dirt"
    },
    {
      "x": -26,
      "y": 21,
      "z": -7,
      "name": "Soil_Grass"
    },
    {
      "x": -26,
      "y": 14,
      "z": -6,
      "name": "Soil_Dirt"
    },
    {
      "x": -26,
      "y": 15,
      "z": -6,
      "name": "Soil_Dirt"
    },
    {
      "x": -26,
      "y": 16,
      "z": -6,
      "name": "Soil_Dirt"
    },
    {
      "x": -26,
      "y": 17,
      "z": -6,
      "name": "Soil_Dirt"
    },
    {
      "x": -26,
      "y": 18,
      "z": -6,
      "name": "Soil_Dirt"
    },
    {
      "x": -26,
      "y": 19,
      "z": -6,
      "name": "Soil_Dirt"
    },
    {
      "x": -26,
      "y": 20,
      "z": -6,
      "name": "Soil_Dirt"
    },
    {
      "x": -26,
      "y": 21,
      "z": -6,
      "name": "Soil_Grass"
    },
    {
      "x": -26,
      "y": 14,
      "z": -5,
      "name": "Soil_Dirt"
    },
    {
      "x": -26,
      "y": 15,
      "z": -5,
      "name": "Soil_Dirt"
    },
    {
      "x": -26,
      "y": 16,
      "z": -5,
      "name": "Soil_Dirt"
    },
    {
      "x": -26,
      "y": 17,
      "z": -5,
      "name": "Soil_Dirt"
    },
    {
      "x": -26,
      "y": 18,
      "z": -5,
      "name": "Soil_Dirt"
    },
    {
      "x": -26,
      "y": 19,
      "z": -5,
      "name": "Soil_Dirt"
    },
    {
      "x": -26,
      "y": 20,
      "z": -5,
      "name": "Soil_Dirt"
    },
    {
      "x": -26,
      "y": 21,
      "z": -5,
      "name": "Soil_Grass"
    },
    {
      "x": -26,
      "y": 22,
      "z": -5,
      "name": "Plant_Grass_Sharp_Overgrown",
      "support": 15
    },
    {
      "x": -26,
      "y": 14,
      "z": -4,
      "name": "Soil_Dirt"
    },
    {
      "x": -26,
      "y": 15,
      "z": -4,
      "name": "Soil_Dirt"
    },
    {
      "x": -26,
      "y": 16,
      "z": -4,
      "name": "Soil_Dirt"
    },
    {
      "x": -26,
      "y": 17,
      "z": -4,
      "name": "Soil_Dirt"
    },
    {
      "x": -26,
      "y": 18,
      "z": -4,
      "name": "Soil_Dirt"
    },
    {
      "x": -26,
      "y": 19,
      "z": -4,
      "name": "Soil_Dirt"
    },
    {
      "x": -26,
      "y": 20,
      "z": -4,
      "name": "Soil_Grass"
    },
    {
      "x": -26,
      "y": 14,
      "z": -3,
      "name": "Soil_Grass"
    },
    {
      "x": -26,
      "y": 16,
      "z": -3,
      "name": "Soil_Dirt"
    },
    {
      "x": -26,
      "y": 17,
      "z": -3,
      "name": "Soil_Dirt"
    },
    {
      "x": -26,
      "y": 18,
      "z": -3,
      "name": "Soil_Dirt"
    },
    {
      "x": -26,
      "y": 19,
      "z": -3,
      "name": "Soil_Dirt"
    },
    {
      "x": -26,
      "y": 20,
      "z": -3,
      "name": "Soil_Grass"
    },
    {
      "x": -26,
      "y": 16,
      "z": -2,
      "name": "Soil_Dirt"
    },
    {
      "x": -26,
      "y": 17,
      "z": -2,
      "name": "Soil_Dirt"
    },
    {
      "x": -26,
      "y": 18,
      "z": -2,
      "name": "Soil_Dirt"
    },
    {
      "x": -26,
      "y": 19,
      "z": -2,
      "name": "Soil_Dirt"
    },
    {
      "x": -26,
      "y": 20,
      "z": -2,
      "name": "Soil_Grass"
    },
    {
      "x": -26,
      "y": 17,
      "z": -1,
      "name": "Soil_Dirt"
    },
    {
      "x": -26,
      "y": 18,
      "z": -1,
      "name": "Soil_Dirt"
    },
    {
      "x": -26,
      "y": 19,
      "z": -1,
      "name": "Soil_Grass"
    },
    {
      "x": -26,
      "y": 18,
      "z": 0,
      "name": "Soil_Grass"
    },
    {
      "x": -26,
      "y": 14,
      "z": 1,
      "name": "Soil_Grass"
    },
    {
      "x": -26,
      "y": 18,
      "z": 1,
      "name": "Soil_Grass"
    },
    {
      "x": -26,
      "y": 19,
      "z": 1,
      "name": "Plant_Grass_Sharp_Overgrown",
      "support": 15
    },
    {
      "x": -26,
      "y": 20,
      "z": 1,
      "name": "Plant_Grass_Sharp_Overgrown",
      "filler": 1024
    },
    {
      "x": -26,
      "y": 14,
      "z": 2,
      "name": "Soil_Dirt"
    },
    {
      "x": -26,
      "y": 15,
      "z": 2,
      "name": "Soil_Grass"
    },
    {
      "x": -26,
      "y": 18,
      "z": 2,
      "name": "Soil_Grass"
    },
    {
      "x": -26,
      "y": 19,
      "z": 2,
      "name": "Plant_Grass_Sharp_Overgrown",
      "support": 15
    },
    {
      "x": -26,
      "y": 20,
      "z": 2,
      "name": "Plant_Grass_Sharp_Overgrown",
      "filler": 1024
    },
    {
      "x": -26,
      "y": 14,
      "z": 3,
      "name": "Soil_Dirt"
    },
    {
      "x": -26,
      "y": 15,
      "z": 3,
      "name": "Soil_Dirt"
    },
    {
      "x": -26,
      "y": 16,
      "z": 3,
      "name": "Soil_Grass"
    },
    {
      "x": -26,
      "y": 18,
      "z": 3,
      "name": "Soil_Grass"
    },
    {
      "x": -26,
      "y": 14,
      "z": 4,
      "name": "Soil_Dirt"
    },
    {
      "x": -26,
      "y": 15,
      "z": 4,
      "name": "Soil_Dirt"
    },
    {
      "x": -26,
      "y": 16,
      "z": 4,
      "name": "Soil_Dirt"
    },
    {
      "x": -26,
      "y": 17,
      "z": 4,
      "name": "Soil_Dirt"
    },
    {
      "x": -26,
      "y": 18,
      "z": 4,
      "name": "Soil_Grass"
    },
    {
      "x": -26,
      "y": 14,
      "z": 5,
      "name": "Soil_Dirt"
    },
    {
      "x": -26,
      "y": 15,
      "z": 5,
      "name": "Soil_Dirt"
    },
    {
      "x": -26,
      "y": 16,
      "z": 5,
      "name": "Soil_Dirt"
    },
    {
      "x": -26,
      "y": 17,
      "z": 5,
      "name": "Soil_Dirt"
    },
    {
      "x": -26,
      "y": 18,
      "z": 5,
      "name": "Soil_Grass"
    },
    {
      "x": -26,
      "y": 14,
      "z": 6,
      "name": "Soil_Dirt"
    },
    {
      "x": -26,
      "y": 15,
      "z": 6,
      "name": "Soil_Dirt"
    },
    {
      "x": -26,
      "y": 16,
      "z": 6,
      "name": "Soil_Dirt"
    },
    {
      "x": -26,
      "y": 17,
      "z": 6,
      "name": "Soil_Dirt"
    },
    {
      "x": -26,
      "y": 18,
      "z": 6,
      "name": "Soil_Grass"
    },
    {
      "x": -26,
      "y": 14,
      "z": 7,
      "name": "Soil_Dirt"
    },
    {
      "x": -26,
      "y": 15,
      "z": 7,
      "name": "Soil_Dirt"
    },
    {
      "x": -26,
      "y": 16,
      "z": 7,
      "name": "Soil_Dirt"
    },
    {
      "x": -26,
      "y": 17,
      "z": 7,
      "name": "Soil_Dirt"
    },
    {
      "x": -26,
      "y": 18,
      "z": 7,
      "name": "Soil_Grass"
    },
    {
      "x": -26,
      "y": 19,
      "z": 7,
      "name": "Plant_Grass_Jungle_Tall",
      "support": 15
    },
    {
      "x": -26,
      "y": 14,
      "z": 8,
      "name": "Soil_Dirt"
    },
    {
      "x": -26,
      "y": 15,
      "z": 8,
      "name": "Soil_Dirt"
    },
    {
      "x": -26,
      "y": 16,
      "z": 8,
      "name": "Soil_Dirt"
    },
    {
      "x": -26,
      "y": 17,
      "z": 8,
      "name": "Soil_Dirt"
    },
    {
      "x": -26,
      "y": 18,
      "z": 8,
      "name": "Soil_Grass"
    },
    {
      "x": -26,
      "y": 14,
      "z": 9,
      "name": "Soil_Dirt"
    },
    {
      "x": -26,
      "y": 15,
      "z": 9,
      "name": "Soil_Dirt"
    },
    {
      "x": -26,
      "y": 16,
      "z": 9,
      "name": "Soil_Dirt"
    },
    {
      "x": -26,
      "y": 17,
      "z": 9,
      "name": "Soil_Dirt"
    },
    {
      "x": -26,
      "y": 18,
      "z": 9,
      "name": "Soil_Grass"
    },
    {
      "x": -26,
      "y": 14,
      "z": 10,
      "name": "Soil_Dirt"
    },
    {
      "x": -26,
      "y": 15,
      "z": 10,
      "name": "Soil_Dirt"
    },
    {
      "x": -26,
      "y": 16,
      "z": 10,
      "name": "Soil_Dirt"
    },
    {
      "x": -26,
      "y": 17,
      "z": 10,
      "name": "Soil_Dirt"
    },
    {
      "x": -26,
      "y": 18,
      "z": 10,
      "name": "Soil_Grass"
    },
    {
      "x": -26,
      "y": 14,
      "z": 11,
      "name": "Soil_Dirt"
    },
    {
      "x": -26,
      "y": 15,
      "z": 11,
      "name": "Soil_Dirt"
    },
    {
      "x": -26,
      "y": 16,
      "z": 11,
      "name": "Soil_Dirt"
    },
    {
      "x": -26,
      "y": 17,
      "z": 11,
      "name": "Soil_Dirt"
    },
    {
      "x": -26,
      "y": 18,
      "z": 11,
      "name": "Soil_Grass"
    },
    {
      "x": -26,
      "y": 19,
      "z": 11,
      "name": "Plant_Grass_Jungle_Tall",
      "support": 15
    },
    {
      "x": -26,
      "y": 14,
      "z": 12,
      "name": "Soil_Dirt"
    },
    {
      "x": -26,
      "y": 15,
      "z": 12,
      "name": "Soil_Dirt"
    },
    {
      "x": -26,
      "y": 16,
      "z": 12,
      "name": "Soil_Dirt"
    },
    {
      "x": -26,
      "y": 17,
      "z": 12,
      "name": "Soil_Dirt"
    },
    {
      "x": -26,
      "y": 18,
      "z": 12,
      "name": "Soil_Grass"
    },
    {
      "x": -26,
      "y": 14,
      "z": 13,
      "name": "Soil_Dirt"
    },
    {
      "x": -26,
      "y": 15,
      "z": 13,
      "name": "Soil_Dirt"
    },
    {
      "x": -26,
      "y": 16,
      "z": 13,
      "name": "Soil_Dirt"
    },
    {
      "x": -26,
      "y": 17,
      "z": 13,
      "name": "Soil_Dirt"
    },
    {
      "x": -26,
      "y": 18,
      "z": 13,
      "name": "Soil_Grass"
    },
    {
      "x": -26,
      "y": 14,
      "z": 14,
      "name": "Soil_Dirt"
    },
    {
      "x": -26,
      "y": 15,
      "z": 14,
      "name": "Soil_Dirt"
    },
    {
      "x": -26,
      "y": 16,
      "z": 14,
      "name": "Soil_Dirt"
    },
    {
      "x": -26,
      "y": 17,
      "z": 14,
      "name": "Soil_Grass"
    },
    {
      "x": -26,
      "y": 18,
      "z": 14,
      "name": "Plant_Grass_Sharp_Overgrown",
      "support": 15
    },
    {
      "x": -26,
      "y": 19,
      "z": 14,
      "name": "Plant_Grass_Sharp_Overgrown",
      "filler": 1024
    },
    {
      "x": -26,
      "y": 14,
      "z": 15,
      "name": "Soil_Dirt"
    },
    {
      "x": -26,
      "y": 15,
      "z": 15,
      "name": "Soil_Dirt"
    },
    {
      "x": -26,
      "y": 16,
      "z": 15,
      "name": "Soil_Dirt"
    },
    {
      "x": -26,
      "y": 17,
      "z": 15,
      "name": "Soil_Grass"
    },
    {
      "x": -26,
      "y": 14,
      "z": 16,
      "name": "Soil_Dirt"
    },
    {
      "x": -26,
      "y": 15,
      "z": 16,
      "name": "Soil_Grass"
    },
    {
      "x": -26,
      "y": 17,
      "z": 16,
      "name": "Soil_Grass"
    },
    {
      "x": -26,
      "y": 14,
      "z": 17,
      "name": "Soil_Grass"
    },
    {
      "x": -26,
      "y": 16,
      "z": 17,
      "name": "Soil_Dirt"
    },
    {
      "x": -26,
      "y": 17,
      "z": 17,
      "name": "Soil_Grass"
    },
    {
      "x": -26,
      "y": 18,
      "z": 17,
      "name": "Plant_Grass_Jungle_Tall",
      "support": 15
    },
    {
      "x": -26,
      "y": 16,
      "z": 18,
      "name": "Soil_Dirt"
    },
    {
      "x": -26,
      "y": 17,
      "z": 18,
      "name": "Soil_Grass"
    },
    {
      "x": -26,
      "y": 16,
      "z": 19,
      "name": "Soil_Grass"
    },
    {
      "x": -26,
      "y": 16,
      "z": 20,
      "name": "Soil_Grass"
    },
    {
      "x": -26,
      "y": 14,
      "z": 21,
      "name": "Soil_Dirt"
    },
    {
      "x": -26,
      "y": 15,
      "z": 21,
      "name": "Soil_Grass"
    },
    {
      "x": -26,
      "y": 16,
      "z": 21,
      "name": "Plant_Grass_Sharp_Overgrown",
      "support": 15
    },
    {
      "x": -26,
      "y": 17,
      "z": 21,
      "name": "Plant_Grass_Sharp_Overgrown",
      "filler": 1024
    },
    {
      "x": -26,
      "y": 15,
      "z": 22,
      "name": "Soil_Grass"
    },
    {
      "x": -26,
      "y": 16,
      "z": 22,
      "name": "Plant_Grass_Sharp_Overgrown",
      "support": 15
    },
    {
      "x": -26,
      "y": 17,
      "z": 22,
      "name": "Plant_Grass_Sharp_Overgrown",
      "filler": 1024
    },
    {
      "x": -26,
      "y": 15,
      "z": 23,
      "name": "Soil_Grass"
    },
    {
      "x": -26,
      "y": 14,
      "z": 24,
      "name": "Soil_Grass"
    },
    {
      "x": -26,
      "y": 14,
      "z": 25,
      "name": "Soil_Grass"
    },
    {
      "x": -26,
      "y": 15,
      "z": 25,
      "name": "Plant_Grass_Sharp_Overgrown",
      "support": 15
    },
    {
      "x": -26,
      "y": 16,
      "z": 25,
      "name": "Plant_Grass_Sharp_Overgrown",
      "filler": 1024
    },
    {
      "x": -26,
      "y": 14,
      "z": 26,
      "name": "Soil_Grass"
    },
    {
      "x": -26,
      "y": 13,
      "z": 27,
      "name": "Soil_Grass"
    },
    {
      "x": -26,
      "y": 13,
      "z": 28,
      "name": "Soil_Grass"
    },
    {
      "x": -25,
      "y": 13,
      "z": -32,
      "name": "Soil_Grass"
    },
    {
      "x": -25,
      "y": 13,
      "z": -31,
      "name": "Soil_Grass"
    },
    {
      "x": -25,
      "y": 14,
      "z": -30,
      "name": "Soil_Grass"
    },
    {
      "x": -25,
      "y": 14,
      "z": -29,
      "name": "Soil_Dirt"
    },
    {
      "x": -25,
      "y": 15,
      "z": -29,
      "name": "Soil_Grass"
    },
    {
      "x": -25,
      "y": 16,
      "z": -29,
      "name": "Plant_Grass_Jungle_Tall",
      "support": 15
    },
    {
      "x": -25,
      "y": 15,
      "z": -28,
      "name": "Soil_Grass"
    },
    {
      "x": -25,
      "y": 16,
      "z": -28,
      "name": "Plant_Grass_Jungle_Tall",
      "support": 15
    },
    {
      "x": -25,
      "y": 16,
      "z": -27,
      "name": "Soil_Grass"
    },
    {
      "x": -25,
      "y": 15,
      "z": -26,
      "name": "Soil_Dirt"
    },
    {
      "x": -25,
      "y": 16,
      "z": -26,
      "name": "Soil_Dirt"
    },
    {
      "x": -25,
      "y": 17,
      "z": -26,
      "name": "Soil_Dirt"
    },
    {
      "x": -25,
      "y": 18,
      "z": -26,
      "name": "Soil_Grass"
    },
    {
      "x": -25,
      "y": 15,
      "z": -25,
      "name": "Soil_Dirt"
    },
    {
      "x": -25,
      "y": 16,
      "z": -25,
      "name": "Soil_Dirt"
    },
    {
      "x": -25,
      "y": 17,
      "z": -25,
      "name": "Soil_Dirt"
    },
    {
      "x": -25,
      "y": 18,
      "z": -25,
      "name": "Soil_Dirt"
    },
    {
      "x": -25,
      "y": 19,
      "z": -25,
      "name": "Soil_Grass"
    },
    {
      "x": -25,
      "y": 15,
      "z": -24,
      "name": "Soil_Dirt"
    },
    {
      "x": -25,
      "y": 16,
      "z": -24,
      "name": "Soil_Dirt"
    },
    {
      "x": -25,
      "y": 17,
      "z": -24,
      "name": "Soil_Dirt"
    },
    {
      "x": -25,
      "y": 18,
      "z": -24,
      "name": "Soil_Dirt"
    },
    {
      "x": -25,
      "y": 19,
      "z": -24,
      "name": "Soil_Dirt"
    },
    {
      "x": -25,
      "y": 20,
      "z": -24,
      "name": "Soil_Grass"
    },
    {
      "x": -25,
      "y": 15,
      "z": -23,
      "name": "Soil_Dirt"
    },
    {
      "x": -25,
      "y": 16,
      "z": -23,
      "name": "Soil_Dirt"
    },
    {
      "x": -25,
      "y": 17,
      "z": -23,
      "name": "Soil_Dirt"
    },
    {
      "x": -25,
      "y": 18,
      "z": -23,
      "name": "Soil_Dirt"
    },
    {
      "x": -25,
      "y": 19,
      "z": -23,
      "name": "Soil_Dirt"
    },
    {
      "x": -25,
      "y": 20,
      "z": -23,
      "name": "Soil_Grass"
    },
    {
      "x": -25,
      "y": 14,
      "z": -22,
      "name": "Soil_Dirt"
    },
    {
      "x": -25,
      "y": 15,
      "z": -22,
      "name": "Soil_Dirt"
    },
    {
      "x": -25,
      "y": 16,
      "z": -22,
      "name": "Soil_Dirt"
    },
    {
      "x": -25,
      "y": 17,
      "z": -22,
      "name": "Soil_Dirt"
    },
    {
      "x": -25,
      "y": 18,
      "z": -22,
      "name": "Soil_Dirt"
    },
    {
      "x": -25,
      "y": 19,
      "z": -22,
      "name": "Soil_Dirt"
    },
    {
      "x": -25,
      "y": 20,
      "z": -22,
      "name": "Soil_Dirt"
    },
    {
      "x": -25,
      "y": 21,
      "z": -22,
      "name": "Soil_Grass"
    },
    {
      "x": -25,
      "y": 14,
      "z": -21,
      "name": "Soil_Dirt"
    },
    {
      "x": -25,
      "y": 15,
      "z": -21,
      "name": "Soil_Dirt"
    },
    {
      "x": -25,
      "y": 16,
      "z": -21,
      "name": "Soil_Dirt"
    },
    {
      "x": -25,
      "y": 17,
      "z": -21,
      "name": "Soil_Dirt"
    },
    {
      "x": -25,
      "y": 18,
      "z": -21,
      "name": "Soil_Dirt"
    },
    {
      "x": -25,
      "y": 19,
      "z": -21,
      "name": "Soil_Dirt"
    },
    {
      "x": -25,
      "y": 20,
      "z": -21,
      "name": "Soil_Dirt"
    },
    {
      "x": -25,
      "y": 21,
      "z": -21,
      "name": "Soil_Grass"
    },
    {
      "x": -25,
      "y": 22,
      "z": -21,
      "name": "Plant_Grass_Jungle_Tall",
      "support": 15
    },
    {
      "x": -25,
      "y": 14,
      "z": -20,
      "name": "Soil_Dirt"
    },
    {
      "x": -25,
      "y": 15,
      "z": -20,
      "name": "Soil_Dirt"
    },
    {
      "x": -25,
      "y": 16,
      "z": -20,
      "name": "Soil_Dirt"
    },
    {
      "x": -25,
      "y": 17,
      "z": -20,
      "name": "Soil_Dirt"
    },
    {
      "x": -25,
      "y": 18,
      "z": -20,
      "name": "Soil_Dirt"
    },
    {
      "x": -25,
      "y": 19,
      "z": -20,
      "name": "Soil_Dirt"
    },
    {
      "x": -25,
      "y": 20,
      "z": -20,
      "name": "Soil_Grass"
    },
    {
      "x": -25,
      "y": 14,
      "z": -19,
      "name": "Soil_Dirt"
    },
    {
      "x": -25,
      "y": 15,
      "z": -19,
      "name": "Soil_Dirt"
    },
    {
      "x": -25,
      "y": 16,
      "z": -19,
      "name": "Soil_Dirt"
    },
    {
      "x": -25,
      "y": 17,
      "z": -19,
      "name": "Soil_Dirt"
    },
    {
      "x": -25,
      "y": 18,
      "z": -19,
      "name": "Soil_Dirt"
    },
    {
      "x": -25,
      "y": 19,
      "z": -19,
      "name": "Soil_Dirt"
    },
    {
      "x": -25,
      "y": 20,
      "z": -19,
      "name": "Soil_Dirt"
    },
    {
      "x": -25,
      "y": 21,
      "z": -19,
      "name": "Soil_Grass"
    },
    {
      "x": -25,
      "y": 14,
      "z": -18,
      "name": "Soil_Dirt"
    },
    {
      "x": -25,
      "y": 15,
      "z": -18,
      "name": "Soil_Dirt"
    },
    {
      "x": -25,
      "y": 16,
      "z": -18,
      "name": "Soil_Dirt"
    },
    {
      "x": -25,
      "y": 17,
      "z": -18,
      "name": "Soil_Dirt"
    },
    {
      "x": -25,
      "y": 18,
      "z": -18,
      "name": "Soil_Dirt"
    },
    {
      "x": -25,
      "y": 19,
      "z": -18,
      "name": "Soil_Dirt"
    },
    {
      "x": -25,
      "y": 20,
      "z": -18,
      "name": "Soil_Dirt"
    },
    {
      "x": -25,
      "y": 21,
      "z": -18,
      "name": "Soil_Grass"
    },
    {
      "x": -25,
      "y": 14,
      "z": -17,
      "name": "Soil_Dirt"
    },
    {
      "x": -25,
      "y": 15,
      "z": -17,
      "name": "Soil_Dirt"
    },
    {
      "x": -25,
      "y": 16,
      "z": -17,
      "name": "Soil_Dirt"
    },
    {
      "x": -25,
      "y": 17,
      "z": -17,
      "name": "Soil_Dirt"
    },
    {
      "x": -25,
      "y": 18,
      "z": -17,
      "name": "Soil_Dirt"
    },
    {
      "x": -25,
      "y": 19,
      "z": -17,
      "name": "Soil_Dirt"
    },
    {
      "x": -25,
      "y": 20,
      "z": -17,
      "name": "Soil_Dirt"
    },
    {
      "x": -25,
      "y": 21,
      "z": -17,
      "name": "Soil_Grass"
    },
    {
      "x": -25,
      "y": 14,
      "z": -16,
      "name": "Soil_Dirt"
    },
    {
      "x": -25,
      "y": 15,
      "z": -16,
      "name": "Soil_Dirt"
    },
    {
      "x": -25,
      "y": 16,
      "z": -16,
      "name": "Soil_Dirt"
    },
    {
      "x": -25,
      "y": 17,
      "z": -16,
      "name": "Soil_Dirt"
    },
    {
      "x": -25,
      "y": 18,
      "z": -16,
      "name": "Soil_Dirt"
    },
    {
      "x": -25,
      "y": 19,
      "z": -16,
      "name": "Soil_Dirt"
    },
    {
      "x": -25,
      "y": 20,
      "z": -16,
      "name": "Soil_Dirt"
    },
    {
      "x": -25,
      "y": 21,
      "z": -16,
      "name": "Soil_Grass"
    },
    {
      "x": -25,
      "y": 14,
      "z": -15,
      "name": "Soil_Dirt"
    },
    {
      "x": -25,
      "y": 15,
      "z": -15,
      "name": "Soil_Dirt"
    },
    {
      "x": -25,
      "y": 16,
      "z": -15,
      "name": "Soil_Dirt"
    },
    {
      "x": -25,
      "y": 17,
      "z": -15,
      "name": "Soil_Dirt"
    },
    {
      "x": -25,
      "y": 18,
      "z": -15,
      "name": "Soil_Dirt"
    },
    {
      "x": -25,
      "y": 19,
      "z": -15,
      "name": "Soil_Dirt"
    },
    {
      "x": -25,
      "y": 20,
      "z": -15,
      "name": "Soil_Grass"
    },
    {
      "x": -25,
      "y": 14,
      "z": -14,
      "name": "Soil_Dirt"
    },
    {
      "x": -25,
      "y": 15,
      "z": -14,
      "name": "Soil_Dirt"
    },
    {
      "x": -25,
      "y": 16,
      "z": -14,
      "name": "Soil_Dirt"
    },
    {
      "x": -25,
      "y": 17,
      "z": -14,
      "name": "Soil_Dirt"
    },
    {
      "x": -25,
      "y": 18,
      "z": -14,
      "name": "Soil_Dirt"
    },
    {
      "x": -25,
      "y": 19,
      "z": -14,
      "name": "Soil_Dirt"
    },
    {
      "x": -25,
      "y": 20,
      "z": -14,
      "name": "Soil_Grass"
    },
    {
      "x": -25,
      "y": 14,
      "z": -13,
      "name": "Soil_Dirt"
    },
    {
      "x": -25,
      "y": 15,
      "z": -13,
      "name": "Soil_Dirt"
    },
    {
      "x": -25,
      "y": 16,
      "z": -13,
      "name": "Soil_Dirt"
    },
    {
      "x": -25,
      "y": 17,
      "z": -13,
      "name": "Soil_Grass"
    },
    {
      "x": -25,
      "y": 19,
      "z": -13,
      "name": "Soil_Dirt"
    },
    {
      "x": -25,
      "y": 20,
      "z": -13,
      "name": "Soil_Grass"
    },
    {
      "x": -25,
      "y": 14,
      "z": -12,
      "name": "Soil_Dirt"
    },
    {
      "x": -25,
      "y": 15,
      "z": -12,
      "name": "Soil_Dirt"
    },
    {
      "x": -25,
      "y": 16,
      "z": -12,
      "name": "Soil_Dirt"
    },
    {
      "x": -25,
      "y": 17,
      "z": -12,
      "name": "Soil_Dirt"
    },
    {
      "x": -25,
      "y": 18,
      "z": -12,
      "name": "Soil_Dirt"
    },
    {
      "x": -25,
      "y": 19,
      "z": -12,
      "name": "Soil_Dirt"
    },
    {
      "x": -25,
      "y": 20,
      "z": -12,
      "name": "Soil_Grass"
    },
    {
      "x": -25,
      "y": 14,
      "z": -11,
      "name": "Soil_Dirt"
    },
    {
      "x": -25,
      "y": 15,
      "z": -11,
      "name": "Soil_Dirt"
    },
    {
      "x": -25,
      "y": 16,
      "z": -11,
      "name": "Soil_Dirt"
    },
    {
      "x": -25,
      "y": 17,
      "z": -11,
      "name": "Soil_Dirt"
    },
    {
      "x": -25,
      "y": 18,
      "z": -11,
      "name": "Soil_Dirt"
    },
    {
      "x": -25,
      "y": 19,
      "z": -11,
      "name": "Soil_Dirt"
    },
    {
