{
  "version": 8,
  "blockIdVersion": 11,
  "anchorX": 0,
  "anchorY": 0,
  "anchorZ": 0,
  "blocks": [
    {
      "x": -22,
      "y": 9,
      "z": -22,
      "name": "Soil_Grass"
    },
    {
      "x": -22,
      "y": 9,
      "z": -21,
      "name": "Soil_Grass"
    },
    {
      "x": -22,
      "y": 9,
      "z": -20,
      "name": "Soil_Grass"
    },
    {
      "x": -22,
      "y": 9,
      "z": -19,
      "name": "Soil_Grass"
    },
    {
      "x": -22,
      "y": 9,
      "z": -18,
      "name": "Soil_Grass"
    },
    {
      "x": -22,
      "y": 9,
      "z": -17,
      "name": "Soil_Grass"
    },
    {
      "x": -22,
      "y": 9,
      "z": -16,
      "name": "Soil_Grass"
    },
    {
      "x": -22,
      "y": 9,
      "z": -15,
      "name": "Soil_Grass"
    },
    {
      "x": -22,
      "y": 9,
      "z": -14,
      "name": "Soil_Grass"
    },
    {
      "x": -22,
      "y": 9,
      "z": -13,
      "name": "Soil_Grass"
    },
    {
      "x": -22,
      "y": 9,
      "z": -12,
      "name": "Soil_Grass"
    },
    {
      "x": -22,
      "y": 9,
      "z": -11,
      "name": "Soil_Grass"
    },
    {
      "x": -22,
      "y": 9,
      "z": -10,
      "name": "Soil_Grass"
    },
    {
      "x": -22,
      "y": 9,
      "z": -9,
      "name": "Soil_Grass"
    },
    {
      "x": -22,
      "y": 10,
      "z": -9,
      "name": "Rock_Shale_Brick_Stairs",
      "rotation": 3
    },
    {
      "x": -22,
      "y": 9,
      "z": -8,
      "name": "Soil_Grass"
    },
    {
      "x": -22,
      "y": 10,
      "z": -8,
      "name": "Rock_Shale_Brick_Stairs",
      "rotation": 3
    },
    {
      "x": -22,
      "y": 9,
      "z": -7,
      "name": "Soil_Grass"
    },
    {
      "x": -22,
      "y": 10,
      "z": -7,
      "name": "Rock_Shale_Brick_Stairs",
      "rotation": 3
    },
    {
      "x": -22,
      "y": 9,
      "z": -6,
      "name": "Soil_Grass"
    },
    {
      "x": -22,
      "y": 10,
      "z": -6,
      "name": "Rock_Shale_Brick_Stairs",
      "rotation": 3
    },
    {
      "x": -22,
      "y": 9,
      "z": -5,
      "name": "Soil_Grass"
    },
    {
      "x": -22,
      "y": 10,
      "z": -5,
      "name": "Rock_Shale_Brick_Stairs",
      "rotation": 3
    },
    {
      "x": -22,
      "y": 9,
      "z": -4,
      "name": "Soil_Grass"
    },
    {
      "x": -22,
      "y": 10,
      "z": -4,
      "name": "Rock_Shale_Brick_Stairs",
      "rotation": 3
    },
    {
      "x": -22,
      "y": 9,
      "z": -3,
      "name": "Soil_Grass"
    },
    {
      "x": -22,
      "y": 10,
      "z": -3,
      "name": "Rock_Shale_Brick_Stairs",
      "rotation": 3
    },
    {
      "x": -22,
      "y": 9,
      "z": -2,
      "name": "Soil_Grass"
    },
    {
      "x": -22,
      "y": 10,
      "z": -2,
      "name": "Rock_Shale_Brick_Stairs",
      "rotation": 3
    },
    {
      "x": -22,
      "y": 9,
      "z": -1,
      "name": "Soil_Grass"
    },
    {
      "x": -22,
      "y": 10,
      "z": -1,
      "name": "Rock_Shale_Brick_Stairs",
      "rotation": 3
    },
    {
      "x": -22,
      "y": 9,
      "z": 0,
      "name": "Soil_Grass"
    },
    {
      "x": -22,
      "y": 10,
      "z": 0,
      "name": "Rock_Shale_Brick_Stairs",
      "rotation": 3
    },
    {
      "x": -22,
      "y": 9,
      "z": 1,
      "name": "Soil_Grass"
    },
    {
      "x": -22,
      "y": 10,
      "z": 1,
      "name": "Rock_Shale_Brick_Stairs",
      "rotation": 3
    },
    {
      "x": -22,
      "y": 9,
      "z": 2,
      "name": "Soil_Grass"
    },
    {
      "x": -22,
      "y": 10,
      "z": 2,
      "name": "Rock_Shale_Brick_Stairs",
      "rotation": 3
    },
    {
      "x": -22,
      "y": 9,
      "z": 3,
      "name": "Soil_Grass"
    },
    {
      "x": -22,
      "y": 10,
      "z": 3,
      "name": "Rock_Shale_Brick_Stairs",
      "rotation": 3
    },
    {
      "x": -22,
      "y": 9,
      "z": 4,
      "name": "Soil_Grass"
    },
    {
      "x": -22,
      "y": 10,
      "z": 4,
      "name": "Rock_Shale_Brick_Stairs",
      "rotation": 3
    },
    {
      "x": -22,
      "y": 9,
      "z": 5,
      "name": "Soil_Grass"
    },
    {
      "x": -22,
      "y": 10,
      "z": 5,
      "name": "Rock_Shale_Brick_Stairs",
      "rotation": 3
    },
    {
      "x": -22,
      "y": 9,
      "z": 6,
      "name": "Soil_Grass"
    },
    {
      "x": -22,
      "y": 10,
      "z": 6,
      "name": "Rock_Shale_Brick_Stairs",
      "rotation": 3
    },
    {
      "x": -22,
      "y": 9,
      "z": 7,
      "name": "Soil_Grass"
    },
    {
      "x": -22,
      "y": 10,
      "z": 7,
      "name": "Rock_Shale_Brick_Stairs",
      "rotation": 3
    },
    {
      "x": -22,
      "y": 9,
      "z": 8,
      "name": "Soil_Grass"
    },
    {
      "x": -22,
      "y": 10,
      "z": 8,
      "name": "Rock_Shale_Brick_Stairs",
      "rotation": 3
    },
    {
      "x": -22,
      "y": 9,
      "z": 9,
      "name": "Soil_Grass"
    },
    {
      "x": -22,
      "y": 10,
      "z": 9,
      "name": "Rock_Shale_Brick_Stairs",
      "rotation": 3
    },
    {
      "x": -22,
      "y": 9,
      "z": 10,
      "name": "Soil_Grass"
    },
    {
      "x": -22,
      "y": 9,
      "z": 11,
      "name": "Soil_Grass"
    },
    {
      "x": -22,
      "y": 9,
      "z": 12,
      "name": "Soil_Grass"
    },
    {
      "x": -22,
      "y": 9,
      "z": 13,
      "name": "Soil_Grass"
    },
    {
      "x": -22,
      "y": 9,
      "z": 14,
      "name": "Soil_Grass"
    },
    {
      "x": -22,
      "y": 9,
      "z": 15,
      "name": "Soil_Grass"
    },
    {
      "x": -22,
      "y": 9,
      "z": 16,
      "name": "Soil_Grass"
    },
    {
      "x": -22,
      "y": 9,
      "z": 17,
      "name": "Soil_Grass"
    },
    {
      "x": -22,
      "y": 9,
      "z": 18,
      "name": "Soil_Grass"
    },
    {
      "x": -22,
      "y": 9,
      "z": 19,
      "name": "Soil_Grass"
    },
    {
      "x": -22,
      "y": 9,
      "z": 20,
      "name": "Soil_Grass"
    },
    {
      "x": -22,
      "y": 9,
      "z": 21,
      "name": "Soil_Grass"
    },
    {
      "x": -22,
      "y": 9,
      "z": 22,
      "name": "Soil_Grass"
    },
    {
      "x": -21,
      "y": 9,
      "z": -22,
      "name": "Soil_Grass"
    },
    {
      "x": -21,
      "y": 9,
      "z": -21,
      "name": "Soil_Dirt"
    },
    {
      "x": -21,
      "y": 10,
      "z": -21,
      "name": "Rock_Shale_Cobble"
    },
    {
      "x": -21,
      "y": 11,
      "z": -21,
      "name": "*Rock_Shale_Cobble_Stairs_State_Definitions_Corner_Left",
      "rotation": 2
    },
    {
      "x": -21,
      "y": 9,
      "z": -20,
      "name": "Soil_Dirt"
    },
    {
      "x": -21,
      "y": 10,
      "z": -20,
      "name": "Rock_Shale_Cobble"
    },
    {
      "x": -21,
      "y": 11,
      "z": -20,
      "name": "Rock_Shale_Cobble_Stairs",
      "rotation": 3
    },
    {
      "x": -21,
      "y": 9,
      "z": -19,
      "name": "Soil_Dirt"
    },
    {
      "x": -21,
      "y": 10,
      "z": -19,
      "name": "Rock_Shale_Cobble"
    },
    {
      "x": -21,
      "y": 11,
      "z": -19,
      "name": "Rock_Shale_Cobble_Stairs",
      "rotation": 3
    },
    {
      "x": -21,
      "y": 9,
      "z": -18,
      "name": "Soil_Dirt"
    },
    {
      "x": -21,
      "y": 10,
      "z": -18,
      "name": "Rock_Shale_Cobble"
    },
    {
      "x": -21,
      "y": 11,
      "z": -18,
      "name": "Rock_Shale_Cobble_Stairs",
      "rotation": 3
    },
    {
      "x": -21,
      "y": 9,
      "z": -17,
      "name": "Soil_Dirt"
    },
    {
      "x": -21,
      "y": 10,
      "z": -17,
      "name": "Rock_Shale_Cobble"
    },
    {
      "x": -21,
      "y": 11,
      "z": -17,
      "name": "Rock_Shale_Cobble_Stairs",
      "rotation": 3
    },
    {
      "x": -21,
      "y": 9,
      "z": -16,
      "name": "Soil_Dirt"
    },
    {
      "x": -21,
      "y": 10,
      "z": -16,
      "name": "Rock_Shale_Cobble"
    },
    {
      "x": -21,
      "y": 11,
      "z": -16,
      "name": "Rock_Shale_Cobble_Stairs",
      "rotation": 3
    },
    {
      "x": -21,
      "y": 9,
      "z": -15,
      "name": "Soil_Dirt"
    },
    {
      "x": -21,
      "y": 10,
      "z": -15,
      "name": "Rock_Shale_Cobble"
    },
    {
      "x": -21,
      "y": 11,
      "z": -15,
      "name": "Rock_Shale_Cobble_Stairs",
      "rotation": 3
    },
    {
      "x": -21,
      "y": 9,
      "z": -14,
      "name": "Soil_Dirt"
    },
    {
      "x": -21,
      "y": 10,
      "z": -14,
      "name": "Rock_Shale_Cobble"
    },
    {
      "x": -21,
      "y": 11,
      "z": -14,
      "name": "Rock_Shale_Cobble_Stairs",
      "rotation": 3
    },
    {
      "x": -21,
      "y": 9,
      "z": -13,
      "name": "Soil_Dirt"
    },
    {
      "x": -21,
      "y": 10,
      "z": -13,
      "name": "Rock_Shale_Cobble"
    },
    {
      "x": -21,
      "y": 11,
      "z": -13,
      "name": "Rock_Shale_Cobble_Stairs",
      "rotation": 3
    },
    {
      "x": -21,
      "y": 9,
      "z": -12,
      "name": "Soil_Dirt"
    },
    {
      "x": -21,
      "y": 10,
      "z": -12,
      "name": "Rock_Shale_Cobble"
    },
    {
      "x": -21,
      "y": 11,
      "z": -12,
      "name": "Rock_Shale_Cobble_Stairs",
      "rotation": 3
    },
    {
      "x": -21,
      "y": 9,
      "z": -11,
      "name": "Soil_Dirt"
    },
    {
      "x": -21,
      "y": 10,
      "z": -11,
      "name": "Rock_Shale_Cobble"
    },
    {
      "x": -21,
      "y": 11,
      "z": -11,
      "name": "Rock_Shale_Cobble_Stairs",
      "rotation": 3
    },
    {
      "x": -21,
      "y": 9,
      "z": -10,
      "name": "Soil_Dirt"
    },
    {
      "x": -21,
      "y": 10,
      "z": -10,
      "name": "Rock_Shale_Cobble"
    },
    {
      "x": -21,
      "y": 11,
      "z": -10,
      "name": "Rock_Shale_Cobble_Stairs",
      "rotation": 3
    },
    {
      "x": -21,
      "y": 9,
      "z": -9,
      "name": "Soil_Dirt"
    },
    {
      "x": -21,
      "y": 10,
      "z": -9,
      "name": "Rock_Shale_Cobble"
    },
    {
      "x": -21,
      "y": 11,
      "z": -9,
      "name": "Rock_Shale_Cobble_Stairs",
      "rotation": 3
    },
    {
      "x": -21,
      "y": 9,
      "z": -8,
      "name": "Soil_Dirt"
    },
    {
      "x": -21,
      "y": 10,
      "z": -8,
      "name": "Rock_Shale_Cobble"
    },
    {
      "x": -21,
      "y": 11,
      "z": -8,
      "name": "Rock_Shale_Cobble_Stairs",
      "rotation": 3
    },
    {
      "x": -21,
      "y": 9,
      "z": -7,
      "name": "Soil_Dirt"
    },
    {
      "x": -21,
      "y": 10,
      "z": -7,
      "name": "Rock_Shale_Cobble"
    },
    {
      "x": -21,
      "y": 11,
      "z": -7,
      "name": "Rock_Shale_Cobble_Stairs",
      "rotation": 3
    },
    {
      "x": -21,
      "y": 9,
      "z": -6,
      "name": "Soil_Dirt"
    },
    {
      "x": -21,
      "y": 10,
      "z": -6,
      "name": "Rock_Shale_Cobble"
    },
    {
      "x": -21,
      "y": 11,
      "z": -6,
      "name": "Rock_Shale_Cobble_Stairs",
      "rotation": 3
    },
    {
      "x": -21,
      "y": 9,
      "z": -5,
      "name": "Soil_Dirt"
    },
    {
      "x": -21,
      "y": 10,
      "z": -5,
      "name": "Rock_Shale_Cobble"
    },
    {
      "x": -21,
      "y": 11,
      "z": -5,
      "name": "Rock_Shale_Cobble_Stairs",
      "rotation": 3
    },
    {
      "x": -21,
      "y": 9,
      "z": -4,
      "name": "Soil_Dirt"
    },
    {
      "x": -21,
      "y": 10,
      "z": -4,
      "name": "Rock_Shale_Cobble"
    },
    {
      "x": -21,
      "y": 11,
      "z": -4,
      "name": "Rock_Shale_Cobble_Stairs",
      "rotation": 3
    },
    {
      "x": -21,
      "y": 9,
      "z": -3,
      "name": "Soil_Dirt"
    },
    {
      "x": -21,
      "y": 10,
      "z": -3,
      "name": "Rock_Shale_Cobble"
    },
    {
      "x": -21,
      "y": 11,
      "z": -3,
      "name": "Rock_Shale_Cobble_Stairs",
      "rotation": 3
    },
    {
      "x": -21,
      "y": 9,
      "z": -2,
      "name": "Soil_Dirt"
    },
    {
      "x": -21,
      "y": 10,
      "z": -2,
      "name": "Rock_Shale_Cobble"
    },
    {
      "x": -21,
      "y": 11,
      "z": -2,
      "name": "Rock_Shale_Cobble_Stairs",
      "rotation": 3
    },
    {
      "x": -21,
      "y": 9,
      "z": -1,
      "name": "Soil_Dirt"
    },
    {
      "x": -21,
      "y": 10,
      "z": -1,
      "name": "Rock_Shale_Cobble"
    },
    {
      "x": -21,
      "y": 11,
      "z": -1,
      "name": "Rock_Shale_Cobble_Stairs",
      "rotation": 3
    },
    {
      "x": -21,
      "y": 9,
      "z": 0,
      "name": "Soil_Dirt"
    },
    {
      "x": -21,
      "y": 10,
      "z": 0,
      "name": "Rock_Shale_Cobble"
    },
    {
      "x": -21,
      "y": 11,
      "z": 0,
      "name": "Rock_Shale_Cobble_Stairs",
      "rotation": 3
    },
    {
      "x": -21,
      "y": 9,
      "z": 1,
      "name": "Soil_Dirt"
    },
    {
      "x": -21,
      "y": 10,
      "z": 1,
      "name": "Rock_Shale_Cobble"
    },
    {
      "x": -21,
      "y": 11,
      "z": 1,
      "name": "Rock_Shale_Cobble_Stairs",
      "rotation": 3
    },
    {
      "x": -21,
      "y": 9,
      "z": 2,
      "name": "Soil_Dirt"
    },
    {
      "x": -21,
      "y": 10,
      "z": 2,
      "name": "Rock_Shale_Cobble"
    },
    {
      "x": -21,
      "y": 11,
      "z": 2,
      "name": "Rock_Shale_Cobble_Stairs",
      "rotation": 3
    },
    {
      "x": -21,
      "y": 9,
      "z": 3,
      "name": "Soil_Dirt"
    },
    {
      "x": -21,
      "y": 10,
      "z": 3,
      "name": "Rock_Shale_Cobble"
    },
    {
      "x": -21,
      "y": 11,
      "z": 3,
      "name": "Rock_Shale_Cobble_Stairs",
      "rotation": 3
    },
    {
      "x": -21,
      "y": 9,
      "z": 4,
      "name": "Soil_Dirt"
    },
    {
      "x": -21,
      "y": 10,
      "z": 4,
      "name": "Rock_Shale_Cobble"
    },
    {
      "x": -21,
      "y": 11,
      "z": 4,
      "name": "Rock_Shale_Cobble_Stairs",
      "rotation": 3
    },
    {
      "x": -21,
      "y": 9,
      "z": 5,
      "name": "Soil_Dirt"
    },
    {
      "x": -21,
      "y": 10,
      "z": 5,
      "name": "Rock_Shale_Cobble"
    },
    {
      "x": -21,
      "y": 11,
      "z": 5,
      "name": "Rock_Shale_Cobble_Stairs",
      "rotation": 3
    },
    {
      "x": -21,
      "y": 9,
      "z": 6,
      "name": "Soil_Dirt"
    },
    {
      "x": -21,
      "y": 10,
      "z": 6,
      "name": "Rock_Shale_Cobble"
    },
    {
      "x": -21,
      "y": 11,
      "z": 6,
      "name": "Rock_Shale_Cobble_Stairs",
      "rotation": 3
    },
    {
      "x": -21,
      "y": 9,
      "z": 7,
      "name": "Soil_Dirt"
    },
    {
      "x": -21,
      "y": 10,
      "z": 7,
      "name": "Rock_Shale_Cobble"
    },
    {
      "x": -21,
      "y": 11,
      "z": 7,
      "name": "Rock_Shale_Cobble_Stairs",
      "rotation": 3
    },
    {
      "x": -21,
      "y": 9,
      "z": 8,
      "name": "Soil_Dirt"
    },
    {
      "x": -21,
      "y": 10,
      "z": 8,
      "name": "Rock_Shale_Cobble"
    },
    {
      "x": -21,
      "y": 11,
      "z": 8,
      "name": "Rock_Shale_Cobble_Stairs",
      "rotation": 3
    },
    {
      "x": -21,
      "y": 9,
      "z": 9,
      "name": "Soil_Dirt"
    },
    {
      "x": -21,
      "y": 10,
      "z": 9,
      "name": "Rock_Shale_Cobble"
    },
    {
      "x": -21,
      "y": 11,
      "z": 9,
      "name": "Rock_Shale_Cobble_Stairs",
      "rotation": 3
    },
    {
      "x": -21,
      "y": 9,
      "z": 10,
      "name": "Soil_Dirt"
    },
    {
      "x": -21,
      "y": 10,
      "z": 10,
      "name": "Rock_Shale_Cobble"
    },
    {
      "x": -21,
      "y": 11,
      "z": 10,
      "name": "Rock_Shale_Cobble_Stairs",
      "rotation": 3
    },
    {
      "x": -21,
      "y": 9,
      "z": 11,
      "name": "Soil_Dirt"
    },
    {
      "x": -21,
      "y": 10,
      "z": 11,
      "name": "Rock_Shale_Cobble"
    },
    {
      "x": -21,
      "y": 11,
      "z": 11,
      "name": "Rock_Shale_Cobble_Stairs",
      "rotation": 3
    },
    {
      "x": -21,
      "y": 9,
      "z": 12,
      "name": "Soil_Dirt"
    },
    {
      "x": -21,
      "y": 10,
      "z": 12,
      "name": "Rock_Shale_Cobble"
    },
    {
      "x": -21,
      "y": 11,
      "z": 12,
      "name": "Rock_Shale_Cobble_Stairs",
      "rotation": 3
    },
    {
      "x": -21,
      "y": 9,
      "z": 13,
      "name": "Soil_Dirt"
    },
    {
      "x": -21,
      "y": 10,
      "z": 13,
      "name": "Rock_Shale_Cobble"
    },
    {
      "x": -21,
      "y": 11,
      "z": 13,
      "name": "Rock_Shale_Cobble_Stairs",
      "rotation": 3
    },
    {
      "x": -21,
      "y": 9,
      "z": 14,
      "name": "Soil_Dirt"
    },
    {
      "x": -21,
      "y": 10,
      "z": 14,
      "name": "Rock_Shale_Cobble"
    },
    {
      "x": -21,
      "y": 11,
      "z": 14,
      "name": "Rock_Shale_Cobble_Stairs",
      "rotation": 3
    },
    {
      "x": -21,
      "y": 9,
      "z": 15,
      "name": "Soil_Dirt"
    },
    {
      "x": -21,
      "y": 10,
      "z": 15,
      "name": "Rock_Shale_Cobble"
    },
    {
      "x": -21,
      "y": 11,
      "z": 15,
      "name": "Rock_Shale_Cobble_Stairs",
      "rotation": 3
    },
    {
      "x": -21,
      "y": 9,
      "z": 16,
      "name": "Soil_Dirt"
    },
    {
      "x": -21,
      "y": 10,
      "z": 16,
      "name": "Rock_Shale_Cobble"
    },
    {
      "x": -21,
      "y": 11,
      "z": 16,
      "name": "Rock_Shale_Cobble_Stairs",
      "rotation": 3
    },
    {
      "x": -21,
      "y": 9,
      "z": 17,
      "name": "Soil_Dirt"
    },
    {
      "x": -21,
      "y": 10,
      "z": 17,
      "name": "Rock_Shale_Cobble"
    },
    {
      "x": -21,
      "y": 11,
      "z": 17,
      "name": "Rock_Shale_Cobble_Stairs",
      "rotation": 3
    },
    {
      "x": -21,
      "y": 9,
      "z": 18,
      "name": "Soil_Dirt"
    },
    {
      "x": -21,
      "y": 10,
      "z": 18,
      "name": "Rock_Shale_Cobble"
    },
    {
      "x": -21,
      "y": 11,
      "z": 18,
      "name": "Rock_Shale_Cobble_Stairs",
      "rotation": 3
    },
    {
      "x": -21,
      "y": 9,
      "z": 19,
      "name": "Soil_Dirt"
    },
    {
      "x": -21,
      "y": 10,
      "z": 19,
      "name": "Rock_Shale_Cobble"
    },
    {
      "x": -21,
      "y": 11,
      "z": 19,
      "name": "Rock_Shale_Cobble_Stairs",
      "rotation": 3
    },
    {
      "x": -21,
      "y": 9,
      "z": 20,
      "name": "Soil_Dirt"
    },
    {
      "x": -21,
      "y": 10,
      "z": 20,
      "name": "Rock_Shale_Cobble"
    },
    {
      "x": -21,
      "y": 11,
      "z": 20,
      "name": "Rock_Shale_Cobble_Stairs",
      "rotation": 3
    },
    {
      "x": -21,
      "y": 9,
      "z": 21,
      "name": "Soil_Dirt"
    },
    {
      "x": -21,
      "y": 10,
      "z": 21,
      "name": "Rock_Shale_Cobble"
    },
    {
      "x": -21,
      "y": 11,
      "z": 21,
      "name": "*Rock_Shale_Cobble_Stairs_State_Definitions_Corner_Left",
      "rotation": 3
    },
    {
      "x": -21,
      "y": 9,
      "z": 22,
      "name": "Soil_Grass"
    },
    {
      "x": -20,
      "y": 9,
      "z": -22,
      "name": "Soil_Grass"
    },
    {
      "x": -20,
      "y": 9,
      "z": -21,
      "name": "Soil_Dirt"
    },
    {
      "x": -20,
      "y": 10,
      "z": -21,
      "name": "Rock_Shale_Cobble"
    },
    {
      "x": -20,
      "y": 11,
      "z": -21,
      "name": "Rock_Shale_Cobble_Stairs",
      "rotation": 2
    },
    {
      "x": -20,
      "y": 9,
      "z": -20,
      "name": "Soil_Dirt"
    },
    {
      "x": -20,
      "y": 10,
      "z": -20,
      "name": "Rock_Shale_Cobble"
    },
    {
      "x": -20,
      "y": 11,
      "z": -20,
      "name": "Rock_Shale_Cobble"
    },
    {
      "x": -20,
      "y": 12,
      "z": -20,
      "name": "*Rock_Shale_Cobble_Stairs_State_Definitions_Corner_Left",
      "rotation": 2
    },
    {
      "x": -20,
      "y": 9,
      "z": -19,
      "name": "Soil_Dirt"
    },
    {
      "x": -20,
      "y": 10,
      "z": -19,
      "name": "Rock_Shale_Cobble"
    },
    {
      "x": -20,
      "y": 11,
      "z": -19,
      "name": "Rock_Shale_Cobble"
    },
    {
      "x": -20,
      "y": 12,
      "z": -19,
      "name": "Rock_Shale_Cobble_Stairs",
      "rotation": 3
    },
    {
      "x": -20,
      "y": 9,
      "z": -18,
      "name": "Soil_Dirt"
    },
    {
      "x": -20,
      "y": 10,
      "z": -18,
      "name": "Rock_Shale_Cobble"
    },
    {
      "x": -20,
      "y": 11,
      "z": -18,
      "name": "Rock_Shale_Cobble"
    },
    {
      "x": -20,
      "y": 12,
      "z": -18,
      "name": "Rock_Shale_Cobble_Stairs",
      "rotation": 3
    },
    {
      "x": -20,
      "y": 9,
      "z": -17,
      "name": "Soil_Dirt"
    },
    {
      "x": -20,
      "y": 10,
      "z": -17,
      "name": "Rock_Shale_Cobble"
    },
    {
      "x": -20,
      "y": 11,
      "z": -17,
      "name": "Rock_Shale_Cobble"
    },
    {
      "x": -20,
      "y": 12,
      "z": -17,
      "name": "Rock_Shale_Cobble_Stairs",
      "rotation": 3
    },
    {
      "x": -20,
      "y": 9,
      "z": -16,
      "name": "Soil_Dirt"
    },
    {
      "x": -20,
      "y": 10,
      "z": -16,
      "name": "Rock_Shale_Cobble"
    },
    {
      "x": -20,
      "y": 11,
      "z": -16,
      "name": "Rock_Shale_Cobble"
    },
    {
      "x": -20,
      "y": 12,
      "z": -16,
      "name": "Rock_Shale_Cobble_Stairs",
      "rotation": 3
    },
    {
      "x": -20,
      "y": 9,
      "z": -15,
      "name": "Soil_Dirt"
    },
    {
      "x": -20,
      "y": 10,
      "z": -15,
      "name": "Rock_Shale_Cobble"
    },
    {
      "x": -20,
      "y": 11,
      "z": -15,
      "name": "Rock_Shale_Cobble"
    },
    {
      "x": -20,
      "y": 12,
      "z": -15,
      "name": "Rock_Shale_Cobble_Stairs",
      "rotation": 3
    },
    {
      "x": -20,
      "y": 9,
      "z": -14,
      "name": "Soil_Dirt"
    },
    {
      "x": -20,
      "y": 10,
      "z": -14,
      "name": "Rock_Shale_Cobble"
    },
    {
      "x": -20,
      "y": 11,
      "z": -14,
      "name": "Rock_Shale_Cobble"
    },
    {
      "x": -20,
      "y": 12,
      "z": -14,
      "name": "Rock_Shale_Cobble_Stairs",
      "rotation": 3
    },
    {
      "x": -20,
      "y": 9,
      "z": -13,
      "name": "Soil_Dirt"
    },
    {
      "x": -20,
      "y": 10,
      "z": -13,
      "name": "Rock_Shale_Cobble"
    },
    {
      "x": -20,
      "y": 11,
      "z": -13,
      "name": "Rock_Shale_Cobble"
    },
    {
      "x": -20,
      "y": 12,
      "z": -13,
      "name": "Rock_Shale_Cobble_Stairs",
      "rotation": 3
    },
    {
      "x": -20,
      "y": 15,
      "z": -13,
      "name": "Plant_Moss_Wall_Green_Dark",
      "support": 15,
      "rotation": 3
    },
    {
      "x": -20,
      "y": 9,
      "z": -12,
      "name": "Soil_Dirt"
    },
    {
      "x": -20,
      "y": 10,
      "z": -12,
      "name": "Rock_Shale_Cobble"
    },
    {
      "x": -20,
      "y": 11,
      "z": -12,
      "name": "Rock_Shale_Cobble"
    },
    {
      "x": -20,
      "y": 12,
      "z": -12,
      "name": "Rock_Shale_Cobble_Stairs",
      "rotation": 3
    },
    {
      "x": -20,
      "y": 9,
      "z": -11,
      "name": "Soil_Dirt"
    },
    {
      "x": -20,
      "y": 10,
      "z": -11,
      "name": "Rock_Shale_Cobble"
    },
    {
      "x": -20,
      "y": 11,
      "z": -11,
      "name": "Rock_Shale_Cobble"
    },
    {
      "x": -20,
      "y": 12,
      "z": -11,
      "name": "Rock_Shale_Cobble_Stairs",
      "rotation": 3
    },
    {
      "x": -20,
      "y": 9,
      "z": -10,
      "name": "Soil_Dirt"
    },
    {
      "x": -20,
      "y": 10,
      "z": -10,
      "name": "Rock_Shale_Cobble"
    },
    {
      "x": -20,
      "y": 11,
      "z": -10,
      "name": "Rock_Shale_Cobble"
    },
    {
      "x": -20,
      "y": 12,
      "z": -10,
      "name": "*Rock_Shale_Cobble_Stairs_State_Definitions_Corner_Left",
      "rotation": 3
    },
    {
      "x": -20,
      "y": 9,
      "z": -9,
      "name": "Soil_Dirt"
    },
    {
      "x": -20,
      "y": 10,
      "z": -9,
      "name": "Rock_Shale_Cobble"
    },
    {
      "x": -20,
      "y": 11,
      "z": -9,
      "name": "Rock_Shale_Cobble"
    },
    {
      "x": -20,
      "y": 9,
      "z": -8,
      "name": "Soil_Dirt"
    },
    {
      "x": -20,
      "y": 10,
      "z": -8,
      "name": "Rock_Shale_Cobble"
    },
    {
      "x": -20,
      "y": 11,
      "z": -8,
      "name": "Rock_Shale_Cobble"
    },
    {
      "x": -20,
      "y": 9,
      "z": -7,
      "name": "Soil_Dirt"
    },
    {
      "x": -20,
      "y": 10,
      "z": -7,
      "name": "Rock_Shale_Cobble"
    },
    {
      "x": -20,
      "y": 11,
      "z": -7,
      "name": "Rock_Shale_Cobble"
    },
    {
      "x": -20,
      "y": 9,
      "z": -6,
      "name": "Soil_Dirt"
    },
    {
      "x": -20,
      "y": 10,
      "z": -6,
      "name": "Rock_Shale_Cobble"
    },
    {
      "x": -20,
      "y": 11,
      "z": -6,
      "name": "Rock_Shale_Cobble"
    },
    {
      "x": -20,
      "y": 9,
      "z": -5,
      "name": "Soil_Dirt"
    },
    {
      "x": -20,
      "y": 10,
      "z": -5,
      "name": "Rock_Shale_Cobble"
    },
    {
      "x": -20,
      "y": 11,
      "z": -5,
      "name": "Rock_Shale_Cobble"
    },
    {
      "x": -20,
      "y": 9,
      "z": -4,
      "name": "Soil_Dirt"
    },
    {
      "x": -20,
      "y": 10,
      "z": -4,
      "name": "Rock_Shale_Cobble"
    },
    {
      "x": -20,
      "y": 11,
      "z": -4,
      "name": "Rock_Shale_Cobble"
    },
    {
      "x": -20,
      "y": 9,
      "z": -3,
      "name": "Soil_Dirt"
    },
    {
      "x": -20,
      "y": 10,
      "z": -3,
      "name": "Rock_Shale_Cobble"
    },
    {
      "x": -20,
      "y": 11,
      "z": -3,
      "name": "Rock_Shale_Cobble"
    },
    {
      "x": -20,
      "y": 9,
      "z": -2,
      "name": "Soil_Dirt"
    },
    {
      "x": -20,
      "y": 10,
      "z": -2,
      "name": "Rock_Shale_Cobble"
    },
    {
      "x": -20,
      "y": 11,
      "z": -2,
      "name": "Rock_Shale_Cobble"
    },
    {
      "x": -20,
      "y": 12,
      "z": -2,
      "name": "Plant_Moss_Rug_Green_Dark",
      "support": 15
    },
    {
      "x": -20,
      "y": 9,
      "z": -1,
      "name": "Soil_Dirt"
    },
    {
      "x": -20,
      "y": 10,
      "z": -1,
      "name": "Rock_Shale_Cobble"
    },
    {
      "x": -20,
      "y": 11,
      "z": -1,
      "name": "Rock_Shale_Cobble"
    },
    {
      "x": -20,
      "y": 9,
      "z": 0,
      "name": "Soil_Dirt"
    },
    {
      "x": -20,
      "y": 10,
      "z": 0,
      "name": "Rock_Shale_Cobble"
    },
    {
      "x": -20,
      "y": 11,
      "z": 0,
      "name": "Rock_Shale_Cobble"
    },
    {
      "x": -20,
      "y": 9,
      "z": 1,
      "name": "Soil_Dirt"
    },
    {
      "x": -20,
      "y": 10,
      "z": 1,
      "name": "Rock_Shale_Cobble"
    },
    {
      "x": -20,
      "y": 11,
      "z": 1,
      "name": "Rock_Shale_Cobble"
    },
    {
      "x": -20,
      "y": 9,
      "z": 2,
      "name": "Soil_Dirt"
    },
    {
      "x": -20,
      "y": 10,
      "z": 2,
      "name": "Rock_Shale_Cobble"
    },
    {
      "x": -20,
      "y": 11,
      "z": 2,
      "name": "Rock_Shale_Cobble"
    },
    {
      "x": -20,
      "y": 9,
      "z": 3,
      "name": "Soil_Dirt"
    },
    {
      "x": -20,
      "y": 10,
      "z": 3,
      "name": "Rock_Shale_Cobble"
    },
    {
      "x": -20,
      "y": 11,
      "z": 3,
      "name": "Rock_Shale_Cobble"
    },
    {
      "x": -20,
      "y": 9,
      "z": 4,
      "name": "Soil_Dirt"
    },
    {
      "x": -20,
      "y": 10,
      "z": 4,
      "name": "Rock_Shale_Cobble"
    },
    {
      "x": -20,
      "y": 11,
      "z": 4,
      "name": "Rock_Shale_Cobble"
    },
    {
      "x": -20,
      "y": 9,
      "z": 5,
      "name": "Soil_Dirt"
    },
    {
      "x": -20,
      "y": 10,
      "z": 5,
      "name": "Rock_Shale_Cobble"
    },
    {
      "x": -20,
      "y": 11,
      "z": 5,
      "name": "Rock_Shale_Cobble"
    },
    {
      "x": -20,
      "y": 9,
      "z": 6,
      "name": "Soil_Dirt"
    },
    {
      "x": -20,
      "y": 10,
      "z": 6,
      "name": "Rock_Shale_Cobble"
    },
    {
      "x": -20,
      "y": 11,
      "z": 6,
      "name": "Rock_Shale_Cobble"
    },
    {
      "x": -20,
      "y": 9,
      "z": 7,
      "name": "Soil_Dirt"
    },
    {
      "x": -20,
      "y": 10,
      "z": 7,
      "name": "Rock_Shale_Cobble"
    },
    {
      "x": -20,
      "y": 11,
      "z": 7,
      "name": "Rock_Shale_Cobble"
    },
    {
      "x": -20,
      "y": 12,
      "z": 7,
      "name": "Plant_Moss_Rug_Green_Dark",
      "support": 15
    },
    {
      "x": -20,
      "y": 9,
      "z": 8,
      "name": "Soil_Dirt"
    },
    {
      "x": -20,
      "y": 10,
      "z": 8,
      "name": "Rock_Shale_Cobble"
    },
    {
      "x": -20,
      "y": 11,
      "z": 8,
      "name": "Rock_Shale_Cobble"
    },
    {
      "x": -20,
      "y": 12,
      "z": 8,
      "name": "Plant_Moss_Rug_Green_Dark",
      "support": 15
    },
    {
      "x": -20,
      "y": 9,
      "z": 9,
      "name": "Soil_Dirt"
    },
    {
      "x": -20,
      "y": 10,
      "z": 9,
      "name": "Rock_Shale_Cobble"
    },
    {
      "x": -20,
      "y": 11,
      "z": 9,
      "name": "Rock_Shale_Cobble"
    },
    {
      "x": -20,
      "y": 9,
      "z": 10,
      "name": "Soil_Dirt"
    },
    {
      "x": -20,
      "y": 10,
      "z": 10,
      "name": "Rock_Shale_Cobble"
    },
    {
      "x": -20,
      "y": 11,
      "z": 10,
      "name": "Rock_Shale_Cobble"
    },
    {
      "x": -20,
      "y": 12,
      "z": 10,
      "name": "*Rock_Shale_Cobble_Stairs_State_Definitions_Corner_Left",
      "rotation": 2
    },
    {
      "x": -20,
      "y": 9,
      "z": 11,
      "name": "Soil_Dirt"
    },
    {
      "x": -20,
      "y": 10,
      "z": 11,
      "name": "Rock_Shale_Cobble"
    },
    {
      "x": -20,
      "y": 11,
      "z": 11,
      "name": "Rock_Shale_Cobble"
    },
    {
      "x": -20,
      "y": 12,
      "z": 11,
      "name": "Rock_Shale_Cobble_Stairs",
      "rotation": 3
    },
    {
      "x": -20,
      "y": 9,
      "z": 12,
      "name": "Soil_Dirt"
    },
    {
      "x": -20,
      "y": 10,
      "z": 12,
      "name": "Rock_Shale_Cobble"
    },
    {
      "x": -20,
      "y": 11,
      "z": 12,
      "name": "Rock_Shale_Cobble"
    },
    {
      "x": -20,
      "y": 12,
      "z": 12,
      "name": "Rock_Shale_Cobble_Stairs",
      "rotation": 3
    },
    {
      "x": -20,
      "y": 14,
      "z": 12,
      "name": "Plant_Moss_Wall_Green_Dark",
      "support": 15,
      "rotation": 3
    },
    {
      "x": -20,
      "y": 9,
      "z": 13,
      "name": "Soil_Dirt"
    },
    {
      "x": -20,
      "y": 10,
      "z": 13,
      "name": "Rock_Shale_Cobble"
    },
    {
      "x": -20,
      "y": 11,
      "z": 13,
      "name": "Rock_Shale_Cobble"
    },
    {
      "x": -20,
      "y": 12,
      "z": 13,
      "name": "Rock_Shale_Cobble_Stairs",
      "rotation": 3
    },
    {
      "x": -20,
      "y": 9,
      "z": 14,
      "name": "Soil_Dirt"
    },
    {
      "x": -20,
      "y": 10,
      "z": 14,
      "name": "Rock_Shale_Cobble"
    },
    {
      "x": -20,
      "y": 11,
      "z": 14,
      "name": "Rock_Shale_Cobble"
    },
    {
      "x": -20,
      "y": 12,
      "z": 14,
      "name": "Rock_Shale_Cobble_Stairs",
      "rotation": 3
    },
    {
      "x": -20,
      "y": 9,
      "z": 15,
      "name": "Soil_Dirt"
    },
    {
      "x": -20,
      "y": 10,
      "z": 15,
      "name": "Rock_Shale_Cobble"
    },
    {
      "x": -20,
      "y": 11,
      "z": 15,
      "name": "Rock_Shale_Cobble"
    },
    {
      "x": -20,
      "y": 12,
      "z": 15,
      "name": "Rock_Shale_Cobble_Stairs",
      "rotation": 3
    },
    {
      "x": -20,
      "y": 9,
      "z": 16,
      "name": "Soil_Dirt"
    },
    {
      "x": -20,
      "y": 10,
      "z": 16,
      "name": "Rock_Shale_Cobble"
    },
    {
      "x": -20,
      "y": 11,
      "z": 16,
      "name": "Rock_Shale_Cobble"
    },
    {
      "x": -20,
      "y": 12,
      "z": 16,
      "name": "Rock_Shale_Cobble_Stairs",
      "rotation": 3
    },
    {
      "x": -20,
      "y": 9,
      "z": 17,
      "name": "Soil_Dirt"
    },
    {
      "x": -20,
      "y": 10,
      "z": 17,
      "name": "Rock_Shale_Cobble"
    },
    {
      "x": -20,
      "y": 11,
      "z": 17,
      "name": "Rock_Shale_Cobble"
    },
    {
      "x": -20,
      "y": 12,
      "z": 17,
      "name": "Rock_Shale_Cobble_Stairs",
      "rotation": 3
    },
    {
      "x": -20,
      "y": 9,
      "z": 18,
      "name": "Soil_Dirt"
    },
    {
      "x": -20,
      "y": 10,
      "z": 18,
      "name": "Rock_Shale_Cobble"
    },
    {
      "x": -20,
      "y": 11,
      "z": 18,
      "name": "Rock_Shale_Cobble"
    },
    {
      "x": -20,
      "y": 12,
      "z": 18,
      "name": "Rock_Shale_Cobble_Stairs",
      "rotation": 3
    },
    {
      "x": -20,
      "y": 9,
      "z": 19,
      "name": "Soil_Dirt"
    },
    {
      "x": -20,
      "y": 10,
      "z": 19,
      "name": "Rock_Shale_Cobble"
    },
    {
      "x": -20,
      "y": 11,
      "z": 19,
      "name": "Rock_Shale_Cobble"
    },
    {
      "x": -20,
      "y": 12,
      "z": 19,
      "name": "Rock_Shale_Cobble_Stairs",
      "rotation": 3
    },
    {
      "x": -20,
      "y": 9,
      "z": 20,
      "name": "Soil_Dirt"
    },
    {
      "x": -20,
      "y": 10,
      "z": 20,
      "name": "Rock_Shale_Cobble"
    },
    {
      "x": -20,
      "y": 11,
      "z": 20,
      "name": "Rock_Shale_Cobble"
    },
    {
      "x": -20,
      "y": 12,
      "z": 20,
      "name": "*Rock_Shale_Cobble_Stairs_State_Definitions_Corner_Left",
      "rotation": 3
    },
    {
      "x": -20,
      "y": 9,
      "z": 21,
      "name": "Soil_Dirt"
    },
    {
      "x": -20,
      "y": 10,
      "z": 21,
      "name": "Rock_Shale_Cobble"
    },
    {
      "x": -20,
      "y": 11,
      "z": 21,
      "name": "Rock_Shale_Cobble_Stairs"
    },
    {
      "x": -20,
      "y": 9,
      "z": 22,
      "name": "Soil_Grass"
    },
    {
      "x": -19,
      "y": 9,
      "z": -22,
      "name": "Soil_Grass"
    },
    {
      "x": -19,
      "y": 9,
      "z": -21,
      "name": "Soil_Dirt"
    },
    {
      "x": -19,
      "y": 10,
      "z": -21,
      "name": "Rock_Shale_Cobble"
    },
    {
      "x": -19,
      "y": 11,
      "z": -21,
      "name": "Rock_Shale_Cobble_Stairs",
      "rotation": 2
    },
    {
      "x": -19,
      "y": 9,
      "z": -20,
      "name": "Soil_Dirt"
    },
    {
      "x": -19,
      "y": 10,
      "z": -20,
      "name": "Rock_Shale_Cobble"
    },
    {
      "x": -19,
      "y": 11,
      "z": -20,
      "name": "Rock_Shale_Cobble"
    },
    {
      "x": -19,
      "y": 12,
      "z": -20,
      "name": "Rock_Shale_Cobble_Stairs",
      "rotation": 2
    },
    {
      "x": -19,
      "y": 9,
      "z": -19,
      "name": "Soil_Dirt"
    },
    {
      "x": -19,
      "y": 10,
      "z": -19,
      "name": "Rock_Shale_Cobble"
    },
    {
      "x": -19,
      "y": 11,
      "z": -19,
      "name": "Rock_Shale_Cobble"
    },
    {
      "x": -19,
      "y": 12,
      "z": -19,
      "name": "Rock_Shale_Cobble",
      "rotation": 3
    },
    {
      "x": -19,
      "y": 13,
      "z": -19,
      "name": "Rock_Shale_Brick",
      "rotation": 3
    },
    {
      "x": -19,
      "y": 14,
      "z": -19,
      "name": "Rock_Shale_Brick",
      "rotation": 3
    },
    {
      "x": -19,
      "y": 15,
      "z": -19,
      "name": "Rock_Shale_Brick_Smooth",
      "rotation": 3
    },
    {
      "x": -19,
      "y": 9,
      "z": -18,
      "name": "Soil_Dirt"
    },
    {
      "x": -19,
      "y": 10,
      "z": -18,
      "name": "Rock_Shale_Cobble"
    },
    {
      "x": -19,
      "y": 11,
      "z": -18,
      "name": "Rock_Shale_Cobble"
    },
    {
      "x": -19,
      "y": 12,
      "z": -18,
      "name": "Rock_Shale_Cobble",
      "rotation": 3
    },
    {
      "x": -19,
      "y": 13,
      "z": -18,
      "name": "Rock_Shale_Brick",
      "rotation": 3
    },
    {
      "x": -19,
      "y": 14,
      "z": -18,
      "name": "Rock_Shale_Brick",
      "rotation": 3
    },
    {
      "x": -19,
      "y": 9,
      "z": -17,
      "name": "Soil_Dirt"
    },
    {
      "x": -19,
      "y": 10,
      "z": -17,
      "name": "Rock_Shale_Cobble"
    },
    {
      "x": -19,
      "y": 11,
      "z": -17,
      "name": "Rock_Shale_Cobble"
    },
    {
      "x": -19,
      "y": 12,
      "z": -17,
      "name": "Rock_Shale_Cobble",
      "rotation": 3
    },
    {
      "x": -19,
      "y": 13,
      "z": -17,
      "name": "Rock_Shale_Brick",
      "rotation": 3
    },
    {
      "x": -19,
      "y": 14,
      "z": -17,
      "name": "Rock_Shale_Brick",
      "rotation": 3
    },
    {
      "x": -19,
      "y": 15,
      "z": -17,
      "name": "Rock_Shale_Brick_Smooth",
      "rotation": 3
    },
    {
      "x": -19,
      "y": 9,
      "z": -16,
      "name": "Soil_Dirt"
    },
    {
      "x": -19,
      "y": 10,
      "z": -16,
      "name": "Rock_Shale_Cobble"
    },
    {
      "x": -19,
      "y": 11,
      "z": -16,
      "name": "Rock_Shale_Cobble"
    },
    {
      "x": -19,
      "y": 12,
      "z": -16,
      "name": "Rock_Shale_Cobble",
      "rotation": 3
    },
    {
      "x": -19,
      "y": 13,
      "z": -16,
      "name": "Rock_Shale_Brick",
      "rotation": 3
    },
    {
      "x": -19,
      "y": 14,
      "z": -16,
      "name": "Rock_Shale_Brick",
      "rotation": 3
    },
    {
      "x": -19,
      "y": 9,
      "z": -15,
      "name": "Soil_Dirt"
    },
    {
      "x": -19,
      "y": 10,
      "z": -15,
      "name": "Rock_Shale_Cobble"
    },
    {
      "x": -19,
      "y": 11,
      "z": -15,
      "name": "Rock_Shale_Cobble"
    },
    {
      "x": -19,
      "y": 12,
      "z": -15,
      "name": "Rock_Shale_Cobble",
      "rotation": 3
    },
    {
      "x": -19,
      "y": 13,
      "z": -15,
      "name": "Rock_Shale_Brick",
      "rotation": 3
    },
    {
      "x": -19,
      "y": 14,
      "z": -15,
      "name": "Rock_Shale_Brick",
      "rotation": 3
    },
    {
      "x": -19,
      "y": 15,
      "z": -15,
      "name": "Rock_Shale_Brick_Smooth",
      "rotation": 3
    },
    {
      "x": -19,
      "y": 9,
      "z": -14,
      "name": "Soil_Dirt"
    },
    {
      "x": -19,
      "y": 10,
      "z": -14,
      "name": "Rock_Shale_Cobble"
    },
    {
      "x": -19,
      "y": 11,
      "z": -14,
      "name": "Rock_Shale_Cobble"
    },
    {
      "x": -19,
      "y": 12,
      "z": -14,
      "name": "Rock_Shale_Cobble",
      "rotation": 3
    },
    {
      "x": -19,
      "y": 13,
      "z": -14,
      "name": "Rock_Shale_Brick",
      "rotation": 3
    },
    {
      "x": -19,
      "y": 14,
      "z": -14,
      "name": "Rock_Shale_Brick",
      "rotation": 3
    },
    {
      "x": -19,
      "y": 15,
      "z": -14,
      "name": "Plant_Moss_Rug_Green_Dark",
      "support": 15
    },
    {
      "x": -19,
      "y": 9,
      "z": -13,
      "name": "Soil_Dirt"
    },
    {
      "x": -19,
      "y": 10,
      "z": -13,
      "name": "Rock_Shale_Cobble"
    },
    {
      "x": -19,
      "y": 11,
      "z": -13,
      "name": "Rock_Shale_Cobble"
    },
    {
      "x": -19,
      "y": 12,
      "z": -13,
      "name": "Rock_Shale_Cobble",
      "rotation": 3
    },
    {
      "x": -19,
      "y": 13,
      "z": -13,
      "name": "Rock_Shale_Brick",
      "rotation": 3
    },
    {
      "x": -19,
      "y": 14,
      "z": -13,
      "name": "Rock_Shale_Brick",
      "rotation": 3
    },
    {
      "x": -19,
      "y": 15,
      "z": -13,
      "name": "Rock_Shale_Brick_Smooth",
      "rotation": 3
    },
    {
      "x": -19,
      "y": 16,
      "z": -13,
      "name": "Plant_Moss_Rug_Green_Dark",
      "support": 15
    },
    {
      "x": -19,
      "y": 9,
      "z": -12,
      "name": "Soil_Dirt"
    },
    {
      "x": -19,
      "y": 10,
      "z": -12,
      "name": "Rock_Shale_Cobble"
    },
    {
      "x": -19,
      "y": 11,
      "z": -12,
      "name": "Rock_Shale_Cobble"
    },
    {
      "x": -19,
      "y": 12,
      "z": -12,
      "name": "Rock_Shale_Cobble",
      "rotation": 3
    },
    {
      "x": -19,
      "y": 13,
      "z": -12,
      "name": "Rock_Shale_Brick",
      "rotation": 3
    },
    {
      "x": -19,
      "y": 14,
      "z": -12,
      "name": "Rock_Shale_Brick",
      "rotation": 3
    },
    {
      "x": -19,
      "y": 9,
      "z": -11,
      "name": "Soil_Dirt"
    },
    {
      "x": -19,
      "y": 10,
      "z": -11,
      "name": "Rock_Shale_Cobble"
    },
    {
      "x": -19,
      "y": 11,
      "z": -11,
      "name": "Rock_Shale_Cobble"
    },
    {
      "x": -19,
      "y": 12,
      "z": -11,
      "name": "Rock_Shale_Cobble",
      "rotation": 3
    },
    {
      "x": -19,
      "y": 13,
      "z": -11,
      "name": "Rock_Shale_Brick",
      "rotation": 3
    },
    {
      "x": -19,
      "y": 14,
      "z": -11,
      "name": "Rock_Shale_Brick",
      "rotation": 3
    },
    {
      "x": -19,
      "y": 15,
      "z": -11,
      "name": "Rock_Shale_Brick_Smooth",
      "rotation": 3
    },
    {
      "x": -19,
      "y": 9,
      "z": -10,
      "name": "Soil_Dirt"
    },
    {
      "x": -19,
      "y": 10,
      "z": -10,
      "name": "Rock_Shale_Cobble"
    },
    {
      "x": -19,
      "y": 11,
      "z": -10,
      "name": "Rock_Shale_Cobble"
    },
    {
      "x": -19,
      "y": 12,
      "z": -10,
      "name": "Rock_Shale_Cobble_Stairs"
    },
    {
      "x": -19,
      "y": 9,
      "z": -9,
      "name": "Soil_Dirt"
    },
    {
      "x": -19,
      "y": 10,
      "z": -9,
      "name": "Rock_Shale_Cobble"
    },
    {
      "x": -19,
      "y": 11,
      "z": -9,
      "name": "Rock_Shale_Cobble"
    },
    {
      "x": -19,
      "y": 12,
      "z": -9,
      "name": "Plant_Moss_Rug_Green_Dark",
      "support": 15
    },
    {
      "x": -19,
      "y": 9,
      "z": -8,
      "name": "Soil_Dirt"
    },
    {
      "x": -19,
      "y": 10,
      "z": -8,
      "name": "Rock_Shale_Cobble"
    },
    {
      "x": -19,
      "y": 11,
      "z": -8,
      "name": "Rock_Shale_Cobble"
    },
    {
      "x": -19,
      "y": 9,
      "z": -7,
      "name": "Soil_Dirt"
    },
    {
      "x": -19,
      "y": 10,
      "z": -7,
      "name": "Rock_Shale_Cobble"
    },
    {
      "x": -19,
      "y": 11,
      "z": -7,
      "name": "Rock_Shale_Cobble"
    },
    {
      "x": -19,
      "y": 9,
      "z": -6,
      "name": "Soil_Dirt"
    },
    {
      "x": -19,
      "y": 10,
      "z": -6,
      "name": "Rock_Shale_Cobble"
    },
    {
      "x": -19,
      "y": 11,
      "z": -6,
      "name": "Rock_Shale_Cobble"
    },
    {
      "x": -19,
      "y": 9,
      "z": -5,
      "name": "Soil_Dirt"
    },
    {
      "x": -19,
      "y": 10,
      "z": -5,
      "name": "Rock_Shale_Cobble"
    },
    {
      "x": -19,
      "y": 11,
      "z": -5,
      "name": "Rock_Shale_Cobble"
    },
    {
      "x": -19,
      "y": 9,
      "z": -4,
      "name": "Soil_Dirt"
    },
    {
      "x": -19,
      "y": 10,
      "z": -4,
      "name": "Rock_Shale_Cobble"
    },
    {
      "x": -19,
      "y": 11,
      "z": -4,
      "name": "Rock_Shale_Cobble"
    },
    {
      "x": -19,
      "y": 9,
      "z": -3,
      "name": "Soil_Dirt"
    },
    {
      "x": -19,
      "y": 10,
      "z": -3,
      "name": "Rock_Shale_Cobble"
    },
    {
      "x": -19,
      "y": 11,
      "z": -3,
      "name": "Rock_Shale_Cobble"
    },
    {
      "x": -19,
      "y": 9,
      "z": -2,
      "name": "Soil_Dirt"
    },
    {
      "x": -19,
      "y": 10,
      "z": -2,
      "name": "Rock_Shale_Cobble"
    },
    {
      "x": -19,
      "y": 11,
      "z": -2,
      "name": "Rock_Shale_Cobble"
    },
    {
      "x": -19,
      "y": 9,
      "z": -1,
      "name": "Soil_Dirt"
    },
    {
      "x": -19,
      "y": 10,
      "z": -1,
      "name": "Rock_Shale_Cobble"
    },
    {
      "x": -19,
      "y": 11,
      "z": -1,
      "name": "Rock_Shale_Cobble"
    },
    {
      "x": -19,
      "y": 9,
      "z": 0,
      "name": "Soil_Dirt"
    },
    {
      "x": -19,
      "y": 10,
      "z": 0,
      "name": "Rock_Shale_Cobble"
    },
    {
      "x": -19,
      "y": 11,
      "z": 0,
      "name": "Rock_Shale_Cobble"
    },
    {
      "x": -19,
      "y": 9,
      "z": 1,
      "name": "Soil_Dirt"
    },
    {
      "x": -19,
      "y": 10,
      "z": 1,
      "name": "Rock_Shale_Cobble"
    },
    {
      "x": -19,
      "y": 11,
      "z": 1,
      "name": "Rock_Shale_Cobble"
    },
    {
      "x": -19,
      "y": 9,
      "z": 2,
      "name": "Soil_Dirt"
    },
    {
      "x": -19,
      "y": 10,
      "z": 2,
      "name": "Rock_Shale_Cobble"
    },
    {
      "x": -19,
      "y": 11,
      "z": 2,
      "name": "Rock_Shale_Cobble"
    },
    {
      "x": -19,
      "y": 9,
      "z": 3,
      "name": "Soil_Dirt"
    },
    {
      "x": -19,
      "y": 10,
      "z": 3,
      "name": "Rock_Shale_Cobble"
    },
    {
      "x": -19,
      "y": 11,
      "z": 3,
      "name": "Rock_Shale_Cobble"
    },
    {
      "x": -19,
      "y": 9,
      "z": 4,
      "name": "Soil_Dirt"
    },
    {
      "x": -19,
      "y": 10,
      "z": 4,
      "name": "Rock_Shale_Cobble"
    },
    {
      "x": -19,
      "y": 11,
      "z": 4,
      "name": "Rock_Shale_Cobble"
    },
    {
      "x": -19,
      "y": 9,
      "z": 5,
      "name": "Soil_Dirt"
    },
    {
      "x": -19,
      "y": 10,
      "z": 5,
      "name": "Rock_Shale_Cobble"
    },
    {
      "x": -19,
      "y": 11,
      "z": 5,
      "name": "Rock_Shale_Cobble"
    },
    {
      "x": -19,
      "y": 9,
      "z": 6,
      "name": "Soil_Dirt"
    },
    {
      "x": -19,
      "y": 10,
      "z": 6,
      "name": "Rock_Shale_Cobble"
    },
    {
      "x": -19,
      "y": 11,
      "z": 6,
      "name": "Rock_Shale_Cobble"
    },
    {
      "x": -19,
      "y": 12,
      "z": 6,
      "name": "Plant_Moss_Rug_Green_Dark",
      "support": 15
    },
    {
      "x": -19,
      "y": 9,
      "z": 7,
      "name": "Soil_Dirt"
    },
    {
      "x": -19,
      "y": 10,
      "z": 7,
      "name": "Rock_Shale_Cobble"
    },
    {
      "x": -19,
      "y": 11,
      "z": 7,
      "name": "Rock_Shale_Cobble"
    },
    {
      "x": -19,
      "y": 12,
      "z": 7,
      "name": "Plant_Moss_Rug_Green_Dark",
      "support": 15
    },
    {
      "x": -19,
      "y": 9,
      "z": 8,
      "name": "Soil_Dirt"
    },
    {
      "x": -19,
      "y": 10,
      "z": 8,
      "name": "Rock_Shale_Cobble"
    },
    {
      "x": -19,
      "y": 11,
      "z": 8,
      "name": "Rock_Shale_Cobble"
    },
    {
      "x": -19,
      "y": 9,
      "z": 9,
      "name": "Soil_Dirt"
    },
    {
      "x": -19,
      "y": 10,
      "z": 9,
      "name": "Rock_Shale_Cobble"
    },
    {
      "x": -19,
      "y": 11,
      "z": 9,
      "name": "Rock_Shale_Cobble"
    },
    {
      "x": -19,
      "y": 9,
      "z": 10,
      "name": "Soil_Dirt"
    },
    {
      "x": -19,
      "y": 10,
      "z": 10,
      "name": "Rock_Shale_Cobble"
    },
    {
      "x": -19,
      "y": 11,
      "z": 10,
      "name": "Rock_Shale_Cobble"
    },
    {
      "x": -19,
      "y": 12,
      "z": 10,
      "name": "Rock_Shale_Cobble_Stairs",
      "rotation": 2
    },
    {
      "x": -19,
      "y": 9,
      "z": 11,
      "name": "Soil_Dirt"
    },
    {
      "x": -19,
      "y": 10,
      "z": 11,
      "name": "Rock_Shale_Cobble"
    },
    {
      "x": -19,
      "y": 11,
      "z": 11,
      "name": "Rock_Shale_Cobble"
    },
    {
      "x": -19,
      "y": 12,
      "z": 11,
      "name": "Rock_Shale_Cobble"
    },
    {
      "x": -19,
      "y": 13,
      "z": 11,
      "name": "Rock_Shale_Brick"
    },
    {
      "x": -19,
      "y": 14,
      "z": 11,
      "name": "Rock_Shale_Brick"
    },
    {
      "x": -19,
      "y": 15,
      "z": 11,
      "name": "Rock_Shale_Brick_Smooth"
    },
    {
      "x": -19,
      "y": 9,
      "z": 12,
      "name": "Soil_Dirt"
    },
    {
      "x": -19,
      "y": 10,
      "z": 12,
      "name": "Rock_Shale_Cobble"
    },
    {
      "x": -19,
      "y": 11,
      "z": 12,
      "name": "Rock_Shale_Cobble"
    },
    {
      "x": -19,
      "y": 12,
      "z": 12,
      "name": "Rock_Shale_Cobble"
    },
    {
      "x": -19,
      "y": 13,
      "z": 12,
      "name": "Rock_Shale_Brick"
    },
    {
      "x": -19,
      "y": 14,
      "z": 12,
      "name": "Rock_Shale_Brick"
    },
    {
      "x": -19,
      "y": 15,
      "z": 12,
      "name": "Plant_Moss_Rug_Green_Dark",
      "support": 15
    },
    {
      "x": -19,
      "y": 9,
      "z": 13,
      "name": "Soil_Dirt"
    },
    {
      "x": -19,
      "y": 10,
      "z": 13,
      "name": "Rock_Shale_Cobble"
    },
    {
      "x": -19,
      "y": 11,
      "z": 13,
      "name": "Rock_Shale_Cobble"
    },
    {
      "x": -19,
      "y": 12,
      "z": 13,
      "name": "Rock_Shale_Cobble"
    },
    {
      "x": -19,
      "y": 13,
      "z": 13,
      "name": "Rock_Shale_Brick"
    },
    {
      "x": -19,
      "y": 14,
      "z": 13,
      "name": "Rock_Shale_Brick"
    },
    {
      "x": -19,
      "y": 15,
      "z": 13,
      "name": "Rock_Shale_Brick_Smooth"
    },
    {
      "x": -19,
      "y": 9,
      "z": 14,
      "name": "Soil_Dirt"
    },
    {
      "x": -19,
      "y": 10,
      "z": 14,
      "name": "Rock_Shale_Cobble"
    },
    {
      "x": -19,
      "y": 11,
      "z": 14,
      "name": "Rock_Shale_Cobble"
    },
    {
      "x": -19,
      "y": 12,
      "z": 14,
      "name": "Rock_Shale_Cobble"
    },
    {
      "x": -19,
      "y": 13,
      "z": 14,
      "name": "Rock_Shale_Brick"
    },
    {
      "x": -19,
      "y": 14,
      "z": 14,
      "name": "Rock_Shale_Brick"
    },
    {
      "x": -19,
      "y": 9,
      "z": 15,
      "name": "Soil_Dirt"
    },
    {
      "x": -19,
      "y": 10,
      "z": 15,
      "name": "Rock_Shale_Cobble"
    },
    {
      "x": -19,
      "y": 11,
      "z": 15,
      "name": "Rock_Shale_Cobble"
    },
    {
      "x": -19,
      "y": 12,
      "z": 15,
      "name": "Rock_Shale_Cobble"
    },
    {
      "x": -19,
      "y": 13,
      "z": 15,
      "name": "Rock_Shale_Brick"
    },
    {
      "x": -19,
      "y": 14,
      "z": 15,
      "name": "Rock_Shale_Brick"
    },
    {
      "x": -19,
      "y": 15,
      "z": 15,
      "name": "Rock_Shale_Brick_Smooth"
    },
    {
      "x": -19,
      "y": 9,
      "z": 16,
      "name": "Soil_Dirt"
    },
    {
      "x": -19,
      "y": 10,
      "z": 16,
      "name": "Rock_Shale_Cobble"
    },
    {
      "x": -19,
      "y": 11,
      "z": 16,
      "name": "Rock_Shale_Cobble"
    },
    {
      "x": -19,
      "y": 12,
      "z": 16,
      "name": "Rock_Shale_Cobble"
    },
    {
      "x": -19,
      "y": 13,
      "z": 16,
      "name": "Rock_Shale_Brick"
    },
    {
      "x": -19,
      "y": 14,
      "z": 16,
      "name": "Rock_Shale_Brick"
    },
    {
      "x": -19,
      "y": 9,
      "z": 17,
      "name": "Soil_Dirt"
    },
    {
      "x": -19,
      "y": 10,
      "z": 17,
      "name": "Rock_Shale_Cobble"
    },
    {
      "x": -19,
      "y": 11,
      "z": 17,
      "name": "Rock_Shale_Cobble"
    },
    {
      "x": -19,
      "y": 12,
      "z": 17,
      "name": "Rock_Shale_Cobble"
    },
    {
      "x": -19,
      "y": 13,
      "z": 17,
      "name": "Rock_Shale_Brick"
    },
    {
      "x": -19,
      "y": 14,
      "z": 17,
      "name": "Rock_Shale_Brick"
    },
    {
      "x": -19,
      "y": 15,
      "z": 17,
      "name": "Rock_Shale_Brick_Smooth"
    },
    {
      "x": -19,
      "y": 9,
      "z": 18,
      "name": "Soil_Dirt"
    },
    {
      "x": -19,
      "y": 10,
      "z": 18,
      "name": "Rock_Shale_Cobble"
    },
    {
      "x": -19,
      "y": 11,
      "z": 18,
      "name": "Rock_Shale_Cobble"
    },
    {
      "x": -19,
      "y": 12,
      "z": 18,
      "name": "Rock_Shale_Cobble"
    },
    {
      "x": -19,
      "y": 13,
      "z": 18,
      "name": "Rock_Shale_Brick"
    },
    {
      "x": -19,
      "y": 14,
      "z": 18,
      "name": "Rock_Shale_Brick"
    },
    {
      "x": -19,
      "y": 9,
      "z": 19,
      "name": "Soil_Dirt"
    },
    {
      "x": -19,
      "y": 10,
      "z": 19,
      "name": "Rock_Shale_Cobble"
    },
    {
      "x": -19,
      "y": 11,
      "z": 19,
      "name": "Rock_Shale_Cobble"
    },
    {
      "x": -19,
      "y": 12,
      "z": 19,
      "name": "Rock_Shale_Cobble"
    },
    {
      "x": -19,
      "y": 13,
      "z": 19,
      "name": "Rock_Shale_Brick"
    },
    {
      "x": -19,
      "y": 14,
      "z": 19,
      "name": "Rock_Shale_Brick"
    },
    {
      "x": -19,
      "y": 15,
      "z": 19,
      "name": "Rock_Shale_Brick_Smooth"
    },
    {
      "x": -19,
      "y": 9,
      "z": 20,
      "name": "Soil_Dirt"
    },
    {
      "x": -19,
      "y": 10,
      "z": 20,
      "name": "Rock_Shale_Cobble"
    },
    {
      "x": -19,
      "y": 11,
      "z": 20,
      "name": "Rock_Shale_Cobble"
    },
    {
      "x": -19,
      "y": 12,
      "z": 20,
      "name": "Rock_Shale_Cobble_Stairs"
    },
    {
      "x": -19,
      "y": 9,
      "z": 21,
      "name": "Soil_Dirt"
    },
    {
      "x": -19,
      "y": 10,
      "z": 21,
      "name": "Rock_Shale_Cobble"
    },
    {
      "x": -19,
      "y": 11,
      "z": 21,
      "name": "Rock_Shale_Cobble_Stairs"
    },
    {
      "x": -19,
      "y": 9,
      "z": 22,
      "name": "Soil_Grass"
    },
    {
      "x": -18,
      "y": 9,
      "z": -22,
      "name": "Soil_Grass"
    },
    {
      "x": -18,
      "y": 9,
      "z": -21,
      "name": "Soil_Dirt"
    },
    {
      "x": -18,
      "y": 10,
      "z": -21,
      "name": "Rock_Shale_Cobble"
    },
    {
      "x": -18,
      "y": 11,
      "z": -21,
      "name": "Rock_Shale_Cobble_Stairs",
      "rotation": 2
    },
    {
      "x": -18,
      "y": 9,
      "z": -20,
      "name": "Soil_Dirt"
    },
    {
      "x": -18,
      "y": 10,
      "z": -20,
      "name": "Rock_Shale_Cobble"
    },
    {
      "x": -18,
      "y": 11,
      "z": -20,
      "name": "Rock_Shale_Cobble"
    },
    {
      "x": -18,
      "y": 12,
      "z": -20,
      "name": "Rock_Shale_Cobble_Stairs",
      "rotation": 2
    },
    {
      "x": -18,
      "y": 9,
      "z": -19,
      "name": "Soil_Dirt"
    },
    {
      "x": -18,
      "y": 10,
      "z": -19,
      "name": "Rock_Shale_Cobble"
    },
    {
      "x": -18,
      "y": 11,
      "z": -19,
      "name": "Rock_Shale_Cobble"
    },
    {
      "x": -18,
      "y": 12,
      "z": -19,
      "name": "Rock_Shale_Cobble",
      "rotation": 3
    },
    {
      "x": -18,
      "y": 13,
      "z": -19,
      "name": "Rock_Shale_Brick",
      "rotation": 3
    },
    {
      "x": -18,
      "y": 14,
      "z": -19,
      "name": "Rock_Shale_Brick",
      "rotation": 3
    },
    {
      "x": -18,
      "y": 9,
      "z": -18,
      "name": "Soil_Dirt"
    },
    {
      "x": -18,
      "y": 10,
      "z": -18,
      "name": "Rock_Shale_Cobble"
    },
    {
      "x": -18,
      "y": 11,
      "z": -18,
      "name": "Rock_Shale_Cobble"
    },
    {
      "x": -18,
      "y": 12,
      "z": -18,
      "name": "Rock_Shale_Cobble",
      "rotation": 3
    },
    {
      "x": -18,
      "y": 9,
      "z": -17,
      "name": "Soil_Dirt"
    },
    {
      "x": -18,
      "y": 10,
      "z": -17,
      "name": "Rock_Shale_Cobble"
    },
    {
      "x": -18,
      "y": 11,
      "z": -17,
      "name": "Rock_Shale_Cobble"
    },
    {
      "x": -18,
      "y": 12,
      "z": -17,
      "name": "Rock_Shale_Cobble",
      "rotation": 3
    },
    {
      "x": -18,
      "y": 9,
      "z": -16,
      "name": "Soil_Dirt"
    },
    {
      "x": -18,
      "y": 10,
      "z": -16,
      "name": "Rock_Shale_Cobble"
    },
    {
      "x": -18,
      "y": 11,
      "z": -16,
      "name": "Rock_Shale_Cobble"
    },
    {
      "x": -18,
      "y": 12,
      "z": -16,
      "name": "Rock_Shale_Cobble",
      "rotation": 3
    },
    {
      "x": -18,
      "y": 9,
      "z": -15,
      "name": "Soil_Dirt"
    },
    {
      "x": -18,
      "y": 10,
      "z": -15,
      "name": "Rock_Shale_Cobble"
    },
    {
      "x": -18,
      "y": 11,
      "z": -15,
      "name": "Rock_Shale_Cobble"
    },
    {
      "x": -18,
      "y": 12,
      "z": -15,
      "name": "Rock_Shale_Cobble",
      "rotation": 3
    },
    {
      "x": -18,
      "y": 9,
      "z": -14,
      "name": "Soil_Dirt"
    },
    {
      "x": -18,
      "y": 10,
      "z": -14,
      "name": "Rock_Shale_Cobble"
    },
    {
      "x": -18,
      "y": 11,
      "z": -14,
      "name": "Rock_Shale_Cobble"
    },
    {
      "x": -18,
      "y": 12,
      "z": -14,
      "name": "Rock_Shale_Cobble",
      "rotation": 3
    },
    {
      "x": -18,
      "y": 9,
      "z": -13,
      "name": "Soil_Dirt"
    },
    {
      "x": -18,
      "y": 10,
      "z": -13,
      "name": "Rock_Shale_Cobble"
    },
    {
      "x": -18,
      "y": 11,
      "z": -13,
      "name": "Rock_Shale_Cobble"
    },
    {
      "x": -18,
      "y": 12,
      "z": -13,
      "name": "Rock_Shale_Cobble",
      "rotation": 3
    },
    {
      "x": -18,
      "y": 9,
      "z": -12,
      "name": "Soil_Dirt"
    },
    {
      "x": -18,
      "y": 10,
      "z": -12,
      "name": "Rock_Shale_Cobble"
    },
    {
      "x": -18,
      "y": 11,
      "z": -12,
      "name": "Rock_Shale_Cobble"
    },
    {
      "x": -18,
      "y": 12,
      "z": -12,
      "name": "Rock_Shale_Cobble",
      "rotation": 3
    },
    {
      "x": -18,
      "y": 9,
      "z": -11,
      "name": "Soil_Dirt"
    },
    {
      "x": -18,
      "y": 10,
      "z": -11,
      "name": "Rock_Shale_Cobble"
    },
    {
      "x": -18,
      "y": 11,
      "z": -11,
      "name": "Rock_Shale_Cobble"
    },
    {
      "x": -18,
      "y": 12,
      "z": -11,
      "name": "Rock_Shale_Cobble",
      "rotation": 3
    },
    {
      "x": -18,
      "y": 13,
      "z": -11,
      "name": "Rock_Shale_Brick",
      "rotation": 3
    },
    {
      "x": -18,
      "y": 14,
      "z": -11,
      "name": "Rock_Shale_Brick",
      "rotation": 3
    },
    {
      "x": -18,
      "y": 9,
      "z": -10,
      "name": "Soil_Dirt"
    },
    {
      "x": -18,
      "y": 10,
      "z": -10,
      "name": "Rock_Shale_Cobble"
    },
    {
      "x": -18,
      "y": 11,
      "z": -10,
      "name": "Rock_Shale_Cobble"
    },
    {
      "x": -18,
      "y": 12,
      "z": -10,
      "name": "Rock_Shale_Cobble_Stairs"
    },
    {
      "x": -18,
      "y": 9,
      "z": -9,
      "name": "Soil_Dirt"
    },
    {
      "x": -18,
      "y": 10,
      "z": -9,
      "name": "Rock_Shale_Cobble"
    },
    {
      "x": -18,
      "y": 11,
      "z": -9,
      "name": "Rock_Shale_Cobble"
    },
    {
      "x": -18,
      "y": 9,
      "z": -8,
      "name": "Soil_Dirt"
    },
    {
      "x": -18,
      "y": 10,
      "z": -8,
      "name": "Rock_Shale_Cobble"
    },
    {
      "x": -18,
      "y": 11,
      "z": -8,
      "name": "Rock_Shale_Cobble"
    },
    {
      "x": -18,
      "y": 9,
      "z": -7,
      "name": "Soil_Dirt"
    },
    {
      "x": -18,
      "y": 10,
      "z": -7,
      "name": "Rock_Shale_Cobble"
    },
    {
      "x": -18,
      "y": 11,
      "z": -7,
      "name": "Rock_Shale_Cobble"
    },
    {
      "x": -18,
      "y": 9,
      "z": -6,
      "name": "Soil_Dirt"
    },
    {
      "x": -18,
      "y": 10,
      "z": -6,
      "name": "Rock_Shale_Cobble"
    },
    {
      "x": -18,
      "y": 11,
      "z": -6,
      "name": "Rock_Shale_Cobble"
    },
    {
      "x": -18,
      "y": 9,
      "z": -5,
      "name": "Soil_Dirt"
    },
    {
      "x": -18,
      "y": 10,
      "z": -5,
      "name": "Rock_Shale_Cobble"
    },
    {
      "x": -18,
      "y": 11,
      "z": -5,
      "name": "Rock_Shale_Cobble"
    },
    {
      "x": -18,
      "y": 9,
      "z": -4,
      "name": "Soil_Dirt"
    },
    {
      "x": -18,
      "y": 10,
      "z": -4,
      "name": "Rock_Shale_Cobble"
    },
    {
      "x": -18,
      "y": 11,
      "z": -4,
      "name": "Rock_Shale_Cobble"
    },
    {
      "x": -18,
      "y": 9,
      "z": -3,
      "name": "Soil_Dirt"
    },
    {
      "x": -18,
      "y": 10,
      "z": -3,
      "name": "Rock_Shale_Cobble"
    },
    {
      "x": -18,
      "y": 11,
      "z": -3,
      "name": "Rock_Shale_Cobble"
    },
    {
      "x": -18,
      "y": 9,
      "z": -2,
      "name": "Soil_Dirt"
    },
    {
      "x": -18,
      "y": 10,
      "z": -2,
      "name": "Rock_Shale_Cobble"
    },
    {
      "x": -18,
      "y": 11,
      "z": -2,
      "name": "Rock_Shale_Cobble"
    },
    {
      "x": -18,
      "y": 9,
      "z": -1,
      "name": "Soil_Dirt"
    },
    {
      "x": -18,
      "y": 10,
      "z": -1,
      "name": "Rock_Shale_Cobble"
    },
    {
      "x": -18,
      "y": 11,
      "z": -1,
      "name": "Rock_Shale_Cobble"
    },
    {
      "x": -18,
      "y": 9,
      "z": 0,
      "name": "Soil_Dirt"
    },
    {
      "x": -18,
      "y": 10,
      "z": 0,
      "name": "Rock_Shale_Cobble"
    },
    {
      "x": -18,
      "y": 11,
      "z": 0,
      "name": "Rock_Shale_Cobble"
    },
    {
      "x": -18,
      "y": 9,
      "z": 1,
      "name": "Soil_Dirt"
    },
    {
      "x": -18,
      "y": 10,
      "z": 1,
      "name": "Rock_Shale_Cobble"
    },
    {
      "x": -18,
      "y": 11,
      "z": 1,
      "name": "Rock_Shale_Cobble"
    },
    {
      "x": -18,
      "y": 9,
      "z": 2,
      "name": "Soil_Dirt"
    },
    {
      "x": -18,
      "y": 10,
      "z": 2,
      "name": "Rock_Shale_Cobble"
    },
    {
      "x": -18,
      "y": 11,
      "z": 2,
      "name": "Rock_Shale_Cobble"
    },
    {
      "x": -18,
      "y": 9,
      "z": 3,
      "name": "Soil_Dirt"
    },
    {
      "x": -18,
      "y": 10,
      "z": 3,
      "name": "Rock_Shale_Cobble"
    },
    {
      "x": -18,
      "y": 11,
      "z": 3,
      "name": "Rock_Shale_Cobble"
    },
    {
      "x": -18,
      "y": 9,
      "z": 4,
      "name": "Soil_Dirt"
    },
    {
      "x": -18,
      "y": 10,
      "z": 4,
      "name": "Rock_Shale_Cobble"
    },
    {
      "x": -18,
      "y": 11,
      "z": 4,
      "name": "Rock_Shale_Cobble"
    },
    {
      "x": -18,
      "y": 9,
      "z": 5,
      "name": "Soil_Dirt"
    },
    {
      "x": -18,
      "y": 10,
      "z": 5,
      "name": "Rock_Shale_Cobble"
    },
    {
      "x": -18,
      "y": 11,
      "z": 5,
      "name": "Rock_Shale_Cobble"
    },
    {
      "x": -18,
      "y": 12,
      "z": 5,
      "name": "Plant_Moss_Rug_Green_Dark",
      "support": 15
    },
    {
      "x": -18,
      "y": 9,
      "z": 6,
      "name": "Soil_Dirt"
    },
    {
      "x": -18,
      "y": 10,
      "z": 6,
      "name": "Rock_Shale_Cobble"
    },
    {
      "x": -18,
      "y": 11,
      "z": 6,
      "name": "Rock_Shale_Cobble"
    },
    {
      "x": -18,
      "y": 9,
      "z": 7,
      "name": "Soil_Dirt"
    },
    {
      "x": -18,
      "y": 10,
      "z": 7,
      "name": "Rock_Shale_Cobble"
    },
    {
      "x": -18,
      "y": 11,
      "z": 7,
      "name": "Rock_Shale_Cobble"
    },
    {
      "x": -18,
      "y": 9,
      "z": 8,
      "name": "Soil_Dirt"
    },
    {
      "x": -18,
      "y": 10,
      "z": 8,
      "name": "Rock_Shale_Cobble"
    },
    {
      "x": -18,
      "y": 11,
      "z": 8,
      "name": "Rock_Shale_Cobble"
    },
    {
      "x": -18,
      "y": 9,
      "z": 9,
      "name": "Soil_Dirt"
    },
    {
      "x": -18,
      "y": 10,
      "z": 9,
      "name": "Rock_Shale_Cobble"
    },
    {
      "x": -18,
      "y": 11,
      "z": 9,
      "name": "Rock_Shale_Cobble"
    },
    {
      "x": -18,
      "y": 9,
      "z": 10,
      "name": "Soil_Dirt"
    },
    {
      "x": -18,
      "y": 10,
      "z": 10,
      "name": "Rock_Shale_Cobble"
    },
    {
      "x": -18,
      "y": 11,
      "z": 10,
      "name": "Rock_Shale_Cobble"
    },
    {
      "x": -18,
      "y": 12,
      "z": 10,
      "name": "Rock_Shale_Cobble_Stairs",
      "rotation": 2
    },
    {
      "x": -18,
      "y": 9,
      "z": 11,
      "name": "Soil_Dirt"
    },
    {
      "x": -18,
      "y": 10,
      "z": 11,
      "name": "Rock_Shale_Cobble"
    },
    {
      "x": -18,
      "y": 11,
      "z": 11,
      "name": "Rock_Shale_Cobble"
    },
    {
      "x": -18,
      "y": 12,
      "z": 11,
      "name": "Rock_Shale_Cobble"
    },
    {
      "x": -18,
      "y": 13,
      "z": 11,
      "name": "Rock_Shale_Brick"
    },
    {
      "x": -18,
      "y": 14,
      "z": 11,
      "name": "Rock_Shale_Brick"
    },
    {
      "x": -18,
      "y": 9,
      "z": 12,
      "name": "Soil_Dirt"
    },
    {
      "x": -18,
      "y": 10,
      "z": 12,
      "name": "Rock_Shale_Cobble"
    },
    {
      "x": -18,
      "y": 11,
      "z": 12,
      "name": "Rock_Shale_Cobble"
    },
    {
      "x": -18,
      "y": 12,
      "z": 12,
      "name": "Rock_Shale_Cobble"
    },
    {
      "x": -18,
      "y": 9,
      "z": 13,
      "name": "Soil_Dirt"
    },
    {
      "x": -18,
      "y": 10,
      "z": 13,
      "name": "Rock_Shale_Cobble"
    },
    {
      "x": -18,
      "y": 11,
      "z": 13,
      "name": "Rock_Shale_Cobble"
    },
    {
      "x": -18,
      "y": 12,
      "z": 13,
      "name": "Rock_Shale_Cobble"
    },
    {
      "x": -18,
      "y": 13,
      "z": 13,
      "name": "Plant_Moss_Rug_Green_Dark",
      "support": 15
    },
    {
      "x": -18,
      "y": 9,
      "z": 14,
      "name": "Soil_Dirt"
    },
    {
      "x": -18,
      "y": 10,
      "z": 14,
      "name": "Rock_Shale_Cobble"
    },
    {
      "x": -18,
      "y": 11,
      "z": 14,
      "name": "Rock_Shale_Cobble"
    },
    {
      "x": -18,
      "y": 12,
      "z": 14,
      "name": "Rock_Shale_Cobble"
    },
    {
      "x": -18,
      "y": 13,
      "z": 14,
      "name": "Plant_Moss_Rug_Green_Dark",
      "support": 15
    },
    {
      "x": -18,
      "y": 9,
      "z": 15,
      "name": "Soil_Dirt"
    },
    {
      "x": -18,
      "y": 10,
      "z": 15,
      "name": "Rock_Shale_Cobble"
    },
    {
      "x": -18,
      "y": 11,
      "z": 15,
      "name": "Rock_Shale_Cobble"
    },
    {
      "x": -18,
      "y": 12,
      "z": 15,
      "name": "Rock_Shale_Cobble"
    },
    {
      "x": -18,
      "y": 9,
      "z": 16,
      "name": "Soil_Dirt"
    },
    {
      "x": -18,
      "y": 10,
      "z": 16,
      "name": "Rock_Shale_Cobble"
    },
    {
      "x": -18,
      "y": 11,
      "z": 16,
      "name": "Rock_Shale_Cobble"
    },
    {
      "x": -18,
      "y": 12,
      "z": 16,
      "name": "Rock_Shale_Cobble"
    },
    {
      "x": -18,
      "y": 9,
      "z": 17,
      "name": "Soil_Dirt"
    },
    {
      "x": -18,
      "y": 10,
      "z": 17,
      "name": "Rock_Shale_Cobble"
    },
    {
      "x": -18,
      "y": 11,
      "z": 17,
      "name": "Rock_Shale_Cobble"
    },
    {
      "x": -18,
      "y": 12,
      "z": 17,
      "name": "Rock_Shale_Cobble"
    },
    {
      "x": -18,
      "y": 9,
      "z": 18,
      "name": "Soil_Dirt"
    },
    {
      "x": -18,
      "y": 10,
      "z": 18,
      "name": "Rock_Shale_Cobble"
    },
    {
      "x": -18,
      "y": 11,
      "z": 18,
      "name": "Rock_Shale_Cobble"
    },
    {
      "x": -18,
      "y": 12,
      "z": 18,
      "name": "Rock_Shale_Cobble"
    },
    {
      "x": -18,
      "y": 14,
      "z": 18,
      "name": "Plant_Moss_Wall_Green_Dark",
      "support": 15,
      "rotation": 2
    },
    {
      "x": -18,
      "y": 9,
      "z": 19,
      "name": "Soil_Dirt"
    },
    {
      "x": -18,
      "y": 10,
      "z": 19,
      "name": "Rock_Shale_Cobble"
    },
    {
      "x": -18,
      "y": 11,
      "z": 19,
      "name": "Rock_Shale_Cobble"
    },
    {
      "x": -18,
      "y": 12,
      "z": 19,
      "name": "Rock_Shale_Cobble"
    },
    {
      "x": -18,
      "y": 13,
      "z": 19,
      "name": "Rock_Shale_Brick"
    },
    {
      "x": -18,
      "y": 14,
      "z": 19,
      "name": "Rock_Shale_Brick"
    },
    {
      "x": -18,
      "y": 15,
      "z": 19,
      "name": "Plant_Moss_Rug_Green_Dark",
      "support": 15
    },
    {
      "x": -18,
      "y": 9,
      "z": 20,
      "name": "Soil_Dirt"
    },
    {
      "x": -18,
      "y": 10,
      "z": 20,
      "name": "Rock_Shale_Cobble"
    },
    {
      "x": -18,
      "y": 11,
      "z": 20,
      "name": "Rock_Shale_Cobble"
    },
    {
      "x": -18,
      "y": 12,
      "z": 20,
      "name": "Rock_Shale_Cobble_Stairs"
    },
    {
      "x": -18,
      "y": 9,
      "z": 21,
      "name": "Soil_Dirt"
    },
    {
      "x": -18,
      "y": 10,
      "z": 21,
      "name": "Rock_Shale_Cobble"
    },
    {
      "x": -18,
      "y": 11,
      "z": 21,
      "name": "Rock_Shale_Cobble_Stairs"
    },
    {
      "x": -18,
      "y": 9,
      "z": 22,
      "name": "Soil_Grass"
    },
    {
      "x": -17,
      "y": 9,
      "z": -22,
      "name": "Soil_Grass"
    },
    {
      "x": -17,
      "y": 9,
      "z": -21,
      "name": "Soil_Dirt"
    },
    {
      "x": -17,
      "y": 10,
      "z": -21,
      "name": "Rock_Shale_Cobble"
    },
    {
      "x": -17,
      "y": 11,
      "z": -21,
      "name": "Rock_Shale_Cobble_Stairs",
      "rotation": 2
    },
    {
      "x": -17,
      "y": 9,
      "z": -20,
      "name": "Soil_Dirt"
    },
    {
      "x": -17,
      "y": 10,
      "z": -20,
      "name": "Rock_Shale_Cobble"
    },
    {
      "x": -17,
      "y": 11,
      "z": -20,
      "name": "Rock_Shale_Cobble"
    },
    {
      "x": -17,
      "y": 12,
      "z": -20,
      "name": "Rock_Shale_Cobble_Stairs",
      "rotation": 2
    },
    {
      "x": -17,
      "y": 9,
      "z": -19,
      "name": "Soil_Dirt"
    },
    {
      "x": -17,
      "y": 10,
      "z": -19,
      "name": "Rock_Shale_Cobble"
    },
    {
      "x": -17,
      "y": 11,
      "z": -19,
      "name": "Rock_Shale_Cobble"
    },
    {
      "x": -17,
      "y": 12,
      "z": -19,
      "name": "Rock_Shale_Cobble",
      "rotation": 3
    },
    {
      "x": -17,
      "y": 13,
      "z": -19,
      "name": "Rock_Shale_Brick",
      "rotation": 3
    },
    {
      "x": -17,
      "y": 14,
      "z": -19,
      "name": "Rock_Shale_Brick",
      "rotation": 3
    },
    {
      "x": -17,
      "y": 15,
      "z": -19,
      "name": "Rock_Shale_Brick_Smooth",
      "rotation": 3
    },
    {
      "x": -17,
      "y": 9,
      "z": -18,
      "name": "Soil_Dirt"
    },
    {
      "x": -17,
      "y": 10,
      "z": -18,
      "name": "Rock_Shale_Cobble"
    },
    {
      "x": -17,
      "y": 11,
      "z": -18,
      "name": "Rock_Shale_Cobble"
    },
    {
      "x": -17,
      "y": 12,
      "z": -18,
      "name": "Rock_Shale_Cobble",
      "rotation": 3
    },
    {
      "x": -17,
      "y": 9,
      "z": -17,
      "name": "Soil_Dirt"
    },
    {
      "x": -17,
      "y": 10,
      "z": -17,
      "name": "Rock_Shale_Cobble"
    },
    {
      "x": -17,
      "y": 11,
      "z": -17,
      "name": "Rock_Shale_Cobble"
    },
    {
      "x": -17,
      "y": 12,
      "z": -17,
      "name": "Rock_Shale_Cobble",
      "rotation": 3
    },
    {
      "x": -17,
      "y": 13,
      "z": -17,
      "name": "Plant_Moss_Rug_Green_Dark",
      "support": 15
    },
    {
      "x": -17,
      "y": 9,
      "z": -16,
      "name": "Soil_Dirt"
    },
    {
      "x": -17,
      "y": 10,
      "z": -16,
      "name": "Rock_Shale_Cobble"
    },
    {
      "x": -17,
      "y": 11,
      "z": -16,
      "name": "Rock_Shale_Cobble"
    },
    {
      "x": -17,
      "y": 12,
      "z": -16,
      "name": "Rock_Shale_Cobble",
      "rotation": 3
    },
    {
      "x": -17,
      "y": 9,
      "z": -15,
      "name": "Soil_Dirt"
    },
    {
      "x": -17,
      "y": 10,
      "z": -15,
      "name": "Rock_Shale_Cobble"
    },
    {
      "x": -17,
      "y": 11,
      "z": -15,
      "name": "Rock_Shale_Cobble"
    },
    {
      "x": -17,
      "y": 12,
      "z": -15,
      "name": "Rock_Shale_Cobble",
      "rotation": 3
    },
    {
      "x": -17,
      "y": 9,
      "z": -14,
      "name": "Soil_Dirt"
    },
    {
      "x": -17,
      "y": 10,
      "z": -14,
      "name": "Rock_Shale_Cobble"
    },
    {
      "x": -17,
      "y": 11,
      "z": -14,
      "name": "Rock_Shale_Cobble"
    },
    {
      "x": -17,
      "y": 12,
      "z": -14,
      "name": "Rock_Shale_Cobble",
      "rotation": 3
    },
    {
      "x": -17,
      "y": 9,
      "z": -13,
      "name": "Soil_Dirt"
    },
    {
      "x": -17,
      "y": 10,
      "z": -13,
      "name": "Rock_Shale_Cobble"
    },
    {
      "x": -17,
      "y": 11,
      "z": -13,
      "name": "Rock_Shale_Cobble"
    },
    {
      "x": -17,
      "y": 12,
      "z": -13,
      "name": "Rock_Shale_Cobble",
      "rotation": 3
    },
    {
      "x": -17,
      "y": 9,
      "z": -12,
      "name": "Soil_Dirt"
    },
    {
      "x": -17,
      "y": 10,
      "z": -12,
      "name": "Rock_Shale_Cobble"
    },
    {
      "x": -17,
      "y": 11,
      "z": -12,
      "name": "Rock_Shale_Cobble"
    },
    {
      "x": -17,
      "y": 12,
      "z": -12,
      "name": "Rock_Shale_Cobble",
      "rotation": 3
    },
    {
      "x": -17,
      "y": 9,
      "z": -11,
      "name": "Soil_Dirt"
    },
    {
      "x": -17,
      "y": 10,
      "z": -11,
      "name": "Rock_Shale_Cobble"
    },
    {
      "x": -17,
      "y": 11,
      "z": -11,
      "name": "Rock_Shale_Cobble"
    },
    {
      "x": -17,
      "y": 12,
      "z": -11,
      "name": "Rock_Shale_Cobble",
      "rotation": 3
    },
    {
      "x": -17,
      "y": 13,
      "z": -11,
      "name": "Rock_Shale_Brick",
      "rotation": 3
    },
    {
      "x": -17,
      "y": 14,
      "z": -11,
      "name": "Rock_Shale_Brick",
      "rotation": 3
    },
    {
      "x": -17,
      "y": 15,
      "z": -11,
      "name": "Rock_Shale_Brick_Smooth",
      "rotation": 3
    },
    {
      "x": -17,
      "y": 9,
      "z": -10,
      "name": "Soil_Dirt"
    },
    {
      "x": -17,
      "y": 10,
      "z": -10,
      "name": "Rock_Shale_Cobble"
    },
    {
      "x": -17,
      "y": 11,
      "z": -10,
      "name": "Rock_Shale_Cobble"
    },
    {
      "x": -17,
      "y": 12,
      "z": -10,
      "name": "Rock_Shale_Cobble_Stairs"
    },
    {
      "x": -17,
      "y": 9,
      "z": -9,
      "name": "Soil_Dirt"
    },
    {
      "x": -17,
      "y": 10,
      "z": -9,
      "name": "Rock_Shale_Cobble"
    },
    {
      "x": -17,
      "y": 11,
      "z": -9,
      "name": "Rock_Shale_Cobble"
    },
    {
      "x": -17,
      "y": 9,
      "z": -8,
      "name": "Soil_Dirt"
    },
    {
      "x": -17,
      "y": 10,
      "z": -8,
      "name": "Rock_Shale_Cobble"
    },
    {
      "x": -17,
      "y": 11,
      "z": -8,
      "name": "Rock_Shale_Cobble"
    },
    {
      "x": -17,
      "y": 9,
      "z": -7,
      "name": "Soil_Dirt"
    },
    {
      "x": -17,
      "y": 10,
      "z": -7,
      "name": "Rock_Shale_Cobble"
    },
    {
      "x": -17,
      "y": 11,
      "z": -7,
      "name": "Rock_Shale_Cobble"
    },
    {
      "x": -17,
      "y": 12,
      "z": -7,
      "name": "Plant_Moss_Rug_Green_Dark",
      "support": 15
    },
    {
      "x": -17,
      "y": 9,
      "z": -6,
      "name": "Soil_Dirt"
    },
    {
      "x": -17,
      "y": 10,
      "z": -6,
      "name": "Rock_Shale_Cobble"
    },
    {
      "x": -17,
      "y": 11,
      "z": -6,
      "name": "Rock_Shale_Cobble"
    },
    {
      "x": -17,
      "y": 9,
      "z": -5,
      "name": "Soil_Dirt"
    },
    {
      "x": -17,
      "y": 10,
      "z": -5,
      "name": "Rock_Shale_Cobble"
    },
    {
      "x": -17,
      "y": 11,
      "z": -5,
      "name": "Rock_Shale_Cobble"
    },
    {
      "x": -17,
      "y": 9,
      "z": -4,
      "name": "Soil_Dirt"
    },
    {
      "x": -17,
      "y": 10,
      "z": -4,
      "name": "Rock_Shale_Cobble"
    },
    {
      "x": -17,
      "y": 11,
      "z": -4,
      "name": "Rock_Shale_Cobble"
    },
    {
      "x": -17,
      "y": 9,
      "z": -3,
      "name": "Soil_Dirt"
    },
    {
      "x": -17,
      "y": 10,
      "z": -3,
      "name": "Rock_Shale_Cobble"
    },
    {
      "x": -17,
      "y": 11,
      "z": -3,
      "name": "Rock_Shale_Cobble"
    },
    {
      "x": -17,
      "y": 9,
      "z": -2,
      "name": "Soil_Dirt"
    },
    {
      "x": -17,
      "y": 10,
      "z": -2,
      "name": "Rock_Shale_Cobble"
    },
    {
      "x": -17,
      "y": 11,
      "z": -2,
      "name": "Rock_Shale_Cobble"
    },
    {
      "x": -17,
      "y": 9,
      "z": -1,
      "name": "Soil_Dirt"
    },
    {
      "x": -17,
      "y": 10,
      "z": -1,
      "name": "Rock_Shale_Cobble"
    },
    {
      "x": -17,
      "y": 11,
      "z": -1,
      "name": "Rock_Shale_Cobble"
    },
    {
      "x": -17,
      "y": 9,
      "z": 0,
      "name": "Soil_Dirt"
    },
    {
      "x": -17,
      "y": 10,
      "z": 0,
      "name": "Rock_Shale_Cobble"
    },
    {
      "x": -17,
      "y": 11,
      "z": 0,
      "name": "Rock_Shale_Cobble"
    },
    {
      "x": -17,
      "y": 9,
      "z": 1,
      "name": "Soil_Dirt"
    },
    {
      "x": -17,
      "y": 10,
      "z": 1,
      "name": "Rock_Shale_Cobble"
    },
    {
      "x": -17,
      "y": 11,
      "z": 1,
      "name": "Rock_Shale_Cobble"
    },
    {
      "x": -17,
      "y": 9,
      "z": 2,
      "name": "Soil_Dirt"
    },
    {
      "x": -17,
      "y": 10,
      "z": 2,
      "name": "Rock_Shale_Cobble"
    },
    {
      "x": -17,
      "y": 11,
      "z": 2,
      "name": "Rock_Shale_Cobble"
    },
    {
      "x": -17,
      "y": 9,
      "z": 3,
      "name": "Soil_Dirt"
    },
    {
      "x": -17,
      "y": 10,
      "z": 3,
      "name": "Rock_Shale_Cobble"
    },
    {
      "x": -17,
      "y": 11,
      "z": 3,
      "name": "Rock_Shale_Cobble"
    },
    {
      "x": -17,
      "y": 9,
      "z": 4,
      "name": "Soil_Dirt"
    },
    {
      "x": -17,
      "y": 10,
      "z": 4,
      "name": "Rock_Shale_Cobble"
    },
    {
      "x": -17,
      "y": 11,
      "z": 4,
      "name": "Rock_Shale_Cobble"
    },
    {
      "x": -17,
      "y": 9,
      "z": 5,
      "name": "Soil_Dirt"
    },
    {
      "x": -17,
      "y": 10,
      "z": 5,
      "name": "Rock_Shale_Cobble"
    },
    {
      "x": -17,
      "y": 11,
      "z": 5,
      "name": "Rock_Shale_Cobble"
    },
    {
      "x": -17,
      "y": 9,
      "z": 6,
      "name": "Soil_Dirt"
    },
    {
      "x": -17,
      "y": 10,
      "z": 6,
      "name": "Rock_Shale_Cobble"
    },
    {
      "x": -17,
      "y": 11,
      "z": 6,
      "name": "Rock_Shale_Cobble"
    },
    {
      "x": -17,
      "y": 9,
      "z": 7,
      "name": "Soil_Dirt"
    },
    {
      "x": -17,
      "y": 10,
      "z": 7,
      "name": "Rock_Shale_Cobble"
    },
    {
      "x": -17,
      "y": 11,
      "z": 7,
      "name": "Rock_Shale_Cobble"
    },
    {
      "x": -17,
      "y": 9,
      "z": 8,
      "name": "Soil_Dirt"
    },
    {
      "x": -17,
      "y": 10,
      "z": 8,
      "name": "Rock_Shale_Cobble"
    },
    {
      "x": -17,
      "y": 11,
      "z": 8,
      "name": "Rock_Shale_Cobble"
    },
    {
      "x": -17,
      "y": 9,
      "z": 9,
      "name": "Soil_Dirt"
    },
    {
      "x": -17,
      "y": 10,
      "z": 9,
      "name": "Rock_Shale_Cobble"
    },
    {
      "x": -17,
      "y": 11,
      "z": 9,
      "name": "Rock_Shale_Cobble"
    },
    {
      "x": -17,
      "y": 9,
      "z": 10,
      "name": "Soil_Dirt"
    },
    {
      "x": -17,
      "y": 10,
      "z": 10,
      "name": "Rock_Shale_Cobble"
    },
    {
      "x": -17,
      "y": 11,
      "z": 10,
      "name": "Rock_Shale_Cobble"
    },
    {
      "x": -17,
      "y": 12,
      "z": 10,
      "name": "Rock_Shale_Cobble_Stairs",
      "rotation": 2
    },
    {
      "x": -17,
      "y": 9,
      "z": 11,
      "name": "Soil_Dirt"
    },
    {
      "x": -17,
      "y": 10,
      "z": 11,
      "name": "Rock_Shale_Cobble"
    },
    {
      "x": -17,
      "y": 11,
      "z": 11,
      "name": "Rock_Shale_Cobble"
    },
    {
      "x": -17,
      "y": 12,
      "z": 11,
      "name": "Rock_Shale_Cobble"
    },
    {
      "x": -17,
      "y": 13,
      "z": 11,
      "name": "Rock_Shale_Brick"
    },
    {
      "x": -17,
      "y": 14,
      "z": 11,
      "name": "Rock_Shale_Brick"
    },
    {
      "x": -17,
      "y": 15,
      "z": 11,
      "name": "Rock_Shale_Brick_Smooth"
    },
    {
      "x": -17,
      "y": 9,
      "z": 12,
      "name": "Soil_Dirt"
    },
    {
      "x": -17,
      "y": 10,
      "z": 12,
      "name": "Rock_Shale_Cobble"
    },
    {
      "x": -17,
      "y": 11,
      "z": 12,
      "name": "Rock_Shale_Cobble"
    },
    {
      "x": -17,
      "y": 12,
      "z": 12,
      "name": "Rock_Shale_Cobble"
    },
    {
      "x": -17,
      "y": 9,
      "z": 13,
      "name": "Soil_Dirt"
    },
    {
      "x": -17,
      "y": 10,
      "z": 13,
      "name": "Rock_Shale_Cobble"
    },
    {
      "x": -17,
      "y": 11,
      "z": 13,
      "name": "Rock_Shale_Cobble"
    },
    {
      "x": -17,
      "y": 12,
      "z": 13,
      "name": "Rock_Shale_Cobble"
    },
    {
      "x": -17,
      "y": 9,
      "z": 14,
      "name": "Soil_Dirt"
    },
    {
      "x": -17,
      "y": 10,
      "z": 14,
      "name": "Rock_Shale_Cobble"
    },
    {
      "x": -17,
      "y": 11,
      "z": 14,
      "name": "Rock_Shale_Cobble"
    },
    {
      "x": -17,
      "y": 12,
      "z": 14,
      "name": "Rock_Shale_Cobble"
    },
    {
      "x": -17,
      "y": 9,
      "z": 15,
      "name": "Soil_Dirt"
    },
    {
      "x": -17,
      "y": 10,
      "z": 15,
      "name": "Rock_Shale_Cobble"
    },
    {
      "x": -17,
      "y": 11,
      "z": 15,
      "name": "Rock_Shale_Cobble"
    },
    {
      "x": -17,
      "y": 12,
      "z": 15,
      "name": "Rock_Shale_Cobble"
    },
    {
      "x": -17,
      "y": 13,
      "z": 15,
      "name": "Plant_Moss_Rug_Green_Dark",
      "support": 15
    },
    {
      "x": -17,
      "y": 9,
      "z": 16,
      "name": "Soil_Dirt"
    },
    {
      "x": -17,
      "y": 10,
      "z": 16,
      "name": "Rock_Shale_Cobble"
    },
    {
      "x": -17,
      "y": 11,
      "z": 16,
      "name": "Rock_Shale_Cobble"
    },
    {
      "x": -17,
      "y": 12,
      "z": 16,
      "name": "Rock_Shale_Cobble"
    },
    {
      "x": -17,
      "y": 9,
      "z": 17,
      "name": "Soil_Dirt"
    },
    {
      "x": -17,
      "y": 10,
      "z": 17,
      "name": "Rock_Shale_Cobble"
    },
    {
      "x": -17,
      "y": 11,
      "z": 17,
      "name": "Rock_Shale_Cobble"
    },
    {
      "x": -17,
      "y": 12,
      "z": 17,
      "name": "Rock_Shale_Cobble"
    },
    {
      "x": -17,
      "y": 9,
      "z": 18,
      "name": "Soil_Dirt"
    },
    {
      "x": -17,
      "y": 10,
      "z": 18,
      "name": "Rock_Shale_Cobble"
    },
    {
      "x": -17,
      "y": 11,
      "z": 18,
      "name": "Rock_Shale_Cobble"
    },
    {
      "x": -17,
      "y": 12,
      "z": 18,
      "name": "Rock_Shale_Cobble"
    },
    {
      "x": -17,
      "y": 15,
      "z": 18,
      "name": "Plant_Moss_Wall_Green_Dark",
      "support": 15,
      "rotation": 2
    },
    {
      "x": -17,
      "y": 9,
      "z": 19,
      "name": "Soil_Dirt"
    },
    {
      "x": -17,
      "y": 10,
      "z": 19,
      "name": "Rock_Shale_Cobble"
    },
    {
      "x": -17,
      "y": 11,
      "z": 19,
      "name": "Rock_Shale_Cobble"
    },
    {
      "x": -17,
      "y": 12,
      "z": 19,
      "name": "Rock_Shale_Cobble"
    },
    {
      "x": -17,
      "y": 13,
      "z": 19,
      "name": "Rock_Shale_Brick"
    },
    {
      "x": -17,
      "y": 14,
      "z": 19,
      "name": "Rock_Shale_Brick"
    },
    {
      "x": -17,
      "y": 15,
      "z": 19,
      "name": "Rock_Shale_Brick_Smooth"
    },
    {
      "x": -17,
      "y": 16,
      "z": 19,
      "name": "Plant_Moss_Rug_Green_Dark",
      "support": 15
    },
    {
      "x": -17,
      "y": 9,
      "z": 20,
      "name": "Soil_Dirt"
    },
    {
      "x": -17,
      "y": 10,
      "z": 20,
      "name": "Rock_Shale_Cobble"
    },
    {
      "x": -17,
      "y": 11,
      "z": 20,
      "name": "Rock_Shale_Cobble"
    },
    {
      "x": -17,
      "y": 12,
      "z": 20,
      "name": "Rock_Shale_Cobble_Stairs"
    },
    {
      "x": -17,
      "y": 9,
      "z": 21,
      "name": "Soil_Dirt"
    },
    {
      "x": -17,
      "y": 10,
      "z": 21,
      "name": "Rock_Shale_Cobble"
    },
    {
      "x": -17,
      "y": 11,
      "z": 21,
      "name": "Rock_Shale_Cobble_Stairs"
    },
    {
      "x": -17,
      "y": 9,
      "z": 22,
      "name": "Soil_Grass"
    },
    {
      "x": -16,
      "y": 9,
      "z": -22,
      "name": "Soil_Grass"
    },
    {
      "x": -16,
      "y": 9,
      "z": -21,
      "name": "Soil_Dirt"
    },
    {
      "x": -16,
      "y": 10,
      "z": -21,
      "name": "Rock_Shale_Cobble"
    },
    {
      "x": -16,
      "y": 11,
      "z": -21,
      "name": "Rock_Shale_Cobble_Stairs",
      "rotation": 2
    },
    {
      "x": -16,
      "y": 9,
      "z": -20,
      "name": "Soil_Dirt"
    },
    {
      "x": -16,
      "y": 10,
      "z": -20,
      "name": "Rock_Shale_Cobble"
    },
    {
      "x": -16,
      "y": 11,
      "z": -20,
      "name": "Rock_Shale_Cobble"
    },
    {
      "x": -16,
      "y": 12,
      "z": -20,
      "name": "Rock_Shale_Cobble_Stairs",
      "rotation": 2
    },
    {
      "x": -16,
      "y": 9,
      "z": -19,
      "name": "Soil_Dirt"
    },
    {
      "x": -16,
      "y": 10,
      "z": -19,
      "name": "Rock_Shale_Cobble"
    },
    {
      "x": -16,
      "y": 11,
      "z": -19,
      "name": "Rock_Shale_Cobble"
    },
    {
      "x": -16,
      "y": 12,
      "z": -19,
      "name": "Rock_Shale_Cobble",
      "rotation": 3
    },
    {
      "x": -16,
      "y": 13,
      "z": -19,
      "name": "Rock_Shale_Brick",
      "rotation": 3
    },
    {
      "x": -16,
      "y": 14,
      "z": -19,
      "name": "Rock_Shale_Brick",
      "rotation": 3
    },
    {
      "x": -16,
      "y": 9,
      "z": -18,
      "name": "Soil_Dirt"
    },
    {
      "x": -16,
      "y": 10,
      "z": -18,
      "name": "Rock_Shale_Cobble"
    },
    {
      "x": -16,
      "y": 11,
      "z": -18,
      "name": "Rock_Shale_Cobble"
    },
    {
      "x": -16,
      "y": 12,
      "z": -18,
      "name": "Rock_Shale_Cobble",
      "rotation": 3
    },
    {
      "x": -16,
      "y": 13,
      "z": -18,
      "name": "Plant_Moss_Rug_Green_Dark",
      "support": 15
    },
    {
      "x": -16,
      "y": 9,
      "z": -17,
      "name": "Soil_Dirt"
    },
    {
      "x": -16,
      "y": 10,
      "z": -17,
      "name": "Rock_Shale_Cobble"
    },
    {
      "x": -16,
      "y": 11,
      "z": -17,
      "name": "Rock_Shale_Cobble"
    },
    {
      "x": -16,
      "y": 12,
      "z": -17,
      "name": "Rock_Shale_Cobble",
      "rotation": 3
    },
    {
      "x": -16,
      "y": 13,
      "z": -17,
      "name": "Plant_Moss_Rug_Green_Dark",
      "support": 15
    },
    {
      "x": -16,
      "y": 9,
      "z": -16,
      "name": "Soil_Dirt"
    },
    {
      "x": -16,
      "y": 10,
      "z": -16,
      "name": "Rock_Shale_Cobble"
    },
    {
      "x": -16,
      "y": 11,
      "z": -16,
      "name": "Rock_Shale_Cobble"
    },
    {
      "x": -16,
      "y": 12,
      "z": -16,
      "name": "Rock_Shale_Cobble",
      "rotation": 3
    },
    {
      "x": -16,
      "y": 13,
      "z": -16,
      "name": "Rock_Shale_Brick_Smooth"
    },
    {
      "x": -16,
      "y": 14,
      "z": -16,
      "name": "Plant_Moss_Rug_Green_Dark",
      "support": 15
    },
    {
      "x": -16,
      "y": 9,
      "z": -15,
      "name": "Soil_Dirt"
    },
    {
      "x": -16,
      "y": 10,
      "z": -15,
      "name": "Rock_Shale_Cobble"
    },
    {
      "x": -16,
      "y": 11,
      "z": -15,
      "name": "Rock_Shale_Cobble"
    },
    {
      "x": -16,
      "y": 12,
      "z": -15,
      "name": "Rock_Shale_Cobble",
      "rotation": 3
    },
    {
      "x": -16,
      "y": 13,
      "z": -15,
      "name": "Rock_Shale_Cobble",
      "rotation": 3
    },
    {
      "x": -16,
      "y": 14,
      "z": -15,
      "name": "Rock_Shale_Cobble",
      "rotation": 3
    },
    {
      "x": -16,
      "y": 9,
      "z": -14,
      "name": "Soil_Dirt"
    },
    {
      "x": -16,
      "y": 10,
      "z": -14,
      "name": "Rock_Shale_Cobble"
    },
    {
      "x": -16,
      "y": 11,
      "z": -14,
      "name": "Rock_Shale_Cobble"
    },
    {
      "x": -16,
      "y": 12,
      "z": -14,
      "name": "Rock_Shale_Cobble",
      "rotation": 3
    },
    {
      "x": -16,
      "y": 13,
      "z": -14,
      "name": "Rock_Shale_Cobble",
      "rotation": 3
    },
    {
      "x": -16,
      "y": 14,
      "z": -14,
      "name": "Rock_Shale_Cobble",
      "rotation": 3
    },
    {
      "x": -16,
      "y": 9,
      "z": -13,
      "name": "Soil_Dirt"
    },
    {
      "x": -16,
      "y": 10,
      "z": -13,
      "name": "Rock_Shale_Cobble"
    },
    {
      "x": -16,
      "y": 11,
      "z": -13,
      "name": "Rock_Shale_Cobble"
    },
    {
      "x": -16,
      "y": 12,
      "z": -13,
      "name": "Rock_Shale_Cobble",
      "rotation": 3
    },
    {
      "x": -16,
      "y": 13,
      "z": -13,
      "name": "Rock_Shale_Cobble",
      "rotation": 3
    },
    {
      "x": -16,
      "y": 14,
      "z": -13,
      "name": "Rock_Shale_Cobble",
      "rotation": 3
    },
    {
      "x": -16,
      "y": 9,
      "z": -12,
      "name": "Soil_Dirt"
    },
    {
      "x": -16,
      "y": 10,
      "z": -12,
      "name": "Rock_Shale_Cobble"
    },
    {
      "x": -16,
      "y": 11,
      "z": -12,
      "name": "Rock_Shale_Cobble"
    },
    {
      "x": -16,
      "y": 12,
      "z": -12,
      "name": "Rock_Shale_Cobble",
      "rotation": 3
    },
    {
      "x": -16,
      "y": 13,
      "z": -12,
      "name": "Rock_Shale_Cobble",
      "rotation": 3
    },
    {
      "x": -16,
      "y": 14,
      "z": -12,
      "name": "Rock_Shale_Cobble",
      "rotation": 3
    },
    {
      "x": -16,
      "y": 15,
      "z": -12,
      "name": "Plant_Moss_Rug_Green_Dark",
      "support": 15
    },
    {
      "x": -16,
      "y": 9,
      "z": -11,
      "name": "Soil_Dirt"
    },
    {
      "x": -16,
      "y": 10,
      "z": -11,
      "name": "Rock_Shale_Cobble"
    },
    {
      "x": -16,
      "y": 11,
      "z": -11,
      "name": "Rock_Shale_Cobble"
    },
    {
      "x": -16,
      "y": 12,
      "z": -11,
      "name": "Rock_Shale_Cobble",
      "rotation": 3
    },
    {
      "x": -16,
      "y": 13,
      "z": -11,
      "name": "Rock_Shale_Brick",
      "rotation": 3
    },
    {
      "x": -16,
      "y": 14,
      "z": -11,
      "name": "Plant_Moss_Rug_Green_Dark",
      "support": 15
    },
    {
      "x": -16,
      "y": 9,
      "z": -10,
      "name": "Soil_Dirt"
    },
    {
      "x": -16,
      "y": 10,
      "z": -10,
      "name": "Rock_Shale_Cobble"
    },
    {
      "x": -16,
      "y": 11,
      "z": -10,
      "name": "Rock_Shale_Cobble"
    },
    {
      "x": -16,
      "y": 12,
      "z": -10,
      "name": "Rock_Shale_Cobble",
      "rotation": 3
    },
    {
      "x": -16,
      "y": 9,
      "z": -9,
      "name": "Soil_Dirt"
    },
    {
      "x": -16,
      "y": 10,
      "z": -9,
      "name": "Rock_Shale_Cobble"
    },
    {
      "x": -16,
      "y": 11,
      "z": -9,
      "name": "Rock_Shale_Cobble"
    },
    {
      "x": -16,
      "y": 9,
      "z": -8,
      "name": "Soil_Dirt"
    },
    {
      "x": -16,
      "y": 10,
      "z": -8,
      "name": "Rock_Shale_Cobble"
    },
    {
      "x": -16,
      "y": 11,
      "z": -8,
      "name": "Rock_Shale_Cobble"
    },
    {
      "x": -16,
      "y": 9,
      "z": -7,
      "name": "Soil_Dirt"
    },
    {
      "x": -16,
      "y": 10,
      "z": -7,
      "name": "Rock_Shale_Cobble"
    },
    {
      "x": -16,
      "y": 11,
      "z": -7,
      "name": "Rock_Shale_Cobble"
    },
    {
      "x": -16,
      "y": 9,
      "z": -6,
      "name": "Soil_Dirt"
    },
    {
      "x": -16,
      "y": 10,
      "z": -6,
      "name": "Rock_Shale_Cobble"
    },
    {
      "x": -16,
      "y": 11,
      "z": -6,
      "name": "Rock_Shale_Cobble"
    },
    {
      "x": -16,
      "y": 12,
      "z": -6,
      "name": "Plant_Moss_Rug_Green_Dark",
      "support": 15
    },
    {
      "x": -16,
      "y": 9,
      "z": -5,
      "name": "Soil_Dirt"
    },
    {
      "x": -16,
      "y": 10,
      "z": -5,
      "name": "Rock_Shale_Cobble"
    },
    {
      "x": -16,
      "y": 11,
      "z": -5,
      "name": "Rock_Shale_Cobble"
    },
    {
      "x": -16,
      "y": 12,
      "z": -5,
      "name": "Plant_Moss_Rug_Green_Dark",
      "support": 15
    },
    {
      "x": -16,
      "y": 9,
      "z": -4,
      "name": "Soil_Dirt"
    },
    {
      "x": -16,
      "y": 10,
      "z": -4,
      "name": "Rock_Shale_Cobble"
    },
    {
      "x": -16,
      "y": 11,
      "z": -4,
      "name": "Rock_Shale_Cobble"
    },
    {
      "x": -16,
      "y": 12,
      "z": -4,
      "name": "Plant_Moss_Rug_Green_Dark",
      "support": 15
    },
    {
      "x": -16,
      "y": 9,
      "z": -3,
      "name": "Soil_Dirt"
    },
    {
      "x": -16,
      "y": 10,
      "z": -3,
      "name": "Rock_Shale_Cobble"
    },
    {
      "x": -16,
      "y": 11,
      "z": -3,
      "name": "Rock_Shale_Cobble"
    },
    {
      "x": -16,
      "y": 9,
      "z": -2,
      "name": "Soil_Dirt"
    },
    {
      "x": -16,
      "y": 10,
      "z": -2,
      "name": "Rock_Shale_Cobble"
    },
    {
      "x": -16,
      "y": 11,
      "z": -2,
      "name": "Rock_Shale_Cobble"
    },
    {
      "x": -16,
      "y": 9,
      "z": -1,
      "name": "Soil_Dirt"
    },
    {
      "x": -16,
      "y": 10,
      "z": -1,
      "name": "Rock_Shale_Cobble"
    },
    {
      "x": -16,
      "y": 11,
      "z": -1,
      "name": "Rock_Shale_Cobble"
    },
    {
      "x": -16,
      "y": 9,
      "z": 0,
      "name": "Soil_Dirt"
    },
    {
      "x": -16,
      "y": 10,
      "z": 0,
      "name": "Rock_Shale_Cobble"
    },
    {
      "x": -16,
      "y": 11,
      "z": 0,
      "name": "Rock_Shale_Cobble"
    },
    {
      "x": -16,
      "y": 9,
      "z": 1,
      "name": "Soil_Dirt"
    },
    {
      "x": -16,
      "y": 10,
      "z": 1,
      "name": "Rock_Shale_Cobble"
    },
    {
      "x": -16,
      "y": 11,
      "z": 1,
      "name": "Rock_Shale_Cobble"
    },
    {
      "x": -16,
      "y": 9,
      "z": 2,
      "name": "Soil_Dirt"
    },
    {
      "x": -16,
      "y": 10,
      "z": 2,
      "name": "Rock_Shale_Cobble"
    },
    {
      "x": -16,
      "y": 11,
      "z": 2,
      "name": "Rock_Shale_Cobble"
    },
    {
      "x": -16,
      "y": 9,
      "z": 3,
      "name": "Soil_Dirt"
    },
    {
      "x": -16,
      "y": 10,
      "z": 3,
      "name": "Rock_Shale_Cobble"
    },
    {
      "x": -16,
      "y": 11,
      "z": 3,
      "name": "Rock_Shale_Cobble"
    },
    {
      "x": -16,
      "y": 9,
      "z": 4,
      "name": "Soil_Dirt"
    },
    {
      "x": -16,
      "y": 10,
      "z": 4,
      "name": "Rock_Shale_Cobble"
    },
    {
      "x": -16,
      "y": 11,
      "z": 4,
      "name": "Rock_Shale_Cobble"
    },
    {
      "x": -16,
      "y": 9,
      "z": 5,
      "name": "Soil_Dirt"
    },
    {
      "x": -16,
      "y": 10,
      "z": 5,
      "name": "Rock_Shale_Cobble"
    },
    {
      "x": -16,
      "y": 11,
      "z": 5,
      "name": "Rock_Shale_Cobble"
    },
    {
      "x": -16,
      "y": 9,
      "z": 6,
      "name": "Soil_Dirt"
    },
    {
      "x": -16,
      "y": 10,
      "z": 6,
      "name": "Rock_Shale_Cobble"
    },
    {
      "x": -16,
      "y": 11,
      "z": 6,
      "name": "Rock_Shale_Cobble"
    },
    {
      "x": -16,
      "y": 9,
      "z": 7,
      "name": "Soil_Dirt"
    },
    {
      "x": -16,
      "y": 10,
      "z": 7,
      "name": "Rock_Shale_Cobble"
    },
    {
      "x": -16,
      "y": 11,
      "z": 7,
      "name": "Rock_Shale_Cobble"
    },
    {
      "x": -16,
      "y": 9,
      "z": 8,
      "name": "Soil_Dirt"
    },
    {
      "x": -16,
      "y": 10,
      "z": 8,
      "name": "Rock_Shale_Cobble"
    },
    {
      "x": -16,
      "y": 11,
      "z": 8,
      "name": "Rock_Shale_Cobble"
    },
    {
      "x": -16,
      "y": 9,
      "z": 9,
      "name": "Soil_Dirt"
    },
    {
      "x": -16,
      "y": 10,
      "z": 9,
      "name": "Rock_Shale_Cobble"
    },
    {
      "x": -16,
      "y": 11,
      "z": 9,
      "name": "Rock_Shale_Cobble"
    },
    {
      "x": -16,
      "y": 9,
      "z": 10,
      "name": "Soil_Dirt"
    },
    {
      "x": -16,
      "y": 10,
      "z": 10,
      "name": "Rock_Shale_Cobble"
    },
    {
      "x": -16,
      "y": 11,
      "z": 10,
      "name": "Rock_Shale_Cobble"
    },
    {
      "x": -16,
      "y": 12,
      "z": 10,
      "name": "Rock_Shale_Cobble"
    },
    {
      "x": -16,
      "y": 9,
      "z": 11,
      "name": "Soil_Dirt"
    },
    {
      "x": -16,
      "y": 10,
      "z": 11,
      "name": "Rock_Shale_Cobble"
    },
    {
      "x": -16,
      "y": 11,
      "z": 11,
      "name": "Rock_Shale_Cobble"
    },
    {
      "x": -16,
      "y": 12,
      "z": 11,
      "name": "Rock_Shale_Cobble"
    },
    {
      "x": -16,
      "y": 13,
      "z": 11,
      "name": "Rock_Shale_Brick"
    },
    {
      "x": -16,
      "y": 9,
      "z": 12,
      "name": "Soil_Dirt"
    },
    {
      "x": -16,
      "y": 10,
      "z": 12,
      "name": "Rock_Shale_Cobble"
    },
    {
      "x": -16,
      "y": 11,
      "z": 12,
      "name": "Rock_Shale_Cobble"
    },
    {
      "x": -16,
      "y": 12,
      "z": 12,
      "name": "Rock_Shale_Cobble"
    },
    {
      "x": -16,
      "y": 13,
      "z": 12,
      "name": "Rock_Shale_Cobble"
    },
    {
      "x": -16,
      "y": 14,
      "z": 12,
      "name": "Rock_Shale_Cobble"
    },
    {
      "x": -16,
      "y": 9,
      "z": 13,
      "name": "Soil_Dirt"
    },
    {
      "x": -16,
      "y": 10,
      "z": 13,
      "name": "Rock_Shale_Cobble"
    },
    {
      "x": -16,
      "y": 11,
      "z": 13,
      "name": "Rock_Shale_Cobble"
    },
    {
      "x": -16,
      "y": 12,
      "z": 13,
      "name": "Rock_Shale_Cobble"
    },
    {
      "x": -16,
      "y": 13,
      "z": 13,
      "name": "Rock_Shale_Cobble"
    },
    {
      "x": -16,
      "y": 14,
      "z": 13,
      "name": "Rock_Shale_Cobble"
    },
    {
      "x": -16,
      "y": 9,
      "z": 14,
      "name": "Soil_Dirt"
    },
    {
      "x": -16,
      "y": 10,
      "z": 14,
