{
  "version": 8,
  "blockIdVersion": 11,
  "anchorX": 0,
  "anchorY": 0,
  "anchorZ": 0,
  "blocks": [
    {
      "x": -10,
      "y": 0,
      "z": -5,
      "name": "Wood_Sallow_Trunk_Full",
      "support": 15,
      "rotation": 4
    },
    {
      "x": -10,
      "y": 1,
      "z": -5,
      "name": "Plant_Moss_Wall_Green_Dark",
      "support": 15,
      "rotation": 2
    },
    {
      "x": -10,
      "y": 0,
      "z": -4,
      "name": "Wood_Sallow_Trunk",
      "support": 15
    },
    {
      "x": -10,
      "y": 1,
      "z": -4,
      "name": "Wood_Sallow_Trunk_Full",
      "support": 15
    },
    {
      "x": -10,
      "y": 2,
      "z": -4,
      "name": "Plant_Moss_Rug_Green_Dark",
      "support": 15
    },
    {
      "x": -10,
      "y": 0,
      "z": -3,
      "name": "Wood_Sallow_Trunk",
      "support": 15
    },
    {
      "x": -10,
      "y": 1,
      "z": -3,
      "name": "Wood_Sallow_Trunk",
      "support": 15
    },
    {
      "x": -10,
      "y": 2,
      "z": -3,
      "name": "Wood_Sallow_Trunk_Full",
      "support": 15
    },
    {
      "x": -10,
      "y": 3,
      "z": -3,
      "name": "Plant_Moss_Rug_Green_Dark",
      "support": 15
    },
    {
      "x": -10,
      "y": 53,
      "z": 0,
      "name": "Plant_Leaves_Beech",
      "support": 15
    },
    {
      "x": -9,
      "y": 52,
      "z": -7,
      "name": "Plant_Leaves_Beech",
      "support": 15
    },
    {
      "x": -9,
      "y": 53,
      "z": -7,
      "name": "Plant_Leaves_Beech",
      "support": 15
    },
    {
      "x": -9,
      "y": 3,
      "z": -4,
      "name": "Plant_Moss_Wall_Green_Dark",
      "support": 15,
      "rotation": 2
    },
    {
      "x": -9,
      "y": 51,
      "z": -4,
      "name": "Plant_Leaves_Beech",
      "support": 15
    },
    {
      "x": -9,
      "y": 52,
      "z": -4,
      "name": "Plant_Leaves_Beech",
      "support": 15
    },
    {
      "x": -9,
      "y": 53,
      "z": -4,
      "name": "Plant_Leaves_Beech",
      "support": 15
    },
    {
      "x": -9,
      "y": 0,
      "z": -3,
      "name": "Wood_Sallow_Trunk",
      "support": 15
    },
    {
      "x": -9,
      "y": 1,
      "z": -3,
      "name": "Wood_Sallow_Trunk",
      "support": 15
    },
    {
      "x": -9,
      "y": 2,
      "z": -3,
      "name": "Wood_Sallow_Trunk",
      "support": 15
    },
    {
      "x": -9,
      "y": 3,
      "z": -3,
      "name": "Wood_Sallow_Trunk_Full",
      "support": 15
    },
    {
      "x": -9,
      "y": 4,
      "z": -3,
      "name": "Plant_Moss_Rug_Green_Dark",
      "support": 15
    },
    {
      "x": -9,
      "y": 0,
      "z": -2,
      "name": "Wood_Sallow_Trunk",
      "support": 15
    },
    {
      "x": -9,
      "y": 1,
      "z": -2,
      "name": "Wood_Sallow_Trunk",
      "support": 15
    },
    {
      "x": -9,
      "y": 2,
      "z": -2,
      "name": "Wood_Sallow_Trunk",
      "support": 15
    },
    {
      "x": -9,
      "y": 3,
      "z": -2,
      "name": "Wood_Sallow_Trunk_Full",
      "support": 15
    },
    {
      "x": -9,
      "y": 4,
      "z": -2,
      "name": "Plant_Moss_Rug_Green_Dark",
      "support": 15
    },
    {
      "x": -9,
      "y": 3,
      "z": -1,
      "name": "Plant_Moss_Wall_Green_Dark",
      "support": 15
    },
    {
      "x": -9,
      "y": 53,
      "z": -1,
      "name": "Plant_Leaves_Beech",
      "support": 15
    },
    {
      "x": -9,
      "y": 52,
      "z": 0,
      "name": "Plant_Leaves_Beech",
      "support": 15
    },
    {
      "x": -9,
      "y": 53,
      "z": 0,
      "name": "Wood_Sallow_Branch_Corner",
      "support": 15,
      "rotation": 3
    },
    {
      "x": -9,
      "y": 54,
      "z": 0,
      "name": "Plant_Leaves_Beech",
      "support": 15
    },
    {
      "x": -9,
      "y": 53,
      "z": 1,
      "name": "Plant_Leaves_Beech",
      "support": 15
    },
    {
      "x": -9,
      "y": 56,
      "z": 1,
      "name": "Plant_Leaves_Beech",
      "support": 15
    },
    {
      "x": -9,
      "y": 57,
      "z": 1,
      "name": "Plant_Leaves_Beech",
      "support": 15
    },
    {
      "x": -8,
      "y": 52,
      "z": -8,
      "name": "Plant_Leaves_Beech",
      "support": 15
    },
    {
      "x": -8,
      "y": 53,
      "z": -8,
      "name": "Plant_Leaves_Beech",
      "support": 15
    },
    {
      "x": -8,
      "y": 51,
      "z": -7,
      "name": "Plant_Leaves_Beech",
      "support": 15
    },
    {
      "x": -8,
      "y": 52,
      "z": -7,
      "name": "Wood_Sallow_Branch_Corner",
      "support": 15,
      "rotation": 3
    },
    {
      "x": -8,
      "y": 53,
      "z": -7,
      "name": "Wood_Sallow_Branch_Long",
      "support": 15
    },
    {
      "x": -8,
      "y": 54,
      "z": -7,
      "name": "Plant_Leaves_Beech",
      "support": 15
    },
    {
      "x": -8,
      "y": 57,
      "z": -7,
      "name": "Plant_Leaves_Beech",
      "support": 15
    },
    {
      "x": -8,
      "y": 58,
      "z": -7,
      "name": "Plant_Leaves_Beech",
      "support": 15
    },
    {
      "x": -8,
      "y": 52,
      "z": -6,
      "name": "Plant_Leaves_Beech",
      "support": 15
    },
    {
      "x": -8,
      "y": 53,
      "z": -6,
      "name": "Plant_Leaves_Beech",
      "support": 15
    },
    {
      "x": -8,
      "y": 51,
      "z": -5,
      "name": "Plant_Leaves_Beech",
      "support": 15
    },
    {
      "x": -8,
      "y": 52,
      "z": -5,
      "name": "Plant_Leaves_Beech",
      "support": 15
    },
    {
      "x": -8,
      "y": 50,
      "z": -4,
      "name": "Plant_Leaves_Beech",
      "support": 15
    },
    {
      "x": -8,
      "y": 51,
      "z": -4,
      "name": "Wood_Sallow_Branch_Corner",
      "support": 15,
      "rotation": 3
    },
    {
      "x": -8,
      "y": 52,
      "z": -4,
      "name": "Wood_Sallow_Branch_Long",
      "support": 15
    },
    {
      "x": -8,
      "y": 53,
      "z": -4,
      "name": "Wood_Sallow_Branch_Long",
      "support": 15
    },
    {
      "x": -8,
      "y": 54,
      "z": -4,
      "name": "Plant_Leaves_Beech",
      "support": 15
    },
    {
      "x": -8,
      "y": 0,
      "z": -3,
      "name": "Wood_Sallow_Trunk",
      "support": 15
    },
    {
      "x": -8,
      "y": 1,
      "z": -3,
      "name": "Wood_Sallow_Trunk_Full",
      "support": 15
    },
    {
      "x": -8,
      "y": 2,
      "z": -3,
      "name": "Plant_Moss_Rug_Green_Dark",
      "support": 15
    },
    {
      "x": -8,
      "y": 51,
      "z": -3,
      "name": "Plant_Leaves_Beech",
      "support": 15
    },
    {
      "x": -8,
      "y": 52,
      "z": -3,
      "name": "Plant_Leaves_Beech",
      "support": 15
    },
    {
      "x": -8,
      "y": 53,
      "z": -3,
      "name": "Plant_Leaves_Beech",
      "support": 15
    },
    {
      "x": -8,
      "y": 0,
      "z": -2,
      "name": "Wood_Sallow_Trunk",
      "support": 15
    },
    {
      "x": -8,
      "y": 1,
      "z": -2,
      "name": "Wood_Sallow_Trunk",
      "support": 15
    },
    {
      "x": -8,
      "y": 2,
      "z": -2,
      "name": "Wood_Sallow_Trunk",
      "support": 15
    },
    {
      "x": -8,
      "y": 3,
      "z": -2,
      "name": "Wood_Sallow_Trunk",
      "support": 15
    },
    {
      "x": -8,
      "y": 4,
      "z": -2,
      "name": "Wood_Sallow_Trunk_Full",
      "support": 15
    },
    {
      "x": -8,
      "y": 0,
      "z": -1,
      "name": "Wood_Sallow_Trunk_Full",
      "support": 15
    },
    {
      "x": -8,
      "y": 48,
      "z": 0,
      "name": "Plant_Leaves_Beech",
      "support": 15
    },
    {
      "x": -8,
      "y": 49,
      "z": 0,
      "name": "Plant_Leaves_Beech",
      "support": 15
    },
    {
      "x": -8,
      "y": 53,
      "z": 0,
      "name": "Wood_Sallow_Branch_Long",
      "support": 15,
      "rotation": 5
    },
    {
      "x": -8,
      "y": 56,
      "z": 0,
      "name": "Plant_Leaves_Beech",
      "support": 15
    },
    {
      "x": -8,
      "y": 57,
      "z": 0,
      "name": "Plant_Leaves_Beech",
      "support": 15
    },
    {
      "x": -8,
      "y": 53,
      "z": 1,
      "name": "Plant_Leaves_Beech",
      "support": 15
    },
    {
      "x": -8,
      "y": 55,
      "z": 1,
      "name": "Plant_Leaves_Beech",
      "support": 15
    },
    {
      "x": -8,
      "y": 56,
      "z": 1,
      "name": "Wood_Sallow_Branch_Corner",
      "support": 15,
      "rotation": 3
    },
    {
      "x": -8,
      "y": 57,
      "z": 1,
      "name": "Wood_Sallow_Branch_Long",
      "support": 15
    },
    {
      "x": -8,
      "y": 58,
      "z": 1,
      "name": "Plant_Leaves_Beech",
      "support": 15
    },
    {
      "x": -8,
      "y": 53,
      "z": 2,
      "name": "Plant_Leaves_Beech",
      "support": 15
    },
    {
      "x": -8,
      "y": 56,
      "z": 2,
      "name": "Plant_Leaves_Beech",
      "support": 15
    },
    {
      "x": -8,
      "y": 57,
      "z": 2,
      "name": "Plant_Leaves_Beech",
      "support": 15
    },
    {
      "x": -8,
      "y": 53,
      "z": 3,
      "name": "Plant_Leaves_Beech",
      "support": 15
    },
    {
      "x": -7,
      "y": 47,
      "z": -8,
      "name": "Plant_Leaves_Beech",
      "support": 15
    },
    {
      "x": -7,
      "y": 48,
      "z": -8,
      "name": "Plant_Leaves_Beech",
      "support": 15
    },
    {
      "x": -7,
      "y": 52,
      "z": -8,
      "name": "Plant_Leaves_Beech",
      "support": 15
    },
    {
      "x": -7,
      "y": 57,
      "z": -8,
      "name": "Plant_Leaves_Beech",
      "support": 15
    },
    {
      "x": -7,
      "y": 58,
      "z": -8,
      "name": "Plant_Leaves_Beech",
      "support": 15
    },
    {
      "x": -7,
      "y": 52,
      "z": -7,
      "name": "Wood_Sallow_Branch_Long",
      "support": 15,
      "rotation": 5
    },
    {
      "x": -7,
      "y": 53,
      "z": -7,
      "name": "Plant_Leaves_Beech",
      "support": 15
    },
    {
      "x": -7,
      "y": 56,
      "z": -7,
      "name": "Plant_Leaves_Beech",
      "support": 15
    },
    {
      "x": -7,
      "y": 57,
      "z": -7,
      "name": "Wood_Sallow_Branch_Corner",
      "support": 15,
      "rotation": 3
    },
    {
      "x": -7,
      "y": 58,
      "z": -7,
      "name": "Wood_Sallow_Branch_Long",
      "support": 15
    },
    {
      "x": -7,
      "y": 59,
      "z": -7,
      "name": "Plant_Leaves_Beech",
      "support": 15
    },
    {
      "x": -7,
      "y": 52,
      "z": -6,
      "name": "Plant_Leaves_Beech",
      "support": 15
    },
    {
      "x": -7,
      "y": 57,
      "z": -6,
      "name": "Plant_Leaves_Beech",
      "support": 15
    },
    {
      "x": -7,
      "y": 58,
      "z": -6,
      "name": "Plant_Leaves_Beech",
      "support": 15
    },
    {
      "x": -7,
      "y": 50,
      "z": -4,
      "name": "Plant_Leaves_Beech",
      "support": 15
    },
    {
      "x": -7,
      "y": 51,
      "z": -4,
      "name": "Wood_Sallow_Branch_Long",
      "support": 15,
      "rotation": 5
    },
    {
      "x": -7,
      "y": 52,
      "z": -4,
      "name": "Plant_Leaves_Beech",
      "support": 15
    },
    {
      "x": -7,
      "y": 53,
      "z": -4,
      "name": "Plant_Leaves_Beech",
      "support": 15
    },
    {
      "x": -7,
      "y": 0,
      "z": -3,
      "name": "Wood_Sallow_Trunk",
      "support": 15
    },
    {
      "x": -7,
      "y": 1,
      "z": -3,
      "name": "Wood_Sallow_Trunk",
      "support": 15
    },
    {
      "x": -7,
      "y": 2,
      "z": -3,
      "name": "Wood_Sallow_Trunk_Full",
      "support": 15
    },
    {
      "x": -7,
      "y": 51,
      "z": -3,
      "name": "Plant_Leaves_Beech",
      "support": 15
    },
    {
      "x": -7,
      "y": 0,
      "z": -2,
      "name": "Wood_Sallow_Trunk",
      "support": 15
    },
    {
      "x": -7,
      "y": 1,
      "z": -2,
      "name": "Wood_Sallow_Trunk",
      "support": 15
    },
    {
      "x": -7,
      "y": 2,
      "z": -2,
      "name": "Wood_Sallow_Trunk",
      "support": 15
    },
    {
      "x": -7,
      "y": 3,
      "z": -2,
      "name": "Wood_Sallow_Trunk",
      "support": 15
    },
    {
      "x": -7,
      "y": 4,
      "z": -2,
      "name": "Wood_Sallow_Trunk",
      "support": 15
    },
    {
      "x": -7,
      "y": 5,
      "z": -2,
      "name": "Wood_Sallow_Trunk_Full",
      "support": 15
    },
    {
      "x": -7,
      "y": 10,
      "z": -2,
      "name": "Plant_Vine_Liana_End",
      "support": 15,
      "rotation": 3
    },
    {
      "x": -7,
      "y": 11,
      "z": -2,
      "name": "Plant_Vine_Liana",
      "support": 15,
      "rotation": 3
    },
    {
      "x": -7,
      "y": 12,
      "z": -2,
      "name": "Plant_Vine_Liana",
      "support": 15,
      "rotation": 3
    },
    {
      "x": -7,
      "y": 13,
      "z": -2,
      "name": "Plant_Vine_Liana",
      "support": 15,
      "rotation": 3
    },
    {
      "x": -7,
      "y": 14,
      "z": -2,
      "name": "Plant_Vine_Liana",
      "support": 15,
      "rotation": 3
    },
    {
      "x": -7,
      "y": 15,
      "z": -2,
      "name": "Plant_Vine_Liana",
      "support": 15,
      "rotation": 3
    },
    {
      "x": -7,
      "y": 16,
      "z": -2,
      "name": "Plant_Vine_Liana",
      "support": 15,
      "rotation": 3
    },
    {
      "x": -7,
      "y": 17,
      "z": -2,
      "name": "Plant_Vine_Liana",
      "support": 15,
      "rotation": 3
    },
    {
      "x": -7,
      "y": 18,
      "z": -2,
      "name": "Plant_Vine_Liana",
      "support": 15,
      "rotation": 3
    },
    {
      "x": -7,
      "y": 19,
      "z": -2,
      "name": "Plant_Vine_Liana",
      "support": 15,
      "rotation": 3
    },
    {
      "x": -7,
      "y": 20,
      "z": -2,
      "name": "Plant_Vine_Liana",
      "support": 15,
      "rotation": 3
    },
    {
      "x": -7,
      "y": 57,
      "z": -2,
      "name": "Plant_Leaves_Beech",
      "support": 15
    },
    {
      "x": -7,
      "y": 58,
      "z": -2,
      "name": "Plant_Leaves_Beech",
      "support": 15
    },
    {
      "x": -7,
      "y": 0,
      "z": -1,
      "name": "Wood_Sallow_Trunk",
      "support": 15
    },
    {
      "x": -7,
      "y": 1,
      "z": -1,
      "name": "Wood_Sallow_Trunk",
      "support": 15
    },
    {
      "x": -7,
      "y": 2,
      "z": -1,
      "name": "Wood_Sallow_Trunk",
      "support": 15
    },
    {
      "x": -7,
      "y": 3,
      "z": -1,
      "name": "Wood_Sallow_Trunk_Full",
      "support": 15
    },
    {
      "x": -7,
      "y": 20,
      "z": -1,
      "name": "Plant_Moss_Wall_Green_Dark",
      "support": 15,
      "rotation": 3
    },
    {
      "x": -7,
      "y": 48,
      "z": -1,
      "name": "Plant_Leaves_Beech",
      "support": 15
    },
    {
      "x": -7,
      "y": 49,
      "z": -1,
      "name": "Plant_Leaves_Beech",
      "support": 15
    },
    {
      "x": -7,
      "y": 51,
      "z": -1,
      "name": "Wood_Sallow_Trunk_Full",
      "support": 15,
      "rotation": 4
    },
    {
      "x": -7,
      "y": 0,
      "z": 0,
      "name": "Wood_Sallow_Trunk_Full",
      "support": 15
    },
    {
      "x": -7,
      "y": 47,
      "z": 0,
      "name": "Plant_Leaves_Beech",
      "support": 15
    },
    {
      "x": -7,
      "y": 48,
      "z": 0,
      "name": "Wood_Sallow_Branch_Corner",
      "support": 15,
      "rotation": 3
    },
    {
      "x": -7,
      "y": 49,
      "z": 0,
      "name": "Wood_Sallow_Branch_Long",
      "support": 15
    },
    {
      "x": -7,
      "y": 50,
      "z": 0,
      "name": "Plant_Leaves_Beech",
      "support": 15
    },
    {
      "x": -7,
      "y": 51,
      "z": 0,
      "name": "Wood_Sallow_Trunk_Full",
      "support": 15,
      "rotation": 4
    },
    {
      "x": -7,
      "y": 52,
      "z": 0,
      "name": "Wood_Sallow_Trunk",
      "support": 15
    },
    {
      "x": -7,
      "y": 53,
      "z": 0,
      "name": "Wood_Sallow_Trunk_Full",
      "support": 15
    },
    {
      "x": -7,
      "y": 56,
      "z": 0,
      "name": "Plant_Leaves_Beech",
      "support": 15
    },
    {
      "x": -7,
      "y": 48,
      "z": 1,
      "name": "Plant_Leaves_Beech",
      "support": 15
    },
    {
      "x": -7,
      "y": 49,
      "z": 1,
      "name": "Plant_Leaves_Beech",
      "support": 15
    },
    {
      "x": -7,
      "y": 53,
      "z": 1,
      "name": "Wood_Sallow_Branch_Long",
      "support": 15,
      "rotation": 4
    },
    {
      "x": -7,
      "y": 55,
      "z": 1,
      "name": "Plant_Leaves_Beech",
      "support": 15
    },
    {
      "x": -7,
      "y": 56,
      "z": 1,
      "name": "Wood_Sallow_Branch_Long",
      "support": 15,
      "rotation": 5
    },
    {
      "x": -7,
      "y": 57,
      "z": 1,
      "name": "Plant_Leaves_Beech",
      "support": 15
    },
    {
      "x": -7,
      "y": 52,
      "z": 2,
      "name": "Plant_Leaves_Beech",
      "support": 15
    },
    {
      "x": -7,
      "y": 53,
      "z": 2,
      "name": "Wood_Sallow_Branch_Long",
      "support": 15,
      "rotation": 4
    },
    {
      "x": -7,
      "y": 54,
      "z": 2,
      "name": "Plant_Leaves_Beech",
      "support": 15
    },
    {
      "x": -7,
      "y": 56,
      "z": 2,
      "name": "Plant_Leaves_Beech",
      "support": 15
    },
    {
      "x": -7,
      "y": 23,
      "z": 3,
      "name": "Plant_Moss_Wall_Green_Dark",
      "support": 15,
      "rotation": 3
    },
    {
      "x": -7,
      "y": 52,
      "z": 3,
      "name": "Plant_Leaves_Beech",
      "support": 15
    },
    {
      "x": -7,
      "y": 53,
      "z": 3,
      "name": "Wood_Sallow_Branch_Corner",
      "support": 15
    },
    {
      "x": -7,
      "y": 54,
      "z": 3,
      "name": "Plant_Leaves_Beech",
      "support": 15
    },
    {
      "x": -7,
      "y": 22,
      "z": 4,
      "name": "Plant_Moss_Wall_Green_Dark",
      "support": 15,
      "rotation": 3
    },
    {
      "x": -7,
      "y": 23,
      "z": 4,
      "name": "Plant_Moss_Wall_Green_Dark",
      "support": 15,
      "rotation": 3
    },
    {
      "x": -7,
      "y": 53,
      "z": 4,
      "name": "Plant_Leaves_Beech",
      "support": 15
    },
    {
      "x": -7,
      "y": 0,
      "z": 6,
      "name": "Wood_Sallow_Trunk",
      "support": 15
    },
    {
      "x": -7,
      "y": 1,
      "z": 6,
      "name": "Wood_Sallow_Trunk_Full",
      "support": 15
    },
    {
      "x": -7,
      "y": 2,
      "z": 6,
      "name": "Plant_Moss_Rug_Green_Dark",
      "support": 15
    },
    {
      "x": -7,
      "y": 0,
      "z": 7,
      "name": "Wood_Sallow_Trunk_Full",
      "support": 15
    },
    {
      "x": -7,
      "y": 1,
      "z": 7,
      "name": "Plant_Moss_Rug_Green_Dark",
      "support": 15
    },
    {
      "x": -7,
      "y": 51,
      "z": 8,
      "name": "Plant_Leaves_Beech",
      "support": 15
    },
    {
      "x": -7,
      "y": 52,
      "z": 8,
      "name": "Plant_Leaves_Beech",
      "support": 15
    },
    {
      "x": -6,
      "y": 52,
      "z": -10,
      "name": "Plant_Leaves_Beech",
      "support": 15
    },
    {
      "x": -6,
      "y": 53,
      "z": -10,
      "name": "Plant_Leaves_Beech",
      "support": 15
    },
    {
      "x": -6,
      "y": 47,
      "z": -9,
      "name": "Plant_Leaves_Beech",
      "support": 15
    },
    {
      "x": -6,
      "y": 48,
      "z": -9,
      "name": "Plant_Leaves_Beech",
      "support": 15
    },
    {
      "x": -6,
      "y": 52,
      "z": -9,
      "name": "Plant_Leaves_Beech",
      "support": 15
    },
    {
      "x": -6,
      "y": 46,
      "z": -8,
      "name": "Plant_Leaves_Beech",
      "support": 15
    },
    {
      "x": -6,
      "y": 47,
      "z": -8,
      "name": "Wood_Sallow_Branch_Corner",
      "support": 15,
      "rotation": 3
    },
    {
      "x": -6,
      "y": 48,
      "z": -8,
      "name": "Wood_Sallow_Branch_Long",
      "support": 15
    },
    {
      "x": -6,
      "y": 49,
      "z": -8,
      "name": "Plant_Leaves_Beech",
      "support": 15
    },
    {
      "x": -6,
      "y": 57,
      "z": -8,
      "name": "Plant_Leaves_Beech",
      "support": 15
    },
    {
      "x": -6,
      "y": 47,
      "z": -7,
      "name": "Plant_Leaves_Beech",
      "support": 15
    },
    {
      "x": -6,
      "y": 48,
      "z": -7,
      "name": "Plant_Leaves_Beech",
      "support": 15
    },
    {
      "x": -6,
      "y": 52,
      "z": -7,
      "name": "Wood_Sallow_Branch_Long",
      "support": 15,
      "rotation": 5
    },
    {
      "x": -6,
      "y": 57,
      "z": -7,
      "name": "Wood_Sallow_Branch_Long",
      "support": 15,
      "rotation": 5
    },
    {
      "x": -6,
      "y": 58,
      "z": -7,
      "name": "Plant_Leaves_Beech",
      "support": 15
    },
    {
      "x": -6,
      "y": 24,
      "z": -6,
      "name": "*Wood_Tropicalwood_Roof_Shallow_State_Definitions_Corner_Right",
      "rotation": 3
    },
    {
      "x": -6,
      "y": 54,
      "z": -6,
      "name": "Plant_Leaves_Beech",
      "support": 15
    },
    {
      "x": -6,
      "y": 57,
      "z": -6,
      "name": "Plant_Leaves_Beech",
      "support": 15
    },
    {
      "x": -6,
      "y": 24,
      "z": -5,
      "name": "*Wood_Tropicalwood_Roof_Shallow_State_Definitions_Corner_Right",
      "filler": 32,
      "rotation": 3
    },
    {
      "x": -6,
      "y": 24,
      "z": -4,
      "name": "Wood_Tropicalwood_Roof_Shallow",
      "rotation": 3
    },
    {
      "x": -6,
      "y": 51,
      "z": -4,
      "name": "Wood_Sallow_Branch_Long",
      "support": 15,
      "rotation": 5
    },
    {
      "x": -6,
      "y": 0,
      "z": -3,
      "name": "Wood_Sallow_Trunk",
      "support": 15
    },
    {
      "x": -6,
      "y": 1,
      "z": -3,
      "name": "Wood_Sallow_Trunk",
      "support": 15
    },
    {
      "x": -6,
      "y": 2,
      "z": -3,
      "name": "Wood_Sallow_Trunk_Full",
      "support": 15
    },
    {
      "x": -6,
      "y": 20,
      "z": -3,
      "name": "Furniture_Crude_Platform",
      "rotation": 1
    },
    {
      "x": -6,
      "y": 21,
      "z": -3,
      "name": "*Wood_Softwood_Fence_State_Definitions_Corner",
      "rotation": 1
    },
    {
      "x": -6,
      "y": 24,
      "z": -3,
      "name": "Wood_Tropicalwood_Roof_Shallow",
      "rotation": 3
    },
    {
      "x": -6,
      "y": 58,
      "z": -3,
      "name": "Plant_Leaves_Beech",
      "support": 15
    },
    {
      "x": -6,
      "y": 0,
      "z": -2,
      "name": "Wood_Sallow_Trunk",
      "support": 15
    },
    {
      "x": -6,
      "y": 1,
      "z": -2,
      "name": "Wood_Sallow_Trunk",
      "support": 15
    },
    {
      "x": -6,
      "y": 2,
      "z": -2,
      "name": "Wood_Sallow_Trunk",
      "support": 15
    },
    {
      "x": -6,
      "y": 3,
      "z": -2,
      "name": "Wood_Sallow_Trunk",
      "support": 15
    },
    {
      "x": -6,
      "y": 4,
      "z": -2,
      "name": "Wood_Sallow_Trunk",
      "support": 15
    },
    {
      "x": -6,
      "y": 5,
      "z": -2,
      "name": "Wood_Sallow_Trunk_Full",
      "support": 15
    },
    {
      "x": -6,
      "y": 20,
      "z": -2,
      "name": "Furniture_Crude_Platform",
      "rotation": 1
    },
    {
      "x": -6,
      "y": 21,
      "z": -2,
      "name": "Wood_Softwood_Fence",
      "rotation": 3
    },
    {
      "x": -6,
      "y": 24,
      "z": -2,
      "name": "Wood_Tropicalwood_Roof_Shallow",
      "rotation": 3
    },
    {
      "x": -6,
      "y": 56,
      "z": -2,
      "name": "Wood_Sallow_Branch_Corner",
      "support": 15,
      "rotation": 2
    },
    {
      "x": -6,
      "y": 57,
      "z": -2,
      "name": "Wood_Sallow_Branch_Long",
      "support": 15
    },
    {
      "x": -6,
      "y": 58,
      "z": -2,
      "name": "Wood_Sallow_Branch_Long",
      "support": 15
    },
    {
      "x": -6,
      "y": 59,
      "z": -2,
      "name": "Plant_Leaves_Beech",
      "support": 15
    },
    {
      "x": -6,
      "y": 0,
      "z": -1,
      "name": "Wood_Sallow_Trunk",
      "support": 15
    },
    {
      "x": -6,
      "y": 1,
      "z": -1,
      "name": "Wood_Sallow_Trunk",
      "support": 15
    },
    {
      "x": -6,
      "y": 2,
      "z": -1,
      "name": "Wood_Sallow_Trunk",
      "support": 15
    },
    {
      "x": -6,
      "y": 3,
      "z": -1,
      "name": "Wood_Sallow_Trunk_Full",
      "support": 15
    },
    {
      "x": -6,
      "y": 20,
      "z": -1,
      "name": "Furniture_Crude_Platform",
      "rotation": 1
    },
    {
      "x": -6,
      "y": 21,
      "z": -1,
      "name": "Wood_Softwood_Fence",
      "rotation": 3
    },
    {
      "x": -6,
      "y": 24,
      "z": -1,
      "name": "Wood_Tropicalwood_Roof_Shallow",
      "rotation": 3
    },
    {
      "x": -6,
      "y": 48,
      "z": -1,
      "name": "Plant_Leaves_Beech",
      "support": 15
    },
    {
      "x": -6,
      "y": 51,
      "z": -1,
      "name": "Wood_Sallow_Trunk",
      "support": 15,
      "rotation": 5
    },
    {
      "x": -6,
      "y": 56,
      "z": -1,
      "name": "Wood_Sallow_Branch_Corner",
      "support": 15,
      "rotation": 19
    },
    {
      "x": -6,
      "y": 58,
      "z": -1,
      "name": "Plant_Leaves_Beech",
      "support": 15
    },
    {
      "x": -6,
      "y": 0,
      "z": 0,
      "name": "Wood_Sallow_Trunk",
      "support": 15
    },
    {
      "x": -6,
      "y": 1,
      "z": 0,
      "name": "Wood_Sallow_Trunk_Full",
      "support": 15
    },
    {
      "x": -6,
      "y": 2,
      "z": 0,
      "name": "Plant_Moss_Rug_Green_Dark",
      "support": 15
    },
    {
      "x": -6,
      "y": 20,
      "z": 0,
      "name": "Furniture_Crude_Platform",
      "rotation": 1
    },
    {
      "x": -6,
      "y": 21,
      "z": 0,
      "name": "Wood_Softwood_Fence",
      "rotation": 3
    },
    {
      "x": -6,
      "y": 24,
      "z": 0,
      "name": "Wood_Tropicalwood_Roof_Shallow",
      "rotation": 3
    },
    {
      "x": -6,
      "y": 48,
      "z": 0,
      "name": "Wood_Sallow_Branch_Long",
      "support": 15,
      "rotation": 5
    },
    {
      "x": -6,
      "y": 49,
      "z": 0,
      "name": "Plant_Leaves_Beech",
      "support": 15
    },
    {
      "x": -6,
      "y": 20,
      "z": 1,
      "name": "Furniture_Crude_Platform",
      "rotation": 1
    },
    {
      "x": -6,
      "y": 21,
      "z": 1,
      "name": "*Wood_Softwood_Fence_State_Definitions_Corner",
      "rotation": 2
    },
    {
      "x": -6,
      "y": 24,
      "z": 1,
      "name": "Wood_Tropicalwood_Roof_Shallow",
      "rotation": 3
    },
    {
      "x": -6,
      "y": 48,
      "z": 1,
      "name": "Plant_Leaves_Beech",
      "support": 15
    },
    {
      "x": -6,
      "y": 56,
      "z": 1,
      "name": "Wood_Sallow_Branch_Long",
      "support": 15,
      "rotation": 5
    },
    {
      "x": -6,
      "y": 24,
      "z": 2,
      "name": "Wood_Tropicalwood_Roof_Shallow",
      "rotation": 3
    },
    {
      "x": -6,
      "y": 53,
      "z": 2,
      "name": "Plant_Leaves_Beech",
      "support": 15
    },
    {
      "x": -6,
      "y": 24,
      "z": 3,
      "name": "*Wood_Tropicalwood_Roof_Shallow_State_Definitions_Corner_Left",
      "filler": 992,
      "rotation": 3
    },
    {
      "x": -6,
      "y": 49,
      "z": 3,
      "name": "Plant_Leaves_Beech",
      "support": 15
    },
    {
      "x": -6,
      "y": 50,
      "z": 3,
      "name": "Plant_Leaves_Beech",
      "support": 15
    },
    {
      "x": -6,
      "y": 53,
      "z": 3,
      "name": "Plant_Leaves_Beech",
      "support": 15
    },
    {
      "x": -6,
      "y": 56,
      "z": 3,
      "name": "Plant_Leaves_Beech",
      "support": 15
    },
    {
      "x": -6,
      "y": 3,
      "z": 4,
      "name": "Plant_Moss_Wall_Green_Dark",
      "support": 15,
      "rotation": 3
    },
    {
      "x": -6,
      "y": 24,
      "z": 4,
      "name": "*Wood_Tropicalwood_Roof_Shallow_State_Definitions_Corner_Left",
      "rotation": 3
    },
    {
      "x": -6,
      "y": 56,
      "z": 4,
      "name": "Plant_Leaves_Beech",
      "support": 15
    },
    {
      "x": -6,
      "y": 57,
      "z": 4,
      "name": "Plant_Leaves_Beech",
      "support": 15
    },
    {
      "x": -6,
      "y": 0,
      "z": 5,
      "name": "Wood_Sallow_Trunk",
      "support": 15
    },
    {
      "x": -6,
      "y": 1,
      "z": 5,
      "name": "Wood_Sallow_Trunk",
      "support": 15
    },
    {
      "x": -6,
      "y": 2,
      "z": 5,
      "name": "Wood_Sallow_Trunk_Full",
      "support": 15
    },
    {
      "x": -6,
      "y": 23,
      "z": 5,
      "name": "Plant_Moss_Wall_Green_Dark",
      "support": 15
    },
    {
      "x": -6,
      "y": 0,
      "z": 6,
      "name": "Wood_Sallow_Trunk",
      "support": 15
    },
    {
      "x": -6,
      "y": 1,
      "z": 6,
      "name": "Wood_Sallow_Trunk",
      "support": 15
    },
    {
      "x": -6,
      "y": 2,
      "z": 6,
      "name": "Wood_Sallow_Trunk_Full",
      "support": 15
    },
    {
      "x": -6,
      "y": 3,
      "z": 6,
      "name": "Plant_Moss_Rug_Green_Dark",
      "support": 15
    },
    {
      "x": -6,
      "y": 2,
      "z": 7,
      "name": "Plant_Moss_Wall_Green_Dark",
      "support": 15
    },
    {
      "x": -6,
      "y": 51,
      "z": 7,
      "name": "Plant_Leaves_Beech",
      "support": 15
    },
    {
      "x": -6,
      "y": 52,
      "z": 7,
      "name": "Plant_Leaves_Beech",
      "support": 15
    },
    {
      "x": -6,
      "y": 50,
      "z": 8,
      "name": "Plant_Leaves_Beech",
      "support": 15
    },
    {
      "x": -6,
      "y": 51,
      "z": 8,
      "name": "Wood_Sallow_Branch_Corner",
      "support": 15,
      "rotation": 3
    },
    {
      "x": -6,
      "y": 52,
      "z": 8,
      "name": "Wood_Sallow_Branch_Long",
      "support": 15
    },
    {
      "x": -6,
      "y": 53,
      "z": 8,
      "name": "Plant_Leaves_Beech",
      "support": 15
    },
    {
      "x": -6,
      "y": 51,
      "z": 9,
      "name": "Plant_Leaves_Beech",
      "support": 15
    },
    {
      "x": -6,
      "y": 52,
      "z": 9,
      "name": "Plant_Leaves_Beech",
      "support": 15
    },
    {
      "x": -5,
      "y": 52,
      "z": -11,
      "name": "Plant_Leaves_Beech",
      "support": 15
    },
    {
      "x": -5,
      "y": 53,
      "z": -11,
      "name": "Plant_Leaves_Beech",
      "support": 15
    },
    {
      "x": -5,
      "y": 0,
      "z": -10,
      "name": "Wood_Sallow_Trunk_Full",
      "support": 15
    },
    {
      "x": -5,
      "y": 1,
      "z": -10,
      "name": "Plant_Moss_Rug_Green_Dark",
      "support": 15
    },
    {
      "x": -5,
      "y": 52,
      "z": -10,
      "name": "Wood_Sallow_Branch_Corner",
      "support": 15,
      "rotation": 2
    },
    {
      "x": -5,
      "y": 53,
      "z": -10,
      "name": "Wood_Sallow_Branch_Long",
      "support": 15
    },
    {
      "x": -5,
      "y": 54,
      "z": -10,
      "name": "Plant_Leaves_Beech",
      "support": 15
    },
    {
      "x": -5,
      "y": 0,
      "z": -9,
      "name": "Wood_Sallow_Trunk_Full",
      "support": 15
    },
    {
      "x": -5,
      "y": 1,
      "z": -9,
      "name": "Plant_Moss_Rug_Green_Dark",
      "support": 15
    },
    {
      "x": -5,
      "y": 47,
      "z": -9,
      "name": "Plant_Leaves_Beech",
      "support": 15
    },
    {
      "x": -5,
      "y": 51,
      "z": -9,
      "name": "Plant_Leaves_Beech",
      "support": 15
    },
    {
      "x": -5,
      "y": 52,
      "z": -9,
      "name": "Wood_Sallow_Branch_Long",
      "support": 15,
      "rotation": 4
    },
    {
      "x": -5,
      "y": 53,
      "z": -9,
      "name": "Plant_Leaves_Beech",
      "support": 15
    },
    {
      "x": -5,
      "y": 2,
      "z": -8,
      "name": "Plant_Moss_Wall_Green_Dark",
      "support": 15,
      "rotation": 3
    },
    {
      "x": -5,
      "y": 47,
      "z": -8,
      "name": "Wood_Sallow_Branch_Long",
      "support": 15,
      "rotation": 5
    },
    {
      "x": -5,
      "y": 48,
      "z": -8,
      "name": "Plant_Leaves_Beech",
      "support": 15
    },
    {
      "x": -5,
      "y": 52,
      "z": -8,
      "name": "Wood_Sallow_Branch_Long",
      "support": 15,
      "rotation": 4
    },
    {
      "x": -5,
      "y": 52,
      "z": -7,
      "name": "Wood_Sallow_Trunk_Full",
      "support": 15,
      "rotation": 4
    },
    {
      "x": -5,
      "y": 54,
      "z": -7,
      "name": "Plant_Leaves_Beech",
      "support": 15
    },
    {
      "x": -5,
      "y": 57,
      "z": -7,
      "name": "Wood_Sallow_Branch_Long",
      "support": 15,
      "rotation": 5
    },
    {
      "x": -5,
      "y": 24,
      "z": -6,
      "name": "*Wood_Tropicalwood_Roof_Shallow_State_Definitions_Corner_Right",
      "filler": 1,
      "rotation": 3
    },
    {
      "x": -5,
      "y": 51,
      "z": -6,
      "name": "Wood_Sallow_Trunk_Full",
      "support": 15,
      "rotation": 5
    },
    {
      "x": -5,
      "y": 52,
      "z": -6,
      "name": "Wood_Sallow_Trunk_Full",
      "support": 15,
      "rotation": 4
    },
    {
      "x": -5,
      "y": 53,
      "z": -6,
      "name": "Wood_Sallow_Branch_Long",
      "support": 15
    },
    {
      "x": -5,
      "y": 54,
      "z": -6,
      "name": "Wood_Sallow_Branch_Long",
      "support": 15
    },
    {
      "x": -5,
      "y": 55,
      "z": -6,
      "name": "Plant_Leaves_Beech",
      "support": 15
    },
    {
      "x": -5,
      "y": 20,
      "z": -5,
      "name": "Furniture_Crude_Platform"
    },
    {
      "x": -5,
      "y": 21,
      "z": -5,
      "name": "*Wood_Softwood_Fence_State_Definitions_Corner",
      "rotation": 1
    },
    {
      "x": -5,
      "y": 22,
      "z": -5,
      "name": "Wood_Softwood_Beam"
    },
    {
      "x": -5,
      "y": 23,
      "z": -5,
      "name": "Wood_Softwood_Beam"
    },
    {
      "x": -5,
      "y": 24,
      "z": -5,
      "name": "*Wood_Tropicalwood_Roof_Shallow_State_Definitions_Corner_Right",
      "filler": 33,
      "rotation": 3
    },
    {
      "x": -5,
      "y": 54,
      "z": -5,
      "name": "Plant_Leaves_Beech",
      "support": 15
    },
    {
      "x": -5,
      "y": 59,
      "z": -5,
      "name": "Plant_Leaves_Beech",
      "support": 15
    },
    {
      "x": -5,
      "y": 20,
      "z": -4,
      "name": "Furniture_Crude_Platform",
      "rotation": 1
    },
    {
      "x": -5,
      "y": 21,
      "z": -4,
      "name": "Wood_Softwood_Fence",
      "rotation": 3
    },
    {
      "x": -5,
      "y": 24,
      "z": -4,
      "name": "Wood_Tropicalwood_Roof_Shallow",
      "filler": 1,
      "rotation": 3
    },
    {
      "x": -5,
      "y": 51,
      "z": -4,
      "name": "Wood_Sallow_Branch_Long",
      "support": 15,
      "rotation": 5
    },
    {
      "x": -5,
      "y": 0,
      "z": -3,
      "name": "Wood_Sallow_Trunk",
      "support": 15
    },
    {
      "x": -5,
      "y": 1,
      "z": -3,
      "name": "Wood_Sallow_Trunk",
      "support": 15
    },
    {
      "x": -5,
      "y": 2,
      "z": -3,
      "name": "Wood_Sallow_Trunk",
      "support": 15
    },
    {
      "x": -5,
      "y": 3,
      "z": -3,
      "name": "Wood_Sallow_Trunk_Full",
      "support": 15
    },
    {
      "x": -5,
      "y": 20,
      "z": -3,
      "name": "Furniture_Crude_Platform"
    },
    {
      "x": -5,
      "y": 21,
      "z": -3,
      "name": "*Wood_Softwood_Fence_State_Definitions_Corner",
      "rotation": 3
    },
    {
      "x": -5,
      "y": 24,
      "z": -3,
      "name": "Wood_Tropicalwood_Roof_Shallow",
      "filler": 1,
      "rotation": 3
    },
    {
      "x": -5,
      "y": 0,
      "z": -2,
      "name": "Wood_Sallow_Trunk",
      "support": 15
    },
    {
      "x": -5,
      "y": 1,
      "z": -2,
      "name": "Wood_Sallow_Trunk",
      "support": 15
    },
    {
      "x": -5,
      "y": 2,
      "z": -2,
      "name": "Wood_Sallow_Trunk",
      "support": 15
    },
    {
      "x": -5,
      "y": 3,
      "z": -2,
      "name": "Wood_Sallow_Trunk",
      "support": 15
    },
    {
      "x": -5,
      "y": 4,
      "z": -2,
      "name": "Wood_Sallow_Trunk",
      "support": 15
    },
    {
      "x": -5,
      "y": 5,
      "z": -2,
      "name": "Wood_Sallow_Trunk",
      "support": 15
    },
    {
      "x": -5,
      "y": 6,
      "z": -2,
      "name": "Wood_Sallow_Trunk_Full",
      "support": 15
    },
    {
      "x": -5,
      "y": 20,
      "z": -2,
      "name": "Wood_Goldenwood_Planks_Half",
      "rotation": 8
    },
    {
      "x": -5,
      "y": 24,
      "z": -2,
      "name": "Wood_Tropicalwood_Roof_Shallow",
      "filler": 1,
      "rotation": 3
    },
    {
      "x": -5,
      "y": 31,
      "z": -2,
      "name": "Plant_Vine_Liana_End",
      "support": 15,
      "rotation": 3
    },
    {
      "x": -5,
      "y": 32,
      "z": -2,
      "name": "Plant_Vine_Liana",
      "support": 15,
      "rotation": 3
    },
    {
      "x": -5,
      "y": 33,
      "z": -2,
      "name": "Plant_Vine_Liana",
      "support": 15,
      "rotation": 3
    },
    {
      "x": -5,
      "y": 34,
      "z": -2,
      "name": "Plant_Vine_Liana",
      "support": 15,
      "rotation": 3
    },
    {
      "x": -5,
      "y": 35,
      "z": -2,
      "name": "Plant_Vine_Liana",
      "support": 15,
      "rotation": 3
    },
    {
      "x": -5,
      "y": 36,
      "z": -2,
      "name": "Plant_Vine_Liana",
      "support": 15,
      "rotation": 3
    },
    {
      "x": -5,
      "y": 37,
      "z": -2,
      "name": "Plant_Vine_Liana",
      "support": 15,
      "rotation": 3
    },
    {
      "x": -5,
      "y": 38,
      "z": -2,
      "name": "Plant_Vine_Liana",
      "support": 15,
      "rotation": 3
    },
    {
      "x": -5,
      "y": 39,
      "z": -2,
      "name": "Plant_Vine_Liana",
      "support": 15,
      "rotation": 3
    },
    {
      "x": -5,
      "y": 40,
      "z": -2,
      "name": "Plant_Vine_Liana",
      "support": 15,
      "rotation": 3
    },
    {
      "x": -5,
      "y": 41,
      "z": -2,
      "name": "Plant_Vine_Liana",
      "support": 15,
      "rotation": 3
    },
    {
      "x": -5,
      "y": 42,
      "z": -2,
      "name": "Plant_Vine_Liana",
      "support": 15,
      "rotation": 3
    },
    {
      "x": -5,
      "y": 43,
      "z": -2,
      "name": "Plant_Vine_Liana",
      "support": 15,
      "rotation": 3
    },
    {
      "x": -5,
      "y": 44,
      "z": -2,
      "name": "Plant_Vine_Liana",
      "support": 15,
      "rotation": 3
    },
    {
      "x": -5,
      "y": 45,
      "z": -2,
      "name": "Plant_Vine_Liana",
      "support": 15,
      "rotation": 3
    },
    {
      "x": -5,
      "y": 46,
      "z": -2,
      "name": "Plant_Vine_Liana",
      "support": 15,
      "rotation": 3
    },
    {
      "x": -5,
      "y": 47,
      "z": -2,
      "name": "Plant_Vine_Liana",
      "support": 15,
      "rotation": 3
    },
    {
      "x": -5,
      "y": 48,
      "z": -2,
      "name": "Plant_Vine_Liana",
      "support": 15,
      "rotation": 3
    },
    {
      "x": -5,
      "y": 49,
      "z": -2,
      "name": "Plant_Vine_Liana",
      "support": 15,
      "rotation": 3
    },
    {
      "x": -5,
      "y": 50,
      "z": -2,
      "name": "Plant_Vine_Liana",
      "support": 15,
      "rotation": 3
    },
    {
      "x": -5,
      "y": 58,
      "z": -2,
      "name": "Plant_Leaves_Beech",
      "support": 15
    },
    {
      "x": -5,
      "y": 0,
      "z": -1,
      "name": "Wood_Sallow_Trunk",
      "support": 15
    },
    {
      "x": -5,
      "y": 1,
      "z": -1,
      "name": "Wood_Sallow_Trunk",
      "support": 15
    },
    {
      "x": -5,
      "y": 2,
      "z": -1,
      "name": "Wood_Sallow_Trunk",
      "support": 15
    },
    {
      "x": -5,
      "y": 3,
      "z": -1,
      "name": "Wood_Sallow_Trunk",
      "support": 15
    },
    {
      "x": -5,
      "y": 4,
      "z": -1,
      "name": "Wood_Sallow_Trunk_Full",
      "support": 15
    },
    {
      "x": -5,
      "y": 20,
      "z": -1,
      "name": "Wood_Goldenwood_Planks_Half",
      "rotation": 8
    },
    {
      "x": -5,
      "y": 24,
      "z": -1,
      "name": "Wood_Tropicalwood_Roof_Shallow",
      "filler": 1,
      "rotation": 3
    },
    {
      "x": -5,
      "y": 50,
      "z": -1,
      "name": "Wood_Sallow_Trunk_Full",
      "support": 15,
      "rotation": 5
    },
    {
      "x": -5,
      "y": 51,
      "z": -1,
      "name": "Wood_Sallow_Trunk_Full",
      "support": 15
    },
    {
      "x": -5,
      "y": 56,
      "z": -1,
      "name": "Wood_Sallow_Branch_Corner",
      "support": 15,
      "rotation": 24
    },
    {
      "x": -5,
      "y": 0,
      "z": 0,
      "name": "Wood_Sallow_Trunk",
      "support": 15
    },
    {
      "x": -5,
      "y": 1,
      "z": 0,
      "name": "Wood_Sallow_Trunk_Full",
      "support": 15
    },
    {
      "x": -5,
      "y": 2,
      "z": 0,
      "name": "Plant_Moss_Rug_Green_Dark",
      "support": 15
    },
    {
      "x": -5,
      "y": 20,
      "z": 0,
      "name": "Wood_Goldenwood_Planks_Half",
      "rotation": 8
    },
    {
      "x": -5,
      "y": 24,
      "z": 0,
      "name": "Wood_Tropicalwood_Roof_Shallow",
      "filler": 1,
      "rotation": 3
    },
    {
      "x": -5,
      "y": 48,
      "z": 0,
      "name": "Wood_Sallow_Branch_Long",
      "support": 15,
      "rotation": 5
    },
    {
      "x": -5,
      "y": 56,
      "z": 0,
      "name": "Wood_Sallow_Branch_Long",
      "support": 15,
      "rotation": 4
    },
    {
      "x": -5,
      "y": 1,
      "z": 1,
      "name": "Plant_Moss_Wall_Green_Dark",
      "support": 15
    },
    {
      "x": -5,
      "y": 20,
      "z": 1,
      "name": "Furniture_Crude_Platform",
      "rotation": 1
    },
    {
      "x": -5,
      "y": 21,
      "z": 1,
      "name": "*Wood_Softwood_Fence_State_Definitions_Corner"
    },
    {
      "x": -5,
      "y": 24,
      "z": 1,
      "name": "Wood_Tropicalwood_Roof_Shallow",
      "filler": 1,
      "rotation": 3
    },
    {
      "x": -5,
      "y": 55,
      "z": 1,
      "name": "Wood_Sallow_Trunk_Full",
      "support": 15,
      "rotation": 5
    },
    {
      "x": -5,
      "y": 56,
      "z": 1,
      "name": "Wood_Sallow_Trunk_Full",
      "support": 15
    },
    {
      "x": -5,
      "y": 20,
      "z": 2,
      "name": "Furniture_Crude_Platform",
      "rotation": 1
    },
    {
      "x": -5,
      "y": 21,
      "z": 2,
      "name": "Wood_Softwood_Fence",
      "rotation": 3
    },
    {
      "x": -5,
      "y": 24,
      "z": 2,
      "name": "Wood_Tropicalwood_Roof_Shallow",
      "filler": 1,
      "rotation": 3
    },
    {
      "x": -5,
      "y": 49,
      "z": 2,
      "name": "Plant_Leaves_Beech",
      "support": 15
    },
    {
      "x": -5,
      "y": 50,
      "z": 2,
      "name": "Plant_Leaves_Beech",
      "support": 15
    },
    {
      "x": -5,
      "y": 56,
      "z": 2,
      "name": "Wood_Sallow_Branch_Long",
      "support": 15,
      "rotation": 4
    },
    {
      "x": -5,
      "y": 20,
      "z": 3,
      "name": "Furniture_Crude_Platform",
      "rotation": 1
    },
    {
      "x": -5,
      "y": 21,
      "z": 3,
      "name": "*Wood_Softwood_Fence_State_Definitions_Corner",
      "rotation": 2
    },
    {
      "x": -5,
      "y": 22,
      "z": 3,
      "name": "Wood_Softwood_Beam"
    },
    {
      "x": -5,
      "y": 23,
      "z": 3,
      "name": "Wood_Softwood_Beam"
    },
    {
      "x": -5,
      "y": 24,
      "z": 3,
      "name": "*Wood_Tropicalwood_Roof_Shallow_State_Definitions_Corner_Left",
      "filler": 993,
      "rotation": 3
    },
    {
      "x": -5,
      "y": 48,
      "z": 3,
      "name": "Plant_Leaves_Beech",
      "support": 15
    },
    {
      "x": -5,
      "y": 49,
      "z": 3,
      "name": "Wood_Sallow_Branch_Corner",
      "support": 15,
      "rotation": 3
    },
    {
      "x": -5,
      "y": 50,
      "z": 3,
      "name": "Wood_Sallow_Branch_Long",
      "support": 15
    },
    {
      "x": -5,
      "y": 51,
      "z": 3,
      "name": "Plant_Leaves_Beech",
      "support": 15
    },
    {
      "x": -5,
      "y": 55,
      "z": 3,
      "name": "Plant_Leaves_Beech",
      "support": 15
    },
    {
      "x": -5,
      "y": 56,
      "z": 3,
      "name": "Wood_Sallow_Branch_Long",
      "support": 15,
      "rotation": 4
    },
    {
      "x": -5,
      "y": 57,
      "z": 3,
      "name": "Plant_Leaves_Beech",
      "support": 15
    },
    {
      "x": -5,
      "y": 0,
      "z": 4,
      "name": "Wood_Sallow_Trunk",
      "support": 15
    },
    {
      "x": -5,
      "y": 1,
      "z": 4,
      "name": "Wood_Sallow_Trunk",
      "support": 15
    },
    {
      "x": -5,
      "y": 2,
      "z": 4,
      "name": "Wood_Sallow_Trunk",
      "support": 15
    },
    {
      "x": -5,
      "y": 3,
      "z": 4,
      "name": "Wood_Sallow_Trunk_Full",
      "support": 15
    },
    {
      "x": -5,
      "y": 4,
      "z": 4,
      "name": "Plant_Moss_Rug_Green_Dark",
      "support": 15
    },
    {
      "x": -5,
      "y": 24,
      "z": 4,
      "name": "*Wood_Tropicalwood_Roof_Shallow_State_Definitions_Corner_Left",
      "filler": 1,
      "rotation": 3
    },
    {
      "x": -5,
      "y": 49,
      "z": 4,
      "name": "Plant_Leaves_Beech",
      "support": 15
    },
    {
      "x": -5,
      "y": 50,
      "z": 4,
      "name": "Plant_Leaves_Beech",
      "support": 15
    },
    {
      "x": -5,
      "y": 55,
      "z": 4,
      "name": "Plant_Leaves_Beech",
      "support": 15
    },
    {
      "x": -5,
      "y": 56,
      "z": 4,
      "name": "Wood_Sallow_Branch_Corner",
      "support": 15
    },
    {
      "x": -5,
      "y": 57,
      "z": 4,
      "name": "Wood_Sallow_Branch_Long",
      "support": 15
    },
    {
      "x": -5,
      "y": 58,
      "z": 4,
      "name": "Plant_Leaves_Beech",
      "support": 15
    },
    {
      "x": -5,
      "y": 0,
      "z": 5,
      "name": "Wood_Sallow_Trunk",
      "support": 15
    },
    {
      "x": -5,
      "y": 1,
      "z": 5,
      "name": "Wood_Sallow_Trunk",
      "support": 15
    },
    {
      "x": -5,
      "y": 2,
      "z": 5,
      "name": "Wood_Sallow_Trunk",
      "support": 15
    },
    {
      "x": -5,
      "y": 3,
      "z": 5,
      "name": "Wood_Sallow_Trunk_Full",
      "support": 15
    },
    {
      "x": -5,
      "y": 56,
      "z": 5,
      "name": "Plant_Leaves_Beech",
      "support": 15
    },
    {
      "x": -5,
      "y": 57,
      "z": 5,
      "name": "Plant_Leaves_Beech",
      "support": 15
    },
    {
      "x": -5,
      "y": 58,
      "z": 5,
      "name": "Plant_Leaves_Beech",
      "support": 15
    },
    {
      "x": -5,
      "y": 2,
      "z": 6,
      "name": "Plant_Moss_Wall_Green_Dark",
      "support": 15,
      "rotation": 1
    },
    {
      "x": -5,
      "y": 49,
      "z": 6,
      "name": "Plant_Leaves_Beech",
      "support": 15
    },
    {
      "x": -5,
      "y": 50,
      "z": 6,
      "name": "Plant_Leaves_Beech",
      "support": 15
    },
    {
      "x": -5,
      "y": 51,
      "z": 7,
      "name": "Plant_Leaves_Beech",
      "support": 15
    },
    {
      "x": -5,
      "y": 50,
      "z": 8,
      "name": "Plant_Leaves_Beech",
      "support": 15
    },
    {
      "x": -5,
      "y": 51,
      "z": 8,
      "name": "Wood_Sallow_Branch_Long",
      "support": 15,
      "rotation": 5
    },
    {
      "x": -5,
      "y": 52,
      "z": 8,
      "name": "Plant_Leaves_Beech",
      "support": 15
    },
    {
      "x": -5,
      "y": 51,
      "z": 9,
      "name": "Plant_Leaves_Beech",
      "support": 15
    },
    {
      "x": -4,
      "y": 47,
      "z": -11,
      "name": "Plant_Leaves_Beech",
      "support": 15
    },
    {
      "x": -4,
      "y": 52,
      "z": -10,
      "name": "Plant_Leaves_Beech",
      "support": 15
    },
    {
      "x": -4,
      "y": 53,
      "z": -10,
      "name": "Plant_Leaves_Beech",
      "support": 15
    },
    {
      "x": -4,
      "y": 58,
      "z": -10,
      "name": "Plant_Leaves_Beech",
      "support": 15
    },
    {
      "x": -4,
      "y": 59,
      "z": -10,
      "name": "Plant_Leaves_Beech",
      "support": 15
    },
    {
      "x": -4,
      "y": 0,
      "z": -9,
      "name": "Wood_Sallow_Trunk",
      "support": 15
    },
    {
      "x": -4,
      "y": 1,
      "z": -9,
      "name": "Wood_Sallow_Trunk_Full",
      "support": 15
    },
    {
      "x": -4,
      "y": 52,
      "z": -9,
      "name": "Plant_Leaves_Beech",
      "support": 15
    },
    {
      "x": -4,
      "y": 58,
      "z": -9,
      "name": "Plant_Leaves_Beech",
      "support": 15
    },
    {
      "x": -4,
      "y": 0,
      "z": -8,
      "name": "Wood_Sallow_Trunk",
      "support": 15
    },
    {
      "x": -4,
      "y": 1,
      "z": -8,
      "name": "Wood_Sallow_Trunk",
      "support": 15
    },
    {
      "x": -4,
      "y": 2,
      "z": -8,
      "name": "Wood_Sallow_Trunk_Full",
      "support": 15
    },
    {
      "x": -4,
      "y": 3,
      "z": -8,
      "name": "Plant_Moss_Rug_Green_Dark",
      "support": 15
    },
    {
      "x": -4,
      "y": 47,
      "z": -8,
      "name": "Wood_Sallow_Branch_Long",
      "support": 15,
      "rotation": 5
    },
    {
      "x": -4,
      "y": 49,
      "z": -8,
      "name": "Plant_Leaves_Beech",
      "support": 15
    },
    {
      "x": -4,
      "y": 0,
      "z": -7,
      "name": "Wood_Sallow_Trunk",
      "support": 15
    },
    {
      "x": -4,
      "y": 1,
      "z": -7,
      "name": "Wood_Sallow_Trunk_Full",
      "support": 15
    },
    {
      "x": -4,
      "y": 3,
      "z": -7,
      "name": "Plant_Moss_Wall_Green_Dark",
      "support": 15,
      "rotation": 3
    },
    {
      "x": -4,
      "y": 57,
      "z": -7,
      "name": "Wood_Sallow_Trunk_Full",
      "support": 15,
      "rotation": 5
    },
    {
      "x": -4,
      "y": 0,
      "z": -6,
      "name": "Wood_Sallow_Trunk",
      "support": 15
    },
    {
      "x": -4,
      "y": 1,
      "z": -6,
      "name": "Wood_Sallow_Trunk_Full",
      "support": 15
    },
    {
      "x": -4,
      "y": 24,
      "z": -6,
      "name": "Wood_Tropicalwood_Roof_Shallow",
      "rotation": 2
    },
    {
      "x": -4,
      "y": 51,
      "z": -6,
      "name": "Wood_Sallow_Trunk_Full",
      "support": 15,
      "rotation": 4
    },
    {
      "x": -4,
      "y": 54,
      "z": -6,
      "name": "Plant_Leaves_Beech",
      "support": 15
    },
    {
      "x": -4,
      "y": 57,
      "z": -6,
      "name": "Wood_Sallow_Trunk",
      "support": 15,
      "rotation": 4
    },
    {
      "x": -4,
      "y": 59,
      "z": -6,
      "name": "Plant_Leaves_Beech",
      "support": 15
    },
    {
      "x": -4,
      "y": 20,
      "z": -5,
      "name": "Furniture_Crude_Platform"
    },
    {
      "x": -4,
      "y": 21,
      "z": -5,
      "name": "Wood_Softwood_Fence",
      "rotation": 2
    },
    {
      "x": -4,
      "y": 24,
      "z": -5,
      "name": "Wood_Tropicalwood_Roof_Shallow",
      "filler": 32,
      "rotation": 2
    },
    {
      "x": -4,
      "y": 51,
      "z": -5,
      "name": "Wood_Sallow_Trunk",
      "support": 15,
      "rotation": 4
    },
    {
      "x": -4,
      "y": 56,
      "z": -5,
      "name": "Wood_Sallow_Trunk_Full",
      "support": 15
    },
    {
      "x": -4,
      "y": 57,
      "z": -5,
      "name": "Wood_Sallow_Trunk_Full",
      "support": 15,
      "rotation": 4
    },
    {
      "x": -4,
      "y": 58,
      "z": -5,
      "name": "Wood_Sallow_Branch_Long",
      "support": 15
    },
    {
      "x": -4,
      "y": 59,
      "z": -5,
      "name": "Wood_Sallow_Branch_Long",
      "support": 15
    },
    {
      "x": -4,
      "y": 60,
      "z": -5,
      "name": "Plant_Leaves_Beech",
      "support": 15
    },
    {
      "x": -4,
      "y": 0,
      "z": -4,
      "name": "Wood_Sallow_Trunk",
      "support": 15
    },
    {
      "x": -4,
      "y": 1,
      "z": -4,
      "name": "Wood_Sallow_Trunk_Full",
      "support": 15
    },
    {
      "x": -4,
      "y": 20,
      "z": -4,
      "name": "Wood_Goldenwood_Planks_Half",
      "rotation": 8
    },
    {
      "x": -4,
      "y": 25,
      "z": -4,
      "name": "Wood_Tropicalwood_Roof_Flat",
      "rotation": 1
    },
    {
      "x": -4,
      "y": 51,
      "z": -4,
      "name": "Wood_Sallow_Trunk_Full",
      "support": 15,
      "rotation": 5
    },
    {
      "x": -4,
      "y": 56,
      "z": -4,
      "name": "Wood_Sallow_Trunk_Full",
      "support": 15,
      "rotation": 4
    },
    {
      "x": -4,
      "y": 59,
      "z": -4,
      "name": "Plant_Leaves_Beech",
      "support": 15
    },
    {
      "x": -4,
      "y": 0,
      "z": -3,
      "name": "Wood_Sallow_Trunk",
      "support": 15
    },
    {
      "x": -4,
      "y": 1,
      "z": -3,
      "name": "Wood_Sallow_Trunk",
      "support": 15
    },
    {
      "x": -4,
      "y": 2,
      "z": -3,
      "name": "Wood_Sallow_Trunk",
      "support": 15
    },
    {
      "x": -4,
      "y": 3,
      "z": -3,
      "name": "Wood_Sallow_Trunk_Full",
      "support": 15
    },
    {
      "x": -4,
      "y": 20,
      "z": -3,
      "name": "Wood_Goldenwood_Planks_Half",
      "rotation": 8
    },
    {
      "x": -4,
      "y": 25,
      "z": -3,
      "name": "Wood_Tropicalwood_Roof_Flat",
      "rotation": 1
    },
    {
      "x": -4,
      "y": 0,
      "z": -2,
      "name": "Wood_Sallow_Trunk",
      "support": 15
    },
    {
      "x": -4,
      "y": 1,
      "z": -2,
      "name": "Wood_Sallow_Trunk",
      "support": 15
    },
    {
      "x": -4,
      "y": 2,
      "z": -2,
      "name": "Wood_Sallow_Trunk",
      "support": 15
    },
    {
      "x": -4,
      "y": 3,
      "z": -2,
      "name": "Wood_Sallow_Trunk",
      "support": 15
    },
    {
      "x": -4,
      "y": 4,
      "z": -2,
      "name": "Wood_Sallow_Trunk",
      "support": 15
    },
    {
      "x": -4,
      "y": 5,
      "z": -2,
      "name": "Wood_Sallow_Trunk",
      "support": 15
    },
    {
      "x": -4,
      "y": 6,
      "z": -2,
      "name": "Wood_Sallow_Trunk",
      "support": 15
    },
    {
      "x": -4,
      "y": 7,
      "z": -2,
      "name": "Wood_Sallow_Trunk_Full",
      "support": 15
    },
    {
      "x": -4,
      "y": 20,
      "z": -2,
      "name": "Wood_Goldenwood_Planks_Half",
      "rotation": 8
    },
    {
      "x": -4,
      "y": 25,
      "z": -2,
      "name": "Wood_Tropicalwood_Roof_Flat",
      "rotation": 1
    },
    {
      "x": -4,
      "y": 49,
      "z": -2,
      "name": "Wood_Sallow_Trunk_Full",
      "support": 15,
      "rotation": 5
    },
    {
      "x": -4,
      "y": 50,
      "z": -2,
      "name": "Wood_Sallow_Trunk_Full",
      "support": 15
    },
    {
      "x": -4,
      "y": 0,
      "z": -1,
      "name": "Wood_Sallow_Trunk",
      "support": 15
    },
    {
      "x": -4,
      "y": 1,
      "z": -1,
      "name": "Wood_Sallow_Trunk",
      "support": 15
    },
    {
      "x": -4,
      "y": 2,
      "z": -1,
      "name": "Wood_Sallow_Trunk",
      "support": 15
    },
    {
      "x": -4,
      "y": 3,
      "z": -1,
      "name": "Wood_Sallow_Trunk",
      "support": 15
    },
    {
      "x": -4,
      "y": 4,
      "z": -1,
      "name": "Wood_Sallow_Trunk",
      "support": 15
    },
    {
      "x": -4,
      "y": 5,
      "z": -1,
      "name": "Wood_Sallow_Trunk",
      "support": 15
    },
    {
      "x": -4,
      "y": 6,
      "z": -1,
      "name": "Wood_Sallow_Trunk_Full",
      "support": 15
    },
    {
      "x": -4,
      "y": 18,
      "z": -1,
      "name": "Wood_Sallow_Trunk_Half",
      "rotation": 7
    },
    {
      "x": -4,
      "y": 19,
      "z": -1,
      "name": "Wood_Sallow_Trunk",
      "support": 15
    },
    {
      "x": -4,
      "y": 20,
      "z": -1,
      "name": "*Wood_Goldenwood_Planks_Half_State_Definitions_Block",
      "rotation": 8
    },
    {
      "x": -4,
      "y": 25,
      "z": -1,
      "name": "Wood_Tropicalwood_Roof_Flat",
      "rotation": 1
    },
    {
      "x": -4,
      "y": 50,
      "z": -1,
      "name": "Wood_Sallow_Trunk_Full",
      "support": 15,
      "rotation": 4
    },
    {
      "x": -4,
      "y": 0,
      "z": 0,
      "name": "Wood_Sallow_Trunk",
      "support": 15
    },
    {
      "x": -4,
      "y": 1,
      "z": 0,
      "name": "Wood_Sallow_Trunk",
      "support": 15
    },
    {
      "x": -4,
      "y": 2,
      "z": 0,
      "name": "Wood_Sallow_Trunk",
      "support": 15
    },
    {
      "x": -4,
      "y": 3,
      "z": 0,
      "name": "Wood_Sallow_Trunk_Full",
      "support": 15
    },
    {
      "x": -4,
      "y": 4,
      "z": 0,
      "name": "Plant_Moss_Rug_Green_Dark",
      "support": 15
    },
    {
      "x": -4,
      "y": 20,
      "z": 0,
      "name": "Wood_Goldenwood_Planks_Half",
      "rotation": 8
    },
    {
      "x": -4,
      "y": 25,
      "z": 0,
      "name": "Wood_Tropicalwood_Roof_Flat",
      "rotation": 1
    },
    {
      "x": -4,
      "y": 48,
      "z": 0,
      "name": "Wood_Sallow_Branch_Long",
      "support": 15,
      "rotation": 5
    },
    {
      "x": -4,
      "y": 59,
      "z": 0,
      "name": "Plant_Leaves_Beech",
      "support": 15
    },
    {
      "x": -4,
      "y": 60,
      "z": 0,
      "name": "Plant_Leaves_Beech",
      "support": 15
    },
    {
      "x": -4,
      "y": 0,
      "z": 1,
      "name": "Wood_Sallow_Trunk",
      "support": 15
    },
    {
      "x": -4,
      "y": 1,
      "z": 1,
      "name": "Wood_Sallow_Trunk",
      "support": 15
    },
    {
      "x": -4,
      "y": 2,
      "z": 1,
      "name": "Wood_Sallow_Trunk_Full",
      "support": 15
    },
    {
      "x": -4,
      "y": 3,
      "z": 1,
      "name": "Plant_Moss_Rug_Green_Dark",
      "support": 15
    },
    {
      "x": -4,
      "y": 20,
      "z": 1,
      "name": "Wood_Goldenwood_Planks_Half",
      "rotation": 8
    },
    {
      "x": -4,
      "y": 25,
      "z": 1,
      "name": "Wood_Tropicalwood_Roof_Flat",
      "rotation": 1
    },
    {
      "x": -4,
      "y": 55,
      "z": 1,
      "name": "Wood_Sallow_Trunk",
      "support": 15,
      "rotation": 5
    },
    {
      "x": -4,
      "y": 20,
      "z": 2,
      "name": "Wood_Goldenwood_Planks_Half",
      "rotation": 8
    },
    {
      "x": -4,
      "y": 25,
      "z": 2,
      "name": "Wood_Tropicalwood_Roof_Flat",
      "rotation": 1
    },
    {
      "x": -4,
      "y": 49,
      "z": 2,
      "name": "Plant_Leaves_Beech",
      "support": 15
    },
    {
      "x": -4,
      "y": 0,
      "z": 3,
      "name": "Wood_Sallow_Trunk",
      "support": 15
    },
    {
      "x": -4,
      "y": 1,
      "z": 3,
      "name": "Wood_Sallow_Trunk",
      "support": 15
    },
    {
      "x": -4,
      "y": 2,
      "z": 3,
      "name": "Wood_Sallow_Trunk_Full",
      "support": 15
    },
    {
      "x": -4,
      "y": 20,
      "z": 3,
      "name": "Furniture_Crude_Platform"
    },
    {
      "x": -4,
      "y": 21,
      "z": 3,
      "name": "Wood_Softwood_Fence"
    },
    {
      "x": -4,
      "y": 24,
      "z": 3,
      "name": "Wood_Tropicalwood_Roof_Shallow",
      "filler": 992
    },
    {
      "x": -4,
      "y": 49,
      "z": 3,
      "name": "Wood_Sallow_Branch_Long",
      "support": 15,
      "rotation": 5
    },
    {
      "x": -4,
      "y": 50,
      "z": 3,
      "name": "Plant_Leaves_Beech",
      "support": 15
    },
    {
      "x": -4,
      "y": 56,
      "z": 3,
      "name": "Plant_Leaves_Beech",
      "support": 15
    },
    {
      "x": -4,
      "y": 0,
      "z": 4,
      "name": "Wood_Sallow_Trunk",
      "support": 15
    },
    {
      "x": -4,
      "y": 1,
      "z": 4,
      "name": "Wood_Sallow_Trunk",
      "support": 15
    },
    {
      "x": -4,
      "y": 2,
      "z": 4,
      "name": "Wood_Sallow_Trunk",
      "support": 15
    },
    {
      "x": -4,
      "y": 3,
      "z": 4,
      "name": "Wood_Sallow_Trunk",
      "support": 15
    },
    {
      "x": -4,
      "y": 4,
      "z": 4,
      "name": "Wood_Sallow_Trunk_Full",
      "support": 15
    },
    {
      "x": -4,
      "y": 24,
      "z": 4,
      "name": "Wood_Tropicalwood_Roof_Shallow"
    },
    {
      "x": -4,
      "y": 49,
      "z": 4,
      "name": "Plant_Leaves_Beech",
      "support": 15
    },
    {
      "x": -4,
      "y": 52,
      "z": 4,
      "name": "Plant_Leaves_Beech",
      "support": 15
    },
    {
      "x": -4,
      "y": 53,
      "z": 4,
      "name": "Plant_Leaves_Beech",
      "support": 15
    },
    {
      "x": -4,
      "y": 56,
      "z": 4,
      "name": "Plant_Leaves_Beech",
      "support": 15
    },
    {
      "x": -4,
      "y": 57,
      "z": 4,
      "name": "Plant_Leaves_Beech",
      "support": 15
    },
    {
      "x": -4,
      "y": 58,
      "z": 4,
      "name": "Plant_Leaves_Beech",
      "support": 15
    },
    {
      "x": -4,
      "y": 0,
      "z": 5,
      "name": "Wood_Sallow_Trunk",
      "support": 15
    },
    {
      "x": -4,
      "y": 1,
      "z": 5,
      "name": "Wood_Sallow_Trunk",
      "support": 15
    },
    {
      "x": -4,
      "y": 2,
      "z": 5,
      "name": "Wood_Sallow_Trunk",
      "support": 15
    },
    {
      "x": -4,
      "y": 3,
      "z": 5,
      "name": "Wood_Sallow_Trunk",
      "support": 15
    },
    {
      "x": -4,
      "y": 4,
      "z": 5,
      "name": "Wood_Sallow_Trunk_Full",
      "support": 15
    },
    {
      "x": -4,
      "y": 49,
      "z": 5,
      "name": "Plant_Leaves_Beech",
      "support": 15
    },
    {
      "x": -4,
      "y": 50,
      "z": 5,
      "name": "Plant_Leaves_Beech",
      "support": 15
    },
    {
      "x": -4,
      "y": 56,
      "z": 5,
      "name": "Plant_Leaves_Beech",
      "support": 15
    },
    {
      "x": -4,
      "y": 57,
      "z": 5,
      "name": "Wood_Sallow_Branch_Corner",
      "support": 15,
      "rotation": 3
    },
    {
      "x": -4,
      "y": 58,
      "z": 5,
      "name": "Wood_Sallow_Branch_Long",
      "support": 15
    },
    {
      "x": -4,
      "y": 59,
      "z": 5,
      "name": "Plant_Leaves_Beech",
      "support": 15
    },
    {
      "x": -4,
      "y": 48,
      "z": 6,
      "name": "Plant_Leaves_Beech",
      "support": 15
    },
    {
      "x": -4,
      "y": 49,
      "z": 6,
      "name": "Wood_Sallow_Branch_Corner",
      "support": 15,
      "rotation": 3
    },
    {
      "x": -4,
      "y": 50,
      "z": 6,
      "name": "Wood_Sallow_Branch_Long",
      "support": 15
    },
    {
      "x": -4,
      "y": 51,
      "z": 6,
      "name": "Plant_Leaves_Beech",
      "support": 15
    },
    {
      "x": -4,
      "y": 57,
      "z": 6,
      "name": "Plant_Leaves_Beech",
      "support": 15
    },
    {
      "x": -4,
      "y": 58,
      "z": 6,
      "name": "Plant_Leaves_Beech",
      "support": 15
    },
    {
      "x": -4,
      "y": 49,
      "z": 7,
      "name": "Plant_Leaves_Beech",
      "support": 15
    },
    {
      "x": -4,
      "y": 50,
      "z": 7,
      "name": "Plant_Leaves_Beech",
      "support": 15
    },
    {
      "x": -4,
      "y": 51,
      "z": 8,
      "name": "Wood_Sallow_Branch_Long",
      "support": 15,
      "rotation": 5
    },
    {
      "x": -4,
      "y": 51,
      "z": 9,
      "name": "Plant_Leaves_Beech",
      "support": 15
    },
    {
      "x": -4,
      "y": 51,
      "z": 10,
      "name": "Plant_Leaves_Beech",
      "support": 15
    },
    {
      "x": -4,
      "y": 52,
      "z": 10,
      "name": "Plant_Leaves_Beech",
      "support": 15
    },
    {
      "x": -3,
      "y": 46,
      "z": -11,
      "name": "Plant_Leaves_Beech",
      "support": 15
    },
    {
      "x": -3,
      "y": 47,
      "z": -11,
      "name": "Wood_Sallow_Branch_Corner",
      "support": 15,
      "rotation": 2
    },
    {
      "x": -3,
      "y": 48,
      "z": -11,
      "name": "Plant_Leaves_Beech",
      "support": 15
    },
    {
      "x": -3,
      "y": 58,
      "z": -11,
      "name": "Plant_Leaves_Beech",
      "support": 15
    },
    {
      "x": -3,
      "y": 59,
      "z": -11,
      "name": "Plant_Leaves_Beech",
      "support": 15
    },
    {
      "x": -3,
      "y": 46,
      "z": -10,
      "name": "Plant_Leaves_Beech",
      "support": 15
    },
    {
      "x": -3,
      "y": 47,
      "z": -10,
      "name": "Wood_Sallow_Branch_Long",
      "support": 15,
      "rotation": 4
    },
    {
      "x": -3,
      "y": 48,
      "z": -10,
      "name": "Plant_Leaves_Beech",
      "support": 15
    },
    {
      "x": -3,
      "y": 57,
      "z": -10,
      "name": "Plant_Leaves_Beech",
      "support": 15
    },
    {
      "x": -3,
      "y": 58,
      "z": -10,
      "name": "Wood_Sallow_Branch_Corner",
      "support": 15,
      "rotation": 2
    },
    {
      "x": -3,
      "y": 59,
      "z": -10,
      "name": "Wood_Sallow_Branch_Long",
      "support": 15
    },
    {
      "x": -3,
      "y": 60,
      "z": -10,
      "name": "Plant_Leaves_Beech",
      "support": 15
    },
    {
      "x": -3,
      "y": 2,
      "z": -9,
      "name": "Plant_Moss_Wall_Green_Dark",
      "support": 15,
      "rotation": 2
    },
    {
      "x": -3,
      "y": 47,
      "z": -9,
      "name": "Wood_Sallow_Trunk_Full",
      "support": 15,
      "rotation": 4
    },
    {
      "x": -3,
      "y": 49,
      "z": -9,
      "name": "Plant_Leaves_Beech",
      "support": 15
    },
    {
      "x": -3,
      "y": 58,
      "z": -9,
      "name": "Wood_Sallow_Branch_Long",
      "support": 15,
      "rotation": 4
    },
    {
      "x": -3,
      "y": 59,
      "z": -9,
      "name": "Plant_Leaves_Beech",
      "support": 15
    },
    {
      "x": -3,
      "y": 0,
      "z": -8,
      "name": "Wood_Sallow_Trunk",
      "support": 15
    },
    {
      "x": -3,
      "y": 1,
      "z": -8,
      "name": "Wood_Sallow_Trunk",
      "support": 15
    },
    {
      "x": -3,
      "y": 2,
      "z": -8,
      "name": "Wood_Sallow_Trunk_Full",
      "support": 15
    },
    {
      "x": -3,
      "y": 3,
      "z": -8,
      "name": "Plant_Moss_Rug_Green_Dark",
      "support": 15
    },
    {
      "x": -3,
      "y": 47,
      "z": -8,
      "name": "Wood_Sallow_Trunk_Full",
      "support": 15,
      "rotation": 4
    },
    {
      "x": -3,
      "y": 48,
      "z": -8,
      "name": "Wood_Sallow_Branch_Long",
      "support": 15
    },
    {
      "x": -3,
      "y": 49,
      "z": -8,
      "name": "Wood_Sallow_Branch_Long",
      "support": 15
    },
    {
      "x": -3,
      "y": 50,
      "z": -8,
      "name": "Plant_Leaves_Beech",
      "support": 15
    },
    {
      "x": -3,
      "y": 58,
      "z": -8,
      "name": "Wood_Sallow_Branch_Long",
      "support": 15,
      "rotation": 4
    },
    {
      "x": -3,
      "y": 0,
      "z": -7,
      "name": "Wood_Sallow_Trunk",
      "support": 15
    },
    {
      "x": -3,
      "y": 1,
      "z": -7,
      "name": "Wood_Sallow_Trunk",
      "support": 15
    },
    {
      "x": -3,
      "y": 2,
      "z": -7,
      "name": "Wood_Sallow_Trunk",
      "support": 15
    },
    {
      "x": -3,
      "y": 3,
      "z": -7,
      "name": "Wood_Sallow_Trunk_Full",
      "support": 15
    },
    {
      "x": -3,
      "y": 4,
      "z": -7,
      "name": "Plant_Moss_Rug_Green_Dark",
      "support": 15
    },
    {
      "x": -3,
      "y": 49,
      "z": -7,
      "name": "Plant_Leaves_Beech",
      "support": 15
    },
    {
      "x": -3,
      "y": 57,
      "z": -7,
      "name": "Wood_Sallow_Trunk_Full",
      "support": 15,
      "rotation": 5
    },
    {
      "x": -3,
      "y": 58,
      "z": -7,
      "name": "Wood_Sallow_Trunk_Full",
      "support": 15
    },
    {
      "x": -3,
      "y": 0,
      "z": -6,
      "name": "Wood_Sallow_Trunk",
      "support": 15
    },
    {
      "x": -3,
      "y": 1,
      "z": -6,
      "name": "Wood_Sallow_Trunk",
      "support": 15
    },
    {
      "x": -3,
      "y": 2,
      "z": -6,
      "name": "Wood_Sallow_Trunk",
      "support": 15
    },
    {
      "x": -3,
      "y": 3,
      "z": -6,
      "name": "Wood_Sallow_Trunk_Full",
      "support": 15
    },
    {
      "x": -3,
      "y": 20,
      "z": -6,
      "name": "Furniture_Crude_Platform"
    },
    {
      "x": -3,
      "y": 21,
      "z": -6,
      "name": "*Wood_Softwood_Fence_State_Definitions_Corner",
      "rotation": 1
    },
    {
      "x": -3,
      "y": 24,
      "z": -6,
      "name": "Wood_Tropicalwood_Roof_Shallow",
      "rotation": 2
    },
    {
      "x": -3,
      "y": 51,
      "z": -6,
      "name": "Wood_Sallow_Branch_Long",
      "support": 15,
      "rotation": 5
    },
    {
      "x": -3,
      "y": 0,
      "z": -5,
      "name": "Wood_Sallow_Trunk",
      "support": 15
    },
    {
      "x": -3,
      "y": 1,
      "z": -5,
      "name": "Wood_Sallow_Trunk",
      "support": 15
    },
    {
      "x": -3,
      "y": 2,
      "z": -5,
      "name": "Wood_Sallow_Trunk_Full",
      "support": 15
    },
    {
      "x": -3,
      "y": 20,
      "z": -5,
      "name": "Furniture_Crude_Platform"
    },
    {
      "x": -3,
      "y": 21,
      "z": -5,
      "name": "*Wood_Softwood_Fence_State_Definitions_Corner",
      "rotation": 3
    },
    {
      "x": -3,
      "y": 24,
      "z": -5,
      "name": "Wood_Tropicalwood_Roof_Shallow",
      "filler": 32,
      "rotation": 2
    },
    {
      "x": -3,
      "y": 59,
      "z": -5,
      "name": "Plant_Leaves_Beech",
      "support": 15
    },
    {
      "x": -3,
      "y": 0,
      "z": -4,
      "name": "Wood_Sallow_Trunk",
      "support": 15
    },
    {
      "x": -3,
      "y": 1,
      "z": -4,
      "name": "Wood_Sallow_Trunk",
      "support": 15
    },
    {
      "x": -3,
      "y": 2,
      "z": -4,
      "name": "Wood_Sallow_Trunk",
      "support": 15
    },
    {
      "x": -3,
      "y": 3,
      "z": -4,
      "name": "Wood_Sallow_Trunk_Full",
      "support": 15
    },
    {
      "x": -3,
      "y": 20,
      "z": -4,
      "name": "Wood_Goldenwood_Planks_Half",
      "rotation": 8
    },
    {
      "x": -3,
      "y": 25,
      "z": -4,
      "name": "Wood_Tropicalwood_Roof_Flat"
    },
    {
      "x": -3,
      "y": 55,
      "z": -4,
      "name": "Wood_Sallow_Trunk_Full",
      "support": 15,
      "rotation": 4
    },
    {
      "x": -3,
      "y": 56,
      "z": -4,
      "name": "Wood_Sallow_Trunk_Full",
      "support": 15,
      "rotation": 5
    },
    {
      "x": -3,
      "y": 0,
      "z": -3,
      "name": "Wood_Sallow_Trunk",
      "support": 15
    },
    {
      "x": -3,
      "y": 1,
      "z": -3,
      "name": "Wood_Sallow_Trunk",
      "support": 15
    },
    {
      "x": -3,
      "y": 2,
      "z": -3,
      "name": "Wood_Sallow_Trunk",
      "support": 15
    },
    {
      "x": -3,
      "y": 3,
      "z": -3,
      "name": "Wood_Sallow_Trunk",
      "support": 15
    },
    {
      "x": -3,
      "y": 4,
      "z": -3,
      "name": "Wood_Sallow_Trunk",
      "support": 15
    },
    {
      "x": -3,
      "y": 5,
      "z": -3,
      "name": "Wood_Sallow_Trunk_Full",
      "support": 15
    },
    {
      "x": -3,
      "y": 6,
      "z": -3,
      "name": "Plant_Moss_Rug_Green_Dark",
      "support": 15
    },
    {
      "x": -3,
      "y": 7,
      "z": -3,
      "name": "Plant_Moss_Wall_Green_Dark",
      "support": 15,
      "rotation": 3
    },
    {
      "x": -3,
      "y": 20,
      "z": -3,
      "name": "Wood_Goldenwood_Planks_Half",
      "rotation": 8
    },
    {
      "x": -3,
      "y": 25,
      "z": -3,
      "name": "Wood_Tropicalwood_Roof_Flat",
      "rotation": 3
    },
    {
      "x": -3,
      "y": 50,
      "z": -3,
      "name": "Wood_Sallow_Trunk_Full",
      "support": 15,
      "rotation": 4
    },
    {
      "x": -3,
      "y": 51,
      "z": -3,
      "name": "Wood_Sallow_Trunk_Full",
      "support": 15
    },
    {
      "x": -3,
      "y": 54,
      "z": -3,
      "name": "Wood_Sallow_Trunk_Full",
      "support": 15
    },
    {
      "x": -3,
      "y": 55,
      "z": -3,
      "name": "Wood_Sallow_Trunk_Full",
      "support": 15,
      "rotation": 4
    },
    {
      "x": -3,
      "y": 0,
      "z": -2,
      "name": "Wood_Sallow_Trunk",
      "support": 15
    },
    {
      "x": -3,
      "y": 1,
      "z": -2,
      "name": "Wood_Sallow_Trunk",
      "support": 15
    },
    {
      "x": -3,
      "y": 2,
      "z": -2,
      "name": "Wood_Sallow_Trunk",
      "support": 15
    },
    {
      "x": -3,
      "y": 3,
      "z": -2,
      "name": "Wood_Sallow_Trunk",
      "support": 15
    },
    {
      "x": -3,
      "y": 4,
      "z": -2,
      "name": "Wood_Sallow_Trunk",
      "support": 15
    },
    {
      "x": -3,
      "y": 5,
      "z": -2,
      "name": "Wood_Sallow_Trunk",
      "support": 15
    },
    {
      "x": -3,
      "y": 6,
      "z": -2,
      "name": "Wood_Sallow_Trunk",
      "support": 15
    },
    {
      "x": -3,
      "y": 7,
      "z": -2,
      "name": "Wood_Sallow_Trunk",
      "support": 15
    },
    {
      "x": -3,
      "y": 8,
      "z": -2,
      "name": "Wood_Sallow_Trunk",
      "support": 15
    },
    {
      "x": -3,
      "y": 9,
      "z": -2,
      "name": "Wood_Sallow_Trunk",
      "support": 15
    },
    {
      "x": -3,
      "y": 10,
      "z": -2,
      "name": "Wood_Sallow_Trunk_Full",
      "support": 15
    },
    {
      "x": -3,
      "y": 20,
      "z": -2,
      "name": "Wood_Goldenwood_Planks_Half",
      "rotation": 8
    },
    {
      "x": -3,
      "y": 25,
      "z": -2,
      "name": "Wood_Tropicalwood_Roof_Flat",
      "rotation": 3
    },
    {
      "x": -3,
      "y": 48,
      "z": -2,
      "name": "Wood_Sallow_Trunk_Full",
      "support": 15,
      "rotation": 5
    },
    {
      "x": -3,
      "y": 49,
      "z": -2,
      "name": "Wood_Sallow_Trunk",
      "support": 15
    },
    {
      "x": -3,
      "y": 50,
      "z": -2,
      "name": "Wood_Sallow_Trunk_Full",
      "support": 15
    },
    {
      "x": -3,
      "y": 0,
      "z": -1,
      "name": "Wood_Sallow_Trunk",
      "support": 15
    },
    {
      "x": -3,
      "y": 1,
      "z": -1,
      "name": "Wood_Sallow_Trunk",
      "support": 15
    },
    {
      "x": -3,
      "y": 2,
      "z": -1,
      "name": "Wood_Sallow_Trunk",
      "support": 15
    },
    {
      "x": -3,
      "y": 3,
      "z": -1,
      "name": "Wood_Sallow_Trunk",
      "support": 15
    },
    {
      "x": -3,
      "y": 4,
      "z": -1,
      "name": "Wood_Sallow_Trunk",
      "support": 15
    },
    {
      "x": -3,
      "y": 5,
      "z": -1,
      "name": "Wood_Sallow_Trunk",
      "support": 15
    },
    {
      "x": -3,
      "y": 6,
      "z": -1,
      "name": "Wood_Sallow_Trunk",
      "support": 15
    },
    {
      "x": -3,
      "y": 7,
      "z": -1,
      "name": "Wood_Sallow_Trunk",
      "support": 15
    },
    {
      "x": -3,
      "y": 8,
      "z": -1,
      "name": "Wood_Sallow_Trunk",
      "support": 15
    },
    {
      "x": -3,
      "y": 9,
      "z": -1,
      "name": "Wood_Sallow_Trunk",
      "support": 15
    },
    {
      "x": -3,
      "y": 10,
      "z": -1,
      "name": "Wood_Sallow_Trunk",
      "support": 15
    },
    {
      "x": -3,
      "y": 11,
      "z": -1,
      "name": "Wood_Sallow_Trunk",
      "support": 15
    },
    {
      "x": -3,
      "y": 12,
      "z": -1,
      "name": "Wood_Sallow_Trunk",
      "support": 15
    },
    {
      "x": -3,
      "y": 13,
      "z": -1,
      "name": "Wood_Sallow_Trunk_Full",
      "support": 15
    },
    {
      "x": -3,
      "y": 17,
      "z": -1,
      "name": "Wood_Sallow_Trunk_Half",
      "rotation": 7
    },
    {
      "x": -3,
      "y": 18,
      "z": -1,
      "name": "Wood_Sallow_Trunk",
      "support": 15,
      "rotation": 5
    },
    {
      "x": -3,
      "y": 19,
      "z": -1,
      "name": "Wood_Sallow_Trunk_Half",
      "rotation": 5
    },
    {
      "x": -3,
      "y": 20,
      "z": -1,
      "name": "Wood_Goldenwood_Planks_Half",
      "rotation": 8
    },
    {
      "x": -3,
      "y": 25,
      "z": -1,
      "name": "Wood_Tropicalwood_Roof_Flat",
      "rotation": 3
    },
    {
      "x": -3,
      "y": 39,
      "z": -1,
      "name": "Wood_Sallow_Branch_Short",
      "support": 15,
      "rotation": 3
    },
    {
      "x": -3,
      "y": 46,
      "z": -1,
      "name": "Wood_Sallow_Branch_Short",
      "support": 15,
      "rotation": 3
    },
    {
      "x": -3,
      "y": 59,
      "z": -1,
      "name": "Plant_Leaves_Beech",
      "support": 15
    },
    {
      "x": -3,
      "y": 60,
      "z": -1,
      "name": "Plant_Leaves_Beech",
      "support": 15
    },
    {
      "x": -3,
      "y": 0,
      "z": 0,
      "name": "Wood_Sallow_Trunk",
      "support": 15
    },
    {
      "x": -3,
      "y": 1,
      "z": 0,
      "name": "Wood_Sallow_Trunk",
      "support": 15
    },
    {
      "x": -3,
      "y": 2,
      "z": 0,
      "name": "Wood_Sallow_Trunk",
      "support": 15
    },
    {
      "x": -3,
      "y": 3,
      "z": 0,
      "name": "Wood_Sallow_Trunk",
      "support": 15
    },
    {
      "x": -3,
      "y": 4,
      "z": 0,
      "name": "Wood_Sallow_Trunk",
      "support": 15
    },
    {
      "x": -3,
      "y": 5,
      "z": 0,
      "name": "Wood_Sallow_Trunk",
      "support": 15
    },
    {
      "x": -3,
      "y": 6,
      "z": 0,
      "name": "Wood_Sallow_Trunk",
      "support": 15
    },
    {
      "x": -3,
      "y": 7,
      "z": 0,
      "name": "Wood_Sallow_Trunk",
      "support": 15
    },
    {
      "x": -3,
      "y": 8,
      "z": 0,
      "name": "Wood_Sallow_Trunk",
      "support": 15
    },
    {
      "x": -3,
      "y": 9,
      "z": 0,
      "name": "Wood_Sallow_Trunk",
      "support": 15
    },
    {
      "x": -3,
      "y": 10,
      "z": 0,
      "name": "Wood_Sallow_Trunk",
      "support": 15
    },
    {
      "x": -3,
      "y": 11,
      "z": 0,
      "name": "Wood_Sallow_Trunk_Full",
      "support": 15
    },
    {
      "x": -3,
      "y": 20,
      "z": 0,
      "name": "Wood_Goldenwood_Planks_Half",
      "rotation": 8
    },
    {
      "x": -3,
      "y": 25,
      "z": 0,
      "name": "Wood_Tropicalwood_Roof_Flat",
      "rotation": 3
    },
    {
      "x": -3,
      "y": 33,
      "z": 0,
      "name": "Wood_Sallow_Branch_Short",
      "support": 15,
      "rotation": 3
    },
    {
      "x": -3,
      "y": 45,
      "z": 0,
      "name": "Wood_Sallow_Trunk_Full",
      "support": 15
    },
    {
      "x": -3,
      "y": 46,
      "z": 0,
      "name": "Wood_Sallow_Trunk",
      "support": 15
    },
    {
      "x": -3,
      "y": 47,
      "z": 0,
      "name": "Wood_Sallow_Trunk",
      "support": 15
    },
    {
      "x": -3,
      "y": 48,
      "z": 0,
      "name": "Wood_Sallow_Trunk",
      "support": 15
    },
    {
      "x": -3,
      "y": 49,
      "z": 0,
      "name": "Wood_Sallow_Trunk_Full",
      "support": 15
    },
    {
      "x": -3,
      "y": 54,
      "z": 0,
      "name": "Wood_Sallow_Trunk_Full",
      "support": 15,
      "rotation": 5
    },
    {
      "x": -3,
      "y": 55,
      "z": 0,
      "name": "Wood_Sallow_Trunk_Full",
      "support": 15
    },
    {
      "x": -3,
      "y": 58,
      "z": 0,
      "name": "Wood_Sallow_Branch_Corner",
      "support": 15,
      "rotation": 2
    },
    {
      "x": -3,
      "y": 59,
      "z": 0,
      "name": "Wood_Sallow_Branch_Long",
      "support": 15
    },
    {
      "x": -3,
      "y": 60,
      "z": 0,
      "name": "Wood_Sallow_Branch_Long",
      "support": 15
    },
    {
      "x": -3,
      "y": 61,
      "z": 0,
      "name": "Plant_Leaves_Beech",
      "support": 15
    },
    {
      "x": -3,
      "y": 0,
      "z": 1,
      "name": "Wood_Sallow_Trunk",
      "support": 15
    },
    {
      "x": -3,
      "y": 1,
      "z": 1,
      "name": "Wood_Sallow_Trunk",
      "support": 15
    },
    {
      "x": -3,
      "y": 2,
      "z": 1,
      "name": "Wood_Sallow_Trunk",
      "support": 15
    },
    {
      "x": -3,
      "y": 3,
      "z": 1,
      "name": "Wood_Sallow_Trunk",
      "support": 15
    },
    {
      "x": -3,
      "y": 4,
      "z": 1,
      "name": "Wood_Sallow_Trunk",
      "support": 15
    },
    {
      "x": -3,
      "y": 5,
      "z": 1,
      "name": "Wood_Sallow_Trunk",
      "support": 15
    },
    {
      "x": -3,
      "y": 6,
      "z": 1,
      "name": "Wood_Sallow_Trunk",
      "support": 15
    },
    {
      "x": -3,
      "y": 7,
      "z": 1,
      "name": "Wood_Sallow_Trunk",
      "support": 15
    },
    {
      "x": -3,
      "y": 8,
      "z": 1,
      "name": "Wood_Sallow_Trunk_Full",
      "support": 15
    },
    {
      "x": -3,
      "y": 9,
      "z": 1,
      "name": "Plant_Moss_Rug_Green_Dark",
      "support": 15
    },
    {
      "x": -3,
      "y": 20,
      "z": 1,
      "name": "Wood_Goldenwood_Planks_Half",
      "rotation": 8
    },
    {
      "x": -3,
      "y": 25,
      "z": 1,
      "name": "Wood_Tropicalwood_Roof_Flat",
      "rotation": 3
    },
    {
      "x": -3,
      "y": 47,
      "z": 1,
      "name": "Wood_Sallow_Trunk_Full",
      "support": 15
    },
    {
      "x": -3,
      "y": 48,
      "z": 1,
      "name": "Wood_Sallow_Trunk",
      "support": 15
    },
    {
      "x": -3,
      "y": 49,
      "z": 1,
      "name": "Wood_Sallow_Trunk_Full",
      "support": 15
    },
    {
      "x": -3,
      "y": 55,
      "z": 1,
      "name": "Wood_Sallow_Trunk_Full",
      "support": 15,
      "rotation": 4
    },
    {
      "x": -3,
      "y": 56,
      "z": 1,
      "name": "Wood_Sallow_Branch_Long",
      "support": 15
    },
    {
      "x": -3,
      "y": 57,
      "z": 1,
      "name": "Wood_Sallow_Branch_Long",
      "support": 15
    },
    {
      "x": -3,
      "y": 58,
      "z": 1,
      "name": "Wood_Sallow_Branch_Corner",
      "support": 15,
      "rotation": 12
    },
    {
      "x": -3,
      "y": 59,
      "z": 1,
      "name": "Plant_Leaves_Beech",
      "support": 15
    },
    {
      "x": -3,
      "y": 60,
      "z": 1,
      "name": "Plant_Leaves_Beech",
      "support": 15
    },
    {
      "x": -3,
      "y": 0,
      "z": 2,
      "name": "Wood_Sallow_Trunk",
      "support": 15
    },
    {
      "x": -3,
      "y": 1,
      "z": 2,
      "name": "Wood_Sallow_Trunk",
      "support": 15
    },
    {
      "x": -3,
      "y": 2,
      "z": 2,
      "name": "Wood_Sallow_Trunk",
      "support": 15
    },
    {
      "x": -3,
      "y": 3,
      "z": 2,
      "name": "Wood_Sallow_Trunk",
      "support": 15
    },
    {
      "x": -3,
      "y": 4,
      "z": 2,
      "name": "Wood_Sallow_Trunk",
      "support": 15
    },
    {
      "x": -3,
      "y": 5,
      "z": 2,
      "name": "Wood_Sallow_Trunk",
      "support": 15
    },
    {
      "x": -3,
      "y": 6,
      "z": 2,
      "name": "Wood_Sallow_Trunk_Full",
      "support": 15
    },
    {
      "x": -3,
      "y": 7,
      "z": 2,
      "name": "Plant_Moss_Rug_Green_Dark",
      "support": 15
    },
    {
      "x": -3,
      "y": 20,
      "z": 2,
      "name": "Wood_Goldenwood_Planks_Half",
      "rotation": 8
    },
    {
      "x": -3,
      "y": 25,
      "z": 2,
      "name": "Wood_Tropicalwood_Roof_Flat",
      "rotation": 2
    },
    {
      "x": -3,
      "y": 57,
      "z": 2,
      "name": "Plant_Leaves_Beech",
      "support": 15
    },
    {
      "x": -3,
      "y": 0,
      "z": 3,
      "name": "Wood_Sallow_Trunk",
      "support": 15
    },
    {
      "x": -3,
      "y": 1,
      "z": 3,
      "name": "Wood_Sallow_Trunk",
      "support": 15
    },
    {
      "x": -3,
      "y": 2,
      "z": 3,
      "name": "Wood_Sallow_Trunk",
      "support": 15
    },
    {
      "x": -3,
      "y": 3,
      "z": 3,
      "name": "Wood_Sallow_Trunk",
      "support": 15
    },
    {
      "x": -3,
      "y": 4,
      "z": 3,
      "name": "Wood_Sallow_Trunk",
      "support": 15
    },
    {
      "x": -3,
      "y": 5,
      "z": 3,
      "name": "Wood_Sallow_Trunk",
      "support": 15
    },
    {
      "x": -3,
      "y": 6,
      "z": 3,
      "name": "Wood_Sallow_Trunk_Full",
      "support": 15
    },
    {
      "x": -3,
      "y": 7,
      "z": 3,
      "name": "Plant_Moss_Rug_Green_Dark",
      "support": 15
    },
    {
      "x": -3,
      "y": 20,
      "z": 3,
      "name": "Furniture_Crude_Platform"
    },
    {
      "x": -3,
      "y": 21,
      "z": 3,
      "name": "*Wood_Softwood_Fence_State_Definitions_Corner"
    },
    {
      "x": -3,
      "y": 24,
      "z": 3,
      "name": "Wood_Tropicalwood_Roof_Shallow",
      "filler": 992
    },
    {
      "x": -3,
      "y": 49,
      "z": 3,
      "name": "Wood_Sallow_Branch_Long",
      "support": 15,
      "rotation": 5
    },
    {
      "x": -3,
      "y": 52,
      "z": 3,
      "name": "Plant_Leaves_Beech",
      "support": 15
    },
    {
      "x": -3,
      "y": 53,
      "z": 3,
      "name": "Plant_Leaves_Beech",
      "support": 15
    },
    {
      "x": -3,
      "y": 0,
      "z": 4,
      "name": "Wood_Sallow_Trunk",
      "support": 15
    },
    {
      "x": -3,
      "y": 1,
      "z": 4,
      "name": "Wood_Sallow_Trunk",
      "support": 15
    },
    {
      "x": -3,
      "y": 2,
      "z": 4,
      "name": "Wood_Sallow_Trunk",
      "support": 15
    },
    {
      "x": -3,
      "y": 3,
      "z": 4,
      "name": "Wood_Sallow_Trunk",
      "support": 15
    },
    {
      "x": -3,
      "y": 4,
      "z": 4,
      "name": "Wood_Sallow_Trunk",
      "support": 15
    },
    {
      "x": -3,
      "y": 5,
      "z": 4,
      "name": "Wood_Sallow_Trunk_Full",
      "support": 15
    },
    {
      "x": -3,
      "y": 20,
      "z": 4,
      "name": "Furniture_Crude_Platform"
    },
    {
      "x": -3,
      "y": 21,
      "z": 4,
      "name": "*Wood_Softwood_Fence_State_Definitions_Corner",
      "rotation": 2
    },
    {
      "x": -3,
      "y": 24,
      "z": 4,
      "name": "Wood_Tropicalwood_Roof_Shallow"
    },
    {
      "x": -3,
      "y": 51,
      "z": 4,
      "name": "Plant_Leaves_Beech",
      "support": 15
    },
    {
      "x": -3,
      "y": 52,
      "z": 4,
      "name": "Wood_Sallow_Branch_Corner",
      "support": 15,
      "rotation": 3
    },
    {
      "x": -3,
      "y": 53,
      "z": 4,
      "name": "Wood_Sallow_Branch_Long",
      "support": 15
    },
    {
      "x": -3,
      "y": 54,
      "z": 4,
      "name": "Plant_Leaves_Beech",
      "support": 15
    },
    {
      "x": -3,
      "y": 57,
      "z": 4,
      "name": "Plant_Leaves_Beech",
      "support": 15
    },
    {
      "x": -3,
      "y": 52,
      "z": 5,
      "name": "Plant_Leaves_Beech",
      "support": 15
    },
    {
      "x": -3,
      "y": 53,
      "z": 5,
      "name": "Plant_Leaves_Beech",
      "support": 15
    },
    {
      "x": -3,
      "y": 57,
      "z": 5,
      "name": "Wood_Sallow_Branch_Long",
      "support": 15,
      "rotation": 5
    },
    {
      "x": -3,
      "y": 58,
      "z": 5,
      "name": "Plant_Leaves_Beech",
      "support": 15
    },
    {
      "x": -3,
      "y": 49,
      "z": 6,
      "name": "Wood_Sallow_Branch_Long",
      "support": 15,
      "rotation": 5
    },
    {
      "x": -3,
      "y": 50,
      "z": 6,
      "name": "Plant_Leaves_Beech",
      "support": 15
    },
    {
      "x": -3,
      "y": 57,
      "z": 6,
      "name": "Plant_Leaves_Beech",
      "support": 15
    },
    {
      "x": -3,
      "y": 51,
      "z": 7,
      "name": "Wood_Sallow_Trunk_Full",
      "support": 15,
      "rotation": 5
    },
    {
      "x": -3,
      "y": 52,
      "z": 7,
      "name": "Wood_Sallow_Branch_Long",
      "support": 15
    },
    {
      "x": -3,
      "y": 53,
      "z": 7,
      "name": "Wood_Sallow_Branch_Long",
      "support": 15
    },
    {
      "x": -3,
      "y": 54,
      "z": 7,
      "name": "Wood_Sallow_Branch_Corner",
      "support": 15,
      "rotation": 15
    },
    {
      "x": -3,
      "y": 51,
      "z": 8,
      "name": "Wood_Sallow_Trunk_Full",
      "support": 15,
      "rotation": 4
    },
    {
      "x": -3,
      "y": 54,
      "z": 8,
      "name": "Plant_Leaves_Beech",
      "support": 15
    },
    {
      "x": -3,
      "y": 51,
      "z": 9,
      "name": "Wood_Sallow_Branch_Long",
      "support": 15,
      "rotation": 4
    },
    {
      "x": -3,
      "y": 52,
      "z": 9,
      "name": "Plant_Leaves_Beech",
      "support": 15
    },
    {
      "x": -3,
      "y": 50,
      "z": 10,
      "name": "Plant_Leaves_Beech",
      "support": 15
    },
    {
      "x": -3,
      "y": 51,
      "z": 10,
      "name": "Wood_Sallow_Branch_Corner",
      "support": 15
    },
    {
      "x": -3,
      "y": 52,
      "z": 10,
      "name": "Wood_Sallow_Branch_Long",
      "support": 15
    },
    {
      "x": -3,
      "y": 53,
      "z": 10,
      "name": "Plant_Leaves_Beech",
      "support": 15
    },
    {
      "x": -3,
      "y": 51,
      "z": 11,
      "name": "Plant_Leaves_Beech",
      "support": 15
    },
    {
      "x": -3,
      "y": 52,
      "z": 11,
      "name": "Plant_Leaves_Beech",
      "support": 15
    },
    {
      "x": -2,
      "y": 47,
      "z": -11,
      "name": "Plant_Leaves_Beech",
      "support": 15
    },
    {
      "x": -2,
      "y": 47,
      "z": -10,
      "name": "Plant_Leaves_Beech",
      "support": 15
    },
    {
      "x": -2,
      "y": 58,
      "z": -10,
      "name": "Plant_Leaves_Beech",
      "support": 15
    },
    {
      "x": -2,
      "y": 59,
      "z": -10,
      "name": "Plant_Leaves_Beech",
      "support": 15
    },
    {
      "x": -2,
      "y": 58,
      "z": -9,
      "name": "Plant_Leaves_Beech",
      "support": 15
    },
    {
      "x": -2,
      "y": 46,
      "z": -8,
      "name": "Wood_Sallow_Trunk_Full",
      "support": 15,
      "rotation": 4
    },
    {
      "x": -2,
      "y": 47,
      "z": -8,
      "name": "Wood_Sallow_Trunk_Full",
      "support": 15
    },
    {
      "x": -2,
      "y": 49,
      "z": -8,
      "name": "Plant_Leaves_Beech",
      "support": 15
    },
    {
      "x": -2,
      "y": 0,
      "z": -7,
      "name": "Wood_Sallow_Trunk",
      "support": 15
    },
    {
      "x": -2,
      "y": 1,
      "z": -7,
      "name": "Wood_Sallow_Trunk_Full",
      "support": 15
    },
    {
      "x": -2,
      "y": 3,
      "z": -7,
      "name": "Plant_Moss_Wall_Green_Dark",
      "support": 15,
      "rotation": 1
    },
    {
      "x": -2,
      "y": 20,
      "z": -7,
      "name": "Plant_Moss_Wall_Green_Dark",
      "support": 15,
      "rotation": 2
    },
    {
      "x": -2,
      "y": 46,
      "z": -7,
      "name": "Wood_Sallow_Trunk",
      "support": 15,
      "rotation": 4
    },
    {
      "x": -2,
      "y": 51,
      "z": -7,
      "name": "Plant_Leaves_Beech",
      "support": 15
    },
    {
      "x": -2,
      "y": 58,
      "z": -7,
      "name": "Wood_Sallow_Branch_Long",
      "support": 15,
      "rotation": 5
    },
    {
      "x": -2,
      "y": 59,
      "z": -7,
      "name": "Plant_Leaves_Beech",
      "support": 15
    },
    {
      "x": -2,
      "y": 0,
      "z": -6,
      "name": "Wood_Sallow_Trunk",
      "support": 15
    },
    {
      "x": -2,
      "y": 1,
      "z": -6,
      "name": "Wood_Sallow_Trunk",
      "support": 15
    },
    {
      "x": -2,
      "y": 2,
      "z": -6,
      "name": "Wood_Sallow_Trunk",
      "support": 15
    },
    {
      "x": -2,
      "y": 3,
      "z": -6,
      "name": "Wood_Sallow_Trunk",
      "support": 15
    },
    {
      "x": -2,
      "y": 4,
      "z": -6,
      "name": "Wood_Sallow_Trunk_Full",
      "support": 15
    },
    {
      "x": -2,
      "y": 20,
      "z": -6,
      "name": "Furniture_Crude_Platform"
    },
    {
      "x": -2,
      "y": 21,
      "z": -6,
      "name": "Wood_Softwood_Fence",
      "rotation": 2
    },
    {
      "x": -2,
      "y": 24,
      "z": -6,
      "name": "Wood_Tropicalwood_Roof_Shallow",
      "rotation": 2
    },
    {
      "x": -2,
      "y": 46,
      "z": -6,
      "name": "Wood_Sallow_Trunk",
      "support": 15,
      "rotation": 4
    },
    {
      "x": -2,
      "y": 50,
      "z": -6,
      "name": "Plant_Leaves_Beech",
      "support": 15
    },
    {
      "x": -2,
      "y": 51,
      "z": -6,
      "name": "Wood_Sallow_Branch_Long",
      "support": 15,
      "rotation": 5
    },
    {
      "x": -2,
      "y": 52,
      "z": -6,
      "name": "Plant_Leaves_Beech",
      "support": 15
    },
    {
      "x": -2,
      "y": 58,
      "z": -6,
      "name": "Plant_Leaves_Beech",
      "support": 15
    },
    {
      "x": -2,
      "y": 0,
      "z": -5,
      "name": "Wood_Sallow_Trunk",
      "support": 15
    },
    {
      "x": -2,
      "y": 1,
      "z": -5,
      "name": "Wood_Sallow_Trunk",
      "support": 15
    },
    {
      "x": -2,
      "y": 2,
      "z": -5,
      "name": "Wood_Sallow_Trunk",
      "support": 15
    },
    {
      "x": -2,
      "y": 3,
      "z": -5,
      "name": "Wood_Sallow_Trunk",
      "support": 15
    },
    {
      "x": -2,
      "y": 4,
      "z": -5,
      "name": "Wood_Sallow_Trunk_Full",
      "support": 15
    },
    {
      "x": -2,
      "y": 20,
      "z": -5,
      "name": "Wood_Goldenwood_Planks_Half",
      "rotation": 8
    },
    {
      "x": -2,
      "y": 24,
      "z": -5,
      "name": "Wood_Tropicalwood_Roof_Shallow",
      "filler": 32,
      "rotation": 2
    },
    {
      "x": -2,
      "y": 46,
      "z": -5,
      "name": "Wood_Sallow_Trunk_Full",
      "support": 15,
      "rotation": 4
    },
    {
      "x": -2,
      "y": 51,
      "z": -5,
      "name": "Plant_Leaves_Beech",
      "support": 15
    },
    {
      "x": -2,
      "y": 0,
      "z": -4,
      "name": "Wood_Sallow_Trunk",
      "support": 15
    },
    {
      "x": -2,
      "y": 1,
      "z": -4,
      "name": "Wood_Sallow_Trunk",
      "support": 15
    },
    {
      "x": -2,
      "y": 2,
      "z": -4,
      "name": "Wood_Sallow_Trunk",
      "support": 15
    },
    {
      "x": -2,
      "y": 3,
      "z": -4,
      "name": "Wood_Sallow_Trunk",
      "support": 15
    },
    {
      "x": -2,
      "y": 4,
      "z": -4,
      "name": "Wood_Sallow_Trunk",
      "support": 15
    },
    {
      "x": -2,
      "y": 5,
      "z": -4,
      "name": "Wood_Sallow_Trunk_Full",
      "support": 15
    },
    {
      "x": -2,
      "y": 6,
      "z": -4,
      "name": "Plant_Moss_Rug_Green_Dark",
      "support": 15
    },
    {
      "x": -2,
      "y": 7,
      "z": -4,
      "name": "Plant_Moss_Wall_Green_Dark",
      "support": 15,
      "rotation": 2
    },
    {
      "x": -2,
      "y": 20,
      "z": -4,
      "name": "Wood_Goldenwood_Planks_Half",
      "rotation": 8
    },
    {
      "x": -2,
      "y": 25,
      "z": -4,
      "name": "Wood_Tropicalwood_Roof_Flat"
    },
    {
      "x": -2,
      "y": 0,
      "z": -3,
      "name": "Wood_Sallow_Trunk",
      "support": 15
    },
    {
      "x": -2,
      "y": 1,
      "z": -3,
      "name": "Wood_Sallow_Trunk",
      "support": 15
    },
    {
      "x": -2,
      "y": 2,
      "z": -3,
      "name": "Wood_Sallow_Trunk",
      "support": 15
    },
    {
      "x": -2,
      "y": 3,
      "z": -3,
      "name": "Wood_Sallow_Trunk",
      "support": 15
    },
    {
      "x": -2,
      "y": 4,
      "z": -3,
      "name": "Wood_Sallow_Trunk",
      "support": 15
    },
    {
      "x": -2,
      "y": 5,
      "z": -3,
      "name": "Wood_Sallow_Trunk",
      "support": 15
    },
    {
      "x": -2,
      "y": 6,
      "z": -3,
      "name": "Wood_Sallow_Trunk",
      "support": 15
    },
    {
      "x": -2,
      "y": 7,
      "z": -3,
      "name": "Wood_Sallow_Trunk_Full",
      "support": 15
    },
    {
      "x": -2,
      "y": 8,
      "z": -3,
      "name": "Plant_Moss_Rug_Green_Dark",
      "support": 15
    },
    {
      "x": -2,
      "y": 20,
      "z": -3,
      "name": "Wood_Goldenwood_Planks_Half",
      "rotation": 8
    },
    {
      "x": -2,
      "y": 25,
      "z": -3,
      "name": "Wood_Tropicalwood_Roof_Flat",
      "rotation": 2
    },
    {
      "x": -2,
      "y": 31,
      "z": -3,
      "name": "Wood_Sallow_Branch_Short",
      "support": 15,
      "rotation": 2
    },
    {
      "x": -2,
      "y": 54,
      "z": -3,
      "name": "Wood_Sallow_Trunk_Full",
      "support": 15,
      "rotation": 5
    },
    {
      "x": -2,
      "y": 0,
      "z": -2,
      "name": "Wood_Sallow_Trunk",
      "support": 15
    },
    {
      "x": -2,
      "y": 1,
      "z": -2,
      "name": "Wood_Sallow_Trunk"
    },
    {
      "x": -2,
      "y": 2,
      "z": -2,
      "name": "Wood_Sallow_Trunk"
    },
    {
      "x": -2,
      "y": 3,
      "z": -2,
      "name": "Wood_Sallow_Trunk"
    },
    {
      "x": -2,
      "y": 4,
      "z": -2,
      "name": "Wood_Sallow_Trunk"
    },
    {
      "x": -2,
      "y": 5,
      "z": -2,
      "name": "Wood_Sallow_Trunk"
    },
    {
      "x": -2,
      "y": 6,
      "z": -2,
      "name": "Wood_Sallow_Trunk"
    },
    {
      "x": -2,
      "y": 7,
      "z": -2,
      "name": "Wood_Sallow_Trunk"
    },
    {
      "x": -2,
      "y": 8,
      "z": -2,
      "name": "Wood_Sallow_Trunk"
    },
    {
      "x": -2,
      "y": 9,
      "z": -2,
      "name": "Wood_Sallow_Trunk"
    },
    {
      "x": -2,
      "y": 10,
      "z": -2,
      "name": "Wood_Sallow_Trunk"
    },
    {
      "x": -2,
      "y": 11,
      "z": -2,
      "name": "Wood_Sallow_Trunk"
    },
    {
      "x": -2,
      "y": 12,
      "z": -2,
      "name": "Wood_Sallow_Trunk"
    },
    {
      "x": -2,
      "y": 13,
      "z": -2,
      "name": "Wood_Sallow_Trunk"
    },
    {
      "x": -2,
      "y": 14,
      "z": -2,
      "name": "Wood_Sallow_Trunk"
    },
    {
      "x": -2,
      "y": 15,
      "z": -2,
      "name": "Wood_Sallow_Trunk"
    },
    {
      "x": -2,
      "y": 16,
      "z": -2,
      "name": "Wood_Sallow_Trunk"
    },
    {
      "x": -2,
      "y": 17,
      "z": -2,
      "name": "Wood_Sallow_Trunk"
    },
    {
      "x": -2,
      "y": 18,
      "z": -2,
      "name": "Wood_Sallow_Trunk"
    },
    {
      "x": -2,
      "y": 19,
      "z": -2,
      "name": "Wood_Sallow_Trunk"
    },
    {
      "x": -2,
      "y": 20,
      "z": -2,
      "name": "Wood_Sallow_Trunk"
    },
    {
      "x": -2,
      "y": 21,
      "z": -2,
      "name": "Wood_Sallow_Trunk"
    },
    {
      "x": -2,
      "y": 22,
      "z": -2,
      "name": "Wood_Sallow_Trunk"
    },
    {
      "x": -2,
      "y": 23,
      "z": -2,
      "name": "Wood_Sallow_Trunk"
    },
    {
      "x": -2,
      "y": 24,
      "z": -2,
      "name": "Wood_Sallow_Trunk"
    },
    {
      "x": -2,
      "y": 25,
      "z": -2,
      "name": "Wood_Sallow_Trunk"
    },
    {
      "x": -2,
      "y": 26,
      "z": -2,
      "name": "Wood_Sallow_Trunk"
    },
    {
      "x": -2,
      "y": 27,
      "z": -2,
      "name": "Wood_Sallow_Trunk"
    },
    {
      "x": -2,
      "y": 28,
      "z": -2,
      "name": "Wood_Sallow_Trunk"
    },
    {
      "x": -2,
      "y": 29,
      "z": -2,
      "name": "Wood_Sallow_Trunk"
    },
    {
      "x": -2,
      "y": 30,
      "z": -2,
      "name": "Wood_Sallow_Trunk"
    },
    {
      "x": -2,
      "y": 31,
      "z": -2,
      "name": "Wood_Sallow_Trunk"
    },
    {
      "x": -2,
      "y": 32,
      "z": -2,
      "name": "Wood_Sallow_Trunk"
    },
    {
      "x": -2,
