{
  "version": 8,
  "blockIdVersion": 11,
  "anchorX": 0,
  "anchorY": 0,
  "anchorZ": 0,
  "blocks": [
    {
      "x": -10,
      "y": 52,
      "z": 7,
      "name": "Plant_Leaves_Beech",
      "support": 15,
      "rotation": 2
    },
    {
      "x": -10,
      "y": 53,
      "z": 7,
      "name": "Plant_Leaves_Beech",
      "support": 15,
      "rotation": 2
    },
    {
      "x": -10,
      "y": 54,
      "z": 7,
      "name": "Plant_Leaves_Beech",
      "support": 15,
      "rotation": 2
    },
    {
      "x": -10,
      "y": 54,
      "z": 8,
      "name": "Plant_Leaves_Beech",
      "support": 15,
      "rotation": 2
    },
    {
      "x": -9,
      "y": 51,
      "z": 4,
      "name": "Plant_Leaves_Beech",
      "support": 15,
      "rotation": 2
    },
    {
      "x": -9,
      "y": 52,
      "z": 6,
      "name": "Plant_Leaves_Beech",
      "support": 15,
      "rotation": 2
    },
    {
      "x": -9,
      "y": 53,
      "z": 6,
      "name": "Plant_Leaves_Beech",
      "support": 15,
      "rotation": 2
    },
    {
      "x": -9,
      "y": 54,
      "z": 6,
      "name": "Plant_Leaves_Beech",
      "support": 15,
      "rotation": 2
    },
    {
      "x": -9,
      "y": 52,
      "z": 7,
      "name": "Wood_Sallow_Branch_Corner",
      "support": 15,
      "rotation": 3
    },
    {
      "x": -9,
      "y": 53,
      "z": 7,
      "name": "Wood_Sallow_Branch_Long",
      "support": 15,
      "rotation": 2
    },
    {
      "x": -9,
      "y": 54,
      "z": 7,
      "name": "Plant_Leaves_Beech",
      "support": 15,
      "rotation": 2
    },
    {
      "x": -9,
      "y": 55,
      "z": 7,
      "name": "Plant_Leaves_Beech",
      "support": 15,
      "rotation": 2
    },
    {
      "x": -9,
      "y": 52,
      "z": 8,
      "name": "Plant_Leaves_Beech",
      "support": 15,
      "rotation": 2
    },
    {
      "x": -9,
      "y": 53,
      "z": 8,
      "name": "Plant_Leaves_Beech",
      "support": 15,
      "rotation": 2
    },
    {
      "x": -9,
      "y": 54,
      "z": 8,
      "name": "Plant_Leaves_Beech",
      "support": 15,
      "rotation": 2
    },
    {
      "x": -8,
      "y": 55,
      "z": -3,
      "name": "Plant_Leaves_Beech",
      "support": 15,
      "rotation": 2
    },
    {
      "x": -8,
      "y": 56,
      "z": -3,
      "name": "Plant_Leaves_Beech",
      "support": 15,
      "rotation": 2
    },
    {
      "x": -8,
      "y": 51,
      "z": 3,
      "name": "Plant_Leaves_Beech",
      "support": 15,
      "rotation": 2
    },
    {
      "x": -8,
      "y": 50,
      "z": 4,
      "name": "Plant_Leaves_Beech",
      "support": 15,
      "rotation": 2
    },
    {
      "x": -8,
      "y": 51,
      "z": 4,
      "name": "Plant_Leaves_Beech",
      "support": 15,
      "rotation": 2
    },
    {
      "x": -8,
      "y": 52,
      "z": 4,
      "name": "Plant_Leaves_Beech",
      "support": 15,
      "rotation": 2
    },
    {
      "x": -8,
      "y": 52,
      "z": 5,
      "name": "Plant_Leaves_Beech",
      "support": 15,
      "rotation": 2
    },
    {
      "x": -8,
      "y": 52,
      "z": 7,
      "name": "Wood_Sallow_Branch_Long",
      "support": 15,
      "rotation": 7
    },
    {
      "x": -8,
      "y": 53,
      "z": 7,
      "name": "Plant_Leaves_Beech",
      "support": 15,
      "rotation": 2
    },
    {
      "x": -8,
      "y": 54,
      "z": 7,
      "name": "Plant_Leaves_Beech",
      "support": 15,
      "rotation": 2
    },
    {
      "x": -7,
      "y": 0,
      "z": -5,
      "name": "Wood_Sallow_Trunk_Full",
      "support": 15,
      "rotation": 2
    },
    {
      "x": -7,
      "y": 1,
      "z": -5,
      "name": "Plant_Moss_Rug_Green_Dark",
      "support": 15,
      "rotation": 2
    },
    {
      "x": -7,
      "y": 51,
      "z": -4,
      "name": "Plant_Leaves_Beech",
      "support": 15,
      "rotation": 2
    },
    {
      "x": -7,
      "y": 52,
      "z": -4,
      "name": "Plant_Leaves_Beech",
      "support": 15,
      "rotation": 2
    },
    {
      "x": -7,
      "y": 55,
      "z": -4,
      "name": "Plant_Leaves_Beech",
      "support": 15,
      "rotation": 2
    },
    {
      "x": -7,
      "y": 56,
      "z": -4,
      "name": "Plant_Leaves_Beech",
      "support": 15,
      "rotation": 2
    },
    {
      "x": -7,
      "y": 54,
      "z": -3,
      "name": "Plant_Leaves_Beech",
      "support": 15,
      "rotation": 2
    },
    {
      "x": -7,
      "y": 55,
      "z": -3,
      "name": "Wood_Sallow_Branch_Corner",
      "support": 15,
      "rotation": 3
    },
    {
      "x": -7,
      "y": 56,
      "z": -3,
      "name": "Wood_Sallow_Branch_Long",
      "support": 15,
      "rotation": 2
    },
    {
      "x": -7,
      "y": 57,
      "z": -3,
      "name": "Plant_Leaves_Beech",
      "support": 15,
      "rotation": 2
    },
    {
      "x": -7,
      "y": 55,
      "z": -2,
      "name": "Plant_Leaves_Beech",
      "support": 15,
      "rotation": 2
    },
    {
      "x": -7,
      "y": 56,
      "z": -2,
      "name": "Plant_Leaves_Beech",
      "support": 15,
      "rotation": 2
    },
    {
      "x": -7,
      "y": 0,
      "z": 2,
      "name": "Wood_Sallow_Trunk_Full",
      "support": 15,
      "rotation": 7
    },
    {
      "x": -7,
      "y": 23,
      "z": 2,
      "name": "Plant_Moss_Wall_Green_Dark",
      "support": 15,
      "rotation": 3
    },
    {
      "x": -7,
      "y": 51,
      "z": 2,
      "name": "Plant_Leaves_Beech",
      "support": 15,
      "rotation": 2
    },
    {
      "x": -7,
      "y": 22,
      "z": 3,
      "name": "Plant_Moss_Wall_Green_Dark",
      "support": 15,
      "rotation": 3
    },
    {
      "x": -7,
      "y": 23,
      "z": 3,
      "name": "Plant_Moss_Wall_Green_Dark",
      "support": 15,
      "rotation": 3
    },
    {
      "x": -7,
      "y": 51,
      "z": 3,
      "name": "Plant_Leaves_Beech",
      "support": 15,
      "rotation": 2
    },
    {
      "x": -7,
      "y": 52,
      "z": 3,
      "name": "Plant_Leaves_Beech",
      "support": 15,
      "rotation": 2
    },
    {
      "x": -7,
      "y": 50,
      "z": 4,
      "name": "Wood_Sallow_Branch_Corner",
      "support": 15,
      "rotation": 3
    },
    {
      "x": -7,
      "y": 51,
      "z": 4,
      "name": "Wood_Sallow_Branch_Long",
      "support": 15,
      "rotation": 2
    },
    {
      "x": -7,
      "y": 52,
      "z": 4,
      "name": "Plant_Leaves_Beech",
      "support": 15,
      "rotation": 2
    },
    {
      "x": -7,
      "y": 53,
      "z": 4,
      "name": "Plant_Leaves_Beech",
      "support": 15,
      "rotation": 2
    },
    {
      "x": -7,
      "y": 51,
      "z": 5,
      "name": "Plant_Leaves_Beech",
      "support": 15,
      "rotation": 2
    },
    {
      "x": -7,
      "y": 52,
      "z": 5,
      "name": "Plant_Leaves_Beech",
      "support": 15,
      "rotation": 2
    },
    {
      "x": -7,
      "y": 0,
      "z": 7,
      "name": "Plant_Moss_Rug_Green_Dark",
      "support": 15,
      "rotation": 2
    },
    {
      "x": -7,
      "y": 1,
      "z": 7,
      "name": "Plant_Moss_Wall_Green_Dark",
      "support": 15,
      "rotation": 3
    },
    {
      "x": -7,
      "y": 50,
      "z": 7,
      "name": "Plant_Leaves_Beech",
      "support": 15,
      "rotation": 2
    },
    {
      "x": -7,
      "y": 52,
      "z": 7,
      "name": "Wood_Sallow_Branch_Long",
      "support": 15,
      "rotation": 7
    },
    {
      "x": -7,
      "y": 0,
      "z": 8,
      "name": "Wood_Sallow_Trunk_Full",
      "support": 15,
      "rotation": 2
    },
    {
      "x": -7,
      "y": 1,
      "z": 8,
      "name": "Plant_Moss_Rug_Green_Dark",
      "support": 15,
      "rotation": 2
    },
    {
      "x": -7,
      "y": 53,
      "z": 9,
      "name": "Plant_Leaves_Beech",
      "support": 15,
      "rotation": 2
    },
    {
      "x": -7,
      "y": 54,
      "z": 9,
      "name": "Plant_Leaves_Beech",
      "support": 15,
      "rotation": 2
    },
    {
      "x": -7,
      "y": 52,
      "z": 10,
      "name": "Plant_Leaves_Beech",
      "support": 15,
      "rotation": 2
    },
    {
      "x": -7,
      "y": 53,
      "z": 10,
      "name": "Plant_Leaves_Beech",
      "support": 15,
      "rotation": 2
    },
    {
      "x": -7,
      "y": 54,
      "z": 10,
      "name": "Plant_Leaves_Beech",
      "support": 15,
      "rotation": 2
    },
    {
      "x": -6,
      "y": 51,
      "z": -5,
      "name": "Plant_Leaves_Beech",
      "support": 15,
      "rotation": 2
    },
    {
      "x": -6,
      "y": 52,
      "z": -5,
      "name": "Plant_Leaves_Beech",
      "support": 15,
      "rotation": 2
    },
    {
      "x": -6,
      "y": 0,
      "z": -4,
      "name": "Wood_Sallow_Trunk",
      "support": 15,
      "rotation": 2
    },
    {
      "x": -6,
      "y": 1,
      "z": -4,
      "name": "Wood_Sallow_Trunk_Full",
      "support": 15,
      "rotation": 2
    },
    {
      "x": -6,
      "y": 2,
      "z": -4,
      "name": "Plant_Moss_Rug_Green_Dark",
      "support": 15,
      "rotation": 2
    },
    {
      "x": -6,
      "y": 50,
      "z": -4,
      "name": "Plant_Leaves_Beech",
      "support": 15,
      "rotation": 2
    },
    {
      "x": -6,
      "y": 51,
      "z": -4,
      "name": "Wood_Sallow_Branch_Long",
      "support": 15,
      "rotation": 2
    },
    {
      "x": -6,
      "y": 52,
      "z": -4,
      "name": "Wood_Sallow_Branch_Corner",
      "support": 15,
      "rotation": 34
    },
    {
      "x": -6,
      "y": 53,
      "z": -4,
      "name": "Plant_Leaves_Beech",
      "support": 15,
      "rotation": 2
    },
    {
      "x": -6,
      "y": 55,
      "z": -4,
      "name": "Plant_Leaves_Beech",
      "support": 15,
      "rotation": 2
    },
    {
      "x": -6,
      "y": 2,
      "z": -3,
      "name": "Plant_Moss_Wall_Green_Dark",
      "support": 15,
      "rotation": 3
    },
    {
      "x": -6,
      "y": 51,
      "z": -3,
      "name": "Plant_Leaves_Beech",
      "support": 15,
      "rotation": 2
    },
    {
      "x": -6,
      "y": 52,
      "z": -3,
      "name": "Wood_Sallow_Branch_Corner",
      "support": 15,
      "rotation": 19
    },
    {
      "x": -6,
      "y": 54,
      "z": -3,
      "name": "Plant_Leaves_Beech",
      "support": 15,
      "rotation": 2
    },
    {
      "x": -6,
      "y": 55,
      "z": -3,
      "name": "Wood_Sallow_Branch_Long",
      "support": 15,
      "rotation": 7
    },
    {
      "x": -6,
      "y": 56,
      "z": -3,
      "name": "Plant_Leaves_Beech",
      "support": 15,
      "rotation": 2
    },
    {
      "x": -6,
      "y": 20,
      "z": -1,
      "name": "Furniture_Crude_Platform",
      "rotation": 1
    },
    {
      "x": -6,
      "y": 21,
      "z": -1,
      "name": "*Wood_Softwood_Fence_State_Definitions_Corner",
      "rotation": 1
    },
    {
      "x": -6,
      "y": 22,
      "z": -1,
      "name": "*Wood_Softwood_Fence_State_Definitions_Corner",
      "rotation": 1
    },
    {
      "x": -6,
      "y": 23,
      "z": -1,
      "name": "*Wood_Softwood_Fence_State_Definitions_Corner",
      "rotation": 1
    },
    {
      "x": -6,
      "y": 24,
      "z": -1,
      "name": "*Wood_Tropicalwood_Roof_State_Definitions_Corner_Left",
      "rotation": 2
    },
    {
      "x": -6,
      "y": 20,
      "z": 0,
      "name": "Furniture_Crude_Platform",
      "rotation": 1
    },
    {
      "x": -6,
      "y": 21,
      "z": 0,
      "name": "Wood_Softwood_Fence",
      "rotation": 3
    },
    {
      "x": -6,
      "y": 22,
      "z": 0,
      "name": "Wood_Softwood_Fence",
      "rotation": 3
    },
    {
      "x": -6,
      "y": 23,
      "z": 0,
      "name": "Wood_Softwood_Fence",
      "rotation": 3
    },
    {
      "x": -6,
      "y": 24,
      "z": 0,
      "name": "Wood_Tropicalwood_Roof",
      "rotation": 3
    },
    {
      "x": -6,
      "y": 50,
      "z": 0,
      "name": "Plant_Leaves_Beech",
      "support": 15,
      "rotation": 2
    },
    {
      "x": -6,
      "y": 51,
      "z": 0,
      "name": "Plant_Leaves_Beech",
      "support": 15,
      "rotation": 2
    },
    {
      "x": -6,
      "y": 20,
      "z": 1,
      "name": "Furniture_Crude_Platform",
      "rotation": 1
    },
    {
      "x": -6,
      "y": 21,
      "z": 1,
      "name": "Wood_Softwood_Fence",
      "rotation": 3
    },
    {
      "x": -6,
      "y": 22,
      "z": 1,
      "name": "Wood_Goldenwood_Fence",
      "rotation": 3
    },
    {
      "x": -6,
      "y": 23,
      "z": 1,
      "name": "Wood_Softwood_Fence",
      "rotation": 3
    },
    {
      "x": -6,
      "y": 24,
      "z": 1,
      "name": "Wood_Tropicalwood_Roof",
      "rotation": 3
    },
    {
      "x": -6,
      "y": 47,
      "z": 1,
      "name": "Plant_Leaves_Beech",
      "support": 15,
      "rotation": 2
    },
    {
      "x": -6,
      "y": 0,
      "z": 2,
      "name": "Wood_Sallow_Trunk",
      "support": 15,
      "rotation": 2
    },
    {
      "x": -6,
      "y": 1,
      "z": 2,
      "name": "Wood_Sallow_Trunk_Full",
      "support": 15,
      "rotation": 2
    },
    {
      "x": -6,
      "y": 20,
      "z": 2,
      "name": "Furniture_Crude_Platform",
      "rotation": 1
    },
    {
      "x": -6,
      "y": 21,
      "z": 2,
      "name": "Wood_Softwood_Fence",
      "rotation": 3
    },
    {
      "x": -6,
      "y": 22,
      "z": 2,
      "name": "Wood_Softwood_Fence",
      "rotation": 3
    },
    {
      "x": -6,
      "y": 23,
      "z": 2,
      "name": "Wood_Softwood_Fence",
      "rotation": 3
    },
    {
      "x": -6,
      "y": 24,
      "z": 2,
      "name": "Wood_Tropicalwood_Roof",
      "rotation": 3
    },
    {
      "x": -6,
      "y": 20,
      "z": 3,
      "name": "Furniture_Crude_Platform",
      "rotation": 1
    },
    {
      "x": -6,
      "y": 21,
      "z": 3,
      "name": "*Wood_Softwood_Fence_State_Definitions_Corner",
      "rotation": 2
    },
    {
      "x": -6,
      "y": 22,
      "z": 3,
      "name": "*Wood_Softwood_Fence_State_Definitions_Corner",
      "rotation": 2
    },
    {
      "x": -6,
      "y": 23,
      "z": 3,
      "name": "*Wood_Softwood_Fence_State_Definitions_Corner",
      "rotation": 2
    },
    {
      "x": -6,
      "y": 24,
      "z": 3,
      "name": "*Wood_Tropicalwood_Roof_State_Definitions_Corner_Left",
      "rotation": 3
    },
    {
      "x": -6,
      "y": 56,
      "z": 3,
      "name": "Plant_Leaves_Beech",
      "support": 15,
      "rotation": 2
    },
    {
      "x": -6,
      "y": 57,
      "z": 3,
      "name": "Plant_Leaves_Beech",
      "support": 15,
      "rotation": 2
    },
    {
      "x": -6,
      "y": 60,
      "z": 3,
      "name": "Plant_Leaves_Beech",
      "support": 15,
      "rotation": 2
    },
    {
      "x": -6,
      "y": 14,
      "z": 4,
      "name": "Plant_Vine_Liana_End",
      "support": 15,
      "rotation": 3
    },
    {
      "x": -6,
      "y": 15,
      "z": 4,
      "name": "Plant_Vine_Liana",
      "support": 15,
      "rotation": 3
    },
    {
      "x": -6,
      "y": 16,
      "z": 4,
      "name": "Plant_Vine_Liana",
      "support": 15,
      "rotation": 3
    },
    {
      "x": -6,
      "y": 17,
      "z": 4,
      "name": "Plant_Vine_Liana",
      "support": 15,
      "rotation": 3
    },
    {
      "x": -6,
      "y": 18,
      "z": 4,
      "name": "Plant_Vine_Liana",
      "support": 15,
      "rotation": 3
    },
    {
      "x": -6,
      "y": 19,
      "z": 4,
      "name": "Plant_Vine_Liana",
      "support": 15,
      "rotation": 3
    },
    {
      "x": -6,
      "y": 20,
      "z": 4,
      "name": "Plant_Vine_Liana",
      "support": 15,
      "rotation": 3
    },
    {
      "x": -6,
      "y": 21,
      "z": 4,
      "name": "Plant_Vine_Liana",
      "support": 15,
      "rotation": 3
    },
    {
      "x": -6,
      "y": 22,
      "z": 4,
      "name": "Plant_Vine_Liana",
      "support": 15,
      "rotation": 3
    },
    {
      "x": -6,
      "y": 23,
      "z": 4,
      "name": "Plant_Vine_Liana",
      "support": 15,
      "rotation": 3
    },
    {
      "x": -6,
      "y": 50,
      "z": 4,
      "name": "Wood_Sallow_Branch_Long",
      "support": 15,
      "rotation": 7
    },
    {
      "x": -6,
      "y": 51,
      "z": 4,
      "name": "Plant_Leaves_Beech",
      "support": 15,
      "rotation": 2
    },
    {
      "x": -6,
      "y": 52,
      "z": 4,
      "name": "Plant_Leaves_Beech",
      "support": 15,
      "rotation": 2
    },
    {
      "x": -6,
      "y": 56,
      "z": 4,
      "name": "Plant_Leaves_Beech",
      "support": 15,
      "rotation": 2
    },
    {
      "x": -6,
      "y": 58,
      "z": 4,
      "name": "Plant_Leaves_Beech",
      "support": 15,
      "rotation": 2
    },
    {
      "x": -6,
      "y": 59,
      "z": 4,
      "name": "Plant_Leaves_Beech",
      "support": 15,
      "rotation": 2
    },
    {
      "x": -6,
      "y": 60,
      "z": 4,
      "name": "Plant_Leaves_Beech",
      "support": 15,
      "rotation": 2
    },
    {
      "x": -6,
      "y": 59,
      "z": 5,
      "name": "Plant_Leaves_Beech",
      "support": 15,
      "rotation": 2
    },
    {
      "x": -6,
      "y": 60,
      "z": 5,
      "name": "Plant_Leaves_Beech",
      "support": 15,
      "rotation": 2
    },
    {
      "x": -6,
      "y": 0,
      "z": 6,
      "name": "Wood_Sallow_Trunk_Full",
      "support": 15,
      "rotation": 7
    },
    {
      "x": -6,
      "y": 50,
      "z": 6,
      "name": "Plant_Leaves_Beech",
      "support": 15,
      "rotation": 2
    },
    {
      "x": -6,
      "y": 51,
      "z": 6,
      "name": "Wood_Sallow_Trunk_Full",
      "support": 15,
      "rotation": 7
    },
    {
      "x": -6,
      "y": 56,
      "z": 6,
      "name": "Plant_Leaves_Beech",
      "support": 15,
      "rotation": 2
    },
    {
      "x": -6,
      "y": 0,
      "z": 7,
      "name": "Wood_Sallow_Trunk",
      "support": 15,
      "rotation": 2
    },
    {
      "x": -6,
      "y": 1,
      "z": 7,
      "name": "Wood_Sallow_Trunk_Full",
      "support": 15,
      "rotation": 2
    },
    {
      "x": -6,
      "y": 2,
      "z": 7,
      "name": "Plant_Moss_Rug_Green_Dark",
      "support": 15,
      "rotation": 2
    },
    {
      "x": -6,
      "y": 49,
      "z": 7,
      "name": "Plant_Leaves_Beech",
      "support": 15,
      "rotation": 2
    },
    {
      "x": -6,
      "y": 50,
      "z": 7,
      "name": "Wood_Sallow_Branch_Long",
      "support": 15,
      "rotation": 2
    },
    {
      "x": -6,
      "y": 51,
      "z": 7,
      "name": "Wood_Sallow_Trunk_Full",
      "support": 15,
      "rotation": 6
    },
    {
      "x": -6,
      "y": 52,
      "z": 7,
      "name": "Wood_Sallow_Trunk_Full",
      "support": 15,
      "rotation": 2
    },
    {
      "x": -6,
      "y": 56,
      "z": 7,
      "name": "Plant_Leaves_Beech",
      "support": 15,
      "rotation": 2
    },
    {
      "x": -6,
      "y": 57,
      "z": 7,
      "name": "Plant_Leaves_Beech",
      "support": 15,
      "rotation": 2
    },
    {
      "x": -6,
      "y": 50,
      "z": 8,
      "name": "Plant_Leaves_Beech",
      "support": 15,
      "rotation": 2
    },
    {
      "x": -6,
      "y": 52,
      "z": 8,
      "name": "Wood_Sallow_Branch_Long",
      "support": 15,
      "rotation": 6
    },
    {
      "x": -6,
      "y": 52,
      "z": 9,
      "name": "Wood_Sallow_Branch_Long",
      "support": 15,
      "rotation": 6
    },
    {
      "x": -6,
      "y": 53,
      "z": 9,
      "name": "Plant_Leaves_Beech",
      "support": 15,
      "rotation": 2
    },
    {
      "x": -6,
      "y": 54,
      "z": 9,
      "name": "Plant_Leaves_Beech",
      "support": 15,
      "rotation": 2
    },
    {
      "x": -6,
      "y": 52,
      "z": 10,
      "name": "Wood_Sallow_Branch_Corner",
      "support": 15
    },
    {
      "x": -6,
      "y": 53,
      "z": 10,
      "name": "Wood_Sallow_Branch_Long",
      "support": 15,
      "rotation": 2
    },
    {
      "x": -6,
      "y": 54,
      "z": 10,
      "name": "Plant_Leaves_Beech",
      "support": 15,
      "rotation": 2
    },
    {
      "x": -6,
      "y": 55,
      "z": 10,
      "name": "Plant_Leaves_Beech",
      "support": 15,
      "rotation": 2
    },
    {
      "x": -6,
      "y": 52,
      "z": 11,
      "name": "Plant_Leaves_Beech",
      "support": 15,
      "rotation": 2
    },
    {
      "x": -6,
      "y": 53,
      "z": 11,
      "name": "Plant_Leaves_Beech",
      "support": 15,
      "rotation": 2
    },
    {
      "x": -5,
      "y": 55,
      "z": -5,
      "name": "Plant_Leaves_Beech",
      "support": 15,
      "rotation": 2
    },
    {
      "x": -5,
      "y": 56,
      "z": -5,
      "name": "Plant_Leaves_Beech",
      "support": 15,
      "rotation": 2
    },
    {
      "x": -5,
      "y": 0,
      "z": -4,
      "name": "Wood_Sallow_Trunk",
      "support": 15,
      "rotation": 2
    },
    {
      "x": -5,
      "y": 1,
      "z": -4,
      "name": "Wood_Sallow_Trunk_Full",
      "support": 15,
      "rotation": 2
    },
    {
      "x": -5,
      "y": 2,
      "z": -4,
      "name": "Plant_Moss_Rug_Green_Dark",
      "support": 15,
      "rotation": 2
    },
    {
      "x": -5,
      "y": 20,
      "z": -4,
      "name": "Plant_Moss_Wall_Green_Dark",
      "support": 15,
      "rotation": 3
    },
    {
      "x": -5,
      "y": 51,
      "z": -4,
      "name": "Plant_Leaves_Beech",
      "support": 15,
      "rotation": 2
    },
    {
      "x": -5,
      "y": 52,
      "z": -4,
      "name": "Plant_Leaves_Beech",
      "support": 15,
      "rotation": 2
    },
    {
      "x": -5,
      "y": 55,
      "z": -4,
      "name": "Plant_Leaves_Beech",
      "support": 15,
      "rotation": 2
    },
    {
      "x": -5,
      "y": 0,
      "z": -3,
      "name": "Wood_Sallow_Trunk",
      "support": 15,
      "rotation": 2
    },
    {
      "x": -5,
      "y": 1,
      "z": -3,
      "name": "Wood_Sallow_Trunk",
      "support": 15,
      "rotation": 2
    },
    {
      "x": -5,
      "y": 2,
      "z": -3,
      "name": "Wood_Sallow_Trunk_Full",
      "support": 15,
      "rotation": 2
    },
    {
      "x": -5,
      "y": 3,
      "z": -3,
      "name": "Plant_Moss_Rug_Green_Dark",
      "support": 15,
      "rotation": 2
    },
    {
      "x": -5,
      "y": 20,
      "z": -3,
      "name": "Furniture_Crude_Platform",
      "rotation": 1
    },
    {
      "x": -5,
      "y": 21,
      "z": -3,
      "name": "*Wood_Softwood_Fence_State_Definitions_Corner",
      "rotation": 1
    },
    {
      "x": -5,
      "y": 22,
      "z": -3,
      "name": "*Wood_Softwood_Fence_State_Definitions_Corner",
      "rotation": 1
    },
    {
      "x": -5,
      "y": 23,
      "z": -3,
      "name": "*Wood_Softwood_Fence_State_Definitions_Corner",
      "rotation": 1
    },
    {
      "x": -5,
      "y": 24,
      "z": -3,
      "name": "*Wood_Tropicalwood_Roof_State_Definitions_Corner_Right",
      "rotation": 3
    },
    {
      "x": -5,
      "y": 52,
      "z": -3,
      "name": "Wood_Sallow_Branch_Long",
      "support": 15,
      "rotation": 7
    },
    {
      "x": -5,
      "y": 55,
      "z": -3,
      "name": "Wood_Sallow_Branch_Long",
      "support": 15,
      "rotation": 7
    },
    {
      "x": -5,
      "y": 57,
      "z": -3,
      "name": "Plant_Leaves_Beech",
      "support": 15,
      "rotation": 2
    },
    {
      "x": -5,
      "y": 0,
      "z": -2,
      "name": "Wood_Sallow_Trunk_Full",
      "support": 15,
      "rotation": 2
    },
    {
      "x": -5,
      "y": 2,
      "z": -2,
      "name": "Plant_Moss_Wall_Green_Dark",
      "support": 15
    },
    {
      "x": -5,
      "y": 20,
      "z": -2,
      "name": "Furniture_Crude_Platform",
      "rotation": 1
    },
    {
      "x": -5,
      "y": 21,
      "z": -2,
      "name": "Wood_Softwood_Fence",
      "rotation": 3
    },
    {
      "x": -5,
      "y": 22,
      "z": -2,
      "name": "Wood_Goldenwood_Fence",
      "rotation": 3
    },
    {
      "x": -5,
      "y": 23,
      "z": -2,
      "name": "Wood_Softwood_Fence",
      "rotation": 3
    },
    {
      "x": -5,
      "y": 24,
      "z": -2,
      "name": "Wood_Tropicalwood_Roof",
      "rotation": 3
    },
    {
      "x": -5,
      "y": 20,
      "z": -1,
      "name": "Furniture_Crude_Platform",
      "rotation": 1
    },
    {
      "x": -5,
      "y": 21,
      "z": -1,
      "name": "*Wood_Softwood_Fence_State_Definitions_Corner",
      "rotation": 3
    },
    {
      "x": -5,
      "y": 22,
      "z": -1,
      "name": "*Wood_Softwood_Fence_State_Definitions_Corner",
      "rotation": 3
    },
    {
      "x": -5,
      "y": 23,
      "z": -1,
      "name": "*Wood_Softwood_Fence_State_Definitions_Corner",
      "rotation": 3
    },
    {
      "x": -5,
      "y": 24,
      "z": -1,
      "name": "*Wood_Tropicalwood_Roof_State_Definitions_Inverted_Corner_Left",
      "rotation": 2
    },
    {
      "x": -5,
      "y": 50,
      "z": -1,
      "name": "Plant_Leaves_Beech",
      "support": 15,
      "rotation": 2
    },
    {
      "x": -5,
      "y": 51,
      "z": -1,
      "name": "Plant_Leaves_Beech",
      "support": 15,
      "rotation": 2
    },
    {
      "x": -5,
      "y": 20,
      "z": 0,
      "name": "Wood_Goldenwood_Planks_Half",
      "rotation": 8
    },
    {
      "x": -5,
      "y": 25,
      "z": 0,
      "name": "Wood_Tropicalwood_Roof_Flat",
      "rotation": 1
    },
    {
      "x": -5,
      "y": 46,
      "z": 0,
      "name": "Plant_Leaves_Beech",
      "support": 15,
      "rotation": 2
    },
    {
      "x": -5,
      "y": 47,
      "z": 0,
      "name": "Plant_Leaves_Beech",
      "support": 15,
      "rotation": 2
    },
    {
      "x": -5,
      "y": 49,
      "z": 0,
      "name": "Plant_Leaves_Beech",
      "support": 15,
      "rotation": 2
    },
    {
      "x": -5,
      "y": 50,
      "z": 0,
      "name": "Wood_Sallow_Branch_Corner",
      "support": 15,
      "rotation": 3
    },
    {
      "x": -5,
      "y": 51,
      "z": 0,
      "name": "Wood_Sallow_Branch_Long",
      "support": 15,
      "rotation": 2
    },
    {
      "x": -5,
      "y": 52,
      "z": 0,
      "name": "Plant_Leaves_Beech",
      "support": 15,
      "rotation": 2
    },
    {
      "x": -5,
      "y": 0,
      "z": 1,
      "name": "Wood_Sallow_Trunk",
      "support": 15,
      "rotation": 2
    },
    {
      "x": -5,
      "y": 1,
      "z": 1,
      "name": "Wood_Sallow_Trunk",
      "support": 15,
      "rotation": 2
    },
    {
      "x": -5,
      "y": 2,
      "z": 1,
      "name": "Wood_Sallow_Trunk_Full",
      "support": 15,
      "rotation": 2
    },
    {
      "x": -5,
      "y": 20,
      "z": 1,
      "name": "Wood_Goldenwood_Planks_Half",
      "rotation": 8
    },
    {
      "x": -5,
      "y": 25,
      "z": 1,
      "name": "Wood_Tropicalwood_Roof_Flat",
      "rotation": 1
    },
    {
      "x": -5,
      "y": 46,
      "z": 1,
      "name": "Plant_Leaves_Beech",
      "support": 15,
      "rotation": 2
    },
    {
      "x": -5,
      "y": 47,
      "z": 1,
      "name": "Wood_Sallow_Branch_Corner",
      "support": 15,
      "rotation": 3
    },
    {
      "x": -5,
      "y": 48,
      "z": 1,
      "name": "Plant_Leaves_Beech",
      "support": 15,
      "rotation": 2
    },
    {
      "x": -5,
      "y": 50,
      "z": 1,
      "name": "Plant_Leaves_Beech",
      "support": 15,
      "rotation": 2
    },
    {
      "x": -5,
      "y": 51,
      "z": 1,
      "name": "Plant_Leaves_Beech",
      "support": 15,
      "rotation": 2
    },
    {
      "x": -5,
      "y": 20,
      "z": 2,
      "name": "Wood_Goldenwood_Planks_Half",
      "rotation": 8
    },
    {
      "x": -5,
      "y": 25,
      "z": 2,
      "name": "Wood_Tropicalwood_Roof_Flat",
      "rotation": 1
    },
    {
      "x": -5,
      "y": 47,
      "z": 2,
      "name": "Plant_Leaves_Beech",
      "support": 15,
      "rotation": 2
    },
    {
      "x": -5,
      "y": 56,
      "z": 2,
      "name": "Plant_Leaves_Beech",
      "support": 15,
      "rotation": 2
    },
    {
      "x": -5,
      "y": 57,
      "z": 2,
      "name": "Plant_Leaves_Beech",
      "support": 15,
      "rotation": 2
    },
    {
      "x": -5,
      "y": 60,
      "z": 2,
      "name": "Plant_Leaves_Beech",
      "support": 15,
      "rotation": 2
    },
    {
      "x": -5,
      "y": 20,
      "z": 3,
      "name": "Furniture_Crude_Platform",
      "rotation": 1
    },
    {
      "x": -5,
      "y": 21,
      "z": 3,
      "name": "*Wood_Softwood_Fence_State_Definitions_Corner"
    },
    {
      "x": -5,
      "y": 22,
      "z": 3,
      "name": "*Wood_Softwood_Fence_State_Definitions_Corner"
    },
    {
      "x": -5,
      "y": 23,
      "z": 3,
      "name": "*Wood_Softwood_Fence_State_Definitions_Corner"
    },
    {
      "x": -5,
      "y": 24,
      "z": 3,
      "name": "*Wood_Tropicalwood_Roof_State_Definitions_Inverted_Corner_Right"
    },
    {
      "x": -5,
      "y": 55,
      "z": 3,
      "name": "Wood_Sallow_Branch_Corner",
      "support": 15,
      "rotation": 3
    },
    {
      "x": -5,
      "y": 56,
      "z": 3,
      "name": "Wood_Sallow_Branch_Long",
      "support": 15,
      "rotation": 2
    },
    {
      "x": -5,
      "y": 57,
      "z": 3,
      "name": "Plant_Leaves_Beech",
      "support": 15,
      "rotation": 2
    },
    {
      "x": -5,
      "y": 58,
      "z": 3,
      "name": "Plant_Leaves_Beech",
      "support": 15,
      "rotation": 2
    },
    {
      "x": -5,
      "y": 59,
      "z": 3,
      "name": "Plant_Leaves_Beech",
      "support": 15,
      "rotation": 2
    },
    {
      "x": -5,
      "y": 60,
      "z": 3,
      "name": "Plant_Leaves_Beech",
      "support": 15,
      "rotation": 2
    },
    {
      "x": -5,
      "y": 61,
      "z": 3,
      "name": "Plant_Leaves_Beech",
      "support": 15,
      "rotation": 2
    },
    {
      "x": -5,
      "y": 20,
      "z": 4,
      "name": "Furniture_Crude_Platform",
      "rotation": 1
    },
    {
      "x": -5,
      "y": 21,
      "z": 4,
      "name": "Wood_Softwood_Fence",
      "rotation": 3
    },
    {
      "x": -5,
      "y": 22,
      "z": 4,
      "name": "Wood_Goldenwood_Fence",
      "rotation": 3
    },
    {
      "x": -5,
      "y": 23,
      "z": 4,
      "name": "Wood_Softwood_Fence",
      "rotation": 3
    },
    {
      "x": -5,
      "y": 24,
      "z": 4,
      "name": "Wood_Tropicalwood_Roof",
      "rotation": 3
    },
    {
      "x": -5,
      "y": 50,
      "z": 4,
      "name": "Wood_Sallow_Branch_Long",
      "support": 15,
      "rotation": 7
    },
    {
      "x": -5,
      "y": 56,
      "z": 4,
      "name": "Plant_Leaves_Beech",
      "support": 15,
      "rotation": 2
    },
    {
      "x": -5,
      "y": 57,
      "z": 4,
      "name": "Plant_Leaves_Beech",
      "support": 15,
      "rotation": 2
    },
    {
      "x": -5,
      "y": 58,
      "z": 4,
      "name": "Wood_Sallow_Branch_Corner",
      "support": 15,
      "rotation": 3
    },
    {
      "x": -5,
      "y": 59,
      "z": 4,
      "name": "Wood_Sallow_Branch_Long",
      "support": 15,
      "rotation": 2
    },
    {
      "x": -5,
      "y": 60,
      "z": 4,
      "name": "Plant_Leaves_Beech",
      "support": 15,
      "rotation": 2
    },
    {
      "x": -5,
      "y": 61,
      "z": 4,
      "name": "Plant_Leaves_Beech",
      "support": 15,
      "rotation": 2
    },
    {
      "x": -5,
      "y": 0,
      "z": 5,
      "name": "Wood_Sallow_Trunk_Full",
      "support": 15,
      "rotation": 7
    },
    {
      "x": -5,
      "y": 20,
      "z": 5,
      "name": "Furniture_Crude_Platform",
      "rotation": 1
    },
    {
      "x": -5,
      "y": 21,
      "z": 5,
      "name": "*Wood_Softwood_Fence_State_Definitions_Corner",
      "rotation": 2
    },
    {
      "x": -5,
      "y": 22,
      "z": 5,
      "name": "*Wood_Softwood_Fence_State_Definitions_Corner",
      "rotation": 2
    },
    {
      "x": -5,
      "y": 23,
      "z": 5,
      "name": "*Wood_Softwood_Fence_State_Definitions_Corner",
      "rotation": 2
    },
    {
      "x": -5,
      "y": 24,
      "z": 5,
      "name": "*Wood_Tropicalwood_Roof_State_Definitions_Corner_Right"
    },
    {
      "x": -5,
      "y": 53,
      "z": 5,
      "name": "Plant_Leaves_Beech",
      "support": 15,
      "rotation": 2
    },
    {
      "x": -5,
      "y": 58,
      "z": 5,
      "name": "Plant_Leaves_Beech",
      "support": 15,
      "rotation": 2
    },
    {
      "x": -5,
      "y": 59,
      "z": 5,
      "name": "Plant_Leaves_Beech",
      "support": 15,
      "rotation": 2
    },
    {
      "x": -5,
      "y": 60,
      "z": 5,
      "name": "Plant_Leaves_Beech",
      "support": 15,
      "rotation": 2
    },
    {
      "x": -5,
      "y": 0,
      "z": 6,
      "name": "Wood_Sallow_Trunk",
      "support": 15,
      "rotation": 2
    },
    {
      "x": -5,
      "y": 1,
      "z": 6,
      "name": "Wood_Sallow_Trunk",
      "support": 15,
      "rotation": 2
    },
    {
      "x": -5,
      "y": 2,
      "z": 6,
      "name": "Wood_Sallow_Trunk_Full",
      "support": 15,
      "rotation": 2
    },
    {
      "x": -5,
      "y": 51,
      "z": 6,
      "name": "Wood_Sallow_Trunk",
      "support": 15,
      "rotation": 7
    },
    {
      "x": -5,
      "y": 56,
      "z": 6,
      "name": "Wood_Sallow_Branch_Corner",
      "support": 15,
      "rotation": 51
    },
    {
      "x": -5,
      "y": 57,
      "z": 6,
      "name": "Plant_Leaves_Beech",
      "support": 15,
      "rotation": 2
    },
    {
      "x": -5,
      "y": 0,
      "z": 7,
      "name": "Wood_Sallow_Trunk",
      "support": 15,
      "rotation": 2
    },
    {
      "x": -5,
      "y": 1,
      "z": 7,
      "name": "Wood_Sallow_Trunk",
      "support": 15,
      "rotation": 2
    },
    {
      "x": -5,
      "y": 2,
      "z": 7,
      "name": "Wood_Sallow_Trunk_Full",
      "support": 15,
      "rotation": 2
    },
    {
      "x": -5,
      "y": 55,
      "z": 7,
      "name": "Plant_Leaves_Beech",
      "support": 15,
      "rotation": 2
    },
    {
      "x": -5,
      "y": 56,
      "z": 7,
      "name": "Wood_Sallow_Branch_Corner",
      "support": 15
    },
    {
      "x": -5,
      "y": 57,
      "z": 7,
      "name": "Wood_Sallow_Branch_Long",
      "support": 15,
      "rotation": 2
    },
    {
      "x": -5,
      "y": 58,
      "z": 7,
      "name": "Plant_Leaves_Beech",
      "support": 15,
      "rotation": 2
    },
    {
      "x": -5,
      "y": 56,
      "z": 8,
      "name": "Plant_Leaves_Beech",
      "support": 15,
      "rotation": 2
    },
    {
      "x": -5,
      "y": 57,
      "z": 8,
      "name": "Plant_Leaves_Beech",
      "support": 15,
      "rotation": 2
    },
    {
      "x": -5,
      "y": 52,
      "z": 9,
      "name": "Plant_Leaves_Beech",
      "support": 15,
      "rotation": 2
    },
    {
      "x": -5,
      "y": 53,
      "z": 9,
      "name": "Plant_Leaves_Beech",
      "support": 15,
      "rotation": 2
    },
    {
      "x": -5,
      "y": 52,
      "z": 10,
      "name": "Plant_Leaves_Beech",
      "support": 15,
      "rotation": 2
    },
    {
      "x": -5,
      "y": 53,
      "z": 10,
      "name": "Plant_Leaves_Beech",
      "support": 15,
      "rotation": 2
    },
    {
      "x": -5,
      "y": 54,
      "z": 10,
      "name": "Plant_Leaves_Beech",
      "support": 15,
      "rotation": 2
    },
    {
      "x": -5,
      "y": 53,
      "z": 11,
      "name": "Plant_Leaves_Beech",
      "support": 15,
      "rotation": 2
    },
    {
      "x": -4,
      "y": 49,
      "z": -6,
      "name": "Plant_Leaves_Beech",
      "support": 15,
      "rotation": 2
    },
    {
      "x": -4,
      "y": 50,
      "z": -6,
      "name": "Plant_Leaves_Beech",
      "support": 15,
      "rotation": 2
    },
    {
      "x": -4,
      "y": 55,
      "z": -6,
      "name": "Plant_Leaves_Beech",
      "support": 15,
      "rotation": 2
    },
    {
      "x": -4,
      "y": 56,
      "z": -6,
      "name": "Plant_Leaves_Beech",
      "support": 15,
      "rotation": 2
    },
    {
      "x": -4,
      "y": 54,
      "z": -5,
      "name": "Plant_Leaves_Beech",
      "support": 15,
      "rotation": 2
    },
    {
      "x": -4,
      "y": 55,
      "z": -5,
      "name": "Wood_Sallow_Branch_Corner",
      "support": 15,
      "rotation": 2
    },
    {
      "x": -4,
      "y": 56,
      "z": -5,
      "name": "Wood_Sallow_Branch_Long",
      "support": 15,
      "rotation": 2
    },
    {
      "x": -4,
      "y": 57,
      "z": -5,
      "name": "Plant_Leaves_Beech",
      "support": 15,
      "rotation": 2
    },
    {
      "x": -4,
      "y": 20,
      "z": -4,
      "name": "Furniture_Crude_Platform"
    },
    {
      "x": -4,
      "y": 21,
      "z": -4,
      "name": "*Wood_Softwood_Fence_State_Definitions_Corner",
      "rotation": 1
    },
    {
      "x": -4,
      "y": 22,
      "z": -4,
      "name": "*Wood_Softwood_Fence_State_Definitions_Corner",
      "rotation": 1
    },
    {
      "x": -4,
      "y": 23,
      "z": -4,
      "name": "*Wood_Softwood_Fence_State_Definitions_Corner",
      "rotation": 1
    },
    {
      "x": -4,
      "y": 24,
      "z": -4,
      "name": "*Wood_Tropicalwood_Roof_State_Definitions_Corner_Right",
      "rotation": 3
    },
    {
      "x": -4,
      "y": 55,
      "z": -4,
      "name": "Wood_Sallow_Branch_Long",
      "support": 15,
      "rotation": 6
    },
    {
      "x": -4,
      "y": 56,
      "z": -4,
      "name": "Plant_Leaves_Beech",
      "support": 15,
      "rotation": 2
    },
    {
      "x": -4,
      "y": 57,
      "z": -4,
      "name": "Plant_Leaves_Beech",
      "support": 15,
      "rotation": 2
    },
    {
      "x": -4,
      "y": 58,
      "z": -4,
      "name": "Plant_Leaves_Beech",
      "support": 15,
      "rotation": 2
    },
    {
      "x": -4,
      "y": 0,
      "z": -3,
      "name": "Wood_Sallow_Trunk",
      "support": 15,
      "rotation": 2
    },
    {
      "x": -4,
      "y": 1,
      "z": -3,
      "name": "Wood_Sallow_Trunk",
      "support": 15,
      "rotation": 2
    },
    {
      "x": -4,
      "y": 2,
      "z": -3,
      "name": "Wood_Sallow_Trunk",
      "support": 15,
      "rotation": 2
    },
    {
      "x": -4,
      "y": 3,
      "z": -3,
      "name": "Wood_Sallow_Trunk_Full",
      "support": 15,
      "rotation": 2
    },
    {
      "x": -4,
      "y": 20,
      "z": -3,
      "name": "Furniture_Crude_Platform",
      "rotation": 1
    },
    {
      "x": -4,
      "y": 21,
      "z": -3,
      "name": "*Wood_Softwood_Fence_State_Definitions_Corner",
      "rotation": 3
    },
    {
      "x": -4,
      "y": 22,
      "z": -3,
      "name": "*Wood_Softwood_Fence_State_Definitions_Corner",
      "rotation": 3
    },
    {
      "x": -4,
      "y": 23,
      "z": -3,
      "name": "*Wood_Softwood_Fence_State_Definitions_Corner",
      "rotation": 3
    },
    {
      "x": -4,
      "y": 24,
      "z": -3,
      "name": "*Wood_Tropicalwood_Roof_State_Definitions_Inverted_Corner_Left",
      "rotation": 2
    },
    {
      "x": -4,
      "y": 52,
      "z": -3,
      "name": "Wood_Sallow_Branch_Corner",
      "support": 15,
      "rotation": 1
    },
    {
      "x": -4,
      "y": 53,
      "z": -3,
      "name": "Wood_Sallow_Trunk_Full",
      "support": 15,
      "rotation": 7
    },
    {
      "x": -4,
      "y": 54,
      "z": -3,
      "name": "Wood_Sallow_Trunk",
      "support": 15,
      "rotation": 2
    },
    {
      "x": -4,
      "y": 55,
      "z": -3,
      "name": "Wood_Sallow_Trunk_Full",
      "support": 15,
      "rotation": 2
    },
    {
      "x": -4,
      "y": 56,
      "z": -3,
      "name": "Wood_Sallow_Branch_Long",
      "support": 15,
      "rotation": 2
    },
    {
      "x": -4,
      "y": 57,
      "z": -3,
      "name": "Wood_Sallow_Branch_Long",
      "support": 15,
      "rotation": 2
    },
    {
      "x": -4,
      "y": 58,
      "z": -3,
      "name": "Plant_Leaves_Beech",
      "support": 15,
      "rotation": 2
    },
    {
      "x": -4,
      "y": 0,
      "z": -2,
      "name": "Wood_Sallow_Trunk",
      "support": 15,
      "rotation": 2
    },
    {
      "x": -4,
      "y": 1,
      "z": -2,
      "name": "Wood_Sallow_Trunk",
      "support": 15,
      "rotation": 2
    },
    {
      "x": -4,
      "y": 2,
      "z": -2,
      "name": "Wood_Sallow_Trunk",
      "support": 15,
      "rotation": 2
    },
    {
      "x": -4,
      "y": 3,
      "z": -2,
      "name": "Wood_Sallow_Trunk",
      "support": 15,
      "rotation": 2
    },
    {
      "x": -4,
      "y": 4,
      "z": -2,
      "name": "Wood_Sallow_Trunk_Full",
      "support": 15,
      "rotation": 2
    },
    {
      "x": -4,
      "y": 20,
      "z": -2,
      "name": "Wood_Goldenwood_Planks_Half",
      "rotation": 8
    },
    {
      "x": -4,
      "y": 25,
      "z": -2,
      "name": "Wood_Tropicalwood_Roof_Flat",
      "rotation": 1
    },
    {
      "x": -4,
      "y": 57,
      "z": -2,
      "name": "Plant_Leaves_Beech",
      "support": 15,
      "rotation": 2
    },
    {
      "x": -4,
      "y": 0,
      "z": -1,
      "name": "Wood_Sallow_Trunk",
      "support": 15,
      "rotation": 2
    },
    {
      "x": -4,
      "y": 1,
      "z": -1,
      "name": "Wood_Sallow_Trunk_Full",
      "support": 15,
      "rotation": 2
    },
    {
      "x": -4,
      "y": 20,
      "z": -1,
      "name": "Wood_Goldenwood_Planks_Half",
      "rotation": 8
    },
    {
      "x": -4,
      "y": 21,
      "z": -1,
      "name": "Furniture_Village_Chair",
      "components": {
        "Components": {}
      }
    },
    {
      "x": -4,
      "y": 22,
      "z": -1,
      "name": "Furniture_Village_Chair",
      "filler": 1024
    },
    {
      "x": -4,
      "y": 25,
      "z": -1,
      "name": "Wood_Tropicalwood_Roof_Flat",
      "rotation": 1
    },
    {
      "x": -4,
      "y": 50,
      "z": -1,
      "name": "Plant_Leaves_Beech",
      "support": 15,
      "rotation": 2
    },
    {
      "x": -4,
      "y": 20,
      "z": 0,
      "name": "Wood_Goldenwood_Planks_Half",
      "rotation": 8
    },
    {
      "x": -4,
      "y": 21,
      "z": 0,
      "name": "Furniture_Village_Table",
      "filler": 1023,
      "rotation": 2
    },
    {
      "x": -4,
      "y": 25,
      "z": 0,
      "name": "Wood_Tropicalwood_Roof_Shallow",
      "rotation": 3
    },
    {
      "x": -4,
      "y": 47,
      "z": 0,
      "name": "Plant_Leaves_Beech",
      "support": 15,
      "rotation": 2
    },
    {
      "x": -4,
      "y": 49,
      "z": 0,
      "name": "Plant_Leaves_Beech",
      "support": 15,
      "rotation": 2
    },
    {
      "x": -4,
      "y": 50,
      "z": 0,
      "name": "Wood_Sallow_Branch_Long",
      "support": 15,
      "rotation": 7
    },
    {
      "x": -4,
      "y": 51,
      "z": 0,
      "name": "Plant_Leaves_Beech",
      "support": 15,
      "rotation": 2
    },
    {
      "x": -4,
      "y": 0,
      "z": 1,
      "name": "Wood_Sallow_Trunk",
      "support": 15,
      "rotation": 2
    },
    {
      "x": -4,
      "y": 1,
      "z": 1,
      "name": "Wood_Sallow_Trunk",
      "support": 15,
      "rotation": 2
    },
    {
      "x": -4,
      "y": 2,
      "z": 1,
      "name": "Wood_Sallow_Trunk_Full",
      "support": 15,
      "rotation": 2
    },
    {
      "x": -4,
      "y": 20,
      "z": 1,
      "name": "Wood_Goldenwood_Planks_Half",
      "rotation": 8
    },
    {
      "x": -4,
      "y": 21,
      "z": 1,
      "name": "Furniture_Village_Table",
      "filler": 31,
      "rotation": 2
    },
    {
      "x": -4,
      "y": 25,
      "z": 1,
      "name": "Wood_Tropicalwood_Roof_Shallow",
      "rotation": 3
    },
    {
      "x": -4,
      "y": 46,
      "z": 1,
      "name": "Plant_Leaves_Beech",
      "support": 15,
      "rotation": 2
    },
    {
      "x": -4,
      "y": 47,
      "z": 1,
      "name": "Wood_Sallow_Branch_Long",
      "support": 15,
      "rotation": 7
    },
    {
      "x": -4,
      "y": 48,
      "z": 1,
      "name": "Plant_Leaves_Beech",
      "support": 15,
      "rotation": 2
    },
    {
      "x": -4,
      "y": 20,
      "z": 2,
      "name": "Wood_Goldenwood_Planks_Half",
      "rotation": 8
    },
    {
      "x": -4,
      "y": 21,
      "z": 2,
      "name": "Furniture_Village_Chair",
      "rotation": 2
    },
    {
      "x": -4,
      "y": 22,
      "z": 2,
      "name": "Furniture_Village_Chair",
      "filler": 1024,
      "rotation": 2
    },
    {
      "x": -4,
      "y": 25,
      "z": 2,
      "name": "Wood_Tropicalwood_Roof_Shallow",
      "rotation": 3
    },
    {
      "x": -4,
      "y": 1,
      "z": 3,
      "name": "Plant_Moss_Wall_Green_Dark",
      "support": 15,
      "rotation": 2
    },
    {
      "x": -4,
      "y": 2,
      "z": 3,
      "name": "Plant_Moss_Wall_Green_Dark",
      "support": 15,
      "rotation": 3
    },
    {
      "x": -4,
      "y": 20,
      "z": 3,
      "name": "Wood_Goldenwood_Planks_Half",
      "rotation": 8
    },
    {
      "x": -4,
      "y": 25,
      "z": 3,
      "name": "Wood_Tropicalwood_Roof_Flat",
      "rotation": 1
    },
    {
      "x": -4,
      "y": 55,
      "z": 3,
      "name": "Wood_Sallow_Branch_Long",
      "support": 15,
      "rotation": 7
    },
    {
      "x": -4,
      "y": 58,
      "z": 3,
      "name": "Plant_Leaves_Beech",
      "support": 15,
      "rotation": 2
    },
    {
      "x": -4,
      "y": 60,
      "z": 3,
      "name": "Plant_Leaves_Beech",
      "support": 15,
      "rotation": 2
    },
    {
      "x": -4,
      "y": 0,
      "z": 4,
      "name": "Wood_Sallow_Trunk",
      "support": 15,
      "rotation": 2
    },
    {
      "x": -4,
      "y": 1,
      "z": 4,
      "name": "Wood_Sallow_Trunk_Full",
      "support": 15,
      "rotation": 2
    },
    {
      "x": -4,
      "y": 2,
      "z": 4,
      "name": "Plant_Moss_Rug_Green_Dark",
      "support": 15,
      "rotation": 2
    },
    {
      "x": -4,
      "y": 20,
      "z": 4,
      "name": "Wood_Goldenwood_Planks_Half",
      "rotation": 8
    },
    {
      "x": -4,
      "y": 25,
      "z": 4,
      "name": "Wood_Tropicalwood_Roof_Flat",
      "rotation": 1
    },
    {
      "x": -4,
      "y": 50,
      "z": 4,
      "name": "Wood_Sallow_Branch_Long",
      "support": 15,
      "rotation": 7
    },
    {
      "x": -4,
      "y": 53,
      "z": 4,
      "name": "Plant_Leaves_Beech",
      "support": 15,
      "rotation": 2
    },
    {
      "x": -4,
      "y": 58,
      "z": 4,
      "name": "Wood_Sallow_Branch_Long",
      "support": 15,
      "rotation": 7
    },
    {
      "x": -4,
      "y": 59,
      "z": 4,
      "name": "Plant_Leaves_Beech",
      "support": 15,
      "rotation": 2
    },
    {
      "x": -4,
      "y": 60,
      "z": 4,
      "name": "Plant_Leaves_Beech",
      "support": 15,
      "rotation": 2
    },
    {
      "x": -4,
      "y": 0,
      "z": 5,
      "name": "Wood_Sallow_Trunk",
      "support": 15,
      "rotation": 2
    },
    {
      "x": -4,
      "y": 1,
      "z": 5,
      "name": "Wood_Sallow_Trunk",
      "support": 15,
      "rotation": 2
    },
    {
      "x": -4,
      "y": 2,
      "z": 5,
      "name": "Wood_Sallow_Trunk_Full",
      "support": 15,
      "rotation": 2
    },
    {
      "x": -4,
      "y": 20,
      "z": 5,
      "name": "Furniture_Crude_Platform",
      "rotation": 1
    },
    {
      "x": -4,
      "y": 21,
      "z": 5,
      "name": "*Wood_Softwood_Fence_State_Definitions_Corner"
    },
    {
      "x": -4,
      "y": 22,
      "z": 5,
      "name": "*Wood_Softwood_Fence_State_Definitions_Corner"
    },
    {
      "x": -4,
      "y": 23,
      "z": 5,
      "name": "*Wood_Softwood_Fence_State_Definitions_Corner"
    },
    {
      "x": -4,
      "y": 24,
      "z": 5,
      "name": "*Wood_Tropicalwood_Roof_State_Definitions_Inverted_Corner_Left",
      "rotation": 3
    },
    {
      "x": -4,
      "y": 50,
      "z": 5,
      "name": "Wood_Sallow_Trunk_Full",
      "support": 15,
      "rotation": 7
    },
    {
      "x": -4,
      "y": 51,
      "z": 5,
      "name": "Wood_Sallow_Trunk_Full",
      "support": 15,
      "rotation": 2
    },
    {
      "x": -4,
      "y": 52,
      "z": 5,
      "name": "Wood_Sallow_Branch_Long",
      "support": 15,
      "rotation": 2
    },
    {
      "x": -4,
      "y": 53,
      "z": 5,
      "name": "Wood_Sallow_Branch_Long",
      "support": 15,
      "rotation": 2
    },
    {
      "x": -4,
      "y": 54,
      "z": 5,
      "name": "Plant_Leaves_Beech",
      "support": 15,
      "rotation": 2
    },
    {
      "x": -4,
      "y": 59,
      "z": 5,
      "name": "Plant_Leaves_Beech",
      "support": 15,
      "rotation": 2
    },
    {
      "x": -4,
      "y": 60,
      "z": 5,
      "name": "Plant_Leaves_Beech",
      "support": 15,
      "rotation": 2
    },
    {
      "x": -4,
      "y": 0,
      "z": 6,
      "name": "Wood_Sallow_Trunk",
      "support": 15,
      "rotation": 2
    },
    {
      "x": -4,
      "y": 1,
      "z": 6,
      "name": "Wood_Sallow_Trunk",
      "support": 15,
      "rotation": 2
    },
    {
      "x": -4,
      "y": 2,
      "z": 6,
      "name": "Wood_Sallow_Trunk",
      "support": 15,
      "rotation": 2
    },
    {
      "x": -4,
      "y": 3,
      "z": 6,
      "name": "Wood_Sallow_Trunk_Full",
      "support": 15,
      "rotation": 2
    },
    {
      "x": -4,
      "y": 20,
      "z": 6,
      "name": "Furniture_Crude_Platform",
      "rotation": 1
    },
    {
      "x": -4,
      "y": 21,
      "z": 6,
      "name": "*Wood_Softwood_Fence_State_Definitions_Corner",
      "rotation": 2
    },
    {
      "x": -4,
      "y": 22,
      "z": 6,
      "name": "*Wood_Softwood_Fence_State_Definitions_Corner",
      "rotation": 2
    },
    {
      "x": -4,
      "y": 23,
      "z": 6,
      "name": "*Wood_Softwood_Fence_State_Definitions_Corner",
      "rotation": 2
    },
    {
      "x": -4,
      "y": 24,
      "z": 6,
      "name": "*Wood_Tropicalwood_Roof_State_Definitions_Corner_Right"
    },
    {
      "x": -4,
      "y": 51,
      "z": 6,
      "name": "Wood_Sallow_Trunk_Full",
      "support": 15,
      "rotation": 7
    },
    {
      "x": -4,
      "y": 53,
      "z": 6,
      "name": "Plant_Leaves_Beech",
      "support": 15,
      "rotation": 2
    },
    {
      "x": -4,
      "y": 56,
      "z": 6,
      "name": "Wood_Sallow_Branch_Long",
      "support": 15,
      "rotation": 7
    },
    {
      "x": -4,
      "y": 0,
      "z": 7,
      "name": "Wood_Sallow_Trunk",
      "support": 15,
      "rotation": 2
    },
    {
      "x": -4,
      "y": 1,
      "z": 7,
      "name": "Wood_Sallow_Trunk",
      "support": 15,
      "rotation": 2
    },
    {
      "x": -4,
      "y": 2,
      "z": 7,
      "name": "Wood_Sallow_Trunk_Full",
      "support": 15,
      "rotation": 2
    },
    {
      "x": -4,
      "y": 56,
      "z": 7,
      "name": "Plant_Leaves_Beech",
      "support": 15,
      "rotation": 2
    },
    {
      "x": -4,
      "y": 57,
      "z": 7,
      "name": "Plant_Leaves_Beech",
      "support": 15,
      "rotation": 2
    },
    {
      "x": -3,
      "y": 0,
      "z": -10,
      "name": "Wood_Sallow_Trunk_Full",
      "support": 15,
      "rotation": 2
    },
    {
      "x": -3,
      "y": 0,
      "z": -9,
      "name": "Wood_Sallow_Trunk_Full",
      "support": 15,
      "rotation": 2
    },
    {
      "x": -3,
      "y": 1,
      "z": -7,
      "name": "Plant_Moss_Wall_Green_Dark",
      "support": 15,
      "rotation": 3
    },
    {
      "x": -3,
      "y": 49,
      "z": -7,
      "name": "Plant_Leaves_Beech",
      "support": 15,
      "rotation": 2
    },
    {
      "x": -3,
      "y": 50,
      "z": -7,
      "name": "Plant_Leaves_Beech",
      "support": 15,
      "rotation": 2
    },
    {
      "x": -3,
      "y": 48,
      "z": -6,
      "name": "Plant_Leaves_Beech",
      "support": 15,
      "rotation": 2
    },
    {
      "x": -3,
      "y": 49,
      "z": -6,
      "name": "Wood_Sallow_Branch_Corner",
      "support": 15,
      "rotation": 3
    },
    {
      "x": -3,
      "y": 50,
      "z": -6,
      "name": "Wood_Sallow_Branch_Long",
      "support": 15,
      "rotation": 2
    },
    {
      "x": -3,
      "y": 51,
      "z": -6,
      "name": "Plant_Leaves_Beech",
      "support": 15,
      "rotation": 2
    },
    {
      "x": -3,
      "y": 53,
      "z": -6,
      "name": "Plant_Leaves_Beech",
      "support": 15,
      "rotation": 2
    },
    {
      "x": -3,
      "y": 54,
      "z": -6,
      "name": "Plant_Leaves_Beech",
      "support": 15,
      "rotation": 2
    },
    {
      "x": -3,
      "y": 20,
      "z": -5,
      "name": "Furniture_Crude_Platform"
    },
    {
      "x": -3,
      "y": 21,
      "z": -5,
      "name": "*Wood_Softwood_Fence_State_Definitions_Corner",
      "rotation": 1
    },
    {
      "x": -3,
      "y": 22,
      "z": -5,
      "name": "*Wood_Softwood_Fence_State_Definitions_Corner",
      "rotation": 1
    },
    {
      "x": -3,
      "y": 23,
      "z": -5,
      "name": "*Wood_Softwood_Fence_State_Definitions_Corner",
      "rotation": 1
    },
    {
      "x": -3,
      "y": 24,
      "z": -5,
      "name": "*Wood_Tropicalwood_Roof_State_Definitions_Corner_Right",
      "rotation": 3
    },
    {
      "x": -3,
      "y": 49,
      "z": -5,
      "name": "Plant_Leaves_Beech",
      "support": 15,
      "rotation": 2
    },
    {
      "x": -3,
      "y": 50,
      "z": -5,
      "name": "Plant_Leaves_Beech",
      "support": 15,
      "rotation": 2
    },
    {
      "x": -3,
      "y": 53,
      "z": -5,
      "name": "Plant_Leaves_Beech",
      "support": 15,
      "rotation": 2
    },
    {
      "x": -3,
      "y": 56,
      "z": -5,
      "name": "Plant_Leaves_Beech",
      "support": 15,
      "rotation": 2
    },
    {
      "x": -3,
      "y": 20,
      "z": -4,
      "name": "Furniture_Crude_Platform",
      "rotation": 1
    },
    {
      "x": -3,
      "y": 21,
      "z": -4,
      "name": "*Wood_Softwood_Fence_State_Definitions_Corner",
      "rotation": 3
    },
    {
      "x": -3,
      "y": 22,
      "z": -4,
      "name": "*Wood_Softwood_Fence_State_Definitions_Corner",
      "rotation": 3
    },
    {
      "x": -3,
      "y": 23,
      "z": -4,
      "name": "*Wood_Softwood_Fence_State_Definitions_Corner",
      "rotation": 3
    },
    {
      "x": -3,
      "y": 24,
      "z": -4,
      "name": "*Wood_Tropicalwood_Roof_State_Definitions_Inverted_Corner_Left",
      "rotation": 2
    },
    {
      "x": -3,
      "y": 55,
      "z": -4,
      "name": "Plant_Leaves_Beech",
      "support": 15,
      "rotation": 2
    },
    {
      "x": -3,
      "y": 20,
      "z": -3,
      "name": "Wood_Goldenwood_Planks_Half",
      "rotation": 8
    },
    {
      "x": -3,
      "y": 25,
      "z": -3,
      "name": "*Wood_Tropicalwood_Roof_Shallow_State_Definitions_Corner_Left",
      "rotation": 2
    },
    {
      "x": -3,
      "y": 53,
      "z": -3,
      "name": "Wood_Sallow_Trunk_Full",
      "support": 15,
      "rotation": 6
    },
    {
      "x": -3,
      "y": 57,
      "z": -3,
      "name": "Plant_Leaves_Beech",
      "support": 15,
      "rotation": 2
    },
    {
      "x": -3,
      "y": 0,
      "z": -2,
      "name": "Wood_Sallow_Trunk",
      "support": 15,
      "rotation": 2
    },
    {
      "x": -3,
      "y": 1,
      "z": -2,
      "name": "Wood_Sallow_Trunk",
      "support": 15,
      "rotation": 2
    },
    {
      "x": -3,
      "y": 2,
      "z": -2,
      "name": "Wood_Sallow_Trunk",
      "support": 15,
      "rotation": 2
    },
    {
      "x": -3,
      "y": 3,
      "z": -2,
      "name": "Wood_Sallow_Trunk",
      "support": 15,
      "rotation": 2
    },
    {
      "x": -3,
      "y": 4,
      "z": -2,
      "name": "Wood_Sallow_Trunk",
      "support": 15,
      "rotation": 2
    },
    {
      "x": -3,
      "y": 5,
      "z": -2,
      "name": "Wood_Sallow_Trunk_Full",
      "support": 15,
      "rotation": 2
    },
    {
      "x": -3,
      "y": 20,
      "z": -2,
      "name": "Wood_Goldenwood_Planks_Half",
      "rotation": 8
    },
    {
      "x": -3,
      "y": 25,
      "z": -2,
      "name": "*Wood_Tropicalwood_Roof_Shallow_State_Definitions_Corner_Left",
      "filler": 32,
      "rotation": 2
    },
    {
      "x": -3,
      "y": 53,
      "z": -2,
      "name": "Wood_Sallow_Trunk_Full",
      "support": 15,
      "rotation": 7
    },
    {
      "x": -3,
      "y": 0,
      "z": -1,
      "name": "Wood_Sallow_Trunk",
      "support": 15,
      "rotation": 2
    },
    {
      "x": -3,
      "y": 1,
      "z": -1,
      "name": "Wood_Sallow_Trunk",
      "support": 15,
      "rotation": 2
    },
    {
      "x": -3,
      "y": 2,
      "z": -1,
      "name": "Wood_Sallow_Trunk",
      "support": 15,
      "rotation": 2
    },
    {
      "x": -3,
      "y": 3,
      "z": -1,
      "name": "Wood_Sallow_Trunk",
      "support": 15,
      "rotation": 2
    },
    {
      "x": -3,
      "y": 4,
      "z": -1,
      "name": "Wood_Sallow_Trunk",
      "support": 15,
      "rotation": 2
    },
    {
      "x": -3,
      "y": 5,
      "z": -1,
      "name": "Wood_Sallow_Trunk_Full",
      "support": 15,
      "rotation": 2
    },
    {
      "x": -3,
      "y": 20,
      "z": -1,
      "name": "Wood_Goldenwood_Planks_Half",
      "rotation": 8
    },
    {
      "x": -3,
      "y": 25,
      "z": -1,
      "name": "Wood_Tropicalwood_Roof_Shallow",
      "rotation": 3
    },
    {
      "x": -3,
      "y": 0,
      "z": 0,
      "name": "Wood_Sallow_Trunk",
      "support": 15,
      "rotation": 2
    },
    {
      "x": -3,
      "y": 1,
      "z": 0,
      "name": "Wood_Sallow_Trunk",
      "support": 15,
      "rotation": 2
    },
    {
      "x": -3,
      "y": 2,
      "z": 0,
      "name": "Wood_Sallow_Trunk_Full",
      "support": 15,
      "rotation": 2
    },
    {
      "x": -3,
      "y": 20,
      "z": 0,
      "name": "Wood_Goldenwood_Planks_Half",
      "rotation": 8
    },
    {
      "x": -3,
      "y": 21,
      "z": 0,
      "name": "Furniture_Village_Table",
      "filler": 992,
      "rotation": 2
    },
    {
      "x": -3,
      "y": 25,
      "z": 0,
      "name": "Wood_Tropicalwood_Roof_Shallow",
      "filler": 1,
      "rotation": 3
    },
    {
      "x": -3,
      "y": 50,
      "z": 0,
      "name": "Wood_Sallow_Branch_Long",
      "support": 15,
      "rotation": 7
    },
    {
      "x": -3,
      "y": 55,
      "z": 0,
      "name": "Plant_Leaves_Beech",
      "support": 15,
      "rotation": 2
    },
    {
      "x": -3,
      "y": 56,
      "z": 0,
      "name": "Plant_Leaves_Beech",
      "support": 15,
      "rotation": 2
    },
    {
      "x": -3,
      "y": 0,
      "z": 1,
      "name": "Wood_Sallow_Trunk",
      "support": 15,
      "rotation": 2
    },
    {
      "x": -3,
      "y": 1,
      "z": 1,
      "name": "Wood_Sallow_Trunk",
      "support": 15,
      "rotation": 2
    },
    {
      "x": -3,
      "y": 2,
      "z": 1,
      "name": "Wood_Sallow_Trunk",
      "support": 15,
      "rotation": 2
    },
    {
      "x": -3,
      "y": 3,
      "z": 1,
      "name": "Wood_Sallow_Trunk",
      "support": 15,
      "rotation": 2
    },
    {
      "x": -3,
      "y": 4,
      "z": 1,
      "name": "Wood_Sallow_Trunk_Full",
      "support": 15,
      "rotation": 2
    },
    {
      "x": -3,
      "y": 18,
      "z": 1,
      "name": "Wood_Sallow_Trunk_Half",
      "rotation": 7
    },
    {
      "x": -3,
      "y": 19,
      "z": 1,
      "name": "Wood_Sallow_Trunk",
      "support": 15
    },
    {
      "x": -3,
      "y": 20,
      "z": 1,
      "name": "*Wood_Goldenwood_Planks_Half_State_Definitions_Block",
      "rotation": 8
    },
    {
      "x": -3,
      "y": 21,
      "z": 1,
      "name": "Furniture_Village_Table",
      "rotation": 2
    },
    {
      "x": -3,
      "y": 25,
      "z": 1,
      "name": "Wood_Tropicalwood_Roof_Shallow",
      "filler": 1,
      "rotation": 3
    },
    {
      "x": -3,
      "y": 47,
      "z": 1,
      "name": "Wood_Sallow_Branch_Long",
      "support": 15,
      "rotation": 7
    },
    {
      "x": -3,
      "y": 20,
      "z": 2,
      "name": "Wood_Goldenwood_Planks_Half",
      "rotation": 8
    },
    {
      "x": -3,
      "y": 25,
      "z": 2,
      "name": "Wood_Tropicalwood_Roof_Shallow",
      "filler": 1,
      "rotation": 3
    },
    {
      "x": -3,
      "y": 0,
      "z": 3,
      "name": "Wood_Sallow_Trunk",
      "support": 15,
      "rotation": 2
    },
    {
      "x": -3,
      "y": 1,
      "z": 3,
      "name": "Wood_Sallow_Trunk",
      "support": 15,
      "rotation": 2
    },
    {
      "x": -3,
      "y": 2,
      "z": 3,
      "name": "Wood_Sallow_Trunk_Full",
      "support": 15,
      "rotation": 2
    },
    {
      "x": -3,
      "y": 3,
      "z": 3,
      "name": "Plant_Moss_Rug_Green_Dark",
      "support": 15,
      "rotation": 2
    },
    {
      "x": -3,
      "y": 20,
      "z": 3,
      "name": "Wood_Goldenwood_Planks_Half",
      "rotation": 8
    },
    {
      "x": -3,
      "y": 25,
      "z": 3,
      "name": "Wood_Tropicalwood_Roof_Shallow",
      "rotation": 3
    },
    {
      "x": -3,
      "y": 55,
      "z": 3,
      "name": "Wood_Sallow_Branch_Long",
      "support": 15,
      "rotation": 7
    },
    {
      "x": -3,
      "y": 0,
      "z": 4,
      "name": "Wood_Sallow_Trunk",
      "support": 15,
      "rotation": 2
    },
    {
      "x": -3,
      "y": 1,
      "z": 4,
      "name": "Wood_Sallow_Trunk",
      "support": 15,
      "rotation": 2
    },
    {
      "x": -3,
      "y": 2,
      "z": 4,
      "name": "Wood_Sallow_Trunk_Full",
      "support": 15,
      "rotation": 2
    },
    {
      "x": -3,
      "y": 3,
      "z": 4,
      "name": "Plant_Moss_Rug_Green_Dark",
      "support": 15,
      "rotation": 2
    },
    {
      "x": -3,
      "y": 5,
      "z": 4,
      "name": "Plant_Moss_Wall_Green_Dark",
      "support": 15,
      "rotation": 3
    },
    {
      "x": -3,
      "y": 20,
      "z": 4,
      "name": "Wood_Goldenwood_Planks_Half",
      "rotation": 8
    },
    {
      "x": -3,
      "y": 25,
      "z": 4,
      "name": "*Wood_Tropicalwood_Roof_Shallow_State_Definitions_Corner_Left",
      "filler": 992,
      "rotation": 3
    },
    {
      "x": -3,
      "y": 50,
      "z": 4,
      "name": "Wood_Sallow_Trunk_Full",
      "support": 15,
      "rotation": 7
    },
    {
      "x": -3,
      "y": 58,
      "z": 4,
      "name": "Wood_Sallow_Branch_Long",
      "support": 15,
      "rotation": 7
    },
    {
      "x": -3,
      "y": 60,
      "z": 4,
      "name": "Plant_Leaves_Beech",
      "support": 15,
      "rotation": 2
    },
    {
      "x": -3,
      "y": 0,
      "z": 5,
      "name": "Wood_Sallow_Trunk",
      "support": 15,
      "rotation": 2
    },
    {
      "x": -3,
      "y": 1,
      "z": 5,
      "name": "Wood_Sallow_Trunk",
      "support": 15,
      "rotation": 2
    },
    {
      "x": -3,
      "y": 2,
      "z": 5,
      "name": "Wood_Sallow_Trunk",
      "support": 15,
      "rotation": 2
    },
    {
      "x": -3,
      "y": 3,
      "z": 5,
      "name": "Wood_Sallow_Trunk",
      "support": 15,
      "rotation": 2
    },
    {
      "x": -3,
      "y": 4,
      "z": 5,
      "name": "Wood_Sallow_Trunk_Full",
      "support": 15,
      "rotation": 2
    },
    {
      "x": -3,
      "y": 20,
      "z": 5,
      "name": "Wood_Goldenwood_Planks_Half",
      "rotation": 8
    },
    {
      "x": -3,
      "y": 25,
      "z": 5,
      "name": "*Wood_Tropicalwood_Roof_Shallow_State_Definitions_Corner_Left",
      "rotation": 3
    },
    {
      "x": -3,
      "y": 50,
      "z": 5,
      "name": "Wood_Sallow_Trunk_Full",
      "support": 15,
      "rotation": 6
    },
    {
      "x": -3,
      "y": 53,
      "z": 5,
      "name": "Plant_Leaves_Beech",
      "support": 15,
      "rotation": 2
    },
    {
      "x": -3,
      "y": 56,
      "z": 5,
      "name": "Wood_Sallow_Branch_Corner",
      "support": 15,
      "rotation": 51
    },
    {
      "x": -3,
      "y": 0,
      "z": 6,
      "name": "Wood_Sallow_Trunk",
      "support": 15,
      "rotation": 2
    },
    {
      "x": -3,
      "y": 1,
      "z": 6,
      "name": "Wood_Sallow_Trunk",
      "support": 15,
      "rotation": 2
    },
    {
      "x": -3,
      "y": 2,
      "z": 6,
      "name": "Wood_Sallow_Trunk",
      "support": 15,
      "rotation": 2
    },
    {
      "x": -3,
      "y": 3,
      "z": 6,
      "name": "Wood_Sallow_Trunk_Full",
      "support": 15,
      "rotation": 2
    },
    {
      "x": -3,
      "y": 20,
      "z": 6,
      "name": "Furniture_Crude_Platform",
      "rotation": 1
    },
    {
      "x": -3,
      "y": 21,
      "z": 6,
      "name": "*Wood_Softwood_Fence_State_Definitions_Corner"
    },
    {
      "x": -3,
      "y": 22,
      "z": 6,
      "name": "*Wood_Softwood_Fence_State_Definitions_Corner"
    },
    {
      "x": -3,
      "y": 23,
      "z": 6,
      "name": "*Wood_Softwood_Fence_State_Definitions_Corner"
    },
    {
      "x": -3,
      "y": 24,
      "z": 6,
      "name": "*Wood_Tropicalwood_Roof_State_Definitions_Inverted_Corner_Left",
      "rotation": 3
    },
    {
      "x": -3,
      "y": 56,
      "z": 6,
      "name": "Wood_Sallow_Branch_Corner",
      "support": 15,
      "rotation": 16
    },
    {
      "x": -3,
      "y": 58,
      "z": 6,
      "name": "Plant_Leaves_Beech",
      "support": 15,
      "rotation": 2
    },
    {
      "x": -3,
      "y": 59,
      "z": 6,
      "name": "Plant_Leaves_Beech",
      "support": 15,
      "rotation": 2
    },
    {
      "x": -3,
      "y": 20,
      "z": 7,
      "name": "Furniture_Crude_Platform"
    },
    {
      "x": -3,
      "y": 21,
      "z": 7,
      "name": "*Wood_Softwood_Fence_State_Definitions_Corner",
      "rotation": 2
    },
    {
      "x": -3,
      "y": 22,
      "z": 7,
      "name": "*Wood_Softwood_Fence_State_Definitions_Corner",
      "rotation": 2
    },
    {
      "x": -3,
      "y": 23,
      "z": 7,
      "name": "*Wood_Softwood_Fence_State_Definitions_Corner",
      "rotation": 2
    },
    {
      "x": -3,
      "y": 24,
      "z": 7,
      "name": "*Wood_Tropicalwood_Roof_State_Definitions_Corner_Right"
    },
    {
      "x": -3,
      "y": 57,
      "z": 7,
      "name": "Plant_Leaves_Beech",
      "support": 15,
      "rotation": 2
    },
    {
      "x": -3,
      "y": 58,
      "z": 7,
      "name": "Plant_Leaves_Beech",
      "support": 15,
      "rotation": 2
    },
    {
      "x": -3,
      "y": 50,
      "z": 8,
      "name": "Plant_Leaves_Beech",
      "support": 15,
      "rotation": 2
    },
    {
      "x": -3,
      "y": 51,
      "z": 8,
      "name": "Plant_Leaves_Beech",
      "support": 15,
      "rotation": 2
    },
    {
      "x": -3,
      "y": 51,
      "z": 9,
      "name": "Plant_Leaves_Beech",
      "support": 15,
      "rotation": 2
    },
    {
      "x": -2,
      "y": 0,
      "z": -9,
      "name": "Wood_Sallow_Trunk_Full",
      "support": 15,
      "rotation": 2
    },
    {
      "x": -2,
      "y": 0,
      "z": -8,
      "name": "Wood_Sallow_Trunk",
      "support": 15,
      "rotation": 2
    },
    {
      "x": -2,
      "y": 1,
      "z": -8,
      "name": "Wood_Sallow_Trunk_Full",
      "support": 15,
      "rotation": 2
    },
    {
      "x": -2,
      "y": 0,
      "z": -7,
      "name": "Wood_Sallow_Trunk",
      "support": 15,
      "rotation": 2
    },
    {
      "x": -2,
      "y": 1,
      "z": -7,
      "name": "Wood_Sallow_Trunk_Full",
      "support": 15,
      "rotation": 2
    },
    {
      "x": -2,
      "y": 2,
      "z": -7,
      "name": "Plant_Moss_Rug_Green_Dark",
      "support": 15,
      "rotation": 2
    },
    {
      "x": -2,
      "y": 49,
      "z": -7,
      "name": "Plant_Leaves_Beech",
      "support": 15,
      "rotation": 2
    },
    {
      "x": -2,
      "y": 53,
      "z": -7,
      "name": "Plant_Leaves_Beech",
      "support": 15,
      "rotation": 2
    },
    {
      "x": -2,
      "y": 54,
      "z": -7,
      "name": "Plant_Leaves_Beech",
      "support": 15,
      "rotation": 2
    },
    {
      "x": -2,
      "y": 3,
      "z": -6,
      "name": "Plant_Moss_Wall_Green_Dark",
      "support": 15,
      "rotation": 3
    },
    {
      "x": -2,
      "y": 49,
      "z": -6,
      "name": "Wood_Sallow_Branch_Corner",
      "support": 15,
      "rotation": 50
    },
    {
      "x": -2,
      "y": 50,
      "z": -6,
      "name": "Plant_Leaves_Beech",
      "support": 15,
      "rotation": 2
    },
    {
      "x": -2,
      "y": 52,
      "z": -6,
      "name": "Plant_Leaves_Beech",
      "support": 15,
      "rotation": 2
    },
    {
      "x": -2,
      "y": 53,
      "z": -6,
      "name": "Wood_Sallow_Branch_Corner",
      "support": 15,
      "rotation": 2
    },
    {
      "x": -2,
      "y": 54,
      "z": -6,
      "name": "Wood_Sallow_Branch_Long",
      "support": 15,
      "rotation": 2
    },
    {
      "x": -2,
      "y": 55,
      "z": -6,
      "name": "Plant_Leaves_Beech",
      "support": 15,
      "rotation": 2
    },
    {
      "x": -2,
      "y": 20,
      "z": -5,
      "name": "Furniture_Crude_Platform"
    },
    {
      "x": -2,
      "y": 21,
      "z": -5,
      "name": "Wood_Softwood_Fence",
      "rotation": 2
    },
    {
      "x": -2,
      "y": 22,
      "z": -5,
      "name": "Wood_Goldenwood_Fence",
      "rotation": 2
    },
    {
      "x": -2,
      "y": 23,
      "z": -5,
      "name": "Wood_Softwood_Fence",
      "rotation": 2
    },
    {
      "x": -2,
      "y": 24,
      "z": -5,
      "name": "Wood_Tropicalwood_Roof",
      "rotation": 2
    },
    {
      "x": -2,
      "y": 49,
      "z": -5,
      "name": "Wood_Sallow_Branch_Long",
      "support": 15,
      "rotation": 6
    },
    {
      "x": -2,
      "y": 52,
      "z": -5,
      "name": "Plant_Leaves_Beech",
      "support": 15,
      "rotation": 2
    },
    {
      "x": -2,
      "y": 53,
      "z": -5,
      "name": "Wood_Sallow_Branch_Long",
      "support": 15,
      "rotation": 6
    },
    {
      "x": -2,
      "y": 54,
      "z": -5,
      "name": "Plant_Leaves_Beech",
      "support": 15,
      "rotation": 2
    },
    {
      "x": -2,
      "y": 57,
      "z": -5,
      "name": "Plant_Leaves_Beech",
      "support": 15,
      "rotation": 2
    },
    {
      "x": -2,
      "y": 58,
      "z": -5,
      "name": "Plant_Leaves_Beech",
      "support": 15,
      "rotation": 2
    },
    {
      "x": -2,
      "y": 20,
      "z": -4,
      "name": "Wood_Goldenwood_Planks_Half",
      "rotation": 8
    },
    {
      "x": -2,
      "y": 21,
      "z": -4,
      "name": "Furniture_Crude_Chest_Small",
      "components": {
        "Components": {
          "PlacedByInteraction": {
            "WhoPlacedUuid": {
              "$binary": "i+Pl1XV4SJWc91StkZuWWA==",
              "$type": "04"
            }
          },
          "ItemContainerBlock": {
            "ItemContainer": {
              "Capacity": 18,
              "Items": {}
            },
            "Capacity": 18
          }
        }
      }
    },
    {
      "x": -2,
      "y": 25,
      "z": -4,
      "name": "Wood_Tropicalwood_Roof_Flat"
    },
    {
      "x": -2,
      "y": 49,
      "z": -4,
      "name": "Wood_Sallow_Branch_Corner",
      "support": 15,
      "rotation": 19
    },
    {
      "x": -2,
      "y": 53,
      "z": -4,
      "name": "Wood_Sallow_Branch_Long",
      "support": 15,
      "rotation": 6
    },
    {
      "x": -2,
      "y": 54,
      "z": -4,
      "name": "Plant_Leaves_Beech",
      "support": 15,
      "rotation": 2
    },
    {
      "x": -2,
      "y": 20,
      "z": -3,
      "name": "Wood_Goldenwood_Planks_Half",
      "rotation": 8
    },
    {
      "x": -2,
      "y": 25,
      "z": -3,
      "name": "*Wood_Tropicalwood_Roof_Shallow_State_Definitions_Corner_Left",
      "filler": 1,
      "rotation": 2
    },
    {
      "x": -2,
      "y": 53,
      "z": -3,
      "name": "Wood_Sallow_Branch_Long",
      "support": 15,
      "rotation": 6
    },
    {
      "x": -2,
      "y": 0,
      "z": -2,
      "name": "Wood_Sallow_Trunk",
      "support": 15,
      "rotation": 2
    },
    {
      "x": -2,
      "y": 1,
      "z": -2,
      "name": "Wood_Sallow_Trunk",
      "support": 15,
      "rotation": 2
    },
    {
      "x": -2,
      "y": 2,
      "z": -2,
      "name": "Wood_Sallow_Trunk_Full",
      "support": 15,
      "rotation": 2
    },
    {
      "x": -2,
      "y": 20,
      "z": -2,
      "name": "Wood_Goldenwood_Planks_Half",
      "rotation": 8
    },
    {
      "x": -2,
      "y": 25,
      "z": -2,
      "name": "*Wood_Tropicalwood_Roof_Shallow_State_Definitions_Corner_Left",
      "filler": 33,
      "rotation": 2
    },
    {
      "x": -2,
      "y": 52,
      "z": -2,
      "name": "Wood_Sallow_Trunk_Full",
      "support": 15,
      "rotation": 6
    },
    {
      "x": -2,
      "y": 53,
      "z": -2,
      "name": "Wood_Sallow_Trunk_Full",
      "support": 15,
      "rotation": 2
    },
    {
      "x": -2,
      "y": 0,
      "z": -1,
      "name": "Wood_Sallow_Trunk",
      "support": 15,
      "rotation": 2
    },
    {
      "x": -2,
      "y": 1,
      "z": -1,
      "name": "Wood_Sallow_Trunk",
      "support": 15,
      "rotation": 2
    },
    {
      "x": -2,
      "y": 2,
      "z": -1,
      "name": "Wood_Sallow_Trunk",
      "support": 15,
      "rotation": 2
    },
    {
      "x": -2,
      "y": 3,
      "z": -1,
      "name": "Wood_Sallow_Trunk",
      "support": 15,
      "rotation": 2
    },
    {
      "x": -2,
      "y": 4,
      "z": -1,
      "name": "Wood_Sallow_Trunk",
      "support": 15,
      "rotation": 2
    },
    {
      "x": -2,
      "y": 5,
      "z": -1,
      "name": "Wood_Sallow_Trunk",
      "support": 15,
      "rotation": 2
    },
    {
      "x": -2,
      "y": 6,
      "z": -1,
      "name": "Wood_Sallow_Trunk_Full",
      "support": 15,
      "rotation": 2
    },
    {
      "x": -2,
      "y": 20,
      "z": -1,
      "name": "Wood_Goldenwood_Planks_Half",
      "rotation": 8
    },
    {
      "x": -2,
      "y": 25,
      "z": -1,
      "name": "Wood_Tropicalwood_Roof_Shallow",
      "filler": 1,
      "rotation": 3
    },
    {
      "x": -2,
      "y": 52,
      "z": -1,
      "name": "Wood_Sallow_Trunk_Full",
      "support": 15,
      "rotation": 6
    },
    {
      "x": -2,
      "y": 55,
      "z": -1,
      "name": "Plant_Leaves_Beech",
      "support": 15,
      "rotation": 2
    },
    {
      "x": -2,
      "y": 56,
      "z": -1,
      "name": "Plant_Leaves_Beech",
      "support": 15,
      "rotation": 2
    },
    {
      "x": -2,
      "y": 0,
      "z": 0,
      "name": "Wood_Sallow_Trunk",
      "support": 15,
      "rotation": 2
    },
    {
      "x": -2,
      "y": 1,
      "z": 0,
      "name": "Wood_Sallow_Trunk",
      "support": 15,
      "rotation": 2
    },
    {
      "x": -2,
      "y": 2,
      "z": 0,
      "name": "Wood_Sallow_Trunk",
      "support": 15,
      "rotation": 2
    },
    {
      "x": -2,
      "y": 3,
      "z": 0,
      "name": "Wood_Sallow_Trunk",
      "support": 15,
      "rotation": 2
    },
    {
      "x": -2,
      "y": 4,
      "z": 0,
      "name": "Wood_Sallow_Trunk",
      "support": 15,
      "rotation": 2
    },
    {
      "x": -2,
      "y": 5,
      "z": 0,
      "name": "Wood_Sallow_Trunk",
      "support": 15,
      "rotation": 2
    },
    {
      "x": -2,
      "y": 6,
      "z": 0,
      "name": "Wood_Sallow_Trunk_Full",
      "support": 15,
      "rotation": 2
    },
    {
      "x": -2,
      "y": 20,
      "z": 0,
      "name": "Wood_Goldenwood_Planks_Half",
      "rotation": 8
    },
    {
      "x": -2,
      "y": 26,
      "z": 0,
      "name": "Wood_Tropicalwood_Roof_Flat",
      "rotation": 1
    },
    {
      "x": -2,
      "y": 50,
      "z": 0,
      "name": "Wood_Sallow_Branch_Long",
      "support": 15,
      "rotation": 7
    },
    {
      "x": -2,
      "y": 54,
      "z": 0,
      "name": "Plant_Leaves_Beech",
      "support": 15,
      "rotation": 2
    },
    {
      "x": -2,
      "y": 55,
      "z": 0,
      "name": "Wood_Sallow_Branch_Corner",
      "support": 15,
      "rotation": 3
    },
    {
      "x": -2,
      "y": 56,
      "z": 0,
      "name": "Wood_Sallow_Branch_Long",
      "support": 15,
      "rotation": 2
    },
    {
      "x": -2,
      "y": 57,
      "z": 0,
      "name": "Plant_Leaves_Beech",
      "support": 15,
      "rotation": 2
    },
    {
      "x": -2,
      "y": 0,
      "z": 1,
      "name": "Wood_Sallow_Trunk",
      "support": 15,
      "rotation": 2
    },
    {
      "x": -2,
      "y": 1,
      "z": 1,
      "name": "Wood_Sallow_Trunk",
      "support": 15,
      "rotation": 2
    },
    {
      "x": -2,
      "y": 2,
      "z": 1,
      "name": "Wood_Sallow_Trunk",
      "support": 15,
      "rotation": 2
    },
    {
      "x": -2,
      "y": 3,
      "z": 1,
      "name": "Wood_Sallow_Trunk",
      "support": 15,
      "rotation": 2
    },
    {
      "x": -2,
      "y": 4,
      "z": 1,
      "name": "Wood_Sallow_Trunk",
      "support": 15,
      "rotation": 2
    },
    {
      "x": -2,
      "y": 5,
      "z": 1,
      "name": "Wood_Sallow_Trunk_Full",
      "support": 15,
      "rotation": 2
    },
    {
      "x": -2,
      "y": 14,
      "z": 1,
      "name": "Plant_Moss_Wall_Green_Dark",
      "support": 15,
      "rotation": 3
    },
    {
      "x": -2,
      "y": 17,
      "z": 1,
      "name": "Wood_Sallow_Trunk_Half",
      "rotation": 7
    },
    {
      "x": -2,
      "y": 18,
      "z": 1,
      "name": "Wood_Sallow_Trunk",
      "support": 15
    },
    {
      "x": -2,
      "y": 19,
      "z": 1,
      "name": "Wood_Sallow_Trunk_Half",
      "rotation": 5
    },
    {
      "x": -2,
      "y": 20,
      "z": 1,
      "name": "Wood_Goldenwood_Planks_Half",
      "rotation": 8
    },
    {
      "x": -2,
      "y": 26,
      "z": 1,
      "name": "Wood_Tropicalwood_Roof_Flat",
      "rotation": 1
    },
    {
      "x": -2,
      "y": 38,
      "z": 1,
      "name": "Plant_Vine_Liana",
      "support": 15,
      "rotation": 3
    },
    {
      "x": -2,
      "y": 39,
      "z": 1,
      "name": "Plant_Vine_Liana",
      "support": 15,
      "rotation": 3
    },
    {
      "x": -2,
      "y": 40,
      "z": 1,
      "name": "Plant_Vine_Liana",
      "support": 15,
      "rotation": 3
    },
    {
      "x": -2,
      "y": 41,
      "z": 1,
      "name": "Plant_Vine_Liana",
      "support": 15,
      "rotation": 3
    },
    {
      "x": -2,
      "y": 42,
      "z": 1,
      "name": "Plant_Vine_Liana",
      "support": 15,
      "rotation": 3
    },
    {
      "x": -2,
      "y": 43,
      "z": 1,
      "name": "Plant_Vine_Liana",
      "support": 15,
      "rotation": 3
    },
    {
      "x": -2,
      "y": 44,
      "z": 1,
      "name": "Plant_Vine_Liana",
      "support": 15,
      "rotation": 3
    },
    {
      "x": -2,
      "y": 45,
      "z": 1,
      "name": "Plant_Vine_Liana",
      "support": 15,
      "rotation": 3
    },
    {
      "x": -2,
      "y": 46,
      "z": 1,
      "name": "Plant_Vine_Liana",
      "support": 15,
      "rotation": 3
    },
    {
      "x": -2,
      "y": 47,
      "z": 1,
      "name": "Wood_Sallow_Branch_Long",
      "support": 15,
      "rotation": 7
    },
    {
      "x": -2,
      "y": 55,
      "z": 1,
      "name": "Plant_Leaves_Beech",
      "support": 15,
      "rotation": 2
    },
    {
      "x": -2,
      "y": 56,
      "z": 1,
      "name": "Plant_Leaves_Beech",
      "support": 15,
      "rotation": 2
    },
    {
      "x": -2,
      "y": 60,
      "z": 1,
      "name": "Plant_Leaves_Beech",
      "support": 15,
      "rotation": 2
    },
    {
      "x": -2,
      "y": 61,
      "z": 1,
      "name": "Plant_Leaves_Beech",
      "support": 15,
      "rotation": 2
    },
    {
      "x": -2,
      "y": 0,
      "z": 2,
      "name": "Wood_Sallow_Trunk",
      "support": 15,
      "rotation": 2
    },
    {
      "x": -2,
      "y": 1,
      "z": 2,
      "name": "Wood_Sallow_Trunk",
      "support": 15,
      "rotation": 2
    },
    {
      "x": -2,
      "y": 2,
      "z": 2,
      "name": "Wood_Sallow_Trunk",
      "support": 15,
      "rotation": 2
    },
    {
      "x": -2,
      "y": 3,
      "z": 2,
      "name": "Wood_Sallow_Trunk",
      "support": 15,
      "rotation": 2
    },
    {
      "x": -2,
      "y": 4,
      "z": 2,
      "name": "Wood_Sallow_Trunk",
      "support": 15,
      "rotation": 2
    },
    {
      "x": -2,
      "y": 5,
      "z": 2,
      "name": "Wood_Sallow_Trunk_Full",
      "support": 15,
      "rotation": 2
    },
    {
      "x": -2,
      "y": 20,
      "z": 2,
      "name": "Wood_Goldenwood_Planks_Half",
      "rotation": 8
    },
    {
      "x": -2,
      "y": 26,
      "z": 2,
      "name": "Wood_Tropicalwood_Roof_Flat",
      "rotation": 1
    },
    {
      "x": -2,
      "y": 47,
      "z": 2,
      "name": "Plant_Vine_Liana",
      "support": 15,
      "rotation": 3
    },
    {
      "x": -2,
      "y": 60,
      "z": 2,
      "name": "Plant_Leaves_Beech",
      "support": 15,
      "rotation": 2
    },
    {
      "x": -2,
      "y": 0,
      "z": 3,
      "name": "Wood_Sallow_Trunk",
      "support": 15,
      "rotation": 2
    },
    {
      "x": -2,
      "y": 1,
      "z": 3,
      "name": "Wood_Sallow_Trunk",
      "support": 15,
      "rotation": 2
    },
    {
      "x": -2,
      "y": 2,
      "z": 3,
      "name": "Wood_Sallow_Trunk",
      "support": 15,
      "rotation": 2
    },
    {
      "x": -2,
      "y": 3,
      "z": 3,
      "name": "Wood_Sallow_Trunk_Full",
      "support": 15,
      "rotation": 2
    },
    {
      "x": -2,
      "y": 20,
      "z": 3,
      "name": "Wood_Goldenwood_Planks_Half",
      "rotation": 8
    },
    {
      "x": -2,
      "y": 25,
      "z": 3,
      "name": "Wood_Tropicalwood_Roof_Shallow",
      "filler": 1,
      "rotation": 3
    },
    {
      "x": -2,
      "y": 49,
      "z": 3,
      "name": "Wood_Sallow_Trunk_Full",
      "support": 15,
      "rotation": 7
    },
    {
      "x": -2,
      "y": 55,
      "z": 3,
      "name": "Wood_Sallow_Branch_Long",
      "support": 15,
      "rotation": 7
    },
    {
      "x": -2,
      "y": 56,
      "z": 3,
      "name": "Wood_Sallow_Trunk_Full",
      "support": 15,
      "rotation": 7
    },
    {
      "x": -2,
      "y": 0,
      "z": 4,
      "name": "Wood_Sallow_Trunk",
      "support": 15,
      "rotation": 2
    },
    {
      "x": -2,
      "y": 1,
      "z": 4,
      "name": "Wood_Sallow_Trunk",
      "support": 15,
      "rotation": 2
    },
    {
      "x": -2,
      "y": 2,
      "z": 4,
      "name": "Wood_Sallow_Trunk",
      "support": 15,
      "rotation": 2
    },
    {
      "x": -2,
      "y": 3,
      "z": 4,
      "name": "Wood_Sallow_Trunk",
      "support": 15,
      "rotation": 2
    },
    {
      "x": -2,
      "y": 4,
      "z": 4,
      "name": "Wood_Sallow_Trunk",
      "support": 15,
      "rotation": 2
    },
    {
      "x": -2,
      "y": 5,
      "z": 4,
      "name": "Wood_Sallow_Trunk_Full",
      "support": 15,
      "rotation": 2
    },
    {
      "x": -2,
      "y": 6,
      "z": 4,
      "name": "Plant_Moss_Rug_Green_Dark",
      "support": 15,
      "rotation": 2
    },
    {
      "x": -2,
      "y": 20,
      "z": 4,
      "name": "Wood_Goldenwood_Planks_Half",
      "rotation": 8
    },
    {
      "x": -2,
      "y": 25,
      "z": 4,
      "name": "*Wood_Tropicalwood_Roof_Shallow_State_Definitions_Corner_Left",
      "filler": 993,
      "rotation": 3
    },
    {
      "x": -2,
      "y": 49,
      "z": 4,
      "name": "Wood_Sallow_Trunk_Full",
      "support": 15,
      "rotation": 6
    },
    {
      "x": -2,
      "y": 50,
      "z": 4,
      "name": "Wood_Sallow_Trunk_Full",
      "support": 15,
      "rotation": 2
    },
    {
      "x": -2,
      "y": 56,
      "z": 4,
      "name": "Wood_Sallow_Trunk_Full",
      "support": 15,
      "rotation": 6
    },
    {
      "x": -2,
      "y": 57,
      "z": 4,
      "name": "Wood_Sallow_Trunk",
      "support": 15,
      "rotation": 2
    },
    {
      "x": -2,
      "y": 58,
      "z": 4,
      "name": "Wood_Sallow_Trunk_Full",
      "support": 15,
      "rotation": 2
    },
    {
      "x": -2,
      "y": 59,
      "z": 4,
      "name": "Plant_Leaves_Beech",
      "support": 15,
      "rotation": 2
    },
    {
      "x": -2,
      "y": 0,
      "z": 5,
      "name": "Wood_Sallow_Trunk",
      "support": 15,
      "rotation": 2
    },
    {
      "x": -2,
      "y": 1,
      "z": 5,
      "name": "Wood_Sallow_Trunk",
      "support": 15,
      "rotation": 2
    },
    {
      "x": -2,
      "y": 2,
      "z": 5,
      "name": "Wood_Sallow_Trunk",
      "support": 15,
      "rotation": 2
    },
    {
      "x": -2,
      "y": 3,
      "z": 5,
      "name": "Wood_Sallow_Trunk",
      "support": 15,
      "rotation": 2
    },
    {
      "x": -2,
      "y": 4,
      "z": 5,
      "name": "Wood_Sallow_Trunk_Full",
      "support": 15,
      "rotation": 2
    },
    {
      "x": -2,
      "y": 5,
      "z": 5,
      "name": "Plant_Moss_Rug_Green_Dark",
      "support": 15,
      "rotation": 2
    },
    {
      "x": -2,
      "y": 20,
      "z": 5,
      "name": "Wood_Goldenwood_Planks_Half",
      "rotation": 8
    },
    {
      "x": -2,
      "y": 25,
      "z": 5,
      "name": "*Wood_Tropicalwood_Roof_Shallow_State_Definitions_Corner_Left",
      "filler": 1,
      "rotation": 3
    },
    {
      "x": -2,
      "y": 50,
      "z": 5,
      "name": "Wood_Sallow_Branch_Long",
      "support": 15,
      "rotation": 6
    },
    {
      "x": -2,
      "y": 56,
      "z": 5,
      "name": "Wood_Sallow_Branch_Corner",
      "support": 15,
      "rotation": 16
    },
    {
      "x": -2,
      "y": 58,
      "z": 5,
      "name": "Wood_Sallow_Branch_Long",
      "support": 15,
      "rotation": 6
    },
    {
      "x": -2,
      "y": 0,
      "z": 6,
      "name": "Wood_Sallow_Trunk",
      "support": 15,
      "rotation": 2
    },
    {
      "x": -2,
      "y": 1,
      "z": 6,
      "name": "Wood_Sallow_Trunk_Full",
      "support": 15,
      "rotation": 2
    },
    {
      "x": -2,
      "y": 4,
      "z": 6,
      "name": "Plant_Moss_Wall_Green_Dark",
      "support": 15
    },
    {
      "x": -2,
      "y": 20,
      "z": 6,
      "name": "Wood_Goldenwood_Planks_Half",
      "rotation": 8
    },
    {
      "x": -2,
      "y": 25,
      "z": 6,
      "name": "Wood_Tropicalwood_Roof_Flat",
      "rotation": 2
    },
    {
      "x": -2,
      "y": 50,
      "z": 6,
      "name": "Wood_Sallow_Branch_Long",
      "support": 15,
      "rotation": 6
    },
    {
      "x": -2,
      "y": 57,
      "z": 6,
      "name": "Plant_Leaves_Beech",
      "support": 15,
      "rotation": 2
    },
    {
      "x": -2,
      "y": 58,
      "z": 6,
      "name": "Wood_Sallow_Branch_Corner",
      "support": 15
    },
    {
      "x": -2,
      "y": 59,
      "z": 6,
      "name": "Plant_Leaves_Beech",
      "support": 15,
      "rotation": 2
    },
    {
      "x": -2,
      "y": 20,
      "z": 7,
      "name": "Furniture_Crude_Platform"
    },
    {
      "x": -2,
      "y": 21,
      "z": 7,
      "name": "Wood_Softwood_Fence"
    },
    {
      "x": -2,
      "y": 22,
      "z": 7,
      "name": "Wood_Goldenwood_Fence"
    },
    {
      "x": -2,
      "y": 23,
      "z": 7,
      "name": "Wood_Softwood_Fence"
    },
    {
      "x": -2,
      "y": 24,
      "z": 7,
      "name": "Wood_Tropicalwood_Roof"
    },
    {
      "x": -2,
      "y": 49,
      "z": 7,
      "name": "Plant_Leaves_Beech",
      "support": 15,
      "rotation": 2
    },
    {
      "x": -2,
      "y": 50,
      "z": 7,
      "name": "Wood_Sallow_Branch_Long",
      "support": 15,
      "rotation": 6
    },
    {
      "x": -2,
      "y": 51,
      "z": 7,
      "name": "Plant_Leaves_Beech",
      "support": 15,
      "rotation": 2
    },
    {
      "x": -2,
      "y": 57,
      "z": 7,
      "name": "Plant_Leaves_Beech",
      "support": 15,
      "rotation": 2
    },
    {
      "x": -2,
      "y": 58,
      "z": 7,
      "name": "Plant_Leaves_Beech",
      "support": 15,
      "rotation": 2
    },
    {
      "x": -2,
      "y": 59,
      "z": 7,
      "name": "Plant_Leaves_Beech",
      "support": 15,
      "rotation": 2
    },
    {
      "x": -2,
      "y": 49,
      "z": 8,
      "name": "Plant_Leaves_Beech",
      "support": 15,
      "rotation": 2
    },
    {
      "x": -2,
      "y": 50,
      "z": 8,
      "name": "Wood_Sallow_Branch_Corner",
      "support": 15
    },
    {
      "x": -2,
      "y": 51,
      "z": 8,
      "name": "Wood_Sallow_Branch_Long",
      "support": 15,
      "rotation": 2
    },
    {
      "x": -2,
      "y": 52,
      "z": 8,
      "name": "Plant_Leaves_Beech",
      "support": 15,
      "rotation": 2
    },
    {
      "x": -2,
      "y": 56,
      "z": 8,
      "name": "Plant_Leaves_Beech",
      "support": 15,
      "rotation": 2
    },
    {
      "x": -2,
      "y": 57,
      "z": 8,
      "name": "Plant_Leaves_Beech",
      "support": 15,
      "rotation": 2
    },
    {
      "x": -2,
      "y": 58,
      "z": 8,
      "name": "Plant_Leaves_Beech",
      "support": 15,
      "rotation": 2
    },
    {
      "x": -2,
      "y": 50,
      "z": 9,
      "name": "Plant_Leaves_Beech",
      "support": 15,
      "rotation": 2
    },
    {
      "x": -2,
      "y": 51,
      "z": 9,
      "name": "Plant_Leaves_Beech",
      "support": 15,
      "rotation": 2
    },
    {
      "x": -1,
      "y": 2,
      "z": -8,
      "name": "Plant_Moss_Wall_Green_Dark",
      "support": 15,
      "rotation": 2
    },
    {
      "x": -1,
      "y": 0,
      "z": -7,
      "name": "Wood_Sallow_Trunk",
      "support": 15,
      "rotation": 2
    },
    {
      "x": -1,
      "y": 1,
      "z": -7,
      "name": "Wood_Sallow_Trunk",
      "support": 15,
      "rotation": 2
    },
    {
      "x": -1,
      "y": 2,
      "z": -7,
      "name": "Wood_Sallow_Trunk_Full",
      "support": 15,
      "rotation": 2
    },
    {
      "x": -1,
      "y": 3,
      "z": -7,
      "name": "Plant_Moss_Rug_Green_Dark",
      "support": 15,
      "rotation": 2
    },
    {
      "x": -1,
      "y": 0,
      "z": -6,
      "name": "Wood_Sallow_Trunk",
      "support": 15,
      "rotation": 2
    },
    {
      "x": -1,
      "y": 1,
      "z": -6,
      "name": "Wood_Sallow_Trunk",
      "support": 15,
      "rotation": 2
    },
    {
      "x": -1,
      "y": 2,
      "z": -6,
      "name": "Wood_Sallow_Trunk",
      "support": 15,
      "rotation": 2
    },
    {
      "x": -1,
      "y": 3,
      "z": -6,
      "name": "Wood_Sallow_Trunk_Full",
      "support": 15,
      "rotation": 2
    },
    {
      "x": -1,
      "y": 4,
      "z": -6,
      "name": "Plant_Moss_Rug_Green_Dark",
      "support": 15,
      "rotation": 2
    },
    {
      "x": -1,
      "y": 20,
      "z": -6,
      "name": "Furniture_Crude_Platform"
    },
    {
      "x": -1,
      "y": 21,
      "z": -6,
      "name": "*Wood_Softwood_Fence_State_Definitions_Corner",
      "rotation": 1
    },
    {
      "x": -1,
      "y": 22,
      "z": -6,
      "name": "*Wood_Softwood_Fence_State_Definitions_Corner",
      "rotation": 1
    },
    {
      "x": -1,
      "y": 23,
      "z": -6,
      "name": "*Wood_Softwood_Fence_State_Definitions_Corner",
      "rotation": 1
    },
    {
      "x": -1,
      "y": 24,
      "z": -6,
      "name": "*Wood_Tropicalwood_Roof_State_Definitions_Corner_Right",
      "rotation": 3
    },
    {
      "x": -1,
      "y": 49,
      "z": -6,
      "name": "Plant_Leaves_Beech",
      "support": 15,
      "rotation": 2
    },
    {
      "x": -1,
      "y": 53,
      "z": -6,
      "name": "Plant_Leaves_Beech",
      "support": 15,
      "rotation": 2
    },
    {
      "x": -1,
      "y": 54,
      "z": -6,
      "name": "Plant_Leaves_Beech",
      "support": 15,
      "rotation": 2
    },
    {
      "x": -1,
      "y": 57,
      "z": -6,
      "name": "Plant_Leaves_Beech",
      "support": 15,
      "rotation": 2
    },
    {
      "x": -1,
      "y": 58,
      "z": -6,
      "name": "Plant_Leaves_Beech",
      "support": 15,
      "rotation": 2
    },
    {
      "x": -1,
      "y": 0,
      "z": -5,
      "name": "Wood_Sallow_Trunk",
      "support": 15,
      "rotation": 2
    },
    {
      "x": -1,
      "y": 1,
      "z": -5,
      "name": "Wood_Sallow_Trunk",
      "support": 15,
      "rotation": 2
    },
    {
      "x": -1,
      "y": 2,
      "z": -5,
      "name": "Wood_Sallow_Trunk",
      "support": 15,
      "rotation": 2
    },
    {
      "x": -1,
      "y": 3,
      "z": -5,
      "name": "Wood_Sallow_Trunk_Full",
      "support": 15,
      "rotation": 2
    },
    {
      "x": -1,
      "y": 20,
      "z": -5,
      "name": "Furniture_Crude_Platform"
    },
    {
      "x": -1,
      "y": 21,
      "z": -5,
      "name": "*Wood_Softwood_Fence_State_Definitions_Corner",
      "rotation": 3
    },
    {
      "x": -1,
      "y": 22,
      "z": -5,
      "name": "*Wood_Softwood_Fence_State_Definitions_Corner",
      "rotation": 3
    },
    {
      "x": -1,
      "y": 23,
      "z": -5,
      "name": "*Wood_Softwood_Fence_State_Definitions_Corner",
      "rotation": 3
    },
    {
      "x": -1,
      "y": 24,
      "z": -5,
      "name": "*Wood_Tropicalwood_Roof_State_Definitions_Inverted_Corner_Left",
      "rotation": 2
    },
    {
      "x": -1,
      "y": 56,
      "z": -5,
      "name": "Plant_Leaves_Beech",
      "support": 15,
      "rotation": 2
    },
    {
      "x": -1,
      "y": 57,
      "z": -5,
      "name": "Wood_Sallow_Branch_Corner",
      "support": 15,
      "rotation": 3
    },
    {
      "x": -1,
      "y": 58,
      "z": -5,
      "name": "Wood_Sallow_Branch_Long",
      "support": 15,
      "rotation": 2
    },
    {
      "x": -1,
      "y": 59,
      "z": -5,
      "name": "Plant_Leaves_Beech",
      "support": 15,
      "rotation": 2
    },
    {
      "x": -1,
      "y": 20,
      "z": -4,
      "name": "Wood_Goldenwood_Planks_Half",
      "rotation": 8
    },
    {
      "x": -1,
      "y": 25,
      "z": -4,
      "name": "Wood_Tropicalwood_Roof_Flat"
    },
    {
      "x": -1,
      "y": 49,
      "z": -4,
      "name": "Wood_Sallow_Branch_Long",
      "support": 15,
      "rotation": 7
    },
    {
      "x": -1,
      "y": 57,
      "z": -4,
      "name": "Plant_Leaves_Beech",
      "support": 15,
      "rotation": 2
    },
    {
      "x": -1,
      "y": 58,
      "z": -4,
      "name": "Plant_Leaves_Beech",
      "support": 15,
      "rotation": 2
    },
    {
      "x": -1,
      "y": 0,
      "z": -3,
      "name": "Wood_Sallow_Trunk",
      "support": 15,
      "rotation": 2
    },
    {
      "x": -1,
      "y": 1,
      "z": -3,
      "name": "Wood_Sallow_Trunk",
      "support": 15,
      "rotation": 2
    },
    {
      "x": -1,
      "y": 2,
      "z": -3,
      "name": "Wood_Sallow_Trunk_Full",
      "support": 15,
      "rotation": 2
    },
    {
      "x": -1,
      "y": 20,
      "z": -3,
      "name": "Wood_Goldenwood_Planks_Half",
      "rotation": 8
    },
    {
      "x": -1,
      "y": 25,
      "z": -3,
      "name": "Wood_Tropicalwood_Roof_Shallow",
      "rotation": 2
    },
    {
      "x": -1,
      "y": 58,
      "z": -3,
      "name": "Plant_Leaves_Beech",
      "support": 15,
      "rotation": 2
    },
    {
      "x": -1,
      "y": 0,
      "z": -2,
      "name": "Wood_Sallow_Trunk",
      "support": 15,
      "rotation": 2
    },
    {
      "x": -1,
      "y": 1,
      "z": -2,
      "name": "Wood_Sallow_Trunk",
      "support": 15,
      "rotation": 2
    },
    {
      "x": -1,
      "y": 2,
      "z": -2,
      "name": "Wood_Sallow_Trunk",
      "support": 15,
      "rotation": 2
    },
    {
      "x": -1,
      "y": 3,
      "z": -2,
      "name": "Wood_Sallow_Trunk",
      "support": 15,
      "rotation": 2
    },
    {
      "x": -1,
      "y": 4,
      "z": -2,
      "name": "Wood_Sallow_Trunk_Full",
      "support": 15,
      "rotation": 2
    },
    {
      "x": -1,
      "y": 20,
      "z": -2,
      "name": "Wood_Goldenwood_Planks_Half",
      "rotation": 8
    },
    {
      "x": -1,
      "y": 25,
      "z": -2,
      "name": "Wood_Tropicalwood_Roof_Shallow",
      "filler": 32,
      "rotation": 2
    },
    {
      "x": -1,
      "y": 0,
      "z": -1,
      "name": "Wood_Sallow_Trunk",
      "support": 15,
      "rotation": 2
    },
    {
      "x": -1,
      "y": 1,
      "z": -1,
      "name": "Wood_Sallow_Trunk",
      "support": 15,
      "rotation": 2
    },
    {
      "x": -1,
      "y": 2,
      "z": -1,
      "name": "Wood_Sallow_Trunk",
      "support": 15,
      "rotation": 2
    },
    {
      "x": -1,
      "y": 3,
      "z": -1,
      "name": "Wood_Sallow_Trunk",
      "support": 15,
      "rotation": 2
    },
    {
      "x": -1,
      "y": 4,
      "z": -1,
      "name": "Wood_Sallow_Trunk",
      "support": 15,
      "rotation": 2
    },
    {
      "x": -1,
      "y": 5,
      "z": -1,
      "name": "Wood_Sallow_Trunk",
      "support": 15,
      "rotation": 2
    },
    {
      "x": -1,
      "y": 6,
      "z": -1,
      "name": "Wood_Sallow_Trunk",
      "support": 15,
      "rotation": 2
    },
    {
      "x": -1,
      "y": 7,
      "z": -1,
      "name": "Wood_Sallow_Trunk_Full",
      "support": 15,
      "rotation": 2
    },
    {
      "x": -1,
      "y": 20,
      "z": -1,
      "name": "Wood_Goldenwood_Planks_Half",
      "rotation": 8
    },
    {
      "x": -1,
      "y": 26,
      "z": -1,
      "name": "Wood_Tropicalwood_Roof_Flat"
    },
    {
      "x": -1,
      "y": 51,
      "z": -1,
      "name": "Wood_Sallow_Trunk_Full",
      "support": 15,
      "rotation": 6
    },
    {
      "x": -1,
      "y": 52,
      "z": -1,
      "name": "Wood_Sallow_Trunk_Full",
      "support": 15,
      "rotation": 2
    },
    {
      "x": -1,
      "y": 55,
      "z": -1,
      "name": "Plant_Leaves_Beech",
      "support": 15,
      "rotation": 2
    },
    {
      "x": -1,
      "y": 0,
      "z": 0,
      "name": "Wood_Sallow_Trunk",
      "support": 15,
      "rotation": 2
    },
    {
      "x": -1,
      "y": 1,
      "z": 0,
      "name": "Wood_Sallow_Trunk",
      "support": 15,
      "rotation": 2
    },
    {
      "x": -1,
      "y": 2,
      "z": 0,
      "name": "Wood_Sallow_Trunk",
      "support": 15,
      "rotation": 2
    },
    {
      "x": -1,
      "y": 3,
      "z": 0,
      "name": "Wood_Sallow_Trunk",
      "support": 15,
      "rotation": 2
    },
    {
      "x": -1,
      "y": 4,
      "z": 0,
      "name": "Wood_Sallow_Trunk",
      "support": 15,
      "rotation": 2
    },
    {
      "x": -1,
      "y": 5,
      "z": 0,
      "name": "Wood_Sallow_Trunk",
      "support": 15,
      "rotation": 2
    },
    {
      "x": -1,
      "y": 6,
      "z": 0,
      "name": "Wood_Sallow_Trunk",
      "support": 15,
      "rotation": 2
    },
    {
      "x": -1,
      "y": 7,
      "z": 0,
      "name": "Wood_Sallow_Trunk_Full",
      "support": 15,
      "rotation": 2
    },
    {
      "x": -1,
      "y": 20,
      "z": 0,
      "name": "Wood_Goldenwood_Planks_Half",
      "rotation": 8
    },
    {
      "x": -1,
      "y": 21,
      "z": 0,
      "name": "Furniture_Lumberjack_Lamp",
      "filler": 992,
      "rotation": 3
    },
    {
      "x": -1,
      "y": 22,
      "z": 0,
      "name": "Furniture_Lumberjack_Lamp",
      "filler": 2016,
