{
  "version": 8,
  "blockIdVersion": 11,
  "anchorX": 0,
  "anchorY": 0,
  "anchorZ": 0,
  "blocks": [
    {
      "x": -10,
      "y": 61,
      "z": 7,
      "name": "Plant_Leaves_Beech",
      "support": 15,
      "rotation": 2
    },
    {
      "x": -10,
      "y": 62,
      "z": 7,
      "name": "Plant_Leaves_Beech",
      "support": 15,
      "rotation": 2
    },
    {
      "x": -10,
      "y": 63,
      "z": 7,
      "name": "Plant_Leaves_Beech",
      "support": 15,
      "rotation": 2
    },
    {
      "x": -10,
      "y": 63,
      "z": 8,
      "name": "Plant_Leaves_Beech",
      "support": 15,
      "rotation": 2
    },
    {
      "x": -9,
      "y": 60,
      "z": 4,
      "name": "Plant_Leaves_Beech",
      "support": 15,
      "rotation": 2
    },
    {
      "x": -9,
      "y": 61,
      "z": 6,
      "name": "Plant_Leaves_Beech",
      "support": 15,
      "rotation": 2
    },
    {
      "x": -9,
      "y": 62,
      "z": 6,
      "name": "Plant_Leaves_Beech",
      "support": 15,
      "rotation": 2
    },
    {
      "x": -9,
      "y": 63,
      "z": 6,
      "name": "Plant_Leaves_Beech",
      "support": 15,
      "rotation": 2
    },
    {
      "x": -9,
      "y": 61,
      "z": 7,
      "name": "Wood_Sallow_Branch_Corner",
      "support": 15,
      "rotation": 3
    },
    {
      "x": -9,
      "y": 62,
      "z": 7,
      "name": "Wood_Sallow_Branch_Long",
      "support": 15,
      "rotation": 2
    },
    {
      "x": -9,
      "y": 63,
      "z": 7,
      "name": "Plant_Leaves_Beech",
      "support": 15,
      "rotation": 2
    },
    {
      "x": -9,
      "y": 64,
      "z": 7,
      "name": "Plant_Leaves_Beech",
      "support": 15,
      "rotation": 2
    },
    {
      "x": -9,
      "y": 61,
      "z": 8,
      "name": "Plant_Leaves_Beech",
      "support": 15,
      "rotation": 2
    },
    {
      "x": -9,
      "y": 62,
      "z": 8,
      "name": "Plant_Leaves_Beech",
      "support": 15,
      "rotation": 2
    },
    {
      "x": -9,
      "y": 63,
      "z": 8,
      "name": "Plant_Leaves_Beech",
      "support": 15,
      "rotation": 2
    },
    {
      "x": -8,
      "y": 64,
      "z": -3,
      "name": "Plant_Leaves_Beech",
      "support": 15,
      "rotation": 2
    },
    {
      "x": -8,
      "y": 65,
      "z": -3,
      "name": "Plant_Leaves_Beech",
      "support": 15,
      "rotation": 2
    },
    {
      "x": -8,
      "y": 60,
      "z": 3,
      "name": "Plant_Leaves_Beech",
      "support": 15,
      "rotation": 2
    },
    {
      "x": -8,
      "y": 59,
      "z": 4,
      "name": "Plant_Leaves_Beech",
      "support": 15,
      "rotation": 2
    },
    {
      "x": -8,
      "y": 60,
      "z": 4,
      "name": "Plant_Leaves_Beech",
      "support": 15,
      "rotation": 2
    },
    {
      "x": -8,
      "y": 61,
      "z": 4,
      "name": "Plant_Leaves_Beech",
      "support": 15,
      "rotation": 2
    },
    {
      "x": -8,
      "y": 61,
      "z": 5,
      "name": "Plant_Leaves_Beech",
      "support": 15,
      "rotation": 2
    },
    {
      "x": -8,
      "y": 61,
      "z": 7,
      "name": "Wood_Sallow_Branch_Long",
      "support": 15,
      "rotation": 7
    },
    {
      "x": -8,
      "y": 62,
      "z": 7,
      "name": "Plant_Leaves_Beech",
      "support": 15,
      "rotation": 2
    },
    {
      "x": -8,
      "y": 63,
      "z": 7,
      "name": "Plant_Leaves_Beech",
      "support": 15,
      "rotation": 2
    },
    {
      "x": -7,
      "y": 2,
      "z": -5,
      "name": "Wood_Sallow_Roots",
      "rotation": 2
    },
    {
      "x": -7,
      "y": 3,
      "z": -5,
      "name": "Wood_Sallow_Trunk_Full",
      "support": 15,
      "rotation": 2
    },
    {
      "x": -7,
      "y": 4,
      "z": -5,
      "name": "Wood_Sallow_Trunk",
      "support": 15,
      "rotation": 2
    },
    {
      "x": -7,
      "y": 5,
      "z": -5,
      "name": "Wood_Sallow_Trunk",
      "support": 15,
      "rotation": 2
    },
    {
      "x": -7,
      "y": 6,
      "z": -5,
      "name": "Wood_Sallow_Trunk",
      "support": 15,
      "rotation": 2
    },
    {
      "x": -7,
      "y": 7,
      "z": -5,
      "name": "Wood_Sallow_Trunk",
      "support": 15,
      "rotation": 2
    },
    {
      "x": -7,
      "y": 8,
      "z": -5,
      "name": "Wood_Sallow_Trunk",
      "support": 15,
      "rotation": 2
    },
    {
      "x": -7,
      "y": 9,
      "z": -5,
      "name": "Wood_Sallow_Trunk_Full",
      "support": 15,
      "rotation": 2
    },
    {
      "x": -7,
      "y": 10,
      "z": -5,
      "name": "Plant_Moss_Rug_Green_Dark",
      "support": 15,
      "rotation": 2
    },
    {
      "x": -7,
      "y": 60,
      "z": -4,
      "name": "Plant_Leaves_Beech",
      "support": 15,
      "rotation": 2
    },
    {
      "x": -7,
      "y": 61,
      "z": -4,
      "name": "Plant_Leaves_Beech",
      "support": 15,
      "rotation": 2
    },
    {
      "x": -7,
      "y": 64,
      "z": -4,
      "name": "Plant_Leaves_Beech",
      "support": 15,
      "rotation": 2
    },
    {
      "x": -7,
      "y": 65,
      "z": -4,
      "name": "Plant_Leaves_Beech",
      "support": 15,
      "rotation": 2
    },
    {
      "x": -7,
      "y": 63,
      "z": -3,
      "name": "Plant_Leaves_Beech",
      "support": 15,
      "rotation": 2
    },
    {
      "x": -7,
      "y": 64,
      "z": -3,
      "name": "Wood_Sallow_Branch_Corner",
      "support": 15,
      "rotation": 3
    },
    {
      "x": -7,
      "y": 65,
      "z": -3,
      "name": "Wood_Sallow_Branch_Long",
      "support": 15,
      "rotation": 2
    },
    {
      "x": -7,
      "y": 66,
      "z": -3,
      "name": "Plant_Leaves_Beech",
      "support": 15,
      "rotation": 2
    },
    {
      "x": -7,
      "y": 64,
      "z": -2,
      "name": "Plant_Leaves_Beech",
      "support": 15,
      "rotation": 2
    },
    {
      "x": -7,
      "y": 65,
      "z": -2,
      "name": "Plant_Leaves_Beech",
      "support": 15,
      "rotation": 2
    },
    {
      "x": -7,
      "y": 3,
      "z": 2,
      "name": "Wood_Sallow_Roots",
      "rotation": 2
    },
    {
      "x": -7,
      "y": 4,
      "z": 2,
      "name": "Wood_Sallow_Trunk_Full",
      "support": 15,
      "rotation": 2
    },
    {
      "x": -7,
      "y": 5,
      "z": 2,
      "name": "Wood_Sallow_Trunk",
      "support": 15,
      "rotation": 2
    },
    {
      "x": -7,
      "y": 6,
      "z": 2,
      "name": "Wood_Sallow_Trunk",
      "support": 15,
      "rotation": 2
    },
    {
      "x": -7,
      "y": 7,
      "z": 2,
      "name": "Wood_Sallow_Trunk",
      "support": 15,
      "rotation": 2
    },
    {
      "x": -7,
      "y": 8,
      "z": 2,
      "name": "Wood_Sallow_Trunk",
      "support": 15,
      "rotation": 2
    },
    {
      "x": -7,
      "y": 9,
      "z": 2,
      "name": "Wood_Sallow_Trunk_Full",
      "support": 15,
      "rotation": 7
    },
    {
      "x": -7,
      "y": 32,
      "z": 2,
      "name": "Plant_Moss_Wall_Green_Dark",
      "support": 15,
      "rotation": 3
    },
    {
      "x": -7,
      "y": 60,
      "z": 2,
      "name": "Plant_Leaves_Beech",
      "support": 15,
      "rotation": 2
    },
    {
      "x": -7,
      "y": 31,
      "z": 3,
      "name": "Plant_Moss_Wall_Green_Dark",
      "support": 15,
      "rotation": 3
    },
    {
      "x": -7,
      "y": 32,
      "z": 3,
      "name": "Plant_Moss_Wall_Green_Dark",
      "support": 15,
      "rotation": 3
    },
    {
      "x": -7,
      "y": 60,
      "z": 3,
      "name": "Plant_Leaves_Beech",
      "support": 15,
      "rotation": 2
    },
    {
      "x": -7,
      "y": 61,
      "z": 3,
      "name": "Plant_Leaves_Beech",
      "support": 15,
      "rotation": 2
    },
    {
      "x": -7,
      "y": 59,
      "z": 4,
      "name": "Wood_Sallow_Branch_Corner",
      "support": 15,
      "rotation": 3
    },
    {
      "x": -7,
      "y": 60,
      "z": 4,
      "name": "Wood_Sallow_Branch_Long",
      "support": 15,
      "rotation": 2
    },
    {
      "x": -7,
      "y": 61,
      "z": 4,
      "name": "Plant_Leaves_Beech",
      "support": 15,
      "rotation": 2
    },
    {
      "x": -7,
      "y": 62,
      "z": 4,
      "name": "Plant_Leaves_Beech",
      "support": 15,
      "rotation": 2
    },
    {
      "x": -7,
      "y": 60,
      "z": 5,
      "name": "Plant_Leaves_Beech",
      "support": 15,
      "rotation": 2
    },
    {
      "x": -7,
      "y": 61,
      "z": 5,
      "name": "Plant_Leaves_Beech",
      "support": 15,
      "rotation": 2
    },
    {
      "x": -7,
      "y": 9,
      "z": 7,
      "name": "Plant_Moss_Rug_Green_Dark",
      "support": 15,
      "rotation": 2
    },
    {
      "x": -7,
      "y": 10,
      "z": 7,
      "name": "Plant_Moss_Wall_Green_Dark",
      "support": 15,
      "rotation": 3
    },
    {
      "x": -7,
      "y": 59,
      "z": 7,
      "name": "Plant_Leaves_Beech",
      "support": 15,
      "rotation": 2
    },
    {
      "x": -7,
      "y": 61,
      "z": 7,
      "name": "Wood_Sallow_Branch_Long",
      "support": 15,
      "rotation": 7
    },
    {
      "x": -7,
      "y": 2,
      "z": 8,
      "name": "Wood_Sallow_Roots",
      "rotation": 2
    },
    {
      "x": -7,
      "y": 3,
      "z": 8,
      "name": "Wood_Sallow_Trunk_Full",
      "support": 15,
      "rotation": 2
    },
    {
      "x": -7,
      "y": 4,
      "z": 8,
      "name": "Wood_Sallow_Trunk",
      "support": 15,
      "rotation": 2
    },
    {
      "x": -7,
      "y": 5,
      "z": 8,
      "name": "Wood_Sallow_Trunk",
      "support": 15,
      "rotation": 2
    },
    {
      "x": -7,
      "y": 6,
      "z": 8,
      "name": "Wood_Sallow_Trunk",
      "support": 15,
      "rotation": 2
    },
    {
      "x": -7,
      "y": 7,
      "z": 8,
      "name": "Wood_Sallow_Trunk",
      "support": 15,
      "rotation": 2
    },
    {
      "x": -7,
      "y": 8,
      "z": 8,
      "name": "Wood_Sallow_Trunk",
      "support": 15,
      "rotation": 2
    },
    {
      "x": -7,
      "y": 9,
      "z": 8,
      "name": "Wood_Sallow_Trunk_Full",
      "support": 15,
      "rotation": 2
    },
    {
      "x": -7,
      "y": 10,
      "z": 8,
      "name": "Plant_Moss_Rug_Green_Dark",
      "support": 15,
      "rotation": 2
    },
    {
      "x": -7,
      "y": 62,
      "z": 9,
      "name": "Plant_Leaves_Beech",
      "support": 15,
      "rotation": 2
    },
    {
      "x": -7,
      "y": 63,
      "z": 9,
      "name": "Plant_Leaves_Beech",
      "support": 15,
      "rotation": 2
    },
    {
      "x": -7,
      "y": 61,
      "z": 10,
      "name": "Plant_Leaves_Beech",
      "support": 15,
      "rotation": 2
    },
    {
      "x": -7,
      "y": 62,
      "z": 10,
      "name": "Plant_Leaves_Beech",
      "support": 15,
      "rotation": 2
    },
    {
      "x": -7,
      "y": 63,
      "z": 10,
      "name": "Plant_Leaves_Beech",
      "support": 15,
      "rotation": 2
    },
    {
      "x": -6,
      "y": 60,
      "z": -5,
      "name": "Plant_Leaves_Beech",
      "support": 15,
      "rotation": 2
    },
    {
      "x": -6,
      "y": 61,
      "z": -5,
      "name": "Plant_Leaves_Beech",
      "support": 15,
      "rotation": 2
    },
    {
      "x": -6,
      "y": 3,
      "z": -4,
      "name": "Wood_Sallow_Roots",
      "rotation": 2
    },
    {
      "x": -6,
      "y": 4,
      "z": -4,
      "name": "Wood_Sallow_Trunk_Full",
      "support": 15,
      "rotation": 2
    },
    {
      "x": -6,
      "y": 5,
      "z": -4,
      "name": "Wood_Sallow_Trunk",
      "support": 15,
      "rotation": 2
    },
    {
      "x": -6,
      "y": 6,
      "z": -4,
      "name": "Wood_Sallow_Trunk",
      "support": 15,
      "rotation": 2
    },
    {
      "x": -6,
      "y": 7,
      "z": -4,
      "name": "Wood_Sallow_Trunk",
      "support": 15,
      "rotation": 2
    },
    {
      "x": -6,
      "y": 8,
      "z": -4,
      "name": "Wood_Sallow_Trunk",
      "support": 15,
      "rotation": 2
    },
    {
      "x": -6,
      "y": 9,
      "z": -4,
      "name": "Wood_Sallow_Trunk",
      "support": 15,
      "rotation": 2
    },
    {
      "x": -6,
      "y": 10,
      "z": -4,
      "name": "Wood_Sallow_Trunk_Full",
      "support": 15,
      "rotation": 2
    },
    {
      "x": -6,
      "y": 11,
      "z": -4,
      "name": "Plant_Moss_Rug_Green_Dark",
      "support": 15,
      "rotation": 2
    },
    {
      "x": -6,
      "y": 59,
      "z": -4,
      "name": "Plant_Leaves_Beech",
      "support": 15,
      "rotation": 2
    },
    {
      "x": -6,
      "y": 60,
      "z": -4,
      "name": "Wood_Sallow_Branch_Long",
      "support": 15,
      "rotation": 2
    },
    {
      "x": -6,
      "y": 61,
      "z": -4,
      "name": "Wood_Sallow_Branch_Corner",
      "support": 15,
      "rotation": 34
    },
    {
      "x": -6,
      "y": 62,
      "z": -4,
      "name": "Plant_Leaves_Beech",
      "support": 15,
      "rotation": 2
    },
    {
      "x": -6,
      "y": 64,
      "z": -4,
      "name": "Plant_Leaves_Beech",
      "support": 15,
      "rotation": 2
    },
    {
      "x": -6,
      "y": 11,
      "z": -3,
      "name": "Plant_Moss_Wall_Green_Dark",
      "support": 15,
      "rotation": 3
    },
    {
      "x": -6,
      "y": 60,
      "z": -3,
      "name": "Plant_Leaves_Beech",
      "support": 15,
      "rotation": 2
    },
    {
      "x": -6,
      "y": 61,
      "z": -3,
      "name": "Wood_Sallow_Branch_Corner",
      "support": 15,
      "rotation": 19
    },
    {
      "x": -6,
      "y": 63,
      "z": -3,
      "name": "Plant_Leaves_Beech",
      "support": 15,
      "rotation": 2
    },
    {
      "x": -6,
      "y": 64,
      "z": -3,
      "name": "Wood_Sallow_Branch_Long",
      "support": 15,
      "rotation": 7
    },
    {
      "x": -6,
      "y": 65,
      "z": -3,
      "name": "Plant_Leaves_Beech",
      "support": 15,
      "rotation": 2
    },
    {
      "x": -6,
      "y": 29,
      "z": -1,
      "name": "Furniture_Crude_Platform",
      "rotation": 1
    },
    {
      "x": -6,
      "y": 30,
      "z": -1,
      "name": "*Wood_Softwood_Fence_State_Definitions_Corner",
      "rotation": 1
    },
    {
      "x": -6,
      "y": 31,
      "z": -1,
      "name": "*Wood_Softwood_Fence_State_Definitions_Corner",
      "rotation": 1
    },
    {
      "x": -6,
      "y": 32,
      "z": -1,
      "name": "*Wood_Softwood_Fence_State_Definitions_Corner",
      "rotation": 1
    },
    {
      "x": -6,
      "y": 33,
      "z": -1,
      "name": "*Wood_Tropicalwood_Roof_State_Definitions_Corner_Left",
      "rotation": 2
    },
    {
      "x": -6,
      "y": 29,
      "z": 0,
      "name": "Furniture_Crude_Platform",
      "rotation": 1
    },
    {
      "x": -6,
      "y": 30,
      "z": 0,
      "name": "Wood_Softwood_Fence",
      "rotation": 3
    },
    {
      "x": -6,
      "y": 31,
      "z": 0,
      "name": "Wood_Softwood_Fence",
      "rotation": 3
    },
    {
      "x": -6,
      "y": 32,
      "z": 0,
      "name": "Wood_Softwood_Fence",
      "rotation": 3
    },
    {
      "x": -6,
      "y": 33,
      "z": 0,
      "name": "Wood_Tropicalwood_Roof",
      "rotation": 3
    },
    {
      "x": -6,
      "y": 59,
      "z": 0,
      "name": "Plant_Leaves_Beech",
      "support": 15,
      "rotation": 2
    },
    {
      "x": -6,
      "y": 60,
      "z": 0,
      "name": "Plant_Leaves_Beech",
      "support": 15,
      "rotation": 2
    },
    {
      "x": -6,
      "y": 29,
      "z": 1,
      "name": "Furniture_Crude_Platform",
      "rotation": 1
    },
    {
      "x": -6,
      "y": 30,
      "z": 1,
      "name": "Wood_Softwood_Fence",
      "rotation": 3
    },
    {
      "x": -6,
      "y": 31,
      "z": 1,
      "name": "Wood_Goldenwood_Fence",
      "rotation": 3
    },
    {
      "x": -6,
      "y": 32,
      "z": 1,
      "name": "Wood_Softwood_Fence",
      "rotation": 3
    },
    {
      "x": -6,
      "y": 33,
      "z": 1,
      "name": "Wood_Tropicalwood_Roof",
      "rotation": 3
    },
    {
      "x": -6,
      "y": 56,
      "z": 1,
      "name": "Plant_Leaves_Beech",
      "support": 15,
      "rotation": 2
    },
    {
      "x": -6,
      "y": 4,
      "z": 2,
      "name": "Wood_Sallow_Roots",
      "rotation": 2
    },
    {
      "x": -6,
      "y": 5,
      "z": 2,
      "name": "Wood_Sallow_Trunk_Full",
      "support": 15,
      "rotation": 2
    },
    {
      "x": -6,
      "y": 6,
      "z": 2,
      "name": "Wood_Sallow_Trunk",
      "support": 15,
      "rotation": 2
    },
    {
      "x": -6,
      "y": 7,
      "z": 2,
      "name": "Wood_Sallow_Trunk",
      "support": 15,
      "rotation": 2
    },
    {
      "x": -6,
      "y": 8,
      "z": 2,
      "name": "Wood_Sallow_Trunk",
      "support": 15,
      "rotation": 2
    },
    {
      "x": -6,
      "y": 9,
      "z": 2,
      "name": "Wood_Sallow_Trunk",
      "support": 15,
      "rotation": 2
    },
    {
      "x": -6,
      "y": 10,
      "z": 2,
      "name": "Wood_Sallow_Trunk_Full",
      "support": 15,
      "rotation": 2
    },
    {
      "x": -6,
      "y": 29,
      "z": 2,
      "name": "Furniture_Crude_Platform",
      "rotation": 1
    },
    {
      "x": -6,
      "y": 30,
      "z": 2,
      "name": "Wood_Softwood_Fence",
      "rotation": 3
    },
    {
      "x": -6,
      "y": 31,
      "z": 2,
      "name": "Wood_Softwood_Fence",
      "rotation": 3
    },
    {
      "x": -6,
      "y": 32,
      "z": 2,
      "name": "Wood_Softwood_Fence",
      "rotation": 3
    },
    {
      "x": -6,
      "y": 33,
      "z": 2,
      "name": "Wood_Tropicalwood_Roof",
      "rotation": 3
    },
    {
      "x": -6,
      "y": 29,
      "z": 3,
      "name": "Furniture_Crude_Platform",
      "rotation": 1
    },
    {
      "x": -6,
      "y": 30,
      "z": 3,
      "name": "*Wood_Softwood_Fence_State_Definitions_Corner",
      "rotation": 2
    },
    {
      "x": -6,
      "y": 31,
      "z": 3,
      "name": "*Wood_Softwood_Fence_State_Definitions_Corner",
      "rotation": 2
    },
    {
      "x": -6,
      "y": 32,
      "z": 3,
      "name": "*Wood_Softwood_Fence_State_Definitions_Corner",
      "rotation": 2
    },
    {
      "x": -6,
      "y": 33,
      "z": 3,
      "name": "*Wood_Tropicalwood_Roof_State_Definitions_Corner_Left",
      "rotation": 3
    },
    {
      "x": -6,
      "y": 65,
      "z": 3,
      "name": "Plant_Leaves_Beech",
      "support": 15,
      "rotation": 2
    },
    {
      "x": -6,
      "y": 66,
      "z": 3,
      "name": "Plant_Leaves_Beech",
      "support": 15,
      "rotation": 2
    },
    {
      "x": -6,
      "y": 69,
      "z": 3,
      "name": "Plant_Leaves_Beech",
      "support": 15,
      "rotation": 2
    },
    {
      "x": -6,
      "y": 23,
      "z": 4,
      "name": "Plant_Vine_Liana_End",
      "support": 15,
      "rotation": 3
    },
    {
      "x": -6,
      "y": 24,
      "z": 4,
      "name": "Plant_Vine_Liana",
      "support": 15,
      "rotation": 3
    },
    {
      "x": -6,
      "y": 25,
      "z": 4,
      "name": "Plant_Vine_Liana",
      "support": 15,
      "rotation": 3
    },
    {
      "x": -6,
      "y": 26,
      "z": 4,
      "name": "Plant_Vine_Liana",
      "support": 15,
      "rotation": 3
    },
    {
      "x": -6,
      "y": 27,
      "z": 4,
      "name": "Plant_Vine_Liana",
      "support": 15,
      "rotation": 3
    },
    {
      "x": -6,
      "y": 28,
      "z": 4,
      "name": "Plant_Vine_Liana",
      "support": 15,
      "rotation": 3
    },
    {
      "x": -6,
      "y": 29,
      "z": 4,
      "name": "Plant_Vine_Liana",
      "support": 15,
      "rotation": 3
    },
    {
      "x": -6,
      "y": 30,
      "z": 4,
      "name": "Plant_Vine_Liana",
      "support": 15,
      "rotation": 3
    },
    {
      "x": -6,
      "y": 31,
      "z": 4,
      "name": "Plant_Vine_Liana",
      "support": 15,
      "rotation": 3
    },
    {
      "x": -6,
      "y": 32,
      "z": 4,
      "name": "Plant_Vine_Liana",
      "support": 15,
      "rotation": 3
    },
    {
      "x": -6,
      "y": 59,
      "z": 4,
      "name": "Wood_Sallow_Branch_Long",
      "support": 15,
      "rotation": 7
    },
    {
      "x": -6,
      "y": 60,
      "z": 4,
      "name": "Plant_Leaves_Beech",
      "support": 15,
      "rotation": 2
    },
    {
      "x": -6,
      "y": 61,
      "z": 4,
      "name": "Plant_Leaves_Beech",
      "support": 15,
      "rotation": 2
    },
    {
      "x": -6,
      "y": 65,
      "z": 4,
      "name": "Plant_Leaves_Beech",
      "support": 15,
      "rotation": 2
    },
    {
      "x": -6,
      "y": 67,
      "z": 4,
      "name": "Plant_Leaves_Beech",
      "support": 15,
      "rotation": 2
    },
    {
      "x": -6,
      "y": 68,
      "z": 4,
      "name": "Plant_Leaves_Beech",
      "support": 15,
      "rotation": 2
    },
    {
      "x": -6,
      "y": 69,
      "z": 4,
      "name": "Plant_Leaves_Beech",
      "support": 15,
      "rotation": 2
    },
    {
      "x": -6,
      "y": 68,
      "z": 5,
      "name": "Plant_Leaves_Beech",
      "support": 15,
      "rotation": 2
    },
    {
      "x": -6,
      "y": 69,
      "z": 5,
      "name": "Plant_Leaves_Beech",
      "support": 15,
      "rotation": 2
    },
    {
      "x": -6,
      "y": 5,
      "z": 6,
      "name": "Wood_Sallow_Trunk_Full",
      "support": 15,
      "rotation": 2
    },
    {
      "x": -6,
      "y": 6,
      "z": 6,
      "name": "Wood_Sallow_Trunk",
      "support": 15,
      "rotation": 2
    },
    {
      "x": -6,
      "y": 7,
      "z": 6,
      "name": "Wood_Sallow_Trunk",
      "support": 15,
      "rotation": 2
    },
    {
      "x": -6,
      "y": 8,
      "z": 6,
      "name": "Wood_Sallow_Trunk",
      "support": 15,
      "rotation": 2
    },
    {
      "x": -6,
      "y": 9,
      "z": 6,
      "name": "Wood_Sallow_Trunk_Full",
      "support": 15,
      "rotation": 7
    },
    {
      "x": -6,
      "y": 59,
      "z": 6,
      "name": "Plant_Leaves_Beech",
      "support": 15,
      "rotation": 2
    },
    {
      "x": -6,
      "y": 60,
      "z": 6,
      "name": "Wood_Sallow_Trunk_Full",
      "support": 15,
      "rotation": 7
    },
    {
      "x": -6,
      "y": 65,
      "z": 6,
      "name": "Plant_Leaves_Beech",
      "support": 15,
      "rotation": 2
    },
    {
      "x": -6,
      "y": 3,
      "z": 7,
      "name": "Wood_Sallow_Roots",
      "rotation": 2
    },
    {
      "x": -6,
      "y": 4,
      "z": 7,
      "name": "Wood_Sallow_Trunk_Full",
      "support": 15,
      "rotation": 2
    },
    {
      "x": -6,
      "y": 5,
      "z": 7,
      "name": "Wood_Sallow_Trunk",
      "support": 15,
      "rotation": 2
    },
    {
      "x": -6,
      "y": 6,
      "z": 7,
      "name": "Wood_Sallow_Trunk",
      "support": 15,
      "rotation": 2
    },
    {
      "x": -6,
      "y": 7,
      "z": 7,
      "name": "Wood_Sallow_Trunk",
      "support": 15,
      "rotation": 2
    },
    {
      "x": -6,
      "y": 8,
      "z": 7,
      "name": "Wood_Sallow_Trunk",
      "support": 15,
      "rotation": 2
    },
    {
      "x": -6,
      "y": 9,
      "z": 7,
      "name": "Wood_Sallow_Trunk",
      "support": 15,
      "rotation": 2
    },
    {
      "x": -6,
      "y": 10,
      "z": 7,
      "name": "Wood_Sallow_Trunk_Full",
      "support": 15,
      "rotation": 2
    },
    {
      "x": -6,
      "y": 11,
      "z": 7,
      "name": "Plant_Moss_Rug_Green_Dark",
      "support": 15,
      "rotation": 2
    },
    {
      "x": -6,
      "y": 58,
      "z": 7,
      "name": "Plant_Leaves_Beech",
      "support": 15,
      "rotation": 2
    },
    {
      "x": -6,
      "y": 59,
      "z": 7,
      "name": "Wood_Sallow_Branch_Long",
      "support": 15,
      "rotation": 2
    },
    {
      "x": -6,
      "y": 60,
      "z": 7,
      "name": "Wood_Sallow_Trunk_Full",
      "support": 15,
      "rotation": 6
    },
    {
      "x": -6,
      "y": 61,
      "z": 7,
      "name": "Wood_Sallow_Trunk_Full",
      "support": 15,
      "rotation": 2
    },
    {
      "x": -6,
      "y": 65,
      "z": 7,
      "name": "Plant_Leaves_Beech",
      "support": 15,
      "rotation": 2
    },
    {
      "x": -6,
      "y": 66,
      "z": 7,
      "name": "Plant_Leaves_Beech",
      "support": 15,
      "rotation": 2
    },
    {
      "x": -6,
      "y": 59,
      "z": 8,
      "name": "Plant_Leaves_Beech",
      "support": 15,
      "rotation": 2
    },
    {
      "x": -6,
      "y": 61,
      "z": 8,
      "name": "Wood_Sallow_Branch_Long",
      "support": 15,
      "rotation": 6
    },
    {
      "x": -6,
      "y": 61,
      "z": 9,
      "name": "Wood_Sallow_Branch_Long",
      "support": 15,
      "rotation": 6
    },
    {
      "x": -6,
      "y": 62,
      "z": 9,
      "name": "Plant_Leaves_Beech",
      "support": 15,
      "rotation": 2
    },
    {
      "x": -6,
      "y": 63,
      "z": 9,
      "name": "Plant_Leaves_Beech",
      "support": 15,
      "rotation": 2
    },
    {
      "x": -6,
      "y": 61,
      "z": 10,
      "name": "Wood_Sallow_Branch_Corner",
      "support": 15
    },
    {
      "x": -6,
      "y": 62,
      "z": 10,
      "name": "Wood_Sallow_Branch_Long",
      "support": 15,
      "rotation": 2
    },
    {
      "x": -6,
      "y": 63,
      "z": 10,
      "name": "Plant_Leaves_Beech",
      "support": 15,
      "rotation": 2
    },
    {
      "x": -6,
      "y": 64,
      "z": 10,
      "name": "Plant_Leaves_Beech",
      "support": 15,
      "rotation": 2
    },
    {
      "x": -6,
      "y": 61,
      "z": 11,
      "name": "Plant_Leaves_Beech",
      "support": 15,
      "rotation": 2
    },
    {
      "x": -6,
      "y": 62,
      "z": 11,
      "name": "Plant_Leaves_Beech",
      "support": 15,
      "rotation": 2
    },
    {
      "x": -5,
      "y": 64,
      "z": -5,
      "name": "Plant_Leaves_Beech",
      "support": 15,
      "rotation": 2
    },
    {
      "x": -5,
      "y": 65,
      "z": -5,
      "name": "Plant_Leaves_Beech",
      "support": 15,
      "rotation": 2
    },
    {
      "x": -5,
      "y": 5,
      "z": -4,
      "name": "Wood_Sallow_Trunk_Full",
      "support": 15,
      "rotation": 2
    },
    {
      "x": -5,
      "y": 6,
      "z": -4,
      "name": "Wood_Sallow_Trunk",
      "support": 15,
      "rotation": 2
    },
    {
      "x": -5,
      "y": 7,
      "z": -4,
      "name": "Wood_Sallow_Trunk",
      "support": 15,
      "rotation": 2
    },
    {
      "x": -5,
      "y": 8,
      "z": -4,
      "name": "Wood_Sallow_Trunk",
      "support": 15,
      "rotation": 2
    },
    {
      "x": -5,
      "y": 9,
      "z": -4,
      "name": "Wood_Sallow_Trunk",
      "support": 15,
      "rotation": 2
    },
    {
      "x": -5,
      "y": 10,
      "z": -4,
      "name": "Wood_Sallow_Trunk_Full",
      "support": 15,
      "rotation": 2
    },
    {
      "x": -5,
      "y": 11,
      "z": -4,
      "name": "Plant_Moss_Rug_Green_Dark",
      "support": 15,
      "rotation": 2
    },
    {
      "x": -5,
      "y": 29,
      "z": -4,
      "name": "Plant_Moss_Wall_Green_Dark",
      "support": 15,
      "rotation": 3
    },
    {
      "x": -5,
      "y": 60,
      "z": -4,
      "name": "Plant_Leaves_Beech",
      "support": 15,
      "rotation": 2
    },
    {
      "x": -5,
      "y": 61,
      "z": -4,
      "name": "Plant_Leaves_Beech",
      "support": 15,
      "rotation": 2
    },
    {
      "x": -5,
      "y": 64,
      "z": -4,
      "name": "Plant_Leaves_Beech",
      "support": 15,
      "rotation": 2
    },
    {
      "x": -5,
      "y": 4,
      "z": -3,
      "name": "Wood_Sallow_Roots",
      "rotation": 2
    },
    {
      "x": -5,
      "y": 5,
      "z": -3,
      "name": "Wood_Sallow_Trunk_Full",
      "support": 15,
      "rotation": 2
    },
    {
      "x": -5,
      "y": 6,
      "z": -3,
      "name": "Wood_Sallow_Trunk",
      "support": 15,
      "rotation": 2
    },
    {
      "x": -5,
      "y": 7,
      "z": -3,
      "name": "Wood_Sallow_Trunk",
      "support": 15,
      "rotation": 2
    },
    {
      "x": -5,
      "y": 8,
      "z": -3,
      "name": "Wood_Sallow_Trunk",
      "support": 15,
      "rotation": 2
    },
    {
      "x": -5,
      "y": 9,
      "z": -3,
      "name": "Wood_Sallow_Trunk",
      "support": 15,
      "rotation": 2
    },
    {
      "x": -5,
      "y": 10,
      "z": -3,
      "name": "Wood_Sallow_Trunk",
      "support": 15,
      "rotation": 2
    },
    {
      "x": -5,
      "y": 11,
      "z": -3,
      "name": "Wood_Sallow_Trunk_Full",
      "support": 15,
      "rotation": 2
    },
    {
      "x": -5,
      "y": 12,
      "z": -3,
      "name": "Plant_Moss_Rug_Green_Dark",
      "support": 15,
      "rotation": 2
    },
    {
      "x": -5,
      "y": 29,
      "z": -3,
      "name": "Furniture_Crude_Platform",
      "rotation": 1
    },
    {
      "x": -5,
      "y": 30,
      "z": -3,
      "name": "*Wood_Softwood_Fence_State_Definitions_Corner",
      "rotation": 1
    },
    {
      "x": -5,
      "y": 31,
      "z": -3,
      "name": "*Wood_Softwood_Fence_State_Definitions_Corner",
      "rotation": 1
    },
    {
      "x": -5,
      "y": 32,
      "z": -3,
      "name": "*Wood_Softwood_Fence_State_Definitions_Corner",
      "rotation": 1
    },
    {
      "x": -5,
      "y": 33,
      "z": -3,
      "name": "*Wood_Tropicalwood_Roof_State_Definitions_Corner_Right",
      "rotation": 3
    },
    {
      "x": -5,
      "y": 61,
      "z": -3,
      "name": "Wood_Sallow_Branch_Long",
      "support": 15,
      "rotation": 7
    },
    {
      "x": -5,
      "y": 64,
      "z": -3,
      "name": "Wood_Sallow_Branch_Long",
      "support": 15,
      "rotation": 7
    },
    {
      "x": -5,
      "y": 66,
      "z": -3,
      "name": "Plant_Leaves_Beech",
      "support": 15,
      "rotation": 2
    },
    {
      "x": -5,
      "y": 6,
      "z": -2,
      "name": "Wood_Sallow_Trunk_Full",
      "support": 15,
      "rotation": 2
    },
    {
      "x": -5,
      "y": 7,
      "z": -2,
      "name": "Wood_Sallow_Trunk",
      "support": 15,
      "rotation": 2
    },
    {
      "x": -5,
      "y": 8,
      "z": -2,
      "name": "Wood_Sallow_Trunk",
      "support": 15,
      "rotation": 2
    },
    {
      "x": -5,
      "y": 9,
      "z": -2,
      "name": "Wood_Sallow_Trunk_Full",
      "support": 15,
      "rotation": 2
    },
    {
      "x": -5,
      "y": 11,
      "z": -2,
      "name": "Plant_Moss_Wall_Green_Dark",
      "support": 15
    },
    {
      "x": -5,
      "y": 29,
      "z": -2,
      "name": "Furniture_Crude_Platform",
      "rotation": 1
    },
    {
      "x": -5,
      "y": 30,
      "z": -2,
      "name": "Wood_Softwood_Fence",
      "rotation": 3
    },
    {
      "x": -5,
      "y": 31,
      "z": -2,
      "name": "Wood_Goldenwood_Fence",
      "rotation": 3
    },
    {
      "x": -5,
      "y": 32,
      "z": -2,
      "name": "Wood_Softwood_Fence",
      "rotation": 3
    },
    {
      "x": -5,
      "y": 33,
      "z": -2,
      "name": "Wood_Tropicalwood_Roof",
      "rotation": 3
    },
    {
      "x": -5,
      "y": 29,
      "z": -1,
      "name": "Furniture_Crude_Platform",
      "rotation": 1
    },
    {
      "x": -5,
      "y": 30,
      "z": -1,
      "name": "*Wood_Softwood_Fence_State_Definitions_Corner",
      "rotation": 3
    },
    {
      "x": -5,
      "y": 31,
      "z": -1,
      "name": "*Wood_Softwood_Fence_State_Definitions_Corner",
      "rotation": 3
    },
    {
      "x": -5,
      "y": 32,
      "z": -1,
      "name": "*Wood_Softwood_Fence_State_Definitions_Corner",
      "rotation": 3
    },
    {
      "x": -5,
      "y": 33,
      "z": -1,
      "name": "*Wood_Tropicalwood_Roof_State_Definitions_Inverted_Corner_Left",
      "rotation": 2
    },
    {
      "x": -5,
      "y": 59,
      "z": -1,
      "name": "Plant_Leaves_Beech",
      "support": 15,
      "rotation": 2
    },
    {
      "x": -5,
      "y": 60,
      "z": -1,
      "name": "Plant_Leaves_Beech",
      "support": 15,
      "rotation": 2
    },
    {
      "x": -5,
      "y": 29,
      "z": 0,
      "name": "Wood_Goldenwood_Planks_Half",
      "rotation": 8
    },
    {
      "x": -5,
      "y": 34,
      "z": 0,
      "name": "Wood_Tropicalwood_Roof_Flat",
      "rotation": 1
    },
    {
      "x": -5,
      "y": 55,
      "z": 0,
      "name": "Plant_Leaves_Beech",
      "support": 15,
      "rotation": 2
    },
    {
      "x": -5,
      "y": 56,
      "z": 0,
      "name": "Plant_Leaves_Beech",
      "support": 15,
      "rotation": 2
    },
    {
      "x": -5,
      "y": 58,
      "z": 0,
      "name": "Plant_Leaves_Beech",
      "support": 15,
      "rotation": 2
    },
    {
      "x": -5,
      "y": 59,
      "z": 0,
      "name": "Wood_Sallow_Branch_Corner",
      "support": 15,
      "rotation": 3
    },
    {
      "x": -5,
      "y": 60,
      "z": 0,
      "name": "Wood_Sallow_Branch_Long",
      "support": 15,
      "rotation": 2
    },
    {
      "x": -5,
      "y": 61,
      "z": 0,
      "name": "Plant_Leaves_Beech",
      "support": 15,
      "rotation": 2
    },
    {
      "x": -5,
      "y": 4,
      "z": 1,
      "name": "Wood_Sallow_Roots",
      "rotation": 2
    },
    {
      "x": -5,
      "y": 5,
      "z": 1,
      "name": "Wood_Sallow_Trunk_Full",
      "support": 15,
      "rotation": 2
    },
    {
      "x": -5,
      "y": 6,
      "z": 1,
      "name": "Wood_Sallow_Trunk",
      "support": 15,
      "rotation": 2
    },
    {
      "x": -5,
      "y": 7,
      "z": 1,
      "name": "Wood_Sallow_Trunk",
      "support": 15,
      "rotation": 2
    },
    {
      "x": -5,
      "y": 8,
      "z": 1,
      "name": "Wood_Sallow_Trunk",
      "support": 15,
      "rotation": 2
    },
    {
      "x": -5,
      "y": 9,
      "z": 1,
      "name": "Wood_Sallow_Trunk",
      "support": 15,
      "rotation": 2
    },
    {
      "x": -5,
      "y": 10,
      "z": 1,
      "name": "Wood_Sallow_Trunk",
      "support": 15,
      "rotation": 2
    },
    {
      "x": -5,
      "y": 11,
      "z": 1,
      "name": "Wood_Sallow_Trunk_Full",
      "support": 15,
      "rotation": 2
    },
    {
      "x": -5,
      "y": 29,
      "z": 1,
      "name": "Wood_Goldenwood_Planks_Half",
      "rotation": 8
    },
    {
      "x": -5,
      "y": 34,
      "z": 1,
      "name": "Wood_Tropicalwood_Roof_Flat",
      "rotation": 1
    },
    {
      "x": -5,
      "y": 55,
      "z": 1,
      "name": "Plant_Leaves_Beech",
      "support": 15,
      "rotation": 2
    },
    {
      "x": -5,
      "y": 56,
      "z": 1,
      "name": "Wood_Sallow_Branch_Corner",
      "support": 15,
      "rotation": 3
    },
    {
      "x": -5,
      "y": 57,
      "z": 1,
      "name": "Plant_Leaves_Beech",
      "support": 15,
      "rotation": 2
    },
    {
      "x": -5,
      "y": 59,
      "z": 1,
      "name": "Plant_Leaves_Beech",
      "support": 15,
      "rotation": 2
    },
    {
      "x": -5,
      "y": 60,
      "z": 1,
      "name": "Plant_Leaves_Beech",
      "support": 15,
      "rotation": 2
    },
    {
      "x": -5,
      "y": 29,
      "z": 2,
      "name": "Wood_Goldenwood_Planks_Half",
      "rotation": 8
    },
    {
      "x": -5,
      "y": 34,
      "z": 2,
      "name": "Wood_Tropicalwood_Roof_Flat",
      "rotation": 1
    },
    {
      "x": -5,
      "y": 56,
      "z": 2,
      "name": "Plant_Leaves_Beech",
      "support": 15,
      "rotation": 2
    },
    {
      "x": -5,
      "y": 65,
      "z": 2,
      "name": "Plant_Leaves_Beech",
      "support": 15,
      "rotation": 2
    },
    {
      "x": -5,
      "y": 66,
      "z": 2,
      "name": "Plant_Leaves_Beech",
      "support": 15,
      "rotation": 2
    },
    {
      "x": -5,
      "y": 69,
      "z": 2,
      "name": "Plant_Leaves_Beech",
      "support": 15,
      "rotation": 2
    },
    {
      "x": -5,
      "y": 29,
      "z": 3,
      "name": "Furniture_Crude_Platform",
      "rotation": 1
    },
    {
      "x": -5,
      "y": 30,
      "z": 3,
      "name": "*Wood_Softwood_Fence_State_Definitions_Corner"
    },
    {
      "x": -5,
      "y": 31,
      "z": 3,
      "name": "*Wood_Softwood_Fence_State_Definitions_Corner"
    },
    {
      "x": -5,
      "y": 32,
      "z": 3,
      "name": "*Wood_Softwood_Fence_State_Definitions_Corner"
    },
    {
      "x": -5,
      "y": 33,
      "z": 3,
      "name": "*Wood_Tropicalwood_Roof_State_Definitions_Inverted_Corner_Right"
    },
    {
      "x": -5,
      "y": 64,
      "z": 3,
      "name": "Wood_Sallow_Branch_Corner",
      "support": 15,
      "rotation": 3
    },
    {
      "x": -5,
      "y": 65,
      "z": 3,
      "name": "Wood_Sallow_Branch_Long",
      "support": 15,
      "rotation": 2
    },
    {
      "x": -5,
      "y": 66,
      "z": 3,
      "name": "Plant_Leaves_Beech",
      "support": 15,
      "rotation": 2
    },
    {
      "x": -5,
      "y": 67,
      "z": 3,
      "name": "Plant_Leaves_Beech",
      "support": 15,
      "rotation": 2
    },
    {
      "x": -5,
      "y": 68,
      "z": 3,
      "name": "Plant_Leaves_Beech",
      "support": 15,
      "rotation": 2
    },
    {
      "x": -5,
      "y": 69,
      "z": 3,
      "name": "Plant_Leaves_Beech",
      "support": 15,
      "rotation": 2
    },
    {
      "x": -5,
      "y": 70,
      "z": 3,
      "name": "Plant_Leaves_Beech",
      "support": 15,
      "rotation": 2
    },
    {
      "x": -5,
      "y": 29,
      "z": 4,
      "name": "Furniture_Crude_Platform",
      "rotation": 1
    },
    {
      "x": -5,
      "y": 30,
      "z": 4,
      "name": "Wood_Softwood_Fence",
      "rotation": 3
    },
    {
      "x": -5,
      "y": 31,
      "z": 4,
      "name": "Wood_Goldenwood_Fence",
      "rotation": 3
    },
    {
      "x": -5,
      "y": 32,
      "z": 4,
      "name": "Wood_Softwood_Fence",
      "rotation": 3
    },
    {
      "x": -5,
      "y": 33,
      "z": 4,
      "name": "Wood_Tropicalwood_Roof",
      "rotation": 3
    },
    {
      "x": -5,
      "y": 59,
      "z": 4,
      "name": "Wood_Sallow_Branch_Long",
      "support": 15,
      "rotation": 7
    },
    {
      "x": -5,
      "y": 65,
      "z": 4,
      "name": "Plant_Leaves_Beech",
      "support": 15,
      "rotation": 2
    },
    {
      "x": -5,
      "y": 66,
      "z": 4,
      "name": "Plant_Leaves_Beech",
      "support": 15,
      "rotation": 2
    },
    {
      "x": -5,
      "y": 67,
      "z": 4,
      "name": "Wood_Sallow_Branch_Corner",
      "support": 15,
      "rotation": 3
    },
    {
      "x": -5,
      "y": 68,
      "z": 4,
      "name": "Wood_Sallow_Branch_Long",
      "support": 15,
      "rotation": 2
    },
    {
      "x": -5,
      "y": 69,
      "z": 4,
      "name": "Plant_Leaves_Beech",
      "support": 15,
      "rotation": 2
    },
    {
      "x": -5,
      "y": 70,
      "z": 4,
      "name": "Plant_Leaves_Beech",
      "support": 15,
      "rotation": 2
    },
    {
      "x": -5,
      "y": 6,
      "z": 5,
      "name": "Wood_Sallow_Trunk_Full",
      "support": 15,
      "rotation": 2
    },
    {
      "x": -5,
      "y": 7,
      "z": 5,
      "name": "Wood_Sallow_Trunk",
      "support": 15,
      "rotation": 2
    },
    {
      "x": -5,
      "y": 8,
      "z": 5,
      "name": "Wood_Sallow_Trunk",
      "support": 15,
      "rotation": 2
    },
    {
      "x": -5,
      "y": 9,
      "z": 5,
      "name": "Wood_Sallow_Trunk_Full",
      "support": 15,
      "rotation": 7
    },
    {
      "x": -5,
      "y": 29,
      "z": 5,
      "name": "Furniture_Crude_Platform",
      "rotation": 1
    },
    {
      "x": -5,
      "y": 30,
      "z": 5,
      "name": "*Wood_Softwood_Fence_State_Definitions_Corner",
      "rotation": 2
    },
    {
      "x": -5,
      "y": 31,
      "z": 5,
      "name": "*Wood_Softwood_Fence_State_Definitions_Corner",
      "rotation": 2
    },
    {
      "x": -5,
      "y": 32,
      "z": 5,
      "name": "*Wood_Softwood_Fence_State_Definitions_Corner",
      "rotation": 2
    },
    {
      "x": -5,
      "y": 33,
      "z": 5,
      "name": "*Wood_Tropicalwood_Roof_State_Definitions_Corner_Right"
    },
    {
      "x": -5,
      "y": 62,
      "z": 5,
      "name": "Plant_Leaves_Beech",
      "support": 15,
      "rotation": 2
    },
    {
      "x": -5,
      "y": 67,
      "z": 5,
      "name": "Plant_Leaves_Beech",
      "support": 15,
      "rotation": 2
    },
    {
      "x": -5,
      "y": 68,
      "z": 5,
      "name": "Plant_Leaves_Beech",
      "support": 15,
      "rotation": 2
    },
    {
      "x": -5,
      "y": 69,
      "z": 5,
      "name": "Plant_Leaves_Beech",
      "support": 15,
      "rotation": 2
    },
    {
      "x": -5,
      "y": 5,
      "z": 6,
      "name": "Wood_Sallow_Roots",
      "rotation": 2
    },
    {
      "x": -5,
      "y": 6,
      "z": 6,
      "name": "Wood_Sallow_Trunk_Full",
      "support": 15,
      "rotation": 2
    },
    {
      "x": -5,
      "y": 7,
      "z": 6,
      "name": "Wood_Sallow_Trunk",
      "support": 15,
      "rotation": 2
    },
    {
      "x": -5,
      "y": 8,
      "z": 6,
      "name": "Wood_Sallow_Trunk",
      "support": 15,
      "rotation": 2
    },
    {
      "x": -5,
      "y": 9,
      "z": 6,
      "name": "Wood_Sallow_Trunk",
      "support": 15,
      "rotation": 2
    },
    {
      "x": -5,
      "y": 10,
      "z": 6,
      "name": "Wood_Sallow_Trunk",
      "support": 15,
      "rotation": 2
    },
    {
      "x": -5,
      "y": 11,
      "z": 6,
      "name": "Wood_Sallow_Trunk_Full",
      "support": 15,
      "rotation": 2
    },
    {
      "x": -5,
      "y": 60,
      "z": 6,
      "name": "Wood_Sallow_Trunk",
      "support": 15,
      "rotation": 7
    },
    {
      "x": -5,
      "y": 65,
      "z": 6,
      "name": "Wood_Sallow_Branch_Corner",
      "support": 15,
      "rotation": 51
    },
    {
      "x": -5,
      "y": 66,
      "z": 6,
      "name": "Plant_Leaves_Beech",
      "support": 15,
      "rotation": 2
    },
    {
      "x": -5,
      "y": 4,
      "z": 7,
      "name": "Wood_Sallow_Roots",
      "rotation": 2
    },
    {
      "x": -5,
      "y": 5,
      "z": 7,
      "name": "Wood_Sallow_Trunk_Full",
      "support": 15,
      "rotation": 2
    },
    {
      "x": -5,
      "y": 6,
      "z": 7,
      "name": "Wood_Sallow_Trunk",
      "support": 15,
      "rotation": 2
    },
    {
      "x": -5,
      "y": 7,
      "z": 7,
      "name": "Wood_Sallow_Trunk",
      "support": 15,
      "rotation": 2
    },
    {
      "x": -5,
      "y": 8,
      "z": 7,
      "name": "Wood_Sallow_Trunk",
      "support": 15,
      "rotation": 2
    },
    {
      "x": -5,
      "y": 9,
      "z": 7,
      "name": "Wood_Sallow_Trunk",
      "support": 15,
      "rotation": 2
    },
    {
      "x": -5,
      "y": 10,
      "z": 7,
      "name": "Wood_Sallow_Trunk",
      "support": 15,
      "rotation": 2
    },
    {
      "x": -5,
      "y": 11,
      "z": 7,
      "name": "Wood_Sallow_Trunk_Full",
      "support": 15,
      "rotation": 2
    },
    {
      "x": -5,
      "y": 64,
      "z": 7,
      "name": "Plant_Leaves_Beech",
      "support": 15,
      "rotation": 2
    },
    {
      "x": -5,
      "y": 65,
      "z": 7,
      "name": "Wood_Sallow_Branch_Corner",
      "support": 15
    },
    {
      "x": -5,
      "y": 66,
      "z": 7,
      "name": "Wood_Sallow_Branch_Long",
      "support": 15,
      "rotation": 2
    },
    {
      "x": -5,
      "y": 67,
      "z": 7,
      "name": "Plant_Leaves_Beech",
      "support": 15,
      "rotation": 2
    },
    {
      "x": -5,
      "y": 65,
      "z": 8,
      "name": "Plant_Leaves_Beech",
      "support": 15,
      "rotation": 2
    },
    {
      "x": -5,
      "y": 66,
      "z": 8,
      "name": "Plant_Leaves_Beech",
      "support": 15,
      "rotation": 2
    },
    {
      "x": -5,
      "y": 61,
      "z": 9,
      "name": "Plant_Leaves_Beech",
      "support": 15,
      "rotation": 2
    },
    {
      "x": -5,
      "y": 62,
      "z": 9,
      "name": "Plant_Leaves_Beech",
      "support": 15,
      "rotation": 2
    },
    {
      "x": -5,
      "y": 61,
      "z": 10,
      "name": "Plant_Leaves_Beech",
      "support": 15,
      "rotation": 2
    },
    {
      "x": -5,
      "y": 62,
      "z": 10,
      "name": "Plant_Leaves_Beech",
      "support": 15,
      "rotation": 2
    },
    {
      "x": -5,
      "y": 63,
      "z": 10,
      "name": "Plant_Leaves_Beech",
      "support": 15,
      "rotation": 2
    },
    {
      "x": -5,
      "y": 62,
      "z": 11,
      "name": "Plant_Leaves_Beech",
      "support": 15,
      "rotation": 2
    },
    {
      "x": -4,
      "y": 58,
      "z": -6,
      "name": "Plant_Leaves_Beech",
      "support": 15,
      "rotation": 2
    },
    {
      "x": -4,
      "y": 59,
      "z": -6,
      "name": "Plant_Leaves_Beech",
      "support": 15,
      "rotation": 2
    },
    {
      "x": -4,
      "y": 64,
      "z": -6,
      "name": "Plant_Leaves_Beech",
      "support": 15,
      "rotation": 2
    },
    {
      "x": -4,
      "y": 65,
      "z": -6,
      "name": "Plant_Leaves_Beech",
      "support": 15,
      "rotation": 2
    },
    {
      "x": -4,
      "y": 63,
      "z": -5,
      "name": "Plant_Leaves_Beech",
      "support": 15,
      "rotation": 2
    },
    {
      "x": -4,
      "y": 64,
      "z": -5,
      "name": "Wood_Sallow_Branch_Corner",
      "support": 15,
      "rotation": 2
    },
    {
      "x": -4,
      "y": 65,
      "z": -5,
      "name": "Wood_Sallow_Branch_Long",
      "support": 15,
      "rotation": 2
    },
    {
      "x": -4,
      "y": 66,
      "z": -5,
      "name": "Plant_Leaves_Beech",
      "support": 15,
      "rotation": 2
    },
    {
      "x": -4,
      "y": 29,
      "z": -4,
      "name": "Furniture_Crude_Platform"
    },
    {
      "x": -4,
      "y": 30,
      "z": -4,
      "name": "*Wood_Softwood_Fence_State_Definitions_Corner",
      "rotation": 1
    },
    {
      "x": -4,
      "y": 31,
      "z": -4,
      "name": "*Wood_Softwood_Fence_State_Definitions_Corner",
      "rotation": 1
    },
    {
      "x": -4,
      "y": 32,
      "z": -4,
      "name": "*Wood_Softwood_Fence_State_Definitions_Corner",
      "rotation": 1
    },
    {
      "x": -4,
      "y": 33,
      "z": -4,
      "name": "*Wood_Tropicalwood_Roof_State_Definitions_Corner_Right",
      "rotation": 3
    },
    {
      "x": -4,
      "y": 64,
      "z": -4,
      "name": "Wood_Sallow_Branch_Long",
      "support": 15,
      "rotation": 6
    },
    {
      "x": -4,
      "y": 65,
      "z": -4,
      "name": "Plant_Leaves_Beech",
      "support": 15,
      "rotation": 2
    },
    {
      "x": -4,
      "y": 66,
      "z": -4,
      "name": "Plant_Leaves_Beech",
      "support": 15,
      "rotation": 2
    },
    {
      "x": -4,
      "y": 67,
      "z": -4,
      "name": "Plant_Leaves_Beech",
      "support": 15,
      "rotation": 2
    },
    {
      "x": -4,
      "y": 6,
      "z": -3,
      "name": "Wood_Sallow_Trunk_Full",
      "support": 15,
      "rotation": 2
    },
    {
      "x": -4,
      "y": 7,
      "z": -3,
      "name": "Wood_Sallow_Trunk",
      "support": 15,
      "rotation": 2
    },
    {
      "x": -4,
      "y": 8,
      "z": -3,
      "name": "Wood_Sallow_Trunk",
      "support": 15,
      "rotation": 2
    },
    {
      "x": -4,
      "y": 9,
      "z": -3,
      "name": "Wood_Sallow_Trunk",
      "support": 15,
      "rotation": 2
    },
    {
      "x": -4,
      "y": 10,
      "z": -3,
      "name": "Wood_Sallow_Trunk",
      "support": 15,
      "rotation": 2
    },
    {
      "x": -4,
      "y": 11,
      "z": -3,
      "name": "Wood_Sallow_Trunk",
      "support": 15,
      "rotation": 2
    },
    {
      "x": -4,
      "y": 12,
      "z": -3,
      "name": "Wood_Sallow_Trunk_Full",
      "support": 15,
      "rotation": 2
    },
    {
      "x": -4,
      "y": 29,
      "z": -3,
      "name": "Furniture_Crude_Platform",
      "rotation": 1
    },
    {
      "x": -4,
      "y": 30,
      "z": -3,
      "name": "*Wood_Softwood_Fence_State_Definitions_Corner",
      "rotation": 3
    },
    {
      "x": -4,
      "y": 31,
      "z": -3,
      "name": "*Wood_Softwood_Fence_State_Definitions_Corner",
      "rotation": 3
    },
    {
      "x": -4,
      "y": 32,
      "z": -3,
      "name": "*Wood_Softwood_Fence_State_Definitions_Corner",
      "rotation": 3
    },
    {
      "x": -4,
      "y": 33,
      "z": -3,
      "name": "*Wood_Tropicalwood_Roof_State_Definitions_Inverted_Corner_Left",
      "rotation": 2
    },
    {
      "x": -4,
      "y": 61,
      "z": -3,
      "name": "Wood_Sallow_Branch_Corner",
      "support": 15,
      "rotation": 1
    },
    {
      "x": -4,
      "y": 62,
      "z": -3,
      "name": "Wood_Sallow_Trunk_Full",
      "support": 15,
      "rotation": 7
    },
    {
      "x": -4,
      "y": 63,
      "z": -3,
      "name": "Wood_Sallow_Trunk",
      "support": 15,
      "rotation": 2
    },
    {
      "x": -4,
      "y": 64,
      "z": -3,
      "name": "Wood_Sallow_Trunk_Full",
      "support": 15,
      "rotation": 2
    },
    {
      "x": -4,
      "y": 65,
      "z": -3,
      "name": "Wood_Sallow_Branch_Long",
      "support": 15,
      "rotation": 2
    },
    {
      "x": -4,
      "y": 66,
      "z": -3,
      "name": "Wood_Sallow_Branch_Long",
      "support": 15,
      "rotation": 2
    },
    {
      "x": -4,
      "y": 67,
      "z": -3,
      "name": "Plant_Leaves_Beech",
      "support": 15,
      "rotation": 2
    },
    {
      "x": -4,
      "y": 5,
      "z": -2,
      "name": "Wood_Sallow_Roots",
      "rotation": 2
    },
    {
      "x": -4,
      "y": 6,
      "z": -2,
      "name": "Wood_Sallow_Trunk_Full",
      "support": 15,
      "rotation": 2
    },
    {
      "x": -4,
      "y": 7,
      "z": -2,
      "name": "Wood_Sallow_Trunk",
      "support": 15,
      "rotation": 2
    },
    {
      "x": -4,
      "y": 8,
      "z": -2,
      "name": "Wood_Sallow_Trunk",
      "support": 15,
      "rotation": 2
    },
    {
      "x": -4,
      "y": 9,
      "z": -2,
      "name": "Wood_Sallow_Trunk",
      "support": 15,
      "rotation": 2
    },
    {
      "x": -4,
      "y": 10,
      "z": -2,
      "name": "Wood_Sallow_Trunk",
      "support": 15,
      "rotation": 2
    },
    {
      "x": -4,
      "y": 11,
      "z": -2,
      "name": "Wood_Sallow_Trunk",
      "support": 15,
      "rotation": 2
    },
    {
      "x": -4,
      "y": 12,
      "z": -2,
      "name": "Wood_Sallow_Trunk",
      "support": 15,
      "rotation": 2
    },
    {
      "x": -4,
      "y": 13,
      "z": -2,
      "name": "Wood_Sallow_Trunk_Full",
      "support": 15,
      "rotation": 2
    },
    {
      "x": -4,
      "y": 29,
      "z": -2,
      "name": "Wood_Goldenwood_Planks_Half",
      "rotation": 8
    },
    {
      "x": -4,
      "y": 34,
      "z": -2,
      "name": "Wood_Tropicalwood_Roof_Flat",
      "rotation": 1
    },
    {
      "x": -4,
      "y": 66,
      "z": -2,
      "name": "Plant_Leaves_Beech",
      "support": 15,
      "rotation": 2
    },
    {
      "x": -4,
      "y": 7,
      "z": -1,
      "name": "Wood_Sallow_Trunk_Full",
      "support": 15,
      "rotation": 2
    },
    {
      "x": -4,
      "y": 8,
      "z": -1,
      "name": "Wood_Sallow_Trunk",
      "support": 15,
      "rotation": 2
    },
    {
      "x": -4,
      "y": 9,
      "z": -1,
      "name": "Wood_Sallow_Trunk",
      "support": 15,
      "rotation": 2
    },
    {
      "x": -4,
      "y": 10,
      "z": -1,
      "name": "Wood_Sallow_Trunk_Full",
      "support": 15,
      "rotation": 2
    },
    {
      "x": -4,
      "y": 29,
      "z": -1,
      "name": "Wood_Goldenwood_Planks_Half",
      "rotation": 8
    },
    {
      "x": -4,
      "y": 30,
      "z": -1,
      "name": "Furniture_Village_Chair",
      "components": {
        "Components": {}
      }
    },
    {
      "x": -4,
      "y": 31,
      "z": -1,
      "name": "Furniture_Village_Chair",
      "filler": 1024
    },
    {
      "x": -4,
      "y": 34,
      "z": -1,
      "name": "Wood_Tropicalwood_Roof_Flat",
      "rotation": 1
    },
    {
      "x": -4,
      "y": 59,
      "z": -1,
      "name": "Plant_Leaves_Beech",
      "support": 15,
      "rotation": 2
    },
    {
      "x": -4,
      "y": 29,
      "z": 0,
      "name": "Wood_Goldenwood_Planks_Half",
      "rotation": 8
    },
    {
      "x": -4,
      "y": 30,
      "z": 0,
      "name": "Furniture_Village_Table",
      "filler": 1023,
      "rotation": 2
    },
    {
      "x": -4,
      "y": 34,
      "z": 0,
      "name": "Wood_Tropicalwood_Roof_Shallow",
      "rotation": 3
    },
    {
      "x": -4,
      "y": 56,
      "z": 0,
      "name": "Plant_Leaves_Beech",
      "support": 15,
      "rotation": 2
    },
    {
      "x": -4,
      "y": 58,
      "z": 0,
      "name": "Plant_Leaves_Beech",
      "support": 15,
      "rotation": 2
    },
    {
      "x": -4,
      "y": 59,
      "z": 0,
      "name": "Wood_Sallow_Branch_Long",
      "support": 15,
      "rotation": 7
    },
    {
      "x": -4,
      "y": 60,
      "z": 0,
      "name": "Plant_Leaves_Beech",
      "support": 15,
      "rotation": 2
    },
    {
      "x": -4,
      "y": 5,
      "z": 1,
      "name": "Wood_Sallow_Roots",
      "rotation": 2
    },
    {
      "x": -4,
      "y": 6,
      "z": 1,
      "name": "Wood_Sallow_Trunk_Full",
      "support": 15,
      "rotation": 2
    },
    {
      "x": -4,
      "y": 7,
      "z": 1,
      "name": "Wood_Sallow_Trunk",
      "support": 15,
      "rotation": 2
    },
    {
      "x": -4,
      "y": 8,
      "z": 1,
      "name": "Wood_Sallow_Trunk",
      "support": 15,
      "rotation": 2
    },
    {
      "x": -4,
      "y": 9,
      "z": 1,
      "name": "Wood_Sallow_Trunk",
      "support": 15,
      "rotation": 2
    },
    {
      "x": -4,
      "y": 10,
      "z": 1,
      "name": "Wood_Sallow_Trunk",
      "support": 15,
      "rotation": 2
    },
    {
      "x": -4,
      "y": 11,
      "z": 1,
      "name": "Wood_Sallow_Trunk_Full",
      "support": 15,
      "rotation": 2
    },
    {
      "x": -4,
      "y": 29,
      "z": 1,
      "name": "Wood_Goldenwood_Planks_Half",
      "rotation": 8
    },
    {
      "x": -4,
      "y": 30,
      "z": 1,
      "name": "Furniture_Village_Table",
      "filler": 31,
      "rotation": 2
    },
    {
      "x": -4,
      "y": 34,
      "z": 1,
      "name": "Wood_Tropicalwood_Roof_Shallow",
      "rotation": 3
    },
    {
      "x": -4,
      "y": 55,
      "z": 1,
      "name": "Plant_Leaves_Beech",
      "support": 15,
      "rotation": 2
    },
    {
      "x": -4,
      "y": 56,
      "z": 1,
      "name": "Wood_Sallow_Branch_Long",
      "support": 15,
      "rotation": 7
    },
    {
      "x": -4,
      "y": 57,
      "z": 1,
      "name": "Plant_Leaves_Beech",
      "support": 15,
      "rotation": 2
    },
    {
      "x": -4,
      "y": 29,
      "z": 2,
      "name": "Wood_Goldenwood_Planks_Half",
      "rotation": 8
    },
    {
      "x": -4,
      "y": 30,
      "z": 2,
      "name": "Furniture_Village_Chair",
      "rotation": 2
    },
    {
      "x": -4,
      "y": 31,
      "z": 2,
      "name": "Furniture_Village_Chair",
      "filler": 1024,
      "rotation": 2
    },
    {
      "x": -4,
      "y": 34,
      "z": 2,
      "name": "Wood_Tropicalwood_Roof_Shallow",
      "rotation": 3
    },
    {
      "x": -4,
      "y": 10,
      "z": 3,
      "name": "Plant_Moss_Wall_Green_Dark",
      "support": 15,
      "rotation": 2
    },
    {
      "x": -4,
      "y": 11,
      "z": 3,
      "name": "Plant_Moss_Wall_Green_Dark",
      "support": 15,
      "rotation": 3
    },
    {
      "x": -4,
      "y": 29,
      "z": 3,
      "name": "Wood_Goldenwood_Planks_Half",
      "rotation": 8
    },
    {
      "x": -4,
      "y": 34,
      "z": 3,
      "name": "Wood_Tropicalwood_Roof_Flat",
      "rotation": 1
    },
    {
      "x": -4,
      "y": 64,
      "z": 3,
      "name": "Wood_Sallow_Branch_Long",
      "support": 15,
      "rotation": 7
    },
    {
      "x": -4,
      "y": 67,
      "z": 3,
      "name": "Plant_Leaves_Beech",
      "support": 15,
      "rotation": 2
    },
    {
      "x": -4,
      "y": 69,
      "z": 3,
      "name": "Plant_Leaves_Beech",
      "support": 15,
      "rotation": 2
    },
    {
      "x": -4,
      "y": 7,
      "z": 4,
      "name": "Wood_Sallow_Trunk_Full",
      "support": 15,
      "rotation": 2
    },
    {
      "x": -4,
      "y": 8,
      "z": 4,
      "name": "Wood_Sallow_Trunk",
      "support": 15,
      "rotation": 2
    },
    {
      "x": -4,
      "y": 9,
      "z": 4,
      "name": "Wood_Sallow_Trunk",
      "support": 15,
      "rotation": 2
    },
    {
      "x": -4,
      "y": 10,
      "z": 4,
      "name": "Wood_Sallow_Trunk_Full",
      "support": 15,
      "rotation": 2
    },
    {
      "x": -4,
      "y": 11,
      "z": 4,
      "name": "Plant_Moss_Rug_Green_Dark",
      "support": 15,
      "rotation": 2
    },
    {
      "x": -4,
      "y": 29,
      "z": 4,
      "name": "Wood_Goldenwood_Planks_Half",
      "rotation": 8
    },
    {
      "x": -4,
      "y": 34,
      "z": 4,
      "name": "Wood_Tropicalwood_Roof_Flat",
      "rotation": 1
    },
    {
      "x": -4,
      "y": 59,
      "z": 4,
      "name": "Wood_Sallow_Branch_Long",
      "support": 15,
      "rotation": 7
    },
    {
      "x": -4,
      "y": 62,
      "z": 4,
      "name": "Plant_Leaves_Beech",
      "support": 15,
      "rotation": 2
    },
    {
      "x": -4,
      "y": 67,
      "z": 4,
      "name": "Wood_Sallow_Branch_Long",
      "support": 15,
      "rotation": 7
    },
    {
      "x": -4,
      "y": 68,
      "z": 4,
      "name": "Plant_Leaves_Beech",
      "support": 15,
      "rotation": 2
    },
    {
      "x": -4,
      "y": 69,
      "z": 4,
      "name": "Plant_Leaves_Beech",
      "support": 15,
      "rotation": 2
    },
    {
      "x": -4,
      "y": 6,
      "z": 5,
      "name": "Wood_Sallow_Roots",
      "rotation": 2
    },
    {
      "x": -4,
      "y": 7,
      "z": 5,
      "name": "Wood_Sallow_Trunk_Full",
      "support": 15,
      "rotation": 2
    },
    {
      "x": -4,
      "y": 8,
      "z": 5,
      "name": "Wood_Sallow_Trunk",
      "support": 15,
      "rotation": 2
    },
    {
      "x": -4,
      "y": 9,
      "z": 5,
      "name": "Wood_Sallow_Trunk",
      "support": 15,
      "rotation": 2
    },
    {
      "x": -4,
      "y": 10,
      "z": 5,
      "name": "Wood_Sallow_Trunk",
      "support": 15,
      "rotation": 2
    },
    {
      "x": -4,
      "y": 11,
      "z": 5,
      "name": "Wood_Sallow_Trunk_Full",
      "support": 15,
      "rotation": 2
    },
    {
      "x": -4,
      "y": 29,
      "z": 5,
      "name": "Furniture_Crude_Platform",
      "rotation": 1
    },
    {
      "x": -4,
      "y": 30,
      "z": 5,
      "name": "*Wood_Softwood_Fence_State_Definitions_Corner"
    },
    {
      "x": -4,
      "y": 31,
      "z": 5,
      "name": "*Wood_Softwood_Fence_State_Definitions_Corner"
    },
    {
      "x": -4,
      "y": 32,
      "z": 5,
      "name": "*Wood_Softwood_Fence_State_Definitions_Corner"
    },
    {
      "x": -4,
      "y": 33,
      "z": 5,
      "name": "*Wood_Tropicalwood_Roof_State_Definitions_Inverted_Corner_Left",
      "rotation": 3
    },
    {
      "x": -4,
      "y": 59,
      "z": 5,
      "name": "Wood_Sallow_Trunk_Full",
      "support": 15,
      "rotation": 7
    },
    {
      "x": -4,
      "y": 60,
      "z": 5,
      "name": "Wood_Sallow_Trunk_Full",
      "support": 15,
      "rotation": 2
    },
    {
      "x": -4,
      "y": 61,
      "z": 5,
      "name": "Wood_Sallow_Branch_Long",
      "support": 15,
      "rotation": 2
    },
    {
      "x": -4,
      "y": 62,
      "z": 5,
      "name": "Wood_Sallow_Branch_Long",
      "support": 15,
      "rotation": 2
    },
    {
      "x": -4,
      "y": 63,
      "z": 5,
      "name": "Plant_Leaves_Beech",
      "support": 15,
      "rotation": 2
    },
    {
      "x": -4,
      "y": 68,
      "z": 5,
      "name": "Plant_Leaves_Beech",
      "support": 15,
      "rotation": 2
    },
    {
      "x": -4,
      "y": 69,
      "z": 5,
      "name": "Plant_Leaves_Beech",
      "support": 15,
      "rotation": 2
    },
    {
      "x": -4,
      "y": 6,
      "z": 6,
      "name": "Wood_Sallow_Roots",
      "rotation": 2
    },
    {
      "x": -4,
      "y": 7,
      "z": 6,
      "name": "Wood_Sallow_Trunk_Full",
      "support": 15,
      "rotation": 2
    },
    {
      "x": -4,
      "y": 8,
      "z": 6,
      "name": "Wood_Sallow_Trunk",
      "support": 15,
      "rotation": 2
    },
    {
      "x": -4,
      "y": 9,
      "z": 6,
      "name": "Wood_Sallow_Trunk",
      "support": 15,
      "rotation": 2
    },
    {
      "x": -4,
      "y": 10,
      "z": 6,
      "name": "Wood_Sallow_Trunk",
      "support": 15,
      "rotation": 2
    },
    {
      "x": -4,
      "y": 11,
      "z": 6,
      "name": "Wood_Sallow_Trunk",
      "support": 15,
      "rotation": 2
    },
    {
      "x": -4,
      "y": 12,
      "z": 6,
      "name": "Wood_Sallow_Trunk_Full",
      "support": 15,
      "rotation": 2
    },
    {
      "x": -4,
      "y": 29,
      "z": 6,
      "name": "Furniture_Crude_Platform",
      "rotation": 1
    },
    {
      "x": -4,
      "y": 30,
      "z": 6,
      "name": "*Wood_Softwood_Fence_State_Definitions_Corner",
      "rotation": 2
    },
    {
      "x": -4,
      "y": 31,
      "z": 6,
      "name": "*Wood_Softwood_Fence_State_Definitions_Corner",
      "rotation": 2
    },
    {
      "x": -4,
      "y": 32,
      "z": 6,
      "name": "*Wood_Softwood_Fence_State_Definitions_Corner",
      "rotation": 2
    },
    {
      "x": -4,
      "y": 33,
      "z": 6,
      "name": "*Wood_Tropicalwood_Roof_State_Definitions_Corner_Right"
    },
    {
      "x": -4,
      "y": 60,
      "z": 6,
      "name": "Wood_Sallow_Trunk_Full",
      "support": 15,
      "rotation": 7
    },
    {
      "x": -4,
      "y": 62,
      "z": 6,
      "name": "Plant_Leaves_Beech",
      "support": 15,
      "rotation": 2
    },
    {
      "x": -4,
      "y": 65,
      "z": 6,
      "name": "Wood_Sallow_Branch_Long",
      "support": 15,
      "rotation": 7
    },
    {
      "x": -4,
      "y": 5,
      "z": 7,
      "name": "Wood_Sallow_Roots",
      "rotation": 2
    },
    {
      "x": -4,
      "y": 6,
      "z": 7,
      "name": "Wood_Sallow_Trunk_Full",
      "support": 15,
      "rotation": 2
    },
    {
      "x": -4,
      "y": 7,
      "z": 7,
      "name": "Wood_Sallow_Trunk",
      "support": 15,
      "rotation": 2
    },
    {
      "x": -4,
      "y": 8,
      "z": 7,
      "name": "Wood_Sallow_Trunk",
      "support": 15,
      "rotation": 2
    },
    {
      "x": -4,
      "y": 9,
      "z": 7,
      "name": "Wood_Sallow_Trunk",
      "support": 15,
      "rotation": 2
    },
    {
      "x": -4,
      "y": 10,
      "z": 7,
      "name": "Wood_Sallow_Trunk",
      "support": 15,
      "rotation": 2
    },
    {
      "x": -4,
      "y": 11,
      "z": 7,
      "name": "Wood_Sallow_Trunk_Full",
      "support": 15,
      "rotation": 2
    },
    {
      "x": -4,
      "y": 65,
      "z": 7,
      "name": "Plant_Leaves_Beech",
      "support": 15,
      "rotation": 2
    },
    {
      "x": -4,
      "y": 66,
      "z": 7,
      "name": "Plant_Leaves_Beech",
      "support": 15,
      "rotation": 2
    },
    {
      "x": -3,
      "y": 3,
      "z": -10,
      "name": "Wood_Sallow_Roots",
      "rotation": 2
    },
    {
      "x": -3,
      "y": 4,
      "z": -10,
      "name": "Wood_Sallow_Trunk_Full",
      "support": 15,
      "rotation": 2
    },
    {
      "x": -3,
      "y": 5,
      "z": -10,
      "name": "Wood_Sallow_Trunk",
      "support": 15,
      "rotation": 2
    },
    {
      "x": -3,
      "y": 6,
      "z": -10,
      "name": "Wood_Sallow_Trunk",
      "support": 15,
      "rotation": 2
    },
    {
      "x": -3,
      "y": 7,
      "z": -10,
      "name": "Wood_Sallow_Trunk",
      "support": 15,
      "rotation": 2
    },
    {
      "x": -3,
      "y": 8,
      "z": -10,
      "name": "Wood_Sallow_Trunk",
      "support": 15,
      "rotation": 2
    },
    {
      "x": -3,
      "y": 9,
      "z": -10,
      "name": "Wood_Sallow_Trunk_Full",
      "support": 15,
      "rotation": 2
    },
    {
      "x": -3,
      "y": 4,
      "z": -9,
      "name": "Wood_Sallow_Roots",
      "rotation": 2
    },
    {
      "x": -3,
      "y": 5,
      "z": -9,
      "name": "Wood_Sallow_Trunk_Full",
      "support": 15,
      "rotation": 2
    },
    {
      "x": -3,
      "y": 6,
      "z": -9,
      "name": "Wood_Sallow_Trunk",
      "support": 15,
      "rotation": 2
    },
    {
      "x": -3,
      "y": 7,
      "z": -9,
      "name": "Wood_Sallow_Trunk",
      "support": 15,
      "rotation": 2
    },
    {
      "x": -3,
      "y": 8,
      "z": -9,
      "name": "Wood_Sallow_Trunk",
      "support": 15,
      "rotation": 2
    },
    {
      "x": -3,
      "y": 9,
      "z": -9,
      "name": "Wood_Sallow_Trunk_Full",
      "support": 15,
      "rotation": 2
    },
    {
      "x": -3,
      "y": 10,
      "z": -7,
      "name": "Plant_Moss_Wall_Green_Dark",
      "support": 15,
      "rotation": 3
    },
    {
      "x": -3,
      "y": 58,
      "z": -7,
      "name": "Plant_Leaves_Beech",
      "support": 15,
      "rotation": 2
    },
    {
      "x": -3,
      "y": 59,
      "z": -7,
      "name": "Plant_Leaves_Beech",
      "support": 15,
      "rotation": 2
    },
    {
      "x": -3,
      "y": 57,
      "z": -6,
      "name": "Plant_Leaves_Beech",
      "support": 15,
      "rotation": 2
    },
    {
      "x": -3,
      "y": 58,
      "z": -6,
      "name": "Wood_Sallow_Branch_Corner",
      "support": 15,
      "rotation": 3
    },
    {
      "x": -3,
      "y": 59,
      "z": -6,
      "name": "Wood_Sallow_Branch_Long",
      "support": 15,
      "rotation": 2
    },
    {
      "x": -3,
      "y": 60,
      "z": -6,
      "name": "Plant_Leaves_Beech",
      "support": 15,
      "rotation": 2
    },
    {
      "x": -3,
      "y": 62,
      "z": -6,
      "name": "Plant_Leaves_Beech",
      "support": 15,
      "rotation": 2
    },
    {
      "x": -3,
      "y": 63,
      "z": -6,
      "name": "Plant_Leaves_Beech",
      "support": 15,
      "rotation": 2
    },
    {
      "x": -3,
      "y": 29,
      "z": -5,
      "name": "Furniture_Crude_Platform"
    },
    {
      "x": -3,
      "y": 30,
      "z": -5,
      "name": "*Wood_Softwood_Fence_State_Definitions_Corner",
      "rotation": 1
    },
    {
      "x": -3,
      "y": 31,
      "z": -5,
      "name": "*Wood_Softwood_Fence_State_Definitions_Corner",
      "rotation": 1
    },
    {
      "x": -3,
      "y": 32,
      "z": -5,
      "name": "*Wood_Softwood_Fence_State_Definitions_Corner",
      "rotation": 1
    },
    {
      "x": -3,
      "y": 33,
      "z": -5,
      "name": "*Wood_Tropicalwood_Roof_State_Definitions_Corner_Right",
      "rotation": 3
    },
    {
      "x": -3,
      "y": 58,
      "z": -5,
      "name": "Plant_Leaves_Beech",
      "support": 15,
      "rotation": 2
    },
    {
      "x": -3,
      "y": 59,
      "z": -5,
      "name": "Plant_Leaves_Beech",
      "support": 15,
      "rotation": 2
    },
    {
      "x": -3,
      "y": 62,
      "z": -5,
      "name": "Plant_Leaves_Beech",
      "support": 15,
      "rotation": 2
    },
    {
      "x": -3,
      "y": 65,
      "z": -5,
      "name": "Plant_Leaves_Beech",
      "support": 15,
      "rotation": 2
    },
    {
      "x": -3,
      "y": 29,
      "z": -4,
      "name": "Furniture_Crude_Platform",
      "rotation": 1
    },
    {
      "x": -3,
      "y": 30,
      "z": -4,
      "name": "*Wood_Softwood_Fence_State_Definitions_Corner",
      "rotation": 3
    },
    {
      "x": -3,
      "y": 31,
      "z": -4,
      "name": "*Wood_Softwood_Fence_State_Definitions_Corner",
      "rotation": 3
    },
    {
      "x": -3,
      "y": 32,
      "z": -4,
      "name": "*Wood_Softwood_Fence_State_Definitions_Corner",
      "rotation": 3
    },
    {
      "x": -3,
      "y": 33,
      "z": -4,
      "name": "*Wood_Tropicalwood_Roof_State_Definitions_Inverted_Corner_Left",
      "rotation": 2
    },
    {
      "x": -3,
      "y": 64,
      "z": -4,
      "name": "Plant_Leaves_Beech",
      "support": 15,
      "rotation": 2
    },
    {
      "x": -3,
      "y": 29,
      "z": -3,
      "name": "Wood_Goldenwood_Planks_Half",
      "rotation": 8
    },
    {
      "x": -3,
      "y": 34,
      "z": -3,
      "name": "*Wood_Tropicalwood_Roof_Shallow_State_Definitions_Corner_Left",
      "rotation": 2
    },
    {
      "x": -3,
      "y": 62,
      "z": -3,
      "name": "Wood_Sallow_Trunk_Full",
      "support": 15,
      "rotation": 6
    },
    {
      "x": -3,
      "y": 66,
      "z": -3,
      "name": "Plant_Leaves_Beech",
      "support": 15,
      "rotation": 2
    },
    {
      "x": -3,
      "y": 7,
      "z": -2,
      "name": "Wood_Sallow_Trunk_Full",
      "support": 15,
      "rotation": 2
    },
    {
      "x": -3,
      "y": 8,
      "z": -2,
      "name": "Wood_Sallow_Trunk",
      "support": 15,
      "rotation": 2
    },
    {
      "x": -3,
      "y": 9,
      "z": -2,
      "name": "Wood_Sallow_Trunk",
      "support": 15,
      "rotation": 2
    },
    {
      "x": -3,
      "y": 10,
      "z": -2,
      "name": "Wood_Sallow_Trunk",
      "support": 15,
      "rotation": 2
    },
    {
      "x": -3,
      "y": 11,
      "z": -2,
      "name": "Wood_Sallow_Trunk",
      "support": 15,
      "rotation": 2
    },
    {
      "x": -3,
      "y": 12,
      "z": -2,
      "name": "Wood_Sallow_Trunk",
      "support": 15,
      "rotation": 2
    },
    {
      "x": -3,
      "y": 13,
      "z": -2,
      "name": "Wood_Sallow_Trunk",
      "support": 15,
      "rotation": 2
    },
    {
      "x": -3,
      "y": 14,
      "z": -2,
      "name": "Wood_Sallow_Trunk_Full",
      "support": 15,
      "rotation": 2
    },
    {
      "x": -3,
      "y": 29,
      "z": -2,
      "name": "Wood_Goldenwood_Planks_Half",
      "rotation": 8
    },
    {
      "x": -3,
      "y": 34,
      "z": -2,
      "name": "*Wood_Tropicalwood_Roof_Shallow_State_Definitions_Corner_Left",
      "filler": 32,
      "rotation": 2
    },
    {
      "x": -3,
      "y": 62,
      "z": -2,
      "name": "Wood_Sallow_Trunk_Full",
      "support": 15,
      "rotation": 7
    },
    {
      "x": -3,
      "y": 6,
      "z": -1,
      "name": "Wood_Sallow_Roots",
      "rotation": 2
    },
    {
      "x": -3,
      "y": 7,
      "z": -1,
      "name": "Wood_Sallow_Trunk_Full",
      "support": 15,
      "rotation": 2
    },
    {
      "x": -3,
      "y": 8,
      "z": -1,
      "name": "Wood_Sallow_Trunk",
      "support": 15,
      "rotation": 2
    },
    {
      "x": -3,
      "y": 9,
      "z": -1,
      "name": "Wood_Sallow_Trunk",
      "support": 15,
      "rotation": 2
    },
    {
      "x": -3,
      "y": 10,
      "z": -1,
      "name": "Wood_Sallow_Trunk",
      "support": 15,
      "rotation": 2
    },
    {
      "x": -3,
      "y": 11,
      "z": -1,
      "name": "Wood_Sallow_Trunk",
      "support": 15,
      "rotation": 2
    },
    {
      "x": -3,
      "y": 12,
      "z": -1,
      "name": "Wood_Sallow_Trunk",
      "support": 15,
      "rotation": 2
    },
    {
      "x": -3,
      "y": 13,
      "z": -1,
      "name": "Wood_Sallow_Trunk",
      "support": 15,
      "rotation": 2
    },
    {
      "x": -3,
      "y": 14,
      "z": -1,
      "name": "Wood_Sallow_Trunk_Full",
      "support": 15,
      "rotation": 2
    },
    {
      "x": -3,
      "y": 29,
      "z": -1,
      "name": "Wood_Goldenwood_Planks_Half",
      "rotation": 8
    },
    {
      "x": -3,
      "y": 34,
      "z": -1,
      "name": "Wood_Tropicalwood_Roof_Shallow",
      "rotation": 3
    },
    {
      "x": -3,
      "y": 6,
      "z": 0,
      "name": "Wood_Sallow_Roots",
      "rotation": 2
    },
    {
      "x": -3,
      "y": 7,
      "z": 0,
      "name": "Wood_Sallow_Trunk_Full",
      "support": 15,
      "rotation": 2
    },
    {
      "x": -3,
      "y": 8,
      "z": 0,
      "name": "Wood_Sallow_Trunk",
      "support": 15,
      "rotation": 2
    },
    {
      "x": -3,
      "y": 9,
      "z": 0,
      "name": "Wood_Sallow_Trunk",
      "support": 15,
      "rotation": 2
    },
    {
      "x": -3,
      "y": 10,
      "z": 0,
      "name": "Wood_Sallow_Trunk",
      "support": 15,
      "rotation": 2
    },
    {
      "x": -3,
      "y": 11,
      "z": 0,
      "name": "Wood_Sallow_Trunk_Full",
      "support": 15,
      "rotation": 2
    },
    {
      "x": -3,
      "y": 29,
      "z": 0,
      "name": "Wood_Goldenwood_Planks_Half",
      "rotation": 8
    },
    {
      "x": -3,
      "y": 30,
      "z": 0,
      "name": "Furniture_Village_Table",
      "filler": 992,
      "rotation": 2
    },
    {
      "x": -3,
      "y": 34,
      "z": 0,
      "name": "Wood_Tropicalwood_Roof_Shallow",
      "filler": 1,
      "rotation": 3
    },
    {
      "x": -3,
      "y": 59,
      "z": 0,
      "name": "Wood_Sallow_Branch_Long",
      "support": 15,
      "rotation": 7
    },
    {
      "x": -3,
      "y": 64,
      "z": 0,
      "name": "Plant_Leaves_Beech",
      "support": 15,
      "rotation": 2
    },
    {
      "x": -3,
      "y": 65,
      "z": 0,
      "name": "Plant_Leaves_Beech",
      "support": 15,
      "rotation": 2
    },
    {
      "x": -3,
      "y": 8,
      "z": 1,
      "name": "Wood_Sallow_Trunk_Full",
      "support": 15,
      "rotation": 2
    },
    {
      "x": -3,
      "y": 9,
      "z": 1,
      "name": "Wood_Sallow_Trunk",
      "support": 15,
      "rotation": 2
    },
    {
      "x": -3,
      "y": 10,
      "z": 1,
      "name": "Wood_Sallow_Trunk",
      "support": 15,
      "rotation": 2
    },
    {
      "x": -3,
      "y": 11,
      "z": 1,
      "name": "Wood_Sallow_Trunk",
      "support": 15,
      "rotation": 2
    },
    {
      "x": -3,
      "y": 12,
      "z": 1,
      "name": "Wood_Sallow_Trunk",
      "support": 15,
      "rotation": 2
    },
    {
      "x": -3,
      "y": 13,
      "z": 1,
      "name": "Wood_Sallow_Trunk_Full",
      "support": 15,
      "rotation": 2
    },
    {
      "x": -3,
      "y": 27,
      "z": 1,
      "name": "Wood_Sallow_Trunk_Half",
      "rotation": 7
    },
    {
      "x": -3,
      "y": 28,
      "z": 1,
      "name": "Wood_Sallow_Trunk",
      "support": 15
    },
    {
      "x": -3,
      "y": 29,
      "z": 1,
      "name": "*Wood_Goldenwood_Planks_Half_State_Definitions_Block",
      "rotation": 8
    },
    {
      "x": -3,
      "y": 30,
      "z": 1,
      "name": "Furniture_Village_Table",
      "rotation": 2
    },
    {
      "x": -3,
      "y": 34,
      "z": 1,
      "name": "Wood_Tropicalwood_Roof_Shallow",
      "filler": 1,
      "rotation": 3
    },
    {
      "x": -3,
      "y": 56,
      "z": 1,
      "name": "Wood_Sallow_Branch_Long",
      "support": 15,
      "rotation": 7
    },
    {
      "x": -3,
      "y": 29,
      "z": 2,
      "name": "Wood_Goldenwood_Planks_Half",
      "rotation": 8
    },
    {
      "x": -3,
      "y": 34,
      "z": 2,
      "name": "Wood_Tropicalwood_Roof_Shallow",
      "filler": 1,
      "rotation": 3
    },
    {
      "x": -3,
      "y": 8,
      "z": 3,
      "name": "Wood_Sallow_Trunk_Full",
      "support": 15,
      "rotation": 2
    },
    {
      "x": -3,
      "y": 9,
      "z": 3,
      "name": "Wood_Sallow_Trunk",
      "support": 15,
      "rotation": 2
    },
    {
      "x": -3,
      "y": 10,
      "z": 3,
      "name": "Wood_Sallow_Trunk",
      "support": 15,
      "rotation": 2
    },
    {
      "x": -3,
      "y": 11,
      "z": 3,
      "name": "Wood_Sallow_Trunk_Full",
      "support": 15,
      "rotation": 2
    },
    {
      "x": -3,
      "y": 12,
      "z": 3,
      "name": "Plant_Moss_Rug_Green_Dark",
      "support": 15,
      "rotation": 2
    },
    {
      "x": -3,
      "y": 29,
      "z": 3,
      "name": "Wood_Goldenwood_Planks_Half",
      "rotation": 8
    },
    {
      "x": -3,
      "y": 34,
      "z": 3,
      "name": "Wood_Tropicalwood_Roof_Shallow",
      "rotation": 3
    },
    {
      "x": -3,
      "y": 64,
      "z": 3,
      "name": "Wood_Sallow_Branch_Long",
      "support": 15,
      "rotation": 7
    },
    {
      "x": -3,
      "y": 6,
      "z": 4,
      "name": "Wood_Sallow_Roots",
      "rotation": 2
    },
    {
      "x": -3,
      "y": 7,
      "z": 4,
      "name": "Wood_Sallow_Trunk_Full",
      "support": 15,
      "rotation": 2
    },
    {
      "x": -3,
      "y": 8,
      "z": 4,
      "name": "Wood_Sallow_Trunk",
      "support": 15,
      "rotation": 2
    },
    {
      "x": -3,
      "y": 9,
      "z": 4,
      "name": "Wood_Sallow_Trunk",
      "support": 15,
      "rotation": 2
    },
    {
      "x": -3,
      "y": 10,
      "z": 4,
      "name": "Wood_Sallow_Trunk",
      "support": 15,
      "rotation": 2
    },
    {
      "x": -3,
      "y": 11,
      "z": 4,
      "name": "Wood_Sallow_Trunk_Full",
      "support": 15,
      "rotation": 2
    },
    {
      "x": -3,
      "y": 12,
      "z": 4,
      "name": "Plant_Moss_Rug_Green_Dark",
      "support": 15,
      "rotation": 2
    },
    {
      "x": -3,
      "y": 14,
      "z": 4,
      "name": "Plant_Moss_Wall_Green_Dark",
      "support": 15,
      "rotation": 3
    },
    {
      "x": -3,
      "y": 29,
      "z": 4,
      "name": "Wood_Goldenwood_Planks_Half",
      "rotation": 8
    },
    {
      "x": -3,
      "y": 34,
      "z": 4,
      "name": "*Wood_Tropicalwood_Roof_Shallow_State_Definitions_Corner_Left",
      "filler": 992,
      "rotation": 3
    },
    {
      "x": -3,
      "y": 59,
      "z": 4,
      "name": "Wood_Sallow_Trunk_Full",
      "support": 15,
      "rotation": 7
    },
    {
      "x": -3,
      "y": 67,
      "z": 4,
      "name": "Wood_Sallow_Branch_Long",
      "support": 15,
      "rotation": 7
    },
    {
      "x": -3,
      "y": 69,
      "z": 4,
      "name": "Plant_Leaves_Beech",
      "support": 15,
      "rotation": 2
    },
    {
      "x": -3,
      "y": 7,
      "z": 5,
      "name": "Wood_Sallow_Trunk_Full",
      "support": 15,
      "rotation": 2
    },
    {
      "x": -3,
      "y": 8,
      "z": 5,
      "name": "Wood_Sallow_Trunk",
      "support": 15,
      "rotation": 2
    },
    {
      "x": -3,
      "y": 9,
      "z": 5,
      "name": "Wood_Sallow_Trunk",
      "support": 15,
      "rotation": 2
    },
    {
      "x": -3,
      "y": 10,
      "z": 5,
      "name": "Wood_Sallow_Trunk",
      "support": 15,
      "rotation": 2
    },
    {
      "x": -3,
      "y": 11,
      "z": 5,
      "name": "Wood_Sallow_Trunk",
      "support": 15,
      "rotation": 2
    },
    {
      "x": -3,
      "y": 12,
      "z": 5,
      "name": "Wood_Sallow_Trunk",
      "support": 15,
      "rotation": 2
    },
    {
      "x": -3,
      "y": 13,
      "z": 5,
      "name": "Wood_Sallow_Trunk_Full",
      "support": 15,
      "rotation": 2
    },
    {
      "x": -3,
      "y": 29,
      "z": 5,
      "name": "Wood_Goldenwood_Planks_Half",
      "rotation": 8
    },
    {
      "x": -3,
      "y": 34,
      "z": 5,
      "name": "*Wood_Tropicalwood_Roof_Shallow_State_Definitions_Corner_Left",
      "rotation": 3
    },
    {
      "x": -3,
      "y": 59,
      "z": 5,
      "name": "Wood_Sallow_Trunk_Full",
      "support": 15,
      "rotation": 6
    },
    {
      "x": -3,
      "y": 62,
      "z": 5,
      "name": "Plant_Leaves_Beech",
      "support": 15,
      "rotation": 2
    },
    {
      "x": -3,
      "y": 65,
      "z": 5,
      "name": "Wood_Sallow_Branch_Corner",
      "support": 15,
      "rotation": 51
    },
    {
      "x": -3,
      "y": 7,
      "z": 6,
      "name": "Wood_Sallow_Trunk_Full",
      "support": 15,
      "rotation": 2
    },
    {
      "x": -3,
      "y": 8,
      "z": 6,
      "name": "Wood_Sallow_Trunk",
      "support": 15,
      "rotation": 2
    },
    {
      "x": -3,
      "y": 9,
      "z": 6,
      "name": "Wood_Sallow_Trunk",
      "support": 15,
      "rotation": 2
    },
    {
      "x": -3,
      "y": 10,
      "z": 6,
      "name": "Wood_Sallow_Trunk",
      "support": 15,
      "rotation": 2
    },
    {
      "x": -3,
      "y": 11,
      "z": 6,
      "name": "Wood_Sallow_Trunk",
      "support": 15,
      "rotation": 2
    },
    {
      "x": -3,
      "y": 12,
      "z": 6,
      "name": "Wood_Sallow_Trunk_Full",
      "support": 15,
      "rotation": 2
    },
    {
      "x": -3,
      "y": 29,
      "z": 6,
      "name": "Furniture_Crude_Platform",
      "rotation": 1
    },
    {
      "x": -3,
      "y": 30,
      "z": 6,
      "name": "*Wood_Softwood_Fence_State_Definitions_Corner"
    },
    {
      "x": -3,
      "y": 31,
      "z": 6,
      "name": "*Wood_Softwood_Fence_State_Definitions_Corner"
    },
    {
      "x": -3,
      "y": 32,
      "z": 6,
      "name": "*Wood_Softwood_Fence_State_Definitions_Corner"
    },
    {
      "x": -3,
      "y": 33,
      "z": 6,
      "name": "*Wood_Tropicalwood_Roof_State_Definitions_Inverted_Corner_Left",
      "rotation": 3
    },
    {
      "x": -3,
      "y": 65,
      "z": 6,
      "name": "Wood_Sallow_Branch_Corner",
      "support": 15,
      "rotation": 16
    },
    {
      "x": -3,
      "y": 67,
      "z": 6,
      "name": "Plant_Leaves_Beech",
      "support": 15,
      "rotation": 2
    },
    {
      "x": -3,
      "y": 68,
      "z": 6,
      "name": "Plant_Leaves_Beech",
      "support": 15,
      "rotation": 2
    },
    {
      "x": -3,
      "y": 29,
      "z": 7,
      "name": "Furniture_Crude_Platform"
    },
    {
      "x": -3,
      "y": 30,
      "z": 7,
      "name": "*Wood_Softwood_Fence_State_Definitions_Corner",
      "rotation": 2
    },
    {
      "x": -3,
      "y": 31,
      "z": 7,
      "name": "*Wood_Softwood_Fence_State_Definitions_Corner",
      "rotation": 2
    },
    {
      "x": -3,
      "y": 32,
      "z": 7,
      "name": "*Wood_Softwood_Fence_State_Definitions_Corner",
      "rotation": 2
    },
    {
      "x": -3,
      "y": 33,
      "z": 7,
      "name": "*Wood_Tropicalwood_Roof_State_Definitions_Corner_Right"
    },
    {
      "x": -3,
      "y": 66,
      "z": 7,
      "name": "Plant_Leaves_Beech",
      "support": 15,
      "rotation": 2
    },
    {
      "x": -3,
      "y": 67,
      "z": 7,
      "name": "Plant_Leaves_Beech",
      "support": 15,
      "rotation": 2
    },
    {
      "x": -3,
      "y": 59,
      "z": 8,
      "name": "Plant_Leaves_Beech",
      "support": 15,
      "rotation": 2
    },
    {
      "x": -3,
      "y": 60,
      "z": 8,
      "name": "Plant_Leaves_Beech",
      "support": 15,
      "rotation": 2
    },
    {
      "x": -3,
      "y": 60,
      "z": 9,
      "name": "Plant_Leaves_Beech",
      "support": 15,
      "rotation": 2
    },
    {
      "x": -2,
      "y": 5,
      "z": -9,
      "name": "Wood_Sallow_Trunk_Full",
      "support": 15,
      "rotation": 2
    },
    {
      "x": -2,
      "y": 6,
      "z": -9,
      "name": "Wood_Sallow_Trunk",
      "support": 15,
      "rotation": 2
    },
    {
      "x": -2,
      "y": 7,
      "z": -9,
      "name": "Wood_Sallow_Trunk",
      "support": 15,
      "rotation": 2
    },
    {
      "x": -2,
      "y": 8,
      "z": -9,
      "name": "Wood_Sallow_Trunk",
      "support": 15,
      "rotation": 2
    },
    {
      "x": -2,
      "y": 9,
      "z": -9,
      "name": "Wood_Sallow_Trunk_Full",
      "support": 15,
      "rotation": 2
    },
    {
      "x": -2,
      "y": 4,
      "z": -8,
      "name": "Wood_Sallow_Roots",
      "rotation": 2
    },
    {
      "x": -2,
      "y": 5,
      "z": -8,
      "name": "Wood_Sallow_Trunk_Full",
      "support": 15,
      "rotation": 2
    },
    {
      "x": -2,
      "y": 6,
      "z": -8,
      "name": "Wood_Sallow_Trunk",
      "support": 15,
      "rotation": 2
    },
    {
      "x": -2,
      "y": 7,
      "z": -8,
      "name": "Wood_Sallow_Trunk",
      "support": 15,
      "rotation": 2
    },
    {
      "x": -2,
      "y": 8,
      "z": -8,
      "name": "Wood_Sallow_Trunk",
      "support": 15,
      "rotation": 2
    },
    {
      "x": -2,
      "y": 9,
      "z": -8,
      "name": "Wood_Sallow_Trunk",
      "support": 15,
      "rotation": 2
    },
    {
      "x": -2,
      "y": 10,
      "z": -8,
      "name": "Wood_Sallow_Trunk_Full",
      "support": 15,
      "rotation": 2
    },
    {
      "x": -2,
      "y": 5,
      "z": -7,
      "name": "Wood_Sallow_Roots",
      "rotation": 2
    },
    {
      "x": -2,
      "y": 6,
      "z": -7,
      "name": "Wood_Sallow_Trunk_Full",
      "support": 15,
      "rotation": 2
    },
    {
      "x": -2,
      "y": 7,
      "z": -7,
      "name": "Wood_Sallow_Trunk",
      "support": 15,
      "rotation": 2
    },
    {
      "x": -2,
      "y": 8,
      "z": -7,
      "name": "Wood_Sallow_Trunk",
      "support": 15,
      "rotation": 2
    },
    {
      "x": -2,
      "y": 9,
      "z": -7,
      "name": "Wood_Sallow_Trunk",
      "support": 15,
      "rotation": 2
    },
    {
      "x": -2,
      "y": 10,
      "z": -7,
      "name": "Wood_Sallow_Trunk_Full",
      "support": 15,
      "rotation": 2
    },
    {
      "x": -2,
      "y": 11,
      "z": -7,
      "name": "Plant_Moss_Rug_Green_Dark",
      "support": 15,
      "rotation": 2
    },
    {
      "x": -2,
      "y": 58,
      "z": -7,
      "name": "Plant_Leaves_Beech",
      "support": 15,
      "rotation": 2
    },
    {
      "x": -2,
      "y": 62,
      "z": -7,
      "name": "Plant_Leaves_Beech",
      "support": 15,
      "rotation": 2
    },
    {
      "x": -2,
      "y": 63,
      "z": -7,
      "name": "Plant_Leaves_Beech",
      "support": 15,
      "rotation": 2
    },
    {
      "x": -2,
      "y": 12,
      "z": -6,
      "name": "Plant_Moss_Wall_Green_Dark",
      "support": 15,
      "rotation": 3
    },
    {
      "x": -2,
      "y": 58,
      "z": -6,
      "name": "Wood_Sallow_Branch_Corner",
      "support": 15,
      "rotation": 50
    },
    {
      "x": -2,
      "y": 59,
      "z": -6,
      "name": "Plant_Leaves_Beech",
      "support": 15,
      "rotation": 2
    },
    {
      "x": -2,
      "y": 61,
      "z": -6,
      "name": "Plant_Leaves_Beech",
      "support": 15,
      "rotation": 2
    },
    {
      "x": -2,
      "y": 62,
      "z": -6,
      "name": "Wood_Sallow_Branch_Corner",
      "support": 15,
      "rotation": 2
    },
    {
      "x": -2,
      "y": 63,
      "z": -6,
      "name": "Wood_Sallow_Branch_Long",
      "support": 15,
      "rotation": 2
    },
    {
      "x": -2,
      "y": 64,
      "z": -6,
      "name": "Plant_Leaves_Beech",
      "support": 15,
      "rotation": 2
    },
    {
      "x": -2,
      "y": 29,
      "z": -5,
      "name": "Furniture_Crude_Platform"
    },
    {
      "x": -2,
      "y": 30,
      "z": -5,
      "name": "Wood_Softwood_Fence",
      "rotation": 2
    },
    {
      "x": -2,
      "y": 31,
      "z": -5,
      "name": "Wood_Goldenwood_Fence",
      "rotation": 2
    },
    {
      "x": -2,
      "y": 32,
      "z": -5,
      "name": "Wood_Softwood_Fence",
      "rotation": 2
    },
    {
      "x": -2,
      "y": 33,
      "z": -5,
      "name": "Wood_Tropicalwood_Roof",
      "rotation": 2
    },
    {
      "x": -2,
      "y": 58,
      "z": -5,
      "name": "Wood_Sallow_Branch_Long",
      "support": 15,
      "rotation": 6
    },
    {
      "x": -2,
      "y": 61,
      "z": -5,
      "name": "Plant_Leaves_Beech",
      "support": 15,
      "rotation": 2
    },
    {
      "x": -2,
      "y": 62,
      "z": -5,
      "name": "Wood_Sallow_Branch_Long",
      "support": 15,
      "rotation": 6
    },
    {
      "x": -2,
      "y": 63,
      "z": -5,
      "name": "Plant_Leaves_Beech",
      "support": 15,
      "rotation": 2
    },
    {
      "x": -2,
      "y": 66,
      "z": -5,
      "name": "Plant_Leaves_Beech",
      "support": 15,
      "rotation": 2
    },
    {
      "x": -2,
      "y": 67,
      "z": -5,
      "name": "Plant_Leaves_Beech",
      "support": 15,
      "rotation": 2
    },
    {
      "x": -2,
      "y": 29,
      "z": -4,
      "name": "Wood_Goldenwood_Planks_Half",
      "rotation": 8
    },
    {
      "x": -2,
      "y": 30,
      "z": -4,
      "name": "Furniture_Crude_Chest_Small",
      "components": {
        "Components": {
          "PlacedByInteraction": {
            "WhoPlacedUuid": {
              "$binary": "i+Pl1XV4SJWc91StkZuWWA==",
              "$type": "04"
            }
          },
          "ItemContainerBlock": {
            "ItemContainer": {
              "Capacity": 18,
              "Items": {}
            },
            "Capacity": 18
          }
        }
      }
    },
    {
      "x": -2,
      "y": 34,
      "z": -4,
      "name": "Wood_Tropicalwood_Roof_Flat"
    },
    {
      "x": -2,
      "y": 58,
      "z": -4,
      "name": "Wood_Sallow_Branch_Corner",
      "support": 15,
      "rotation": 19
    },
    {
      "x": -2,
      "y": 62,
      "z": -4,
      "name": "Wood_Sallow_Branch_Long",
      "support": 15,
      "rotation": 6
    },
    {
      "x": -2,
      "y": 63,
      "z": -4,
      "name": "Plant_Leaves_Beech",
      "support": 15,
      "rotation": 2
    },
    {
      "x": -2,
      "y": 29,
      "z": -3,
      "name": "Wood_Goldenwood_Planks_Half",
      "rotation": 8
    },
    {
      "x": -2,
      "y": 34,
      "z": -3,
      "name": "*Wood_Tropicalwood_Roof_Shallow_State_Definitions_Corner_Left",
      "filler": 1,
      "rotation": 2
    },
    {
      "x": -2,
      "y": 62,
      "z": -3,
      "name": "Wood_Sallow_Branch_Long",
      "support": 15,
      "rotation": 6
    },
    {
      "x": -2,
      "y": 8,
      "z": -2,
      "name": "Wood_Sallow_Trunk_Full",
      "support": 15,
      "rotation": 2
    },
    {
      "x": -2,
      "y": 9,
      "z": -2,
      "name": "Wood_Sallow_Trunk",
      "support": 15,
      "rotation": 2
    },
    {
      "x": -2,
      "y": 10,
      "z": -2,
      "name": "Wood_Sallow_Trunk",
      "support": 15,
      "rotation": 2
    },
    {
      "x": -2,
      "y": 11,
      "z": -2,
      "name": "Wood_Sallow_Trunk_Full",
      "support": 15,
      "rotation": 2
    },
    {
      "x": -2,
      "y": 29,
      "z": -2,
      "name": "Wood_Goldenwood_Planks_Half",
      "rotation": 8
    },
    {
      "x": -2,
      "y": 34,
      "z": -2,
      "name": "*Wood_Tropicalwood_Roof_Shallow_State_Definitions_Corner_Left",
      "filler": 33,
      "rotation": 2
    },
    {
      "x": -2,
      "y": 61,
      "z": -2,
      "name": "Wood_Sallow_Trunk_Full",
      "support": 15,
      "rotation": 6
    },
    {
      "x": -2,
      "y": 62,
      "z": -2,
      "name": "Wood_Sallow_Trunk_Full",
      "support": 15,
      "rotation": 2
    },
    {
      "x": -2,
      "y": 7,
      "z": -1,
      "name": "Wood_Sallow_Roots",
      "rotation": 2
    },
    {
      "x": -2,
      "y": 8,
      "z": -1,
      "name": "Wood_Sallow_Trunk_Full",
      "support": 15,
      "rotation": 2
    },
    {
      "x": -2,
      "y": 9,
      "z": -1,
      "name": "Wood_Sallow_Trunk",
      "support": 15,
      "rotation": 2
    },
    {
      "x": -2,
      "y": 10,
      "z": -1,
      "name": "Wood_Sallow_Trunk",
      "support": 15,
      "rotation": 2
    },
    {
      "x": -2,
      "y": 11,
      "z": -1,
      "name": "Wood_Sallow_Trunk",
      "support": 15,
      "rotation": 2
    },
    {
      "x": -2,
      "y": 12,
      "z": -1,
      "name": "Wood_Sallow_Trunk",
      "support": 15,
      "rotation": 2
    },
    {
      "x": -2,
      "y": 13,
      "z": -1,
      "name": "Wood_Sallow_Trunk",
      "support": 15,
      "rotation": 2
    },
    {
      "x": -2,
      "y": 14,
      "z": -1,
      "name": "Wood_Sallow_Trunk",
      "support": 15,
      "rotation": 2
    },
    {
      "x": -2,
      "y": 15,
      "z": -1,
      "name": "Wood_Sallow_Trunk_Full",
      "support": 15,
      "rotation": 2
    },
    {
      "x": -2,
      "y": 29,
      "z": -1,
      "name": "Wood_Goldenwood_Planks_Half",
      "rotation": 8
    },
    {
      "x": -2,
      "y": 34,
      "z": -1,
      "name": "Wood_Tropicalwood_Roof_Shallow",
      "filler": 1,
      "rotation": 3
    },
    {
      "x": -2,
      "y": 61,
      "z": -1,
      "name": "Wood_Sallow_Trunk_Full",
      "support": 15,
      "rotation": 6
    },
    {
      "x": -2,
      "y": 64,
      "z": -1,
      "name": "Plant_Leaves_Beech",
      "support": 15,
      "rotation": 2
    },
    {
      "x": -2,
      "y": 65,
      "z": -1,
      "name": "Plant_Leaves_Beech",
      "support": 15,
      "rotation": 2
    },
    {
      "x": -2,
      "y": 7,
      "z": 0,
      "name": "Wood_Sallow_Roots",
      "rotation": 2
    },
    {
      "x": -2,
      "y": 8,
      "z": 0,
      "name": "Wood_Sallow_Trunk_Full",
      "support": 15,
      "rotation": 2
    },
    {
      "x": -2,
      "y": 9,
      "z": 0,
      "name": "Wood_Sallow_Trunk",
      "support": 15,
      "rotation": 2
    },
    {
      "x": -2,
      "y": 10,
      "z": 0,
      "name": "Wood_Sallow_Trunk",
      "support": 15,
      "rotation": 2
    },
    {
      "x": -2,
      "y": 11,
      "z": 0,
      "name": "Wood_Sallow_Trunk",
      "support": 15,
      "rotation": 2
    },
    {
      "x": -2,
      "y": 12,
      "z": 0,
      "name": "Wood_Sallow_Trunk",
      "support": 15,
      "rotation": 2
    },
    {
      "x": -2,
      "y": 13,
      "z": 0,
      "name": "Wood_Sallow_Trunk",
      "support": 15,
      "rotation": 2
    },
    {
      "x": -2,
      "y": 14,
      "z": 0,
      "name": "Wood_Sallow_Trunk",
      "support": 15,
      "rotation": 2
    },
    {
      "x": -2,
      "y": 15,
      "z": 0,
      "name": "Wood_Sallow_Trunk_Full",
      "support": 15,
      "rotation": 2
    },
    {
      "x": -2,
      "y": 29,
      "z": 0,
      "name": "Wood_Goldenwood_Planks_Half",
      "rotation": 8
    },
    {
      "x": -2,
      "y": 35,
      "z": 0,
      "name": "Wood_Tropicalwood_Roof_Flat",
      "rotation": 1
    },
    {
      "x": -2,
      "y": 59,
      "z": 0,
      "name": "Wood_Sallow_Branch_Long",
      "support": 15,
      "rotation": 7
    },
    {
      "x": -2,
      "y": 63,
      "z": 0,
      "name": "Plant_Leaves_Beech",
      "support": 15,
      "rotation": 2
    },
    {
      "x": -2,
      "y": 64,
      "z": 0,
      "name": "Wood_Sallow_Branch_Corner",
      "support": 15,
      "rotation": 3
    },
    {
      "x": -2,
      "y": 65,
      "z": 0,
      "name": "Wood_Sallow_Branch_Long",
      "support": 15,
      "rotation": 2
    },
    {
      "x": -2,
      "y": 66,
      "z": 0,
      "name": "Plant_Leaves_Beech",
      "support": 15,
      "rotation": 2
    },
    {
      "x": -2,
      "y": 8,
      "z": 1,
      "name": "Wood_Sallow_Trunk_Full",
      "support": 15,
      "rotation": 2
    },
    {
      "x": -2,
      "y": 9,
      "z": 1,
      "name": "Wood_Sallow_Trunk",
      "support": 15,
      "rotation": 2
    },
    {
      "x": -2,
      "y": 10,
      "z": 1,
      "name": "Wood_Sallow_Trunk",
      "support": 15,
      "rotation": 2
    },
    {
      "x": -2,
      "y": 11,
      "z": 1,
      "name": "Wood_Sallow_Trunk",
      "support": 15,
      "rotation": 2
    },
    {
      "x": -2,
      "y": 12,
      "z": 1,
      "name": "Wood_Sallow_Trunk",
      "support": 15,
      "rotation": 2
    },
    {
      "x": -2,
      "y": 13,
      "z": 1,
      "name": "Wood_Sallow_Trunk",
      "support": 15,
      "rotation": 2
    },
    {
      "x": -2,
      "y": 14,
      "z": 1,
      "name": "Wood_Sallow_Trunk_Full",
      "support": 15,
      "rotation": 2
    },
    {
      "x": -2,
      "y": 23,
      "z": 1,
      "name": "Plant_Moss_Wall_Green_Dark",
      "support": 15,
      "rotation": 3
    },
    {
      "x": -2,
      "y": 26,
      "z": 1,
      "name": "Wood_Sallow_Trunk_Half",
      "rotation": 7
    },
    {
      "x": -2,
      "y": 27,
      "z": 1,
      "name": "Wood_Sallow_Trunk",
      "support": 15
    },
    {
      "x": -2,
      "y": 28,
      "z": 1,
      "name": "Wood_Sallow_Trunk_Half",
      "rotation": 5
    },
    {
      "x": -2,
      "y": 29,
      "z": 1,
      "name": "Wood_Goldenwood_Planks_Half",
      "rotation": 8
    },
    {
      "x": -2,
      "y": 35,
      "z": 1,
      "name": "Wood_Tropicalwood_Roof_Flat",
      "rotation": 1
    },
    {
      "x": -2,
      "y": 47,
      "z": 1,
      "name": "Plant_Vine_Liana",
      "support": 15,
      "rotation": 3
    },
    {
      "x": -2,
      "y": 48,
      "z": 1,
      "name": "Plant_Vine_Liana",
      "support": 15,
      "rotation": 3
    },
    {
      "x": -2,
      "y": 49,
      "z": 1,
      "name": "Plant_Vine_Liana",
      "support": 15,
      "rotation": 3
    },
    {
      "x": -2,
      "y": 50,
      "z": 1,
      "name": "Plant_Vine_Liana",
      "support": 15,
      "rotation": 3
    },
    {
      "x": -2,
      "y": 51,
      "z": 1,
      "name": "Plant_Vine_Liana",
      "support": 15,
      "rotation": 3
    },
    {
      "x": -2,
      "y": 52,
      "z": 1,
      "name": "Plant_Vine_Liana",
      "support": 15,
      "rotation": 3
    },
    {
      "x": -2,
      "y": 53,
      "z": 1,
      "name": "Plant_Vine_Liana",
      "support": 15,
      "rotation": 3
    },
    {
      "x": -2,
      "y": 54,
      "z": 1,
      "name": "Plant_Vine_Liana",
      "support": 15,
      "rotation": 3
    },
    {
      "x": -2,
      "y": 55,
      "z": 1,
      "name": "Plant_Vine_Liana",
      "support": 15,
      "rotation": 3
    },
    {
      "x": -2,
      "y": 56,
      "z": 1,
      "name": "Wood_Sallow_Branch_Long",
      "support": 15,
      "rotation": 7
    },
    {
      "x": -2,
      "y": 64,
      "z": 1,
      "name": "Plant_Leaves_Beech",
      "support": 15,
      "rotation": 2
    },
    {
      "x": -2,
      "y": 65,
      "z": 1,
      "name": "Plant_Leaves_Beech",
      "support": 15,
      "rotation": 2
    },
    {
      "x": -2,
      "y": 69,
      "z": 1,
      "name": "Plant_Leaves_Beech",
      "support": 15,
      "rotation": 2
    },
    {
      "x": -2,
      "y": 70,
      "z": 1,
      "name": "Plant_Leaves_Beech",
      "support": 15,
      "rotation": 2
    },
    {
      "x": -2,
      "y": 8,
      "z": 2,
      "name": "Wood_Sallow_Trunk_Full",
      "support": 15,
      "rotation": 2
    },
    {
      "x": -2,
      "y": 9,
      "z": 2,
      "name": "Wood_Sallow_Trunk",
      "support": 15,
      "rotation": 2
    },
    {
      "x": -2,
      "y": 10,
      "z": 2,
      "name": "Wood_Sallow_Trunk",
      "support": 15,
      "rotation": 2
    },
    {
      "x": -2,
      "y": 11,
      "z": 2,
      "name": "Wood_Sallow_Trunk",
      "support": 15,
      "rotation": 2
    },
    {
      "x": -2,
      "y": 12,
      "z": 2,
      "name": "Wood_Sallow_Trunk",
      "support": 15,
      "rotation": 2
    },
    {
      "x": -2,
      "y": 13,
      "z": 2,
      "name": "Wood_Sallow_Trunk",
      "support": 15,
      "rotation": 2
    },
    {
      "x": -2,
      "y": 14,
      "z": 2,
      "name": "Wood_Sallow_Trunk_Full",
      "support": 15,
      "rotation": 2
    },
    {
      "x": -2,
      "y": 29,
      "z": 2,
      "name": "Wood_Goldenwood_Planks_Half",
      "rotation": 8
    },
    {
      "x": -2,
      "y": 35,
      "z": 2,
