{
  "version": 8,
  "blockIdVersion": 11,
  "anchorX": 0,
  "anchorY": 0,
  "anchorZ": 0,
  "blocks": [
    {
      "x": -20,
      "y": 21,
      "z": 0,
      "name": "Plant_Moss_Wall_Green_Dark",
      "support": 15,
      "rotation": 3
    },
    {
      "x": -20,
      "y": 16,
      "z": 2,
      "name": "Plant_Moss_Wall_Green_Dark",
      "support": 15,
      "rotation": 3
    },
    {
      "x": -20,
      "y": 17,
      "z": 2,
      "name": "Plant_Moss_Wall_Green_Dark",
      "support": 15,
      "rotation": 3
    },
    {
      "x": -20,
      "y": 21,
      "z": 3,
      "name": "Plant_Moss_Wall_Green_Dark",
      "support": 15,
      "rotation": 3
    },
    {
      "x": -19,
      "y": 17,
      "z": -2,
      "name": "Rock_Shale_Brick_Smooth",
      "rotation": 1
    },
    {
      "x": -19,
      "y": 21,
      "z": -2,
      "name": "Rock_Shale_Brick_Smooth",
      "rotation": 1
    },
    {
      "x": -19,
      "y": 17,
      "z": -1,
      "name": "Rock_Shale_Brick_Smooth",
      "rotation": 1
    },
    {
      "x": -19,
      "y": 18,
      "z": -1,
      "name": "Plant_Moss_Rug_Green_Dark",
      "support": 15
    },
    {
      "x": -19,
      "y": 21,
      "z": -1,
      "name": "Rock_Shale_Brick_Smooth",
      "rotation": 1
    },
    {
      "x": -19,
      "y": 17,
      "z": 0,
      "name": "Rock_Shale_Brick_Smooth",
      "rotation": 1
    },
    {
      "x": -19,
      "y": 21,
      "z": 0,
      "name": "Rock_Shale_Brick_Smooth",
      "rotation": 1
    },
    {
      "x": -19,
      "y": 22,
      "z": 0,
      "name": "Plant_Moss_Rug_Green_Dark",
      "support": 15
    },
    {
      "x": -19,
      "y": 17,
      "z": 1,
      "name": "Rock_Shale_Brick_Smooth",
      "rotation": 1
    },
    {
      "x": -19,
      "y": 18,
      "z": 1,
      "name": "Plant_Moss_Rug_Green_Dark",
      "support": 15
    },
    {
      "x": -19,
      "y": 21,
      "z": 1,
      "name": "Rock_Shale_Brick_Smooth",
      "rotation": 1
    },
    {
      "x": -19,
      "y": 17,
      "z": 2,
      "name": "Rock_Shale_Brick_Smooth",
      "rotation": 1
    },
    {
      "x": -19,
      "y": 18,
      "z": 2,
      "name": "Plant_Moss_Rug_Green_Dark",
      "support": 15
    },
    {
      "x": -19,
      "y": 21,
      "z": 2,
      "name": "Rock_Shale_Brick_Smooth",
      "rotation": 1
    },
    {
      "x": -19,
      "y": 17,
      "z": 3,
      "name": "Rock_Shale_Brick_Smooth",
      "rotation": 1
    },
    {
      "x": -19,
      "y": 21,
      "z": 3,
      "name": "Rock_Shale_Brick_Smooth",
      "rotation": 1
    },
    {
      "x": -19,
      "y": 22,
      "z": 3,
      "name": "Plant_Moss_Rug_Green_Dark",
      "support": 15
    },
    {
      "x": -18,
      "y": 17,
      "z": -3,
      "name": "Rock_Shale_Brick_Smooth",
      "rotation": 1
    },
    {
      "x": -18,
      "y": 18,
      "z": -3,
      "name": "Plant_Moss_Rug_Green_Dark",
      "support": 15
    },
    {
      "x": -18,
      "y": 21,
      "z": -3,
      "name": "Rock_Shale_Brick_Smooth",
      "rotation": 1
    },
    {
      "x": -18,
      "y": 17,
      "z": -2,
      "name": "Rock_Shale_Cobble",
      "rotation": 7
    },
    {
      "x": -18,
      "y": 18,
      "z": -2,
      "name": "Rock_Shale_Cobble",
      "rotation": 7
    },
    {
      "x": -18,
      "y": 19,
      "z": -2,
      "name": "Build_Lightsource_Cyan",
      "rotation": 7
    },
    {
      "x": -18,
      "y": 20,
      "z": -2,
      "name": "Rock_Shale_Cobble",
      "rotation": 7
    },
    {
      "x": -18,
      "y": 21,
      "z": -2,
      "name": "Rock_Shale_Cobble",
      "rotation": 7
    },
    {
      "x": -18,
      "y": 16,
      "z": -1,
      "name": "Rock_Shale_Cobble_Half",
      "rotation": 7
    },
    {
      "x": -18,
      "y": 17,
      "z": -1,
      "name": "Rock_Shale_Cobble",
      "rotation": 7
    },
    {
      "x": -18,
      "y": 18,
      "z": -1,
      "name": "Rock_Shale_Cobble",
      "rotation": 7
    },
    {
      "x": -18,
      "y": 19,
      "z": -1,
      "name": "Build_Lightsource_Cyan",
      "rotation": 17
    },
    {
      "x": -18,
      "y": 20,
      "z": -1,
      "name": "Rock_Shale_Cobble",
      "rotation": 7
    },
    {
      "x": -18,
      "y": 21,
      "z": -1,
      "name": "Rock_Shale_Cobble",
      "rotation": 7
    },
    {
      "x": -18,
      "y": 22,
      "z": -1,
      "name": "Rock_Shale_Cobble_Half",
      "rotation": 7
    },
    {
      "x": -18,
      "y": 17,
      "z": 0,
      "name": "Rock_Shale_Cobble",
      "rotation": 7
    },
    {
      "x": -18,
      "y": 18,
      "z": 0,
      "name": "Rock_Shale_Cobble",
      "rotation": 7
    },
    {
      "x": -18,
      "y": 19,
      "z": 0,
      "name": "Build_Lightsource_Cyan",
      "rotation": 17
    },
    {
      "x": -18,
      "y": 20,
      "z": 0,
      "name": "Rock_Shale_Cobble",
      "rotation": 7
    },
    {
      "x": -18,
      "y": 21,
      "z": 0,
      "name": "Rock_Shale_Cobble",
      "rotation": 7
    },
    {
      "x": -18,
      "y": 22,
      "z": 0,
      "name": "Plant_Moss_Rug_Green_Dark",
      "support": 15
    },
    {
      "x": -18,
      "y": 17,
      "z": 1,
      "name": "Rock_Shale_Cobble",
      "rotation": 7
    },
    {
      "x": -18,
      "y": 18,
      "z": 1,
      "name": "Rock_Shale_Cobble",
      "rotation": 7
    },
    {
      "x": -18,
      "y": 19,
      "z": 1,
      "name": "Build_Lightsource_Cyan",
      "rotation": 17
    },
    {
      "x": -18,
      "y": 20,
      "z": 1,
      "name": "Rock_Shale_Cobble",
      "rotation": 7
    },
    {
      "x": -18,
      "y": 21,
      "z": 1,
      "name": "Rock_Shale_Cobble",
      "rotation": 7
    },
    {
      "x": -18,
      "y": 22,
      "z": 1,
      "name": "Plant_Moss_Rug_Green_Dark",
      "support": 15
    },
    {
      "x": -18,
      "y": 16,
      "z": 2,
      "name": "Rock_Shale_Cobble_Half",
      "rotation": 7
    },
    {
      "x": -18,
      "y": 17,
      "z": 2,
      "name": "Rock_Shale_Cobble",
      "rotation": 7
    },
    {
      "x": -18,
      "y": 18,
      "z": 2,
      "name": "Rock_Shale_Cobble",
      "rotation": 7
    },
    {
      "x": -18,
      "y": 19,
      "z": 2,
      "name": "Build_Lightsource_Cyan",
      "rotation": 7
    },
    {
      "x": -18,
      "y": 20,
      "z": 2,
      "name": "Rock_Shale_Cobble",
      "rotation": 7
    },
    {
      "x": -18,
      "y": 21,
      "z": 2,
      "name": "Rock_Shale_Cobble",
      "rotation": 7
    },
    {
      "x": -18,
      "y": 22,
      "z": 2,
      "name": "Rock_Shale_Cobble_Half",
      "rotation": 7
    },
    {
      "x": -18,
      "y": 17,
      "z": 3,
      "name": "Rock_Shale_Cobble",
      "rotation": 7
    },
    {
      "x": -18,
      "y": 18,
      "z": 3,
      "name": "Rock_Shale_Cobble",
      "rotation": 7
    },
    {
      "x": -18,
      "y": 19,
      "z": 3,
      "name": "Build_Lightsource_Cyan",
      "rotation": 7
    },
    {
      "x": -18,
      "y": 20,
      "z": 3,
      "name": "Rock_Shale_Cobble",
      "rotation": 7
    },
    {
      "x": -18,
      "y": 21,
      "z": 3,
      "name": "Rock_Shale_Cobble",
      "rotation": 7
    },
    {
      "x": -18,
      "y": 17,
      "z": 4,
      "name": "Rock_Shale_Brick_Smooth",
      "rotation": 1
    },
    {
      "x": -18,
      "y": 21,
      "z": 4,
      "name": "Rock_Shale_Brick_Smooth",
      "rotation": 1
    },
    {
      "x": -17,
      "y": 17,
      "z": -4,
      "name": "Rock_Shale_Brick_Smooth",
      "rotation": 1
    },
    {
      "x": -17,
      "y": 18,
      "z": -4,
      "name": "Plant_Moss_Rug_Green_Dark",
      "support": 15
    },
    {
      "x": -17,
      "y": 21,
      "z": -4,
      "name": "Rock_Shale_Brick_Smooth",
      "rotation": 1
    },
    {
      "x": -17,
      "y": 17,
      "z": -3,
      "name": "Rock_Shale_Cobble",
      "rotation": 7
    },
    {
      "x": -17,
      "y": 18,
      "z": -3,
      "name": "Rock_Shale_Cobble",
      "rotation": 7
    },
    {
      "x": -17,
      "y": 19,
      "z": -3,
      "name": "Build_Lightsource_Cyan",
      "rotation": 17
    },
    {
      "x": -17,
      "y": 20,
      "z": -3,
      "name": "Rock_Shale_Cobble",
      "rotation": 7
    },
    {
      "x": -17,
      "y": 21,
      "z": -3,
      "name": "Rock_Shale_Cobble",
      "rotation": 1
    },
    {
      "x": -17,
      "y": 16,
      "z": -2,
      "name": "Rock_Shale_Cobble",
      "rotation": 17
    },
    {
      "x": -17,
      "y": 17,
      "z": -2,
      "name": "Rock_Shale_Cobble",
      "rotation": 6
    },
    {
      "x": -17,
      "y": 18,
      "z": -2,
      "name": "Rock_Shale_Cobble",
      "rotation": 6
    },
    {
      "x": -17,
      "y": 19,
      "z": -2,
      "name": "Rock_Shale_Cobble",
      "rotation": 6
    },
    {
      "x": -17,
      "y": 20,
      "z": -2,
      "name": "Rock_Shale_Cobble",
      "rotation": 6
    },
    {
      "x": -17,
      "y": 21,
      "z": -2,
      "name": "Rock_Shale_Cobble",
      "rotation": 7
    },
    {
      "x": -17,
      "y": 13,
      "z": -1,
      "name": "Rock_Shale_Cobble_Half",
      "rotation": 7
    },
    {
      "x": -17,
      "y": 14,
      "z": -1,
      "name": "Rock_Shale_Cobble_Half",
      "rotation": 7
    },
    {
      "x": -17,
      "y": 15,
      "z": -1,
      "name": "Rock_Shale_Cobble_Half",
      "rotation": 7
    },
    {
      "x": -17,
      "y": 16,
      "z": -1,
      "name": "Rock_Shale_Cobble",
      "rotation": 17
    },
    {
      "x": -17,
      "y": 17,
      "z": -1,
      "name": "Rock_Shale_Cobble",
      "rotation": 6
    },
    {
      "x": -17,
      "y": 18,
      "z": -1,
      "name": "Rock_Shale_Cobble",
      "rotation": 6
    },
    {
      "x": -17,
      "y": 19,
      "z": -1,
      "name": "Rock_Shale_Cobble",
      "rotation": 6
    },
    {
      "x": -17,
      "y": 20,
      "z": -1,
      "name": "Rock_Shale_Cobble",
      "rotation": 6
    },
    {
      "x": -17,
      "y": 21,
      "z": -1,
      "name": "Rock_Shale_Cobble",
      "rotation": 6
    },
    {
      "x": -17,
      "y": 16,
      "z": 0,
      "name": "Rock_Shale_Cobble",
      "rotation": 17
    },
    {
      "x": -17,
      "y": 17,
      "z": 0,
      "name": "Rock_Shale_Cobble",
      "rotation": 6
    },
    {
      "x": -17,
      "y": 18,
      "z": 0,
      "name": "Rock_Shale_Cobble",
      "rotation": 6
    },
    {
      "x": -17,
      "y": 19,
      "z": 0,
      "name": "Rock_Shale_Cobble",
      "rotation": 6
    },
    {
      "x": -17,
      "y": 20,
      "z": 0,
      "name": "Rock_Shale_Cobble",
      "rotation": 6
    },
    {
      "x": -17,
      "y": 21,
      "z": 0,
      "name": "Rock_Shale_Cobble",
      "rotation": 6
    },
    {
      "x": -17,
      "y": 22,
      "z": 0,
      "name": "Rock_Shale_Cobble",
      "rotation": 4
    },
    {
      "x": -17,
      "y": 23,
      "z": 0,
      "name": "Plant_Moss_Wall_Green_Dark",
      "support": 15,
      "rotation": 3
    },
    {
      "x": -17,
      "y": 16,
      "z": 1,
      "name": "Rock_Shale_Cobble",
      "rotation": 17
    },
    {
      "x": -17,
      "y": 17,
      "z": 1,
      "name": "Rock_Shale_Cobble",
      "rotation": 6
    },
    {
      "x": -17,
      "y": 18,
      "z": 1,
      "name": "Rock_Shale_Cobble",
      "rotation": 6
    },
    {
      "x": -17,
      "y": 19,
      "z": 1,
      "name": "Rock_Shale_Cobble",
      "rotation": 6
    },
    {
      "x": -17,
      "y": 20,
      "z": 1,
      "name": "Rock_Shale_Cobble",
      "rotation": 6
    },
    {
      "x": -17,
      "y": 21,
      "z": 1,
      "name": "Rock_Shale_Cobble",
      "rotation": 6
    },
    {
      "x": -17,
      "y": 22,
      "z": 1,
      "name": "Rock_Shale_Cobble",
      "rotation": 4
    },
    {
      "x": -17,
      "y": 23,
      "z": 1,
      "name": "Plant_Moss_Rug_Green_Dark",
      "support": 15
    },
    {
      "x": -17,
      "y": 13,
      "z": 2,
      "name": "Rock_Shale_Cobble_Half",
      "rotation": 7
    },
    {
      "x": -17,
      "y": 14,
      "z": 2,
      "name": "Rock_Shale_Cobble_Half",
      "rotation": 7
    },
    {
      "x": -17,
      "y": 15,
      "z": 2,
      "name": "Rock_Shale_Cobble_Half",
      "rotation": 7
    },
    {
      "x": -17,
      "y": 16,
      "z": 2,
      "name": "Rock_Shale_Cobble",
      "rotation": 17
    },
    {
      "x": -17,
      "y": 17,
      "z": 2,
      "name": "Rock_Shale_Cobble",
      "rotation": 6
    },
    {
      "x": -17,
      "y": 18,
      "z": 2,
      "name": "Rock_Shale_Cobble",
      "rotation": 6
    },
    {
      "x": -17,
      "y": 19,
      "z": 2,
      "name": "Rock_Shale_Cobble",
      "rotation": 6
    },
    {
      "x": -17,
      "y": 20,
      "z": 2,
      "name": "Rock_Shale_Cobble",
      "rotation": 6
    },
    {
      "x": -17,
      "y": 21,
      "z": 2,
      "name": "Rock_Shale_Cobble",
      "rotation": 6
    },
    {
      "x": -17,
      "y": 22,
      "z": 2,
      "name": "Rock_Shale_Cobble",
      "rotation": 4
    },
    {
      "x": -17,
      "y": 23,
      "z": 2,
      "name": "Rock_Shale_Cobble_Half",
      "rotation": 7
    },
    {
      "x": -17,
      "y": 16,
      "z": 3,
      "name": "Rock_Shale_Cobble",
      "rotation": 17
    },
    {
      "x": -17,
      "y": 17,
      "z": 3,
      "name": "Rock_Shale_Cobble",
      "rotation": 6
    },
    {
      "x": -17,
      "y": 18,
      "z": 3,
      "name": "Rock_Shale_Cobble",
      "rotation": 6
    },
    {
      "x": -17,
      "y": 19,
      "z": 3,
      "name": "Rock_Shale_Cobble",
      "rotation": 6
    },
    {
      "x": -17,
      "y": 20,
      "z": 3,
      "name": "Rock_Shale_Cobble",
      "rotation": 6
    },
    {
      "x": -17,
      "y": 21,
      "z": 3,
      "name": "Rock_Shale_Cobble",
      "rotation": 6
    },
    {
      "x": -17,
      "y": 22,
      "z": 3,
      "name": "Rock_Shale_Cobble",
      "rotation": 4
    },
    {
      "x": -17,
      "y": 17,
      "z": 4,
      "name": "Rock_Shale_Cobble",
      "rotation": 7
    },
    {
      "x": -17,
      "y": 18,
      "z": 4,
      "name": "Rock_Shale_Cobble",
      "rotation": 7
    },
    {
      "x": -17,
      "y": 19,
      "z": 4,
      "name": "Build_Lightsource_Cyan",
      "rotation": 17
    },
    {
      "x": -17,
      "y": 20,
      "z": 4,
      "name": "Rock_Shale_Cobble",
      "rotation": 7
    },
    {
      "x": -17,
      "y": 21,
      "z": 4,
      "name": "Rock_Shale_Cobble",
      "rotation": 7
    },
    {
      "x": -17,
      "y": 22,
      "z": 4,
      "name": "Plant_Moss_Rug_Green_Dark",
      "support": 15
    },
    {
      "x": -17,
      "y": 17,
      "z": 5,
      "name": "Rock_Shale_Brick_Smooth",
      "rotation": 1
    },
    {
      "x": -17,
      "y": 21,
      "z": 5,
      "name": "Rock_Shale_Brick_Smooth",
      "rotation": 1
    },
    {
      "x": -16,
      "y": 17,
      "z": -4,
      "name": "Rock_Shale_Brick_Smooth",
      "rotation": 1
    },
    {
      "x": -16,
      "y": 21,
      "z": -4,
      "name": "Rock_Shale_Brick_Smooth",
      "rotation": 1
    },
    {
      "x": -16,
      "y": 17,
      "z": -3,
      "name": "Rock_Shale_Cobble",
      "rotation": 7
    },
    {
      "x": -16,
      "y": 18,
      "z": -3,
      "name": "Rock_Shale_Cobble",
      "rotation": 7
    },
    {
      "x": -16,
      "y": 19,
      "z": -3,
      "name": "Build_Lightsource_Cyan",
      "rotation": 17
    },
    {
      "x": -16,
      "y": 20,
      "z": -3,
      "name": "Rock_Shale_Cobble",
      "rotation": 7
    },
    {
      "x": -16,
      "y": 21,
      "z": -3,
      "name": "Rock_Shale_Cobble",
      "rotation": 1
    },
    {
      "x": -16,
      "y": 22,
      "z": -3,
      "name": "Plant_Moss_Rug_Green_Dark",
      "support": 15
    },
    {
      "x": -16,
      "y": 13,
      "z": -2,
      "name": "Rock_Shale_Cobble",
      "rotation": 17
    },
    {
      "x": -16,
      "y": 14,
      "z": -2,
      "name": "Rock_Shale_Cobble",
      "rotation": 17
    },
    {
      "x": -16,
      "y": 15,
      "z": -2,
      "name": "Rock_Shale_Cobble",
      "rotation": 17
    },
    {
      "x": -16,
      "y": 16,
      "z": -2,
      "name": "Rock_Shale_Cobble",
      "rotation": 17
    },
    {
      "x": -16,
      "y": 17,
      "z": -2,
      "name": "Rock_Shale_Cobble",
      "rotation": 6
    },
    {
      "x": -16,
      "y": 18,
      "z": -2,
      "name": "Rock_Shale_Cobble",
      "rotation": 6
    },
    {
      "x": -16,
      "y": 19,
      "z": -2,
      "name": "Rock_Shale_Cobble",
      "rotation": 6
    },
    {
      "x": -16,
      "y": 20,
      "z": -2,
      "name": "Rock_Shale_Cobble",
      "rotation": 6
    },
    {
      "x": -16,
      "y": 21,
      "z": -2,
      "name": "Rock_Shale_Cobble",
      "rotation": 7
    },
    {
      "x": -16,
      "y": 11,
      "z": -1,
      "name": "Rock_Shale_Cobble_Half",
      "rotation": 7
    },
    {
      "x": -16,
      "y": 12,
      "z": -1,
      "name": "Rock_Shale_Cobble_Half",
      "rotation": 7
    },
    {
      "x": -16,
      "y": 13,
      "z": -1,
      "name": "Rock_Shale_Cobble",
      "rotation": 17
    },
    {
      "x": -16,
      "y": 14,
      "z": -1,
      "name": "Rock_Shale_Cobble",
      "rotation": 17
    },
    {
      "x": -16,
      "y": 15,
      "z": -1,
      "name": "Rock_Shale_Cobble",
      "rotation": 17
    },
    {
      "x": -16,
      "y": 16,
      "z": -1,
      "name": "Rock_Shale_Cobble",
      "rotation": 17
    },
    {
      "x": -16,
      "y": 17,
      "z": -1,
      "name": "Rock_Shale_Cobble",
      "rotation": 6
    },
    {
      "x": -16,
      "y": 18,
      "z": -1,
      "name": "Rock_Shale_Cobble",
      "rotation": 6
    },
    {
      "x": -16,
      "y": 19,
      "z": -1,
      "name": "Rock_Shale_Cobble",
      "rotation": 6
    },
    {
      "x": -16,
      "y": 20,
      "z": -1,
      "name": "Rock_Shale_Cobble",
      "rotation": 6
    },
    {
      "x": -16,
      "y": 21,
      "z": -1,
      "name": "Rock_Shale_Cobble",
      "rotation": 6
    },
    {
      "x": -16,
      "y": 13,
      "z": 0,
      "name": "Rock_Shale_Cobble",
      "rotation": 17
    },
    {
      "x": -16,
      "y": 14,
      "z": 0,
      "name": "Rock_Shale_Cobble",
      "rotation": 17
    },
    {
      "x": -16,
      "y": 15,
      "z": 0,
      "name": "Rock_Shale_Cobble",
      "rotation": 17
    },
    {
      "x": -16,
      "y": 16,
      "z": 0,
      "name": "Rock_Shale_Cobble",
      "rotation": 17
    },
    {
      "x": -16,
      "y": 17,
      "z": 0,
      "name": "Rock_Shale_Cobble",
      "rotation": 6
    },
    {
      "x": -16,
      "y": 18,
      "z": 0,
      "name": "Rock_Shale_Cobble",
      "rotation": 6
    },
    {
      "x": -16,
      "y": 19,
      "z": 0,
      "name": "Rock_Shale_Cobble",
      "rotation": 6
    },
    {
      "x": -16,
      "y": 20,
      "z": 0,
      "name": "Rock_Shale_Cobble",
      "rotation": 6
    },
    {
      "x": -16,
      "y": 21,
      "z": 0,
      "name": "Rock_Shale_Cobble",
      "rotation": 6
    },
    {
      "x": -16,
      "y": 22,
      "z": 0,
      "name": "Rock_Shale_Cobble",
      "rotation": 4
    },
    {
      "x": -16,
      "y": 23,
      "z": 0,
      "name": "Rock_Shale_Cobble",
      "rotation": 4
    },
    {
      "x": -16,
      "y": 24,
      "z": 0,
      "name": "Plant_Moss_Rug_Green_Dark",
      "support": 15
    },
    {
      "x": -16,
      "y": 13,
      "z": 1,
      "name": "Rock_Shale_Cobble",
      "rotation": 17
    },
    {
      "x": -16,
      "y": 14,
      "z": 1,
      "name": "Rock_Shale_Cobble",
      "rotation": 17
    },
    {
      "x": -16,
      "y": 15,
      "z": 1,
      "name": "Rock_Shale_Cobble",
      "rotation": 17
    },
    {
      "x": -16,
      "y": 16,
      "z": 1,
      "name": "Rock_Shale_Cobble",
      "rotation": 17
    },
    {
      "x": -16,
      "y": 17,
      "z": 1,
      "name": "Rock_Shale_Cobble",
      "rotation": 6
    },
    {
      "x": -16,
      "y": 18,
      "z": 1,
      "name": "Rock_Shale_Cobble",
      "rotation": 6
    },
    {
      "x": -16,
      "y": 19,
      "z": 1,
      "name": "Rock_Shale_Cobble",
      "rotation": 6
    },
    {
      "x": -16,
      "y": 20,
      "z": 1,
      "name": "Rock_Shale_Cobble",
      "rotation": 6
    },
    {
      "x": -16,
      "y": 21,
      "z": 1,
      "name": "Rock_Shale_Cobble",
      "rotation": 6
    },
    {
      "x": -16,
      "y": 22,
      "z": 1,
      "name": "Rock_Shale_Cobble",
      "rotation": 4
    },
    {
      "x": -16,
      "y": 23,
      "z": 1,
      "name": "Rock_Shale_Cobble",
      "rotation": 4
    },
    {
      "x": -16,
      "y": 11,
      "z": 2,
      "name": "Rock_Shale_Cobble_Half",
      "rotation": 7
    },
    {
      "x": -16,
      "y": 12,
      "z": 2,
      "name": "Rock_Shale_Cobble_Half",
      "rotation": 7
    },
    {
      "x": -16,
      "y": 13,
      "z": 2,
      "name": "Rock_Shale_Cobble",
      "rotation": 17
    },
    {
      "x": -16,
      "y": 14,
      "z": 2,
      "name": "Rock_Shale_Cobble",
      "rotation": 17
    },
    {
      "x": -16,
      "y": 15,
      "z": 2,
      "name": "Rock_Shale_Cobble",
      "rotation": 17
    },
    {
      "x": -16,
      "y": 16,
      "z": 2,
      "name": "Rock_Shale_Cobble",
      "rotation": 17
    },
    {
      "x": -16,
      "y": 17,
      "z": 2,
      "name": "Rock_Shale_Cobble",
      "rotation": 6
    },
    {
      "x": -16,
      "y": 18,
      "z": 2,
      "name": "Rock_Shale_Cobble",
      "rotation": 6
    },
    {
      "x": -16,
      "y": 19,
      "z": 2,
      "name": "Rock_Shale_Cobble",
      "rotation": 6
    },
    {
      "x": -16,
      "y": 20,
      "z": 2,
      "name": "Rock_Shale_Cobble",
      "rotation": 6
    },
    {
      "x": -16,
      "y": 21,
      "z": 2,
      "name": "Rock_Shale_Cobble",
      "rotation": 6
    },
    {
      "x": -16,
      "y": 22,
      "z": 2,
      "name": "Rock_Shale_Cobble",
      "rotation": 4
    },
    {
      "x": -16,
      "y": 23,
      "z": 2,
      "name": "Rock_Shale_Cobble",
      "rotation": 4
    },
    {
      "x": -16,
      "y": 24,
      "z": 2,
      "name": "Plant_Moss_Rug_Green_Dark",
      "support": 15
    },
    {
      "x": -16,
      "y": 13,
      "z": 3,
      "name": "Rock_Shale_Cobble",
      "rotation": 17
    },
    {
      "x": -16,
      "y": 14,
      "z": 3,
      "name": "Rock_Shale_Cobble",
      "rotation": 17
    },
    {
      "x": -16,
      "y": 15,
      "z": 3,
      "name": "Rock_Shale_Cobble",
      "rotation": 17
    },
    {
      "x": -16,
      "y": 16,
      "z": 3,
      "name": "Rock_Shale_Cobble",
      "rotation": 17
    },
    {
      "x": -16,
      "y": 17,
      "z": 3,
      "name": "Rock_Shale_Cobble",
      "rotation": 6
    },
    {
      "x": -16,
      "y": 18,
      "z": 3,
      "name": "Rock_Shale_Cobble",
      "rotation": 6
    },
    {
      "x": -16,
      "y": 19,
      "z": 3,
      "name": "Rock_Shale_Cobble",
      "rotation": 6
    },
    {
      "x": -16,
      "y": 20,
      "z": 3,
      "name": "Rock_Shale_Cobble",
      "rotation": 6
    },
    {
      "x": -16,
      "y": 21,
      "z": 3,
      "name": "Rock_Shale_Cobble",
      "rotation": 6
    },
    {
      "x": -16,
      "y": 22,
      "z": 3,
      "name": "Rock_Shale_Cobble",
      "rotation": 4
    },
    {
      "x": -16,
      "y": 23,
      "z": 3,
      "name": "Rock_Shale_Cobble",
      "rotation": 4
    },
    {
      "x": -16,
      "y": 17,
      "z": 4,
      "name": "Rock_Shale_Cobble",
      "rotation": 7
    },
    {
      "x": -16,
      "y": 18,
      "z": 4,
      "name": "Rock_Shale_Cobble",
      "rotation": 7
    },
    {
      "x": -16,
      "y": 19,
      "z": 4,
      "name": "Build_Lightsource_Cyan",
      "rotation": 7
    },
    {
      "x": -16,
      "y": 20,
      "z": 4,
      "name": "Rock_Shale_Cobble",
      "rotation": 7
    },
    {
      "x": -16,
      "y": 21,
      "z": 4,
      "name": "Rock_Shale_Cobble",
      "rotation": 7
    },
    {
      "x": -16,
      "y": 22,
      "z": 4,
      "name": "Plant_Moss_Rug_Green_Dark",
      "support": 15
    },
    {
      "x": -16,
      "y": 17,
      "z": 5,
      "name": "Rock_Shale_Brick_Smooth",
      "rotation": 1
    },
    {
      "x": -16,
      "y": 18,
      "z": 5,
      "name": "Plant_Moss_Rug_Green_Dark",
      "support": 15
    },
    {
      "x": -16,
      "y": 21,
      "z": 5,
      "name": "Rock_Shale_Brick_Smooth",
      "rotation": 1
    },
    {
      "x": -16,
      "y": 22,
      "z": 5,
      "name": "Plant_Moss_Rug_Green_Dark",
      "support": 15
    },
    {
      "x": -16,
      "y": 21,
      "z": 6,
      "name": "Plant_Moss_Wall_Green_Dark",
      "support": 15
    },
    {
      "x": -15,
      "y": 17,
      "z": -4,
      "name": "Rock_Shale_Brick_Smooth",
      "rotation": 1
    },
    {
      "x": -15,
      "y": 21,
      "z": -4,
      "name": "Rock_Shale_Brick_Smooth",
      "rotation": 1
    },
    {
      "x": -15,
      "y": 17,
      "z": -3,
      "name": "Rock_Shale_Cobble",
      "rotation": 7
    },
    {
      "x": -15,
      "y": 18,
      "z": -3,
      "name": "Rock_Shale_Cobble",
      "rotation": 7
    },
    {
      "x": -15,
      "y": 19,
      "z": -3,
      "name": "Build_Lightsource_Cyan",
      "rotation": 7
    },
    {
      "x": -15,
      "y": 20,
      "z": -3,
      "name": "Rock_Shale_Cobble",
      "rotation": 7
    },
    {
      "x": -15,
      "y": 21,
      "z": -3,
      "name": "Rock_Shale_Cobble",
      "rotation": 1
    },
    {
      "x": -15,
      "y": 22,
      "z": -3,
      "name": "Plant_Moss_Rug_Green_Dark",
      "support": 15
    },
    {
      "x": -15,
      "y": 11,
      "z": -2,
      "name": "Rock_Shale_Cobble",
      "rotation": 17
    },
    {
      "x": -15,
      "y": 12,
      "z": -2,
      "name": "Rock_Shale_Cobble",
      "rotation": 17
    },
    {
      "x": -15,
      "y": 13,
      "z": -2,
      "name": "Rock_Shale_Cobble",
      "rotation": 17
    },
    {
      "x": -15,
      "y": 14,
      "z": -2,
      "name": "Rock_Shale_Cobble",
      "rotation": 17
    },
    {
      "x": -15,
      "y": 15,
      "z": -2,
      "name": "Rock_Shale_Cobble",
      "rotation": 17
    },
    {
      "x": -15,
      "y": 16,
      "z": -2,
      "name": "Deko_Block_Test",
      "rotation": 6
    },
    {
      "x": -15,
      "y": 17,
      "z": -2,
      "name": "Rock_Shale_Cobble",
      "rotation": 6
    },
    {
      "x": -15,
      "y": 18,
      "z": -2,
      "name": "Rock_Shale_Cobble",
      "rotation": 6
    },
    {
      "x": -15,
      "y": 19,
      "z": -2,
      "name": "Rock_Shale_Cobble",
      "rotation": 6
    },
    {
      "x": -15,
      "y": 20,
      "z": -2,
      "name": "Rock_Shale_Cobble",
      "rotation": 6
    },
    {
      "x": -15,
      "y": 21,
      "z": -2,
      "name": "Rock_Shale_Cobble",
      "rotation": 7
    },
    {
      "x": -15,
      "y": 9,
      "z": -1,
      "name": "Rock_Shale_Cobble_Half",
      "rotation": 7
    },
    {
      "x": -15,
      "y": 10,
      "z": -1,
      "name": "Rock_Shale_Cobble_Half",
      "rotation": 7
    },
    {
      "x": -15,
      "y": 11,
      "z": -1,
      "name": "Rock_Shale_Cobble",
      "rotation": 17
    },
    {
      "x": -15,
      "y": 12,
      "z": -1,
      "name": "Rock_Shale_Cobble",
      "rotation": 17
    },
    {
      "x": -15,
      "y": 13,
      "z": -1,
      "name": "Rock_Shale_Cobble",
      "rotation": 17
    },
    {
      "x": -15,
      "y": 14,
      "z": -1,
      "name": "Rock_Shale_Cobble",
      "rotation": 17
    },
    {
      "x": -15,
      "y": 15,
      "z": -1,
      "name": "Rock_Shale_Cobble",
      "rotation": 17
    },
    {
      "x": -15,
      "y": 16,
      "z": -1,
      "name": "Rock_Shale_Cobble",
      "rotation": 17
    },
    {
      "x": -15,
      "y": 17,
      "z": -1,
      "name": "Rock_Shale_Cobble",
      "rotation": 6
    },
    {
      "x": -15,
      "y": 18,
      "z": -1,
      "name": "Rock_Shale_Cobble",
      "rotation": 6
    },
    {
      "x": -15,
      "y": 19,
      "z": -1,
      "name": "Rock_Shale_Cobble",
      "rotation": 6
    },
    {
      "x": -15,
      "y": 20,
      "z": -1,
      "name": "Rock_Shale_Cobble",
      "rotation": 6
    },
    {
      "x": -15,
      "y": 21,
      "z": -1,
      "name": "Rock_Shale_Cobble",
      "rotation": 6
    },
    {
      "x": -15,
      "y": 11,
      "z": 0,
      "name": "Rock_Shale_Cobble",
      "rotation": 17
    },
    {
      "x": -15,
      "y": 12,
      "z": 0,
      "name": "Rock_Shale_Cobble",
      "rotation": 17
    },
    {
      "x": -15,
      "y": 13,
      "z": 0,
      "name": "Rock_Shale_Cobble",
      "rotation": 17
    },
    {
      "x": -15,
      "y": 14,
      "z": 0,
      "name": "Rock_Shale_Cobble",
      "rotation": 17
    },
    {
      "x": -15,
      "y": 15,
      "z": 0,
      "name": "Rock_Shale_Cobble",
      "rotation": 17
    },
    {
      "x": -15,
      "y": 16,
      "z": 0,
      "name": "Rock_Shale_Cobble",
      "rotation": 17
    },
    {
      "x": -15,
      "y": 17,
      "z": 0,
      "name": "Rock_Shale_Cobble",
      "rotation": 6
    },
    {
      "x": -15,
      "y": 18,
      "z": 0,
      "name": "Rock_Shale_Cobble",
      "rotation": 6
    },
    {
      "x": -15,
      "y": 19,
      "z": 0,
      "name": "Rock_Shale_Cobble",
      "rotation": 6
    },
    {
      "x": -15,
      "y": 20,
      "z": 0,
      "name": "Rock_Shale_Cobble",
      "rotation": 6
    },
    {
      "x": -15,
      "y": 11,
      "z": 1,
      "name": "Rock_Shale_Cobble",
      "rotation": 17
    },
    {
      "x": -15,
      "y": 12,
      "z": 1,
      "name": "Rock_Shale_Cobble",
      "rotation": 17
    },
    {
      "x": -15,
      "y": 13,
      "z": 1,
      "name": "Rock_Shale_Cobble",
      "rotation": 17
    },
    {
      "x": -15,
      "y": 14,
      "z": 1,
      "name": "Rock_Shale_Cobble",
      "rotation": 17
    },
    {
      "x": -15,
      "y": 15,
      "z": 1,
      "name": "Rock_Shale_Cobble",
      "rotation": 17
    },
    {
      "x": -15,
      "y": 16,
      "z": 1,
      "name": "Rock_Shale_Cobble",
      "rotation": 17
    },
    {
      "x": -15,
      "y": 17,
      "z": 1,
      "name": "Rock_Shale_Cobble",
      "rotation": 6
    },
    {
      "x": -15,
      "y": 18,
      "z": 1,
      "name": "Rock_Shale_Cobble",
      "rotation": 6
    },
    {
      "x": -15,
      "y": 19,
      "z": 1,
      "name": "Rock_Shale_Cobble",
      "rotation": 6
    },
    {
      "x": -15,
      "y": 20,
      "z": 1,
      "name": "Rock_Shale_Cobble",
      "rotation": 6
    },
    {
      "x": -15,
      "y": 9,
      "z": 2,
      "name": "Rock_Shale_Cobble_Half",
      "rotation": 7
    },
    {
      "x": -15,
      "y": 10,
      "z": 2,
      "name": "Rock_Shale_Cobble_Half",
      "rotation": 7
    },
    {
      "x": -15,
      "y": 11,
      "z": 2,
      "name": "Rock_Shale_Cobble",
      "rotation": 17
    },
    {
      "x": -15,
      "y": 12,
      "z": 2,
      "name": "Rock_Shale_Cobble",
      "rotation": 17
    },
    {
      "x": -15,
      "y": 13,
      "z": 2,
      "name": "Rock_Shale_Cobble",
      "rotation": 17
    },
    {
      "x": -15,
      "y": 14,
      "z": 2,
      "name": "Rock_Shale_Cobble",
      "rotation": 17
    },
    {
      "x": -15,
      "y": 15,
      "z": 2,
      "name": "Rock_Shale_Cobble",
      "rotation": 17
    },
    {
      "x": -15,
      "y": 16,
      "z": 2,
      "name": "Rock_Shale_Cobble",
      "rotation": 17
    },
    {
      "x": -15,
      "y": 17,
      "z": 2,
      "name": "Rock_Shale_Cobble",
      "rotation": 6
    },
    {
      "x": -15,
      "y": 18,
      "z": 2,
      "name": "Rock_Shale_Cobble",
      "rotation": 6
    },
    {
      "x": -15,
      "y": 19,
      "z": 2,
      "name": "Rock_Shale_Cobble",
      "rotation": 6
    },
    {
      "x": -15,
      "y": 20,
      "z": 2,
      "name": "Rock_Shale_Cobble",
      "rotation": 6
    },
    {
      "x": -15,
      "y": 11,
      "z": 3,
      "name": "Rock_Shale_Cobble",
      "rotation": 17
    },
    {
      "x": -15,
      "y": 12,
      "z": 3,
      "name": "Rock_Shale_Cobble",
      "rotation": 17
    },
    {
      "x": -15,
      "y": 13,
      "z": 3,
      "name": "Rock_Shale_Cobble",
      "rotation": 17
    },
    {
      "x": -15,
      "y": 14,
      "z": 3,
      "name": "Rock_Shale_Cobble",
      "rotation": 17
    },
    {
      "x": -15,
      "y": 15,
      "z": 3,
      "name": "Rock_Shale_Cobble",
      "rotation": 17
    },
    {
      "x": -15,
      "y": 16,
      "z": 3,
      "name": "Deko_Block_Test",
      "rotation": 4
    },
    {
      "x": -15,
      "y": 17,
      "z": 3,
      "name": "Rock_Shale_Cobble",
      "rotation": 6
    },
    {
      "x": -15,
      "y": 18,
      "z": 3,
      "name": "Rock_Shale_Cobble",
      "rotation": 6
    },
    {
      "x": -15,
      "y": 19,
      "z": 3,
      "name": "Rock_Shale_Cobble",
      "rotation": 6
    },
    {
      "x": -15,
      "y": 20,
      "z": 3,
      "name": "Rock_Shale_Cobble",
      "rotation": 6
    },
    {
      "x": -15,
      "y": 21,
      "z": 3,
      "name": "Rock_Shale_Cobble",
      "rotation": 6
    },
    {
      "x": -15,
      "y": 22,
      "z": 3,
      "name": "Deko_Block_Test",
      "rotation": 4
    },
    {
      "x": -15,
      "y": 23,
      "z": 3,
      "name": "Rock_Shale_Cobble",
      "rotation": 4
    },
    {
      "x": -15,
      "y": 17,
      "z": 4,
      "name": "Rock_Shale_Cobble",
      "rotation": 7
    },
    {
      "x": -15,
      "y": 18,
      "z": 4,
      "name": "Rock_Shale_Cobble",
      "rotation": 7
    },
    {
      "x": -15,
      "y": 19,
      "z": 4,
      "name": "Build_Lightsource_Cyan",
      "rotation": 17
    },
    {
      "x": -15,
      "y": 20,
      "z": 4,
      "name": "Rock_Shale_Cobble",
      "rotation": 7
    },
    {
      "x": -15,
      "y": 21,
      "z": 4,
      "name": "Rock_Shale_Cobble",
      "rotation": 7
    },
    {
      "x": -15,
      "y": 17,
      "z": 5,
      "name": "Rock_Shale_Brick_Smooth",
      "rotation": 1
    },
    {
      "x": -15,
      "y": 21,
      "z": 5,
      "name": "Rock_Shale_Brick_Smooth",
      "rotation": 1
    },
    {
      "x": -14,
      "y": 17,
      "z": -5,
      "name": "Plant_Moss_Wall_Green_Dark",
      "support": 15,
      "rotation": 2
    },
    {
      "x": -14,
      "y": 17,
      "z": -4,
      "name": "Rock_Shale_Brick_Smooth",
      "rotation": 1
    },
    {
      "x": -14,
      "y": 18,
      "z": -4,
      "name": "Plant_Moss_Rug_Green_Dark",
      "support": 15
    },
    {
      "x": -14,
      "y": 21,
      "z": -4,
      "name": "Rock_Shale_Brick_Smooth",
      "rotation": 1
    },
    {
      "x": -14,
      "y": 17,
      "z": -3,
      "name": "Rock_Shale_Cobble",
      "rotation": 7
    },
    {
      "x": -14,
      "y": 18,
      "z": -3,
      "name": "Rock_Shale_Cobble",
      "rotation": 7
    },
    {
      "x": -14,
      "y": 19,
      "z": -3,
      "name": "Build_Lightsource_Cyan",
      "rotation": 17
    },
    {
      "x": -14,
      "y": 20,
      "z": -3,
      "name": "Rock_Shale_Cobble",
      "rotation": 7
    },
    {
      "x": -14,
      "y": 21,
      "z": -3,
      "name": "Rock_Shale_Cobble",
      "rotation": 1
    },
    {
      "x": -14,
      "y": 22,
      "z": -3,
      "name": "Plant_Moss_Rug_Green_Dark",
      "support": 15
    },
    {
      "x": -14,
      "y": 9,
      "z": -2,
      "name": "Rock_Shale_Cobble",
      "rotation": 17
    },
    {
      "x": -14,
      "y": 10,
      "z": -2,
      "name": "Rock_Shale_Cobble",
      "rotation": 17
    },
    {
      "x": -14,
      "y": 11,
      "z": -2,
      "name": "Rock_Shale_Cobble",
      "rotation": 17
    },
    {
      "x": -14,
      "y": 12,
      "z": -2,
      "name": "Rock_Shale_Cobble",
      "rotation": 17
    },
    {
      "x": -14,
      "y": 13,
      "z": -2,
      "name": "Rock_Shale_Cobble",
      "rotation": 17
    },
    {
      "x": -14,
      "y": 14,
      "z": -2,
      "name": "Rock_Shale_Cobble",
      "rotation": 17
    },
    {
      "x": -14,
      "y": 15,
      "z": -2,
      "name": "Rock_Shale_Cobble",
      "rotation": 17
    },
    {
      "x": -14,
      "y": 16,
      "z": -2,
      "name": "Rock_Shale_Cobble",
      "rotation": 17
    },
    {
      "x": -14,
      "y": 17,
      "z": -2,
      "name": "Rock_Shale_Cobble",
      "rotation": 6
    },
    {
      "x": -14,
      "y": 18,
      "z": -2,
      "name": "Rock_Shale_Cobble",
      "rotation": 6
    },
    {
      "x": -14,
      "y": 19,
      "z": -2,
      "name": "Build_Lightsource_Cyan",
      "rotation": 17
    },
    {
      "x": -14,
      "y": 20,
      "z": -2,
      "name": "Rock_Shale_Cobble",
      "rotation": 6
    },
    {
      "x": -14,
      "y": 21,
      "z": -2,
      "name": "Rock_Shale_Cobble",
      "rotation": 7
    },
    {
      "x": -14,
      "y": 22,
      "z": -2,
      "name": "Rock_Shale_Cobble",
      "rotation": 4
    },
    {
      "x": -14,
      "y": 23,
      "z": -2,
      "name": "Rock_Shale_Cobble",
      "rotation": 4
    },
    {
      "x": -14,
      "y": 8,
      "z": -1,
      "name": "Rock_Shale_Cobble_Half",
      "rotation": 7
    },
    {
      "x": -14,
      "y": 9,
      "z": -1,
      "name": "Rock_Shale_Cobble",
      "rotation": 17
    },
    {
      "x": -14,
      "y": 10,
      "z": -1,
      "name": "Rock_Shale_Cobble",
      "rotation": 17
    },
    {
      "x": -14,
      "y": 11,
      "z": -1,
      "name": "Rock_Shale_Cobble",
      "rotation": 17
    },
    {
      "x": -14,
      "y": 12,
      "z": -1,
      "name": "Rock_Shale_Cobble",
      "rotation": 17
    },
    {
      "x": -14,
      "y": 13,
      "z": -1,
      "name": "Rock_Shale_Cobble",
      "rotation": 17
    },
    {
      "x": -14,
      "y": 14,
      "z": -1,
      "name": "Rock_Shale_Cobble",
      "rotation": 17
    },
    {
      "x": -14,
      "y": 15,
      "z": -1,
      "name": "Rock_Shale_Cobble",
      "rotation": 17
    },
    {
      "x": -14,
      "y": 16,
      "z": -1,
      "name": "Rock_Shale_Cobble",
      "rotation": 17
    },
    {
      "x": -14,
      "y": 17,
      "z": -1,
      "name": "Rock_Shale_Cobble",
      "rotation": 6
    },
    {
      "x": -14,
      "y": 18,
      "z": -1,
      "name": "Rock_Shale_Cobble",
      "rotation": 6
    },
    {
      "x": -14,
      "y": 19,
      "z": -1,
      "name": "Rock_Shale_Cobble",
      "rotation": 6
    },
    {
      "x": -14,
      "y": 20,
      "z": -1,
      "name": "Rock_Shale_Cobble",
      "rotation": 6
    },
    {
      "x": -14,
      "y": 21,
      "z": -1,
      "name": "Rock_Shale_Cobble",
      "rotation": 6
    },
    {
      "x": -14,
      "y": 22,
      "z": -1,
      "name": "Rock_Shale_Cobble",
      "rotation": 4
    },
    {
      "x": -14,
      "y": 23,
      "z": -1,
      "name": "Rock_Shale_Cobble",
      "rotation": 4
    },
    {
      "x": -14,
      "y": 24,
      "z": -1,
      "name": "Plant_Moss_Rug_Green_Dark",
      "support": 15
    },
    {
      "x": -14,
      "y": 9,
      "z": 0,
      "name": "Rock_Shale_Cobble",
      "rotation": 17
    },
    {
      "x": -14,
      "y": 10,
      "z": 0,
      "name": "Rock_Shale_Cobble",
      "rotation": 17
    },
    {
      "x": -14,
      "y": 11,
      "z": 0,
      "name": "Rock_Shale_Cobble",
      "rotation": 17
    },
    {
      "x": -14,
      "y": 12,
      "z": 0,
      "name": "Rock_Shale_Cobble",
      "rotation": 17
    },
    {
      "x": -14,
      "y": 13,
      "z": 0,
      "name": "Rock_Shale_Cobble",
      "rotation": 17
    },
    {
      "x": -14,
      "y": 14,
      "z": 0,
      "name": "Rock_Shale_Cobble",
      "rotation": 17
    },
    {
      "x": -14,
      "y": 15,
      "z": 0,
      "name": "Rock_Shale_Cobble",
      "rotation": 1
    },
    {
      "x": -14,
      "y": 16,
      "z": 0,
      "name": "Build_Lightsource_Cyan",
      "rotation": 5
    },
    {
      "x": -14,
      "y": 17,
      "z": 0,
      "name": "Build_Lightsource_Cyan",
      "rotation": 5
    },
    {
      "x": -14,
      "y": 18,
      "z": 0,
      "name": "Build_Lightsource_Cyan",
      "rotation": 1
    },
    {
      "x": -14,
      "y": 19,
      "z": 0,
      "name": "Build_Lightsource_Cyan",
      "rotation": 5
    },
    {
      "x": -14,
      "y": 20,
      "z": 0,
      "name": "Build_Lightsource_Cyan",
      "rotation": 5
    },
    {
      "x": -14,
      "y": 9,
      "z": 1,
      "name": "Rock_Shale_Cobble",
      "rotation": 17
    },
    {
      "x": -14,
      "y": 10,
      "z": 1,
      "name": "Rock_Shale_Cobble",
      "rotation": 17
    },
    {
      "x": -14,
      "y": 11,
      "z": 1,
      "name": "Rock_Shale_Cobble",
      "rotation": 17
    },
    {
      "x": -14,
      "y": 12,
      "z": 1,
      "name": "Rock_Shale_Cobble",
      "rotation": 17
    },
    {
      "x": -14,
      "y": 13,
      "z": 1,
      "name": "Rock_Shale_Cobble",
      "rotation": 17
    },
    {
      "x": -14,
      "y": 14,
      "z": 1,
      "name": "Rock_Shale_Cobble",
      "rotation": 17
    },
    {
      "x": -14,
      "y": 15,
      "z": 1,
      "name": "Rock_Shale_Cobble",
      "rotation": 1
    },
    {
      "x": -14,
      "y": 16,
      "z": 1,
      "name": "Build_Lightsource_Cyan",
      "rotation": 5
    },
    {
      "x": -14,
      "y": 17,
      "z": 1,
      "name": "Build_Lightsource_Cyan",
      "rotation": 5
    },
    {
      "x": -14,
      "y": 18,
      "z": 1,
      "name": "Build_Lightsource_Cyan",
      "rotation": 1
    },
    {
      "x": -14,
      "y": 19,
      "z": 1,
      "name": "Build_Lightsource_Cyan",
      "rotation": 5
    },
    {
      "x": -14,
      "y": 20,
      "z": 1,
      "name": "Build_Lightsource_Cyan",
      "rotation": 5
    },
    {
      "x": -14,
      "y": 8,
      "z": 2,
      "name": "Rock_Shale_Cobble_Half",
      "rotation": 7
    },
    {
      "x": -14,
      "y": 9,
      "z": 2,
      "name": "Rock_Shale_Cobble",
      "rotation": 17
    },
    {
      "x": -14,
      "y": 10,
      "z": 2,
      "name": "Rock_Shale_Cobble",
      "rotation": 17
    },
    {
      "x": -14,
      "y": 11,
      "z": 2,
      "name": "Rock_Shale_Cobble",
      "rotation": 17
    },
    {
      "x": -14,
      "y": 12,
      "z": 2,
      "name": "Rock_Shale_Cobble",
      "rotation": 17
    },
    {
      "x": -14,
      "y": 13,
      "z": 2,
      "name": "Rock_Shale_Cobble",
      "rotation": 17
    },
    {
      "x": -14,
      "y": 14,
      "z": 2,
      "name": "Rock_Shale_Cobble",
      "rotation": 17
    },
    {
      "x": -14,
      "y": 15,
      "z": 2,
      "name": "Rock_Shale_Cobble",
      "rotation": 17
    },
    {
      "x": -14,
      "y": 16,
      "z": 2,
      "name": "Rock_Shale_Cobble",
      "rotation": 17
    },
    {
      "x": -14,
      "y": 17,
      "z": 2,
      "name": "Rock_Shale_Cobble",
      "rotation": 6
    },
    {
      "x": -14,
      "y": 18,
      "z": 2,
      "name": "Rock_Shale_Cobble",
      "rotation": 6
    },
    {
      "x": -14,
      "y": 19,
      "z": 2,
      "name": "Rock_Shale_Cobble",
      "rotation": 6
    },
    {
      "x": -14,
      "y": 20,
      "z": 2,
      "name": "Rock_Shale_Cobble",
      "rotation": 6
    },
    {
      "x": -14,
      "y": 9,
      "z": 3,
      "name": "Rock_Shale_Cobble",
      "rotation": 17
    },
    {
      "x": -14,
      "y": 10,
      "z": 3,
      "name": "Rock_Shale_Cobble",
      "rotation": 17
    },
    {
      "x": -14,
      "y": 11,
      "z": 3,
      "name": "Rock_Shale_Cobble",
      "rotation": 17
    },
    {
      "x": -14,
      "y": 12,
      "z": 3,
      "name": "Rock_Shale_Cobble",
      "rotation": 17
    },
    {
      "x": -14,
      "y": 13,
      "z": 3,
      "name": "Rock_Shale_Cobble",
      "rotation": 17
    },
    {
      "x": -14,
      "y": 14,
      "z": 3,
      "name": "Rock_Shale_Cobble",
      "rotation": 17
    },
    {
      "x": -14,
      "y": 15,
      "z": 3,
      "name": "Rock_Shale_Cobble",
      "rotation": 17
    },
    {
      "x": -14,
      "y": 16,
      "z": 3,
      "name": "Rock_Shale_Cobble",
      "rotation": 17
    },
    {
      "x": -14,
      "y": 17,
      "z": 3,
      "name": "Rock_Shale_Cobble",
      "rotation": 6
    },
    {
      "x": -14,
      "y": 18,
      "z": 3,
      "name": "Rock_Shale_Cobble",
      "rotation": 6
    },
    {
      "x": -14,
      "y": 19,
      "z": 3,
      "name": "Build_Lightsource_Cyan",
      "rotation": 17
    },
    {
      "x": -14,
      "y": 20,
      "z": 3,
      "name": "Rock_Shale_Cobble",
      "rotation": 6
    },
    {
      "x": -14,
      "y": 21,
      "z": 3,
      "name": "Rock_Shale_Cobble",
      "rotation": 6
    },
    {
      "x": -14,
      "y": 22,
      "z": 3,
      "name": "Rock_Shale_Cobble",
      "rotation": 4
    },
    {
      "x": -14,
      "y": 23,
      "z": 3,
      "name": "Rock_Shale_Cobble",
      "rotation": 4
    },
    {
      "x": -14,
      "y": 24,
      "z": 3,
      "name": "Plant_Moss_Rug_Green_Dark",
      "support": 15
    },
    {
      "x": -14,
      "y": 11,
      "z": 4,
      "name": "Metal_Iron_Glowing_Pipe_Corner",
      "support": 15
    },
    {
      "x": -14,
      "y": 12,
      "z": 4,
      "name": "Metal_Iron_Glowing_Pipe_Corner",
      "support": 15,
      "rotation": 15
    },
    {
      "x": -14,
      "y": 17,
      "z": 4,
      "name": "Rock_Shale_Cobble",
      "rotation": 7
    },
    {
      "x": -14,
      "y": 18,
      "z": 4,
      "name": "Rock_Shale_Cobble",
      "rotation": 7
    },
    {
      "x": -14,
      "y": 19,
      "z": 4,
      "name": "Build_Lightsource_Cyan",
      "rotation": 17
    },
    {
      "x": -14,
      "y": 20,
      "z": 4,
      "name": "Metal_Iron_Glowing_Pipe_Corner",
      "support": 15,
      "rotation": 10
    },
    {
      "x": -14,
      "y": 21,
      "z": 4,
      "name": "Rock_Shale_Cobble",
      "rotation": 7
    },
    {
      "x": -14,
      "y": 22,
      "z": 4,
      "name": "Metal_Iron_Glowing_Pipe_Corner",
      "support": 15
    },
    {
      "x": -14,
      "y": 23,
      "z": 4,
      "name": "Metal_Iron_Glowing_Pipe",
      "support": 15
    },
    {
      "x": -14,
      "y": 17,
      "z": 5,
      "name": "Rock_Shale_Brick_Smooth",
      "rotation": 1
    },
    {
      "x": -14,
      "y": 18,
      "z": 5,
      "name": "Plant_Moss_Rug_Green_Dark",
      "support": 15
    },
    {
      "x": -14,
      "y": 21,
      "z": 5,
      "name": "Rock_Shale_Brick_Smooth",
      "rotation": 1
    },
    {
      "x": -14,
      "y": 22,
      "z": 5,
      "name": "Plant_Moss_Rug_Green_Dark",
      "support": 15
    },
    {
      "x": -13,
      "y": 17,
      "z": -3,
      "name": "Rock_Shale_Brick_Smooth",
      "rotation": 1
    },
    {
      "x": -13,
      "y": 21,
      "z": -3,
      "name": "Plant_Moss_Wall_Green_Dark",
      "support": 15,
      "rotation": 1
    },
    {
      "x": -13,
      "y": 8,
      "z": -2,
      "name": "Rock_Shale_Cobble",
      "rotation": 17
    },
    {
      "x": -13,
      "y": 9,
      "z": -2,
      "name": "Rock_Shale_Cobble",
      "rotation": 17
    },
    {
      "x": -13,
      "y": 10,
      "z": -2,
      "name": "Rock_Shale_Cobble",
      "rotation": 17
    },
    {
      "x": -13,
      "y": 11,
      "z": -2,
      "name": "Rock_Shale_Cobble",
      "rotation": 17
    },
    {
      "x": -13,
      "y": 12,
      "z": -2,
      "name": "Rock_Shale_Cobble",
      "rotation": 17
    },
    {
      "x": -13,
      "y": 13,
      "z": -2,
      "name": "Rock_Shale_Cobble",
      "rotation": 17
    },
    {
      "x": -13,
      "y": 14,
      "z": -2,
      "name": "Rock_Shale_Cobble",
      "rotation": 17
    },
    {
      "x": -13,
      "y": 15,
      "z": -2,
      "name": "Rock_Shale_Cobble",
      "rotation": 1
    },
    {
      "x": -13,
      "y": 17,
      "z": -2,
      "name": "Rock_Shale_Cobble",
      "rotation": 7
    },
    {
      "x": -13,
      "y": 18,
      "z": -2,
      "name": "Rock_Shale_Cobble",
      "rotation": 1
    },
    {
      "x": -13,
      "y": 19,
      "z": -2,
      "name": "Plant_Moss_Rug_Green_Dark",
      "support": 15
    },
    {
      "x": -13,
      "y": 20,
      "z": -2,
      "name": "Rock_Shale_Cobble",
      "rotation": 1
    },
    {
      "x": -13,
      "y": 7,
      "z": -1,
      "name": "Rock_Shale_Cobble_Half",
      "rotation": 7
    },
    {
      "x": -13,
      "y": 8,
      "z": -1,
      "name": "Rock_Shale_Cobble",
      "rotation": 17
    },
    {
      "x": -13,
      "y": 9,
      "z": -1,
      "name": "Rock_Shale_Cobble",
      "rotation": 17
    },
    {
      "x": -13,
      "y": 10,
      "z": -1,
      "name": "Rock_Shale_Cobble",
      "rotation": 17
    },
    {
      "x": -13,
      "y": 11,
      "z": -1,
      "name": "Rock_Shale_Cobble",
      "rotation": 17
    },
    {
      "x": -13,
      "y": 12,
      "z": -1,
      "name": "Rock_Shale_Cobble",
      "rotation": 17
    },
    {
      "x": -13,
      "y": 13,
      "z": -1,
      "name": "Rock_Shale_Cobble",
      "rotation": 17
    },
    {
      "x": -13,
      "y": 14,
      "z": -1,
      "name": "Rock_Shale_Cobble",
      "rotation": 17
    },
    {
      "x": -13,
      "y": 15,
      "z": -1,
      "name": "Rock_Shale_Cobble",
      "rotation": 17
    },
    {
      "x": -13,
      "y": 16,
      "z": -1,
      "name": "Rock_Shale_Brick_Smooth",
      "rotation": 1
    },
    {
      "x": -13,
      "y": 17,
      "z": -1,
      "name": "Rock_Shale_Cobble",
      "rotation": 6
    },
    {
      "x": -13,
      "y": 18,
      "z": -1,
      "name": "Rock_Shale_Brick_Smooth",
      "rotation": 1
    },
    {
      "x": -13,
      "y": 19,
      "z": -1,
      "name": "Rock_Shale_Brick_Smooth",
      "rotation": 1
    },
    {
      "x": -13,
      "y": 20,
      "z": -1,
      "name": "Rock_Shale_Brick_Smooth",
      "rotation": 1
    },
    {
      "x": -13,
      "y": 8,
      "z": 0,
      "name": "Rock_Shale_Cobble",
      "rotation": 17
    },
    {
      "x": -13,
      "y": 9,
      "z": 0,
      "name": "Rock_Shale_Cobble",
      "rotation": 17
    },
    {
      "x": -13,
      "y": 10,
      "z": 0,
      "name": "Rock_Shale_Cobble",
      "rotation": 17
    },
    {
      "x": -13,
      "y": 11,
      "z": 0,
      "name": "Rock_Shale_Cobble",
      "rotation": 17
    },
    {
      "x": -13,
      "y": 12,
      "z": 0,
      "name": "Rock_Shale_Cobble",
      "rotation": 17
    },
    {
      "x": -13,
      "y": 13,
      "z": 0,
      "name": "Build_Lightsource_Cyan",
      "rotation": 5
    },
    {
      "x": -13,
      "y": 14,
      "z": 0,
      "name": "Build_Lightsource_Cyan",
      "rotation": 5
    },
    {
      "x": -13,
      "y": 15,
      "z": 0,
      "name": "Build_Lightsource_Cyan",
      "rotation": 5
    },
    {
      "x": -13,
      "y": 17,
      "z": 0,
      "name": "Rock_Shale_Cobble",
      "rotation": 6
    },
    {
      "x": -13,
      "y": 18,
      "z": 0,
      "name": "Rock_Shale_Cobble",
      "rotation": 1
    },
    {
      "x": -13,
      "y": 20,
      "z": 0,
      "name": "Rock_Shale_Cobble",
      "rotation": 1
    },
    {
      "x": -13,
      "y": 21,
      "z": 0,
      "name": "Rock_Shale_Cobble",
      "rotation": 6
    },
    {
      "x": -13,
      "y": 23,
      "z": 0,
      "name": "Build_Lightsource_Cyan",
      "rotation": 5
    },
    {
      "x": -13,
      "y": 8,
      "z": 1,
      "name": "Rock_Shale_Cobble",
      "rotation": 17
    },
    {
      "x": -13,
      "y": 9,
      "z": 1,
      "name": "Rock_Shale_Cobble",
      "rotation": 17
    },
    {
      "x": -13,
      "y": 10,
      "z": 1,
      "name": "Rock_Shale_Cobble",
      "rotation": 17
    },
    {
      "x": -13,
      "y": 11,
      "z": 1,
      "name": "Rock_Shale_Cobble",
      "rotation": 1
    },
    {
      "x": -13,
      "y": 12,
      "z": 1,
      "name": "Rock_Shale_Cobble",
      "rotation": 17
    },
    {
      "x": -13,
      "y": 13,
      "z": 1,
      "name": "Build_Lightsource_Cyan",
      "rotation": 5
    },
    {
      "x": -13,
      "y": 14,
      "z": 1,
      "name": "Build_Lightsource_Cyan",
      "rotation": 5
    },
    {
      "x": -13,
      "y": 15,
      "z": 1,
      "name": "Build_Lightsource_Cyan",
      "rotation": 5
    },
    {
      "x": -13,
      "y": 17,
      "z": 1,
      "name": "Rock_Shale_Cobble",
      "rotation": 6
    },
    {
      "x": -13,
      "y": 18,
      "z": 1,
      "name": "Rock_Shale_Cobble",
      "rotation": 1
    },
    {
      "x": -13,
      "y": 20,
      "z": 1,
      "name": "Rock_Shale_Cobble",
      "rotation": 1
    },
    {
      "x": -13,
      "y": 21,
      "z": 1,
      "name": "Rock_Shale_Cobble",
      "rotation": 1
    },
    {
      "x": -13,
      "y": 23,
      "z": 1,
      "name": "Build_Lightsource_Cyan",
      "rotation": 5
    },
    {
      "x": -13,
      "y": 24,
      "z": 1,
      "name": "Plant_Moss_Rug_Green_Dark",
      "support": 15
    },
    {
      "x": -13,
      "y": 7,
      "z": 2,
      "name": "Rock_Shale_Cobble_Half",
      "rotation": 7
    },
    {
      "x": -13,
      "y": 8,
      "z": 2,
      "name": "Rock_Shale_Cobble",
      "rotation": 17
    },
    {
      "x": -13,
      "y": 9,
      "z": 2,
      "name": "Rock_Shale_Cobble",
      "rotation": 17
    },
    {
      "x": -13,
      "y": 10,
      "z": 2,
      "name": "Rock_Shale_Cobble",
      "rotation": 17
    },
    {
      "x": -13,
      "y": 11,
      "z": 2,
      "name": "Rock_Shale_Cobble",
      "rotation": 17
    },
    {
      "x": -13,
      "y": 12,
      "z": 2,
      "name": "Rock_Shale_Cobble",
      "rotation": 17
    },
    {
      "x": -13,
      "y": 13,
      "z": 2,
      "name": "Rock_Shale_Cobble",
      "rotation": 17
    },
    {
      "x": -13,
      "y": 14,
      "z": 2,
      "name": "Rock_Shale_Cobble",
      "rotation": 17
    },
    {
      "x": -13,
      "y": 15,
      "z": 2,
      "name": "Rock_Shale_Cobble",
      "rotation": 17
    },
    {
      "x": -13,
      "y": 16,
      "z": 2,
      "name": "Rock_Shale_Brick_Smooth",
      "rotation": 1
    },
    {
      "x": -13,
      "y": 17,
      "z": 2,
      "name": "Rock_Shale_Cobble",
      "rotation": 6
    },
    {
      "x": -13,
      "y": 18,
      "z": 2,
      "name": "Rock_Shale_Brick_Smooth",
      "rotation": 1
    },
    {
      "x": -13,
      "y": 19,
      "z": 2,
      "name": "Rock_Shale_Brick_Smooth",
      "rotation": 1
    },
    {
      "x": -13,
      "y": 20,
      "z": 2,
      "name": "Rock_Shale_Brick_Smooth",
      "rotation": 1
    },
    {
      "x": -13,
      "y": 21,
      "z": 2,
      "name": "Rock_Shale_Cobble",
      "rotation": 1
    },
    {
      "x": -13,
      "y": 22,
      "z": 2,
      "name": "Rock_Shale_Brick_Smooth",
      "rotation": 1
    },
    {
      "x": -13,
      "y": 23,
      "z": 2,
      "name": "Rock_Shale_Cobble",
      "rotation": 1
    },
    {
      "x": -13,
      "y": 24,
      "z": 2,
      "name": "Plant_Moss_Rug_Green_Dark",
      "support": 15
    },
    {
      "x": -13,
      "y": 8,
      "z": 3,
      "name": "Rock_Shale_Cobble",
      "rotation": 17
    },
    {
      "x": -13,
      "y": 9,
      "z": 3,
      "name": "Rock_Shale_Cobble",
      "rotation": 17
    },
    {
      "x": -13,
      "y": 10,
      "z": 3,
      "name": "Rock_Shale_Cobble",
      "rotation": 17
    },
    {
      "x": -13,
      "y": 11,
      "z": 3,
      "name": "Rock_Shale_Cobble",
      "rotation": 17
    },
    {
      "x": -13,
      "y": 12,
      "z": 3,
      "name": "Rock_Shale_Cobble",
      "rotation": 17
    },
    {
      "x": -13,
      "y": 13,
      "z": 3,
      "name": "Rock_Shale_Cobble",
      "rotation": 17
    },
    {
      "x": -13,
      "y": 14,
      "z": 3,
      "name": "Rock_Shale_Cobble",
      "rotation": 17
    },
    {
      "x": -13,
      "y": 15,
      "z": 3,
      "name": "Rock_Shale_Cobble",
      "rotation": 17
    },
    {
      "x": -13,
      "y": 17,
      "z": 3,
      "name": "Rock_Shale_Cobble",
      "rotation": 7
    },
    {
      "x": -13,
      "y": 18,
      "z": 3,
      "name": "Rock_Shale_Cobble",
      "rotation": 1
    },
    {
      "x": -13,
      "y": 19,
      "z": 3,
      "name": "Plant_Moss_Rug_Green_Dark",
      "support": 15
    },
    {
      "x": -13,
      "y": 20,
      "z": 3,
      "name": "Rock_Shale_Cobble",
      "rotation": 1
    },
    {
      "x": -13,
      "y": 21,
      "z": 3,
      "name": "Rock_Shale_Cobble",
      "rotation": 6
    },
    {
      "x": -13,
      "y": 22,
      "z": 3,
      "name": "Plant_Moss_Rug_Green_Dark",
      "support": 15
    },
    {
      "x": -13,
      "y": 23,
      "z": 3,
      "name": "Rock_Shale_Cobble",
      "rotation": 1
    },
    {
      "x": -13,
      "y": 24,
      "z": 3,
      "name": "Plant_Moss_Rug_Green_Dark",
      "support": 15
    },
    {
      "x": -13,
      "y": 12,
      "z": 4,
      "name": "Metal_Iron_Glowing_Pipe",
      "support": 15,
      "rotation": 5
    },
    {
      "x": -13,
      "y": 17,
      "z": 4,
      "name": "Rock_Shale_Brick_Smooth",
      "rotation": 1
    },
    {
      "x": -13,
      "y": 18,
      "z": 4,
      "name": "Plant_Moss_Rug_Green_Dark",
      "support": 15
    },
    {
      "x": -13,
      "y": 21,
      "z": 4,
      "name": "Rock_Shale_Brick_Smooth",
      "rotation": 1
    },
    {
      "x": -13,
      "y": 23,
      "z": 4,
      "name": "Plant_Moss_Wall_Green_Dark",
      "support": 15
    },
    {
      "x": -12,
      "y": 17,
      "z": -3,
      "name": "Plant_Moss_Wall_Green_Dark",
      "support": 15,
      "rotation": 2
    },
    {
      "x": -12,
      "y": 7,
      "z": -2,
      "name": "Rock_Shale_Cobble",
      "rotation": 17
    },
    {
      "x": -12,
      "y": 8,
      "z": -2,
      "name": "Rock_Shale_Cobble",
      "rotation": 17
    },
    {
      "x": -12,
      "y": 9,
      "z": -2,
      "name": "Rock_Shale_Cobble",
      "rotation": 17
    },
    {
      "x": -12,
      "y": 10,
      "z": -2,
      "name": "Rock_Shale_Cobble",
      "rotation": 17
    },
    {
      "x": -12,
      "y": 11,
      "z": -2,
      "name": "Rock_Shale_Cobble",
      "rotation": 17
    },
    {
      "x": -12,
      "y": 12,
      "z": -2,
      "name": "Rock_Shale_Cobble",
      "rotation": 17
    },
    {
      "x": -12,
      "y": 17,
      "z": -2,
      "name": "Rock_Shale_Brick_Smooth",
      "rotation": 1
    },
    {
      "x": -12,
      "y": 18,
      "z": -2,
      "name": "Plant_Moss_Rug_Green_Dark",
      "support": 15
    },
    {
      "x": -12,
      "y": 6,
      "z": -1,
      "name": "Rock_Shale_Cobble_Half",
      "rotation": 35
    },
    {
      "x": -12,
      "y": 7,
      "z": -1,
      "name": "Rock_Shale_Cobble",
      "rotation": 17
    },
    {
      "x": -12,
      "y": 8,
      "z": -1,
      "name": "Rock_Shale_Cobble",
      "rotation": 17
    },
    {
      "x": -12,
      "y": 9,
      "z": -1,
      "name": "Rock_Shale_Cobble",
      "rotation": 17
    },
    {
      "x": -12,
      "y": 10,
      "z": -1,
      "name": "Rock_Shale_Cobble",
      "rotation": 17
    },
    {
      "x": -12,
      "y": 11,
      "z": -1,
      "name": "Rock_Shale_Cobble",
      "rotation": 17
    },
    {
      "x": -12,
      "y": 12,
      "z": -1,
      "name": "Rock_Shale_Cobble",
      "rotation": 17
    },
    {
      "x": -12,
      "y": 13,
      "z": -1,
      "name": "Rock_Shale_Brick_Smooth",
      "rotation": 1
    },
    {
      "x": -12,
      "y": 14,
      "z": -1,
      "name": "Rock_Shale_Brick_Smooth",
      "rotation": 1
    },
    {
      "x": -12,
      "y": 15,
      "z": -1,
      "name": "Rock_Shale_Brick_Smooth",
      "rotation": 1
    },
    {
      "x": -12,
      "y": 16,
      "z": -1,
      "name": "Plant_Moss_Rug_Green_Dark",
      "support": 15
    },
    {
      "x": -12,
      "y": 17,
      "z": -1,
      "name": "Rock_Shale_Brick_Smooth",
      "rotation": 1
    },
    {
      "x": -12,
      "y": 18,
      "z": -1,
      "name": "Plant_Moss_Rug_Green_Dark",
      "support": 15
    },
    {
      "x": -12,
      "y": 7,
      "z": 0,
      "name": "Rock_Shale_Cobble",
      "rotation": 17
    },
    {
      "x": -12,
      "y": 8,
      "z": 0,
      "name": "Rock_Shale_Cobble",
      "rotation": 17
    },
    {
      "x": -12,
      "y": 9,
      "z": 0,
      "name": "Rock_Shale_Cobble",
      "rotation": 17
    },
    {
      "x": -12,
      "y": 10,
      "z": 0,
      "name": "Rock_Shale_Cobble",
      "rotation": 17
    },
    {
      "x": -12,
      "y": 11,
      "z": 0,
      "name": "Build_Lightsource_Cyan",
      "rotation": 1
    },
    {
      "x": -12,
      "y": 12,
      "z": 0,
      "name": "Build_Lightsource_Cyan",
      "rotation": 1
    },
    {
      "x": -12,
      "y": 17,
      "z": 0,
      "name": "Rock_Shale_Brick_Smooth",
      "rotation": 1
    },
    {
      "x": -12,
      "y": 21,
      "z": 0,
      "name": "Rock_Shale_Brick_Smooth",
      "rotation": 1
    },
    {
      "x": -12,
      "y": 7,
      "z": 1,
      "name": "Rock_Shale_Cobble",
      "rotation": 17
    },
    {
      "x": -12,
      "y": 8,
      "z": 1,
      "name": "Rock_Shale_Cobble",
      "rotation": 17
    },
    {
      "x": -12,
      "y": 9,
      "z": 1,
      "name": "Rock_Shale_Cobble",
      "rotation": 17
    },
    {
      "x": -12,
      "y": 10,
      "z": 1,
      "name": "Rock_Shale_Cobble",
      "rotation": 17
    },
    {
      "x": -12,
      "y": 11,
      "z": 1,
      "name": "Build_Lightsource_Cyan",
      "rotation": 1
    },
    {
      "x": -12,
      "y": 12,
      "z": 1,
      "name": "Build_Lightsource_Cyan",
      "rotation": 1
    },
    {
      "x": -12,
      "y": 17,
      "z": 1,
      "name": "Rock_Shale_Brick_Smooth",
      "rotation": 1
    },
    {
      "x": -12,
      "y": 21,
      "z": 1,
      "name": "Rock_Shale_Brick_Smooth",
      "rotation": 1
    },
    {
      "x": -12,
      "y": 22,
      "z": 1,
      "name": "Plant_Moss_Rug_Green_Dark",
      "support": 15
    },
    {
      "x": -12,
      "y": 23,
      "z": 1,
      "name": "Plant_Moss_Wall_Green_Dark",
      "support": 15,
      "rotation": 1
    },
    {
      "x": -12,
      "y": 6,
      "z": 2,
      "name": "Rock_Shale_Cobble_Half",
      "rotation": 35
    },
    {
      "x": -12,
      "y": 7,
      "z": 2,
      "name": "Rock_Shale_Cobble",
      "rotation": 17
    },
    {
      "x": -12,
      "y": 8,
      "z": 2,
      "name": "Rock_Shale_Cobble",
      "rotation": 17
    },
    {
      "x": -12,
      "y": 9,
      "z": 2,
      "name": "Rock_Shale_Cobble",
      "rotation": 17
    },
    {
      "x": -12,
      "y": 10,
      "z": 2,
      "name": "Rock_Shale_Cobble",
      "rotation": 17
    },
    {
      "x": -12,
      "y": 11,
      "z": 2,
      "name": "Rock_Shale_Cobble",
      "rotation": 17
    },
    {
      "x": -12,
      "y": 12,
      "z": 2,
      "name": "Rock_Shale_Cobble",
      "rotation": 1
    },
    {
      "x": -12,
      "y": 13,
      "z": 2,
      "name": "Rock_Shale_Brick_Smooth",
      "rotation": 1
    },
    {
      "x": -12,
      "y": 14,
      "z": 2,
      "name": "Rock_Shale_Brick_Smooth",
      "rotation": 1
    },
    {
      "x": -12,
      "y": 15,
      "z": 2,
      "name": "Rock_Shale_Brick_Smooth",
      "rotation": 1
    },
    {
      "x": -12,
      "y": 16,
      "z": 2,
      "name": "Plant_Moss_Rug_Green_Dark",
      "support": 15
    },
    {
      "x": -12,
      "y": 17,
      "z": 2,
      "name": "Rock_Shale_Brick_Smooth",
      "rotation": 1
    },
    {
      "x": -12,
      "y": 21,
      "z": 2,
      "name": "Rock_Shale_Brick_Smooth",
      "rotation": 1
    },
    {
      "x": -12,
      "y": 23,
      "z": 2,
      "name": "Rock_Shale_Brick_Smooth",
      "rotation": 1
    },
    {
      "x": -12,
      "y": 7,
      "z": 3,
      "name": "Rock_Shale_Cobble",
      "rotation": 17
    },
    {
      "x": -12,
      "y": 8,
      "z": 3,
      "name": "Rock_Shale_Cobble",
      "rotation": 17
    },
    {
      "x": -12,
      "y": 9,
      "z": 3,
      "name": "Rock_Shale_Cobble",
      "rotation": 17
    },
    {
      "x": -12,
      "y": 10,
      "z": 3,
      "name": "Rock_Shale_Cobble",
      "rotation": 17
    },
    {
      "x": -12,
      "y": 11,
      "z": 3,
      "name": "Rock_Shale_Cobble",
      "rotation": 17
    },
    {
      "x": -12,
      "y": 12,
      "z": 3,
      "name": "Rock_Shale_Cobble",
      "rotation": 17
    },
    {
      "x": -12,
      "y": 13,
      "z": 3,
      "name": "Plant_Moss_Rug_Green_Dark",
      "support": 15
    },
    {
      "x": -12,
      "y": 17,
      "z": 3,
      "name": "Rock_Shale_Brick_Smooth",
      "rotation": 1
    },
    {
      "x": -12,
      "y": 18,
      "z": 3,
      "name": "Plant_Moss_Rug_Green_Dark",
      "support": 15
    },
    {
      "x": -12,
      "y": 21,
      "z": 3,
      "name": "Rock_Shale_Brick_Smooth",
      "rotation": 1
    },
    {
      "x": -12,
      "y": 22,
      "z": 3,
      "name": "Plant_Moss_Rug_Green_Dark",
      "support": 15
    },
    {
      "x": -12,
      "y": 12,
      "z": 4,
      "name": "Metal_Iron_Glowing_Pipe",
      "support": 15,
      "rotation": 5
    },
    {
      "x": -12,
      "y": 21,
      "z": 4,
      "name": "Plant_Moss_Wall_Green_Dark",
      "support": 15
    },
    {
      "x": -11,
      "y": 10,
      "z": -3,
      "name": "Plant_Moss_Wall_Green_Dark",
      "support": 15,
      "rotation": 2
    },
    {
      "x": -11,
      "y": 6,
      "z": -2,
      "name": "Rock_Shale_Cobble",
      "rotation": 17
    },
    {
      "x": -11,
      "y": 7,
      "z": -2,
      "name": "Rock_Shale_Cobble",
      "rotation": 17
    },
    {
      "x": -11,
      "y": 8,
      "z": -2,
      "name": "Rock_Shale_Cobble",
      "rotation": 17
    },
    {
      "x": -11,
      "y": 9,
      "z": -2,
      "name": "Rock_Shale_Cobble",
      "rotation": 17
    },
    {
      "x": -11,
      "y": 10,
      "z": -2,
      "name": "Rock_Shale_Cobble",
      "rotation": 17
    },
    {
      "x": -11,
      "y": 11,
      "z": -2,
      "name": "Plant_Moss_Rug_Green_Dark",
      "support": 15
    },
    {
      "x": -11,
      "y": 17,
      "z": -2,
      "name": "Plant_Moss_Wall_Green_Dark",
      "support": 15,
      "rotation": 1
    },
    {
      "x": -11,
      "y": 5,
      "z": -1,
      "name": "Rock_Shale_Cobble_Half",
      "rotation": 35
    },
    {
      "x": -11,
      "y": 6,
      "z": -1,
      "name": "Rock_Shale_Cobble",
      "rotation": 17
    },
    {
      "x": -11,
      "y": 7,
      "z": -1,
      "name": "Rock_Shale_Cobble",
      "rotation": 17
    },
    {
      "x": -11,
      "y": 8,
      "z": -1,
      "name": "Rock_Shale_Cobble",
      "rotation": 17
    },
    {
      "x": -11,
      "y": 9,
      "z": -1,
      "name": "Rock_Shale_Cobble",
      "rotation": 17
    },
    {
      "x": -11,
      "y": 10,
      "z": -1,
      "name": "Rock_Shale_Cobble",
      "rotation": 17
    },
    {
      "x": -11,
      "y": 11,
      "z": -1,
      "name": "Rock_Shale_Brick_Smooth",
      "rotation": 1
    },
    {
      "x": -11,
      "y": 12,
      "z": -1,
      "name": "Rock_Shale_Brick_Smooth",
      "rotation": 1
    },
    {
      "x": -11,
      "y": 6,
      "z": 0,
      "name": "Rock_Shale_Cobble",
      "rotation": 17
    },
    {
      "x": -11,
      "y": 7,
      "z": 0,
      "name": "Rock_Shale_Cobble",
      "rotation": 17
    },
    {
      "x": -11,
      "y": 8,
      "z": 0,
      "name": "Rock_Shale_Cobble",
      "rotation": 17
    },
    {
      "x": -11,
      "y": 9,
      "z": 0,
      "name": "Rock_Shale_Cobble",
      "rotation": 17
    },
    {
      "x": -11,
      "y": 10,
      "z": 0,
      "name": "Build_Lightsource_Cyan",
      "rotation": 1
    },
    {
      "x": -11,
      "y": 6,
      "z": 1,
      "name": "Rock_Shale_Cobble",
      "rotation": 17
    },
    {
      "x": -11,
      "y": 7,
      "z": 1,
      "name": "Rock_Shale_Cobble",
      "rotation": 17
    },
    {
      "x": -11,
      "y": 8,
      "z": 1,
      "name": "Rock_Shale_Cobble",
      "rotation": 17
    },
    {
      "x": -11,
      "y": 9,
      "z": 1,
      "name": "Rock_Shale_Cobble",
      "rotation": 1
    },
    {
      "x": -11,
      "y": 10,
      "z": 1,
      "name": "Build_Lightsource_Cyan",
      "rotation": 1
    },
    {
      "x": -11,
      "y": 5,
      "z": 2,
      "name": "Rock_Shale_Cobble_Half",
      "rotation": 35
    },
    {
      "x": -11,
      "y": 6,
      "z": 2,
      "name": "Rock_Shale_Cobble",
      "rotation": 17
    },
    {
      "x": -11,
      "y": 7,
      "z": 2,
      "name": "Rock_Shale_Cobble",
      "rotation": 17
    },
    {
      "x": -11,
      "y": 8,
      "z": 2,
      "name": "Rock_Shale_Cobble",
      "rotation": 17
    },
    {
      "x": -11,
      "y": 9,
      "z": 2,
      "name": "Rock_Shale_Cobble",
      "rotation": 1
    },
    {
      "x": -11,
      "y": 10,
      "z": 2,
      "name": "Rock_Shale_Cobble",
      "rotation": 17
    },
    {
      "x": -11,
      "y": 11,
      "z": 2,
      "name": "Rock_Shale_Brick_Smooth",
      "rotation": 1
    },
    {
      "x": -11,
      "y": 12,
      "z": 2,
      "name": "Rock_Shale_Brick_Smooth",
      "rotation": 1
    },
    {
      "x": -11,
      "y": 13,
      "z": 2,
      "name": "Plant_Moss_Rug_Green_Dark",
      "support": 15
    },
    {
      "x": -11,
      "y": 6,
      "z": 3,
      "name": "Rock_Shale_Cobble",
      "rotation": 17
    },
    {
      "x": -11,
      "y": 7,
      "z": 3,
      "name": "Rock_Shale_Cobble",
      "rotation": 17
    },
    {
      "x": -11,
      "y": 8,
      "z": 3,
      "name": "Rock_Shale_Cobble",
      "rotation": 17
    },
    {
      "x": -11,
      "y": 9,
      "z": 3,
      "name": "Rock_Shale_Cobble",
      "rotation": 1
    },
    {
      "x": -11,
      "y": 10,
      "z": 3,
      "name": "Rock_Shale_Cobble",
      "rotation": 1
    },
    {
      "x": -11,
      "y": 12,
      "z": 3,
      "name": "Plant_Moss_Wall_Green_Dark",
      "support": 15,
      "rotation": 1
    },
    {
      "x": -11,
      "y": 11,
      "z": 4,
      "name": "Metal_Iron_Glowing_Pipe_Corner",
      "support": 15,
      "rotation": 3
    },
    {
      "x": -11,
      "y": 12,
      "z": 4,
      "name": "Metal_Iron_Glowing_Pipe_Corner",
      "support": 15,
      "rotation": 11
    },
    {
      "x": -10,
      "y": 9,
      "z": -3,
      "name": "Plant_Moss_Wall_Green_Dark",
      "support": 15,
      "rotation": 2
    },
    {
      "x": -10,
      "y": 5,
      "z": -2,
      "name": "Rock_Shale_Cobble",
      "rotation": 17
    },
    {
      "x": -10,
      "y": 6,
      "z": -2,
      "name": "Rock_Shale_Cobble",
      "rotation": 17
    },
    {
      "x": -10,
      "y": 7,
      "z": -2,
      "name": "Rock_Shale_Cobble",
      "rotation": 17
    },
    {
      "x": -10,
      "y": 8,
      "z": -2,
      "name": "Rock_Shale_Cobble",
      "rotation": 17
    },
    {
      "x": -10,
      "y": 9,
      "z": -2,
      "name": "Rock_Shale_Cobble",
      "rotation": 17
    },
    {
      "x": -10,
      "y": 10,
      "z": -2,
      "name": "Plant_Moss_Rug_Green_Dark",
      "support": 15
    },
    {
      "x": -10,
      "y": 4,
      "z": -1,
      "name": "Rock_Shale_Cobble_Half",
      "rotation": 35
    },
    {
      "x": -10,
      "y": 5,
      "z": -1,
      "name": "Rock_Shale_Cobble",
      "rotation": 17
    },
    {
      "x": -10,
      "y": 6,
      "z": -1,
      "name": "Rock_Shale_Cobble",
      "rotation": 17
    },
    {
      "x": -10,
      "y": 7,
      "z": -1,
      "name": "Rock_Shale_Cobble",
      "rotation": 17
    },
    {
      "x": -10,
      "y": 8,
      "z": -1,
      "name": "Rock_Shale_Cobble",
      "rotation": 17
    },
    {
      "x": -10,
      "y": 9,
      "z": -1,
      "name": "Rock_Shale_Cobble",
      "rotation": 17
    },
    {
      "x": -10,
      "y": 10,
      "z": -1,
      "name": "Rock_Shale_Brick_Smooth",
      "rotation": 1
    },
    {
      "x": -10,
      "y": 5,
      "z": 0,
      "name": "Rock_Shale_Cobble",
      "rotation": 17
    },
    {
      "x": -10,
      "y": 6,
      "z": 0,
      "name": "Rock_Shale_Cobble",
      "rotation": 17
    },
    {
      "x": -10,
      "y": 7,
      "z": 0,
      "name": "Rock_Shale_Cobble",
      "rotation": 17
    },
    {
      "x": -10,
      "y": 8,
      "z": 0,
      "name": "Build_Lightsource_Cyan",
      "rotation": 5
    },
    {
      "x": -10,
      "y": 9,
      "z": 0,
      "name": "Build_Lightsource_Cyan",
      "rotation": 5
    },
    {
      "x": -10,
      "y": 11,
      "z": 0,
      "name": "Metal_Iron_Glowing_Pipe_Corner",
      "support": 15,
      "rotation": 18
    },
    {
      "x": -10,
      "y": 5,
      "z": 1,
      "name": "Rock_Shale_Cobble",
      "rotation": 17
    },
    {
      "x": -10,
      "y": 6,
      "z": 1,
      "name": "Rock_Shale_Cobble",
      "rotation": 17
    },
    {
      "x": -10,
      "y": 7,
      "z": 1,
      "name": "Rock_Shale_Cobble",
      "rotation": 17
    },
    {
      "x": -10,
      "y": 8,
      "z": 1,
      "name": "Rock_Shale_Cobble",
      "rotation": 17
    },
    {
      "x": -10,
      "y": 9,
      "z": 1,
      "name": "Build_Lightsource_Cyan",
      "rotation": 5
    },
    {
      "x": -10,
      "y": 11,
      "z": 1,
      "name": "Metal_Iron_Glowing_Pipe",
      "support": 15,
      "rotation": 4
    },
    {
      "x": -10,
      "y": 4,
      "z": 2,
      "name": "Rock_Shale_Cobble_Half",
      "rotation": 35
    },
    {
      "x": -10,
      "y": 5,
      "z": 2,
      "name": "Rock_Shale_Cobble",
      "rotation": 17
    },
    {
      "x": -10,
      "y": 6,
      "z": 2,
      "name": "Rock_Shale_Cobble",
      "rotation": 17
    },
    {
      "x": -10,
      "y": 7,
      "z": 2,
      "name": "Rock_Shale_Cobble",
      "rotation": 17
    },
    {
      "x": -10,
      "y": 8,
      "z": 2,
      "name": "Rock_Shale_Cobble",
      "rotation": 17
    },
    {
      "x": -10,
      "y": 9,
      "z": 2,
      "name": "Rock_Shale_Cobble",
      "rotation": 17
    },
    {
      "x": -10,
      "y": 10,
      "z": 2,
      "name": "Rock_Shale_Brick_Smooth",
      "rotation": 1
    },
    {
      "x": -10,
      "y": 11,
      "z": 2,
      "name": "Metal_Iron_Glowing_Pipe",
      "support": 15,
      "rotation": 4
    },
    {
      "x": -10,
      "y": 12,
      "z": 2,
      "name": "Plant_Moss_Wall_Green_Dark",
      "support": 15,
      "rotation": 1
    },
    {
      "x": -10,
      "y": 5,
      "z": 3,
      "name": "Rock_Shale_Cobble",
      "rotation": 17
    },
    {
      "x": -10,
      "y": 6,
      "z": 3,
      "name": "Rock_Shale_Cobble",
      "rotation": 17
    },
    {
      "x": -10,
      "y": 7,
      "z": 3,
      "name": "Rock_Shale_Cobble",
      "rotation": 17
    },
    {
      "x": -10,
      "y": 8,
      "z": 3,
      "name": "Rock_Shale_Cobble",
      "rotation": 17
    },
    {
      "x": -10,
      "y": 9,
      "z": 3,
      "name": "Rock_Shale_Cobble",
      "rotation": 17
    },
    {
      "x": -10,
      "y": 10,
      "z": 3,
      "name": "Plant_Moss_Rug_Green_Dark",
      "support": 15
    },
    {
      "x": -10,
      "y": 11,
      "z": 3,
      "name": "Metal_Iron_Glowing_Pipe",
      "support": 15,
      "rotation": 4
    },
    {
      "x": -10,
      "y": 11,
      "z": 4,
      "name": "Metal_Iron_Glowing_Pipe_Corner",
      "support": 15,
      "rotation": 27
    },
    {
      "x": -9,
      "y": 9,
      "z": -3,
      "name": "Metal_Iron_Glowing_Pipe_Corner",
      "support": 15,
      "rotation": 5
    },
    {
      "x": -9,
      "y": 10,
      "z": -3,
      "name": "Metal_Iron_Glowing_Pipe_Corner",
      "support": 15,
      "rotation": 8
    },
    {
      "x": -9,
      "y": 5,
      "z": -2,
      "name": "Rock_Shale_Cobble",
      "rotation": 17
    },
    {
      "x": -9,
      "y": 6,
      "z": -2,
      "name": "Rock_Shale_Cobble",
      "rotation": 17
    },
    {
      "x": -9,
      "y": 7,
      "z": -2,
      "name": "Rock_Shale_Cobble",
      "rotation": 17
    },
    {
      "x": -9,
      "y": 8,
      "z": -2,
      "name": "Rock_Shale_Cobble",
      "rotation": 17
    },
    {
      "x": -9,
      "y": 10,
      "z": -2,
      "name": "Metal_Iron_Glowing_Pipe",
      "support": 15,
      "rotation": 4
    },
    {
      "x": -9,
      "y": 4,
      "z": -1,
      "name": "Rock_Shale_Cobble_Half",
      "rotation": 35
    },
    {
      "x": -9,
      "y": 5,
      "z": -1,
      "name": "Rock_Shale_Cobble",
      "rotation": 17
    },
    {
      "x": -9,
      "y": 6,
      "z": -1,
      "name": "Rock_Shale_Cobble",
      "rotation": 17
    },
    {
      "x": -9,
      "y": 7,
      "z": -1,
      "name": "Rock_Shale_Cobble",
      "rotation": 17
    },
    {
      "x": -9,
      "y": 8,
      "z": -1,
      "name": "Rock_Shale_Cobble",
      "rotation": 17
    },
    {
      "x": -9,
      "y": 9,
      "z": -1,
      "name": "Rock_Shale_Brick_Smooth",
      "rotation": 1
    },
    {
      "x": -9,
      "y": 10,
      "z": -1,
      "name": "Metal_Iron_Glowing_Pipe",
      "support": 15,
      "rotation": 4
    },
    {
      "x": -9,
      "y": 5,
      "z": 0,
      "name": "Rock_Shale_Cobble",
      "rotation": 17
    },
    {
      "x": -9,
      "y": 6,
      "z": 0,
      "name": "Rock_Shale_Cobble",
      "rotation": 17
    },
    {
      "x": -9,
      "y": 7,
      "z": 0,
      "name": "Rock_Shale_Cobble",
      "rotation": 17
    },
    {
      "x": -9,
      "y": 8,
      "z": 0,
      "name": "Build_Lightsource_Cyan",
      "rotation": 1
    },
    {
      "x": -9,
      "y": 10,
      "z": 0,
      "name": "Metal_Iron_Glowing_Pipe_Corner",
      "support": 15,
      "rotation": 6
    },
    {
      "x": -9,
      "y": 11,
      "z": 0,
      "name": "Metal_Iron_Glowing_Pipe_Corner",
      "support": 15,
      "rotation": 11
    },
    {
      "x": -9,
      "y": 5,
      "z": 1,
      "name": "Rock_Shale_Cobble",
      "rotation": 17
    },
    {
      "x": -9,
      "y": 6,
      "z": 1,
      "name": "Rock_Shale_Cobble",
      "rotation": 17
    },
    {
      "x": -9,
      "y": 7,
      "z": 1,
      "name": "Rock_Shale_Cobble",
      "rotation": 17
    },
    {
      "x": -9,
      "y": 8,
      "z": 1,
      "name": "Build_Lightsource_Cyan",
      "rotation": 5
    },
    {
      "x": -9,
      "y": 4,
      "z": 2,
      "name": "Rock_Shale_Cobble_Half",
      "rotation": 35
    },
    {
      "x": -9,
      "y": 5,
      "z": 2,
      "name": "Rock_Shale_Cobble",
      "rotation": 17
    },
    {
      "x": -9,
      "y": 6,
      "z": 2,
      "name": "Rock_Shale_Cobble",
      "rotation": 17
    },
    {
      "x": -9,
      "y": 7,
      "z": 2,
      "name": "Rock_Shale_Cobble",
      "rotation": 17
    },
    {
      "x": -9,
      "y": 8,
      "z": 2,
      "name": "Rock_Shale_Cobble",
      "rotation": 17
    },
    {
      "x": -9,
      "y": 9,
      "z": 2,
      "name": "Rock_Shale_Brick_Smooth",
      "rotation": 1
    },
    {
      "x": -9,
      "y": 5,
      "z": 3,
      "name": "Rock_Shale_Cobble",
      "rotation": 17
    },
    {
      "x": -9,
      "y": 6,
      "z": 3,
      "name": "Rock_Shale_Cobble",
      "rotation": 17
    },
    {
      "x": -9,
      "y": 7,
      "z": 3,
      "name": "Rock_Shale_Cobble",
      "rotation": 17
    },
    {
      "x": -9,
      "y": 8,
      "z": 3,
      "name": "Rock_Shale_Cobble",
      "rotation": 17
    },
    {
      "x": -9,
      "y": 9,
      "z": 3,
      "name": "Plant_Moss_Rug_Green_Dark",
      "support": 15
    },
    {
      "x": -8,
      "y": 7,
      "z": -3,
      "name": "Metal_Iron_Glowing_Pipe_Corner",
      "support": 15,
      "rotation": 3
    },
    {
      "x": -8,
      "y": 8,
      "z": -3,
      "name": "Metal_Iron_Glowing_Pipe",
      "support": 15
    },
    {
      "x": -8,
      "y": 9,
      "z": -3,
      "name": "Metal_Iron_Glowing_Pipe_Corner",
      "support": 15,
      "rotation": 11
    },
    {
      "x": -8,
      "y": 4,
      "z": -2,
      "name": "Rock_Shale_Cobble",
      "rotation": 17
    },
    {
      "x": -8,
      "y": 5,
      "z": -2,
      "name": "Rock_Shale_Cobble",
      "rotation": 17
    },
    {
      "x": -8,
      "y": 6,
      "z": -2,
      "name": "Rock_Shale_Cobble",
      "rotation": 17
    },
    {
      "x": -8,
      "y": 7,
      "z": -2,
      "name": "Rock_Shale_Cobble",
      "rotation": 17
    },
    {
      "x": -8,
      "y": 3,
      "z": -1,
      "name": "Rock_Shale_Cobble_Half",
      "rotation": 35
    },
    {
      "x": -8,
      "y": 4,
      "z": -1,
      "name": "Rock_Shale_Cobble",
      "rotation": 17
    },
    {
      "x": -8,
      "y": 5,
      "z": -1,
      "name": "Rock_Shale_Cobble",
      "rotation": 17
    },
    {
      "x": -8,
      "y": 6,
      "z": -1,
      "name": "Rock_Shale_Cobble",
      "rotation": 17
    },
    {
      "x": -8,
      "y": 7,
      "z": -1,
      "name": "Rock_Shale_Cobble",
      "rotation": 17
    },
    {
      "x": -8,
      "y": 8,
      "z": -1,
      "name": "Rock_Shale_Brick_Smooth",
      "rotation": 1
    },
    {
      "x": -8,
      "y": 4,
      "z": 0,
      "name": "Rock_Shale_Cobble",
      "rotation": 17
    },
    {
      "x": -8,
      "y": 5,
      "z": 0,
      "name": "Rock_Shale_Cobble",
      "rotation": 17
    },
    {
      "x": -8,
      "y": 6,
      "z": 0,
      "name": "Rock_Shale_Cobble",
      "rotation": 17
    },
    {
      "x": -8,
      "y": 7,
      "z": 0,
      "name": "Build_Lightsource_Cyan",
      "rotation": 5
    },
    {
      "x": -8,
      "y": 4,
      "z": 1,
      "name": "Rock_Shale_Cobble",
      "rotation": 17
    },
    {
      "x": -8,
      "y": 5,
      "z": 1,
      "name": "Rock_Shale_Cobble",
      "rotation": 17
    },
    {
      "x": -8,
      "y": 6,
      "z": 1,
      "name": "Rock_Shale_Cobble",
      "rotation": 17
    },
    {
      "x": -8,
      "y": 7,
      "z": 1,
      "name": "Build_Lightsource_Cyan",
      "rotation": 1
    },
    {
      "x": -8,
      "y": 3,
      "z": 2,
      "name": "Rock_Shale_Cobble_Half",
      "rotation": 35
    },
    {
      "x": -8,
      "y": 4,
      "z": 2,
      "name": "Rock_Shale_Cobble",
      "rotation": 17
    },
    {
      "x": -8,
      "y": 5,
      "z": 2,
      "name": "Rock_Shale_Cobble",
      "rotation": 17
    },
    {
      "x": -8,
      "y": 6,
      "z": 2,
      "name": "Rock_Shale_Cobble",
      "rotation": 17
    },
    {
      "x": -8,
      "y": 7,
      "z": 2,
      "name": "Rock_Shale_Cobble",
      "rotation": 17
    },
    {
      "x": -8,
      "y": 8,
      "z": 2,
      "name": "Rock_Shale_Brick_Smooth",
      "rotation": 1
    },
    {
      "x": -8,
      "y": 4,
      "z": 3,
      "name": "Rock_Shale_Cobble",
      "rotation": 17
    },
    {
      "x": -8,
      "y": 5,
      "z": 3,
      "name": "Rock_Shale_Cobble",
      "rotation": 17
    },
    {
      "x": -8,
      "y": 6,
      "z": 3,
      "name": "Rock_Shale_Cobble",
      "rotation": 17
    },
    {
      "x": -8,
      "y": 7,
      "z": 3,
      "name": "Rock_Shale_Cobble",
      "rotation": 17
    },
    {
      "x": -8,
      "y": 8,
      "z": 3,
      "name": "Plant_Moss_Wall_Green_Dark",
      "support": 15,
      "rotation": 1
    },
    {
      "x": -7,
      "y": 6,
      "z": -3,
      "name": "Metal_Iron_Glowing_Pipe_Corner",
      "support": 15,
      "rotation": 5
    },
    {
      "x": -7,
      "y": 7,
      "z": -3,
      "name": "Metal_Iron_Glowing_Pipe_Corner",
      "support": 15,
      "rotation": 11
    },
    {
      "x": -7,
      "y": 4,
      "z": -2,
      "name": "Rock_Shale_Cobble",
      "rotation": 17
    },
    {
      "x": -7,
      "y": 5,
      "z": -2,
      "name": "Rock_Shale_Cobble",
      "rotation": 17
    },
    {
      "x": -7,
      "y": 6,
      "z": -2,
      "name": "Rock_Shale_Cobble",
      "rotation": 17
    },
    {
      "x": -7,
      "y": 7,
      "z": -2,
      "name": "Rock_Shale_Cobble",
      "rotation": 17
    },
    {
      "x": -7,
      "y": 3,
      "z": -1,
      "name": "Rock_Shale_Cobble_Half",
      "rotation": 35
    },
    {
      "x": -7,
      "y": 4,
      "z": -1,
      "name": "Rock_Shale_Cobble",
      "rotation": 17
    },
    {
      "x": -7,
      "y": 5,
      "z": -1,
      "name": "Rock_Shale_Cobble",
      "rotation": 17
    },
    {
      "x": -7,
      "y": 6,
      "z": -1,
      "name": "Rock_Shale_Cobble",
      "rotation": 17
    },
    {
      "x": -7,
      "y": 7,
      "z": -1,
      "name": "Rock_Shale_Cobble",
      "rotation": 17
    },
    {
      "x": -7,
      "y": 8,
      "z": -1,
      "name": "Rock_Shale_Brick_Smooth",
      "rotation": 1
    },
    {
      "x": -7,
      "y": 4,
      "z": 0,
      "name": "Rock_Shale_Cobble",
      "rotation": 17
    },
    {
      "x": -7,
      "y": 5,
      "z": 0,
      "name": "Rock_Shale_Cobble",
      "rotation": 17
    },
    {
      "x": -7,
      "y": 6,
      "z": 0,
      "name": "Rock_Shale_Cobble",
      "rotation": 17
    },
    {
      "x": -7,
      "y": 7,
      "z": 0,
      "name": "Build_Lightsource_Cyan",
      "rotation": 5
    },
    {
      "x": -7,
      "y": 4,
      "z": 1,
      "name": "Rock_Shale_Cobble",
      "rotation": 17
    },
    {
      "x": -7,
      "y": 5,
      "z": 1,
      "name": "Rock_Shale_Cobble",
      "rotation": 17
    },
    {
      "x": -7,
      "y": 6,
      "z": 1,
      "name": "Rock_Shale_Cobble",
      "rotation": 17
    },
    {
      "x": -7,
      "y": 7,
      "z": 1,
      "name": "Build_Lightsource_Cyan",
      "rotation": 5
    },
    {
      "x": -7,
      "y": 3,
      "z": 2,
      "name": "Rock_Shale_Cobble_Half",
      "rotation": 35
    },
    {
      "x": -7,
      "y": 4,
      "z": 2,
      "name": "Rock_Shale_Cobble",
      "rotation": 17
    },
    {
      "x": -7,
      "y": 5,
      "z": 2,
      "name": "Rock_Shale_Cobble",
      "rotation": 17
    },
    {
      "x": -7,
      "y": 6,
      "z": 2,
      "name": "Rock_Shale_Cobble",
      "rotation": 17
    },
    {
      "x": -7,
      "y": 7,
      "z": 2,
      "name": "Rock_Shale_Cobble",
      "rotation": 17
    },
    {
      "x": -7,
      "y": 8,
      "z": 2,
      "name": "Rock_Shale_Brick_Smooth",
      "rotation": 1
    },
    {
      "x": -7,
      "y": 4,
      "z": 3,
      "name": "Rock_Shale_Cobble",
      "rotation": 17
    },
    {
      "x": -7,
      "y": 5,
      "z": 3,
      "name": "Rock_Shale_Cobble",
      "rotation": 17
    },
    {
      "x": -7,
      "y": 6,
      "z": 3,
      "name": "Rock_Shale_Cobble",
      "rotation": 17
    },
    {
      "x": -7,
      "y": 7,
      "z": 3,
      "name": "Rock_Shale_Cobble",
      "rotation": 17
    },
    {
      "x": -6,
      "y": 6,
      "z": -3,
      "name": "Metal_Iron_Glowing_Pipe",
      "support": 15,
      "rotation": 5
    },
    {
      "x": -6,
      "y": 3,
      "z": -2,
      "name": "Rock_Shale_Cobble",
      "rotation": 17
    },
    {
      "x": -6,
      "y": 4,
      "z": -2,
      "name": "Rock_Shale_Cobble",
      "rotation": 17
    },
    {
      "x": -6,
      "y": 5,
      "z": -2,
      "name": "Rock_Shale_Cobble",
      "rotation": 17
    },
    {
      "x": -6,
      "y": 6,
      "z": -2,
      "name": "Rock_Shale_Cobble",
      "rotation": 17
    },
    {
      "x": -6,
      "y": 2,
      "z": -1,
      "name": "Rock_Shale_Cobble_Half",
      "rotation": 35
    },
    {
      "x": -6,
      "y": 3,
      "z": -1,
      "name": "Rock_Shale_Cobble",
      "rotation": 17
    },
    {
      "x": -6,
      "y": 4,
      "z": -1,
      "name": "Rock_Shale_Cobble",
      "rotation": 17
    },
    {
      "x": -6,
      "y": 5,
      "z": -1,
      "name": "Rock_Shale_Cobble",
      "rotation": 17
    },
    {
      "x": -6,
      "y": 6,
      "z": -1,
      "name": "Rock_Shale_Cobble",
      "rotation": 17
    },
    {
      "x": -6,
      "y": 7,
      "z": -1,
      "name": "Rock_Shale_Brick_Smooth",
      "rotation": 1
    },
    {
      "x": -6,
      "y": 36,
      "z": -1,
      "name": "Rock_Shale_Cobble_Half",
      "rotation": 1
    },
    {
      "x": -6,
      "y": 3,
      "z": 0,
      "name": "Rock_Shale_Cobble",
      "rotation": 17
    },
    {
      "x": -6,
      "y": 4,
      "z": 0,
      "name": "Rock_Shale_Cobble",
      "rotation": 17
    },
    {
      "x": -6,
      "y": 5,
      "z": 0,
      "name": "Rock_Shale_Cobble",
      "rotation": 17
    },
    {
      "x": -6,
      "y": 6,
      "z": 0,
      "name": "Build_Lightsource_Cyan",
      "rotation": 1
    },
    {
      "x": -6,
      "y": 3,
      "z": 1,
      "name": "Rock_Shale_Cobble",
      "rotation": 17
    },
    {
      "x": -6,
      "y": 4,
      "z": 1,
      "name": "Rock_Shale_Cobble",
      "rotation": 17
    },
    {
      "x": -6,
      "y": 5,
      "z": 1,
      "name": "Rock_Shale_Cobble",
      "rotation": 17
    },
    {
      "x": -6,
      "y": 6,
      "z": 1,
      "name": "Build_Lightsource_Cyan",
      "rotation": 6
    },
    {
      "x": -6,
      "y": 2,
      "z": 2,
      "name": "Rock_Shale_Cobble_Half",
      "rotation": 35
    },
    {
      "x": -6,
      "y": 3,
      "z": 2,
      "name": "Rock_Shale_Cobble",
      "rotation": 17
    },
    {
      "x": -6,
      "y": 4,
      "z": 2,
      "name": "Rock_Shale_Cobble",
      "rotation": 17
    },
    {
      "x": -6,
      "y": 5,
      "z": 2,
      "name": "Rock_Shale_Cobble",
      "rotation": 17
    },
    {
      "x": -6,
      "y": 6,
      "z": 2,
      "name": "Rock_Shale_Cobble",
      "rotation": 17
    },
    {
      "x": -6,
      "y": 7,
      "z": 2,
      "name": "Rock_Shale_Brick_Smooth",
      "rotation": 1
    },
    {
      "x": -6,
      "y": 8,
      "z": 2,
      "name": "Plant_Moss_Rug_Green_Dark",
      "support": 15
    },
    {
      "x": -6,
      "y": 34,
      "z": 2,
      "name": "Rock_Shale_Cobble",
      "rotation": 4
    },
    {
      "x": -6,
      "y": 35,
      "z": 2,
      "name": "Rock_Shale_Cobble",
      "rotation": 4
    },
    {
      "x": -6,
      "y": 36,
      "z": 2,
      "name": "Rock_Shale_Cobble_Half",
      "rotation": 1
    },
    {
      "x": -6,
      "y": 3,
      "z": 3,
      "name": "Rock_Shale_Cobble",
      "rotation": 17
    },
    {
      "x": -6,
      "y": 4,
      "z": 3,
      "name": "Rock_Shale_Cobble",
      "rotation": 17
    },
    {
      "x": -6,
      "y": 5,
      "z": 3,
      "name": "Rock_Shale_Cobble",
      "rotation": 17
    },
    {
      "x": -6,
      "y": 6,
      "z": 3,
      "name": "Rock_Shale_Cobble",
      "rotation": 17
    },
    {
      "x": -6,
      "y": 7,
      "z": 3,
      "name": "Plant_Moss_Rug_Green_Dark",
      "support": 15
    },
    {
      "x": -6,
      "y": 34,
      "z": 3,
      "name": "Rock_Shale_Cobble",
      "rotation": 4
    },
    {
      "x": -6,
      "y": 35,
      "z": 3,
      "name": "Rock_Shale_Cobble",
      "rotation": 4
    },
    {
      "x": -6,
      "y": 6,
      "z": 4,
      "name": "Plant_Moss_Wall_Green_Dark",
      "support": 15
    },
    {
      "x": -5,
      "y": 6,
      "z": -3,
      "name": "Metal_Iron_Glowing_Pipe",
      "support": 15,
      "rotation": 5
    },
    {
      "x": -5,
      "y": 3,
      "z": -2,
      "name": "Rock_Shale_Cobble",
      "rotation": 17
    },
    {
      "x": -5,
      "y": 4,
      "z": -2,
      "name": "Rock_Shale_Cobble",
      "rotation": 17
    },
    {
      "x": -5,
      "y": 5,
      "z": -2,
      "name": "Rock_Shale_Cobble",
      "rotation": 17
    },
    {
      "x": -5,
      "y": 6,
      "z": -2,
      "name": "Rock_Shale_Cobble",
      "rotation": 17
    },
    {
      "x": -5,
      "y": 2,
      "z": -1,
      "name": "Rock_Shale_Cobble_Half",
      "rotation": 35
    },
    {
      "x": -5,
      "y": 3,
      "z": -1,
      "name": "Rock_Shale_Cobble",
      "rotation": 17
    },
    {
      "x": -5,
      "y": 4,
      "z": -1,
      "name": "Rock_Shale_Cobble",
      "rotation": 17
    },
    {
      "x": -5,
      "y": 5,
      "z": -1,
      "name": "Rock_Shale_Cobble",
      "rotation": 17
    },
    {
      "x": -5,
      "y": 6,
      "z": -1,
      "name": "Rock_Shale_Cobble",
      "rotation": 17
    },
    {
      "x": -5,
      "y": 7,
      "z": -1,
      "name": "Rock_Shale_Brick_Smooth",
      "rotation": 1
    },
    {
      "x": -5,
      "y": 8,
      "z": -1,
      "name": "Plant_Moss_Rug_Green_Dark",
      "support": 15
    },
    {
      "x": -5,
      "y": 36,
      "z": -1,
      "name": "Rock_Shale_Cobble_Half",
      "rotation": 1
    },
    {
      "x": -5,
      "y": 3,
      "z": 0,
      "name": "Rock_Shale_Cobble",
      "rotation": 17
    },
    {
      "x": -5,
      "y": 4,
      "z": 0,
      "name": "Rock_Shale_Cobble",
      "rotation": 17
    },
    {
      "x": -5,
      "y": 5,
      "z": 0,
      "name": "Rock_Shale_Cobble",
      "rotation": 17
    },
    {
      "x": -5,
      "y": 6,
      "z": 0,
      "name": "Build_Lightsource_Cyan",
      "rotation": 1
    },
    {
      "x": -5,
      "y": 3,
      "z": 1,
      "name": "Rock_Shale_Cobble",
      "rotation": 17
    },
    {
      "x": -5,
      "y": 4,
      "z": 1,
      "name": "Rock_Shale_Cobble",
      "rotation": 17
    },
    {
      "x": -5,
      "y": 5,
      "z": 1,
      "name": "Rock_Shale_Cobble",
      "rotation": 17
    },
    {
      "x": -5,
      "y": 6,
      "z": 1,
      "name": "Build_Lightsource_Cyan",
      "rotation": 6
    },
    {
      "x": -5,
      "y": 36,
      "z": 1,
      "name": "Plant_Moss_Rug_Green_Dark",
      "support": 15
    },
    {
      "x": -5,
      "y": 2,
      "z": 2,
      "name": "Rock_Shale_Cobble_Half",
      "rotation": 35
    },
    {
      "x": -5,
      "y": 3,
      "z": 2,
      "name": "Rock_Shale_Cobble",
      "rotation": 17
    },
    {
      "x": -5,
      "y": 4,
      "z": 2,
      "name": "Rock_Shale_Cobble",
      "rotation": 17
    },
    {
      "x": -5,
      "y": 5,
      "z": 2,
      "name": "Rock_Shale_Cobble",
      "rotation": 17
    },
    {
      "x": -5,
      "y": 6,
      "z": 2,
      "name": "Rock_Shale_Cobble",
      "rotation": 17
    },
    {
      "x": -5,
      "y": 7,
      "z": 2,
      "name": "Rock_Shale_Brick_Smooth",
      "rotation": 1
    },
    {
      "x": -5,
      "y": 34,
      "z": 2,
      "name": "Rock_Shale_Cobble",
      "rotation": 4
    },
    {
      "x": -5,
      "y": 35,
      "z": 2,
      "name": "Rock_Shale_Cobble",
      "rotation": 4
    },
    {
      "x": -5,
      "y": 36,
      "z": 2,
      "name": "Rock_Shale_Cobble_Half",
      "rotation": 1
    },
    {
      "x": -5,
      "y": 3,
      "z": 3,
      "name": "Rock_Shale_Cobble",
      "rotation": 17
    },
    {
      "x": -5,
      "y": 4,
      "z": 3,
      "name": "Rock_Shale_Cobble",
      "rotation": 17
    },
    {
      "x": -5,
      "y": 5,
      "z": 3,
      "name": "Rock_Shale_Cobble",
      "rotation": 17
    },
    {
      "x": -5,
      "y": 6,
      "z": 3,
      "name": "Rock_Shale_Cobble",
      "rotation": 17
    },
    {
      "x": -5,
      "y": 34,
      "z": 3,
      "name": "Rock_Shale_Cobble",
      "rotation": 4
    },
    {
      "x": -5,
      "y": 35,
      "z": 3,
      "name": "Rock_Shale_Cobble",
      "rotation": 4
    },
    {
      "x": -4,
      "y": 4,
      "z": -3,
      "name": "Metal_Iron_Glowing_Pipe_Corner",
      "support": 15,
      "rotation": 2
    },
    {
      "x": -4,
      "y": 5,
      "z": -3,
      "name": "Metal_Iron_Glowing_Pipe",
      "support": 15
    },
    {
      "x": -4,
      "y": 6,
      "z": -3,
      "name": "Metal_Iron_Glowing_Pipe_Corner",
      "support": 15,
      "rotation": 11
    },
    {
      "x": -4,
      "y": 3,
      "z": -2,
      "name": "Rock_Shale_Cobble",
      "rotation": 17
    },
    {
      "x": -4,
      "y": 4,
      "z": -2,
      "name": "Rock_Shale_Cobble",
      "rotation": 17
    },
    {
      "x": -4,
      "y": 5,
      "z": -2,
      "name": "Rock_Shale_Cobble",
      "rotation": 17
    },
    {
      "x": -4,
      "y": 6,
      "z": -2,
      "name": "Rock_Shale_Cobble",
      "rotation": 17
    },
    {
      "x": -4,
      "y": 7,
      "z": -2,
      "name": "Plant_Moss_Rug_Green_Dark",
      "support": 15
    },
    {
      "x": -4,
      "y": 35,
      "z": -2,
      "name": "Plant_Moss_Wall_Green_Dark",
      "support": 15,
      "rotation": 3
    },
    {
      "x": -4,
      "y": 36,
      "z": -2,
      "name": "Plant_Moss_Wall_Green_Dark",
      "support": 15,
      "rotation": 3
    },
    {
      "x": -4,
      "y": 2,
      "z": -1,
      "name": "Rock_Shale_Cobble_Half",
      "rotation": 35
    },
    {
      "x": -4,
      "y": 3,
      "z": -1,
      "name": "Rock_Shale_Cobble",
      "rotation": 17
    },
    {
      "x": -4,
      "y": 4,
      "z": -1,
      "name": "Rock_Shale_Cobble",
      "rotation": 17
    },
    {
      "x": -4,
      "y": 5,
      "z": -1,
      "name": "Rock_Shale_Cobble",
      "rotation": 17
    },
    {
      "x": -4,
      "y": 6,
      "z": -1,
      "name": "Rock_Shale_Cobble",
      "rotation": 17
    },
    {
      "x": -4,
      "y": 7,
      "z": -1,
      "name": "Rock_Shale_Brick_Smooth",
      "rotation": 1
    },
    {
      "x": -4,
      "y": 36,
      "z": -1,
      "name": "Rock_Shale_Cobble_Half",
      "rotation": 1
    },
    {
      "x": -4,
      "y": 3,
      "z": 0,
      "name": "Rock_Shale_Cobble",
      "rotation": 17
    },
    {
      "x": -4,
      "y": 4,
      "z": 0,
      "name": "Rock_Shale_Cobble",
      "rotation": 17
    },
    {
      "x": -4,
      "y": 5,
      "z": 0,
      "name": "Rock_Shale_Cobble",
      "rotation": 17
    },
    {
      "x": -4,
      "y": 6,
      "z": 0,
      "name": "Build_Lightsource_Cyan",
      "rotation": 1
    },
    {
      "x": -4,
      "y": 33,
      "z": 0,
      "name": "Rock_Shale_Cobble",
      "rotation": 5
    },
    {
      "x": -4,
      "y": 34,
      "z": 0,
      "name": "Rock_Shale_Cobble",
      "rotation": 4
    },
    {
      "x": -4,
      "y": 35,
      "z": 0,
      "name": "Rock_Shale_Cobble",
      "rotation": 4
    },
    {
      "x": -4,
      "y": 3,
      "z": 1,
      "name": "Rock_Shale_Cobble",
      "rotation": 17
    },
    {
      "x": -4,
      "y": 4,
      "z": 1,
      "name": "Rock_Shale_Cobble",
      "rotation": 17
    },
    {
      "x": -4,
      "y": 5,
      "z": 1,
      "name": "Rock_Shale_Cobble",
      "rotation": 17
    },
    {
      "x": -4,
      "y": 6,
      "z": 1,
      "name": "Build_Lightsource_Cyan",
      "rotation": 1
    },
    {
      "x": -4,
      "y": 33,
      "z": 1,
      "name": "Rock_Shale_Cobble",
      "rotation": 5
    },
    {
      "x": -4,
      "y": 34,
      "z": 1,
      "name": "Rock_Shale_Cobble",
      "rotation": 4
    },
    {
      "x": -4,
      "y": 35,
      "z": 1,
      "name": "Rock_Shale_Cobble",
      "rotation": 4
    },
    {
      "x": -4,
      "y": 36,
      "z": 1,
      "name": "Plant_Moss_Wall_Green_Dark",
      "support": 15,
      "rotation": 3
    },
    {
      "x": -4,
      "y": 2,
      "z": 2,
