{
  "version": 8,
  "blockIdVersion": 11,
  "anchorX": 0,
  "anchorY": 0,
  "anchorZ": 0,
  "blocks": [
    {
      "x": -8,
      "y": 6,
      "z": -6,
      "name": "Rock_Shale_Cobble",
      "rotation": 8
    },
    {
      "x": -8,
      "y": 7,
      "z": -6,
      "name": "Rock_Shale_Cobble",
      "rotation": 8
    },
    {
      "x": -8,
      "y": 6,
      "z": -5,
      "name": "Rock_Shale_Cobble_Half",
      "rotation": 24
    },
    {
      "x": -8,
      "y": 3,
      "z": -4,
      "name": "Rock_Shale_Cobble_Half",
      "rotation": 24
    },
    {
      "x": -8,
      "y": 6,
      "z": -4,
      "name": "Rock_Shale_Cobble_Half",
      "rotation": 24
    },
    {
      "x": -8,
      "y": 3,
      "z": -3,
      "name": "Rock_Shale_Cobble_Half",
      "rotation": 24
    },
    {
      "x": -8,
      "y": 4,
      "z": -3,
      "name": "Plant_Moss_Wall_Green_Dark",
      "rotation": 25
    },
    {
      "x": -8,
      "y": 6,
      "z": -3,
      "name": "Rock_Shale_Cobble_Half",
      "rotation": 24
    },
    {
      "x": -7,
      "y": 6,
      "z": -6,
      "name": "Rock_Shale_Cobble",
      "rotation": 8
    },
    {
      "x": -7,
      "y": 7,
      "z": -6,
      "name": "Rock_Shale_Cobble",
      "rotation": 8
    },
    {
      "x": -7,
      "y": 6,
      "z": -5,
      "name": "Rock_Shale_Cobble",
      "rotation": 8
    },
    {
      "x": -7,
      "y": 7,
      "z": -5,
      "name": "Rock_Shale_Cobble",
      "rotation": 8
    },
    {
      "x": -7,
      "y": 2,
      "z": -4,
      "name": "Rock_Shale_Cobble",
      "rotation": 8
    },
    {
      "x": -7,
      "y": 3,
      "z": -4,
      "name": "Rock_Shale_Cobble",
      "rotation": 8
    },
    {
      "x": -7,
      "y": 4,
      "z": -4,
      "name": "Rock_Shale_Cobble",
      "rotation": 8
    },
    {
      "x": -7,
      "y": 5,
      "z": -4,
      "name": "Rock_Shale_Cobble",
      "rotation": 8
    },
    {
      "x": -7,
      "y": 6,
      "z": -4,
      "name": "Rock_Shale_Cobble",
      "rotation": 8
    },
    {
      "x": -7,
      "y": 7,
      "z": -4,
      "name": "Rock_Shale_Cobble",
      "rotation": 8
    },
    {
      "x": -7,
      "y": 2,
      "z": -3,
      "name": "Rock_Shale_Cobble",
      "rotation": 8
    },
    {
      "x": -7,
      "y": 3,
      "z": -3,
      "name": "Rock_Shale_Cobble",
      "rotation": 8
    },
    {
      "x": -7,
      "y": 4,
      "z": -3,
      "name": "Rock_Shale_Cobble",
      "rotation": 8
    },
    {
      "x": -7,
      "y": 5,
      "z": -3,
      "name": "Rock_Shale_Cobble",
      "rotation": 8
    },
    {
      "x": -7,
      "y": 6,
      "z": -3,
      "name": "Rock_Shale_Cobble",
      "rotation": 8
    },
    {
      "x": -7,
      "y": 7,
      "z": -3,
      "name": "Rock_Shale_Cobble",
      "rotation": 8
    },
    {
      "x": -7,
      "y": 8,
      "z": -3,
      "name": "Plant_Moss_Wall_Green_Dark",
      "rotation": 14
    },
    {
      "x": -7,
      "y": 3,
      "z": -2,
      "name": "Rock_Shale_Cobble_Half",
      "rotation": 24
    },
    {
      "x": -7,
      "y": 4,
      "z": -2,
      "name": "Plant_Moss_Rug_Green_Dark",
      "rotation": 4
    },
    {
      "x": -7,
      "y": 6,
      "z": -2,
      "name": "Rock_Shale_Cobble_Half",
      "rotation": 24
    },
    {
      "x": -7,
      "y": 7,
      "z": -2,
      "name": "Plant_Moss_Rug_Green_Dark",
      "rotation": 4
    },
    {
      "x": -7,
      "y": 1,
      "z": -1,
      "name": "Metal_Iron_Glowing_Pipe_Corner",
      "rotation": 25
    },
    {
      "x": -7,
      "y": 3,
      "z": -1,
      "name": "Rock_Shale_Cobble_Half",
      "rotation": 24
    },
    {
      "x": -7,
      "y": 6,
      "z": -1,
      "name": "Rock_Shale_Cobble_Half",
      "rotation": 24
    },
    {
      "x": -7,
      "y": 1,
      "z": 0,
      "name": "Metal_Iron_Glowing_Pipe_Corner"
    },
    {
      "x": -7,
      "y": 2,
      "z": 0,
      "name": "Metal_Iron_Glowing_Pipe",
      "rotation": 8
    },
    {
      "x": -7,
      "y": 3,
      "z": 0,
      "name": "Metal_Iron_Glowing_Pipe",
      "rotation": 8
    },
    {
      "x": -7,
      "y": 4,
      "z": 0,
      "name": "Metal_Iron_Glowing_Pipe",
      "rotation": 8
    },
    {
      "x": -7,
      "y": 5,
      "z": 0,
      "name": "Metal_Iron_Glowing_Pipe_Corner",
      "rotation": 14
    },
    {
      "x": -7,
      "y": 5,
      "z": 1,
      "name": "Metal_Iron_Glowing_Pipe_Corner",
      "rotation": 6
    },
    {
      "x": -7,
      "y": 6,
      "z": 1,
      "name": "Metal_Iron_Glowing_Pipe",
      "rotation": 8
    },
    {
      "x": -7,
      "y": 7,
      "z": 1,
      "name": "Metal_Iron_Glowing_Pipe_Corner",
      "rotation": 15
    },
    {
      "x": -6,
      "y": 3,
      "z": -7,
      "name": "Rock_Shale_Cobble",
      "rotation": 2
    },
    {
      "x": -6,
      "y": 4,
      "z": -7,
      "name": "Rock_Shale_Cobble",
      "rotation": 2
    },
    {
      "x": -6,
      "y": 5,
      "z": -7,
      "name": "Rock_Shale_Cobble",
      "rotation": 2
    },
    {
      "x": -6,
      "y": 3,
      "z": -6,
      "name": "Rock_Shale_Cobble",
      "rotation": 8
    },
    {
      "x": -6,
      "y": 4,
      "z": -6,
      "name": "Rock_Shale_Cobble",
      "rotation": 8
    },
    {
      "x": -6,
      "y": 5,
      "z": -6,
      "name": "Rock_Shale_Cobble",
      "rotation": 8
    },
    {
      "x": -6,
      "y": 6,
      "z": -6,
      "name": "Rock_Shale_Cobble",
      "rotation": 8
    },
    {
      "x": -6,
      "y": 7,
      "z": -6,
      "name": "Deko_Block_Test",
      "rotation": 2
    },
    {
      "x": -6,
      "y": 3,
      "z": -5,
      "name": "Rock_Shale_Cobble",
      "rotation": 8
    },
    {
      "x": -6,
      "y": 4,
      "z": -5,
      "name": "Rock_Shale_Cobble",
      "rotation": 8
    },
    {
      "x": -6,
      "y": 5,
      "z": -5,
      "name": "Rock_Shale_Cobble",
      "rotation": 8
    },
    {
      "x": -6,
      "y": 6,
      "z": -5,
      "name": "Rock_Shale_Cobble",
      "rotation": 8
    },
    {
      "x": -6,
      "y": 7,
      "z": -5,
      "name": "Rock_Shale_Cobble",
      "rotation": 8
    },
    {
      "x": -6,
      "y": 2,
      "z": -4,
      "name": "Rock_Shale_Cobble",
      "rotation": 8
    },
    {
      "x": -6,
      "y": 3,
      "z": -4,
      "name": "Rock_Shale_Cobble",
      "rotation": 8
    },
    {
      "x": -6,
      "y": 4,
      "z": -4,
      "name": "Rock_Shale_Cobble",
      "rotation": 8
    },
    {
      "x": -6,
      "y": 5,
      "z": -4,
      "name": "Rock_Shale_Cobble",
      "rotation": 8
    },
    {
      "x": -6,
      "y": 6,
      "z": -4,
      "name": "Rock_Shale_Cobble",
      "rotation": 8
    },
    {
      "x": -6,
      "y": 7,
      "z": -4,
      "name": "Rock_Shale_Cobble",
      "rotation": 8
    },
    {
      "x": -6,
      "y": 1,
      "z": -3,
      "name": "Metal_Iron_Glowing_Pipe_Corner",
      "rotation": 25
    },
    {
      "x": -6,
      "y": 2,
      "z": -3,
      "name": "Rock_Shale_Cobble",
      "rotation": 8
    },
    {
      "x": -6,
      "y": 3,
      "z": -3,
      "name": "Rock_Shale_Cobble",
      "rotation": 8
    },
    {
      "x": -6,
      "y": 4,
      "z": -3,
      "name": "Rock_Shale_Cobble",
      "rotation": 8
    },
    {
      "x": -6,
      "y": 5,
      "z": -3,
      "name": "Rock_Shale_Cobble",
      "rotation": 8
    },
    {
      "x": -6,
      "y": 6,
      "z": -3,
      "name": "Rock_Shale_Cobble",
      "rotation": 8
    },
    {
      "x": -6,
      "y": 7,
      "z": -3,
      "name": "Rock_Shale_Cobble",
      "rotation": 8
    },
    {
      "x": -6,
      "y": 1,
      "z": -2,
      "name": "Metal_Iron_Glowing_Pipe",
      "rotation": 4
    },
    {
      "x": -6,
      "y": 2,
      "z": -2,
      "name": "Rock_Shale_Cobble",
      "rotation": 8
    },
    {
      "x": -6,
      "y": 3,
      "z": -2,
      "name": "Rock_Shale_Cobble",
      "rotation": 8
    },
    {
      "x": -6,
      "y": 4,
      "z": -2,
      "name": "Rock_Shale_Cobble",
      "rotation": 8
    },
    {
      "x": -6,
      "y": 5,
      "z": -2,
      "name": "Rock_Shale_Cobble",
      "rotation": 8
    },
    {
      "x": -6,
      "y": 6,
      "z": -2,
      "name": "Rock_Shale_Cobble",
      "rotation": 8
    },
    {
      "x": -6,
      "y": 7,
      "z": -2,
      "name": "Rock_Shale_Cobble",
      "rotation": 8
    },
    {
      "x": -6,
      "y": 1,
      "z": -1,
      "name": "Metal_Iron_Glowing_Pipe_Corner",
      "rotation": 27
    },
    {
      "x": -6,
      "y": 2,
      "z": -1,
      "name": "Rock_Shale_Cobble",
      "rotation": 8
    },
    {
      "x": -6,
      "y": 3,
      "z": -1,
      "name": "Rock_Shale_Cobble",
      "rotation": 8
    },
    {
      "x": -6,
      "y": 4,
      "z": -1,
      "name": "Rock_Shale_Cobble",
      "rotation": 8
    },
    {
      "x": -6,
      "y": 5,
      "z": -1,
      "name": "Rock_Shale_Cobble",
      "rotation": 8
    },
    {
      "x": -6,
      "y": 6,
      "z": -1,
      "name": "Rock_Shale_Cobble",
      "rotation": 8
    },
    {
      "x": -6,
      "y": 7,
      "z": -1,
      "name": "Rock_Shale_Cobble",
      "rotation": 8
    },
    {
      "x": -6,
      "y": 2,
      "z": 0,
      "name": "Plant_Moss_Wall_Green_Dark",
      "rotation": 25
    },
    {
      "x": -6,
      "y": 3,
      "z": 0,
      "name": "Rock_Shale_Cobble_Half",
      "rotation": 24
    },
    {
      "x": -6,
      "y": 4,
      "z": 0,
      "name": "Plant_Moss_Rug_Green_Dark",
      "rotation": 4
    },
    {
      "x": -6,
      "y": 6,
      "z": 0,
      "name": "Rock_Shale_Cobble_Half",
      "rotation": 24
    },
    {
      "x": -6,
      "y": 2,
      "z": 1,
      "name": "Plant_Moss_Wall_Green_Dark",
      "rotation": 25
    },
    {
      "x": -6,
      "y": 3,
      "z": 1,
      "name": "Rock_Shale_Cobble_Half",
      "rotation": 24
    },
    {
      "x": -6,
      "y": 6,
      "z": 1,
      "name": "Rock_Shale_Cobble_Half",
      "rotation": 24
    },
    {
      "x": -6,
      "y": 7,
      "z": 1,
      "name": "Metal_Iron_Glowing_Pipe_Corner",
      "rotation": 7
    },
    {
      "x": -6,
      "y": 8,
      "z": 1,
      "name": "Metal_Iron_Glowing_Pipe_Corner",
      "rotation": 15
    },
    {
      "x": -5,
      "y": 3,
      "z": -7,
      "name": "Build_Lightsource_Cyan",
      "rotation": 18
    },
    {
      "x": -5,
      "y": 4,
      "z": -7,
      "name": "Build_Lightsource_Cyan",
      "rotation": 25
    },
    {
      "x": -5,
      "y": 5,
      "z": -7,
      "name": "Build_Lightsource_Cyan",
      "rotation": 25
    },
    {
      "x": -5,
      "y": 3,
      "z": -6,
      "name": "Rock_Shale_Cobble",
      "rotation": 17
    },
    {
      "x": -5,
      "y": 4,
      "z": -6,
      "name": "Build_Lightsource_Cyan",
      "rotation": 3
    },
    {
      "x": -5,
      "y": 5,
      "z": -6,
      "name": "Build_Lightsource_Cyan",
      "rotation": 18
    },
    {
      "x": -5,
      "y": 3,
      "z": -5,
      "name": "Rock_Shale_Cobble",
      "rotation": 8
    },
    {
      "x": -5,
      "y": 4,
      "z": -5,
      "name": "Rock_Shale_Cobble",
      "rotation": 8
    },
    {
      "x": -5,
      "y": 5,
      "z": -5,
      "name": "Rock_Shale_Cobble",
      "rotation": 8
    },
    {
      "x": -5,
      "y": 1,
      "z": -4,
      "name": "Metal_Iron_Glowing_Pipe",
      "rotation": 4
    },
    {
      "x": -5,
      "y": 2,
      "z": -4,
      "name": "Rock_Shale_Cobble",
      "rotation": 8
    },
    {
      "x": -5,
      "y": 3,
      "z": -4,
      "name": "Rock_Shale_Cobble",
      "rotation": 8
    },
    {
      "x": -5,
      "y": 4,
      "z": -4,
      "name": "Rock_Shale_Cobble",
      "rotation": 8
    },
    {
      "x": -5,
      "y": 5,
      "z": -4,
      "name": "Rock_Shale_Cobble",
      "rotation": 8
    },
    {
      "x": -5,
      "y": 6,
      "z": -4,
      "name": "Rock_Shale_Cobble",
      "rotation": 8
    },
    {
      "x": -5,
      "y": 7,
      "z": -4,
      "name": "Rock_Shale_Cobble",
      "rotation": 8
    },
    {
      "x": -5,
      "y": 1,
      "z": -3,
      "name": "Metal_Iron_Glowing_Pipe_Corner",
      "rotation": 16
    },
    {
      "x": -5,
      "y": 2,
      "z": -3,
      "name": "Rock_Shale_Cobble",
      "rotation": 8
    },
    {
      "x": -5,
      "y": 3,
      "z": -3,
      "name": "Rock_Shale_Cobble",
      "rotation": 8
    },
    {
      "x": -5,
      "y": 4,
      "z": -3,
      "name": "Rock_Shale_Cobble",
      "rotation": 8
    },
    {
      "x": -5,
      "y": 5,
      "z": -3,
      "name": "Rock_Shale_Cobble",
      "rotation": 8
    },
    {
      "x": -5,
      "y": 6,
      "z": -3,
      "name": "Rock_Shale_Cobble",
      "rotation": 8
    },
    {
      "x": -5,
      "y": 7,
      "z": -3,
      "name": "Rock_Shale_Cobble",
      "rotation": 8
    },
    {
      "x": -5,
      "y": 2,
      "z": -2,
      "name": "Rock_Shale_Cobble",
      "rotation": 8
    },
    {
      "x": -5,
      "y": 3,
      "z": -2,
      "name": "Rock_Shale_Cobble",
      "rotation": 8
    },
    {
      "x": -5,
      "y": 4,
      "z": -2,
      "name": "Rock_Shale_Cobble",
      "rotation": 8
    },
    {
      "x": -5,
      "y": 5,
      "z": -2,
      "name": "Rock_Shale_Cobble",
      "rotation": 8
    },
    {
      "x": -5,
      "y": 6,
      "z": -2,
      "name": "Rock_Shale_Cobble",
      "rotation": 8
    },
    {
      "x": -5,
      "y": 7,
      "z": -2,
      "name": "Rock_Shale_Cobble",
      "rotation": 8
    },
    {
      "x": -5,
      "y": 2,
      "z": -1,
      "name": "Rock_Shale_Cobble",
      "rotation": 8
    },
    {
      "x": -5,
      "y": 3,
      "z": -1,
      "name": "Rock_Shale_Cobble",
      "rotation": 8
    },
    {
      "x": -5,
      "y": 4,
      "z": -1,
      "name": "Rock_Shale_Cobble",
      "rotation": 8
    },
    {
      "x": -5,
      "y": 5,
      "z": -1,
      "name": "Rock_Shale_Cobble",
      "rotation": 8
    },
    {
      "x": -5,
      "y": 6,
      "z": -1,
      "name": "Rock_Shale_Cobble",
      "rotation": 8
    },
    {
      "x": -5,
      "y": 7,
      "z": -1,
      "name": "Rock_Shale_Cobble",
      "rotation": 8
    },
    {
      "x": -5,
      "y": 2,
      "z": 0,
      "name": "Rock_Shale_Cobble",
      "rotation": 8
    },
    {
      "x": -5,
      "y": 3,
      "z": 0,
      "name": "Rock_Shale_Cobble",
      "rotation": 8
    },
    {
      "x": -5,
      "y": 4,
      "z": 0,
      "name": "Rock_Shale_Cobble",
      "rotation": 8
    },
    {
      "x": -5,
      "y": 5,
      "z": 0,
      "name": "Rock_Shale_Cobble",
      "rotation": 8
    },
    {
      "x": -5,
      "y": 6,
      "z": 0,
      "name": "Rock_Shale_Cobble",
      "rotation": 8
    },
    {
      "x": -5,
      "y": 7,
      "z": 0,
      "name": "Rock_Shale_Cobble",
      "rotation": 8
    },
    {
      "x": -5,
      "y": 1,
      "z": 1,
      "name": "Plant_Moss_Wall_Green_Dark",
      "rotation": 4
    },
    {
      "x": -5,
      "y": 2,
      "z": 1,
      "name": "Rock_Shale_Cobble",
      "rotation": 8
    },
    {
      "x": -5,
      "y": 3,
      "z": 1,
      "name": "Rock_Shale_Cobble",
      "rotation": 8
    },
    {
      "x": -5,
      "y": 4,
      "z": 1,
      "name": "Rock_Shale_Cobble",
      "rotation": 8
    },
    {
      "x": -5,
      "y": 5,
      "z": 1,
      "name": "Rock_Shale_Cobble",
      "rotation": 8
    },
    {
      "x": -5,
      "y": 6,
      "z": 1,
      "name": "Rock_Shale_Cobble",
      "rotation": 8
    },
    {
      "x": -5,
      "y": 7,
      "z": 1,
      "name": "Rock_Shale_Cobble",
      "rotation": 8
    },
    {
      "x": -5,
      "y": 8,
      "z": 1,
      "name": "Metal_Iron_Glowing_Pipe",
      "rotation": 18
    },
    {
      "x": -5,
      "y": 2,
      "z": 2,
      "name": "Plant_Moss_Rug_Green_Dark",
      "rotation": 4
    },
    {
      "x": -5,
      "y": 3,
      "z": 2,
      "name": "Rock_Shale_Cobble_Half",
      "rotation": 24
    },
    {
      "x": -5,
      "y": 4,
      "z": 2,
      "name": "Plant_Moss_Wall_Green_Dark",
      "rotation": 25
    },
    {
      "x": -5,
      "y": 6,
      "z": 2,
      "name": "Rock_Shale_Cobble_Half",
      "rotation": 24
    },
    {
      "x": -4,
      "y": 6,
      "z": -7,
      "name": "Rock_Shale_Cobble",
      "rotation": 24
    },
    {
      "x": -4,
      "y": 7,
      "z": -7,
      "name": "Rock_Shale_Cobble",
      "rotation": 24
    },
    {
      "x": -4,
      "y": 8,
      "z": -7,
      "name": "Rock_Shale_Brick_Smooth",
      "rotation": 17
    },
    {
      "x": -4,
      "y": 6,
      "z": -6,
      "name": "Rock_Shale_Brick_Smooth",
      "rotation": 17
    },
    {
      "x": -4,
      "y": 6,
      "z": -5,
      "name": "Rock_Shale_Cobble",
      "rotation": 8
    },
    {
      "x": -4,
      "y": 7,
      "z": -5,
      "name": "Rock_Shale_Cobble",
      "rotation": 8
    },
    {
      "x": -4,
      "y": 2,
      "z": -4,
      "name": "Rock_Shale_Cobble",
      "rotation": 8
    },
    {
      "x": -4,
      "y": 3,
      "z": -4,
      "name": "Rock_Shale_Cobble",
      "rotation": 8
    },
    {
      "x": -4,
      "y": 4,
      "z": -4,
      "name": "Build_Lightsource_Cyan",
      "rotation": 3
    },
    {
      "x": -4,
      "y": 5,
      "z": -4,
      "name": "Build_Lightsource_Cyan",
      "rotation": 18
    },
    {
      "x": -4,
      "y": 6,
      "z": -4,
      "name": "Rock_Shale_Cobble",
      "rotation": 8
    },
    {
      "x": -4,
      "y": 7,
      "z": -4,
      "name": "Rock_Shale_Cobble",
      "rotation": 8
    },
    {
      "x": -4,
      "y": 2,
      "z": -3,
      "name": "Rock_Shale_Cobble",
      "rotation": 8
    },
    {
      "x": -4,
      "y": 3,
      "z": -3,
      "name": "Rock_Shale_Cobble",
      "rotation": 8
    },
    {
      "x": -4,
      "y": 4,
      "z": -3,
      "name": "Build_Lightsource_Cyan",
      "rotation": 3
    },
    {
      "x": -4,
      "y": 5,
      "z": -3,
      "name": "Build_Lightsource_Cyan",
      "rotation": 18
    },
    {
      "x": -4,
      "y": 6,
      "z": -3,
      "name": "Rock_Shale_Cobble",
      "rotation": 8
    },
    {
      "x": -4,
      "y": 7,
      "z": -3,
      "name": "Rock_Shale_Cobble",
      "rotation": 8
    },
    {
      "x": -4,
      "y": 2,
      "z": -2,
      "name": "Rock_Shale_Cobble",
      "rotation": 8
    },
    {
      "x": -4,
      "y": 3,
      "z": -2,
      "name": "Rock_Shale_Cobble",
      "rotation": 8
    },
    {
      "x": -4,
      "y": 4,
      "z": -2,
      "name": "Rock_Shale_Cobble",
      "rotation": 8
    },
    {
      "x": -4,
      "y": 5,
      "z": -2,
      "name": "Rock_Shale_Cobble",
      "rotation": 8
    },
    {
      "x": -4,
      "y": 6,
      "z": -2,
      "name": "Rock_Shale_Cobble",
      "rotation": 8
    },
    {
      "x": -4,
      "y": 7,
      "z": -2,
      "name": "Rock_Shale_Cobble",
      "rotation": 8
    },
    {
      "x": -4,
      "y": 2,
      "z": -1,
      "name": "Rock_Shale_Cobble",
      "rotation": 8
    },
    {
      "x": -4,
      "y": 3,
      "z": -1,
      "name": "Rock_Shale_Cobble",
      "rotation": 8
    },
    {
      "x": -4,
      "y": 4,
      "z": -1,
      "name": "Rock_Shale_Cobble",
      "rotation": 8
    },
    {
      "x": -4,
      "y": 5,
      "z": -1,
      "name": "Rock_Shale_Cobble",
      "rotation": 8
    },
    {
      "x": -4,
      "y": 6,
      "z": -1,
      "name": "Rock_Shale_Cobble",
      "rotation": 8
    },
    {
      "x": -4,
      "y": 7,
      "z": -1,
      "name": "Rock_Shale_Cobble",
      "rotation": 8
    },
    {
      "x": -4,
      "y": 2,
      "z": 0,
      "name": "Rock_Shale_Cobble",
      "rotation": 8
    },
    {
      "x": -4,
      "y": 3,
      "z": 0,
      "name": "Rock_Shale_Cobble",
      "rotation": 8
    },
    {
      "x": -4,
      "y": 4,
      "z": 0,
      "name": "Rock_Shale_Cobble",
      "rotation": 8
    },
    {
      "x": -4,
      "y": 5,
      "z": 0,
      "name": "Rock_Shale_Cobble",
      "rotation": 8
    },
    {
      "x": -4,
      "y": 6,
      "z": 0,
      "name": "Rock_Shale_Cobble",
      "rotation": 8
    },
    {
      "x": -4,
      "y": 7,
      "z": 0,
      "name": "Rock_Shale_Cobble",
      "rotation": 8
    },
    {
      "x": -4,
      "y": 2,
      "z": 1,
      "name": "Rock_Shale_Cobble",
      "rotation": 8
    },
    {
      "x": -4,
      "y": 3,
      "z": 1,
      "name": "Rock_Shale_Cobble",
      "rotation": 8
    },
    {
      "x": -4,
      "y": 4,
      "z": 1,
      "name": "Rock_Shale_Cobble",
      "rotation": 8
    },
    {
      "x": -4,
      "y": 5,
      "z": 1,
      "name": "Rock_Shale_Cobble",
      "rotation": 8
    },
    {
      "x": -4,
      "y": 6,
      "z": 1,
      "name": "Rock_Shale_Cobble",
      "rotation": 8
    },
    {
      "x": -4,
      "y": 7,
      "z": 1,
      "name": "Rock_Shale_Cobble",
      "rotation": 8
    },
    {
      "x": -4,
      "y": 8,
      "z": 1,
      "name": "Metal_Iron_Glowing_Pipe",
      "rotation": 18
    },
    {
      "x": -4,
      "y": 2,
      "z": 2,
      "name": "Rock_Shale_Cobble",
      "rotation": 8
    },
    {
      "x": -4,
      "y": 3,
      "z": 2,
      "name": "Rock_Shale_Cobble",
      "rotation": 8
    },
    {
      "x": -4,
      "y": 4,
      "z": 2,
      "name": "Rock_Shale_Cobble",
      "rotation": 8
    },
    {
      "x": -4,
      "y": 5,
      "z": 2,
      "name": "Rock_Shale_Cobble",
      "rotation": 8
    },
    {
      "x": -4,
      "y": 6,
      "z": 2,
      "name": "Rock_Shale_Cobble",
      "rotation": 8
    },
    {
      "x": -4,
      "y": 7,
      "z": 2,
      "name": "Rock_Shale_Cobble",
      "rotation": 8
    },
    {
      "x": -4,
      "y": 3,
      "z": 3,
      "name": "Rock_Shale_Cobble_Half",
      "rotation": 24
    },
    {
      "x": -4,
      "y": 4,
      "z": 3,
      "name": "Plant_Moss_Rug_Green_Dark",
      "rotation": 4
    },
    {
      "x": -4,
      "y": 5,
      "z": 3,
      "name": "Plant_Moss_Rug_Green_Dark",
      "rotation": 4
    },
    {
      "x": -4,
      "y": 6,
      "z": 3,
      "name": "Rock_Shale_Cobble_Half",
      "rotation": 24
    },
    {
      "x": -3,
      "y": 6,
      "z": -7,
      "name": "Rock_Shale_Brick_Smooth",
      "rotation": 17
    },
    {
      "x": -3,
      "y": 7,
      "z": -7,
      "name": "Rock_Shale_Brick_Smooth",
      "rotation": 17
    },
    {
      "x": -3,
      "y": 7,
      "z": -6,
      "name": "Plant_Moss_Rug_Green_Dark",
      "rotation": 4
    },
    {
      "x": -3,
      "y": 6,
      "z": -5,
      "name": "Rock_Shale_Brick_Smooth",
      "rotation": 17
    },
    {
      "x": -3,
      "y": 3,
      "z": -4,
      "name": "Rock_Shale_Brick_Smooth",
      "rotation": 17
    },
    {
      "x": -3,
      "y": 6,
      "z": -4,
      "name": "Rock_Shale_Brick_Smooth",
      "rotation": 17
    },
    {
      "x": -3,
      "y": 3,
      "z": -3,
      "name": "Rock_Shale_Brick_Smooth",
      "rotation": 17
    },
    {
      "x": -3,
      "y": 6,
      "z": -3,
      "name": "Rock_Shale_Brick_Smooth",
      "rotation": 17
    },
    {
      "x": -3,
      "y": 2,
      "z": -2,
      "name": "Rock_Shale_Cobble",
      "rotation": 8
    },
    {
      "x": -3,
      "y": 3,
      "z": -2,
      "name": "Rock_Shale_Cobble",
      "rotation": 8
    },
    {
      "x": -3,
      "y": 4,
      "z": -2,
      "name": "Build_Lightsource_Cyan",
      "rotation": 19
    },
    {
      "x": -3,
      "y": 5,
      "z": -2,
      "name": "Build_Lightsource_Cyan",
      "rotation": 19
    },
    {
      "x": -3,
      "y": 6,
      "z": -2,
      "name": "Rock_Shale_Cobble",
      "rotation": 8
    },
    {
      "x": -3,
      "y": 7,
      "z": -2,
      "name": "Rock_Shale_Cobble",
      "rotation": 8
    },
    {
      "x": -3,
      "y": 2,
      "z": -1,
      "name": "Rock_Shale_Cobble",
      "rotation": 8
    },
    {
      "x": -3,
      "y": 3,
      "z": -1,
      "name": "Rock_Shale_Cobble",
      "rotation": 8
    },
    {
      "x": -3,
      "y": 4,
      "z": -1,
      "name": "Build_Lightsource_Cyan",
      "rotation": 18
    },
    {
      "x": -3,
      "y": 5,
      "z": -1,
      "name": "Build_Lightsource_Cyan",
      "rotation": 19
    },
    {
      "x": -3,
      "y": 6,
      "z": -1,
      "name": "Rock_Shale_Cobble",
      "rotation": 8
    },
    {
      "x": -3,
      "y": 7,
      "z": -1,
      "name": "Rock_Shale_Cobble",
      "rotation": 8
    },
    {
      "x": -3,
      "y": 2,
      "z": 0,
      "name": "Rock_Shale_Cobble",
      "rotation": 8
    },
    {
      "x": -3,
      "y": 3,
      "z": 0,
      "name": "Rock_Shale_Cobble",
      "rotation": 8
    },
    {
      "x": -3,
      "y": 4,
      "z": 0,
      "name": "Rock_Shale_Cobble",
      "rotation": 8
    },
    {
      "x": -3,
      "y": 5,
      "z": 0,
      "name": "Rock_Shale_Cobble",
      "rotation": 8
    },
    {
      "x": -3,
      "y": 6,
      "z": 0,
      "name": "Rock_Shale_Cobble",
      "rotation": 8
    },
    {
      "x": -3,
      "y": 7,
      "z": 0,
      "name": "Rock_Shale_Cobble",
      "rotation": 8
    },
    {
      "x": -3,
      "y": 2,
      "z": 1,
      "name": "Rock_Shale_Cobble",
      "rotation": 8
    },
    {
      "x": -3,
      "y": 3,
      "z": 1,
      "name": "Rock_Shale_Cobble",
      "rotation": 8
    },
    {
      "x": -3,
      "y": 4,
      "z": 1,
      "name": "Rock_Shale_Cobble",
      "rotation": 8
    },
    {
      "x": -3,
      "y": 5,
      "z": 1,
      "name": "Rock_Shale_Cobble",
      "rotation": 8
    },
    {
      "x": -3,
      "y": 6,
      "z": 1,
      "name": "Rock_Shale_Cobble",
      "rotation": 8
    },
    {
      "x": -3,
      "y": 7,
      "z": 1,
      "name": "Rock_Shale_Cobble",
      "rotation": 8
    },
    {
      "x": -3,
      "y": 8,
      "z": 1,
      "name": "Metal_Iron_Glowing_Pipe_Corner",
      "rotation": 17
    },
    {
      "x": -3,
      "y": 2,
      "z": 2,
      "name": "Rock_Shale_Cobble",
      "rotation": 8
    },
    {
      "x": -3,
      "y": 3,
      "z": 2,
      "name": "Rock_Shale_Cobble",
      "rotation": 8
    },
    {
      "x": -3,
      "y": 4,
      "z": 2,
      "name": "Rock_Shale_Cobble",
      "rotation": 8
    },
    {
      "x": -3,
      "y": 5,
      "z": 2,
      "name": "Rock_Shale_Cobble",
      "rotation": 8
    },
    {
      "x": -3,
      "y": 6,
      "z": 2,
      "name": "Rock_Shale_Cobble",
      "rotation": 8
    },
    {
      "x": -3,
      "y": 7,
      "z": 2,
      "name": "Rock_Shale_Cobble",
      "rotation": 8
    },
    {
      "x": -3,
      "y": 8,
      "z": 2,
      "name": "Metal_Iron_Glowing_Pipe_Corner",
      "rotation": 26
    },
    {
      "x": -3,
      "y": 2,
      "z": 3,
      "name": "Rock_Shale_Cobble",
      "rotation": 8
    },
    {
      "x": -3,
      "y": 3,
      "z": 3,
      "name": "Rock_Shale_Cobble",
      "rotation": 8
    },
    {
      "x": -3,
      "y": 4,
      "z": 3,
      "name": "Rock_Shale_Cobble",
      "rotation": 8
    },
    {
      "x": -3,
      "y": 5,
      "z": 3,
      "name": "Rock_Shale_Cobble",
      "rotation": 8
    },
    {
      "x": -3,
      "y": 6,
      "z": 3,
      "name": "Rock_Shale_Cobble",
      "rotation": 8
    },
    {
      "x": -3,
      "y": 7,
      "z": 3,
      "name": "Rock_Shale_Cobble",
      "rotation": 8
    },
    {
      "x": -3,
      "y": 2,
      "z": 4,
      "name": "Plant_Moss_Wall_Green_Dark",
      "rotation": 25
    },
    {
      "x": -3,
      "y": 3,
      "z": 4,
      "name": "Rock_Shale_Cobble_Half",
      "rotation": 17
    },
    {
      "x": -3,
      "y": 6,
      "z": 4,
      "name": "Rock_Shale_Cobble_Half",
      "rotation": 17
    },
    {
      "x": -3,
      "y": 7,
      "z": 4,
      "name": "Plant_Moss_Rug_Green_Dark",
      "rotation": 4
    },
    {
      "x": -2,
      "y": 3,
      "z": -2,
      "name": "Rock_Shale_Brick_Smooth",
      "rotation": 17
    },
    {
      "x": -2,
      "y": 6,
      "z": -2,
      "name": "Rock_Shale_Brick_Smooth",
      "rotation": 17
    },
    {
      "x": -2,
      "y": 3,
      "z": -1,
      "name": "Rock_Shale_Brick_Smooth",
      "rotation": 17
    },
    {
      "x": -2,
      "y": 6,
      "z": -1,
      "name": "Rock_Shale_Brick_Smooth",
      "rotation": 17
    },
    {
      "x": -2,
      "y": 2,
      "z": 0,
      "name": "Rock_Shale_Cobble",
      "rotation": 8
    },
    {
      "x": -2,
      "y": 3,
      "z": 0,
      "name": "Rock_Shale_Cobble",
      "rotation": 8
    },
    {
      "x": -2,
      "y": 4,
      "z": 0,
      "name": "Build_Lightsource_Cyan",
      "rotation": 19
    },
    {
      "x": -2,
      "y": 5,
      "z": 0,
      "name": "Build_Lightsource_Cyan",
      "rotation": 18
    },
    {
      "x": -2,
      "y": 6,
      "z": 0,
      "name": "Rock_Shale_Cobble",
      "rotation": 8
    },
    {
      "x": -2,
      "y": 7,
      "z": 0,
      "name": "Rock_Shale_Cobble",
      "rotation": 8
    },
    {
      "x": -2,
      "y": 2,
      "z": 1,
      "name": "Rock_Shale_Cobble",
      "rotation": 8
    },
    {
      "x": -2,
      "y": 3,
      "z": 1,
      "name": "Rock_Shale_Cobble",
      "rotation": 8
    },
    {
      "x": -2,
      "y": 4,
      "z": 1,
      "name": "Rock_Shale_Cobble",
      "rotation": 8
    },
    {
      "x": -2,
      "y": 5,
      "z": 1,
      "name": "Build_Lightsource_Cyan",
      "rotation": 19
    },
    {
      "x": -2,
      "y": 6,
      "z": 1,
      "name": "Rock_Shale_Cobble",
      "rotation": 8
    },
    {
      "x": -2,
      "y": 7,
      "z": 1,
      "name": "Rock_Shale_Cobble",
      "rotation": 8
    },
    {
      "x": -2,
      "y": 2,
      "z": 2,
      "name": "Rock_Shale_Cobble",
      "rotation": 8
    },
    {
      "x": -2,
      "y": 3,
      "z": 2,
      "name": "Rock_Shale_Cobble",
      "rotation": 8
    },
    {
      "x": -2,
      "y": 4,
      "z": 2,
      "name": "Rock_Shale_Cobble",
      "rotation": 8
    },
    {
      "x": -2,
      "y": 5,
      "z": 2,
      "name": "Rock_Shale_Cobble",
      "rotation": 8
    },
    {
      "x": -2,
      "y": 6,
      "z": 2,
      "name": "Rock_Shale_Cobble",
      "rotation": 8
    },
    {
      "x": -2,
      "y": 7,
      "z": 2,
      "name": "Rock_Shale_Cobble",
      "rotation": 8
    },
    {
      "x": -2,
      "y": 8,
      "z": 2,
      "name": "Metal_Iron_Glowing_Pipe",
      "rotation": 18
    },
    {
      "x": -2,
      "y": 2,
      "z": 3,
      "name": "Rock_Shale_Cobble",
      "rotation": 8
    },
    {
      "x": -2,
      "y": 3,
      "z": 3,
      "name": "Rock_Shale_Cobble",
      "rotation": 8
    },
    {
      "x": -2,
      "y": 4,
      "z": 3,
      "name": "Rock_Shale_Cobble",
      "rotation": 8
    },
    {
      "x": -2,
      "y": 5,
      "z": 3,
      "name": "Rock_Shale_Cobble",
      "rotation": 8
    },
    {
      "x": -2,
      "y": 6,
      "z": 3,
      "name": "Rock_Shale_Cobble",
      "rotation": 8
    },
    {
      "x": -2,
      "y": 7,
      "z": 3,
      "name": "Rock_Shale_Cobble",
      "rotation": 8
    },
    {
      "x": -2,
      "y": 2,
      "z": 4,
      "name": "Rock_Shale_Cobble",
      "rotation": 8
    },
    {
      "x": -2,
      "y": 3,
      "z": 4,
      "name": "Rock_Shale_Cobble",
      "rotation": 8
    },
    {
      "x": -2,
      "y": 4,
      "z": 4,
      "name": "Rock_Shale_Cobble",
      "rotation": 8
    },
    {
      "x": -2,
      "y": 5,
      "z": 4,
      "name": "Rock_Shale_Cobble",
      "rotation": 8
    },
    {
      "x": -2,
      "y": 6,
      "z": 4,
      "name": "Rock_Shale_Cobble",
      "rotation": 8
    },
    {
      "x": -2,
      "y": 7,
      "z": 4,
      "name": "Rock_Shale_Cobble",
      "rotation": 8
    },
    {
      "x": -2,
      "y": 8,
      "z": 4,
      "name": "Plant_Moss_Wall_Green_Dark",
      "rotation": 14
    },
    {
      "x": -2,
      "y": 2,
      "z": 5,
      "name": "Plant_Moss_Rug_Green_Dark",
      "rotation": 4
    },
    {
      "x": -2,
      "y": 3,
      "z": 5,
      "name": "Rock_Shale_Cobble_Half",
      "rotation": 17
    },
    {
      "x": -2,
      "y": 6,
      "z": 5,
      "name": "Rock_Shale_Cobble_Half",
      "rotation": 17
    },
    {
      "x": -2,
      "y": 7,
      "z": 5,
      "name": "Plant_Moss_Rug_Green_Dark",
      "rotation": 4
    },
    {
      "x": -1,
      "y": 3,
      "z": 0,
      "name": "Rock_Shale_Brick_Smooth",
      "rotation": 17
    },
    {
      "x": -1,
      "y": 6,
      "z": 0,
      "name": "Rock_Shale_Brick_Smooth",
      "rotation": 17
    },
    {
      "x": -1,
      "y": 2,
      "z": 1,
      "name": "Rock_Shale_Cobble",
      "rotation": 8
    },
    {
      "x": -1,
      "y": 3,
      "z": 1,
      "name": "Rock_Shale_Cobble",
      "rotation": 8
    },
    {
      "x": -1,
      "y": 4,
      "z": 1,
      "name": "Build_Lightsource_Cyan",
      "rotation": 19
    },
    {
      "x": -1,
      "y": 5,
      "z": 1,
      "name": "Build_Lightsource_Cyan",
      "rotation": 19
    },
    {
      "x": -1,
      "y": 6,
      "z": 1,
      "name": "Rock_Shale_Cobble",
      "rotation": 8
    },
    {
      "x": -1,
      "y": 7,
      "z": 1,
      "name": "Rock_Shale_Cobble",
      "rotation": 8
    },
    {
      "x": -1,
      "y": 2,
      "z": 2,
      "name": "Rock_Shale_Cobble",
      "rotation": 8
    },
    {
      "x": -1,
      "y": 3,
      "z": 2,
      "name": "Rock_Shale_Cobble",
      "rotation": 8
    },
    {
      "x": -1,
      "y": 4,
      "z": 2,
      "name": "Rock_Shale_Cobble",
      "rotation": 8
    },
    {
      "x": -1,
      "y": 5,
      "z": 2,
      "name": "Rock_Shale_Cobble",
      "rotation": 8
    },
    {
      "x": -1,
      "y": 6,
      "z": 2,
      "name": "Rock_Shale_Cobble",
      "rotation": 8
    },
    {
      "x": -1,
      "y": 7,
      "z": 2,
      "name": "Rock_Shale_Cobble",
      "rotation": 8
    },
    {
      "x": -1,
      "y": 8,
      "z": 2,
      "name": "Metal_Iron_Glowing_Pipe_Corner",
      "rotation": 13
    },
    {
      "x": -1,
      "y": 2,
      "z": 3,
      "name": "Rock_Shale_Cobble",
      "rotation": 8
    },
    {
      "x": -1,
      "y": 3,
      "z": 3,
      "name": "Rock_Shale_Cobble",
      "rotation": 8
    },
    {
      "x": -1,
      "y": 4,
      "z": 3,
      "name": "Rock_Shale_Cobble",
      "rotation": 8
    },
    {
      "x": -1,
      "y": 5,
      "z": 3,
      "name": "Rock_Shale_Cobble",
      "rotation": 8
    },
    {
      "x": -1,
      "y": 6,
      "z": 3,
      "name": "Rock_Shale_Cobble",
      "rotation": 8
    },
    {
      "x": -1,
      "y": 7,
      "z": 3,
      "name": "Rock_Shale_Cobble",
      "rotation": 8
    },
    {
      "x": -1,
      "y": 2,
      "z": 4,
      "name": "Rock_Shale_Cobble",
      "rotation": 8
    },
    {
      "x": -1,
      "y": 3,
      "z": 4,
      "name": "Rock_Shale_Cobble",
      "rotation": 8
    },
    {
      "x": -1,
      "y": 4,
      "z": 4,
      "name": "Rock_Shale_Cobble",
      "rotation": 8
    },
    {
      "x": -1,
      "y": 5,
      "z": 4,
      "name": "Rock_Shale_Cobble",
      "rotation": 8
    },
    {
      "x": -1,
      "y": 6,
      "z": 4,
      "name": "Rock_Shale_Cobble",
      "rotation": 8
    },
    {
      "x": -1,
      "y": 7,
      "z": 4,
      "name": "Rock_Shale_Cobble",
      "rotation": 8
    },
    {
      "x": -1,
      "y": 2,
      "z": 5,
      "name": "Rock_Shale_Cobble",
      "rotation": 8
    },
    {
      "x": -1,
      "y": 3,
      "z": 5,
      "name": "Rock_Shale_Cobble",
      "rotation": 8
    },
    {
      "x": -1,
      "y": 4,
      "z": 5,
      "name": "Rock_Shale_Cobble",
      "rotation": 8
    },
    {
      "x": -1,
      "y": 5,
      "z": 5,
      "name": "Rock_Shale_Cobble",
      "rotation": 8
    },
    {
      "x": -1,
      "y": 6,
      "z": 5,
      "name": "Rock_Shale_Cobble",
      "rotation": 8
    },
    {
      "x": -1,
      "y": 7,
      "z": 5,
      "name": "Rock_Shale_Cobble",
      "rotation": 8
    },
    {
      "x": -1,
      "y": 3,
      "z": 6,
      "name": "Rock_Shale_Cobble_Half",
      "rotation": 17
    },
    {
      "x": -1,
      "y": 6,
      "z": 6,
      "name": "Rock_Shale_Cobble_Half",
      "rotation": 17
    },
    {
      "x": 0,
      "y": 3,
      "z": 1,
      "name": "Rock_Shale_Brick_Smooth",
      "rotation": 17
    },
    {
      "x": 0,
      "y": 6,
      "z": 1,
      "name": "Rock_Shale_Brick_Smooth",
      "rotation": 17
    },
    {
      "x": 0,
      "y": 2,
      "z": 2,
      "name": "Rock_Shale_Cobble",
      "rotation": 8
    },
    {
      "x": 0,
      "y": 3,
      "z": 2,
      "name": "Rock_Shale_Cobble",
      "rotation": 8
    },
    {
      "x": 0,
      "y": 4,
      "z": 2,
      "name": "Build_Lightsource_Cyan",
      "rotation": 18
    },
    {
      "x": 0,
      "y": 5,
      "z": 2,
      "name": "Build_Lightsource_Cyan",
      "rotation": 18
    },
    {
      "x": 0,
      "y": 6,
      "z": 2,
      "name": "Rock_Shale_Cobble",
      "rotation": 8
    },
    {
      "x": 0,
      "y": 7,
      "z": 2,
      "name": "Rock_Shale_Cobble",
      "rotation": 8
    },
    {
      "x": 0,
      "y": 2,
      "z": 3,
      "name": "Rock_Shale_Cobble",
      "rotation": 8
    },
    {
      "x": 0,
      "y": 3,
      "z": 3,
      "name": "Rock_Shale_Cobble",
      "rotation": 8
    },
    {
      "x": 0,
      "y": 4,
      "z": 3,
      "name": "Rock_Shale_Cobble",
      "rotation": 8
    },
    {
      "x": 0,
      "y": 5,
      "z": 3,
      "name": "Rock_Shale_Cobble",
      "rotation": 8
    },
    {
      "x": 0,
      "y": 6,
      "z": 3,
      "name": "Rock_Shale_Cobble",
      "rotation": 8
    },
    {
      "x": 0,
      "y": 7,
      "z": 3,
      "name": "Rock_Shale_Cobble",
      "rotation": 8
    },
    {
      "x": 0,
      "y": 2,
      "z": 4,
      "name": "Rock_Shale_Cobble",
      "rotation": 8
    },
    {
      "x": 0,
      "y": 3,
      "z": 4,
      "name": "Rock_Shale_Cobble",
      "rotation": 8
    },
    {
      "x": 0,
      "y": 4,
      "z": 4,
      "name": "Rock_Shale_Cobble",
      "rotation": 8
    },
    {
      "x": 0,
      "y": 5,
      "z": 4,
      "name": "Rock_Shale_Cobble",
      "rotation": 8
    },
    {
      "x": 0,
      "y": 6,
      "z": 4,
      "name": "Rock_Shale_Cobble",
      "rotation": 8
    },
    {
      "x": 0,
      "y": 7,
      "z": 4,
      "name": "Rock_Shale_Cobble",
      "rotation": 8
    },
    {
      "x": 0,
      "y": 2,
      "z": 5,
      "name": "Rock_Shale_Cobble",
      "rotation": 8
    },
    {
      "x": 0,
      "y": 3,
      "z": 5,
      "name": "Rock_Shale_Cobble",
      "rotation": 8
    },
    {
      "x": 0,
      "y": 4,
      "z": 5,
      "name": "Rock_Shale_Cobble",
      "rotation": 8
    },
    {
      "x": 0,
      "y": 5,
      "z": 5,
      "name": "Rock_Shale_Cobble",
      "rotation": 8
    },
    {
      "x": 0,
      "y": 6,
      "z": 5,
      "name": "Rock_Shale_Cobble",
      "rotation": 8
    },
    {
      "x": 0,
      "y": 7,
      "z": 5,
      "name": "Rock_Shale_Cobble",
      "rotation": 8
    },
    {
      "x": 0,
      "y": 8,
      "z": 5,
      "name": "Plant_Moss_Wall_Green_Dark",
      "rotation": 14
    },
    {
      "x": 0,
      "y": 3,
      "z": 6,
      "name": "Rock_Shale_Cobble_Half",
      "rotation": 17
    },
    {
      "x": 0,
      "y": 5,
      "z": 6,
      "name": "Plant_Moss_Rug_Green_Dark",
      "rotation": 4
    },
    {
      "x": 0,
      "y": 6,
      "z": 6,
      "name": "Rock_Shale_Cobble_Half",
      "rotation": 17
    },
    {
      "x": 0,
      "y": 7,
      "z": 6,
      "name": "Plant_Moss_Rug_Green_Dark",
      "rotation": 4
    },
    {
      "x": 1,
      "y": 3,
      "z": 2,
      "name": "Rock_Shale_Brick_Smooth",
      "rotation": 17
    },
    {
      "x": 1,
      "y": 6,
      "z": 2,
      "name": "Rock_Shale_Brick_Smooth",
      "rotation": 17
    },
    {
      "x": 1,
      "y": 2,
      "z": 3,
      "name": "Rock_Shale_Cobble",
      "rotation": 8
    },
    {
      "x": 1,
      "y": 3,
      "z": 3,
      "name": "Rock_Shale_Cobble",
      "rotation": 8
    },
    {
      "x": 1,
      "y": 4,
      "z": 3,
      "name": "Build_Lightsource_Cyan",
      "rotation": 18
    },
    {
      "x": 1,
      "y": 5,
      "z": 3,
      "name": "Build_Lightsource_Cyan",
      "rotation": 18
    },
    {
      "x": 1,
      "y": 6,
      "z": 3,
      "name": "Rock_Shale_Cobble",
      "rotation": 8
    },
    {
      "x": 1,
      "y": 7,
      "z": 3,
      "name": "Rock_Shale_Cobble",
      "rotation": 8
    },
    {
      "x": 1,
      "y": 2,
      "z": 4,
      "name": "Rock_Shale_Cobble",
      "rotation": 8
    },
    {
      "x": 1,
      "y": 3,
      "z": 4,
      "name": "Rock_Shale_Cobble",
      "rotation": 8
    },
    {
      "x": 1,
      "y": 4,
      "z": 4,
      "name": "Rock_Shale_Cobble",
      "rotation": 18
    },
    {
      "x": 1,
      "y": 5,
      "z": 4,
      "name": "Rock_Shale_Cobble",
      "rotation": 8
    },
    {
      "x": 1,
      "y": 6,
      "z": 4,
      "name": "Rock_Shale_Cobble",
      "rotation": 8
    },
    {
      "x": 1,
      "y": 7,
      "z": 4,
      "name": "Rock_Shale_Cobble",
      "rotation": 8
    },
    {
      "x": 1,
      "y": 1,
      "z": 5,
      "name": "Plant_Moss_Wall_Green_Dark",
      "rotation": 4
    },
    {
      "x": 1,
      "y": 2,
      "z": 5,
      "name": "Rock_Shale_Cobble",
      "rotation": 8
    },
    {
      "x": 1,
      "y": 3,
      "z": 5,
      "name": "Rock_Shale_Cobble",
      "rotation": 8
    },
    {
      "x": 1,
      "y": 4,
      "z": 5,
      "name": "Rock_Shale_Cobble",
      "rotation": 8
    },
    {
      "x": 1,
      "y": 5,
      "z": 5,
      "name": "Rock_Shale_Cobble",
      "rotation": 8
    },
    {
      "x": 1,
      "y": 6,
      "z": 5,
      "name": "Rock_Shale_Cobble",
      "rotation": 8
    },
    {
      "x": 1,
      "y": 7,
      "z": 5,
      "name": "Rock_Shale_Cobble",
      "rotation": 8
    },
    {
      "x": 1,
      "y": 1,
      "z": 6,
      "name": "Plant_Moss_Wall_Green_Dark",
      "rotation": 4
    },
    {
      "x": 1,
      "y": 2,
      "z": 6,
      "name": "Rock_Shale_Cobble",
      "rotation": 8
    },
    {
      "x": 1,
      "y": 3,
      "z": 6,
      "name": "Rock_Shale_Cobble",
      "rotation": 8
    },
    {
      "x": 1,
      "y": 4,
      "z": 6,
      "name": "Rock_Shale_Cobble",
      "rotation": 8
    },
    {
      "x": 1,
      "y": 5,
      "z": 6,
      "name": "Rock_Shale_Cobble",
      "rotation": 8
    },
    {
      "x": 1,
      "y": 6,
      "z": 6,
      "name": "Rock_Shale_Cobble",
      "rotation": 8
    },
    {
      "x": 1,
      "y": 7,
      "z": 6,
      "name": "Rock_Shale_Cobble",
      "rotation": 8
    },
    {
      "x": 1,
      "y": 2,
      "z": 7,
      "name": "Plant_Moss_Rug_Green_Dark",
      "rotation": 4
    },
    {
      "x": 1,
      "y": 3,
      "z": 7,
      "name": "Rock_Shale_Cobble_Half",
      "rotation": 17
    },
    {
      "x": 1,
      "y": 4,
      "z": 7,
      "name": "Plant_Moss_Rug_Green_Dark",
      "rotation": 4
    },
    {
      "x": 1,
      "y": 6,
      "z": 7,
      "name": "Rock_Shale_Cobble_Half",
      "rotation": 17
    },
    {
      "x": 2,
      "y": 3,
      "z": 2,
      "name": "Rock_Shale_Brick_Smooth",
      "rotation": 17
    },
    {
      "x": 2,
      "y": 6,
      "z": 2,
      "name": "Rock_Shale_Brick_Smooth",
      "rotation": 17
    },
    {
      "x": 2,
      "y": 2,
      "z": 3,
      "name": "Rock_Shale_Cobble",
      "rotation": 8
    },
    {
      "x": 2,
      "y": 3,
      "z": 3,
      "name": "Rock_Shale_Cobble",
      "rotation": 18
    },
    {
      "x": 2,
      "y": 4,
      "z": 3,
      "name": "Build_Lightsource_Cyan",
      "rotation": 18
    },
    {
      "x": 2,
      "y": 5,
      "z": 3,
      "name": "Build_Lightsource_Cyan",
      "rotation": 18
    },
    {
      "x": 2,
      "y": 6,
      "z": 3,
      "name": "Rock_Shale_Cobble",
      "rotation": 8
    },
    {
      "x": 2,
      "y": 7,
      "z": 3,
      "name": "Rock_Shale_Cobble",
      "rotation": 8
    },
    {
      "x": 2,
      "y": 2,
      "z": 4,
      "name": "Rock_Shale_Cobble",
      "rotation": 8
    },
    {
      "x": 2,
      "y": 3,
      "z": 4,
      "name": "Rock_Shale_Cobble",
      "rotation": 8
    },
    {
      "x": 2,
      "y": 4,
      "z": 4,
      "name": "Rock_Shale_Cobble",
      "rotation": 8
    },
    {
      "x": 2,
      "y": 5,
      "z": 4,
      "name": "Rock_Shale_Cobble",
      "rotation": 8
    },
    {
      "x": 2,
      "y": 6,
      "z": 4,
      "name": "Rock_Shale_Cobble",
      "rotation": 8
    },
    {
      "x": 2,
      "y": 7,
      "z": 4,
      "name": "Rock_Shale_Cobble",
      "rotation": 8
    },
    {
      "x": 2,
      "y": 2,
      "z": 5,
      "name": "Rock_Shale_Cobble",
      "rotation": 8
    },
    {
      "x": 2,
      "y": 3,
      "z": 5,
      "name": "Rock_Shale_Cobble",
      "rotation": 8
    },
    {
      "x": 2,
      "y": 4,
      "z": 5,
      "name": "Rock_Shale_Cobble",
      "rotation": 8
    },
    {
      "x": 2,
      "y": 5,
      "z": 5,
      "name": "Rock_Shale_Cobble",
      "rotation": 8
    },
    {
      "x": 2,
      "y": 6,
      "z": 5,
      "name": "Rock_Shale_Cobble",
      "rotation": 8
    },
    {
      "x": 2,
      "y": 7,
      "z": 5,
      "name": "Rock_Shale_Cobble",
      "rotation": 8
    },
    {
      "x": 2,
      "y": 8,
      "z": 5,
      "name": "Plant_Moss_Wall_Green_Dark",
      "rotation": 14
    },
    {
      "x": 2,
      "y": 2,
      "z": 6,
      "name": "Rock_Shale_Cobble",
      "rotation": 8
    },
    {
      "x": 2,
      "y": 3,
      "z": 6,
      "name": "Rock_Shale_Cobble",
      "rotation": 8
    },
    {
      "x": 2,
      "y": 4,
      "z": 6,
      "name": "Rock_Shale_Cobble",
      "rotation": 8
    },
    {
      "x": 2,
      "y": 5,
      "z": 6,
      "name": "Rock_Shale_Cobble",
      "rotation": 8
    },
    {
      "x": 2,
      "y": 6,
      "z": 6,
      "name": "Rock_Shale_Cobble",
      "rotation": 8
    },
    {
      "x": 2,
      "y": 7,
      "z": 6,
      "name": "Rock_Shale_Cobble",
      "rotation": 8
    },
    {
      "x": 2,
      "y": 8,
      "z": 6,
      "name": "Plant_Moss_Wall_Green_Dark",
      "rotation": 14
    },
    {
      "x": 2,
      "y": 3,
      "z": 7,
      "name": "Rock_Shale_Cobble_Half",
      "rotation": 17
    },
    {
      "x": 2,
      "y": 6,
      "z": 7,
      "name": "Rock_Shale_Cobble_Half",
      "rotation": 17
    },
    {
      "x": 2,
      "y": 7,
      "z": 7,
      "name": "Plant_Moss_Rug_Green_Dark",
      "rotation": 4
    },
    {
      "x": 3,
      "y": 3,
      "z": 3,
      "name": "Rock_Shale_Brick_Smooth",
      "rotation": 17
    },
    {
      "x": 3,
      "y": 6,
      "z": 3,
      "name": "Rock_Shale_Brick_Smooth",
      "rotation": 17
    },
    {
      "x": 3,
      "y": 2,
      "z": 4,
      "name": "Rock_Shale_Cobble",
      "rotation": 8
    },
    {
      "x": 3,
      "y": 3,
      "z": 4,
      "name": "Rock_Shale_Cobble",
      "rotation": 17
    },
    {
      "x": 3,
      "y": 4,
      "z": 4,
      "name": "Build_Lightsource_Cyan",
      "rotation": 19
    },
    {
      "x": 3,
      "y": 5,
      "z": 4,
      "name": "Build_Lightsource_Cyan",
      "rotation": 19
    },
    {
      "x": 3,
      "y": 6,
      "z": 4,
      "name": "Rock_Shale_Cobble",
      "rotation": 8
    },
    {
      "x": 3,
      "y": 7,
      "z": 4,
      "name": "Rock_Shale_Cobble",
      "rotation": 8
    },
    {
      "x": 3,
      "y": 2,
      "z": 5,
      "name": "Rock_Shale_Cobble",
      "rotation": 8
    },
    {
      "x": 3,
      "y": 3,
      "z": 5,
      "name": "Rock_Shale_Cobble",
      "rotation": 8
    },
    {
      "x": 3,
      "y": 4,
      "z": 5,
      "name": "Rock_Shale_Cobble",
      "rotation": 8
    },
    {
      "x": 3,
      "y": 5,
      "z": 5,
      "name": "Rock_Shale_Cobble",
      "rotation": 8
    },
    {
      "x": 3,
      "y": 6,
      "z": 5,
      "name": "Rock_Shale_Cobble",
      "rotation": 8
    },
    {
      "x": 3,
      "y": 7,
      "z": 5,
      "name": "Rock_Shale_Cobble",
      "rotation": 8
    },
    {
      "x": 3,
      "y": 2,
      "z": 6,
      "name": "Plant_Moss_Rug_Green_Dark",
      "rotation": 4
    },
    {
      "x": 3,
      "y": 3,
      "z": 6,
      "name": "Plant_Moss_Rug_Green_Dark",
      "rotation": 4
    },
    {
      "x": 3,
      "y": 4,
      "z": 6,
      "name": "Rock_Shale_Cobble",
      "rotation": 8
    },
    {
      "x": 3,
      "y": 5,
      "z": 6,
      "name": "Rock_Shale_Cobble",
      "rotation": 8
    },
    {
      "x": 3,
      "y": 6,
      "z": 6,
      "name": "Rock_Shale_Cobble",
      "rotation": 8
    },
    {
      "x": 3,
      "y": 7,
      "z": 6,
      "name": "Rock_Shale_Cobble",
      "rotation": 8
    },
    {
      "x": 3,
      "y": 4,
      "z": 7,
      "name": "Rock_Shale_Cobble",
      "rotation": 8
    },
    {
      "x": 3,
      "y": 5,
      "z": 7,
      "name": "Rock_Shale_Cobble",
      "rotation": 8
    },
    {
      "x": 3,
      "y": 6,
      "z": 7,
      "name": "Rock_Shale_Cobble",
      "rotation": 8
    },
    {
      "x": 3,
      "y": 7,
      "z": 7,
      "name": "Rock_Shale_Cobble",
      "rotation": 8
    },
    {
      "x": 4,
      "y": 3,
      "z": 3,
      "name": "Rock_Shale_Brick_Smooth",
      "rotation": 17
    },
    {
      "x": 4,
      "y": 6,
      "z": 3,
      "name": "Rock_Shale_Brick_Smooth",
      "rotation": 17
    },
    {
      "x": 4,
      "y": 2,
      "z": 4,
      "name": "Rock_Shale_Cobble",
      "rotation": 8
    },
    {
      "x": 4,
      "y": 3,
      "z": 4,
      "name": "Rock_Shale_Cobble",
      "rotation": 8
    },
    {
      "x": 4,
      "y": 4,
      "z": 4,
      "name": "Build_Lightsource_Cyan",
      "rotation": 19
    },
    {
      "x": 4,
      "y": 5,
      "z": 4,
      "name": "Build_Lightsource_Cyan",
      "rotation": 19
    },
    {
      "x": 4,
      "y": 6,
      "z": 4,
      "name": "Rock_Shale_Cobble",
      "rotation": 8
    },
    {
      "x": 4,
      "y": 7,
      "z": 4,
      "name": "Rock_Shale_Cobble",
      "rotation": 8
    },
    {
      "x": 4,
      "y": 2,
      "z": 5,
      "name": "Rock_Shale_Cobble",
      "rotation": 8
    },
    {
      "x": 4,
      "y": 3,
      "z": 5,
      "name": "Rock_Shale_Cobble",
      "rotation": 8
    },
    {
      "x": 4,
      "y": 4,
      "z": 5,
      "name": "Rock_Shale_Cobble",
      "rotation": 8
    },
    {
      "x": 4,
      "y": 5,
      "z": 5,
      "name": "Rock_Shale_Cobble",
      "rotation": 8
    },
    {
      "x": 4,
      "y": 6,
      "z": 5,
      "name": "Rock_Shale_Cobble",
      "rotation": 8
    },
    {
      "x": 4,
      "y": 7,
      "z": 5,
      "name": "Rock_Shale_Cobble",
      "rotation": 8
    },
    {
      "x": 4,
      "y": 2,
      "z": 6,
      "name": "Plant_Moss_Rug_Green_Dark",
      "rotation": 4
    },
    {
      "x": 4,
      "y": 4,
      "z": 6,
      "name": "Rock_Shale_Cobble",
      "rotation": 8
    },
    {
      "x": 4,
      "y": 5,
      "z": 6,
      "name": "Rock_Shale_Cobble",
      "rotation": 8
    },
    {
      "x": 4,
      "y": 6,
      "z": 6,
      "name": "Rock_Shale_Cobble",
      "rotation": 8
    },
    {
      "x": 4,
      "y": 7,
      "z": 6,
      "name": "Rock_Shale_Cobble",
      "rotation": 8
    },
    {
      "x": 4,
      "y": 4,
      "z": 7,
      "name": "Rock_Shale_Cobble",
      "rotation": 8
    },
    {
      "x": 4,
      "y": 5,
      "z": 7,
      "name": "Rock_Shale_Cobble",
      "rotation": 8
    },
    {
      "x": 4,
      "y": 6,
      "z": 7,
      "name": "Rock_Shale_Cobble",
      "rotation": 8
    },
    {
      "x": 4,
      "y": 7,
      "z": 7,
      "name": "Rock_Shale_Cobble",
      "rotation": 8
    },
    {
      "x": 4,
      "y": 4,
      "z": 8,
      "name": "Plant_Moss_Rug_Green_Dark",
      "rotation": 4
    },
    {
      "x": 4,
      "y": 5,
      "z": 8,
      "name": "Plant_Moss_Rug_Green_Dark",
      "rotation": 4
    },
    {
      "x": 4,
      "y": 6,
      "z": 8,
      "name": "Plant_Moss_Rug_Green_Dark",
      "rotation": 4
    },
    {
      "x": 5,
      "y": 3,
      "z": 3,
      "name": "Rock_Shale_Brick_Smooth",
      "rotation": 17
    },
    {
      "x": 5,
      "y": 6,
      "z": 3,
      "name": "Rock_Shale_Brick_Smooth",
      "rotation": 17
    },
    {
      "x": 5,
      "y": 2,
      "z": 4,
      "name": "Rock_Shale_Cobble",
      "rotation": 8
    },
    {
      "x": 5,
      "y": 3,
      "z": 4,
      "name": "Rock_Shale_Cobble",
      "rotation": 8
    },
    {
      "x": 5,
      "y": 4,
      "z": 4,
      "name": "Build_Lightsource_Cyan",
      "rotation": 19
    },
    {
      "x": 5,
      "y": 5,
      "z": 4,
      "name": "Build_Lightsource_Cyan",
      "rotation": 19
    },
    {
      "x": 5,
      "y": 6,
      "z": 4,
      "name": "Rock_Shale_Cobble",
      "rotation": 8
    },
    {
      "x": 5,
      "y": 7,
      "z": 4,
      "name": "Rock_Shale_Cobble",
      "rotation": 18
    },
    {
      "x": 5,
      "y": 2,
      "z": 5,
      "name": "Rock_Shale_Cobble",
      "rotation": 8
    },
    {
      "x": 5,
      "y": 3,
      "z": 5,
      "name": "Rock_Shale_Cobble",
      "rotation": 8
    },
    {
      "x": 5,
      "y": 5,
      "z": 5,
      "name": "Plant_Moss_Rug_Green_Dark",
      "rotation": 4
    },
    {
      "x": 5,
      "y": 6,
      "z": 5,
      "name": "Rock_Shale_Cobble",
      "rotation": 8
    },
    {
      "x": 5,
      "y": 7,
      "z": 5,
      "name": "Rock_Shale_Cobble",
      "rotation": 8
    },
    {
      "x": 5,
      "y": 6,
      "z": 6,
      "name": "Rock_Shale_Cobble",
      "rotation": 8
    },
    {
      "x": 5,
      "y": 7,
      "z": 6,
      "name": "Rock_Shale_Cobble",
      "rotation": 8
    },
    {
      "x": 5,
      "y": 6,
      "z": 7,
      "name": "Rock_Shale_Cobble",
      "rotation": 8
    },
    {
      "x": 5,
      "y": 7,
      "z": 7,
      "name": "Rock_Shale_Cobble",
      "rotation": 8
    },
    {
      "x": 5,
      "y": 8,
      "z": 7,
      "name": "Plant_Moss_Wall_Green_Dark",
      "rotation": 14
    },
    {
      "x": 5,
      "y": 7,
      "z": 8,
      "name": "Plant_Moss_Rug_Green_Dark",
      "rotation": 4
    },
    {
      "x": 6,
      "y": 2,
      "z": 4,
      "name": "Rock_Shale_Cobble",
      "rotation": 11
    },
    {
      "x": 6,
      "y": 3,
      "z": 4,
      "name": "Rock_Shale_Brick_Smooth",
      "rotation": 17
    },
    {
      "x": 6,
      "y": 6,
      "z": 4,
      "name": "Rock_Shale_Brick_Smooth",
      "rotation": 17
    },
    {
      "x": 6,
      "y": 2,
      "z": 5,
      "name": "Rock_Shale_Cobble",
      "rotation": 8
    },
    {
      "x": 6,
      "y": 3,
      "z": 5,
      "name": "Rock_Shale_Cobble",
      "rotation": 8
    },
    {
      "x": 7,
      "y": 2,
      "z": 3,
      "name": "Rock_Shale_Brick_Smooth",
      "rotation": 17
    },
    {
      "x": 7,
      "y": 3,
      "z": 3,
      "name": "Rock_Shale_Brick_Smooth",
      "rotation": 17
    },
    {
      "x": 7,
      "y": 4,
      "z": 3,
      "name": "Rock_Shale_Brick_Smooth",
      "rotation": 17
    },
    {
      "x": 7,
      "y": 5,
      "z": 3,
      "name": "Rock_Shale_Brick_Smooth",
      "rotation": 17
    },
    {
      "x": 7,
      "y": 6,
      "z": 3,
      "name": "Rock_Shale_Brick_Smooth",
      "rotation": 17
    },
    {
      "x": 7,
      "y": 7,
      "z": 3,
      "name": "Rock_Shale_Brick_Smooth",
      "rotation": 17
    },
    {
      "x": 7,
      "y": 1,
      "z": 4,
      "name": "Rock_Shale_Brick_Smooth",
      "rotation": 17
    },
    {
      "x": 7,
      "y": 2,
      "z": 4,
      "name": "Rock_Shale_Cobble",
      "rotation": 11
    },
    {
      "x": 7,
      "y": 3,
      "z": 4,
      "name": "Rock_Shale_Cobble",
      "rotation": 11
    },
    {
      "x": 7,
      "y": 4,
      "z": 4,
      "name": "Rock_Shale_Cobble",
      "rotation": 11
    },
    {
      "x": 7,
      "y": 5,
      "z": 4,
      "name": "Rock_Shale_Cobble",
      "rotation": 11
    },
    {
      "x": 7,
      "y": 6,
      "z": 4,
      "name": "Rock_Shale_Cobble",
      "rotation": 17
    },
    {
      "x": 7,
      "y": 7,
      "z": 4,
      "name": "Plant_Moss_Rug_Green_Dark",
      "rotation": 4
    },
    {
      "x": 7,
      "y": 0,
      "z": 5,
      "name": "Rock_Shale_Brick_Smooth",
      "rotation": 17
    },
    {
      "x": 7,
      "y": 1,
      "z": 5,
      "name": "Rock_Shale_Cobble",
      "rotation": 17
    },
    {
      "x": 7,
      "y": 2,
      "z": 5,
      "name": "Rock_Shale_Cobble",
      "rotation": 11
    },
    {
      "x": 7,
      "y": 3,
      "z": 5,
      "name": "Rock_Shale_Cobble",
      "rotation": 11
    },
    {
      "x": 7,
      "y": 0,
      "z": 6,
      "name": "Rock_Shale_Brick_Smooth",
      "rotation": 17
    },
    {
      "x": 7,
      "y": 0,
      "z": 7,
      "name": "Rock_Shale_Brick_Smooth",
      "rotation": 17
    },
    {
      "x": 8,
      "y": 3,
      "z": 4,
      "name": "Rock_Shale_Cobble",
      "rotation": 11
    },
    {
      "x": 8,
      "y": 4,
      "z": 4,
      "name": "Rock_Shale_Cobble",
      "rotation": 17
    },
    {
      "x": 8,
      "y": 5,
      "z": 4,
      "name": "Rock_Shale_Cobble",
      "rotation": 17
    },
    {
      "x": 8,
      "y": 6,
      "z": 4,
      "name": "Rock_Shale_Cobble",
      "rotation": 11
    },
    {
      "x": 8,
      "y": 1,
      "z": 5,
      "name": "Rock_Shale_Cobble",
      "rotation": 17
    },
    {
      "x": 8,
      "y": 2,
      "z": 5,
      "name": "Rock_Shale_Cobble",
      "rotation": 11
    },
    {
      "x": 8,
      "y": 3,
      "z": 5,
      "name": "Rock_Shale_Cobble",
      "rotation": 11
    },
    {
      "x": 8,
      "y": 4,
      "z": 5,
      "name": "Build_Lightsource_Cyan",
      "rotation": 17
    },
    {
      "x": 8,
      "y": 5,
      "z": 5,
      "name": "Build_Lightsource_Cyan",
      "rotation": 18
    },
    {
      "x": 8,
      "y": 1,
      "z": 6,
      "name": "Rock_Shale_Cobble",
      "rotation": 17
    },
    {
      "x": 8,
      "y": 2,
      "z": 6,
      "name": "Rock_Shale_Cobble",
      "rotation": 11
    },
    {
      "x": 8,
      "y": 3,
      "z": 6,
      "name": "Plant_Moss_Rug_Green_Dark",
      "rotation": 4
    },
    {
      "x": 8,
      "y": 5,
      "z": 6,
      "name": "Plant_Moss_Rug_Green_Dark",
      "rotation": 4
    },
    {
      "x": 8,
      "y": 1,
      "z": 7,
      "name": "Rock_Shale_Cobble",
      "rotation": 17
    },
    {
      "x": 8,
      "y": 2,
      "z": 7,
      "name": "Rock_Shale_Cobble",
      "rotation": 11
    },
    {
      "x": 8,
      "y": 1,
      "z": 8,
      "name": "Plant_Moss_Rug_Green_Dark",
      "rotation": 4
    },
    {
      "x": 8,
      "y": 2,
      "z": 8,
      "name": "Plant_Moss_Rug_Green_Dark",
      "rotation": 4
    }
  ],
  "fluids": [
    {
      "x": -8,
      "y": 6,
      "z": -6,
      "name": "Empty",
      "level": 0
    },
    {
      "x": -8,
      "y": 7,
      "z": -6,
      "name": "Empty",
      "level": 0
    },
    {
      "x": -8,
      "y": 6,
      "z": -5,
      "name": "Empty",
      "level": 0
    },
    {
      "x": -8,
      "y": 3,
      "z": -4,
      "name": "Empty",
      "level": 0
    },
    {
      "x": -8,
      "y": 6,
      "z": -4,
      "name": "Empty",
      "level": 0
    },
    {
      "x": -8,
      "y": 3,
      "z": -3,
      "name": "Empty",
      "level": 0
    },
    {
      "x": -8,
      "y": 4,
      "z": -3,
      "name": "Empty",
      "level": 0
    },
    {
      "x": -8,
      "y": 6,
      "z": -3,
      "name": "Empty",
      "level": 0
    },
    {
      "x": -7,
      "y": 6,
      "z": -6,
      "name": "Empty",
      "level": 0
    },
    {
      "x": -7,
      "y": 7,
      "z": -6,
      "name": "Empty",
      "level": 0
    },
    {
      "x": -7,
      "y": 6,
      "z": -5,
      "name": "Empty",
      "level": 0
    },
    {
      "x": -7,
      "y": 7,
      "z": -5,
      "name": "Empty",
      "level": 0
    },
    {
      "x": -7,
      "y": 2,
      "z": -4,
      "name": "Empty",
      "level": 0
    },
    {
      "x": -7,
      "y": 3,
      "z": -4,
      "name": "Empty",
      "level": 0
    },
    {
      "x": -7,
      "y": 4,
      "z": -4,
      "name": "Empty",
      "level": 0
    },
    {
      "x": -7,
      "y": 5,
      "z": -4,
      "name": "Empty",
      "level": 0
    },
    {
      "x": -7,
      "y": 6,
      "z": -4,
      "name": "Empty",
      "level": 0
    },
    {
      "x": -7,
      "y": 7,
      "z": -4,
      "name": "Empty",
      "level": 0
    },
    {
      "x": -7,
      "y": 2,
      "z": -3,
      "name": "Empty",
      "level": 0
    },
    {
      "x": -7,
      "y": 3,
      "z": -3,
      "name": "Empty",
      "level": 0
    },
    {
      "x": -7,
      "y": 4,
      "z": -3,
      "name": "Empty",
      "level": 0
    },
    {
      "x": -7,
      "y": 5,
      "z": -3,
      "name": "Empty",
      "level": 0
    },
    {
      "x": -7,
      "y": 6,
      "z": -3,
      "name": "Empty",
      "level": 0
    },
    {
      "x": -7,
      "y": 7,
      "z": -3,
      "name": "Empty",
      "level": 0
    },
    {
      "x": -7,
      "y": 8,
      "z": -3,
      "name": "Empty",
      "level": 0
    },
    {
      "x": -7,
      "y": 3,
      "z": -2,
      "name": "Empty",
      "level": 0
    },
    {
      "x": -7,
      "y": 4,
      "z": -2,
      "name": "Empty",
      "level": 0
    },
    {
      "x": -7,
      "y": 6,
      "z": -2,
      "name": "Empty",
      "level": 0
    },
    {
      "x": -7,
      "y": 7,
      "z": -2,
      "name": "Empty",
      "level": 0
    },
    {
      "x": -7,
      "y": 1,
      "z": -1,
      "name": "Empty",
      "level": 0
    },
    {
      "x": -7,
      "y": 3,
      "z": -1,
      "name": "Empty",
      "level": 0
    },
    {
      "x": -7,
      "y": 6,
      "z": -1,
      "name": "Empty",
      "level": 0
    },
    {
      "x": -7,
      "y": 1,
      "z": 0,
      "name": "Empty",
      "level": 0
    },
    {
      "x": -7,
      "y": 2,
      "z": 0,
      "name": "Empty",
      "level": 0
    },
    {
      "x": -7,
      "y": 3,
      "z": 0,
      "name": "Empty",
      "level": 0
    },
    {
      "x": -7,
      "y": 4,
      "z": 0,
      "name": "Empty",
      "level": 0
    },
    {
      "x": -7,
      "y": 5,
      "z": 0,
      "name": "Empty",
      "level": 0
    },
    {
      "x": -7,
      "y": 5,
      "z": 1,
      "name": "Empty",
      "level": 0
    },
    {
      "x": -7,
      "y": 6,
      "z": 1,
      "name": "Empty",
      "level": 0
    },
    {
      "x": -7,
      "y": 7,
      "z": 1,
      "name": "Empty",
      "level": 0
    },
    {
      "x": -6,
      "y": 3,
      "z": -7,
      "name": "Empty",
      "level": 0
    },
    {
      "x": -6,
      "y": 4,
      "z": -7,
      "name": "Empty",
      "level": 0
    },
    {
      "x": -6,
      "y": 5,
      "z": -7,
      "name": "Empty",
      "level": 0
    },
    {
      "x": -6,
      "y": 3,
      "z": -6,
      "name": "Empty",
      "level": 0
    },
    {
      "x": -6,
      "y": 4,
      "z": -6,
      "name": "Empty",
      "level": 0
    },
    {
      "x": -6,
      "y": 5,
      "z": -6,
      "name": "Empty",
      "level": 0
    },
    {
      "x": -6,
      "y": 6,
      "z": -6,
      "name": "Empty",
      "level": 0
    },
    {
      "x": -6,
      "y": 7,
      "z": -6,
      "name": "Empty",
      "level": 0
    },
    {
      "x": -6,
      "y": 3,
      "z": -5,
      "name": "Empty",
      "level": 0
    },
    {
      "x": -6,
      "y": 4,
      "z": -5,
      "name": "Empty",
      "level": 0
    },
    {
      "x": -6,
      "y": 5,
      "z": -5,
      "name": "Empty",
      "level": 0
    },
    {
      "x": -6,
      "y": 6,
      "z": -5,
      "name": "Empty",
      "level": 0
    },
    {
      "x": -6,
      "y": 7,
      "z": -5,
      "name": "Empty",
      "level": 0
    },
    {
      "x": -6,
      "y": 2,
      "z": -4,
      "name": "Empty",
      "level": 0
    },
    {
      "x": -6,
      "y": 3,
      "z": -4,
      "name": "Empty",
      "level": 0
    },
    {
      "x": -6,
      "y": 4,
      "z": -4,
      "name": "Empty",
      "level": 0
    },
    {
      "x": -6,
      "y": 5,
      "z": -4,
      "name": "Empty",
      "level": 0
    },
    {
      "x": -6,
      "y": 6,
      "z": -4,
      "name": "Empty",
      "level": 0
    },
    {
      "x": -6,
      "y": 7,
      "z": -4,
      "name": "Empty",
      "level": 0
    },
    {
      "x": -6,
      "y": 1,
      "z": -3,
      "name": "Empty",
      "level": 0
    },
    {
      "x": -6,
      "y": 2,
      "z": -3,
      "name": "Empty",
      "level": 0
    },
    {
      "x": -6,
      "y": 3,
      "z": -3,
      "name": "Empty",
      "level": 0
    },
    {
      "x": -6,
      "y": 4,
      "z": -3,
      "name": "Empty",
      "level": 0
    },
    {
      "x": -6,
      "y": 5,
      "z": -3,
      "name": "Empty",
      "level": 0
    },
    {
      "x": -6,
      "y": 6,
      "z": -3,
      "name": "Empty",
      "level": 0
    },
    {
      "x": -6,
      "y": 7,
      "z": -3,
      "name": "Empty",
      "level": 0
    },
    {
      "x": -6,
      "y": 1,
      "z": -2,
      "name": "Empty",
      "level": 0
    },
    {
      "x": -6,
      "y": 2,
      "z": -2,
      "name": "Empty",
      "level": 0
    },
    {
      "x": -6,
      "y": 3,
      "z": -2,
      "name": "Empty",
      "level": 0
    },
    {
      "x": -6,
      "y": 4,
      "z": -2,
      "name": "Empty",
      "level": 0
    },
    {
      "x": -6,
      "y": 5,
      "z": -2,
      "name": "Empty",
      "level": 0
    },
    {
      "x": -6,
      "y": 6,
      "z": -2,
      "name": "Empty",
      "level": 0
    },
    {
      "x": -6,
      "y": 7,
      "z": -2,
      "name": "Empty",
      "level": 0
    },
    {
      "x": -6,
      "y": 1,
      "z": -1,
      "name": "Empty",
      "level": 0
    },
    {
      "x": -6,
      "y": 2,
      "z": -1,
      "name": "Empty",
      "level": 0
    },
    {
      "x": -6,
      "y": 3,
      "z": -1,
      "name": "Empty",
      "level": 0
    },
    {
      "x": -6,
      "y": 4,
      "z": -1,
      "name": "Empty",
      "level": 0
    },
    {
      "x": -6,
      "y": 5,
      "z": -1,
      "name": "Empty",
      "level": 0
    },
    {
      "x": -6,
      "y": 6,
      "z": -1,
      "name": "Empty",
      "level": 0
    },
    {
      "x": -6,
      "y": 7,
      "z": -1,
      "name": "Empty",
      "level": 0
    },
    {
      "x": -6,
      "y": 2,
      "z": 0,
      "name": "Empty",
      "level": 0
    },
    {
      "x": -6,
      "y": 3,
      "z": 0,
      "name": "Empty",
      "level": 0
    },
    {
      "x": -6,
      "y": 4,
      "z": 0,
      "name": "Empty",
      "level": 0
    },
    {
      "x": -6,
      "y": 6,
      "z": 0,
      "name": "Empty",
      "level": 0
    },
    {
      "x": -6,
      "y": 2,
      "z": 1,
      "name": "Empty",
      "level": 0
    },
    {
      "x": -6,
      "y": 3,
      "z": 1,
      "name": "Empty",
      "level": 0
    },
    {
      "x": -6,
      "y": 6,
      "z": 1,
      "name": "Empty",
      "level": 0
    },
    {
      "x": -6,
      "y": 7,
      "z": 1,
      "name": "Empty",
      "level": 0
    },
    {
      "x": -6,
      "y": 8,
      "z": 1,
      "name": "Empty",
      "level": 0
    },
    {
      "x": -5,
      "y": 3,
      "z": -7,
      "name": "Empty",
      "level": 0
    },
    {
      "x": -5,
      "y": 4,
      "z": -7,
      "name": "Empty",
      "level": 0
    },
    {
      "x": -5,
      "y": 5,
      "z": -7,
      "name": "Empty",
      "level": 0
    },
    {
      "x": -5,
      "y": 3,
      "z": -6,
      "name": "Empty",
      "level": 0
    },
    {
      "x": -5,
      "y": 4,
      "z": -6,
      "name": "Empty",
      "level": 0
    },
    {
      "x": -5,
      "y": 5,
      "z": -6,
      "name": "Empty",
      "level": 0
    },
    {
      "x": -5,
      "y": 3,
      "z": -5,
      "name": "Empty",
      "level": 0
    },
    {
      "x": -5,
      "y": 4,
      "z": -5,
      "name": "Empty",
      "level": 0
    },
    {
      "x": -5,
      "y": 5,
      "z": -5,
      "name": "Empty",
      "level": 0
    },
    {
      "x": -5,
      "y": 1,
      "z": -4,
      "name": "Empty",
      "level": 0
    },
    {
      "x": -5,
      "y": 2,
      "z": -4,
      "name": "Empty",
      "level": 0
    },
    {
      "x": -5,
      "y": 3,
      "z": -4,
      "name": "Empty",
      "level": 0
    },
    {
      "x": -5,
      "y": 4,
      "z": -4,
      "name": "Empty",
      "level": 0
    },
    {
      "x": -5,
      "y": 5,
      "z": -4,
      "name": "Empty",
      "level": 0
    },
    {
      "x": -5,
      "y": 6,
      "z": -4,
      "name": "Empty",
      "level": 0
    },
    {
      "x": -5,
      "y": 7,
      "z": -4,
      "name": "Empty",
      "level": 0
    },
    {
      "x": -5,
      "y": 1,
      "z": -3,
      "name": "Empty",
      "level": 0
    },
    {
      "x": -5,
      "y": 2,
      "z": -3,
      "name": "Empty",
      "level": 0
    },
    {
      "x": -5,
      "y": 3,
      "z": -3,
      "name": "Empty",
      "level": 0
    },
    {
      "x": -5,
      "y": 4,
      "z": -3,
      "name": "Empty",
      "level": 0
    },
    {
      "x": -5,
      "y": 5,
      "z": -3,
      "name": "Empty",
      "level": 0
    },
    {
      "x": -5,
      "y": 6,
      "z": -3,
      "name": "Empty",
      "level": 0
    },
    {
      "x": -5,
      "y": 7,
      "z": -3,
      "name": "Empty",
      "level": 0
    },
    {
      "x": -5,
      "y": 2,
      "z": -2,
      "name": "Empty",
      "level": 0
    },
    {
      "x": -5,
      "y": 3,
      "z": -2,
      "name": "Empty",
      "level": 0
    },
    {
      "x": -5,
      "y": 4,
      "z": -2,
      "name": "Empty",
      "level": 0
    },
    {
      "x": -5,
      "y": 5,
      "z": -2,
      "name": "Empty",
      "level": 0
    },
    {
      "x": -5,
      "y": 6,
      "z": -2,
      "name": "Empty",
      "level": 0
    },
    {
      "x": -5,
      "y": 7,
      "z": -2,
      "name": "Empty",
      "level": 0
    },
    {
      "x": -5,
      "y": 2,
      "z": -1,
      "name": "Empty",
      "level": 0
    },
    {
      "x": -5,
      "y": 3,
      "z": -1,
      "name": "Empty",
      "level": 0
    },
    {
      "x": -5,
      "y": 4,
      "z": -1,
      "name": "Empty",
      "level": 0
    },
    {
      "x": -5,
      "y": 5,
      "z": -1,
      "name": "Empty",
      "level": 0
    },
    {
      "x": -5,
      "y": 6,
      "z": -1,
      "name": "Empty",
      "level": 0
    },
    {
      "x": -5,
      "y": 7,
      "z": -1,
      "name": "Empty",
      "level": 0
    },
    {
      "x": -5,
      "y": 2,
      "z": 0,
      "name": "Empty",
      "level": 0
    },
    {
      "x": -5,
      "y": 3,
      "z": 0,
      "name": "Empty",
      "level": 0
    },
    {
      "x": -5,
      "y": 4,
      "z": 0,
      "name": "Empty",
      "level": 0
    },
    {
      "x": -5,
      "y": 5,
      "z": 0,
      "name": "Empty",
      "level": 0
    },
    {
      "x": -5,
      "y": 6,
      "z": 0,
      "name": "Empty",
      "level": 0
    },
    {
      "x": -5,
      "y": 7,
      "z": 0,
      "name": "Empty",
      "level": 0
    },
    {
      "x": -5,
      "y": 1,
      "z": 1,
      "name": "Empty",
      "level": 0
    },
    {
      "x": -5,
      "y": 2,
      "z": 1,
      "name": "Empty",
      "level": 0
    },
    {
      "x": -5,
      "y": 3,
      "z": 1,
      "name": "Empty",
      "level": 0
    },
    {
      "x": -5,
      "y": 4,
      "z": 1,
      "name": "Empty",
      "level": 0
    },
    {
      "x": -5,
      "y": 5,
      "z": 1,
      "name": "Empty",
      "level": 0
    },
    {
      "x": -5,
      "y": 6,
      "z": 1,
      "name": "Empty",
      "level": 0
    },
    {
      "x": -5,
      "y": 7,
      "z": 1,
      "name": "Empty",
      "level": 0
    },
    {
      "x": -5,
      "y": 8,
      "z": 1,
      "name": "Empty",
      "level": 0
    },
    {
      "x": -5,
      "y": 2,
      "z": 2,
      "name": "Empty",
      "level": 0
    },
    {
      "x": -5,
      "y": 3,
      "z": 2,
      "name": "Empty",
      "level": 0
    },
    {
      "x": -5,
      "y": 4,
      "z": 2,
      "name": "Empty",
      "level": 0
    },
    {
      "x": -5,
      "y": 6,
      "z": 2,
      "name": "Empty",
      "level": 0
    },
    {
      "x": -4,
      "y": 6,
      "z": -7,
      "name": "Empty",
      "level": 0
    },
    {
      "x": -4,
      "y": 7,
      "z": -7,
      "name": "Empty",
      "level": 0
    },
    {
      "x": -4,
      "y": 8,
      "z": -7,
      "name": "Empty",
      "level": 0
    },
    {
      "x": -4,
      "y": 6,
      "z": -6,
      "name": "Empty",
      "level": 0
    },
    {
      "x": -4,
      "y": 6,
      "z": -5,
      "name": "Empty",
      "level": 0
    },
    {
      "x": -4,
      "y": 7,
      "z": -5,
      "name": "Empty",
      "level": 0
    },
    {
      "x": -4,
      "y": 2,
      "z": -4,
      "name": "Empty",
      "level": 0
    },
    {
      "x": -4,
      "y": 3,
      "z": -4,
      "name": "Empty",
      "level": 0
    },
    {
      "x": -4,
      "y": 4,
      "z": -4,
      "name": "Empty",
      "level": 0
    },
    {
      "x": -4,
      "y": 5,
      "z": -4,
      "name": "Empty",
      "level": 0
    },
    {
      "x": -4,
      "y": 6,
      "z": -4,
      "name": "Empty",
      "level": 0
    },
    {
      "x": -4,
      "y": 7,
      "z": -4,
      "name": "Empty",
      "level": 0
    },
    {
      "x": -4,
      "y": 2,
      "z": -3,
      "name": "Empty",
      "level": 0
    },
    {
      "x": -4,
      "y": 3,
      "z": -3,
      "name": "Empty",
      "level": 0
    },
    {
      "x": -4,
      "y": 4,
      "z": -3,
      "name": "Empty",
      "level": 0
    },
    {
      "x": -4,
      "y": 5,
      "z": -3,
      "name": "Empty",
      "level": 0
    },
    {
      "x": -4,
      "y": 6,
      "z": -3,
      "name": "Empty",
      "level": 0
    },
    {
      "x": -4,
      "y": 7,
      "z": -3,
      "name": "Empty",
      "level": 0
    },
    {
      "x": -4,
      "y": 2,
      "z": -2,
      "name": "Empty",
      "level": 0
    },
    {
      "x": -4,
      "y": 3,
      "z": -2,
      "name": "Empty",
      "level": 0
    },
    {
      "x": -4,
      "y": 4,
      "z": -2,
      "name": "Empty",
      "level": 0
    },
    {
      "x": -4,
      "y": 5,
      "z": -2,
      "name": "Empty",
      "level": 0
    },
    {
      "x": -4,
      "y": 6,
      "z": -2,
      "name": "Empty",
      "level": 0
    },
    {
      "x": -4,
      "y": 7,
      "z": -2,
      "name": "Empty",
      "level": 0
    },
    {
      "x": -4,
      "y": 2,
      "z": -1,
      "name": "Empty",
      "level": 0
    },
    {
      "x": -4,
      "y": 3,
      "z": -1,
      "name": "Empty",
      "level": 0
    },
    {
      "x": -4,
      "y": 4,
      "z": -1,
      "name": "Empty",
      "level": 0
    },
    {
      "x": -4,
      "y": 5,
      "z": -1,
      "name": "Empty",
      "level": 0
    },
    {
      "x": -4,
      "y": 6,
      "z": -1,
      "name": "Empty",
      "level": 0
    },
    {
      "x": -4,
      "y": 7,
      "z": -1,
      "name": "Empty",
      "level": 0
    },
    {
      "x": -4,
      "y": 2,
      "z": 0,
      "name": "Empty",
      "level": 0
    },
    {
      "x": -4,
      "y": 3,
      "z": 0,
      "name": "Empty",
      "level": 0
    },
    {
      "x": -4,
      "y": 4,
      "z": 0,
      "name": "Empty",
      "level": 0
    },
    {
      "x": -4,
      "y": 5,
      "z": 0,
      "name": "Empty",
      "level": 0
    },
    {
      "x": -4,
      "y": 6,
      "z": 0,
      "name": "Empty",
      "level": 0
    },
    {
      "x": -4,
      "y": 7,
      "z": 0,
      "name": "Empty",
      "level": 0
    },
    {
      "x": -4,
      "y": 2,
      "z": 1,
      "name": "Empty",
      "level": 0
    },
    {
      "x": -4,
      "y": 3,
      "z": 1,
      "name": "Empty",
      "level": 0
    },
    {
      "x": -4,
      "y": 4,
      "z": 1,
      "name": "Empty",
      "level": 0
    },
    {
      "x": -4,
      "y": 5,
      "z": 1,
      "name": "Empty",
      "level": 0
    },
    {
      "x": -4,
      "y": 6,
      "z": 1,
      "name": "Empty",
      "level": 0
    },
    {
      "x": -4,
      "y": 7,
      "z": 1,
      "name": "Empty",
      "level": 0
    },
    {
      "x": -4,
      "y": 8,
      "z": 1,
      "name": "Empty",
      "level": 0
    },
    {
      "x": -4,
      "y": 2,
      "z": 2,
      "name": "Empty",
      "level": 0
    },
    {
      "x": -4,
      "y": 3,
      "z": 2,
      "name": "Empty",
      "level": 0
    },
    {
      "x": -4,
      "y": 4,
      "z": 2,
      "name": "Empty",
      "level": 0
    },
    {
      "x": -4,
      "y": 5,
      "z": 2,
      "name": "Empty",
      "level": 0
    },
    {
      "x": -4,
      "y": 6,
      "z": 2,
      "name": "Empty",
      "level": 0
    },
    {
      "x": -4,
      "y": 7,
      "z": 2,
      "name": "Empty",
      "level": 0
    },
    {
      "x": -4,
      "y": 3,
      "z": 3,
      "name": "Empty",
      "level": 0
    },
    {
      "x": -4,
      "y": 4,
      "z": 3,
      "name": "Empty",
      "level": 0
    },
    {
      "x": -4,
      "y": 5,
      "z": 3,
      "name": "Empty",
      "level": 0
    },
    {
      "x": -4,
      "y": 6,
      "z": 3,
      "name": "Empty",
      "level": 0
    },
    {
      "x": -3,
      "y": 6,
      "z": -7,
      "name": "Empty",
      "level": 0
    },
    {
      "x": -3,
      "y": 7,
      "z": -7,
      "name": "Empty",
      "level": 0
    },
    {
      "x": -3,
      "y": 7,
      "z": -6,
      "name": "Empty",
      "level": 0
    },
    {
      "x": -3,
      "y": 6,
      "z": -5,
      "name": "Empty",
      "level": 0
    },
    {
      "x": -3,
      "y": 3,
      "z": -4,
      "name": "Empty",
      "level": 0
    },
    {
      "x": -3,
      "y": 6,
      "z": -4,
      "name": "Empty",
      "level": 0
    },
    {
      "x": -3,
      "y": 3,
      "z": -3,
      "name": "Empty",
      "level": 0
    },
    {
      "x": -3,
      "y": 6,
      "z": -3,
      "name": "Empty",
      "level": 0
    },
    {
      "x": -3,
      "y": 2,
      "z": -2,
      "name": "Empty",
      "level": 0
    },
    {
      "x": -3,
      "y": 3,
      "z": -2,
      "name": "Empty",
      "level": 0
    },
    {
      "x": -3,
      "y": 4,
      "z": -2,
      "name": "Empty",
      "level": 0
    },
    {
      "x": -3,
      "y": 5,
      "z": -2,
      "name": "Empty",
      "level": 0
    },
    {
      "x": -3,
      "y": 6,
      "z": -2,
      "name": "Empty",
      "level": 0
    },
    {
      "x": -3,
      "y": 7,
      "z": -2,
      "name": "Empty",
      "level": 0
    },
    {
      "x": -3,
      "y": 2,
      "z": -1,
      "name": "Empty",
      "level": 0
    },
    {
      "x": -3,
      "y": 3,
      "z": -1,
      "name": "Empty",
      "level": 0
    },
    {
      "x": -3,
      "y": 4,
      "z": -1,
      "name": "Empty",
      "level": 0
    },
    {
      "x": -3,
      "y": 5,
      "z": -1,
      "name": "Empty",
      "level": 0
    },
    {
      "x": -3,
      "y": 6,
      "z": -1,
      "name": "Empty",
      "level": 0
    },
    {
      "x": -3,
      "y": 7,
      "z": -1,
      "name": "Empty",
      "level": 0
    },
    {
      "x": -3,
      "y": 2,
      "z": 0,
      "name": "Empty",
      "level": 0
    },
    {
      "x": -3,
      "y": 3,
      "z": 0,
      "name": "Empty",
      "level": 0
    },
    {
      "x": -3,
      "y": 4,
      "z": 0,
      "name": "Empty",
      "level": 0
    },
    {
      "x": -3,
      "y": 5,
      "z": 0,
      "name": "Empty",
      "level": 0
    },
    {
      "x": -3,
      "y": 6,
      "z": 0,
      "name": "Empty",
      "level": 0
    },
    {
      "x": -3,
      "y": 7,
      "z": 0,
      "name": "Empty",
      "level": 0
    },
    {
      "x": -3,
      "y": 2,
      "z": 1,
      "name": "Empty",
      "level": 0
    },
    {
      "x": -3,
      "y": 3,
      "z": 1,
      "name": "Empty",
      "level": 0
    },
    {
      "x": -3,
      "y": 4,
      "z": 1,
      "name": "Empty",
      "level": 0
    },
    {
      "x": -3,
      "y": 5,
      "z": 1,
      "name": "Empty",
      "level": 0
    },
    {
      "x": -3,
      "y": 6,
      "z": 1,
      "name": "Empty",
      "level": 0
    },
    {
      "x": -3,
      "y": 7,
      "z": 1,
      "name": "Empty",
      "level": 0
    },
    {
      "x": -3,
      "y": 8,
      "z": 1,
      "name": "Empty",
      "level": 0
    },
    {
      "x": -3,
      "y": 2,
      "z": 2,
      "name": "Empty",
      "level": 0
    },
    {
      "x": -3,
      "y": 3,
      "z": 2,
      "name": "Empty",
      "level": 0
    },
    {
      "x": -3,
      "y": 4,
      "z": 2,
      "name": "Empty",
      "level": 0
    },
    {
      "x": -3,
      "y": 5,
      "z": 2,
      "name": "Empty",
      "level": 0
    },
    {
      "x": -3,
      "y": 6,
      "z": 2,
      "name": "Empty",
      "level": 0
    },
    {
      "x": -3,
      "y": 7,
      "z": 2,
      "name": "Empty",
      "level": 0
    },
    {
      "x": -3,
      "y": 8,
      "z": 2,
      "name": "Empty",
      "level": 0
    },
    {
      "x": -3,
      "y": 2,
      "z": 3,
      "name": "Empty",
      "level": 0
    },
    {
      "x": -3,
      "y": 3,
      "z": 3,
      "name": "Empty",
      "level": 0
    },
    {
      "x": -3,
      "y": 4,
      "z": 3,
      "name": "Empty",
      "level": 0
    },
    {
      "x": -3,
      "y": 5,
      "z": 3,
      "name": "Empty",
      "level": 0
    },
    {
      "x": -3,
      "y": 6,
      "z": 3,
      "name": "Empty",
      "level": 0
    },
    {
      "x": -3,
      "y": 7,
      "z": 3,
      "name": "Empty",
      "level": 0
    },
    {
      "x": -3,
      "y": 2,
      "z": 4,
      "name": "Empty",
      "level": 0
    },
    {
      "x": -3,
      "y": 3,
      "z": 4,
      "name": "Empty",
      "level": 0
    },
    {
      "x": -3,
      "y": 6,
      "z": 4,
      "name": "Empty",
      "level": 0
    },
    {
      "x": -3,
      "y": 7,
      "z": 4,
      "name": "Empty",
      "level": 0
    },
    {
      "x": -2,
      "y": 3,
      "z": -2,
      "name": "Empty",
      "level": 0
    },
    {
      "x": -2,
      "y": 6,
      "z": -2,
      "name": "Empty",
      "level": 0
    },
    {
      "x": -2,
      "y": 3,
      "z": -1,
      "name": "Empty",
      "level": 0
    },
    {
      "x": -2,
      "y": 6,
      "z": -1,
      "name": "Empty",
      "level": 0
    },
    {
      "x": -2,
      "y": 2,
      "z": 0,
      "name": "Empty",
      "level": 0
    },
    {
      "x": -2,
      "y": 3,
      "z": 0,
      "name": "Empty",
      "level": 0
    },
    {
      "x": -2,
      "y": 4,
      "z": 0,
      "name": "Empty",
      "level": 0
    },
    {
      "x": -2,
      "y": 5,
      "z": 0,
      "name": "Empty",
      "level": 0
    },
    {
      "x": -2,
      "y": 6,
      "z": 0,
      "name": "Empty",
      "level": 0
    },
    {
      "x": -2,
      "y": 7,
      "z": 0,
      "name": "Empty",
      "level": 0
    },
    {
      "x": -2,
      "y": 2,
      "z": 1,
      "name": "Empty",
      "level": 0
    },
    {
      "x": -2,
      "y": 3,
      "z": 1,
      "name": "Empty",
      "level": 0
    },
    {
      "x": -2,
      "y": 4,
      "z": 1,
      "name": "Empty",
      "level": 0
    },
    {
      "x": -2,
      "y": 5,
      "z": 1,
      "name": "Empty",
      "level": 0
    },
    {
      "x": -2,
      "y": 6,
      "z": 1,
      "name": "Empty",
      "level": 0
    },
    {
      "x": -2,
      "y": 7,
      "z": 1,
      "name": "Empty",
      "level": 0
    },
    {
      "x": -2,
      "y": 2,
      "z": 2,
      "name": "Empty",
      "level": 0
    },
    {
      "x": -2,
      "y": 3,
      "z": 2,
      "name": "Empty",
      "level": 0
    },
    {
      "x": -2,
      "y": 4,
      "z": 2,
      "name": "Empty",
      "level": 0
    },
    {
      "x": -2,
      "y": 5,
      "z": 2,
      "name": "Empty",
      "level": 0
    },
    {
      "x": -2,
      "y": 6,
      "z": 2,
      "name": "Empty",
      "level": 0
    },
    {
      "x": -2,
      "y": 7,
      "z": 2,
      "name": "Empty",
      "level": 0
    },
    {
      "x": -2,
      "y": 8,
      "z": 2,
      "name": "Empty",
      "level": 0
    },
    {
      "x": -2,
      "y": 2,
      "z": 3,
      "name": "Empty",
      "level": 0
    },
    {
      "x": -2,
      "y": 3,
      "z": 3,
      "name": "Empty",
      "level": 0
    },
    {
      "x": -2,
      "y": 4,
      "z": 3,
      "name": "Empty",
      "level": 0
    },
    {
      "x": -2,
      "y": 5,
      "z": 3,
      "name": "Empty",
      "level": 0
    },
    {
      "x": -2,
      "y": 6,
      "z": 3,
      "name": "Empty",
      "level": 0
    },
    {
      "x": -2,
      "y": 7,
      "z": 3,
      "name": "Empty",
      "level": 0
    },
    {
      "x": -2,
      "y": 2,
      "z": 4,
      "name": "Empty",
      "level": 0
    },
    {
      "x": -2,
      "y": 3,
      "z": 4,
      "name": "Empty",
      "level": 0
    },
    {
      "x": -2,
      "y": 4,
      "z": 4,
      "name": "Empty",
      "level": 0
    },
    {
      "x": -2,
      "y": 5,
      "z": 4,
      "name": "Empty",
      "level": 0
    },
    {
      "x": -2,
      "y": 6,
      "z": 4,
      "name": "Empty",
      "level": 0
    },
    {
      "x": -2,
      "y": 7,
      "z": 4,
      "name": "Empty",
      "level": 0
    },
    {
      "x": -2,
      "y": 8,
      "z": 4,
      "name": "Empty",
      "level": 0
    },
    {
      "x": -2,
      "y": 2,
      "z": 5,
      "name": "Empty",
      "level": 0
    },
    {
      "x": -2,
      "y": 3,
      "z": 5,
      "name": "Empty",
      "level": 0
    },
    {
      "x": -2,
      "y": 6,
      "z": 5,
      "name": "Empty",
      "level": 0
    },
    {
      "x": -2,
      "y": 7,
      "z": 5,
      "name": "Empty",
      "level": 0
    },
    {
      "x": -1,
      "y": 3,
      "z": 0,
      "name": "Empty",
      "level": 0
    },
    {
      "x": -1,
      "y": 6,
      "z": 0,
      "name": "Empty",
      "level": 0
    },
    {
      "x": -1,
      "y": 2,
      "z": 1,
      "name": "Empty",
      "level": 0
    },
    {
      "x": -1,
      "y": 3,
      "z": 1,
      "name": "Empty",
      "level": 0
    },
    {
      "x": -1,
      "y": 4,
      "z": 1,
      "name": "Empty",
      "level": 0
    },
    {
      "x": -1,
      "y": 5,
      "z": 1,
      "name": "Empty",
      "level": 0
    },
    {
      "x": -1,
      "y": 6,
      "z": 1,
      "name": "Empty",
      "level": 0
    },
    {
      "x": -1,
      "y": 7,
      "z": 1,
      "name": "Empty",
      "level": 0
    },
    {
      "x": -1,
      "y": 2,
      "z": 2,
      "name": "Empty",
      "level": 0
    },
    {
      "x": -1,
      "y": 3,
      "z": 2,
      "name": "Empty",
      "level": 0
    },
    {
      "x": -1,
      "y": 4,
      "z": 2,
      "name": "Empty",
      "level": 0
    },
    {
      "x": -1,
      "y": 5,
      "z": 2,
      "name": "Empty",
      "level": 0
    },
    {
      "x": -1,
      "y": 6,
      "z": 2,
      "name": "Empty",
      "level": 0
    },
    {
      "x": -1,
      "y": 7,
      "z": 2,
      "name": "Empty",
      "level": 0
    },
    {
      "x": -1,
      "y": 8,
      "z": 2,
      "name": "Empty",
      "level": 0
    },
    {
      "x": -1,
      "y": 2,
      "z": 3,
      "name": "Empty",
      "level": 0
    },
    {
      "x": -1,
      "y": 3,
      "z": 3,
      "name": "Empty",
      "level": 0
    },
    {
      "x": -1,
      "y": 4,
      "z": 3,
      "name": "Empty",
      "level": 0
    },
    {
      "x": -1,
      "y": 5,
      "z": 3,
      "name": "Empty",
      "level": 0
    },
    {
      "x": -1,
      "y": 6,
      "z": 3,
      "name": "Empty",
      "level": 0
    },
    {
      "x": -1,
      "y": 7,
      "z": 3,
      "name": "Empty",
      "level": 0
    },
    {
      "x": -1,
      "y": 2,
      "z": 4,
      "name": "Empty",
      "level": 0
    },
    {
      "x": -1,
      "y": 3,
      "z": 4,
      "name": "Empty",
      "level": 0
    },
    {
      "x": -1,
      "y": 4,
      "z": 4,
      "name": "Empty",
      "level": 0
    },
    {
      "x": -1,
      "y": 5,
      "z": 4,
      "name": "Empty",
      "level": 0
    },
    {
      "x": -1,
      "y": 6,
      "z": 4,
      "name": "Empty",
      "level": 0
    },
    {
      "x": -1,
      "y": 7,
      "z": 4,
      "name": "Empty",
      "level": 0
    },
    {
      "x": -1,
      "y": 2,
      "z": 5,
      "name": "Empty",
      "level": 0
    },
    {
      "x": -1,
      "y": 3,
      "z": 5,
      "name": "Empty",
      "level": 0
    },
    {
      "x": -1,
      "y": 4,
      "z": 5,
      "name": "Empty",
      "level": 0
    },
    {
      "x": -1,
      "y": 5,
      "z": 5,
      "name": "Empty",
      "level": 0
    },
    {
      "x": -1,
      "y": 6,
      "z": 5,
      "name": "Empty",
      "level": 0
    },
    {
      "x": -1,
      "y": 7,
      "z": 5,
      "name": "Empty",
      "level": 0
    },
    {
      "x": -1,
      "y": 3,
      "z": 6,
      "name": "Empty",
      "level": 0
    },
    {
      "x": -1,
      "y": 6,
      "z": 6,
      "name": "Empty",
      "level": 0
    },
    {
      "x": 0,
      "y": 3,
      "z": 1,
      "name": "Empty",
      "level": 0
    },
    {
      "x": 0,
      "y": 6,
      "z": 1,
      "name": "Empty",
      "level": 0
    },
    {
      "x": 0,
      "y": 2,
      "z": 2,
      "name": "Empty",
      "level": 0
    },
    {
      "x": 0,
      "y": 3,
      "z": 2,
      "name": "Empty",
      "level": 0
    },
    {
      "x": 0,
      "y": 4,
      "z": 2,
      "name": "Empty",
      "level": 0
    },
    {
      "x": 0,
      "y": 5,
      "z": 2,
      "name": "Empty",
      "level": 0
    },
    {
      "x": 0,
      "y": 6,
      "z": 2,
      "name": "Empty",
      "level": 0
    },
    {
      "x": 0,
      "y": 7,
      "z": 2,
      "name": "Empty",
      "level": 0
    },
    {
      "x": 0,
      "y": 2,
      "z": 3,
      "name": "Empty",
      "level": 0
    },
    {
      "x": 0,
      "y": 3,
      "z": 3,
      "name": "Empty",
      "level": 0
    },
    {
      "x": 0,
      "y": 4,
      "z": 3,
      "name": "Empty",
      "level": 0
    },
    {
      "x": 0,
      "y": 5,
      "z": 3,
      "name": "Empty",
      "level": 0
    },
    {
      "x": 0,
      "y": 6,
      "z": 3,
      "name": "Empty",
      "level": 0
    },
    {
      "x": 0,
      "y": 7,
      "z": 3,
      "name": "Empty",
      "level": 0
    },
    {
      "x": 0,
      "y": 2,
      "z": 4,
      "name": "Empty",
      "level": 0
    },
    {
      "x": 0,
      "y": 3,
      "z": 4,
      "name": "Empty",
      "level": 0
    },
    {
      "x": 0,
      "y": 4,
      "z": 4,
      "name": "Empty",
      "level": 0
    },
    {
      "x": 0,
      "y": 5,
      "z": 4,
      "name": "Empty",
      "level": 0
    },
    {
      "x": 0,
      "y": 6,
      "z": 4,
      "name": "Empty",
      "level": 0
    },
    {
      "x": 0,
      "y": 7,
      "z": 4,
      "name": "Empty",
      "level": 0
    },
    {
      "x": 0,
      "y": 2,
      "z": 5,
      "name": "Empty",
      "level": 0
    },
    {
      "x": 0,
      "y": 3,
      "z": 5,
      "name": "Empty",
      "level": 0
    },
    {
      "x": 0,
      "y": 4,
      "z": 5,
      "name": "Empty",
      "level": 0
    },
    {
      "x": 0,
      "y": 5,
      "z": 5,
      "name": "Empty",
      "level": 0
    },
    {
      "x": 0,
      "y": 6,
      "z": 5,
      "name": "Empty",
      "level": 0
    },
    {
      "x": 0,
      "y": 7,
      "z": 5,
      "name": "Empty",
      "level": 0
    },
    {
      "x": 0,
      "y": 8,
      "z": 5,
      "name": "Empty",
      "level": 0
    },
    {
      "x": 0,
      "y": 3,
      "z": 6,
      "name": "Empty",
      "level": 0
    },
    {
      "x": 0,
      "y": 5,
      "z": 6,
      "name": "Empty",
      "level": 0
    },
    {
      "x": 0,
      "y": 6,
      "z": 6,
      "name": "Empty",
      "level": 0
    },
    {
      "x": 0,
      "y": 7,
      "z": 6,
      "name": "Empty",
      "level": 0
    },
    {
      "x": 1,
      "y": 3,
      "z": 2,
      "name": "Empty",
      "level": 0
    },
    {
      "x": 1,
      "y": 6,
      "z": 2,
      "name": "Empty",
      "level": 0
    },
    {
      "x": 1,
      "y": 2,
      "z": 3,
      "name": "Empty",
      "level": 0
    },
    {
      "x": 1,
      "y": 3,
      "z": 3,
      "name": "Empty",
      "level": 0
    },
    {
      "x": 1,
      "y": 4,
      "z": 3,
      "name": "Empty",
      "level": 0
    },
    {
      "x": 1,
      "y": 5,
      "z": 3,
      "name": "Empty",
      "level": 0
    },
    {
      "x": 1,
      "y": 6,
      "z": 3,
      "name": "Empty",
      "level": 0
    },
    {
      "x": 1,
      "y": 7,
      "z": 3,
      "name": "Empty",
      "level": 0
    },
    {
      "x": 1,
      "y": 2,
      "z": 4,
      "name": "Empty",
      "level": 0
    },
    {
      "x": 1,
      "y": 3,
      "z": 4,
      "name": "Empty",
      "level": 0
    },
    {
      "x": 1,
      "y": 4,
      "z": 4,
      "name": "Empty",
      "level": 0
    },
    {
      "x": 1,
      "y": 5,
      "z": 4,
      "name": "Empty",
      "level": 0
    },
    {
      "x": 1,
      "y": 6,
      "z": 4,
      "name": "Empty",
      "level": 0
    },
    {
      "x": 1,
      "y": 7,
      "z": 4,
      "name": "Empty",
      "level": 0
    },
    {
      "x": 1,
      "y": 1,
      "z": 5,
      "name": "Empty",
      "level": 0
    },
    {
      "x": 1,
      "y": 2,
      "z": 5,
      "name": "Empty",
      "level": 0
    },
    {
      "x": 1,
      "y": 3,
      "z": 5,
      "name": "Empty",
      "level": 0
    },
    {
      "x": 1,
      "y": 4,
      "z": 5,
      "name": "Empty",
      "level": 0
    },
    {
      "x": 1,
      "y": 5,
      "z": 5,
      "name": "Empty",
      "level": 0
    },
    {
      "x": 1,
      "y": 6,
      "z": 5,
      "name": "Empty",
      "level": 0
    },
    {
      "x": 1,
      "y": 7,
      "z": 5,
      "name": "Empty",
      "level": 0
    },
    {
      "x": 1,
      "y": 1,
      "z": 6,
      "name": "Empty",
      "level": 0
    },
    {
      "x": 1,
      "y": 2,
      "z": 6,
      "name": "Empty",
      "level": 0
    },
    {
      "x": 1,
      "y": 3,
      "z": 6,
      "name": "Empty",
      "level": 0
    },
    {
      "x": 1,
      "y": 4,
      "z": 6,
      "name": "Empty",
      "level": 0
    },
    {
      "x": 1,
      "y": 5,
      "z": 6,
      "name": "Empty",
      "level": 0
    },
    {
      "x": 1,
      "y": 6,
      "z": 6,
      "name": "Empty",
      "level": 0
    },
    {
      "x": 1,
      "y": 7,
      "z": 6,
      "name": "Empty",
      "level": 0
    },
    {
      "x": 1,
      "y": 2,
      "z": 7,
      "name": "Empty",
      "level": 0
    },
    {
      "x": 1,
      "y": 3,
      "z": 7,
      "name": "Empty",
      "level": 0
    },
    {
      "x": 1,
      "y": 4,
      "z": 7,
      "name": "Empty",
      "level": 0
    },
    {
      "x": 1,
      "y": 6,
      "z": 7,
      "name": "Empty",
      "level": 0
    },
    {
      "x": 2,
      "y": 3,
      "z": 2,
      "name": "Empty",
      "level": 0
    },
    {
      "x": 2,
      "y": 6,
      "z": 2,
      "name": "Empty",
      "level": 0
    },
    {
      "x": 2,
      "y": 2,
      "z": 3,
      "name": "Empty",
      "level": 0
    },
    {
      "x": 2,
      "y": 3,
      "z": 3,
      "name": "Empty",
      "level": 0
    },
    {
      "x": 2,
      "y": 4,
      "z": 3,
      "name": "Empty",
      "level": 0
    },
    {
      "x": 2,
      "y": 5,
      "z": 3,
      "name": "Empty",
      "level": 0
    },
    {
      "x": 2,
      "y": 6,
      "z": 3,
      "name": "Empty",
      "level": 0
    },
    {
      "x": 2,
      "y": 7,
      "z": 3,
      "name": "Empty",
      "level": 0
    },
    {
      "x": 2,
      "y": 2,
      "z": 4,
      "name": "Empty",
      "level": 0
    },
    {
      "x": 2,
      "y": 3,
      "z": 4,
      "name": "Empty",
      "level": 0
    },
    {
      "x": 2,
      "y": 4,
      "z": 4,
      "name": "Empty",
      "level": 0
    },
    {
      "x": 2,
      "y": 5,
      "z": 4,
      "name": "Empty",
      "level": 0
    },
    {
      "x": 2,
      "y": 6,
      "z": 4,
      "name": "Empty",
      "level": 0
    },
    {
      "x": 2,
      "y": 7,
      "z": 4,
      "name": "Empty",
      "level": 0
    },
    {
      "x": 2,
      "y": 2,
      "z": 5,
      "name": "Empty",
      "level": 0
    },
    {
      "x": 2,
      "y": 3,
      "z": 5,
      "name": "Empty",
      "level": 0
    },
    {
      "x": 2,
      "y": 4,
      "z": 5,
      "name": "Empty",
      "level": 0
    },
    {
      "x": 2,
      "y": 5,
      "z": 5,
      "name": "Empty",
      "level": 0
    },
    {
      "x": 2,
      "y": 6,
      "z": 5,
      "name": "Empty",
      "level": 0
    },
    {
      "x": 2,
      "y": 7,
      "z": 5,
      "name": "Empty",
      "level": 0
    },
    {
      "x": 2,
      "y": 8,
      "z": 5,
      "name": "Empty",
      "level": 0
    },
    {
      "x": 2,
      "y": 2,
      "z": 6,
      "name": "Empty",
      "level": 0
    },
    {
      "x": 2,
      "y": 3,
      "z": 6,
      "name": "Empty",
      "level": 0
    },
    {
      "x": 2,
      "y": 4,
      "z": 6,
      "name": "Empty",
      "level": 0
    },
    {
      "x": 2,
      "y": 5,
      "z": 6,
      "name": "Empty",
      "level": 0
    },
    {
      "x": 2,
      "y": 6,
      "z": 6,
      "name": "Empty",
      "level": 0
    },
    {
      "x": 2,
      "y": 7,
      "z": 6,
      "name": "Empty",
      "level": 0
    },
    {
      "x": 2,
      "y": 8,
      "z": 6,
      "name": "Empty",
      "level": 0
    },
    {
      "x": 2,
      "y": 3,
      "z": 7,
      "name": "Empty",
      "level": 0
    },
    {
      "x": 2,
      "y": 6,
      "z": 7,
      "name": "Empty",
      "level": 0
    },
    {
      "x": 2,
      "y": 7,
      "z": 7,
      "name": "Empty",
      "level": 0
    },
    {
      "x": 3,
      "y": 3,
      "z": 3,
      "name": "Empty",
      "level": 0
    },
    {
      "x": 3,
      "y": 6,
      "z": 3,
      "name": "Empty",
      "level": 0
    },
    {
      "x": 3,
      "y": 2,
      "z": 4,
      "name": "Empty",
      "level": 0
    },
    {
      "x": 3,
      "y": 3,
      "z": 4,
      "name": "Empty",
      "level": 0
    },
    {
      "x": 3,
      "y": 4,
      "z": 4,
      "name": "Empty",
      "level": 0
    },
    {
      "x": 3,
      "y": 5,
      "z": 4,
      "name": "Empty",
      "level": 0
    },
    {
      "x": 3,
      "y": 6,
      "z": 4,
      "name": "Empty",
      "level": 0
    },
    {
      "x": 3,
      "y": 7,
