{
  "version": 8,
  "blockIdVersion": 11,
  "anchorX": 0,
  "anchorY": 0,
  "anchorZ": 0,
  "blocks": [
    {
      "x": -8,
      "y": 2,
      "z": -3,
      "name": "Rock_Shale_Cobble",
      "rotation": 4
    },
    {
      "x": -8,
      "y": 2,
      "z": -2,
      "name": "Rock_Shale_Cobble",
      "rotation": 4
    },
    {
      "x": -8,
      "y": 3,
      "z": -2,
      "name": "Rock_Shale_Cobble_Half",
      "rotation": 7
    },
    {
      "x": -8,
      "y": 4,
      "z": -2,
      "name": "Rock_Shale_Cobble_Half",
      "rotation": 7
    },
    {
      "x": -8,
      "y": 5,
      "z": -2,
      "name": "Rock_Shale_Cobble_Half",
      "rotation": 7
    },
    {
      "x": -8,
      "y": 5,
      "z": 0,
      "name": "Plant_Moss_Wall_Green_Dark",
      "rotation": 3
    },
    {
      "x": -8,
      "y": 4,
      "z": 1,
      "name": "Rock_Shale_Cobble_Half",
      "rotation": 7
    },
    {
      "x": -8,
      "y": 5,
      "z": 1,
      "name": "Rock_Shale_Cobble_Half",
      "rotation": 7
    },
    {
      "x": -7,
      "y": 5,
      "z": -4,
      "name": "Plant_Moss_Wall_Green_Dark",
      "rotation": 2
    },
    {
      "x": -7,
      "y": 2,
      "z": -3,
      "name": "Rock_Shale_Cobble",
      "rotation": 4
    },
    {
      "x": -7,
      "y": 3,
      "z": -3,
      "name": "Rock_Shale_Cobble",
      "rotation": 4
    },
    {
      "x": -7,
      "y": 4,
      "z": -3,
      "name": "Rock_Shale_Cobble",
      "rotation": 4
    },
    {
      "x": -7,
      "y": 5,
      "z": -3,
      "name": "Rock_Shale_Cobble",
      "rotation": 4
    },
    {
      "x": -7,
      "y": 6,
      "z": -3,
      "name": "Plant_Moss_Rug_Green_Dark"
    },
    {
      "x": -7,
      "y": 9,
      "z": -3,
      "name": "Metal_Iron_Glowing_Pipe_Corner",
      "rotation": 18
    },
    {
      "x": -7,
      "y": 2,
      "z": -2,
      "name": "Rock_Shale_Cobble",
      "rotation": 4
    },
    {
      "x": -7,
      "y": 3,
      "z": -2,
      "name": "Rock_Shale_Cobble",
      "rotation": 4
    },
    {
      "x": -7,
      "y": 4,
      "z": -2,
      "name": "Rock_Shale_Cobble",
      "rotation": 4
    },
    {
      "x": -7,
      "y": 5,
      "z": -2,
      "name": "Rock_Shale_Cobble",
      "rotation": 4
    },
    {
      "x": -7,
      "y": 6,
      "z": -2,
      "name": "Rock_Shale_Cobble_Half",
      "rotation": 7
    },
    {
      "x": -7,
      "y": 7,
      "z": -2,
      "name": "Rock_Shale_Cobble_Half",
      "rotation": 7
    },
    {
      "x": -7,
      "y": 9,
      "z": -2,
      "name": "Metal_Iron_Glowing_Pipe",
      "rotation": 4
    },
    {
      "x": -7,
      "y": 4,
      "z": -1,
      "name": "Rock_Shale_Cobble",
      "rotation": 4
    },
    {
      "x": -7,
      "y": 5,
      "z": -1,
      "name": "Rock_Shale_Cobble",
      "rotation": 4
    },
    {
      "x": -7,
      "y": 8,
      "z": -1,
      "name": "Metal_Iron_Glowing_Pipe_Corner",
      "rotation": 2
    },
    {
      "x": -7,
      "y": 9,
      "z": -1,
      "name": "Metal_Iron_Glowing_Pipe_Corner",
      "rotation": 10
    },
    {
      "x": -7,
      "y": 4,
      "z": 0,
      "name": "Rock_Shale_Cobble",
      "rotation": 4
    },
    {
      "x": -7,
      "y": 5,
      "z": 0,
      "name": "Rock_Shale_Cobble",
      "rotation": 4
    },
    {
      "x": -7,
      "y": 6,
      "z": 0,
      "name": "Plant_Moss_Rug_Green_Dark"
    },
    {
      "x": -7,
      "y": 8,
      "z": 0,
      "name": "Metal_Iron_Glowing_Pipe",
      "rotation": 4
    },
    {
      "x": -7,
      "y": 4,
      "z": 1,
      "name": "Rock_Shale_Cobble",
      "rotation": 4
    },
    {
      "x": -7,
      "y": 5,
      "z": 1,
      "name": "Rock_Shale_Cobble",
      "rotation": 4
    },
    {
      "x": -7,
      "y": 6,
      "z": 1,
      "name": "Rock_Shale_Cobble_Half",
      "rotation": 7
    },
    {
      "x": -7,
      "y": 7,
      "z": 1,
      "name": "Rock_Shale_Cobble_Half",
      "rotation": 7
    },
    {
      "x": -7,
      "y": 8,
      "z": 1,
      "name": "Metal_Iron_Glowing_Pipe",
      "rotation": 4
    },
    {
      "x": -7,
      "y": 4,
      "z": 2,
      "name": "Rock_Shale_Cobble",
      "rotation": 4
    },
    {
      "x": -7,
      "y": 5,
      "z": 2,
      "name": "Rock_Shale_Cobble",
      "rotation": 4
    },
    {
      "x": -7,
      "y": 8,
      "z": 2,
      "name": "Metal_Iron_Glowing_Pipe",
      "rotation": 4
    },
    {
      "x": -7,
      "y": 7,
      "z": 3,
      "name": "Metal_Iron_Glowing_Pipe_Corner",
      "rotation": 3
    },
    {
      "x": -7,
      "y": 8,
      "z": 3,
      "name": "Metal_Iron_Glowing_Pipe_Corner",
      "rotation": 12
    },
    {
      "x": -6,
      "y": 9,
      "z": -4,
      "name": "Metal_Iron_Glowing_Pipe_Corner",
      "rotation": 18
    },
    {
      "x": -6,
      "y": 2,
      "z": -3,
      "name": "Deko_Block_Test",
      "rotation": 6
    },
    {
      "x": -6,
      "y": 3,
      "z": -3,
      "name": "Rock_Shale_Cobble",
      "rotation": 4
    },
    {
      "x": -6,
      "y": 4,
      "z": -3,
      "name": "Rock_Shale_Cobble",
      "rotation": 4
    },
    {
      "x": -6,
      "y": 5,
      "z": -3,
      "name": "Rock_Shale_Cobble",
      "rotation": 4
    },
    {
      "x": -6,
      "y": 6,
      "z": -3,
      "name": "Rock_Shale_Cobble",
      "rotation": 4
    },
    {
      "x": -6,
      "y": 7,
      "z": -3,
      "name": "Rock_Shale_Cobble",
      "rotation": 4
    },
    {
      "x": -6,
      "y": 9,
      "z": -3,
      "name": "Metal_Iron_Glowing_Pipe_Corner",
      "rotation": 16
    },
    {
      "x": -6,
      "y": 2,
      "z": -2,
      "name": "Rock_Shale_Cobble",
      "rotation": 4
    },
    {
      "x": -6,
      "y": 3,
      "z": -2,
      "name": "Rock_Shale_Cobble",
      "rotation": 4
    },
    {
      "x": -6,
      "y": 4,
      "z": -2,
      "name": "Rock_Shale_Cobble",
      "rotation": 4
    },
    {
      "x": -6,
      "y": 5,
      "z": -2,
      "name": "Rock_Shale_Cobble",
      "rotation": 4
    },
    {
      "x": -6,
      "y": 6,
      "z": -2,
      "name": "Rock_Shale_Cobble",
      "rotation": 4
    },
    {
      "x": -6,
      "y": 7,
      "z": -2,
      "name": "Rock_Shale_Cobble",
      "rotation": 4
    },
    {
      "x": -6,
      "y": 8,
      "z": -2,
      "name": "Rock_Shale_Cobble_Half",
      "rotation": 7
    },
    {
      "x": -6,
      "y": 9,
      "z": -2,
      "name": "Rock_Shale_Cobble_Half",
      "rotation": 7
    },
    {
      "x": -6,
      "y": 1,
      "z": -1,
      "name": "Rock_Shale_Cobble",
      "rotation": 6
    },
    {
      "x": -6,
      "y": 2,
      "z": -1,
      "name": "Rock_Shale_Cobble",
      "rotation": 4
    },
    {
      "x": -6,
      "y": 3,
      "z": -1,
      "name": "Rock_Shale_Cobble",
      "rotation": 4
    },
    {
      "x": -6,
      "y": 4,
      "z": -1,
      "name": "Rock_Shale_Cobble",
      "rotation": 4
    },
    {
      "x": -6,
      "y": 5,
      "z": -1,
      "name": "Rock_Shale_Cobble",
      "rotation": 4
    },
    {
      "x": -6,
      "y": 6,
      "z": -1,
      "name": "Rock_Shale_Cobble",
      "rotation": 4
    },
    {
      "x": -6,
      "y": 7,
      "z": -1,
      "name": "Rock_Shale_Cobble",
      "rotation": 4
    },
    {
      "x": -6,
      "y": 1,
      "z": 0,
      "name": "Rock_Shale_Cobble",
      "rotation": 6
    },
    {
      "x": -6,
      "y": 2,
      "z": 0,
      "name": "Rock_Shale_Cobble",
      "rotation": 4
    },
    {
      "x": -6,
      "y": 3,
      "z": 0,
      "name": "Rock_Shale_Cobble",
      "rotation": 4
    },
    {
      "x": -6,
      "y": 4,
      "z": 0,
      "name": "Rock_Shale_Cobble",
      "rotation": 4
    },
    {
      "x": -6,
      "y": 5,
      "z": 0,
      "name": "Rock_Shale_Cobble",
      "rotation": 4
    },
    {
      "x": -6,
      "y": 6,
      "z": 0,
      "name": "Rock_Shale_Cobble",
      "rotation": 4
    },
    {
      "x": -6,
      "y": 7,
      "z": 0,
      "name": "Rock_Shale_Cobble",
      "rotation": 4
    },
    {
      "x": -6,
      "y": 8,
      "z": 0,
      "name": "Plant_Moss_Rug_Green_Dark"
    },
    {
      "x": -6,
      "y": 1,
      "z": 1,
      "name": "Rock_Shale_Cobble",
      "rotation": 6
    },
    {
      "x": -6,
      "y": 2,
      "z": 1,
      "name": "Rock_Shale_Cobble",
      "rotation": 4
    },
    {
      "x": -6,
      "y": 3,
      "z": 1,
      "name": "Rock_Shale_Cobble",
      "rotation": 4
    },
    {
      "x": -6,
      "y": 4,
      "z": 1,
      "name": "Rock_Shale_Cobble",
      "rotation": 4
    },
    {
      "x": -6,
      "y": 5,
      "z": 1,
      "name": "Rock_Shale_Cobble",
      "rotation": 4
    },
    {
      "x": -6,
      "y": 6,
      "z": 1,
      "name": "Rock_Shale_Cobble",
      "rotation": 4
    },
    {
      "x": -6,
      "y": 7,
      "z": 1,
      "name": "Rock_Shale_Cobble",
      "rotation": 4
    },
    {
      "x": -6,
      "y": 8,
      "z": 1,
      "name": "Rock_Shale_Cobble_Half",
      "rotation": 7
    },
    {
      "x": -6,
      "y": 9,
      "z": 1,
      "name": "Rock_Shale_Cobble_Half",
      "rotation": 7
    },
    {
      "x": -6,
      "y": 4,
      "z": 2,
      "name": "Rock_Shale_Cobble",
      "rotation": 4
    },
    {
      "x": -6,
      "y": 5,
      "z": 2,
      "name": "Rock_Shale_Cobble",
      "rotation": 4
    },
    {
      "x": -6,
      "y": 6,
      "z": 2,
      "name": "Rock_Shale_Cobble",
      "rotation": 4
    },
    {
      "x": -6,
      "y": 7,
      "z": 2,
      "name": "Rock_Shale_Cobble",
      "rotation": 4
    },
    {
      "x": -6,
      "y": 8,
      "z": 2,
      "name": "Plant_Moss_Wall_Green_Dark",
      "rotation": 3
    },
    {
      "x": -6,
      "y": 9,
      "z": 2,
      "name": "Plant_Moss_Wall_Green_Dark",
      "rotation": 3
    },
    {
      "x": -6,
      "y": 5,
      "z": 3,
      "name": "Metal_Iron_Glowing_Pipe_Corner",
      "rotation": 3
    },
    {
      "x": -6,
      "y": 6,
      "z": 3,
      "name": "Metal_Iron_Glowing_Pipe"
    },
    {
      "x": -6,
      "y": 7,
      "z": 3,
      "name": "Metal_Iron_Glowing_Pipe_Corner",
      "rotation": 11
    },
    {
      "x": -5,
      "y": 9,
      "z": -4,
      "name": "Metal_Iron_Glowing_Pipe",
      "rotation": 5
    },
    {
      "x": -5,
      "y": 4,
      "z": -3,
      "name": "Rock_Shale_Cobble",
      "rotation": 4
    },
    {
      "x": -5,
      "y": 5,
      "z": -3,
      "name": "Rock_Shale_Cobble",
      "rotation": 4
    },
    {
      "x": -5,
      "y": 6,
      "z": -3,
      "name": "Rock_Shale_Cobble",
      "rotation": 4
    },
    {
      "x": -5,
      "y": 7,
      "z": -3,
      "name": "Rock_Shale_Cobble",
      "rotation": 4
    },
    {
      "x": -5,
      "y": 8,
      "z": -3,
      "name": "Rock_Shale_Cobble",
      "rotation": 4
    },
    {
      "x": -5,
      "y": 9,
      "z": -3,
      "name": "Rock_Shale_Cobble",
      "rotation": 4
    },
    {
      "x": -5,
      "y": 4,
      "z": -2,
      "name": "Rock_Shale_Cobble",
      "rotation": 4
    },
    {
      "x": -5,
      "y": 5,
      "z": -2,
      "name": "Rock_Shale_Cobble",
      "rotation": 4
    },
    {
      "x": -5,
      "y": 6,
      "z": -2,
      "name": "Rock_Shale_Cobble",
      "rotation": 4
    },
    {
      "x": -5,
      "y": 7,
      "z": -2,
      "name": "Rock_Shale_Cobble",
      "rotation": 4
    },
    {
      "x": -5,
      "y": 8,
      "z": -2,
      "name": "Rock_Shale_Cobble",
      "rotation": 4
    },
    {
      "x": -5,
      "y": 9,
      "z": -2,
      "name": "Rock_Shale_Cobble",
      "rotation": 4
    },
    {
      "x": -5,
      "y": 10,
      "z": -2,
      "name": "Rock_Shale_Cobble_Half",
      "rotation": 7
    },
    {
      "x": -5,
      "y": 1,
      "z": -1,
      "name": "Build_Lightsource_Cyan",
      "rotation": 3
    },
    {
      "x": -5,
      "y": 2,
      "z": -1,
      "name": "Build_Lightsource_Cyan",
      "rotation": 5
    },
    {
      "x": -5,
      "y": 3,
      "z": -1,
      "name": "Rock_Shale_Cobble",
      "rotation": 4
    },
    {
      "x": -5,
      "y": 4,
      "z": -1,
      "name": "Rock_Shale_Cobble",
      "rotation": 4
    },
    {
      "x": -5,
      "y": 5,
      "z": -1,
      "name": "Rock_Shale_Cobble",
      "rotation": 4
    },
    {
      "x": -5,
      "y": 6,
      "z": -1,
      "name": "Rock_Shale_Cobble",
      "rotation": 4
    },
    {
      "x": -5,
      "y": 7,
      "z": -1,
      "name": "Rock_Shale_Cobble",
      "rotation": 4
    },
    {
      "x": -5,
      "y": 8,
      "z": -1,
      "name": "Rock_Shale_Cobble",
      "rotation": 4
    },
    {
      "x": -5,
      "y": 9,
      "z": -1,
      "name": "Rock_Shale_Cobble",
      "rotation": 4
    },
    {
      "x": -5,
      "y": 1,
      "z": 0,
      "name": "Build_Lightsource_Cyan",
      "rotation": 3
    },
    {
      "x": -5,
      "y": 2,
      "z": 0,
      "name": "Build_Lightsource_Cyan",
      "rotation": 19
    },
    {
      "x": -5,
      "y": 3,
      "z": 0,
      "name": "Rock_Shale_Cobble",
      "rotation": 4
    },
    {
      "x": -5,
      "y": 4,
      "z": 0,
      "name": "Rock_Shale_Cobble",
      "rotation": 4
    },
    {
      "x": -5,
      "y": 5,
      "z": 0,
      "name": "Rock_Shale_Cobble",
      "rotation": 4
    },
    {
      "x": -5,
      "y": 6,
      "z": 0,
      "name": "Rock_Shale_Cobble",
      "rotation": 4
    },
    {
      "x": -5,
      "y": 7,
      "z": 0,
      "name": "Rock_Shale_Cobble",
      "rotation": 4
    },
    {
      "x": -5,
      "y": 8,
      "z": 0,
      "name": "Rock_Shale_Cobble",
      "rotation": 4
    },
    {
      "x": -5,
      "y": 9,
      "z": 0,
      "name": "Rock_Shale_Cobble",
      "rotation": 4
    },
    {
      "x": -5,
      "y": 10,
      "z": 0,
      "name": "Plant_Moss_Wall_Green_Dark",
      "rotation": 3
    },
    {
      "x": -5,
      "y": 1,
      "z": 1,
      "name": "Build_Lightsource_Cyan",
      "rotation": 5
    },
    {
      "x": -5,
      "y": 2,
      "z": 1,
      "name": "Rock_Shale_Cobble",
      "rotation": 1
    },
    {
      "x": -5,
      "y": 3,
      "z": 1,
      "name": "Rock_Shale_Cobble",
      "rotation": 4
    },
    {
      "x": -5,
      "y": 4,
      "z": 1,
      "name": "Rock_Shale_Cobble",
      "rotation": 4
    },
    {
      "x": -5,
      "y": 5,
      "z": 1,
      "name": "Rock_Shale_Cobble",
      "rotation": 4
    },
    {
      "x": -5,
      "y": 6,
      "z": 1,
      "name": "Rock_Shale_Cobble",
      "rotation": 4
    },
    {
      "x": -5,
      "y": 7,
      "z": 1,
      "name": "Rock_Shale_Cobble",
      "rotation": 4
    },
    {
      "x": -5,
      "y": 8,
      "z": 1,
      "name": "Rock_Shale_Cobble",
      "rotation": 4
    },
    {
      "x": -5,
      "y": 9,
      "z": 1,
      "name": "Rock_Shale_Cobble",
      "rotation": 4
    },
    {
      "x": -5,
      "y": 10,
      "z": 1,
      "name": "Rock_Shale_Cobble_Half",
      "rotation": 7
    },
    {
      "x": -5,
      "y": 4,
      "z": 2,
      "name": "Rock_Shale_Cobble",
      "rotation": 4
    },
    {
      "x": -5,
      "y": 5,
      "z": 2,
      "name": "Rock_Shale_Cobble",
      "rotation": 4
    },
    {
      "x": -5,
      "y": 6,
      "z": 2,
      "name": "Rock_Shale_Cobble",
      "rotation": 4
    },
    {
      "x": -5,
      "y": 7,
      "z": 2,
      "name": "Rock_Shale_Cobble",
      "rotation": 4
    },
    {
      "x": -5,
      "y": 8,
      "z": 2,
      "name": "Rock_Shale_Cobble",
      "rotation": 4
    },
    {
      "x": -5,
      "y": 9,
      "z": 2,
      "name": "Rock_Shale_Cobble",
      "rotation": 4
    },
    {
      "x": -5,
      "y": 10,
      "z": 2,
      "name": "Plant_Moss_Rug_Green_Dark"
    },
    {
      "x": -5,
      "y": 4,
      "z": 3,
      "name": "Metal_Iron_Glowing_Pipe"
    },
    {
      "x": -5,
      "y": 5,
      "z": 3,
      "name": "Metal_Iron_Glowing_Pipe_Corner",
      "rotation": 13
    },
    {
      "x": -5,
      "y": 9,
      "z": 3,
      "name": "Plant_Moss_Wall_Green_Dark"
    },
    {
      "x": -4,
      "y": 1,
      "z": -4,
      "name": "Rock_Shale_Brick_Smooth",
      "rotation": 1
    },
    {
      "x": -4,
      "y": 9,
      "z": -4,
      "name": "Metal_Iron_Glowing_Pipe",
      "rotation": 5
    },
    {
      "x": -4,
      "y": 1,
      "z": -3,
      "name": "Rock_Shale_Cobble",
      "rotation": 7
    },
    {
      "x": -4,
      "y": 3,
      "z": -3,
      "name": "Rock_Shale_Cobble",
      "rotation": 4
    },
    {
      "x": -4,
      "y": 4,
      "z": -3,
      "name": "Rock_Shale_Cobble",
      "rotation": 4
    },
    {
      "x": -4,
      "y": 5,
      "z": -3,
      "name": "Rock_Shale_Cobble",
      "rotation": 4
    },
    {
      "x": -4,
      "y": 6,
      "z": -3,
      "name": "Rock_Shale_Cobble",
      "rotation": 4
    },
    {
      "x": -4,
      "y": 7,
      "z": -3,
      "name": "Rock_Shale_Cobble",
      "rotation": 4
    },
    {
      "x": -4,
      "y": 8,
      "z": -3,
      "name": "Rock_Shale_Cobble",
      "rotation": 4
    },
    {
      "x": -4,
      "y": 9,
      "z": -3,
      "name": "Rock_Shale_Cobble",
      "rotation": 4
    },
    {
      "x": -4,
      "y": 10,
      "z": -3,
      "name": "Rock_Shale_Cobble",
      "rotation": 4
    },
    {
      "x": -4,
      "y": 1,
      "z": -2,
      "name": "Rock_Shale_Cobble",
      "rotation": 7
    },
    {
      "x": -4,
      "y": 2,
      "z": -2,
      "name": "Rock_Shale_Brick_Smooth",
      "rotation": 1
    },
    {
      "x": -4,
      "y": 3,
      "z": -2,
      "name": "Rock_Shale_Cobble",
      "rotation": 4
    },
    {
      "x": -4,
      "y": 4,
      "z": -2,
      "name": "Rock_Shale_Cobble",
      "rotation": 4
    },
    {
      "x": -4,
      "y": 5,
      "z": -2,
      "name": "Rock_Shale_Cobble",
      "rotation": 4
    },
    {
      "x": -4,
      "y": 6,
      "z": -2,
      "name": "Rock_Shale_Cobble",
      "rotation": 4
    },
    {
      "x": -4,
      "y": 7,
      "z": -2,
      "name": "Rock_Shale_Cobble",
      "rotation": 4
    },
    {
      "x": -4,
      "y": 8,
      "z": -2,
      "name": "Rock_Shale_Cobble",
      "rotation": 4
    },
    {
      "x": -4,
      "y": 9,
      "z": -2,
      "name": "Rock_Shale_Cobble",
      "rotation": 4
    },
    {
      "x": -4,
      "y": 10,
      "z": -2,
      "name": "Rock_Shale_Cobble",
      "rotation": 4
    },
    {
      "x": -4,
      "y": 11,
      "z": -2,
      "name": "Rock_Shale_Cobble_Half",
      "rotation": 7
    },
    {
      "x": -4,
      "y": 4,
      "z": -1,
      "name": "Build_Lightsource_Cyan",
      "rotation": 5
    },
    {
      "x": -4,
      "y": 5,
      "z": -1,
      "name": "Build_Lightsource_Cyan",
      "rotation": 5
    },
    {
      "x": -4,
      "y": 6,
      "z": -1,
      "name": "Rock_Shale_Cobble",
      "rotation": 4
    },
    {
      "x": -4,
      "y": 7,
      "z": -1,
      "name": "Rock_Shale_Cobble",
      "rotation": 4
    },
    {
      "x": -4,
      "y": 8,
      "z": -1,
      "name": "Rock_Shale_Cobble",
      "rotation": 4
    },
    {
      "x": -4,
      "y": 9,
      "z": -1,
      "name": "Rock_Shale_Cobble",
      "rotation": 4
    },
    {
      "x": -4,
      "y": 10,
      "z": -1,
      "name": "Rock_Shale_Cobble",
      "rotation": 4
    },
    {
      "x": -4,
      "y": 11,
      "z": -1,
      "name": "Plant_Moss_Rug_Green_Dark"
    },
    {
      "x": -4,
      "y": 4,
      "z": 0,
      "name": "Build_Lightsource_Cyan",
      "rotation": 19
    },
    {
      "x": -4,
      "y": 5,
      "z": 0,
      "name": "Build_Lightsource_Cyan",
      "rotation": 19
    },
    {
      "x": -4,
      "y": 6,
      "z": 0,
      "name": "Rock_Shale_Cobble",
      "rotation": 4
    },
    {
      "x": -4,
      "y": 7,
      "z": 0,
      "name": "Rock_Shale_Cobble",
      "rotation": 4
    },
    {
      "x": -4,
      "y": 8,
      "z": 0,
      "name": "Rock_Shale_Cobble",
      "rotation": 4
    },
    {
      "x": -4,
      "y": 9,
      "z": 0,
      "name": "Rock_Shale_Cobble",
      "rotation": 4
    },
    {
      "x": -4,
      "y": 10,
      "z": 0,
      "name": "Rock_Shale_Cobble",
      "rotation": 4
    },
    {
      "x": -4,
      "y": 11,
      "z": 0,
      "name": "Plant_Moss_Rug_Green_Dark"
    },
    {
      "x": -4,
      "y": 4,
      "z": 1,
      "name": "Rock_Shale_Cobble",
      "rotation": 4
    },
    {
      "x": -4,
      "y": 5,
      "z": 1,
      "name": "Rock_Shale_Cobble",
      "rotation": 4
    },
    {
      "x": -4,
      "y": 6,
      "z": 1,
      "name": "Rock_Shale_Cobble",
      "rotation": 4
    },
    {
      "x": -4,
      "y": 7,
      "z": 1,
      "name": "Rock_Shale_Cobble",
      "rotation": 4
    },
    {
      "x": -4,
      "y": 8,
      "z": 1,
      "name": "Rock_Shale_Cobble",
      "rotation": 4
    },
    {
      "x": -4,
      "y": 9,
      "z": 1,
      "name": "Rock_Shale_Cobble",
      "rotation": 4
    },
    {
      "x": -4,
      "y": 10,
      "z": 1,
      "name": "Rock_Shale_Cobble",
      "rotation": 4
    },
    {
      "x": -4,
      "y": 11,
      "z": 1,
      "name": "Rock_Shale_Cobble_Half",
      "rotation": 7
    },
    {
      "x": -4,
      "y": 4,
      "z": 2,
      "name": "Rock_Shale_Cobble",
      "rotation": 4
    },
    {
      "x": -4,
      "y": 5,
      "z": 2,
      "name": "Rock_Shale_Cobble",
      "rotation": 4
    },
    {
      "x": -4,
      "y": 6,
      "z": 2,
      "name": "Rock_Shale_Cobble",
      "rotation": 4
    },
    {
      "x": -4,
      "y": 7,
      "z": 2,
      "name": "Rock_Shale_Cobble",
      "rotation": 4
    },
    {
      "x": -4,
      "y": 8,
      "z": 2,
      "name": "Rock_Shale_Cobble",
      "rotation": 4
    },
    {
      "x": -4,
      "y": 9,
      "z": 2,
      "name": "Rock_Shale_Cobble",
      "rotation": 4
    },
    {
      "x": -4,
      "y": 10,
      "z": 2,
      "name": "Rock_Shale_Cobble",
      "rotation": 4
    },
    {
      "x": -3,
      "y": 9,
      "z": -4,
      "name": "Metal_Iron_Glowing_Pipe_Corner",
      "rotation": 1
    },
    {
      "x": -3,
      "y": 10,
      "z": -4,
      "name": "Metal_Iron_Glowing_Pipe_Corner",
      "rotation": 15
    },
    {
      "x": -3,
      "y": 1,
      "z": -3,
      "name": "Rock_Shale_Brick_Smooth",
      "rotation": 1
    },
    {
      "x": -3,
      "y": 2,
      "z": -3,
      "name": "Plant_Moss_Rug_Green_Dark"
    },
    {
      "x": -3,
      "y": 6,
      "z": -3,
      "name": "Rock_Shale_Cobble",
      "rotation": 4
    },
    {
      "x": -3,
      "y": 7,
      "z": -3,
      "name": "Rock_Shale_Cobble",
      "rotation": 4
    },
    {
      "x": -3,
      "y": 8,
      "z": -3,
      "name": "Rock_Shale_Cobble",
      "rotation": 4
    },
    {
      "x": -3,
      "y": 9,
      "z": -3,
      "name": "Rock_Shale_Cobble",
      "rotation": 4
    },
    {
      "x": -3,
      "y": 10,
      "z": -3,
      "name": "Rock_Shale_Cobble",
      "rotation": 4
    },
    {
      "x": -3,
      "y": 11,
      "z": -3,
      "name": "Rock_Shale_Cobble",
      "rotation": 4
    },
    {
      "x": -3,
      "y": 12,
      "z": -3,
      "name": "Plant_Moss_Rug_Green_Dark"
    },
    {
      "x": -3,
      "y": 1,
      "z": -2,
      "name": "Rock_Shale_Brick_Smooth",
      "rotation": 1
    },
    {
      "x": -3,
      "y": 3,
      "z": -2,
      "name": "Rock_Shale_Brick_Smooth",
      "rotation": 1
    },
    {
      "x": -3,
      "y": 4,
      "z": -2,
      "name": "Rock_Shale_Brick_Smooth",
      "rotation": 1
    },
    {
      "x": -3,
      "y": 5,
      "z": -2,
      "name": "Rock_Shale_Brick_Smooth",
      "rotation": 1
    },
    {
      "x": -3,
      "y": 6,
      "z": -2,
      "name": "Rock_Shale_Cobble",
      "rotation": 4
    },
    {
      "x": -3,
      "y": 7,
      "z": -2,
      "name": "Rock_Shale_Cobble",
      "rotation": 4
    },
    {
      "x": -3,
      "y": 8,
      "z": -2,
      "name": "Rock_Shale_Cobble",
      "rotation": 4
    },
    {
      "x": -3,
      "y": 9,
      "z": -2,
      "name": "Rock_Shale_Cobble",
      "rotation": 4
    },
    {
      "x": -3,
      "y": 10,
      "z": -2,
      "name": "Rock_Shale_Cobble",
      "rotation": 4
    },
    {
      "x": -3,
      "y": 11,
      "z": -2,
      "name": "Rock_Shale_Cobble",
      "rotation": 4
    },
    {
      "x": -3,
      "y": 12,
      "z": -2,
      "name": "Rock_Shale_Cobble_Half",
      "rotation": 1
    },
    {
      "x": -3,
      "y": 6,
      "z": -1,
      "name": "Build_Lightsource_Cyan",
      "rotation": 9
    },
    {
      "x": -3,
      "y": 7,
      "z": -1,
      "name": "Build_Lightsource_Cyan",
      "rotation": 9
    },
    {
      "x": -3,
      "y": 8,
      "z": -1,
      "name": "Rock_Shale_Cobble",
      "rotation": 4
    },
    {
      "x": -3,
      "y": 9,
      "z": -1,
      "name": "Rock_Shale_Cobble",
      "rotation": 4
    },
    {
      "x": -3,
      "y": 10,
      "z": -1,
      "name": "Rock_Shale_Cobble",
      "rotation": 4
    },
    {
      "x": -3,
      "y": 11,
      "z": -1,
      "name": "Rock_Shale_Cobble",
      "rotation": 4
    },
    {
      "x": -3,
      "y": 6,
      "z": 0,
      "name": "Build_Lightsource_Cyan",
      "rotation": 9
    },
    {
      "x": -3,
      "y": 7,
      "z": 0,
      "name": "Build_Lightsource_Cyan",
      "rotation": 5
    },
    {
      "x": -3,
      "y": 8,
      "z": 0,
      "name": "Rock_Shale_Cobble",
      "rotation": 4
    },
    {
      "x": -3,
      "y": 9,
      "z": 0,
      "name": "Rock_Shale_Cobble",
      "rotation": 4
    },
    {
      "x": -3,
      "y": 10,
      "z": 0,
      "name": "Rock_Shale_Cobble",
      "rotation": 4
    },
    {
      "x": -3,
      "y": 11,
      "z": 0,
      "name": "Rock_Shale_Cobble",
      "rotation": 4
    },
    {
      "x": -3,
      "y": 4,
      "z": 1,
      "name": "Rock_Shale_Brick_Smooth",
      "rotation": 1
    },
    {
      "x": -3,
      "y": 5,
      "z": 1,
      "name": "Rock_Shale_Brick_Smooth",
      "rotation": 1
    },
    {
      "x": -3,
      "y": 6,
      "z": 1,
      "name": "Rock_Shale_Cobble",
      "rotation": 4
    },
    {
      "x": -3,
      "y": 7,
      "z": 1,
      "name": "Rock_Shale_Cobble",
      "rotation": 4
    },
    {
      "x": -3,
      "y": 8,
      "z": 1,
      "name": "Rock_Shale_Cobble",
      "rotation": 4
    },
    {
      "x": -3,
      "y": 9,
      "z": 1,
      "name": "Rock_Shale_Cobble",
      "rotation": 4
    },
    {
      "x": -3,
      "y": 10,
      "z": 1,
      "name": "Rock_Shale_Cobble",
      "rotation": 4
    },
    {
      "x": -3,
      "y": 11,
      "z": 1,
      "name": "Rock_Shale_Cobble",
      "rotation": 4
    },
    {
      "x": -3,
      "y": 12,
      "z": 1,
      "name": "Rock_Shale_Cobble_Half",
      "rotation": 1
    },
    {
      "x": -3,
      "y": 6,
      "z": 2,
      "name": "Rock_Shale_Cobble",
      "rotation": 4
    },
    {
      "x": -3,
      "y": 7,
      "z": 2,
      "name": "Rock_Shale_Cobble",
      "rotation": 4
    },
    {
      "x": -3,
      "y": 8,
      "z": 2,
      "name": "Rock_Shale_Cobble",
      "rotation": 4
    },
    {
      "x": -3,
      "y": 9,
      "z": 2,
      "name": "Rock_Shale_Cobble",
      "rotation": 4
    },
    {
      "x": -3,
      "y": 10,
      "z": 2,
      "name": "Rock_Shale_Cobble",
      "rotation": 4
    },
    {
      "x": -3,
      "y": 11,
      "z": 2,
      "name": "Rock_Shale_Cobble",
      "rotation": 4
    },
    {
      "x": -3,
      "y": 12,
      "z": 2,
      "name": "Plant_Moss_Wall_Green_Dark",
      "rotation": 3
    },
    {
      "x": -2,
      "y": 10,
      "z": -4,
      "name": "Metal_Iron_Glowing_Pipe",
      "rotation": 5
    },
    {
      "x": -2,
      "y": 12,
      "z": -4,
      "name": "Plant_Moss_Wall_Green_Dark",
      "rotation": 2
    },
    {
      "x": -2,
      "y": 8,
      "z": -3,
      "name": "Rock_Shale_Cobble",
      "rotation": 4
    },
    {
      "x": -2,
      "y": 9,
      "z": -3,
      "name": "Rock_Shale_Cobble",
      "rotation": 4
    },
    {
      "x": -2,
      "y": 10,
      "z": -3,
      "name": "Rock_Shale_Cobble",
      "rotation": 4
    },
    {
      "x": -2,
      "y": 11,
      "z": -3,
      "name": "Rock_Shale_Cobble",
      "rotation": 4
    },
    {
      "x": -2,
      "y": 12,
      "z": -3,
      "name": "Rock_Shale_Cobble",
      "rotation": 4
    },
    {
      "x": -2,
      "y": 13,
      "z": -3,
      "name": "Plant_Moss_Rug_Green_Dark"
    },
    {
      "x": -2,
      "y": 6,
      "z": -2,
      "name": "Rock_Shale_Brick_Smooth",
      "rotation": 1
    },
    {
      "x": -2,
      "y": 7,
      "z": -2,
      "name": "Rock_Shale_Brick_Smooth",
      "rotation": 1
    },
    {
      "x": -2,
      "y": 8,
      "z": -2,
      "name": "Rock_Shale_Cobble",
      "rotation": 4
    },
    {
      "x": -2,
      "y": 9,
      "z": -2,
      "name": "Rock_Shale_Cobble",
      "rotation": 4
    },
    {
      "x": -2,
      "y": 10,
      "z": -2,
      "name": "Rock_Shale_Cobble",
      "rotation": 4
    },
    {
      "x": -2,
      "y": 11,
      "z": -2,
      "name": "Rock_Shale_Cobble",
      "rotation": 4
    },
    {
      "x": -2,
      "y": 12,
      "z": -2,
      "name": "Rock_Shale_Cobble",
      "rotation": 4
    },
    {
      "x": -2,
      "y": 13,
      "z": -2,
      "name": "Rock_Shale_Cobble_Half",
      "rotation": 1
    },
    {
      "x": -2,
      "y": 8,
      "z": -1,
      "name": "Build_Lightsource_Cyan",
      "rotation": 5
    },
    {
      "x": -2,
      "y": 9,
      "z": -1,
      "name": "Build_Lightsource_Cyan",
      "rotation": 9
    },
    {
      "x": -2,
      "y": 10,
      "z": -1,
      "name": "Rock_Shale_Cobble",
      "rotation": 4
    },
    {
      "x": -2,
      "y": 11,
      "z": -1,
      "name": "Rock_Shale_Cobble",
      "rotation": 4
    },
    {
      "x": -2,
      "y": 12,
      "z": -1,
      "name": "Rock_Shale_Cobble",
      "rotation": 4
    },
    {
      "x": -2,
      "y": 8,
      "z": 0,
      "name": "Build_Lightsource_Cyan",
      "rotation": 9
    },
    {
      "x": -2,
      "y": 9,
      "z": 0,
      "name": "Rock_Shale_Cobble",
      "rotation": 4
    },
    {
      "x": -2,
      "y": 10,
      "z": 0,
      "name": "Rock_Shale_Cobble",
      "rotation": 4
    },
    {
      "x": -2,
      "y": 11,
      "z": 0,
      "name": "Rock_Shale_Cobble",
      "rotation": 4
    },
    {
      "x": -2,
      "y": 12,
      "z": 0,
      "name": "Rock_Shale_Cobble",
      "rotation": 4
    },
    {
      "x": -2,
      "y": 6,
      "z": 1,
      "name": "Rock_Shale_Brick_Smooth",
      "rotation": 1
    },
    {
      "x": -2,
      "y": 7,
      "z": 1,
      "name": "Rock_Shale_Brick_Smooth",
      "rotation": 1
    },
    {
      "x": -2,
      "y": 8,
      "z": 1,
      "name": "Rock_Shale_Cobble",
      "rotation": 4
    },
    {
      "x": -2,
      "y": 9,
      "z": 1,
      "name": "Rock_Shale_Cobble",
      "rotation": 4
    },
    {
      "x": -2,
      "y": 10,
      "z": 1,
      "name": "Rock_Shale_Cobble",
      "rotation": 4
    },
    {
      "x": -2,
      "y": 11,
      "z": 1,
      "name": "Rock_Shale_Cobble",
      "rotation": 4
    },
    {
      "x": -2,
      "y": 12,
      "z": 1,
      "name": "Rock_Shale_Cobble",
      "rotation": 4
    },
    {
      "x": -2,
      "y": 13,
      "z": 1,
      "name": "Rock_Shale_Cobble_Half",
      "rotation": 1
    },
    {
      "x": -2,
      "y": 8,
      "z": 2,
      "name": "Rock_Shale_Cobble",
      "rotation": 4
    },
    {
      "x": -2,
      "y": 9,
      "z": 2,
      "name": "Rock_Shale_Cobble",
      "rotation": 4
    },
    {
      "x": -2,
      "y": 10,
      "z": 2,
      "name": "Rock_Shale_Cobble",
      "rotation": 4
    },
    {
      "x": -2,
      "y": 11,
      "z": 2,
      "name": "Rock_Shale_Cobble",
      "rotation": 4
    },
    {
      "x": -2,
      "y": 12,
      "z": 2,
      "name": "Rock_Shale_Cobble",
      "rotation": 4
    },
    {
      "x": -2,
      "y": 13,
      "z": 2,
      "name": "Plant_Moss_Rug_Green_Dark"
    },
    {
      "x": -1,
      "y": 10,
      "z": -4,
      "name": "Metal_Iron_Glowing_Pipe_Corner",
      "rotation": 24
    },
    {
      "x": -1,
      "y": 9,
      "z": -3,
      "name": "Rock_Shale_Cobble",
      "rotation": 4
    },
    {
      "x": -1,
      "y": 10,
      "z": -3,
      "name": "Rock_Shale_Cobble",
      "rotation": 4
    },
    {
      "x": -1,
      "y": 11,
      "z": -3,
      "name": "Rock_Shale_Cobble",
      "rotation": 4
    },
    {
      "x": -1,
      "y": 12,
      "z": -3,
      "name": "Rock_Shale_Cobble",
      "rotation": 4
    },
    {
      "x": -1,
      "y": 13,
      "z": -3,
      "name": "Rock_Shale_Cobble",
      "rotation": 4
    },
    {
      "x": -1,
      "y": 8,
      "z": -2,
      "name": "Rock_Shale_Brick_Smooth",
      "rotation": 1
    },
    {
      "x": -1,
      "y": 9,
      "z": -2,
      "name": "Rock_Shale_Cobble",
      "rotation": 4
    },
    {
      "x": -1,
      "y": 10,
      "z": -2,
      "name": "Rock_Shale_Cobble",
      "rotation": 4
    },
    {
      "x": -1,
      "y": 11,
      "z": -2,
      "name": "Rock_Shale_Cobble",
      "rotation": 4
    },
    {
      "x": -1,
      "y": 12,
      "z": -2,
      "name": "Rock_Shale_Cobble",
      "rotation": 4
    },
    {
      "x": -1,
      "y": 13,
      "z": -2,
      "name": "Rock_Shale_Cobble",
      "rotation": 4
    },
    {
      "x": -1,
      "y": 14,
      "z": -2,
      "name": "Rock_Shale_Cobble_Half",
      "rotation": 1
    },
    {
      "x": -1,
      "y": 9,
      "z": -1,
      "name": "Build_Lightsource_Cyan",
      "rotation": 9
    },
    {
      "x": -1,
      "y": 10,
      "z": -1,
      "name": "Rock_Shale_Cobble",
      "rotation": 4
    },
    {
      "x": -1,
      "y": 11,
      "z": -1,
      "name": "Rock_Shale_Cobble",
      "rotation": 4
    },
    {
      "x": -1,
      "y": 12,
      "z": -1,
      "name": "Rock_Shale_Cobble",
      "rotation": 4
    },
    {
      "x": -1,
      "y": 13,
      "z": -1,
      "name": "Rock_Shale_Cobble",
      "rotation": 4
    },
    {
      "x": -1,
      "y": 9,
      "z": 0,
      "name": "Build_Lightsource_Cyan",
      "rotation": 9
    },
    {
      "x": -1,
      "y": 10,
      "z": 0,
      "name": "Rock_Shale_Cobble",
      "rotation": 4
    },
    {
      "x": -1,
      "y": 11,
      "z": 0,
      "name": "Rock_Shale_Cobble",
      "rotation": 4
    },
    {
      "x": -1,
      "y": 12,
      "z": 0,
      "name": "Rock_Shale_Cobble",
      "rotation": 4
    },
    {
      "x": -1,
      "y": 13,
      "z": 0,
      "name": "Rock_Shale_Cobble",
      "rotation": 4
    },
    {
      "x": -1,
      "y": 8,
      "z": 1,
      "name": "Rock_Shale_Brick_Smooth",
      "rotation": 1
    },
    {
      "x": -1,
      "y": 9,
      "z": 1,
      "name": "Rock_Shale_Cobble",
      "rotation": 4
    },
    {
      "x": -1,
      "y": 10,
      "z": 1,
      "name": "Rock_Shale_Cobble",
      "rotation": 4
    },
    {
      "x": -1,
      "y": 11,
      "z": 1,
      "name": "Rock_Shale_Cobble",
      "rotation": 4
    },
    {
      "x": -1,
      "y": 12,
      "z": 1,
      "name": "Rock_Shale_Cobble",
      "rotation": 4
    },
    {
      "x": -1,
      "y": 13,
      "z": 1,
      "name": "Rock_Shale_Cobble",
      "rotation": 4
    },
    {
      "x": -1,
      "y": 14,
      "z": 1,
      "name": "Rock_Shale_Cobble_Half",
      "rotation": 1
    },
    {
      "x": -1,
      "y": 9,
      "z": 2,
      "name": "Rock_Shale_Cobble",
      "rotation": 4
    },
    {
      "x": -1,
      "y": 10,
      "z": 2,
      "name": "Rock_Shale_Cobble",
      "rotation": 4
    },
    {
      "x": -1,
      "y": 11,
      "z": 2,
      "name": "Rock_Shale_Cobble",
      "rotation": 4
    },
    {
      "x": -1,
      "y": 12,
      "z": 2,
      "name": "Rock_Shale_Cobble",
      "rotation": 4
    },
    {
      "x": -1,
      "y": 13,
      "z": 2,
      "name": "Rock_Shale_Cobble",
      "rotation": 4
    },
    {
      "x": 0,
      "y": 13,
      "z": -4,
      "name": "Plant_Moss_Wall_Green_Dark",
      "rotation": 2
    },
    {
      "x": 0,
      "y": 10,
      "z": -3,
      "name": "Rock_Shale_Cobble",
      "rotation": 4
    },
    {
      "x": 0,
      "y": 11,
      "z": -3,
      "name": "Rock_Shale_Cobble",
      "rotation": 4
    },
    {
      "x": 0,
      "y": 12,
      "z": -3,
      "name": "Rock_Shale_Cobble",
      "rotation": 4
    },
    {
      "x": 0,
      "y": 13,
      "z": -3,
      "name": "Rock_Shale_Cobble",
      "rotation": 4
    },
    {
      "x": 0,
      "y": 14,
      "z": -3,
      "name": "Plant_Moss_Rug_Green_Dark"
    },
    {
      "x": 0,
      "y": 9,
      "z": -2,
      "name": "Rock_Shale_Brick_Smooth",
      "rotation": 1
    },
    {
      "x": 0,
      "y": 10,
      "z": -2,
      "name": "Rock_Shale_Cobble",
      "rotation": 4
    },
    {
      "x": 0,
      "y": 11,
      "z": -2,
      "name": "Rock_Shale_Cobble",
      "rotation": 4
    },
    {
      "x": 0,
      "y": 12,
      "z": -2,
      "name": "Rock_Shale_Cobble",
      "rotation": 4
    },
    {
      "x": 0,
      "y": 13,
      "z": -2,
      "name": "Rock_Shale_Cobble",
      "rotation": 4
    },
    {
      "x": 0,
      "y": 14,
      "z": -2,
      "name": "Rock_Shale_Cobble_Half",
      "rotation": 1
    },
    {
      "x": 0,
      "y": 10,
      "z": -1,
      "name": "Build_Lightsource_Cyan",
      "rotation": 5
    },
    {
      "x": 0,
      "y": 11,
      "z": -1,
      "name": "Rock_Shale_Cobble",
      "rotation": 4
    },
    {
      "x": 0,
      "y": 12,
      "z": -1,
      "name": "Rock_Shale_Cobble",
      "rotation": 4
    },
    {
      "x": 0,
      "y": 13,
      "z": -1,
      "name": "Rock_Shale_Cobble",
      "rotation": 4
    },
    {
      "x": 0,
      "y": 14,
      "z": -1,
      "name": "Plant_Moss_Rug_Green_Dark"
    },
    {
      "x": 0,
      "y": 10,
      "z": 0,
      "name": "Build_Lightsource_Cyan",
      "rotation": 5
    },
    {
      "x": 0,
      "y": 11,
      "z": 0,
      "name": "Rock_Shale_Cobble",
      "rotation": 4
    },
    {
      "x": 0,
      "y": 12,
      "z": 0,
      "name": "Rock_Shale_Cobble",
      "rotation": 4
    },
    {
      "x": 0,
      "y": 13,
      "z": 0,
      "name": "Rock_Shale_Cobble",
      "rotation": 4
    },
    {
      "x": 0,
      "y": 9,
      "z": 1,
      "name": "Rock_Shale_Brick_Smooth",
      "rotation": 1
    },
    {
      "x": 0,
      "y": 10,
      "z": 1,
      "name": "Rock_Shale_Cobble",
      "rotation": 4
    },
    {
      "x": 0,
      "y": 11,
      "z": 1,
      "name": "Rock_Shale_Cobble",
      "rotation": 4
    },
    {
      "x": 0,
      "y": 12,
      "z": 1,
      "name": "Rock_Shale_Cobble",
      "rotation": 4
    },
    {
      "x": 0,
      "y": 13,
      "z": 1,
      "name": "Rock_Shale_Cobble",
      "rotation": 4
    },
    {
      "x": 0,
      "y": 14,
      "z": 1,
      "name": "Rock_Shale_Cobble_Half",
      "rotation": 1
    },
    {
      "x": 0,
      "y": 10,
      "z": 2,
      "name": "Rock_Shale_Cobble",
      "rotation": 4
    },
    {
      "x": 0,
      "y": 11,
      "z": 2,
      "name": "Rock_Shale_Cobble",
      "rotation": 4
    },
    {
      "x": 0,
      "y": 12,
      "z": 2,
      "name": "Rock_Shale_Cobble",
      "rotation": 4
    },
    {
      "x": 0,
      "y": 13,
      "z": 2,
      "name": "Rock_Shale_Cobble",
      "rotation": 4
    },
    {
      "x": 1,
      "y": 11,
      "z": -3,
      "name": "Rock_Shale_Cobble",
      "rotation": 4
    },
    {
      "x": 1,
      "y": 12,
      "z": -3,
      "name": "Rock_Shale_Cobble",
      "rotation": 4
    },
    {
      "x": 1,
      "y": 13,
      "z": -3,
      "name": "Rock_Shale_Cobble",
      "rotation": 4
    },
    {
      "x": 1,
      "y": 14,
      "z": -3,
      "name": "Rock_Shale_Cobble",
      "rotation": 4
    },
    {
      "x": 1,
      "y": 10,
      "z": -2,
      "name": "Rock_Shale_Brick_Smooth",
      "rotation": 1
    },
    {
      "x": 1,
      "y": 11,
      "z": -2,
      "name": "Rock_Shale_Cobble",
      "rotation": 4
    },
    {
      "x": 1,
      "y": 12,
      "z": -2,
      "name": "Rock_Shale_Cobble",
      "rotation": 4
    },
    {
      "x": 1,
      "y": 13,
      "z": -2,
      "name": "Rock_Shale_Cobble",
      "rotation": 4
    },
    {
      "x": 1,
      "y": 14,
      "z": -2,
      "name": "Rock_Shale_Cobble",
      "rotation": 4
    },
    {
      "x": 1,
      "y": 15,
      "z": -2,
      "name": "Rock_Shale_Cobble_Half",
      "rotation": 1
    },
    {
      "x": 1,
      "y": 11,
      "z": -1,
      "name": "Build_Lightsource_Cyan",
      "rotation": 5
    },
    {
      "x": 1,
      "y": 12,
      "z": -1,
      "name": "Rock_Shale_Cobble",
      "rotation": 4
    },
    {
      "x": 1,
      "y": 13,
      "z": -1,
      "name": "Rock_Shale_Cobble",
      "rotation": 4
    },
    {
      "x": 1,
      "y": 14,
      "z": -1,
      "name": "Rock_Shale_Cobble",
      "rotation": 4
    },
    {
      "x": 1,
      "y": 11,
      "z": 0,
      "name": "Build_Lightsource_Cyan",
      "rotation": 5
    },
    {
      "x": 1,
      "y": 12,
      "z": 0,
      "name": "Rock_Shale_Cobble",
      "rotation": 5
    },
    {
      "x": 1,
      "y": 13,
      "z": 0,
      "name": "Rock_Shale_Cobble",
      "rotation": 4
    },
    {
      "x": 1,
      "y": 14,
      "z": 0,
      "name": "Rock_Shale_Cobble",
      "rotation": 4
    },
    {
      "x": 1,
      "y": 15,
      "z": 0,
      "name": "Plant_Moss_Rug_Green_Dark"
    },
    {
      "x": 1,
      "y": 10,
      "z": 1,
      "name": "Rock_Shale_Brick_Smooth",
      "rotation": 1
    },
    {
      "x": 1,
      "y": 11,
      "z": 1,
      "name": "Rock_Shale_Cobble",
      "rotation": 4
    },
    {
      "x": 1,
      "y": 12,
      "z": 1,
      "name": "Rock_Shale_Cobble",
      "rotation": 4
    },
    {
      "x": 1,
      "y": 13,
      "z": 1,
      "name": "Rock_Shale_Cobble",
      "rotation": 4
    },
    {
      "x": 1,
      "y": 14,
      "z": 1,
      "name": "Rock_Shale_Cobble",
      "rotation": 4
    },
    {
      "x": 1,
      "y": 15,
      "z": 1,
      "name": "Rock_Shale_Cobble_Half",
      "rotation": 1
    },
    {
      "x": 1,
      "y": 11,
      "z": 2,
      "name": "Rock_Shale_Cobble",
      "rotation": 4
    },
    {
      "x": 1,
      "y": 12,
      "z": 2,
      "name": "Rock_Shale_Cobble",
      "rotation": 4
    },
    {
      "x": 1,
      "y": 13,
      "z": 2,
      "name": "Rock_Shale_Cobble",
      "rotation": 4
    },
    {
      "x": 1,
      "y": 14,
      "z": 2,
      "name": "Rock_Shale_Cobble",
      "rotation": 4
    },
    {
      "x": 1,
      "y": 15,
      "z": 2,
      "name": "Plant_Moss_Rug_Green_Dark",
      "support": 15
    },
    {
      "x": 1,
      "y": 13,
      "z": 3,
      "name": "Plant_Moss_Wall_Green_Dark",
      "support": 15
    },
    {
      "x": 1,
      "y": 14,
      "z": 3,
      "name": "Plant_Moss_Wall_Green_Dark",
      "support": 15
    },
    {
      "x": 2,
      "y": 13,
      "z": -4,
      "name": "Plant_Moss_Wall_Green_Dark",
      "rotation": 2
    },
    {
      "x": 2,
      "y": 14,
      "z": -4,
      "name": "Plant_Moss_Wall_Green_Dark",
      "rotation": 2
    },
    {
      "x": 2,
      "y": 11,
      "z": -3,
      "name": "Rock_Shale_Cobble",
      "rotation": 4
    },
    {
      "x": 2,
      "y": 12,
      "z": -3,
      "name": "Rock_Shale_Cobble",
      "rotation": 4
    },
    {
      "x": 2,
      "y": 13,
      "z": -3,
      "name": "Rock_Shale_Cobble",
      "rotation": 4
    },
    {
      "x": 2,
      "y": 14,
      "z": -3,
      "name": "Rock_Shale_Cobble",
      "rotation": 4
    },
    {
      "x": 2,
      "y": 15,
      "z": -3,
      "name": "Plant_Moss_Rug_Green_Dark"
    },
    {
      "x": 2,
      "y": 10,
      "z": -2,
      "name": "Rock_Shale_Brick_Smooth",
      "rotation": 1
    },
    {
      "x": 2,
      "y": 11,
      "z": -2,
      "name": "Rock_Shale_Cobble",
      "rotation": 4
    },
    {
      "x": 2,
      "y": 12,
      "z": -2,
      "name": "Rock_Shale_Cobble",
      "rotation": 4
    },
    {
      "x": 2,
      "y": 13,
      "z": -2,
      "name": "Rock_Shale_Cobble",
      "rotation": 4
    },
    {
      "x": 2,
      "y": 14,
      "z": -2,
      "name": "Rock_Shale_Cobble",
      "rotation": 4
    },
    {
      "x": 2,
      "y": 15,
      "z": -2,
      "name": "Rock_Shale_Cobble_Half",
      "rotation": 1
    },
    {
      "x": 2,
      "y": 11,
      "z": -1,
      "name": "Build_Lightsource_Cyan",
      "rotation": 5
    },
    {
      "x": 2,
      "y": 12,
      "z": -1,
      "name": "Rock_Shale_Cobble",
      "rotation": 4
    },
    {
      "x": 2,
      "y": 13,
      "z": -1,
      "name": "Rock_Shale_Cobble",
      "rotation": 4
    },
    {
      "x": 2,
      "y": 14,
      "z": -1,
      "name": "Rock_Shale_Cobble",
      "rotation": 4
    },
    {
      "x": 2,
      "y": 11,
      "z": 0,
      "name": "Build_Lightsource_Cyan",
      "rotation": 5
    },
    {
      "x": 2,
      "y": 12,
      "z": 0,
      "name": "Rock_Shale_Cobble",
      "rotation": 4
    },
    {
      "x": 2,
      "y": 13,
      "z": 0,
      "name": "Rock_Shale_Cobble",
      "rotation": 4
    },
    {
      "x": 2,
      "y": 14,
      "z": 0,
      "name": "Rock_Shale_Cobble",
      "rotation": 4
    },
    {
      "x": 2,
      "y": 10,
      "z": 1,
      "name": "Rock_Shale_Brick_Smooth",
      "rotation": 1
    },
    {
      "x": 2,
      "y": 11,
      "z": 1,
      "name": "Rock_Shale_Cobble",
      "rotation": 5
    },
    {
      "x": 2,
      "y": 12,
      "z": 1,
      "name": "Rock_Shale_Cobble",
      "rotation": 4
    },
    {
      "x": 2,
      "y": 13,
      "z": 1,
      "name": "Rock_Shale_Cobble",
      "rotation": 4
    },
    {
      "x": 2,
      "y": 14,
      "z": 1,
      "name": "Rock_Shale_Cobble",
      "rotation": 4
    },
    {
      "x": 2,
      "y": 15,
      "z": 1,
      "name": "Rock_Shale_Cobble_Half",
      "rotation": 1
    },
    {
      "x": 2,
      "y": 11,
      "z": 2,
      "name": "Rock_Shale_Cobble",
      "rotation": 4
    },
    {
      "x": 2,
      "y": 12,
      "z": 2,
      "name": "Rock_Shale_Cobble",
      "rotation": 4
    },
    {
      "x": 2,
      "y": 13,
      "z": 2,
      "name": "Rock_Shale_Cobble",
      "rotation": 4
    },
    {
      "x": 2,
      "y": 14,
      "z": 2,
      "name": "Rock_Shale_Cobble",
      "rotation": 4
    },
    {
      "x": 3,
      "y": 12,
      "z": -3,
      "name": "Rock_Shale_Cobble",
      "rotation": 4
    },
    {
      "x": 3,
      "y": 13,
      "z": -3,
      "name": "Rock_Shale_Cobble",
      "rotation": 4
    },
    {
      "x": 3,
      "y": 14,
      "z": -3,
      "name": "Rock_Shale_Cobble",
      "rotation": 4
    },
    {
      "x": 3,
      "y": 15,
      "z": -3,
      "name": "Rock_Shale_Cobble",
      "rotation": 4
    },
    {
      "x": 3,
      "y": 11,
      "z": -2,
      "name": "Rock_Shale_Brick_Smooth",
      "rotation": 1
    },
    {
      "x": 3,
      "y": 12,
      "z": -2,
      "name": "Rock_Shale_Cobble",
      "rotation": 4
    },
    {
      "x": 3,
      "y": 13,
      "z": -2,
      "name": "Rock_Shale_Cobble",
      "rotation": 4
    },
    {
      "x": 3,
      "y": 14,
      "z": -2,
      "name": "Rock_Shale_Cobble",
      "rotation": 4
    },
    {
      "x": 3,
      "y": 15,
      "z": -2,
      "name": "Rock_Shale_Cobble",
      "rotation": 4
    },
    {
      "x": 3,
      "y": 12,
      "z": -1,
      "name": "Build_Lightsource_Cyan",
      "rotation": 9
    },
    {
      "x": 3,
      "y": 13,
      "z": -1,
      "name": "Rock_Shale_Cobble",
      "rotation": 4
    },
    {
      "x": 3,
      "y": 14,
      "z": -1,
      "name": "Rock_Shale_Cobble",
      "rotation": 4
    },
    {
      "x": 3,
      "y": 15,
      "z": -1,
      "name": "Rock_Shale_Cobble",
      "rotation": 4
    },
    {
      "x": 3,
      "y": 12,
      "z": 0,
      "name": "Build_Lightsource_Cyan",
      "rotation": 9
    },
    {
      "x": 3,
      "y": 13,
      "z": 0,
      "name": "Rock_Shale_Cobble",
      "rotation": 4
    },
    {
      "x": 3,
      "y": 14,
      "z": 0,
      "name": "Rock_Shale_Cobble",
      "rotation": 4
    },
    {
      "x": 3,
      "y": 15,
      "z": 0,
      "name": "Rock_Shale_Cobble",
      "rotation": 4
    },
    {
      "x": 3,
      "y": 11,
      "z": 1,
      "name": "Rock_Shale_Brick_Smooth",
      "rotation": 1
    },
    {
      "x": 3,
      "y": 12,
      "z": 1,
      "name": "Rock_Shale_Cobble",
      "rotation": 1
    },
    {
      "x": 3,
      "y": 13,
      "z": 1,
      "name": "Rock_Shale_Cobble",
      "rotation": 4
    },
    {
      "x": 3,
      "y": 14,
      "z": 1,
      "name": "Plant_Moss_Rug_Green_Dark",
      "support": 15
    },
    {
      "x": 3,
      "y": 12,
      "z": 2,
      "name": "Rock_Shale_Cobble",
      "rotation": 4
    },
    {
      "x": 3,
      "y": 13,
      "z": 2,
      "name": "Rock_Shale_Cobble",
      "rotation": 4
    },
    {
      "x": 3,
      "y": 14,
      "z": 2,
      "name": "Plant_Moss_Rug_Green_Dark",
      "support": 15
    },
    {
      "x": 4,
      "y": 12,
      "z": -3,
      "name": "Rock_Shale_Cobble",
      "rotation": 4
    },
    {
      "x": 4,
      "y": 13,
      "z": -3,
      "name": "Rock_Shale_Cobble",
      "rotation": 4
    },
    {
      "x": 4,
      "y": 14,
      "z": -3,
      "name": "Rock_Shale_Cobble",
      "rotation": 4
    },
    {
      "x": 4,
      "y": 15,
      "z": -3,
      "name": "Rock_Shale_Cobble",
      "rotation": 4
    },
    {
      "x": 4,
      "y": 11,
      "z": -2,
      "name": "Rock_Shale_Brick_Smooth",
      "rotation": 1
    },
    {
      "x": 4,
      "y": 12,
      "z": -2,
      "name": "Rock_Shale_Cobble",
      "rotation": 4
    },
    {
      "x": 4,
      "y": 13,
      "z": -2,
      "name": "Rock_Shale_Cobble",
      "rotation": 4
    },
    {
      "x": 4,
      "y": 14,
      "z": -2,
      "name": "Rock_Shale_Cobble",
      "rotation": 4
    },
    {
      "x": 4,
      "y": 15,
      "z": -2,
      "name": "Rock_Shale_Cobble",
      "rotation": 4
    },
    {
      "x": 4,
      "y": 16,
      "z": -2,
      "name": "Plant_Moss_Rug_Green_Dark",
      "support": 15
    },
    {
      "x": 4,
      "y": 12,
      "z": -1,
      "name": "Build_Lightsource_Cyan",
      "rotation": 9
    },
    {
      "x": 4,
      "y": 13,
      "z": -1,
      "name": "Rock_Shale_Cobble",
      "rotation": 4
    },
    {
      "x": 4,
      "y": 14,
      "z": -1,
      "name": "Rock_Shale_Cobble",
      "rotation": 4
    },
    {
      "x": 4,
      "y": 15,
      "z": -1,
      "name": "Rock_Shale_Cobble",
      "rotation": 4
    },
    {
      "x": 4,
      "y": 16,
      "z": -1,
      "name": "Plant_Moss_Rug_Green_Dark",
      "support": 15
    },
    {
      "x": 4,
      "y": 12,
      "z": 0,
      "name": "Build_Lightsource_Cyan",
      "rotation": 9
    },
    {
      "x": 4,
      "y": 13,
      "z": 0,
      "name": "Rock_Shale_Cobble",
      "rotation": 4
    },
    {
      "x": 4,
      "y": 14,
      "z": 0,
      "name": "Rock_Shale_Cobble",
      "rotation": 4
    },
    {
      "x": 4,
      "y": 15,
      "z": 0,
      "name": "Rock_Shale_Cobble",
      "rotation": 4
    },
    {
      "x": 4,
      "y": 16,
      "z": 0,
      "name": "Plant_Moss_Rug_Green_Dark",
      "support": 15
    },
    {
      "x": 4,
      "y": 11,
      "z": 1,
      "name": "Rock_Shale_Brick_Smooth",
      "rotation": 1
    },
    {
      "x": 4,
      "y": 12,
      "z": 1,
      "name": "Rock_Shale_Cobble",
      "rotation": 4
    },
    {
      "x": 4,
      "y": 13,
      "z": 1,
      "name": "Rock_Shale_Cobble",
      "rotation": 4
    },
    {
      "x": 4,
      "y": 12,
      "z": 2,
      "name": "Rock_Shale_Cobble",
      "rotation": 4
    },
    {
      "x": 4,
      "y": 13,
      "z": 2,
      "name": "Rock_Shale_Cobble",
      "rotation": 4
    },
    {
      "x": 4,
      "y": 14,
      "z": 2,
      "name": "Plant_Moss_Rug_Green_Dark",
      "support": 15
    },
    {
      "x": 5,
      "y": 15,
      "z": -4,
      "name": "Plant_Moss_Wall_Green_Dark",
      "rotation": 2
    },
    {
      "x": 5,
      "y": 12,
      "z": -3,
      "name": "Rock_Shale_Cobble",
      "rotation": 5
    },
    {
      "x": 5,
      "y": 13,
      "z": -3,
      "name": "Rock_Shale_Cobble",
      "rotation": 4
    },
    {
      "x": 5,
      "y": 14,
      "z": -3,
      "name": "Rock_Shale_Cobble",
      "rotation": 4
    },
    {
      "x": 5,
      "y": 15,
      "z": -3,
      "name": "Rock_Shale_Cobble",
      "rotation": 4
    },
    {
      "x": 5,
      "y": 16,
      "z": -3,
      "name": "Plant_Moss_Rug_Green_Dark",
      "support": 15
    },
    {
      "x": 5,
      "y": 11,
      "z": -2,
      "name": "Rock_Shale_Brick_Smooth",
      "rotation": 1
    },
    {
      "x": 5,
      "y": 12,
      "z": -2,
      "name": "Rock_Shale_Cobble",
      "rotation": 4
    },
    {
      "x": 5,
      "y": 13,
      "z": -2,
      "name": "Rock_Shale_Cobble",
      "rotation": 4
    },
    {
      "x": 5,
      "y": 14,
      "z": -2,
      "name": "Rock_Shale_Cobble",
      "rotation": 4
    },
    {
      "x": 5,
      "y": 15,
      "z": -2,
      "name": "Rock_Shale_Cobble",
      "rotation": 4
    },
    {
      "x": 5,
      "y": 12,
      "z": -1,
      "name": "Build_Lightsource_Cyan",
      "rotation": 9
    },
    {
      "x": 5,
      "y": 13,
      "z": -1,
      "name": "Plant_Moss_Rug_Green_Dark",
      "support": 15
    },
    {
      "x": 5,
      "y": 12,
      "z": 0,
      "name": "Build_Lightsource_Cyan",
      "rotation": 9
    },
    {
      "x": 5,
      "y": 11,
      "z": 1,
      "name": "Rock_Shale_Brick_Smooth",
      "rotation": 1
    },
    {
      "x": 5,
      "y": 12,
      "z": 1,
      "name": "Rock_Shale_Cobble",
      "rotation": 4
    },
    {
      "x": 5,
      "y": 13,
      "z": 1,
      "name": "Rock_Shale_Cobble",
      "rotation": 4
    },
    {
      "x": 5,
      "y": 12,
      "z": 2,
      "name": "Rock_Shale_Cobble",
      "rotation": 4
    },
    {
      "x": 5,
      "y": 13,
      "z": 2,
      "name": "Rock_Shale_Cobble",
      "rotation": 4
    },
    {
      "x": 6,
      "y": 12,
      "z": -2,
      "name": "Rock_Shale_Brick_Smooth",
      "rotation": 1
    },
    {
      "x": 6,
      "y": 12,
      "z": 1,
      "name": "Rock_Shale_Brick_Smooth",
      "rotation": 1
    },
    {
      "x": 6,
      "y": 13,
      "z": 1,
      "name": "Rock_Shale_Cobble",
      "rotation": 4
    },
    {
      "x": 6,
      "y": 12,
      "z": 2,
      "name": "Rock_Shale_Cobble",
      "rotation": 17
    },
    {
      "x": 6,
      "y": 13,
      "z": 2,
      "name": "Rock_Shale_Cobble",
      "rotation": 4
    },
    {
      "x": 7,
      "y": 11,
      "z": -3,
      "name": "Rock_Shale_Brick_Smooth",
      "rotation": 1
    },
    {
      "x": 7,
      "y": 12,
      "z": -3,
      "name": "Plant_Moss_Rug_Green_Dark",
      "support": 15
    },
    {
      "x": 7,
      "y": 11,
      "z": -2,
      "name": "Rock_Shale_Brick_Smooth",
      "rotation": 1
    },
    {
      "x": 7,
      "y": 12,
      "z": -2,
      "name": "Rock_Shale_Cobble",
      "rotation": 1
    },
    {
      "x": 7,
      "y": 11,
      "z": -1,
      "name": "Rock_Shale_Brick_Smooth",
      "rotation": 1
    },
    {
      "x": 7,
      "y": 12,
      "z": -1,
      "name": "Rock_Shale_Cobble",
      "rotation": 17
    },
    {
      "x": 7,
      "y": 11,
      "z": 0,
      "name": "Rock_Shale_Brick_Smooth",
      "rotation": 1
    },
    {
      "x": 7,
      "y": 12,
      "z": 0,
      "name": "Rock_Shale_Cobble",
      "rotation": 17
    },
    {
      "x": 7,
      "y": 11,
      "z": 1,
      "name": "Rock_Shale_Brick_Smooth",
      "rotation": 1
    },
    {
      "x": 7,
      "y": 12,
      "z": 1,
      "name": "Rock_Shale_Cobble",
      "rotation": 17
    },
    {
      "x": 7,
      "y": 13,
      "z": 1,
      "name": "Rock_Shale_Cobble",
      "rotation": 17
    },
    {
      "x": 7,
      "y": 11,
      "z": 2,
      "name": "Rock_Shale_Brick_Smooth",
      "rotation": 1
    },
    {
      "x": 7,
      "y": 12,
      "z": 2,
      "name": "Rock_Shale_Cobble",
      "rotation": 17
    },
    {
      "x": 7,
      "y": 13,
      "z": 2,
      "name": "Rock_Shale_Cobble",
      "rotation": 17
    },
    {
      "x": 7,
      "y": 12,
      "z": 3,
      "name": "Rock_Shale_Brick_Smooth",
      "rotation": 1
    },
    {
      "x": 7,
      "y": 13,
      "z": 3,
      "name": "Rock_Shale_Cobble",
      "rotation": 1
    },
    {
      "x": 7,
      "y": 13,
      "z": 4,
      "name": "Rock_Shale_Brick_Smooth",
      "rotation": 1
    },
    {
      "x": 7,
      "y": 14,
      "z": 4,
      "name": "Rock_Shale_Brick_Smooth",
      "rotation": 1
    },
    {
      "x": 7,
      "y": 15,
      "z": 4,
      "name": "Rock_Shale_Brick_Smooth",
      "rotation": 1
    },
    {
      "x": 8,
      "y": 12,
      "z": -2,
      "name": "Rock_Shale_Cobble",
      "rotation": 17
    },
    {
      "x": 8,
      "y": 12,
      "z": -1,
      "name": "Rock_Shale_Cobble",
      "rotation": 1
    },
    {
      "x": 8,
      "y": 13,
      "z": -1,
      "name": "Build_Lightsource_Cyan",
      "rotation": 5
    },
    {
      "x": 8,
      "y": 14,
      "z": -1,
      "name": "Plant_Moss_Rug_Green_Dark",
      "support": 15
    },
    {
      "x": 8,
      "y": 12,
      "z": 0,
      "name": "Rock_Shale_Cobble",
      "rotation": 1
    },
    {
      "x": 8,
      "y": 13,
      "z": 0,
      "name": "Build_Lightsource_Cyan",
      "rotation": 1
    },
    {
      "x": 8,
      "y": 12,
      "z": 1,
      "name": "Rock_Shale_Cobble",
      "rotation": 17
    },
    {
      "x": 8,
      "y": 13,
      "z": 1,
      "name": "Rock_Shale_Cobble",
      "rotation": 17
    },
    {
      "x": 8,
      "y": 14,
      "z": 1,
      "name": "Plant_Moss_Rug_Green_Dark",
      "support": 15
    },
    {
      "x": 8,
      "y": 13,
      "z": 2,
      "name": "Rock_Shale_Cobble",
      "rotation": 17
    },
    {
      "x": 8,
      "y": 14,
      "z": 2,
      "name": "Rock_Shale_Cobble",
      "rotation": 17
    },
    {
      "x": 8,
      "y": 15,
      "z": 2,
      "name": "Rock_Shale_Cobble",
      "rotation": 17
    },
    {
      "x": 8,
      "y": 16,
      "z": 2,
      "name": "Plant_Moss_Rug_Green_Dark",
      "support": 15
    },
    {
      "x": 8,
      "y": 13,
      "z": 3,
      "name": "Rock_Shale_Cobble",
      "rotation": 1
    },
    {
      "x": 8,
      "y": 14,
      "z": 3,
      "name": "Rock_Shale_Cobble",
      "rotation": 1
    },
    {
      "x": 8,
      "y": 15,
      "z": 3,
      "name": "Rock_Shale_Cobble",
      "rotation": 1
    },
    {
      "x": 8,
      "y": 16,
      "z": 3,
      "name": "Plant_Moss_Rug_Green_Dark",
      "support": 15
    }
  ],
  "fluids": [
    {
      "x": -8,
      "y": 2,
      "z": -3,
      "name": "Empty",
      "level": 0
    },
    {
      "x": -8,
      "y": 2,
      "z": -2,
      "name": "Empty",
      "level": 0
    },
    {
      "x": -8,
      "y": 3,
      "z": -2,
      "name": "Empty",
      "level": 0
    },
    {
      "x": -8,
      "y": 4,
      "z": -2,
      "name": "Empty",
      "level": 0
    },
    {
      "x": -8,
      "y": 5,
      "z": -2,
      "name": "Empty",
      "level": 0
    },
    {
      "x": -8,
      "y": 5,
      "z": 0,
      "name": "Empty",
      "level": 0
    },
    {
      "x": -8,
      "y": 4,
      "z": 1,
      "name": "Empty",
      "level": 0
    },
    {
      "x": -8,
      "y": 5,
      "z": 1,
      "name": "Empty",
      "level": 0
    },
    {
      "x": -7,
      "y": 5,
      "z": -4,
      "name": "Empty",
      "level": 0
    },
    {
      "x": -7,
      "y": 2,
      "z": -3,
      "name": "Empty",
      "level": 0
    },
    {
      "x": -7,
      "y": 3,
      "z": -3,
      "name": "Empty",
      "level": 0
    },
    {
      "x": -7,
      "y": 4,
      "z": -3,
      "name": "Empty",
      "level": 0
    },
    {
      "x": -7,
      "y": 5,
      "z": -3,
      "name": "Empty",
      "level": 0
    },
    {
      "x": -7,
      "y": 6,
      "z": -3,
      "name": "Empty",
      "level": 0
    },
    {
      "x": -7,
      "y": 9,
      "z": -3,
      "name": "Empty",
      "level": 0
    },
    {
      "x": -7,
      "y": 2,
      "z": -2,
      "name": "Empty",
      "level": 0
    },
    {
      "x": -7,
      "y": 3,
      "z": -2,
      "name": "Empty",
      "level": 0
    },
    {
      "x": -7,
      "y": 4,
      "z": -2,
      "name": "Empty",
      "level": 0
    },
    {
      "x": -7,
      "y": 5,
      "z": -2,
      "name": "Empty",
      "level": 0
    },
    {
      "x": -7,
      "y": 6,
      "z": -2,
      "name": "Empty",
      "level": 0
    },
    {
      "x": -7,
      "y": 7,
      "z": -2,
      "name": "Empty",
      "level": 0
    },
    {
      "x": -7,
      "y": 9,
      "z": -2,
      "name": "Empty",
      "level": 0
    },
    {
      "x": -7,
      "y": 4,
      "z": -1,
      "name": "Empty",
      "level": 0
    },
    {
      "x": -7,
      "y": 5,
      "z": -1,
      "name": "Empty",
      "level": 0
    },
    {
      "x": -7,
      "y": 8,
      "z": -1,
      "name": "Empty",
      "level": 0
    },
    {
      "x": -7,
      "y": 9,
      "z": -1,
      "name": "Empty",
      "level": 0
    },
    {
      "x": -7,
      "y": 4,
      "z": 0,
      "name": "Empty",
      "level": 0
    },
    {
      "x": -7,
      "y": 5,
      "z": 0,
      "name": "Empty",
      "level": 0
    },
    {
      "x": -7,
      "y": 6,
      "z": 0,
      "name": "Empty",
      "level": 0
    },
    {
      "x": -7,
      "y": 8,
      "z": 0,
      "name": "Empty",
      "level": 0
    },
    {
      "x": -7,
      "y": 4,
      "z": 1,
      "name": "Empty",
      "level": 0
    },
    {
      "x": -7,
      "y": 5,
      "z": 1,
      "name": "Empty",
      "level": 0
    },
    {
      "x": -7,
      "y": 6,
      "z": 1,
      "name": "Empty",
      "level": 0
    },
    {
      "x": -7,
      "y": 7,
      "z": 1,
      "name": "Empty",
      "level": 0
    },
    {
      "x": -7,
      "y": 8,
      "z": 1,
      "name": "Empty",
      "level": 0
    },
    {
      "x": -7,
      "y": 4,
      "z": 2,
      "name": "Empty",
      "level": 0
    },
    {
      "x": -7,
      "y": 5,
      "z": 2,
      "name": "Empty",
      "level": 0
    },
    {
      "x": -7,
      "y": 8,
      "z": 2,
      "name": "Empty",
      "level": 0
    },
    {
      "x": -7,
      "y": 7,
      "z": 3,
      "name": "Empty",
      "level": 0
    },
    {
      "x": -7,
      "y": 8,
      "z": 3,
      "name": "Empty",
      "level": 0
    },
    {
      "x": -6,
      "y": 9,
      "z": -4,
      "name": "Empty",
      "level": 0
    },
    {
      "x": -6,
      "y": 2,
      "z": -3,
      "name": "Empty",
      "level": 0
    },
    {
      "x": -6,
      "y": 3,
      "z": -3,
      "name": "Empty",
      "level": 0
    },
    {
      "x": -6,
      "y": 4,
      "z": -3,
      "name": "Empty",
      "level": 0
    },
    {
      "x": -6,
      "y": 5,
      "z": -3,
      "name": "Empty",
      "level": 0
    },
    {
      "x": -6,
      "y": 6,
      "z": -3,
      "name": "Empty",
      "level": 0
    },
    {
      "x": -6,
      "y": 7,
      "z": -3,
      "name": "Empty",
      "level": 0
    },
    {
      "x": -6,
      "y": 9,
      "z": -3,
      "name": "Empty",
      "level": 0
    },
    {
      "x": -6,
      "y": 2,
      "z": -2,
      "name": "Empty",
      "level": 0
    },
    {
      "x": -6,
      "y": 3,
      "z": -2,
      "name": "Empty",
      "level": 0
    },
    {
      "x": -6,
      "y": 4,
      "z": -2,
      "name": "Empty",
      "level": 0
    },
    {
      "x": -6,
      "y": 5,
      "z": -2,
      "name": "Empty",
      "level": 0
    },
    {
      "x": -6,
      "y": 6,
      "z": -2,
      "name": "Empty",
      "level": 0
    },
    {
      "x": -6,
      "y": 7,
      "z": -2,
      "name": "Empty",
      "level": 0
    },
    {
      "x": -6,
      "y": 8,
      "z": -2,
      "name": "Empty",
      "level": 0
    },
    {
      "x": -6,
      "y": 9,
      "z": -2,
      "name": "Empty",
      "level": 0
    },
    {
      "x": -6,
      "y": 1,
      "z": -1,
      "name": "Empty",
      "level": 0
    },
    {
      "x": -6,
      "y": 2,
      "z": -1,
      "name": "Empty",
      "level": 0
    },
    {
      "x": -6,
      "y": 3,
      "z": -1,
      "name": "Empty",
      "level": 0
    },
    {
      "x": -6,
      "y": 4,
      "z": -1,
      "name": "Empty",
      "level": 0
    },
    {
      "x": -6,
      "y": 5,
      "z": -1,
      "name": "Empty",
      "level": 0
    },
    {
      "x": -6,
      "y": 6,
      "z": -1,
      "name": "Empty",
      "level": 0
    },
    {
      "x": -6,
      "y": 7,
      "z": -1,
      "name": "Empty",
      "level": 0
    },
    {
      "x": -6,
      "y": 1,
      "z": 0,
      "name": "Empty",
      "level": 0
    },
    {
      "x": -6,
      "y": 2,
      "z": 0,
      "name": "Empty",
      "level": 0
    },
    {
      "x": -6,
      "y": 3,
      "z": 0,
      "name": "Empty",
      "level": 0
    },
    {
      "x": -6,
      "y": 4,
      "z": 0,
      "name": "Empty",
      "level": 0
    },
    {
      "x": -6,
      "y": 5,
      "z": 0,
      "name": "Empty",
      "level": 0
    },
    {
      "x": -6,
      "y": 6,
      "z": 0,
      "name": "Empty",
      "level": 0
    },
    {
      "x": -6,
      "y": 7,
      "z": 0,
      "name": "Empty",
      "level": 0
    },
    {
      "x": -6,
      "y": 8,
      "z": 0,
      "name": "Empty",
      "level": 0
    },
    {
      "x": -6,
      "y": 1,
      "z": 1,
      "name": "Empty",
      "level": 0
    },
    {
      "x": -6,
      "y": 2,
      "z": 1,
      "name": "Empty",
      "level": 0
    },
    {
      "x": -6,
      "y": 3,
      "z": 1,
      "name": "Empty",
      "level": 0
    },
    {
      "x": -6,
      "y": 4,
      "z": 1,
      "name": "Empty",
      "level": 0
    },
    {
      "x": -6,
      "y": 5,
      "z": 1,
      "name": "Empty",
      "level": 0
    },
    {
      "x": -6,
      "y": 6,
      "z": 1,
      "name": "Empty",
      "level": 0
    },
    {
      "x": -6,
      "y": 7,
      "z": 1,
      "name": "Empty",
      "level": 0
    },
    {
      "x": -6,
      "y": 8,
      "z": 1,
      "name": "Empty",
      "level": 0
    },
    {
      "x": -6,
      "y": 9,
      "z": 1,
      "name": "Empty",
      "level": 0
    },
    {
      "x": -6,
      "y": 4,
      "z": 2,
      "name": "Empty",
      "level": 0
    },
    {
      "x": -6,
      "y": 5,
      "z": 2,
      "name": "Empty",
      "level": 0
    },
    {
      "x": -6,
      "y": 6,
      "z": 2,
      "name": "Empty",
      "level": 0
    },
    {
      "x": -6,
      "y": 7,
      "z": 2,
      "name": "Empty",
      "level": 0
    },
    {
      "x": -6,
      "y": 8,
      "z": 2,
      "name": "Empty",
      "level": 0
    },
    {
      "x": -6,
      "y": 9,
      "z": 2,
      "name": "Empty",
      "level": 0
    },
    {
      "x": -6,
      "y": 5,
      "z": 3,
      "name": "Empty",
      "level": 0
    },
    {
      "x": -6,
      "y": 6,
      "z": 3,
      "name": "Empty",
      "level": 0
    },
    {
      "x": -6,
      "y": 7,
      "z": 3,
      "name": "Empty",
      "level": 0
    },
    {
      "x": -5,
      "y": 9,
      "z": -4,
      "name": "Empty",
      "level": 0
    },
    {
      "x": -5,
      "y": 4,
      "z": -3,
      "name": "Empty",
      "level": 0
    },
    {
      "x": -5,
      "y": 5,
      "z": -3,
      "name": "Empty",
      "level": 0
    },
    {
      "x": -5,
      "y": 6,
      "z": -3,
      "name": "Empty",
      "level": 0
    },
    {
      "x": -5,
      "y": 7,
      "z": -3,
      "name": "Empty",
      "level": 0
    },
    {
      "x": -5,
      "y": 8,
      "z": -3,
      "name": "Empty",
      "level": 0
    },
    {
      "x": -5,
      "y": 9,
      "z": -3,
      "name": "Empty",
      "level": 0
    },
    {
      "x": -5,
      "y": 4,
      "z": -2,
      "name": "Empty",
      "level": 0
    },
    {
      "x": -5,
      "y": 5,
      "z": -2,
      "name": "Empty",
      "level": 0
    },
    {
      "x": -5,
      "y": 6,
      "z": -2,
      "name": "Empty",
      "level": 0
    },
    {
      "x": -5,
      "y": 7,
      "z": -2,
      "name": "Empty",
      "level": 0
    },
    {
      "x": -5,
      "y": 8,
      "z": -2,
      "name": "Empty",
      "level": 0
    },
    {
      "x": -5,
      "y": 9,
      "z": -2,
      "name": "Empty",
      "level": 0
    },
    {
      "x": -5,
      "y": 10,
      "z": -2,
      "name": "Empty",
      "level": 0
    },
    {
      "x": -5,
      "y": 1,
      "z": -1,
      "name": "Empty",
      "level": 0
    },
    {
      "x": -5,
      "y": 2,
      "z": -1,
      "name": "Empty",
      "level": 0
    },
    {
      "x": -5,
      "y": 3,
      "z": -1,
      "name": "Empty",
      "level": 0
    },
    {
      "x": -5,
      "y": 4,
      "z": -1,
      "name": "Empty",
      "level": 0
    },
    {
      "x": -5,
      "y": 5,
      "z": -1,
      "name": "Empty",
      "level": 0
    },
    {
      "x": -5,
      "y": 6,
      "z": -1,
      "name": "Empty",
      "level": 0
    },
    {
      "x": -5,
      "y": 7,
      "z": -1,
      "name": "Empty",
      "level": 0
    },
    {
      "x": -5,
      "y": 8,
      "z": -1,
      "name": "Empty",
      "level": 0
    },
    {
      "x": -5,
      "y": 9,
      "z": -1,
      "name": "Empty",
      "level": 0
    },
    {
      "x": -5,
      "y": 1,
      "z": 0,
      "name": "Empty",
      "level": 0
    },
    {
      "x": -5,
      "y": 2,
      "z": 0,
      "name": "Empty",
      "level": 0
    },
    {
      "x": -5,
      "y": 3,
      "z": 0,
      "name": "Empty",
      "level": 0
    },
    {
      "x": -5,
      "y": 4,
      "z": 0,
      "name": "Empty",
      "level": 0
    },
    {
      "x": -5,
      "y": 5,
      "z": 0,
      "name": "Empty",
      "level": 0
    },
    {
      "x": -5,
      "y": 6,
      "z": 0,
      "name": "Empty",
      "level": 0
    },
    {
      "x": -5,
      "y": 7,
      "z": 0,
      "name": "Empty",
      "level": 0
    },
    {
      "x": -5,
      "y": 8,
      "z": 0,
      "name": "Empty",
      "level": 0
    },
    {
      "x": -5,
      "y": 9,
      "z": 0,
      "name": "Empty",
      "level": 0
    },
    {
      "x": -5,
      "y": 10,
      "z": 0,
      "name": "Empty",
      "level": 0
    },
    {
      "x": -5,
      "y": 1,
      "z": 1,
      "name": "Empty",
      "level": 0
    },
    {
      "x": -5,
      "y": 2,
      "z": 1,
      "name": "Empty",
      "level": 0
    },
    {
      "x": -5,
      "y": 3,
      "z": 1,
      "name": "Empty",
      "level": 0
    },
    {
      "x": -5,
      "y": 4,
      "z": 1,
      "name": "Empty",
      "level": 0
    },
    {
      "x": -5,
      "y": 5,
      "z": 1,
      "name": "Empty",
      "level": 0
    },
    {
      "x": -5,
      "y": 6,
      "z": 1,
      "name": "Empty",
      "level": 0
    },
    {
      "x": -5,
      "y": 7,
      "z": 1,
      "name": "Empty",
      "level": 0
    },
    {
      "x": -5,
      "y": 8,
      "z": 1,
      "name": "Empty",
      "level": 0
    },
    {
      "x": -5,
      "y": 9,
      "z": 1,
      "name": "Empty",
      "level": 0
    },
    {
      "x": -5,
      "y": 10,
      "z": 1,
      "name": "Empty",
      "level": 0
    },
    {
      "x": -5,
      "y": 4,
      "z": 2,
      "name": "Empty",
      "level": 0
    },
    {
      "x": -5,
      "y": 5,
      "z": 2,
      "name": "Empty",
      "level": 0
    },
    {
      "x": -5,
      "y": 6,
      "z": 2,
      "name": "Empty",
      "level": 0
    },
    {
      "x": -5,
      "y": 7,
      "z": 2,
      "name": "Empty",
      "level": 0
    },
    {
      "x": -5,
      "y": 8,
      "z": 2,
      "name": "Empty",
      "level": 0
    },
    {
      "x": -5,
      "y": 9,
      "z": 2,
      "name": "Empty",
      "level": 0
    },
    {
      "x": -5,
      "y": 10,
      "z": 2,
      "name": "Empty",
      "level": 0
    },
    {
      "x": -5,
      "y": 4,
      "z": 3,
      "name": "Empty",
      "level": 0
    },
    {
      "x": -5,
      "y": 5,
      "z": 3,
      "name": "Empty",
      "level": 0
    },
    {
      "x": -5,
      "y": 9,
      "z": 3,
      "name": "Empty",
      "level": 0
    },
    {
      "x": -4,
      "y": 1,
      "z": -4,
      "name": "Empty",
      "level": 0
    },
    {
      "x": -4,
      "y": 9,
      "z": -4,
      "name": "Empty",
      "level": 0
    },
    {
      "x": -4,
      "y": 1,
      "z": -3,
      "name": "Empty",
      "level": 0
    },
    {
      "x": -4,
      "y": 3,
      "z": -3,
      "name": "Empty",
      "level": 0
    },
    {
      "x": -4,
      "y": 4,
      "z": -3,
      "name": "Empty",
      "level": 0
    },
    {
      "x": -4,
      "y": 5,
      "z": -3,
      "name": "Empty",
      "level": 0
    },
    {
      "x": -4,
      "y": 6,
      "z": -3,
      "name": "Empty",
      "level": 0
    },
    {
      "x": -4,
      "y": 7,
      "z": -3,
      "name": "Empty",
      "level": 0
    },
    {
      "x": -4,
      "y": 8,
      "z": -3,
      "name": "Empty",
      "level": 0
    },
    {
      "x": -4,
      "y": 9,
      "z": -3,
      "name": "Empty",
      "level": 0
    },
    {
      "x": -4,
      "y": 10,
      "z": -3,
      "name": "Empty",
      "level": 0
    },
    {
      "x": -4,
      "y": 1,
      "z": -2,
      "name": "Empty",
      "level": 0
    },
    {
      "x": -4,
      "y": 2,
      "z": -2,
      "name": "Empty",
      "level": 0
    },
    {
      "x": -4,
      "y": 3,
      "z": -2,
      "name": "Empty",
      "level": 0
    },
    {
      "x": -4,
      "y": 4,
      "z": -2,
      "name": "Empty",
      "level": 0
    },
    {
      "x": -4,
      "y": 5,
      "z": -2,
      "name": "Empty",
      "level": 0
    },
    {
      "x": -4,
      "y": 6,
      "z": -2,
      "name": "Empty",
      "level": 0
    },
    {
      "x": -4,
      "y": 7,
      "z": -2,
      "name": "Empty",
      "level": 0
    },
    {
      "x": -4,
      "y": 8,
      "z": -2,
      "name": "Empty",
      "level": 0
    },
    {
      "x": -4,
      "y": 9,
      "z": -2,
      "name": "Empty",
      "level": 0
    },
    {
      "x": -4,
      "y": 10,
      "z": -2,
      "name": "Empty",
      "level": 0
    },
    {
      "x": -4,
      "y": 11,
      "z": -2,
      "name": "Empty",
      "level": 0
    },
    {
      "x": -4,
      "y": 4,
      "z": -1,
      "name": "Empty",
      "level": 0
    },
    {
      "x": -4,
      "y": 5,
      "z": -1,
      "name": "Empty",
      "level": 0
    },
    {
      "x": -4,
      "y": 6,
      "z": -1,
      "name": "Empty",
      "level": 0
    },
    {
      "x": -4,
      "y": 7,
      "z": -1,
      "name": "Empty",
      "level": 0
    },
    {
      "x": -4,
      "y": 8,
      "z": -1,
      "name": "Empty",
      "level": 0
    },
    {
      "x": -4,
      "y": 9,
      "z": -1,
      "name": "Empty",
      "level": 0
    },
    {
      "x": -4,
      "y": 10,
      "z": -1,
      "name": "Empty",
      "level": 0
    },
    {
      "x": -4,
      "y": 11,
      "z": -1,
      "name": "Empty",
      "level": 0
    },
    {
      "x": -4,
      "y": 4,
      "z": 0,
      "name": "Empty",
      "level": 0
    },
    {
      "x": -4,
      "y": 5,
      "z": 0,
      "name": "Empty",
      "level": 0
    },
    {
      "x": -4,
      "y": 6,
      "z": 0,
      "name": "Empty",
      "level": 0
    },
    {
      "x": -4,
      "y": 7,
      "z": 0,
      "name": "Empty",
      "level": 0
    },
    {
      "x": -4,
      "y": 8,
      "z": 0,
      "name": "Empty",
      "level": 0
    },
    {
      "x": -4,
      "y": 9,
      "z": 0,
      "name": "Empty",
      "level": 0
    },
    {
      "x": -4,
      "y": 10,
      "z": 0,
      "name": "Empty",
      "level": 0
    },
    {
      "x": -4,
      "y": 11,
      "z": 0,
      "name": "Empty",
      "level": 0
    },
    {
      "x": -4,
      "y": 4,
      "z": 1,
      "name": "Empty",
      "level": 0
    },
    {
      "x": -4,
      "y": 5,
      "z": 1,
      "name": "Empty",
      "level": 0
    },
    {
      "x": -4,
      "y": 6,
      "z": 1,
      "name": "Empty",
      "level": 0
    },
    {
      "x": -4,
      "y": 7,
      "z": 1,
      "name": "Empty",
      "level": 0
    },
    {
      "x": -4,
      "y": 8,
      "z": 1,
      "name": "Empty",
      "level": 0
    },
    {
      "x": -4,
      "y": 9,
      "z": 1,
      "name": "Empty",
      "level": 0
    },
    {
      "x": -4,
      "y": 10,
      "z": 1,
      "name": "Empty",
      "level": 0
    },
    {
      "x": -4,
      "y": 11,
      "z": 1,
      "name": "Empty",
      "level": 0
    },
    {
      "x": -4,
      "y": 4,
      "z": 2,
      "name": "Empty",
      "level": 0
    },
    {
      "x": -4,
      "y": 5,
      "z": 2,
      "name": "Empty",
      "level": 0
    },
    {
      "x": -4,
      "y": 6,
      "z": 2,
      "name": "Empty",
      "level": 0
    },
    {
      "x": -4,
      "y": 7,
      "z": 2,
      "name": "Empty",
      "level": 0
    },
    {
      "x": -4,
      "y": 8,
      "z": 2,
      "name": "Empty",
      "level": 0
    },
    {
      "x": -4,
      "y": 9,
      "z": 2,
      "name": "Empty",
      "level": 0
    },
    {
      "x": -4,
      "y": 10,
      "z": 2,
      "name": "Empty",
      "level": 0
    },
    {
      "x": -3,
      "y": 9,
      "z": -4,
      "name": "Empty",
      "level": 0
    },
    {
      "x": -3,
      "y": 10,
      "z": -4,
      "name": "Empty",
      "level": 0
    },
    {
      "x": -3,
      "y": 1,
      "z": -3,
      "name": "Empty",
      "level": 0
    },
    {
      "x": -3,
      "y": 2,
      "z": -3,
      "name": "Empty",
      "level": 0
    },
    {
      "x": -3,
      "y": 6,
      "z": -3,
      "name": "Empty",
      "level": 0
    },
    {
      "x": -3,
      "y": 7,
      "z": -3,
      "name": "Empty",
      "level": 0
    },
    {
      "x": -3,
      "y": 8,
      "z": -3,
      "name": "Empty",
      "level": 0
    },
    {
      "x": -3,
      "y": 9,
      "z": -3,
      "name": "Empty",
      "level": 0
    },
    {
      "x": -3,
      "y": 10,
      "z": -3,
      "name": "Empty",
      "level": 0
    },
    {
      "x": -3,
      "y": 11,
      "z": -3,
      "name": "Empty",
      "level": 0
    },
    {
      "x": -3,
      "y": 12,
      "z": -3,
      "name": "Empty",
      "level": 0
    },
    {
      "x": -3,
      "y": 1,
      "z": -2,
      "name": "Empty",
      "level": 0
    },
    {
      "x": -3,
      "y": 3,
      "z": -2,
      "name": "Empty",
      "level": 0
    },
    {
      "x": -3,
      "y": 4,
      "z": -2,
      "name": "Empty",
      "level": 0
    },
    {
      "x": -3,
      "y": 5,
      "z": -2,
      "name": "Empty",
      "level": 0
    },
    {
      "x": -3,
      "y": 6,
      "z": -2,
      "name": "Empty",
      "level": 0
    },
    {
      "x": -3,
      "y": 7,
      "z": -2,
      "name": "Empty",
      "level": 0
    },
    {
      "x": -3,
      "y": 8,
      "z": -2,
      "name": "Empty",
      "level": 0
    },
    {
      "x": -3,
      "y": 9,
      "z": -2,
      "name": "Empty",
      "level": 0
    },
    {
      "x": -3,
      "y": 10,
      "z": -2,
      "name": "Empty",
      "level": 0
    },
    {
      "x": -3,
      "y": 11,
      "z": -2,
      "name": "Empty",
      "level": 0
    },
    {
      "x": -3,
      "y": 12,
      "z": -2,
      "name": "Empty",
      "level": 0
    },
    {
      "x": -3,
      "y": 6,
      "z": -1,
      "name": "Empty",
      "level": 0
    },
    {
      "x": -3,
      "y": 7,
      "z": -1,
      "name": "Empty",
      "level": 0
    },
    {
      "x": -3,
      "y": 8,
      "z": -1,
      "name": "Empty",
      "level": 0
    },
    {
      "x": -3,
      "y": 9,
      "z": -1,
      "name": "Empty",
      "level": 0
    },
    {
      "x": -3,
      "y": 10,
      "z": -1,
      "name": "Empty",
      "level": 0
    },
    {
      "x": -3,
      "y": 11,
      "z": -1,
      "name": "Empty",
      "level": 0
    },
    {
      "x": -3,
      "y": 6,
      "z": 0,
      "name": "Empty",
      "level": 0
    },
    {
      "x": -3,
      "y": 7,
      "z": 0,
      "name": "Empty",
      "level": 0
    },
    {
      "x": -3,
      "y": 8,
      "z": 0,
      "name": "Empty",
      "level": 0
    },
    {
      "x": -3,
      "y": 9,
      "z": 0,
      "name": "Empty",
      "level": 0
    },
    {
      "x": -3,
      "y": 10,
      "z": 0,
      "name": "Empty",
      "level": 0
    },
    {
      "x": -3,
      "y": 11,
      "z": 0,
      "name": "Empty",
      "level": 0
    },
    {
      "x": -3,
      "y": 4,
      "z": 1,
      "name": "Empty",
      "level": 0
    },
    {
      "x": -3,
      "y": 5,
      "z": 1,
      "name": "Empty",
      "level": 0
    },
    {
      "x": -3,
      "y": 6,
      "z": 1,
      "name": "Empty",
      "level": 0
    },
    {
      "x": -3,
      "y": 7,
      "z": 1,
      "name": "Empty",
      "level": 0
    },
    {
      "x": -3,
      "y": 8,
      "z": 1,
      "name": "Empty",
      "level": 0
    },
    {
      "x": -3,
      "y": 9,
      "z": 1,
      "name": "Empty",
      "level": 0
    },
    {
      "x": -3,
      "y": 10,
      "z": 1,
      "name": "Empty",
      "level": 0
    },
    {
      "x": -3,
      "y": 11,
      "z": 1,
      "name": "Empty",
      "level": 0
    },
    {
      "x": -3,
      "y": 12,
      "z": 1,
      "name": "Empty",
      "level": 0
    },
    {
      "x": -3,
      "y": 6,
      "z": 2,
      "name": "Empty",
      "level": 0
    },
    {
      "x": -3,
      "y": 7,
      "z": 2,
      "name": "Empty",
      "level": 0
    },
    {
      "x": -3,
      "y": 8,
      "z": 2,
      "name": "Empty",
      "level": 0
    },
    {
      "x": -3,
      "y": 9,
      "z": 2,
      "name": "Empty",
      "level": 0
    },
    {
      "x": -3,
      "y": 10,
      "z": 2,
      "name": "Empty",
      "level": 0
    },
    {
      "x": -3,
      "y": 11,
      "z": 2,
      "name": "Empty",
      "level": 0
    },
    {
      "x": -3,
      "y": 12,
      "z": 2,
      "name": "Empty",
      "level": 0
    },
    {
      "x": -2,
      "y": 10,
      "z": -4,
      "name": "Empty",
      "level": 0
    },
    {
      "x": -2,
      "y": 12,
      "z": -4,
      "name": "Empty",
      "level": 0
    },
    {
      "x": -2,
      "y": 8,
      "z": -3,
      "name": "Empty",
      "level": 0
    },
    {
      "x": -2,
      "y": 9,
      "z": -3,
      "name": "Empty",
      "level": 0
    },
    {
      "x": -2,
      "y": 10,
      "z": -3,
      "name": "Empty",
      "level": 0
    },
    {
      "x": -2,
      "y": 11,
      "z": -3,
      "name": "Empty",
      "level": 0
    },
    {
      "x": -2,
      "y": 12,
      "z": -3,
      "name": "Empty",
      "level": 0
    },
    {
      "x": -2,
      "y": 13,
      "z": -3,
      "name": "Empty",
      "level": 0
    },
    {
      "x": -2,
      "y": 6,
      "z": -2,
      "name": "Empty",
      "level": 0
    },
    {
      "x": -2,
      "y": 7,
      "z": -2,
      "name": "Empty",
      "level": 0
    },
    {
      "x": -2,
      "y": 8,
      "z": -2,
      "name": "Empty",
      "level": 0
    },
    {
      "x": -2,
      "y": 9,
      "z": -2,
      "name": "Empty",
      "level": 0
    },
    {
      "x": -2,
      "y": 10,
      "z": -2,
      "name": "Empty",
      "level": 0
    },
    {
      "x": -2,
      "y": 11,
      "z": -2,
      "name": "Empty",
      "level": 0
    },
    {
      "x": -2,
      "y": 12,
      "z": -2,
      "name": "Empty",
      "level": 0
    },
    {
      "x": -2,
      "y": 13,
      "z": -2,
      "name": "Empty",
      "level": 0
    },
    {
      "x": -2,
      "y": 8,
      "z": -1,
      "name": "Empty",
      "level": 0
    },
    {
      "x": -2,
      "y": 9,
      "z": -1,
      "name": "Empty",
      "level": 0
    },
    {
      "x": -2,
      "y": 10,
      "z": -1,
      "name": "Empty",
      "level": 0
    },
    {
      "x": -2,
      "y": 11,
      "z": -1,
      "name": "Empty",
      "level": 0
    },
    {
      "x": -2,
      "y": 12,
      "z": -1,
      "name": "Empty",
      "level": 0
    },
    {
      "x": -2,
      "y": 8,
      "z": 0,
      "name": "Empty",
      "level": 0
    },
    {
      "x": -2,
      "y": 9,
      "z": 0,
      "name": "Empty",
      "level": 0
    },
    {
      "x": -2,
      "y": 10,
      "z": 0,
      "name": "Empty",
      "level": 0
    },
    {
      "x": -2,
      "y": 11,
      "z": 0,
      "name": "Empty",
      "level": 0
    },
    {
      "x": -2,
      "y": 12,
      "z": 0,
      "name": "Empty",
      "level": 0
    },
    {
      "x": -2,
      "y": 6,
      "z": 1,
      "name": "Empty",
      "level": 0
    },
    {
      "x": -2,
      "y": 7,
      "z": 1,
      "name": "Empty",
      "level": 0
    },
    {
      "x": -2,
      "y": 8,
      "z": 1,
      "name": "Empty",
      "level": 0
    },
    {
      "x": -2,
      "y": 9,
      "z": 1,
      "name": "Empty",
      "level": 0
    },
    {
      "x": -2,
      "y": 10,
      "z": 1,
      "name": "Empty",
      "level": 0
    },
    {
      "x": -2,
      "y": 11,
      "z": 1,
      "name": "Empty",
      "level": 0
    },
    {
      "x": -2,
      "y": 12,
      "z": 1,
      "name": "Empty",
      "level": 0
    },
    {
      "x": -2,
      "y": 13,
      "z": 1,
      "name": "Empty",
      "level": 0
    },
    {
      "x": -2,
      "y": 8,
      "z": 2,
      "name": "Empty",
      "level": 0
    },
    {
      "x": -2,
      "y": 9,
      "z": 2,
      "name": "Empty",
      "level": 0
    },
    {
      "x": -2,
      "y": 10,
      "z": 2,
      "name": "Empty",
      "level": 0
    },
    {
      "x": -2,
      "y": 11,
      "z": 2,
      "name": "Empty",
      "level": 0
    },
    {
      "x": -2,
      "y": 12,
      "z": 2,
      "name": "Empty",
      "level": 0
    },
    {
      "x": -2,
      "y": 13,
      "z": 2,
      "name": "Empty",
      "level": 0
    },
    {
      "x": -1,
      "y": 10,
      "z": -4,
      "name": "Empty",
      "level": 0
    },
    {
      "x": -1,
      "y": 9,
      "z": -3,
      "name": "Empty",
      "level": 0
    },
    {
      "x": -1,
      "y": 10,
      "z": -3,
      "name": "Empty",
      "level": 0
    },
    {
      "x": -1,
      "y": 11,
      "z": -3,
      "name": "Empty",
      "level": 0
    },
    {
      "x": -1,
      "y": 12,
      "z": -3,
      "name": "Empty",
      "level": 0
    },
    {
      "x": -1,
      "y": 13,
      "z": -3,
      "name": "Empty",
      "level": 0
    },
    {
      "x": -1,
      "y": 8,
      "z": -2,
      "name": "Empty",
      "level": 0
    },
    {
      "x": -1,
      "y": 9,
      "z": -2,
      "name": "Empty",
      "level": 0
    },
    {
      "x": -1,
      "y": 10,
      "z": -2,
      "name": "Empty",
      "level": 0
    },
    {
      "x": -1,
      "y": 11,
      "z": -2,
      "name": "Empty",
      "level": 0
    },
    {
      "x": -1,
      "y": 12,
      "z": -2,
      "name": "Empty",
      "level": 0
    },
    {
      "x": -1,
      "y": 13,
      "z": -2,
      "name": "Empty",
      "level": 0
    },
    {
      "x": -1,
      "y": 14,
      "z": -2,
      "name": "Empty",
      "level": 0
    },
    {
      "x": -1,
      "y": 9,
      "z": -1,
      "name": "Empty",
      "level": 0
    },
    {
      "x": -1,
      "y": 10,
      "z": -1,
      "name": "Empty",
      "level": 0
    },
    {
      "x": -1,
      "y": 11,
      "z": -1,
      "name": "Empty",
      "level": 0
    },
    {
      "x": -1,
      "y": 12,
      "z": -1,
      "name": "Empty",
      "level": 0
    },
    {
      "x": -1,
      "y": 13,
      "z": -1,
      "name": "Empty",
      "level": 0
    },
    {
      "x": -1,
      "y": 9,
      "z": 0,
      "name": "Empty",
      "level": 0
    },
    {
      "x": -1,
      "y": 10,
      "z": 0,
      "name": "Empty",
      "level": 0
    },
    {
      "x": -1,
      "y": 11,
      "z": 0,
      "name": "Empty",
      "level": 0
    },
    {
      "x": -1,
      "y": 12,
      "z": 0,
      "name": "Empty",
      "level": 0
    },
    {
      "x": -1,
      "y": 13,
      "z": 0,
      "name": "Empty",
      "level": 0
    },
    {
      "x": -1,
      "y": 8,
      "z": 1,
      "name": "Empty",
      "level": 0
    },
    {
      "x": -1,
      "y": 9,
      "z": 1,
      "name": "Empty",
      "level": 0
    },
    {
      "x": -1,
      "y": 10,
      "z": 1,
      "name": "Empty",
      "level": 0
    },
    {
      "x": -1,
      "y": 11,
      "z": 1,
      "name": "Empty",
      "level": 0
    },
    {
      "x": -1,
      "y": 12,
      "z": 1,
      "name": "Empty",
      "level": 0
    },
    {
      "x": -1,
      "y": 13,
      "z": 1,
      "name": "Empty",
      "level": 0
    },
    {
      "x": -1,
      "y": 14,
      "z": 1,
      "name": "Empty",
      "level": 0
    },
    {
      "x": -1,
      "y": 9,
      "z": 2,
      "name": "Empty",
      "level": 0
    },
    {
      "x": -1,
      "y": 10,
      "z": 2,
      "name": "Empty",
      "level": 0
    },
    {
      "x": -1,
      "y": 11,
      "z": 2,
      "name": "Empty",
      "level": 0
    },
    {
      "x": -1,
      "y": 12,
      "z": 2,
      "name": "Empty",
      "level": 0
    },
    {
      "x": -1,
      "y": 13,
      "z": 2,
      "name": "Empty",
      "level": 0
    },
    {
      "x": 0,
      "y": 13,
      "z": -4,
      "name": "Empty",
      "level": 0
    },
    {
      "x": 0,
      "y": 10,
      "z": -3,
      "name": "Empty",
      "level": 0
    },
    {
      "x": 0,
      "y": 11,
      "z": -3,
      "name": "Empty",
      "level": 0
    },
    {
      "x": 0,
      "y": 12,
      "z": -3,
      "name": "Empty",
      "level": 0
    },
    {
      "x": 0,
      "y": 13,
      "z": -3,
      "name": "Empty",
      "level": 0
    },
    {
      "x": 0,
      "y": 14,
      "z": -3,
      "name": "Empty",
      "level": 0
    },
    {
      "x": 0,
      "y": 9,
      "z": -2,
      "name": "Empty",
      "level": 0
    },
    {
      "x": 0,
      "y": 10,
      "z": -2,
      "name": "Empty",
      "level": 0
    },
    {
      "x": 0,
      "y": 11,
      "z": -2,
      "name": "Empty",
      "level": 0
    },
    {
      "x": 0,
      "y": 12,
      "z": -2,
      "name": "Empty",
      "level": 0
    },
    {
      "x": 0,
      "y": 13,
      "z": -2,
      "name": "Empty",
      "level": 0
    },
    {
      "x": 0,
      "y": 14,
      "z": -2,
      "name": "Empty",
      "level": 0
    },
    {
      "x": 0,
      "y": 10,
      "z": -1,
      "name": "Empty",
      "level": 0
    },
    {
      "x": 0,
      "y": 11,
      "z": -1,
      "name": "Empty",
      "level": 0
    },
    {
      "x": 0,
      "y": 12,
      "z": -1,
      "name": "Empty",
      "level": 0
    },
    {
      "x": 0,
      "y": 13,
      "z": -1,
      "name": "Empty",
      "level": 0
    },
    {
      "x": 0,
      "y": 14,
      "z": -1,
      "name": "Empty",
      "level": 0
    },
    {
      "x": 0,
      "y": 10,
      "z": 0,
      "name": "Empty",
      "level": 0
    },
    {
      "x": 0,
      "y": 11,
      "z": 0,
      "name": "Empty",
      "level": 0
    },
    {
      "x": 0,
      "y": 12,
      "z": 0,
      "name": "Empty",
      "level": 0
    },
    {
      "x": 0,
      "y": 13,
      "z": 0,
      "name": "Empty",
      "level": 0
    },
    {
      "x": 0,
      "y": 9,
      "z": 1,
      "name": "Empty",
      "level": 0
    },
    {
      "x": 0,
      "y": 10,
      "z": 1,
      "name": "Empty",
      "level": 0
    },
    {
      "x": 0,
      "y": 11,
      "z": 1,
      "name": "Empty",
      "level": 0
    },
    {
      "x": 0,
      "y": 12,
      "z": 1,
      "name": "Empty",
      "level": 0
    },
    {
      "x": 0,
      "y": 13,
      "z": 1,
      "name": "Empty",
      "level": 0
    },
    {
      "x": 0,
      "y": 14,
      "z": 1,
      "name": "Empty",
      "level": 0
    },
    {
      "x": 0,
      "y": 10,
      "z": 2,
      "name": "Empty",
      "level": 0
    },
    {
      "x": 0,
      "y": 11,
      "z": 2,
      "name": "Empty",
      "level": 0
    },
    {
      "x": 0,
      "y": 12,
      "z": 2,
      "name": "Empty",
      "level": 0
    },
    {
      "x": 0,
      "y": 13,
      "z": 2,
      "name": "Empty",
      "level": 0
    },
    {
      "x": 1,
      "y": 11,
      "z": -3,
      "name": "Empty",
      "level": 0
    },
    {
      "x": 1,
      "y": 12,
      "z": -3,
      "name": "Empty",
      "level": 0
    },
    {
      "x": 1,
      "y": 13,
      "z": -3,
      "name": "Empty",
      "level": 0
    },
    {
      "x": 1,
      "y": 14,
      "z": -3,
      "name": "Empty",
      "level": 0
    },
    {
      "x": 1,
      "y": 10,
      "z": -2,
      "name": "Empty",
      "level": 0
    },
    {
      "x": 1,
      "y": 11,
      "z": -2,
      "name": "Empty",
      "level": 0
    },
    {
      "x": 1,
      "y": 12,
      "z": -2,
      "name": "Empty",
      "level": 0
    },
    {
      "x": 1,
      "y": 13,
      "z": -2,
      "name": "Empty",
      "level": 0
    },
    {
      "x": 1,
      "y": 14,
      "z": -2,
      "name": "Empty",
      "level": 0
    },
    {
      "x": 1,
      "y": 15,
      "z": -2,
      "name": "Empty",
      "level": 0
    },
    {
      "x": 1,
      "y": 11,
      "z": -1,
      "name": "Empty",
      "level": 0
    },
    {
      "x": 1,
      "y": 12,
      "z": -1,
      "name": "Empty",
      "level": 0
    },
    {
      "x": 1,
      "y": 13,
      "z": -1,
      "name": "Empty",
      "level": 0
    },
    {
      "x": 1,
      "y": 14,
      "z": -1,
      "name": "Empty",
      "level": 0
    },
    {
      "x": 1,
      "y": 11,
      "z": 0,
      "name": "Empty",
      "level": 0
    },
    {
      "x": 1,
      "y": 12,
      "z": 0,
      "name": "Empty",
      "level": 0
    },
    {
      "x": 1,
      "y": 13,
      "z": 0,
      "name": "Empty",
      "level": 0
    },
    {
      "x": 1,
      "y": 14,
      "z": 0,
      "name": "Empty",
      "level": 0
    },
    {
      "x": 1,
      "y": 15,
      "z": 0,
      "name": "Empty",
      "level": 0
    },
    {
      "x": 1,
      "y": 10,
      "z": 1,
      "name": "Empty",
      "level": 0
    },
    {
      "x": 1,
      "y": 11,
      "z": 1,
      "name": "Empty",
      "level": 0
    },
    {
      "x": 1,
      "y": 12,
      "z": 1,
      "name": "Empty",
      "level": 0
    },
    {
      "x": 1,
      "y": 13,
      "z": 1,
      "name": "Empty",
      "level": 0
    },
    {
      "x": 1,
      "y": 14,
      "z": 1,
      "name": "Empty",
      "level": 0
    },
    {
      "x": 1,
      "y": 15,
      "z": 1,
      "name": "Empty",
      "level": 0
    },
    {
      "x": 1,
      "y": 11,
      "z": 2,
      "name": "Empty",
      "level": 0
    },
    {
      "x": 1,
      "y": 12,
      "z": 2,
      "name": "Empty",
      "level": 0
    },
    {
      "x": 1,
      "y": 13,
      "z": 2,
      "name": "Empty",
      "level": 0
    },
    {
      "x": 1,
      "y": 14,
      "z": 2,
      "name": "Empty",
      "level": 0
    },
    {
      "x": 1,
      "y": 15,
      "z": 2,
      "name": "Empty",
      "level": 0
    },
    {
      "x": 1,
      "y": 13,
      "z": 3,
      "name": "Empty",
      "level": 0
    },
    {
      "x": 1,
      "y": 14,
      "z": 3,
      "name": "Empty",
      "level": 0
    },
    {
      "x": 2,
      "y": 13,
      "z": -4,
      "name": "Empty",
      "level": 0
    },
    {
      "x": 2,
      "y": 14,
      "z": -4,
      "name": "Empty",
      "level": 0
    },
    {
      "x": 2,
      "y": 11,
      "z": -3,
      "name": "Empty",
      "level": 0
    },
    {
      "x": 2,
      "y": 12,
      "z": -3,
      "name": "Empty",
      "level": 0
    },
    {
      "x": 2,
      "y": 13,
      "z": -3,
      "name": "Empty",
      "level": 0
    },
    {
      "x": 2,
      "y": 14,
      "z": -3,
      "name": "Empty",
      "level": 0
    },
    {
      "x": 2,
      "y": 15,
      "z": -3,
      "name": "Empty",
      "level": 0
    },
    {
      "x": 2,
      "y": 10,
      "z": -2,
      "name": "Empty",
      "level": 0
    },
    {
      "x": 2,
      "y": 11,
      "z": -2,
      "name": "Empty",
      "level": 0
    },
    {
      "x": 2,
      "y": 12,
      "z": -2,
      "name": "Empty",
      "level": 0
    },
    {
      "x": 2,
      "y": 13,
      "z": -2,
      "name": "Empty",
      "level": 0
    },
    {
      "x": 2,
      "y": 14,
      "z": -2,
      "name": "Empty",
      "level": 0
    },
    {
      "x": 2,
      "y": 15,
      "z": -2,
      "name": "Empty",
      "level": 0
    },
    {
      "x": 2,
      "y": 11,
      "z": -1,
      "name": "Empty",
      "level": 0
    },
    {
      "x": 2,
      "y": 12,
      "z": -1,
      "name": "Empty",
      "level": 0
    },
    {
      "x": 2,
      "y": 13,
      "z": -1,
      "name": "Empty",
      "level": 0
    },
    {
      "x": 2,
      "y": 14,
      "z": -1,
      "name": "Empty",
      "level": 0
    },
    {
      "x": 2,
      "y": 11,
      "z": 0,
      "name": "Empty",
      "level": 0
    },
    {
      "x": 2,
      "y": 12,
      "z": 0,
      "name": "Empty",
      "level": 0
    },
    {
      "x": 2,
      "y": 13,
      "z": 0,
      "name": "Empty",
      "level": 0
    },
    {
      "x": 2,
      "y": 14,
      "z": 0,
      "name": "Empty",
      "level": 0
    },
    {
      "x": 2,
      "y": 10,
      "z": 1,
      "name": "Empty",
      "level": 0
    },
    {
      "x": 2,
      "y": 11,
      "z": 1,
      "name": "Empty",
      "level": 0
    },
    {
      "x": 2,
      "y": 12,
      "z": 1,
      "name": "Empty",
      "level": 0
    },
    {
      "x": 2,
      "y": 13,
      "z": 1,
      "name": "Empty",
      "level": 0
    },
    {
      "x": 2,
      "y": 14,
      "z": 1,
      "name": "Empty",
      "level": 0
    },
    {
      "x": 2,
      "y": 15,
      "z": 1,
      "name": "Empty",
      "level": 0
    },
    {
      "x": 2,
      "y": 11,
      "z": 2,
      "name": "Empty",
      "level": 0
    },
    {
      "x": 2,
      "y": 12,
      "z": 2,
      "name": "Empty",
      "level": 0
    },
    {
      "x": 2,
      "y": 13,
      "z": 2,
      "name": "Empty",
      "level": 0
    },
    {
      "x": 2,
      "y": 14,
      "z": 2,
      "name": "Empty",
      "level": 0
    },
    {
      "x": 3,
      "y": 12,
      "z": -3,
      "name": "Empty",
      "level": 0
    },
    {
      "x": 3,
      "y": 13,
      "z": -3,
      "name": "Empty",
      "level": 0
    },
    {
      "x": 3,
      "y": 14,
      "z": -3,
      "name": "Empty",
      "level": 0
    },
    {
      "x": 3,
      "y": 15,
      "z": -3,
      "name": "Empty",
      "level": 0
    },
    {
      "x": 3,
      "y": 11,
      "z": -2,
      "name": "Empty",
      "level": 0
    },
    {
      "x": 3,
      "y": 12,
      "z": -2,
