{
  "version": 8,
  "blockIdVersion": 11,
  "anchorX": 0,
  "anchorY": 0,
  "anchorZ": 0,
  "blocks": [
    {
      "x": -25,
      "y": 5,
      "z": 9,
      "name": "Rock_Shale_Brick"
    },
    {
      "x": -25,
      "y": 6,
      "z": 9,
      "name": "Rock_Shale_Brick"
    },
    {
      "x": -25,
      "y": 7,
      "z": 9,
      "name": "Rock_Shale_Brick"
    },
    {
      "x": -25,
      "y": 8,
      "z": 9,
      "name": "Rock_Shale_Brick"
    },
    {
      "x": -25,
      "y": 9,
      "z": 9,
      "name": "Rock_Shale_Brick"
    },
    {
      "x": -25,
      "y": 10,
      "z": 9,
      "name": "Rock_Shale_Brick"
    },
    {
      "x": -25,
      "y": 11,
      "z": 9,
      "name": "Rock_Shale_Brick"
    },
    {
      "x": -25,
      "y": 5,
      "z": 10,
      "name": "Rock_Shale_Brick"
    },
    {
      "x": -25,
      "y": 6,
      "z": 10,
      "name": "Rock_Shale_Brick"
    },
    {
      "x": -25,
      "y": 7,
      "z": 10,
      "name": "Rock_Shale_Brick"
    },
    {
      "x": -25,
      "y": 8,
      "z": 10,
      "name": "Rock_Shale_Brick"
    },
    {
      "x": -25,
      "y": 9,
      "z": 10,
      "name": "Rock_Shale_Brick"
    },
    {
      "x": -25,
      "y": 10,
      "z": 10,
      "name": "Rock_Shale_Brick"
    },
    {
      "x": -25,
      "y": 11,
      "z": 10,
      "name": "Rock_Shale_Brick"
    },
    {
      "x": -25,
      "y": 5,
      "z": 11,
      "name": "Rock_Shale_Brick"
    },
    {
      "x": -25,
      "y": 6,
      "z": 11,
      "name": "Rock_Shale_Brick"
    },
    {
      "x": -25,
      "y": 7,
      "z": 11,
      "name": "Rock_Shale_Brick"
    },
    {
      "x": -25,
      "y": 8,
      "z": 11,
      "name": "Rock_Shale_Brick"
    },
    {
      "x": -25,
      "y": 9,
      "z": 11,
      "name": "Rock_Shale_Brick"
    },
    {
      "x": -25,
      "y": 10,
      "z": 11,
      "name": "Rock_Shale_Brick"
    },
    {
      "x": -25,
      "y": 11,
      "z": 11,
      "name": "Rock_Shale_Brick"
    },
    {
      "x": -25,
      "y": 5,
      "z": 12,
      "name": "Rock_Shale_Brick"
    },
    {
      "x": -25,
      "y": 6,
      "z": 12,
      "name": "Rock_Shale_Brick"
    },
    {
      "x": -25,
      "y": 7,
      "z": 12,
      "name": "Rock_Shale_Brick"
    },
    {
      "x": -25,
      "y": 8,
      "z": 12,
      "name": "Rock_Shale_Brick"
    },
    {
      "x": -25,
      "y": 9,
      "z": 12,
      "name": "Rock_Shale_Brick"
    },
    {
      "x": -25,
      "y": 10,
      "z": 12,
      "name": "Rock_Shale_Brick"
    },
    {
      "x": -25,
      "y": 11,
      "z": 12,
      "name": "Rock_Shale_Brick"
    },
    {
      "x": -25,
      "y": 5,
      "z": 13,
      "name": "Rock_Shale_Brick"
    },
    {
      "x": -25,
      "y": 6,
      "z": 13,
      "name": "Rock_Shale_Brick"
    },
    {
      "x": -25,
      "y": 7,
      "z": 13,
      "name": "Rock_Shale_Brick"
    },
    {
      "x": -25,
      "y": 8,
      "z": 13,
      "name": "Rock_Shale_Brick"
    },
    {
      "x": -25,
      "y": 9,
      "z": 13,
      "name": "Rock_Shale_Brick"
    },
    {
      "x": -25,
      "y": 10,
      "z": 13,
      "name": "Rock_Shale_Brick"
    },
    {
      "x": -25,
      "y": 11,
      "z": 13,
      "name": "Rock_Shale_Brick"
    },
    {
      "x": -25,
      "y": 5,
      "z": 14,
      "name": "Rock_Shale_Brick"
    },
    {
      "x": -25,
      "y": 6,
      "z": 14,
      "name": "Rock_Shale_Brick"
    },
    {
      "x": -25,
      "y": 7,
      "z": 14,
      "name": "Rock_Shale_Brick"
    },
    {
      "x": -25,
      "y": 8,
      "z": 14,
      "name": "Rock_Shale_Brick"
    },
    {
      "x": -25,
      "y": 9,
      "z": 14,
      "name": "Rock_Shale_Brick"
    },
    {
      "x": -25,
      "y": 10,
      "z": 14,
      "name": "Rock_Shale_Brick"
    },
    {
      "x": -25,
      "y": 11,
      "z": 14,
      "name": "Rock_Shale_Brick"
    },
    {
      "x": -25,
      "y": 5,
      "z": 15,
      "name": "Rock_Shale_Brick"
    },
    {
      "x": -25,
      "y": 6,
      "z": 15,
      "name": "Rock_Shale_Brick"
    },
    {
      "x": -25,
      "y": 7,
      "z": 15,
      "name": "Rock_Shale_Brick"
    },
    {
      "x": -25,
      "y": 8,
      "z": 15,
      "name": "Rock_Shale_Brick"
    },
    {
      "x": -25,
      "y": 9,
      "z": 15,
      "name": "Rock_Shale_Brick"
    },
    {
      "x": -25,
      "y": 10,
      "z": 15,
      "name": "Rock_Shale_Brick"
    },
    {
      "x": -25,
      "y": 11,
      "z": 15,
      "name": "Rock_Shale_Brick"
    },
    {
      "x": -25,
      "y": 5,
      "z": 16,
      "name": "Rock_Shale_Brick"
    },
    {
      "x": -25,
      "y": 6,
      "z": 16,
      "name": "Rock_Shale_Brick"
    },
    {
      "x": -25,
      "y": 7,
      "z": 16,
      "name": "Rock_Shale_Brick"
    },
    {
      "x": -25,
      "y": 8,
      "z": 16,
      "name": "Rock_Shale_Brick"
    },
    {
      "x": -25,
      "y": 9,
      "z": 16,
      "name": "Rock_Shale_Brick"
    },
    {
      "x": -25,
      "y": 10,
      "z": 16,
      "name": "Rock_Shale_Brick"
    },
    {
      "x": -25,
      "y": 11,
      "z": 16,
      "name": "Rock_Shale_Brick"
    },
    {
      "x": -25,
      "y": 5,
      "z": 17,
      "name": "Rock_Shale_Brick"
    },
    {
      "x": -25,
      "y": 6,
      "z": 17,
      "name": "Rock_Shale_Brick"
    },
    {
      "x": -25,
      "y": 7,
      "z": 17,
      "name": "Rock_Shale_Brick"
    },
    {
      "x": -25,
      "y": 8,
      "z": 17,
      "name": "Rock_Shale_Brick"
    },
    {
      "x": -25,
      "y": 9,
      "z": 17,
      "name": "Rock_Shale_Brick"
    },
    {
      "x": -25,
      "y": 10,
      "z": 17,
      "name": "Rock_Shale_Brick"
    },
    {
      "x": -25,
      "y": 11,
      "z": 17,
      "name": "Rock_Shale_Brick"
    },
    {
      "x": -25,
      "y": 5,
      "z": 18,
      "name": "Rock_Shale_Brick"
    },
    {
      "x": -25,
      "y": 6,
      "z": 18,
      "name": "Rock_Shale_Brick"
    },
    {
      "x": -25,
      "y": 7,
      "z": 18,
      "name": "Rock_Shale_Brick"
    },
    {
      "x": -25,
      "y": 8,
      "z": 18,
      "name": "Rock_Shale_Brick"
    },
    {
      "x": -25,
      "y": 9,
      "z": 18,
      "name": "Rock_Shale_Brick"
    },
    {
      "x": -25,
      "y": 10,
      "z": 18,
      "name": "Rock_Shale_Brick"
    },
    {
      "x": -25,
      "y": 11,
      "z": 18,
      "name": "Rock_Shale_Brick"
    },
    {
      "x": -25,
      "y": 5,
      "z": 19,
      "name": "Rock_Shale_Brick"
    },
    {
      "x": -25,
      "y": 6,
      "z": 19,
      "name": "Rock_Shale_Brick"
    },
    {
      "x": -25,
      "y": 7,
      "z": 19,
      "name": "Rock_Shale_Brick"
    },
    {
      "x": -25,
      "y": 8,
      "z": 19,
      "name": "Rock_Shale_Brick"
    },
    {
      "x": -25,
      "y": 9,
      "z": 19,
      "name": "Rock_Shale_Brick"
    },
    {
      "x": -25,
      "y": 10,
      "z": 19,
      "name": "Rock_Shale_Brick"
    },
    {
      "x": -25,
      "y": 11,
      "z": 19,
      "name": "Rock_Shale_Brick"
    },
    {
      "x": -25,
      "y": 5,
      "z": 20,
      "name": "Rock_Shale_Brick"
    },
    {
      "x": -25,
      "y": 6,
      "z": 20,
      "name": "Rock_Shale_Brick"
    },
    {
      "x": -25,
      "y": 7,
      "z": 20,
      "name": "Rock_Shale_Brick"
    },
    {
      "x": -25,
      "y": 8,
      "z": 20,
      "name": "Rock_Shale_Brick"
    },
    {
      "x": -25,
      "y": 9,
      "z": 20,
      "name": "Rock_Shale_Brick"
    },
    {
      "x": -25,
      "y": 10,
      "z": 20,
      "name": "Rock_Shale_Brick"
    },
    {
      "x": -25,
      "y": 11,
      "z": 20,
      "name": "Rock_Shale_Brick"
    },
    {
      "x": -24,
      "y": 5,
      "z": 9,
      "name": "Rock_Shale_Brick"
    },
    {
      "x": -24,
      "y": 6,
      "z": 9,
      "name": "Rock_Shale_Brick"
    },
    {
      "x": -24,
      "y": 7,
      "z": 9,
      "name": "Rock_Shale_Brick"
    },
    {
      "x": -24,
      "y": 8,
      "z": 9,
      "name": "Rock_Shale_Brick"
    },
    {
      "x": -24,
      "y": 9,
      "z": 9,
      "name": "Rock_Shale_Brick"
    },
    {
      "x": -24,
      "y": 10,
      "z": 9,
      "name": "Rock_Shale_Brick"
    },
    {
      "x": -24,
      "y": 11,
      "z": 9,
      "name": "Rock_Shale_Brick"
    },
    {
      "x": -24,
      "y": 5,
      "z": 10,
      "name": "Rock_Shale_Brick"
    },
    {
      "x": -24,
      "y": 6,
      "z": 10,
      "name": "Furniture_SK_Monument_Chest_Small",
      "components": {
        "Components": {
          "ItemContainerBlock": {
            "ItemContainer": {
              "Capacity": 18,
              "Items": {
                "0": {
                  "Id": "Ore_Cobalt",
                  "Quantity": 3,
                  "Durability": 0.0,
                  "MaxDurability": 0.0,
                  "OverrideDroppedItemAnimation": false
                },
                "6": {
                  "Id": "Weapon_Arrow_Crude",
                  "Quantity": 6,
                  "Durability": 0.0,
                  "MaxDurability": 0.0,
                  "OverrideDroppedItemAnimation": false
                },
                "1": {
                  "Id": "Food_Vegetable_Cooked",
                  "Quantity": 1,
                  "Durability": 0.0,
                  "MaxDurability": 0.0,
                  "OverrideDroppedItemAnimation": false
                },
                "3": {
                  "Id": "Wood_Redwood_Trunk",
                  "Quantity": 5,
                  "Durability": 0.0,
                  "MaxDurability": 0.0,
                  "OverrideDroppedItemAnimation": false
                },
                "7": {
                  "Id": "Wood_Birch_Trunk",
                  "Quantity": 8,
                  "Durability": 0.0,
                  "MaxDurability": 0.0,
                  "OverrideDroppedItemAnimation": false
                },
                "5": {
                  "Id": "Ingredient_Fabric_Scrap_Linen",
                  "Quantity": 2,
                  "Durability": 0.0,
                  "MaxDurability": 0.0,
                  "OverrideDroppedItemAnimation": false
                },
                "17": {
                  "Id": "Ingredient_Fabric_Scrap_Linen",
                  "Quantity": 3,
                  "Durability": 0.0,
                  "MaxDurability": 0.0,
                  "OverrideDroppedItemAnimation": false
                }
              }
            },
            "Capacity": 20
          }
        }
      }
    },
    {
      "x": -24,
      "y": 7,
      "z": 10,
      "name": "Empty"
    },
    {
      "x": -24,
      "y": 8,
      "z": 10,
      "name": "Empty"
    },
    {
      "x": -24,
      "y": 9,
      "z": 10,
      "name": "Empty"
    },
    {
      "x": -24,
      "y": 10,
      "z": 10,
      "name": "Plant_Moss_Cave_Green_Dark",
      "support": 15,
      "rotation": 8
    },
    {
      "x": -24,
      "y": 11,
      "z": 10,
      "name": "Rock_Shale_Brick"
    },
    {
      "x": -24,
      "y": 5,
      "z": 11,
      "name": "Rock_Shale_Brick"
    },
    {
      "x": -24,
      "y": 6,
      "z": 11,
      "name": "Empty"
    },
    {
      "x": -24,
      "y": 7,
      "z": 11,
      "name": "Empty"
    },
    {
      "x": -24,
      "y": 8,
      "z": 11,
      "name": "Empty"
    },
    {
      "x": -24,
      "y": 9,
      "z": 11,
      "name": "Empty"
    },
    {
      "x": -24,
      "y": 10,
      "z": 11,
      "name": "Empty"
    },
    {
      "x": -24,
      "y": 11,
      "z": 11,
      "name": "Rock_Shale_Brick"
    },
    {
      "x": -24,
      "y": 5,
      "z": 12,
      "name": "Rock_Shale_Brick"
    },
    {
      "x": -24,
      "y": 6,
      "z": 12,
      "name": "Empty"
    },
    {
      "x": -24,
      "y": 7,
      "z": 12,
      "name": "Empty"
    },
    {
      "x": -24,
      "y": 8,
      "z": 12,
      "name": "Empty"
    },
    {
      "x": -24,
      "y": 9,
      "z": 12,
      "name": "Empty"
    },
    {
      "x": -24,
      "y": 10,
      "z": 12,
      "name": "Empty"
    },
    {
      "x": -24,
      "y": 11,
      "z": 12,
      "name": "Rock_Shale_Brick"
    },
    {
      "x": -24,
      "y": 5,
      "z": 13,
      "name": "Rock_Shale_Brick"
    },
    {
      "x": -24,
      "y": 6,
      "z": 13,
      "name": "Empty"
    },
    {
      "x": -24,
      "y": 7,
      "z": 13,
      "name": "Empty"
    },
    {
      "x": -24,
      "y": 8,
      "z": 13,
      "name": "Empty"
    },
    {
      "x": -24,
      "y": 9,
      "z": 13,
      "name": "Empty"
    },
    {
      "x": -24,
      "y": 10,
      "z": 13,
      "name": "Empty"
    },
    {
      "x": -24,
      "y": 11,
      "z": 13,
      "name": "Rock_Shale_Brick"
    },
    {
      "x": -24,
      "y": 5,
      "z": 14,
      "name": "Rock_Shale_Brick"
    },
    {
      "x": -24,
      "y": 6,
      "z": 14,
      "name": "Deco_Bone_Pile"
    },
    {
      "x": -24,
      "y": 7,
      "z": 14,
      "name": "Empty"
    },
    {
      "x": -24,
      "y": 8,
      "z": 14,
      "name": "Empty"
    },
    {
      "x": -24,
      "y": 9,
      "z": 14,
      "name": "Empty"
    },
    {
      "x": -24,
      "y": 10,
      "z": 14,
      "name": "Empty"
    },
    {
      "x": -24,
      "y": 11,
      "z": 14,
      "name": "Rock_Shale_Brick"
    },
    {
      "x": -24,
      "y": 5,
      "z": 15,
      "name": "Rock_Shale_Brick"
    },
    {
      "x": -24,
      "y": 6,
      "z": 15,
      "name": "Deco_Bone_Pile"
    },
    {
      "x": -24,
      "y": 7,
      "z": 15,
      "name": "Empty"
    },
    {
      "x": -24,
      "y": 8,
      "z": 15,
      "name": "Empty"
    },
    {
      "x": -24,
      "y": 9,
      "z": 15,
      "name": "Empty"
    },
    {
      "x": -24,
      "y": 10,
      "z": 15,
      "name": "Empty"
    },
    {
      "x": -24,
      "y": 11,
      "z": 15,
      "name": "Rock_Shale_Brick"
    },
    {
      "x": -24,
      "y": 5,
      "z": 16,
      "name": "Rock_Shale_Brick"
    },
    {
      "x": -24,
      "y": 6,
      "z": 16,
      "name": "Empty"
    },
    {
      "x": -24,
      "y": 7,
      "z": 16,
      "name": "Empty"
    },
    {
      "x": -24,
      "y": 8,
      "z": 16,
      "name": "Empty"
    },
    {
      "x": -24,
      "y": 9,
      "z": 16,
      "name": "Empty"
    },
    {
      "x": -24,
      "y": 10,
      "z": 16,
      "name": "Empty"
    },
    {
      "x": -24,
      "y": 11,
      "z": 16,
      "name": "Rock_Shale_Brick"
    },
    {
      "x": -24,
      "y": 5,
      "z": 17,
      "name": "Rock_Shale_Brick"
    },
    {
      "x": -24,
      "y": 6,
      "z": 17,
      "name": "Empty"
    },
    {
      "x": -24,
      "y": 7,
      "z": 17,
      "name": "Empty"
    },
    {
      "x": -24,
      "y": 8,
      "z": 17,
      "name": "Empty"
    },
    {
      "x": -24,
      "y": 9,
      "z": 17,
      "name": "Empty"
    },
    {
      "x": -24,
      "y": 10,
      "z": 17,
      "name": "Empty"
    },
    {
      "x": -24,
      "y": 11,
      "z": 17,
      "name": "Rock_Shale_Brick"
    },
    {
      "x": -24,
      "y": 5,
      "z": 18,
      "name": "Rock_Shale_Brick"
    },
    {
      "x": -24,
      "y": 6,
      "z": 18,
      "name": "Plant_Moss_Rug_Green_Dark",
      "support": 15
    },
    {
      "x": -24,
      "y": 7,
      "z": 18,
      "name": "Empty"
    },
    {
      "x": -24,
      "y": 8,
      "z": 18,
      "name": "Empty"
    },
    {
      "x": -24,
      "y": 9,
      "z": 18,
      "name": "Empty"
    },
    {
      "x": -24,
      "y": 10,
      "z": 18,
      "name": "Empty"
    },
    {
      "x": -24,
      "y": 11,
      "z": 18,
      "name": "Rock_Shale_Brick"
    },
    {
      "x": -24,
      "y": 5,
      "z": 19,
      "name": "Rock_Shale_Brick"
    },
    {
      "x": -24,
      "y": 6,
      "z": 19,
      "name": "Plant_Moss_Rug_Green_Dark",
      "support": 15
    },
    {
      "x": -24,
      "y": 7,
      "z": 19,
      "name": "Empty"
    },
    {
      "x": -24,
      "y": 8,
      "z": 19,
      "name": "Empty"
    },
    {
      "x": -24,
      "y": 9,
      "z": 19,
      "name": "Empty"
    },
    {
      "x": -24,
      "y": 10,
      "z": 19,
      "name": "Empty"
    },
    {
      "x": -24,
      "y": 11,
      "z": 19,
      "name": "Rock_Shale_Brick"
    },
    {
      "x": -24,
      "y": 5,
      "z": 20,
      "name": "Rock_Shale_Brick"
    },
    {
      "x": -24,
      "y": 6,
      "z": 20,
      "name": "Rock_Shale_Brick"
    },
    {
      "x": -24,
      "y": 7,
      "z": 20,
      "name": "Rock_Shale_Brick"
    },
    {
      "x": -24,
      "y": 8,
      "z": 20,
      "name": "Rock_Shale_Brick"
    },
    {
      "x": -24,
      "y": 9,
      "z": 20,
      "name": "Rock_Shale_Brick"
    },
    {
      "x": -24,
      "y": 10,
      "z": 20,
      "name": "Rock_Shale_Brick"
    },
    {
      "x": -24,
      "y": 11,
      "z": 20,
      "name": "Rock_Shale_Brick"
    },
    {
      "x": -23,
      "y": 5,
      "z": 9,
      "name": "Rock_Shale_Brick"
    },
    {
      "x": -23,
      "y": 6,
      "z": 9,
      "name": "Rock_Shale_Brick"
    },
    {
      "x": -23,
      "y": 7,
      "z": 9,
      "name": "Rock_Shale_Brick"
    },
    {
      "x": -23,
      "y": 8,
      "z": 9,
      "name": "Rock_Shale_Brick"
    },
    {
      "x": -23,
      "y": 9,
      "z": 9,
      "name": "Rock_Shale_Brick"
    },
    {
      "x": -23,
      "y": 10,
      "z": 9,
      "name": "Rock_Shale_Brick"
    },
    {
      "x": -23,
      "y": 11,
      "z": 9,
      "name": "Rock_Shale_Brick"
    },
    {
      "x": -23,
      "y": 5,
      "z": 10,
      "name": "Rock_Shale_Brick"
    },
    {
      "x": -23,
      "y": 6,
      "z": 10,
      "name": "Rubble_Stone_Mossy",
      "support": 15
    },
    {
      "x": -23,
      "y": 7,
      "z": 10,
      "name": "Empty"
    },
    {
      "x": -23,
      "y": 8,
      "z": 10,
      "name": "Empty"
    },
    {
      "x": -23,
      "y": 9,
      "z": 10,
      "name": "Plant_Moss_Wall_Green_Dark",
      "support": 15
    },
    {
      "x": -23,
      "y": 10,
      "z": 10,
      "name": "Plant_Moss_Wall_Green_Dark",
      "support": 15
    },
    {
      "x": -23,
      "y": 11,
      "z": 10,
      "name": "Rock_Shale_Brick"
    },
    {
      "x": -23,
      "y": 5,
      "z": 11,
      "name": "Rock_Shale_Brick"
    },
    {
      "x": -23,
      "y": 6,
      "z": 11,
      "name": "Empty"
    },
    {
      "x": -23,
      "y": 7,
      "z": 11,
      "name": "Empty"
    },
    {
      "x": -23,
      "y": 8,
      "z": 11,
      "name": "Empty"
    },
    {
      "x": -23,
      "y": 9,
      "z": 11,
      "name": "Empty"
    },
    {
      "x": -23,
      "y": 10,
      "z": 11,
      "name": "Empty"
    },
    {
      "x": -23,
      "y": 11,
      "z": 11,
      "name": "Rock_Shale_Brick"
    },
    {
      "x": -23,
      "y": 5,
      "z": 12,
      "name": "Rock_Shale_Brick"
    },
    {
      "x": -23,
      "y": 6,
      "z": 12,
      "name": "Empty"
    },
    {
      "x": -23,
      "y": 7,
      "z": 12,
      "name": "Empty"
    },
    {
      "x": -23,
      "y": 8,
      "z": 12,
      "name": "Empty"
    },
    {
      "x": -23,
      "y": 9,
      "z": 12,
      "name": "Empty"
    },
    {
      "x": -23,
      "y": 10,
      "z": 12,
      "name": "Empty"
    },
    {
      "x": -23,
      "y": 11,
      "z": 12,
      "name": "Rock_Shale_Brick"
    },
    {
      "x": -23,
      "y": 5,
      "z": 13,
      "name": "Rock_Shale_Brick"
    },
    {
      "x": -23,
      "y": 6,
      "z": 13,
      "name": "Empty"
    },
    {
      "x": -23,
      "y": 7,
      "z": 13,
      "name": "Empty"
    },
    {
      "x": -23,
      "y": 8,
      "z": 13,
      "name": "Empty"
    },
    {
      "x": -23,
      "y": 9,
      "z": 13,
      "name": "Empty"
    },
    {
      "x": -23,
      "y": 10,
      "z": 13,
      "name": "Empty"
    },
    {
      "x": -23,
      "y": 11,
      "z": 13,
      "name": "Rock_Shale_Brick"
    },
    {
      "x": -23,
      "y": 5,
      "z": 14,
      "name": "Rock_Shale_Brick"
    },
    {
      "x": -23,
      "y": 6,
      "z": 14,
      "name": "Empty"
    },
    {
      "x": -23,
      "y": 7,
      "z": 14,
      "name": "Empty"
    },
    {
      "x": -23,
      "y": 8,
      "z": 14,
      "name": "Empty"
    },
    {
      "x": -23,
      "y": 9,
      "z": 14,
      "name": "Empty"
    },
    {
      "x": -23,
      "y": 10,
      "z": 14,
      "name": "Empty"
    },
    {
      "x": -23,
      "y": 11,
      "z": 14,
      "name": "Rock_Shale_Brick"
    },
    {
      "x": -23,
      "y": 5,
      "z": 15,
      "name": "Rock_Shale_Brick"
    },
    {
      "x": -23,
      "y": 6,
      "z": 15,
      "name": "Empty"
    },
    {
      "x": -23,
      "y": 7,
      "z": 15,
      "name": "Empty"
    },
    {
      "x": -23,
      "y": 8,
      "z": 15,
      "name": "Empty"
    },
    {
      "x": -23,
      "y": 9,
      "z": 15,
      "name": "Empty"
    },
    {
      "x": -23,
      "y": 10,
      "z": 15,
      "name": "Empty"
    },
    {
      "x": -23,
      "y": 11,
      "z": 15,
      "name": "Rock_Shale_Brick"
    },
    {
      "x": -23,
      "y": 5,
      "z": 16,
      "name": "Rock_Shale_Brick"
    },
    {
      "x": -23,
      "y": 6,
      "z": 16,
      "name": "Empty"
    },
    {
      "x": -23,
      "y": 7,
      "z": 16,
      "name": "Empty"
    },
    {
      "x": -23,
      "y": 8,
      "z": 16,
      "name": "Empty"
    },
    {
      "x": -23,
      "y": 9,
      "z": 16,
      "name": "Empty"
    },
    {
      "x": -23,
      "y": 10,
      "z": 16,
      "name": "Empty"
    },
    {
      "x": -23,
      "y": 11,
      "z": 16,
      "name": "Rock_Shale_Brick"
    },
    {
      "x": -23,
      "y": 5,
      "z": 17,
      "name": "Rock_Shale_Brick"
    },
    {
      "x": -23,
      "y": 6,
      "z": 17,
      "name": "Empty"
    },
    {
      "x": -23,
      "y": 7,
      "z": 17,
      "name": "Empty"
    },
    {
      "x": -23,
      "y": 8,
      "z": 17,
      "name": "Empty"
    },
    {
      "x": -23,
      "y": 9,
      "z": 17,
      "name": "Empty"
    },
    {
      "x": -23,
      "y": 10,
      "z": 17,
      "name": "Empty"
    },
    {
      "x": -23,
      "y": 11,
      "z": 17,
      "name": "Rock_Shale_Brick"
    },
    {
      "x": -23,
      "y": 5,
      "z": 18,
      "name": "Rock_Shale_Brick"
    },
    {
      "x": -23,
      "y": 6,
      "z": 18,
      "name": "Empty"
    },
    {
      "x": -23,
      "y": 7,
      "z": 18,
      "name": "Empty"
    },
    {
      "x": -23,
      "y": 8,
      "z": 18,
      "name": "Empty"
    },
    {
      "x": -23,
      "y": 9,
      "z": 18,
      "name": "Empty"
    },
    {
      "x": -23,
      "y": 10,
      "z": 18,
      "name": "Empty"
    },
    {
      "x": -23,
      "y": 11,
      "z": 18,
      "name": "Rock_Shale_Brick"
    },
    {
      "x": -23,
      "y": 5,
      "z": 19,
      "name": "Rock_Shale_Brick"
    },
    {
      "x": -23,
      "y": 6,
      "z": 19,
      "name": "Plant_Moss_Rug_Green_Dark",
      "support": 15
    },
    {
      "x": -23,
      "y": 7,
      "z": 19,
      "name": "Empty"
    },
    {
      "x": -23,
      "y": 8,
      "z": 19,
      "name": "Empty"
    },
    {
      "x": -23,
      "y": 9,
      "z": 19,
      "name": "Empty"
    },
    {
      "x": -23,
      "y": 10,
      "z": 19,
      "name": "Empty"
    },
    {
      "x": -23,
      "y": 11,
      "z": 19,
      "name": "Rock_Shale_Brick"
    },
    {
      "x": -23,
      "y": 5,
      "z": 20,
      "name": "Rock_Shale_Brick"
    },
    {
      "x": -23,
      "y": 6,
      "z": 20,
      "name": "Rock_Shale_Brick"
    },
    {
      "x": -23,
      "y": 7,
      "z": 20,
      "name": "Rock_Shale_Brick"
    },
    {
      "x": -23,
      "y": 8,
      "z": 20,
      "name": "Rock_Shale_Brick"
    },
    {
      "x": -23,
      "y": 9,
      "z": 20,
      "name": "Rock_Shale_Brick"
    },
    {
      "x": -23,
      "y": 10,
      "z": 20,
      "name": "Rock_Shale_Brick"
    },
    {
      "x": -23,
      "y": 11,
      "z": 20,
      "name": "Rock_Shale_Brick"
    },
    {
      "x": -22,
      "y": 5,
      "z": 9,
      "name": "Rock_Shale_Brick"
    },
    {
      "x": -22,
      "y": 6,
      "z": 9,
      "name": "Rock_Shale_Brick"
    },
    {
      "x": -22,
      "y": 7,
      "z": 9,
      "name": "Rock_Shale_Brick"
    },
    {
      "x": -22,
      "y": 8,
      "z": 9,
      "name": "Rock_Shale_Brick"
    },
    {
      "x": -22,
      "y": 9,
      "z": 9,
      "name": "Rock_Shale_Brick"
    },
    {
      "x": -22,
      "y": 10,
      "z": 9,
      "name": "Rock_Shale_Brick"
    },
    {
      "x": -22,
      "y": 11,
      "z": 9,
      "name": "Rock_Shale_Brick"
    },
    {
      "x": -22,
      "y": 5,
      "z": 10,
      "name": "Rock_Shale_Brick"
    },
    {
      "x": -22,
      "y": 6,
      "z": 10,
      "name": "Plant_Moss_Rug_Green_Dark",
      "support": 15
    },
    {
      "x": -22,
      "y": 7,
      "z": 10,
      "name": "Empty"
    },
    {
      "x": -22,
      "y": 8,
      "z": 10,
      "name": "Empty"
    },
    {
      "x": -22,
      "y": 9,
      "z": 10,
      "name": "Empty"
    },
    {
      "x": -22,
      "y": 10,
      "z": 10,
      "name": "Plant_Moss_Cave_Green_Dark",
      "support": 15,
      "rotation": 8
    },
    {
      "x": -22,
      "y": 11,
      "z": 10,
      "name": "Rock_Shale_Brick"
    },
    {
      "x": -22,
      "y": 5,
      "z": 11,
      "name": "Rock_Shale_Brick"
    },
    {
      "x": -22,
      "y": 6,
      "z": 11,
      "name": "Empty"
    },
    {
      "x": -22,
      "y": 7,
      "z": 11,
      "name": "Empty"
    },
    {
      "x": -22,
      "y": 8,
      "z": 11,
      "name": "Empty"
    },
    {
      "x": -22,
      "y": 9,
      "z": 11,
      "name": "Empty"
    },
    {
      "x": -22,
      "y": 10,
      "z": 11,
      "name": "Empty"
    },
    {
      "x": -22,
      "y": 11,
      "z": 11,
      "name": "Rock_Shale_Brick"
    },
    {
      "x": -22,
      "y": 5,
      "z": 12,
      "name": "Rock_Shale_Brick"
    },
    {
      "x": -22,
      "y": 6,
      "z": 12,
      "name": "Empty"
    },
    {
      "x": -22,
      "y": 7,
      "z": 12,
      "name": "Empty"
    },
    {
      "x": -22,
      "y": 8,
      "z": 12,
      "name": "Empty"
    },
    {
      "x": -22,
      "y": 9,
      "z": 12,
      "name": "Empty"
    },
    {
      "x": -22,
      "y": 10,
      "z": 12,
      "name": "Empty"
    },
    {
      "x": -22,
      "y": 11,
      "z": 12,
      "name": "Rock_Shale_Brick"
    },
    {
      "x": -22,
      "y": 5,
      "z": 13,
      "name": "Rock_Shale_Brick"
    },
    {
      "x": -22,
      "y": 6,
      "z": 13,
      "name": "Empty"
    },
    {
      "x": -22,
      "y": 7,
      "z": 13,
      "name": "Empty"
    },
    {
      "x": -22,
      "y": 8,
      "z": 13,
      "name": "Empty"
    },
    {
      "x": -22,
      "y": 9,
      "z": 13,
      "name": "Empty"
    },
    {
      "x": -22,
      "y": 10,
      "z": 13,
      "name": "Empty"
    },
    {
      "x": -22,
      "y": 11,
      "z": 13,
      "name": "Rock_Shale_Brick"
    },
    {
      "x": -22,
      "y": 5,
      "z": 14,
      "name": "Rock_Shale_Brick"
    },
    {
      "x": -22,
      "y": 6,
      "z": 14,
      "name": "Empty"
    },
    {
      "x": -22,
      "y": 7,
      "z": 14,
      "name": "Empty"
    },
    {
      "x": -22,
      "y": 8,
      "z": 14,
      "name": "Empty"
    },
    {
      "x": -22,
      "y": 9,
      "z": 14,
      "name": "Empty"
    },
    {
      "x": -22,
      "y": 10,
      "z": 14,
      "name": "Empty"
    },
    {
      "x": -22,
      "y": 11,
      "z": 14,
      "name": "Rock_Shale_Brick"
    },
    {
      "x": -22,
      "y": 5,
      "z": 15,
      "name": "Rock_Shale_Brick"
    },
    {
      "x": -22,
      "y": 6,
      "z": 15,
      "name": "Empty"
    },
    {
      "x": -22,
      "y": 7,
      "z": 15,
      "name": "Empty"
    },
    {
      "x": -22,
      "y": 8,
      "z": 15,
      "name": "Empty"
    },
    {
      "x": -22,
      "y": 9,
      "z": 15,
      "name": "Empty"
    },
    {
      "x": -22,
      "y": 10,
      "z": 15,
      "name": "Empty"
    },
    {
      "x": -22,
      "y": 11,
      "z": 15,
      "name": "Rock_Shale_Brick"
    },
    {
      "x": -22,
      "y": 5,
      "z": 16,
      "name": "Rock_Shale_Brick"
    },
    {
      "x": -22,
      "y": 6,
      "z": 16,
      "name": "Empty"
    },
    {
      "x": -22,
      "y": 7,
      "z": 16,
      "name": "Empty"
    },
    {
      "x": -22,
      "y": 8,
      "z": 16,
      "name": "Empty"
    },
    {
      "x": -22,
      "y": 9,
      "z": 16,
      "name": "Empty"
    },
    {
      "x": -22,
      "y": 10,
      "z": 16,
      "name": "Empty"
    },
    {
      "x": -22,
      "y": 11,
      "z": 16,
      "name": "Rock_Shale_Brick"
    },
    {
      "x": -22,
      "y": 5,
      "z": 17,
      "name": "Rock_Shale_Brick"
    },
    {
      "x": -22,
      "y": 6,
      "z": 17,
      "name": "Empty"
    },
    {
      "x": -22,
      "y": 7,
      "z": 17,
      "name": "Empty"
    },
    {
      "x": -22,
      "y": 8,
      "z": 17,
      "name": "Empty"
    },
    {
      "x": -22,
      "y": 9,
      "z": 17,
      "name": "Empty"
    },
    {
      "x": -22,
      "y": 10,
      "z": 17,
      "name": "Empty"
    },
    {
      "x": -22,
      "y": 11,
      "z": 17,
      "name": "Rock_Shale_Brick"
    },
    {
      "x": -22,
      "y": 5,
      "z": 18,
      "name": "Rock_Shale_Brick"
    },
    {
      "x": -22,
      "y": 6,
      "z": 18,
      "name": "Empty"
    },
    {
      "x": -22,
      "y": 7,
      "z": 18,
      "name": "Empty"
    },
    {
      "x": -22,
      "y": 8,
      "z": 18,
      "name": "Empty"
    },
    {
      "x": -22,
      "y": 9,
      "z": 18,
      "name": "Empty"
    },
    {
      "x": -22,
      "y": 10,
      "z": 18,
      "name": "Empty"
    },
    {
      "x": -22,
      "y": 11,
      "z": 18,
      "name": "Rock_Shale_Brick"
    },
    {
      "x": -22,
      "y": 5,
      "z": 19,
      "name": "Rock_Shale_Brick"
    },
    {
      "x": -22,
      "y": 6,
      "z": 19,
      "name": "Plant_Moss_Rug_Green_Dark",
      "support": 15
    },
    {
      "x": -22,
      "y": 7,
      "z": 19,
      "name": "Empty"
    },
    {
      "x": -22,
      "y": 8,
      "z": 19,
      "name": "Empty"
    },
    {
      "x": -22,
      "y": 9,
      "z": 19,
      "name": "Empty"
    },
    {
      "x": -22,
      "y": 10,
      "z": 19,
      "name": "Empty"
    },
    {
      "x": -22,
      "y": 11,
      "z": 19,
      "name": "Rock_Shale_Brick"
    },
    {
      "x": -22,
      "y": 5,
      "z": 20,
      "name": "Rock_Shale_Brick"
    },
    {
      "x": -22,
      "y": 6,
      "z": 20,
      "name": "Rock_Shale_Brick"
    },
    {
      "x": -22,
      "y": 7,
      "z": 20,
      "name": "Rock_Shale_Brick"
    },
    {
      "x": -22,
      "y": 8,
      "z": 20,
      "name": "Rock_Shale_Brick"
    },
    {
      "x": -22,
      "y": 9,
      "z": 20,
      "name": "Rock_Shale_Brick"
    },
    {
      "x": -22,
      "y": 10,
      "z": 20,
      "name": "Rock_Shale_Brick"
    },
    {
      "x": -22,
      "y": 11,
      "z": 20,
      "name": "Rock_Shale_Brick"
    },
    {
      "x": -21,
      "y": 5,
      "z": 9,
      "name": "Rock_Shale_Brick"
    },
    {
      "x": -21,
      "y": 6,
      "z": 9,
      "name": "Rock_Shale_Brick"
    },
    {
      "x": -21,
      "y": 7,
      "z": 9,
      "name": "Rock_Shale_Brick"
    },
    {
      "x": -21,
      "y": 8,
      "z": 9,
      "name": "Rock_Shale_Brick"
    },
    {
      "x": -21,
      "y": 9,
      "z": 9,
      "name": "Rock_Shale_Brick"
    },
    {
      "x": -21,
      "y": 10,
      "z": 9,
      "name": "Rock_Shale_Brick"
    },
    {
      "x": -21,
      "y": 11,
      "z": 9,
      "name": "Rock_Shale_Brick"
    },
    {
      "x": -21,
      "y": 5,
      "z": 10,
      "name": "Rock_Shale_Brick"
    },
    {
      "x": -21,
      "y": 6,
      "z": 10,
      "name": "Furniture_SK_Monument_Chest_Small",
      "components": {
        "Components": {
          "ItemContainerBlock": {
            "ItemContainer": {
              "Capacity": 18,
              "Items": {
                "2": {
                  "Id": "Ingredient_Fabric_Scrap_Linen",
                  "Quantity": 6,
                  "Durability": 0.0,
                  "MaxDurability": 0.0,
                  "OverrideDroppedItemAnimation": false
                },
                "4": {
                  "Id": "Tool_Repair_Kit_Iron",
                  "Quantity": 1,
                  "Durability": 0.0,
                  "MaxDurability": 0.0,
                  "OverrideDroppedItemAnimation": false
                },
                "14": {
                  "Id": "Ore_Mithril",
                  "Quantity": 3,
                  "Durability": 0.0,
                  "MaxDurability": 0.0,
                  "OverrideDroppedItemAnimation": false
                },
                "9": {
                  "Id": "Food_Wildmeat_Cooked",
                  "Quantity": 1,
                  "Durability": 0.0,
                  "MaxDurability": 0.0,
                  "OverrideDroppedItemAnimation": false
                },
                "1": {
                  "Id": "Tool_Hatchet_Crude",
                  "Quantity": 1,
                  "Durability": 150.0,
                  "MaxDurability": 150.0,
                  "OverrideDroppedItemAnimation": false
                },
                "3": {
                  "Id": "Ingredient_Fabric_Scrap_Linen",
                  "Quantity": 4,
                  "Durability": 0.0,
                  "MaxDurability": 0.0,
                  "OverrideDroppedItemAnimation": false
                },
                "17": {
                  "Id": "Food_Kebab_Meat",
                  "Quantity": 1,
                  "Durability": 0.0,
                  "MaxDurability": 0.0,
                  "OverrideDroppedItemAnimation": false
                }
              }
            },
            "Capacity": 20
          }
        }
      }
    },
    {
      "x": -21,
      "y": 7,
      "z": 10,
      "name": "Empty"
    },
    {
      "x": -21,
      "y": 8,
      "z": 10,
      "name": "Empty"
    },
    {
      "x": -21,
      "y": 9,
      "z": 10,
      "name": "Empty"
    },
    {
      "x": -21,
      "y": 10,
      "z": 10,
      "name": "Plant_Moss_Wall_Green_Dark",
      "support": 15
    },
    {
      "x": -21,
      "y": 11,
      "z": 10,
      "name": "Rock_Shale_Brick"
    },
    {
      "x": -21,
      "y": 5,
      "z": 11,
      "name": "Rock_Shale_Brick"
    },
    {
      "x": -21,
      "y": 6,
      "z": 11,
      "name": "Empty"
    },
    {
      "x": -21,
      "y": 7,
      "z": 11,
      "name": "Empty"
    },
    {
      "x": -21,
      "y": 8,
      "z": 11,
      "name": "Empty"
    },
    {
      "x": -21,
      "y": 9,
      "z": 11,
      "name": "Empty"
    },
    {
      "x": -21,
      "y": 10,
      "z": 11,
      "name": "Empty"
    },
    {
      "x": -21,
      "y": 11,
      "z": 11,
      "name": "Rock_Shale_Brick"
    },
    {
      "x": -21,
      "y": 5,
      "z": 12,
      "name": "Rock_Shale_Brick"
    },
    {
      "x": -21,
      "y": 6,
      "z": 12,
      "name": "Empty"
    },
    {
      "x": -21,
      "y": 7,
      "z": 12,
      "name": "Empty"
    },
    {
      "x": -21,
      "y": 8,
      "z": 12,
      "name": "Empty"
    },
    {
      "x": -21,
      "y": 9,
      "z": 12,
      "name": "Empty"
    },
    {
      "x": -21,
      "y": 10,
      "z": 12,
      "name": "Empty"
    },
    {
      "x": -21,
      "y": 11,
      "z": 12,
      "name": "Rock_Shale_Brick"
    },
    {
      "x": -21,
      "y": 5,
      "z": 13,
      "name": "Rock_Shale_Brick"
    },
    {
      "x": -21,
      "y": 6,
      "z": 13,
      "name": "Empty"
    },
    {
      "x": -21,
      "y": 7,
      "z": 13,
      "name": "Empty"
    },
    {
      "x": -21,
      "y": 8,
      "z": 13,
      "name": "Empty"
    },
    {
      "x": -21,
      "y": 9,
      "z": 13,
      "name": "Empty"
    },
    {
      "x": -21,
      "y": 10,
      "z": 13,
      "name": "Empty"
    },
    {
      "x": -21,
      "y": 11,
      "z": 13,
      "name": "Rock_Shale_Brick"
    },
    {
      "x": -21,
      "y": 5,
      "z": 14,
      "name": "Rock_Shale_Brick"
    },
    {
      "x": -21,
      "y": 6,
      "z": 14,
      "name": "Empty"
    },
    {
      "x": -21,
      "y": 7,
      "z": 14,
      "name": "Empty"
    },
    {
      "x": -21,
      "y": 8,
      "z": 14,
      "name": "Empty"
    },
    {
      "x": -21,
      "y": 9,
      "z": 14,
      "name": "Empty"
    },
    {
      "x": -21,
      "y": 10,
      "z": 14,
      "name": "Empty"
    },
    {
      "x": -21,
      "y": 11,
      "z": 14,
      "name": "Rock_Shale_Brick"
    },
    {
      "x": -21,
      "y": 5,
      "z": 15,
      "name": "Rock_Shale_Brick"
    },
    {
      "x": -21,
      "y": 6,
      "z": 15,
      "name": "Empty"
    },
    {
      "x": -21,
      "y": 7,
      "z": 15,
      "name": "Empty"
    },
    {
      "x": -21,
      "y": 8,
      "z": 15,
      "name": "Empty"
    },
    {
      "x": -21,
      "y": 9,
      "z": 15,
      "name": "Empty"
    },
    {
      "x": -21,
      "y": 10,
      "z": 15,
      "name": "Empty"
    },
    {
      "x": -21,
      "y": 11,
      "z": 15,
      "name": "Rock_Shale_Brick"
    },
    {
      "x": -21,
      "y": 5,
      "z": 16,
      "name": "Rock_Shale_Brick"
    },
    {
      "x": -21,
      "y": 6,
      "z": 16,
      "name": "Empty"
    },
    {
      "x": -21,
      "y": 7,
      "z": 16,
      "name": "Empty"
    },
    {
      "x": -21,
      "y": 8,
      "z": 16,
      "name": "Empty"
    },
    {
      "x": -21,
      "y": 9,
      "z": 16,
      "name": "Empty"
    },
    {
      "x": -21,
      "y": 10,
      "z": 16,
      "name": "Empty"
    },
    {
      "x": -21,
      "y": 11,
      "z": 16,
      "name": "Rock_Shale_Brick"
    },
    {
      "x": -21,
      "y": 5,
      "z": 17,
      "name": "Rock_Shale_Brick"
    },
    {
      "x": -21,
      "y": 6,
      "z": 17,
      "name": "Empty"
    },
    {
      "x": -21,
      "y": 7,
      "z": 17,
      "name": "Empty"
    },
    {
      "x": -21,
      "y": 8,
      "z": 17,
      "name": "Empty"
    },
    {
      "x": -21,
      "y": 9,
      "z": 17,
      "name": "Empty"
    },
    {
      "x": -21,
      "y": 10,
      "z": 17,
      "name": "Empty"
    },
    {
      "x": -21,
      "y": 11,
      "z": 17,
      "name": "Rock_Shale_Brick"
    },
    {
      "x": -21,
      "y": 5,
      "z": 18,
      "name": "Rock_Shale_Brick"
    },
    {
      "x": -21,
      "y": 6,
      "z": 18,
      "name": "Plant_Moss_Rug_Green_Dark",
      "support": 15
    },
    {
      "x": -21,
      "y": 7,
      "z": 18,
      "name": "Empty"
    },
    {
      "x": -21,
      "y": 8,
      "z": 18,
      "name": "Empty"
    },
    {
      "x": -21,
      "y": 9,
      "z": 18,
      "name": "Empty"
    },
    {
      "x": -21,
      "y": 10,
      "z": 18,
      "name": "Empty"
    },
    {
      "x": -21,
      "y": 11,
      "z": 18,
      "name": "Rock_Shale_Brick"
    },
    {
      "x": -21,
      "y": 5,
      "z": 19,
      "name": "Rock_Shale_Brick"
    },
    {
      "x": -21,
      "y": 6,
      "z": 19,
      "name": "Empty"
    },
    {
      "x": -21,
      "y": 7,
      "z": 19,
      "name": "Empty"
    },
    {
      "x": -21,
      "y": 8,
      "z": 19,
      "name": "Empty"
    },
    {
      "x": -21,
      "y": 9,
      "z": 19,
      "name": "Empty"
    },
    {
      "x": -21,
      "y": 10,
      "z": 19,
      "name": "Empty"
    },
    {
      "x": -21,
      "y": 11,
      "z": 19,
      "name": "Rock_Shale_Brick"
    },
    {
      "x": -21,
      "y": 5,
      "z": 20,
      "name": "Rock_Shale_Brick"
    },
    {
      "x": -21,
      "y": 6,
      "z": 20,
      "name": "Rock_Shale_Brick"
    },
    {
      "x": -21,
      "y": 7,
      "z": 20,
      "name": "Rock_Shale_Brick"
    },
    {
      "x": -21,
      "y": 8,
      "z": 20,
      "name": "Rock_Shale_Brick"
    },
    {
      "x": -21,
      "y": 9,
      "z": 20,
      "name": "Rock_Shale_Brick"
    },
    {
      "x": -21,
      "y": 10,
      "z": 20,
      "name": "Rock_Shale_Brick"
    },
    {
      "x": -21,
      "y": 11,
      "z": 20,
      "name": "Rock_Shale_Brick"
    },
    {
      "x": -20,
      "y": 5,
      "z": 9,
      "name": "Rock_Shale_Brick"
    },
    {
      "x": -20,
      "y": 6,
      "z": 9,
      "name": "Rock_Shale_Brick"
    },
    {
      "x": -20,
      "y": 7,
      "z": 9,
      "name": "Rock_Shale_Brick"
    },
    {
      "x": -20,
      "y": 8,
      "z": 9,
      "name": "Rock_Shale_Brick"
    },
    {
      "x": -20,
      "y": 9,
      "z": 9,
      "name": "Rock_Shale_Brick"
    },
    {
      "x": -20,
      "y": 10,
      "z": 9,
      "name": "Rock_Shale_Brick"
    },
    {
      "x": -20,
      "y": 11,
      "z": 9,
      "name": "Rock_Shale_Brick"
    },
    {
      "x": -20,
      "y": 5,
      "z": 10,
      "name": "Rock_Shale_Brick"
    },
    {
      "x": -20,
      "y": 6,
      "z": 10,
      "name": "Rock_Shale_Brick"
    },
    {
      "x": -20,
      "y": 7,
      "z": 10,
      "name": "Rock_Shale_Brick"
    },
    {
      "x": -20,
      "y": 8,
      "z": 10,
      "name": "Rock_Shale_Brick"
    },
    {
      "x": -20,
      "y": 9,
      "z": 10,
      "name": "Rock_Shale_Brick"
    },
    {
      "x": -20,
      "y": 10,
      "z": 10,
      "name": "Rock_Shale_Brick"
    },
    {
      "x": -20,
      "y": 11,
      "z": 10,
      "name": "Rock_Shale_Brick"
    },
    {
      "x": -20,
      "y": 5,
      "z": 11,
      "name": "Rock_Shale_Brick"
    },
    {
      "x": -20,
      "y": 6,
      "z": 11,
      "name": "Rock_Shale_Brick"
    },
    {
      "x": -20,
      "y": 7,
      "z": 11,
      "name": "Rock_Shale_Brick"
    },
    {
      "x": -20,
      "y": 8,
      "z": 11,
      "name": "Rock_Shale_Brick"
    },
    {
      "x": -20,
      "y": 9,
      "z": 11,
      "name": "Rock_Shale_Brick"
    },
    {
      "x": -20,
      "y": 10,
      "z": 11,
      "name": "Rock_Shale_Brick"
    },
    {
      "x": -20,
      "y": 11,
      "z": 11,
      "name": "Rock_Shale_Brick"
    },
    {
      "x": -20,
      "y": 5,
      "z": 12,
      "name": "Rock_Shale_Brick"
    },
    {
      "x": -20,
      "y": 6,
      "z": 12,
      "name": "Rock_Shale_Brick"
    },
    {
      "x": -20,
      "y": 7,
      "z": 12,
      "name": "Rock_Shale_Brick"
    },
    {
      "x": -20,
      "y": 8,
      "z": 12,
      "name": "Rock_Shale_Brick"
    },
    {
      "x": -20,
      "y": 9,
      "z": 12,
      "name": "Rock_Shale_Brick"
    },
    {
      "x": -20,
      "y": 10,
      "z": 12,
      "name": "Rock_Shale_Brick"
    },
    {
      "x": -20,
      "y": 11,
      "z": 12,
      "name": "Rock_Shale_Brick"
    },
    {
      "x": -20,
      "y": 5,
      "z": 13,
      "name": "Rock_Shale_Brick"
    },
    {
      "x": -20,
      "y": 6,
      "z": 13,
      "name": "Rock_Shale_Brick"
    },
    {
      "x": -20,
      "y": 7,
      "z": 13,
      "name": "Rock_Shale_Brick"
    },
    {
      "x": -20,
      "y": 8,
      "z": 13,
      "name": "Rock_Shale_Brick"
    },
    {
      "x": -20,
      "y": 9,
      "z": 13,
      "name": "Rock_Shale_Brick"
    },
    {
      "x": -20,
      "y": 10,
      "z": 13,
      "name": "Rock_Shale_Brick"
    },
    {
      "x": -20,
      "y": 11,
      "z": 13,
      "name": "Rock_Shale_Brick"
    },
    {
      "x": -20,
      "y": 5,
      "z": 14,
      "name": "Rock_Shale_Brick"
    },
    {
      "x": -20,
      "y": 6,
      "z": 14,
      "name": "Rock_Shale_Brick"
    },
    {
      "x": -20,
      "y": 7,
      "z": 14,
      "name": "Rock_Shale_Brick"
    },
    {
      "x": -20,
      "y": 8,
      "z": 14,
      "name": "Rock_Shale_Brick"
    },
    {
      "x": -20,
      "y": 9,
      "z": 14,
      "name": "Rock_Shale_Brick"
    },
    {
      "x": -20,
      "y": 10,
      "z": 14,
      "name": "Rock_Shale_Brick"
    },
    {
      "x": -20,
      "y": 11,
      "z": 14,
      "name": "Rock_Shale_Brick"
    },
    {
      "x": -20,
      "y": 5,
      "z": 15,
      "name": "Rock_Shale_Brick"
    },
    {
      "x": -20,
      "y": 6,
      "z": 15,
      "name": "Rock_Shale_Brick"
    },
    {
      "x": -20,
      "y": 7,
      "z": 15,
      "name": "Rock_Shale_Brick"
    },
    {
      "x": -20,
      "y": 8,
      "z": 15,
      "name": "Rock_Shale_Brick"
    },
    {
      "x": -20,
      "y": 9,
      "z": 15,
      "name": "Rock_Shale_Brick"
    },
    {
      "x": -20,
      "y": 10,
      "z": 15,
      "name": "Rock_Shale_Brick"
    },
    {
      "x": -20,
      "y": 11,
      "z": 15,
      "name": "Rock_Shale_Brick"
    },
    {
      "x": -20,
      "y": 5,
      "z": 16,
      "name": "Rock_Shale_Brick"
    },
    {
      "x": -20,
      "y": 6,
      "z": 16,
      "name": "Empty"
    },
    {
      "x": -20,
      "y": 7,
      "z": 16,
      "name": "Empty"
    },
    {
      "x": -20,
      "y": 8,
      "z": 16,
      "name": "Empty"
    },
    {
      "x": -20,
      "y": 9,
      "z": 16,
      "name": "Empty"
    },
    {
      "x": -20,
      "y": 10,
      "z": 16,
      "name": "Empty"
    },
    {
      "x": -20,
      "y": 11,
      "z": 16,
      "name": "Rock_Shale_Brick"
    },
    {
      "x": -20,
      "y": 5,
      "z": 17,
      "name": "Rock_Shale_Brick"
    },
    {
      "x": -20,
      "y": 6,
      "z": 17,
      "name": "Empty"
    },
    {
      "x": -20,
      "y": 7,
      "z": 17,
      "name": "Empty"
    },
    {
      "x": -20,
      "y": 8,
      "z": 17,
      "name": "Empty"
    },
    {
      "x": -20,
      "y": 9,
      "z": 17,
      "name": "Empty"
    },
    {
      "x": -20,
      "y": 10,
      "z": 17,
      "name": "Empty"
    },
    {
      "x": -20,
      "y": 11,
      "z": 17,
      "name": "Rock_Shale_Brick"
    },
    {
      "x": -20,
      "y": 5,
      "z": 18,
      "name": "Rock_Shale_Brick"
    },
    {
      "x": -20,
      "y": 6,
      "z": 18,
      "name": "Empty"
    },
    {
      "x": -20,
      "y": 7,
      "z": 18,
      "name": "Empty"
    },
    {
      "x": -20,
      "y": 8,
      "z": 18,
      "name": "Empty"
    },
    {
      "x": -20,
      "y": 9,
      "z": 18,
      "name": "Empty"
    },
    {
      "x": -20,
      "y": 10,
      "z": 18,
      "name": "Empty"
    },
    {
      "x": -20,
      "y": 11,
      "z": 18,
      "name": "Rock_Shale_Brick"
    },
    {
      "x": -20,
      "y": 5,
      "z": 19,
      "name": "Rock_Shale_Brick"
    },
    {
      "x": -20,
      "y": 6,
      "z": 19,
      "name": "Empty"
    },
    {
      "x": -20,
      "y": 7,
      "z": 19,
      "name": "Empty"
    },
    {
      "x": -20,
      "y": 8,
      "z": 19,
      "name": "Empty"
    },
    {
      "x": -20,
      "y": 9,
      "z": 19,
      "name": "Empty"
    },
    {
      "x": -20,
      "y": 10,
      "z": 19,
      "name": "Empty"
    },
    {
      "x": -20,
      "y": 11,
      "z": 19,
      "name": "Rock_Shale_Brick"
    },
    {
      "x": -20,
      "y": 5,
      "z": 20,
      "name": "Rock_Shale_Brick"
    },
    {
      "x": -20,
      "y": 6,
      "z": 20,
      "name": "Rock_Shale_Brick"
    },
    {
      "x": -20,
      "y": 7,
      "z": 20,
      "name": "Rock_Shale_Brick"
    },
    {
      "x": -20,
      "y": 8,
      "z": 20,
      "name": "Rock_Shale_Brick"
    },
    {
      "x": -20,
      "y": 9,
      "z": 20,
      "name": "Rock_Shale_Brick"
    },
    {
      "x": -20,
      "y": 10,
      "z": 20,
      "name": "Rock_Shale_Brick"
    },
    {
      "x": -20,
      "y": 11,
      "z": 20,
      "name": "Rock_Shale_Brick"
    },
    {
      "x": -19,
      "y": 5,
      "z": 15,
      "name": "Rock_Shale_Brick"
    },
    {
      "x": -19,
      "y": 6,
      "z": 15,
      "name": "Rock_Shale_Brick"
    },
    {
      "x": -19,
      "y": 7,
      "z": 15,
      "name": "Rock_Shale_Brick"
    },
    {
      "x": -19,
      "y": 8,
      "z": 15,
      "name": "Rock_Shale_Brick"
    },
    {
      "x": -19,
      "y": 9,
      "z": 15,
      "name": "Rock_Shale_Brick"
    },
    {
      "x": -19,
      "y": 10,
      "z": 15,
      "name": "Rock_Shale_Brick"
    },
    {
      "x": -19,
      "y": 11,
      "z": 15,
      "name": "Rock_Shale_Brick"
    },
    {
      "x": -19,
      "y": 5,
      "z": 16,
      "name": "Rock_Shale_Brick"
    },
    {
      "x": -19,
      "y": 6,
      "z": 16,
      "name": "Empty"
    },
    {
      "x": -19,
      "y": 7,
      "z": 16,
      "name": "Empty"
    },
    {
      "x": -19,
      "y": 8,
      "z": 16,
      "name": "Empty"
    },
    {
      "x": -19,
      "y": 9,
      "z": 16,
      "name": "Empty"
    },
    {
      "x": -19,
      "y": 10,
      "z": 16,
      "name": "Empty"
    },
    {
      "x": -19,
      "y": 11,
      "z": 16,
      "name": "Rock_Shale_Brick"
    },
    {
      "x": -19,
      "y": 5,
      "z": 17,
      "name": "Rock_Shale_Brick"
    },
    {
      "x": -19,
      "y": 6,
      "z": 17,
      "name": "Empty"
    },
    {
      "x": -19,
      "y": 7,
      "z": 17,
      "name": "Empty"
    },
    {
      "x": -19,
      "y": 8,
      "z": 17,
      "name": "Empty"
    },
    {
      "x": -19,
      "y": 9,
      "z": 17,
      "name": "Empty"
    },
    {
      "x": -19,
      "y": 10,
      "z": 17,
      "name": "Empty"
    },
    {
      "x": -19,
      "y": 11,
      "z": 17,
      "name": "Rock_Shale_Brick"
    },
    {
      "x": -19,
      "y": 5,
      "z": 18,
      "name": "Rock_Shale_Brick"
    },
    {
      "x": -19,
      "y": 6,
      "z": 18,
      "name": "Empty"
    },
    {
      "x": -19,
      "y": 7,
      "z": 18,
      "name": "Empty"
    },
    {
      "x": -19,
      "y": 8,
      "z": 18,
      "name": "Empty"
    },
    {
      "x": -19,
      "y": 9,
      "z": 18,
      "name": "Empty"
    },
    {
      "x": -19,
      "y": 10,
      "z": 18,
      "name": "Empty"
    },
    {
      "x": -19,
      "y": 11,
      "z": 18,
      "name": "Rock_Shale_Brick"
    },
    {
      "x": -19,
      "y": 5,
      "z": 19,
      "name": "Rock_Shale_Brick"
    },
    {
      "x": -19,
      "y": 6,
      "z": 19,
      "name": "Empty"
    },
    {
      "x": -19,
      "y": 7,
      "z": 19,
      "name": "Empty"
    },
    {
      "x": -19,
      "y": 8,
      "z": 19,
      "name": "Empty"
    },
    {
      "x": -19,
      "y": 9,
      "z": 19,
      "name": "Empty"
    },
    {
      "x": -19,
      "y": 10,
      "z": 19,
      "name": "Empty"
    },
    {
      "x": -19,
      "y": 11,
      "z": 19,
      "name": "Rock_Shale_Brick"
    },
    {
      "x": -19,
      "y": 5,
      "z": 20,
      "name": "Rock_Shale_Brick"
    },
    {
      "x": -19,
      "y": 6,
      "z": 20,
      "name": "Rock_Shale_Brick"
    },
    {
      "x": -19,
      "y": 7,
      "z": 20,
      "name": "Rock_Shale_Brick"
    },
    {
      "x": -19,
      "y": 8,
      "z": 20,
      "name": "Rock_Shale_Brick"
    },
    {
      "x": -19,
      "y": 9,
      "z": 20,
      "name": "Rock_Shale_Brick"
    },
    {
      "x": -19,
      "y": 10,
      "z": 20,
      "name": "Rock_Shale_Brick"
    },
    {
      "x": -19,
      "y": 11,
      "z": 20,
      "name": "Rock_Shale_Brick"
    },
    {
      "x": -18,
      "y": 5,
      "z": 15,
      "name": "Rock_Shale_Brick"
    },
    {
      "x": -18,
      "y": 6,
      "z": 15,
      "name": "Rock_Shale_Brick"
    },
    {
      "x": -18,
      "y": 7,
      "z": 15,
      "name": "Rock_Shale_Brick"
    },
    {
      "x": -18,
      "y": 8,
      "z": 15,
      "name": "Rock_Shale_Brick"
    },
    {
      "x": -18,
      "y": 9,
      "z": 15,
      "name": "Rock_Shale_Brick"
    },
    {
      "x": -18,
      "y": 10,
      "z": 15,
      "name": "Rock_Shale_Brick"
    },
    {
      "x": -18,
      "y": 11,
      "z": 15,
      "name": "Rock_Shale_Brick"
    },
    {
      "x": -18,
      "y": 5,
      "z": 16,
      "name": "Rock_Shale_Brick"
    },
    {
      "x": -18,
      "y": 6,
      "z": 16,
      "name": "Empty"
    },
    {
      "x": -18,
      "y": 7,
      "z": 16,
      "name": "Empty"
    },
    {
      "x": -18,
      "y": 8,
      "z": 16,
      "name": "Empty"
    },
    {
      "x": -18,
      "y": 9,
      "z": 16,
      "name": "Plant_Moss_Wall_Green_Dark",
      "support": 15
    },
    {
      "x": -18,
      "y": 10,
      "z": 16,
      "name": "Plant_Moss_Wall_Green_Dark",
      "support": 15
    },
    {
      "x": -18,
      "y": 11,
      "z": 16,
      "name": "Rock_Shale_Brick"
    },
    {
      "x": -18,
      "y": 5,
      "z": 17,
      "name": "Rock_Shale_Brick"
    },
    {
      "x": -18,
      "y": 6,
      "z": 17,
      "name": "Empty"
    },
    {
      "x": -18,
      "y": 7,
      "z": 17,
      "name": "Empty"
    },
    {
      "x": -18,
      "y": 8,
      "z": 17,
      "name": "Empty"
    },
    {
      "x": -18,
      "y": 9,
      "z": 17,
      "name": "Empty"
    },
    {
      "x": -18,
      "y": 10,
      "z": 17,
      "name": "Empty"
    },
    {
      "x": -18,
      "y": 11,
      "z": 17,
      "name": "Rock_Shale_Brick"
    },
    {
      "x": -18,
      "y": 5,
      "z": 18,
      "name": "Rock_Shale_Brick"
    },
    {
      "x": -18,
      "y": 6,
      "z": 18,
      "name": "Empty"
    },
    {
      "x": -18,
      "y": 7,
      "z": 18,
      "name": "Empty"
    },
    {
      "x": -18,
      "y": 8,
      "z": 18,
      "name": "Empty"
    },
    {
      "x": -18,
      "y": 9,
      "z": 18,
      "name": "Empty"
    },
    {
      "x": -18,
      "y": 10,
      "z": 18,
      "name": "Empty"
    },
    {
      "x": -18,
      "y": 11,
      "z": 18,
      "name": "Rock_Shale_Brick"
    },
    {
      "x": -18,
      "y": 5,
      "z": 19,
      "name": "Rock_Shale_Brick"
    },
    {
      "x": -18,
      "y": 6,
      "z": 19,
      "name": "Rubble_Stone_Mossy",
      "support": 15
    },
    {
      "x": -18,
      "y": 7,
      "z": 19,
      "name": "Empty"
    },
    {
      "x": -18,
      "y": 8,
      "z": 19,
      "name": "Empty"
    },
    {
      "x": -18,
      "y": 9,
      "z": 19,
      "name": "Empty"
    },
    {
      "x": -18,
      "y": 10,
      "z": 19,
      "name": "Empty"
    },
    {
      "x": -18,
      "y": 11,
      "z": 19,
      "name": "Rock_Shale_Brick"
    },
    {
      "x": -18,
      "y": 5,
      "z": 20,
      "name": "Rock_Shale_Brick"
    },
    {
      "x": -18,
      "y": 6,
      "z": 20,
      "name": "Rock_Shale_Brick"
    },
    {
      "x": -18,
      "y": 7,
      "z": 20,
      "name": "Rock_Shale_Brick"
    },
    {
      "x": -18,
      "y": 8,
      "z": 20,
      "name": "Rock_Shale_Brick"
    },
    {
      "x": -18,
      "y": 9,
      "z": 20,
      "name": "Rock_Shale_Brick"
    },
    {
      "x": -18,
      "y": 10,
      "z": 20,
      "name": "Rock_Shale_Brick"
    },
    {
      "x": -18,
      "y": 11,
      "z": 20,
      "name": "Rock_Shale_Brick"
    },
    {
      "x": -17,
      "y": 5,
      "z": 15,
      "name": "Rock_Shale_Brick"
    },
    {
      "x": -17,
      "y": 6,
      "z": 15,
      "name": "Rock_Shale_Brick"
    },
    {
      "x": -17,
      "y": 7,
      "z": 15,
      "name": "Rock_Shale_Brick"
    },
    {
      "x": -17,
      "y": 8,
      "z": 15,
      "name": "Rock_Shale_Brick"
    },
    {
      "x": -17,
      "y": 9,
      "z": 15,
      "name": "Rock_Shale_Brick"
    },
    {
      "x": -17,
      "y": 10,
      "z": 15,
      "name": "Rock_Shale_Brick"
    },
    {
      "x": -17,
      "y": 11,
      "z": 15,
      "name": "Rock_Shale_Brick"
    },
    {
      "x": -17,
      "y": 5,
      "z": 16,
      "name": "Rock_Shale_Brick"
    },
    {
      "x": -17,
      "y": 6,
      "z": 16,
      "name": "Empty"
    },
    {
      "x": -17,
      "y": 7,
      "z": 16,
      "name": "Empty"
    },
    {
      "x": -17,
      "y": 8,
      "z": 16,
      "name": "Empty"
    },
    {
      "x": -17,
      "y": 9,
      "z": 16,
      "name": "Plant_Moss_Wall_Green_Dark",
      "support": 15
    },
    {
      "x": -17,
      "y": 10,
      "z": 16,
      "name": "Plant_Moss_Wall_Green_Dark",
      "support": 15
    },
    {
      "x": -17,
      "y": 11,
      "z": 16,
      "name": "Rock_Shale_Brick"
    },
    {
      "x": -17,
      "y": 5,
      "z": 17,
      "name": "Rock_Shale_Brick"
    },
    {
      "x": -17,
      "y": 6,
      "z": 17,
      "name": "Empty"
    },
    {
      "x": -17,
      "y": 7,
      "z": 17,
      "name": "Empty"
    },
    {
      "x": -17,
      "y": 8,
      "z": 17,
      "name": "Empty"
    },
    {
      "x": -17,
      "y": 9,
      "z": 17,
      "name": "Empty"
    },
    {
      "x": -17,
      "y": 10,
      "z": 17,
      "name": "Empty"
    },
    {
      "x": -17,
      "y": 11,
      "z": 17,
      "name": "Rock_Shale_Brick"
    },
    {
      "x": -17,
      "y": 5,
      "z": 18,
      "name": "Rock_Shale_Brick"
    },
    {
      "x": -17,
      "y": 6,
      "z": 18,
      "name": "Empty"
    },
    {
      "x": -17,
      "y": 7,
      "z": 18,
      "name": "Empty"
    },
    {
      "x": -17,
      "y": 8,
      "z": 18,
      "name": "Empty"
    },
    {
      "x": -17,
      "y": 9,
      "z": 18,
      "name": "Empty"
    },
    {
      "x": -17,
      "y": 10,
      "z": 18,
      "name": "Empty"
    },
    {
      "x": -17,
      "y": 11,
      "z": 18,
      "name": "Rock_Shale_Brick"
    },
    {
      "x": -17,
      "y": 5,
      "z": 19,
      "name": "Rock_Shale_Brick"
    },
    {
      "x": -17,
      "y": 6,
      "z": 19,
      "name": "Empty"
    },
    {
      "x": -17,
      "y": 7,
      "z": 19,
      "name": "Empty"
    },
    {
      "x": -17,
      "y": 8,
      "z": 19,
      "name": "Empty"
    },
    {
      "x": -17,
      "y": 9,
      "z": 19,
      "name": "Empty"
    },
    {
      "x": -17,
      "y": 10,
      "z": 19,
      "name": "Empty"
    },
    {
      "x": -17,
      "y": 11,
      "z": 19,
      "name": "Rock_Shale_Brick"
    },
    {
      "x": -17,
      "y": 5,
      "z": 20,
      "name": "Rock_Shale_Brick"
    },
    {
      "x": -17,
      "y": 6,
      "z": 20,
      "name": "Rock_Shale_Brick"
    },
    {
      "x": -17,
      "y": 7,
      "z": 20,
      "name": "Rock_Shale_Brick"
    },
    {
      "x": -17,
      "y": 8,
      "z": 20,
      "name": "Rock_Shale_Brick"
    },
    {
      "x": -17,
      "y": 9,
      "z": 20,
      "name": "Rock_Shale_Brick"
    },
    {
      "x": -17,
      "y": 10,
      "z": 20,
      "name": "Rock_Shale_Brick"
    },
    {
      "x": -17,
      "y": 11,
      "z": 20,
      "name": "Rock_Shale_Brick"
    },
    {
      "x": -16,
      "y": 5,
      "z": 15,
      "name": "Rock_Shale_Brick"
    },
    {
      "x": -16,
      "y": 6,
      "z": 15,
      "name": "Rock_Shale_Brick"
    },
    {
      "x": -16,
      "y": 7,
      "z": 15,
      "name": "Rock_Shale_Brick"
    },
    {
      "x": -16,
      "y": 8,
      "z": 15,
      "name": "Rock_Shale_Brick"
    },
    {
      "x": -16,
      "y": 9,
      "z": 15,
      "name": "Rock_Shale_Brick"
    },
    {
      "x": -16,
      "y": 10,
      "z": 15,
      "name": "Rock_Shale_Brick"
    },
    {
      "x": -16,
      "y": 11,
      "z": 15,
      "name": "Rock_Shale_Brick"
    },
    {
      "x": -16,
      "y": 5,
      "z": 16,
      "name": "Rock_Shale_Brick"
    },
    {
      "x": -16,
      "y": 6,
      "z": 16,
      "name": "Deco_Bone_Pile"
    },
    {
      "x": -16,
      "y": 7,
      "z": 16,
      "name": "Empty"
    },
    {
      "x": -16,
      "y": 8,
      "z": 16,
      "name": "Plant_Moss_Wall_Green_Dark",
      "support": 15
    },
    {
      "x": -16,
      "y": 9,
      "z": 16,
      "name": "Plant_Moss_Wall_Green_Dark",
      "support": 15
    },
    {
      "x": -16,
      "y": 10,
      "z": 16,
      "name": "Empty"
    },
    {
      "x": -16,
      "y": 11,
      "z": 16,
      "name": "Rock_Shale_Brick"
    },
    {
      "x": -16,
      "y": 5,
      "z": 17,
      "name": "Rock_Shale_Brick"
    },
    {
      "x": -16,
      "y": 6,
      "z": 17,
      "name": "Empty"
    },
    {
      "x": -16,
      "y": 7,
      "z": 17,
      "name": "Empty"
    },
    {
      "x": -16,
      "y": 8,
      "z": 17,
      "name": "Empty"
    },
    {
      "x": -16,
      "y": 9,
      "z": 17,
      "name": "Empty"
    },
    {
      "x": -16,
      "y": 10,
      "z": 17,
      "name": "Empty"
    },
    {
      "x": -16,
      "y": 11,
      "z": 17,
      "name": "Rock_Shale_Brick"
    },
    {
      "x": -16,
      "y": 5,
      "z": 18,
      "name": "Rock_Shale_Brick"
    },
    {
      "x": -16,
      "y": 6,
      "z": 18,
      "name": "Empty"
    },
    {
      "x": -16,
      "y": 7,
      "z": 18,
      "name": "Empty"
    },
    {
      "x": -16,
      "y": 8,
      "z": 18,
      "name": "Empty"
    },
    {
      "x": -16,
      "y": 9,
      "z": 18,
      "name": "Empty"
    },
    {
      "x": -16,
      "y": 10,
      "z": 18,
      "name": "Empty"
    },
    {
      "x": -16,
      "y": 11,
      "z": 18,
      "name": "Rock_Shale_Brick"
    },
    {
      "x": -16,
      "y": 5,
      "z": 19,
      "name": "Rock_Shale_Brick"
    },
    {
      "x": -16,
      "y": 6,
      "z": 19,
      "name": "Empty"
    },
    {
      "x": -16,
      "y": 7,
      "z": 19,
      "name": "Empty"
    },
    {
      "x": -16,
      "y": 8,
      "z": 19,
      "name": "Empty"
    },
    {
      "x": -16,
      "y": 9,
      "z": 19,
      "name": "Empty"
    },
    {
      "x": -16,
      "y": 10,
      "z": 19,
      "name": "Empty"
    },
    {
      "x": -16,
      "y": 11,
      "z": 19,
      "name": "Rock_Shale_Brick"
    },
    {
      "x": -16,
      "y": 5,
      "z": 20,
      "name": "Rock_Shale_Brick"
    },
    {
      "x": -16,
      "y": 6,
      "z": 20,
      "name": "Rock_Shale_Brick"
    },
    {
      "x": -16,
      "y": 7,
      "z": 20,
      "name": "Rock_Shale_Brick"
    },
    {
      "x": -16,
      "y": 8,
      "z": 20,
      "name": "Rock_Shale_Brick"
    },
    {
      "x": -16,
      "y": 9,
      "z": 20,
      "name": "Rock_Shale_Brick"
    },
    {
      "x": -16,
      "y": 10,
      "z": 20,
      "name": "Rock_Shale_Brick"
    },
    {
      "x": -16,
      "y": 11,
      "z": 20,
      "name": "Rock_Shale_Brick"
    },
    {
      "x": -15,
      "y": 1,
      "z": 15,
      "name": "Rock_Shale_Brick"
    },
    {
      "x": -15,
      "y": 2,
      "z": 15,
      "name": "Rock_Shale_Brick"
    },
    {
      "x": -15,
      "y": 3,
      "z": 15,
      "name": "Rock_Shale_Brick"
    },
    {
      "x": -15,
      "y": 4,
      "z": 15,
      "name": "Rock_Shale_Brick"
    },
    {
      "x": -15,
      "y": 5,
      "z": 15,
      "name": "Rock_Shale_Brick"
    },
    {
      "x": -15,
      "y": 6,
      "z": 15,
      "name": "Rock_Shale_Brick"
    },
    {
      "x": -15,
      "y": 7,
      "z": 15,
      "name": "Rock_Shale_Brick"
    },
    {
      "x": -15,
      "y": 8,
      "z": 15,
      "name": "Rock_Shale_Brick"
    },
    {
      "x": -15,
      "y": 9,
      "z": 15,
      "name": "Rock_Shale_Brick"
    },
    {
      "x": -15,
      "y": 10,
      "z": 15,
      "name": "Rock_Shale_Brick"
    },
    {
      "x": -15,
      "y": 11,
      "z": 15,
      "name": "Rock_Shale_Brick"
    },
    {
      "x": -15,
      "y": 1,
      "z": 16,
      "name": "Rock_Shale_Brick"
    },
    {
      "x": -15,
      "y": 2,
      "z": 16,
      "name": "Rock_Shale_Brick"
    },
    {
      "x": -15,
      "y": 3,
      "z": 16,
      "name": "Rock_Shale_Brick"
    },
    {
      "x": -15,
      "y": 4,
      "z": 16,
      "name": "Rock_Shale_Brick"
    },
    {
      "x": -15,
      "y": 5,
      "z": 16,
      "name": "Rock_Shale_Brick"
    },
    {
      "x": -15,
      "y": 6,
      "z": 16,
      "name": "Empty"
    },
    {
      "x": -15,
      "y": 7,
      "z": 16,
      "name": "Empty"
    },
    {
      "x": -15,
      "y": 8,
      "z": 16,
      "name": "Plant_Moss_Wall_Green_Dark",
      "support": 15
    },
    {
      "x": -15,
      "y": 9,
      "z": 16,
      "name": "Empty"
    },
    {
      "x": -15,
      "y": 10,
      "z": 16,
      "name": "Empty"
    },
    {
      "x": -15,
      "y": 11,
      "z": 16,
      "name": "Rock_Shale_Brick"
    },
    {
      "x": -15,
      "y": 1,
      "z": 17,
      "name": "Rock_Shale_Brick"
    },
    {
      "x": -15,
      "y": 2,
      "z": 17,
      "name": "Rock_Shale_Brick"
    },
    {
      "x": -15,
      "y": 3,
      "z": 17,
      "name": "Rock_Shale_Brick"
    },
    {
      "x": -15,
      "y": 4,
      "z": 17,
      "name": "Rock_Shale_Brick"
    },
    {
      "x": -15,
      "y": 5,
      "z": 17,
      "name": "Rock_Shale_Brick"
    },
    {
      "x": -15,
      "y": 6,
      "z": 17,
      "name": "Plant_Moss_Rug_Green_Dark",
      "support": 15
    },
    {
      "x": -15,
      "y": 7,
      "z": 17,
      "name": "Empty"
    },
    {
      "x": -15,
      "y": 8,
      "z": 17,
      "name": "Empty"
    },
    {
      "x": -15,
      "y": 9,
      "z": 17,
      "name": "Empty"
    },
    {
      "x": -15,
      "y": 10,
      "z": 17,
      "name": "Empty"
    },
    {
      "x": -15,
      "y": 11,
      "z": 17,
      "name": "Rock_Shale_Brick"
    },
    {
      "x": -15,
      "y": 1,
      "z": 18,
      "name": "Rock_Shale_Brick"
    },
    {
      "x": -15,
      "y": 2,
      "z": 18,
      "name": "Rock_Shale_Brick"
    },
    {
      "x": -15,
      "y": 3,
      "z": 18,
      "name": "Rock_Shale_Brick"
    },
    {
      "x": -15,
      "y": 4,
      "z": 18,
      "name": "Rock_Shale_Brick"
    },
    {
      "x": -15,
      "y": 5,
      "z": 18,
      "name": "Rock_Shale_Brick"
    },
    {
      "x": -15,
      "y": 6,
      "z": 18,
      "name": "Empty"
    },
    {
      "x": -15,
      "y": 7,
      "z": 18,
      "name": "Empty"
    },
    {
      "x": -15,
      "y": 8,
      "z": 18,
      "name": "Empty"
    },
    {
      "x": -15,
      "y": 9,
      "z": 18,
      "name": "Empty"
    },
    {
      "x": -15,
      "y": 10,
      "z": 18,
      "name": "Empty"
    },
    {
      "x": -15,
      "y": 11,
      "z": 18,
      "name": "Rock_Shale_Brick"
    },
    {
      "x": -15,
      "y": 1,
      "z": 19,
      "name": "Rock_Shale_Brick"
    },
    {
      "x": -15,
      "y": 2,
      "z": 19,
      "name": "Rock_Shale_Brick"
    },
    {
      "x": -15,
      "y": 3,
      "z": 19,
      "name": "Rock_Shale_Brick"
    },
    {
      "x": -15,
      "y": 4,
      "z": 19,
      "name": "Rock_Shale_Brick"
    },
    {
      "x": -15,
      "y": 5,
      "z": 19,
      "name": "Rock_Shale_Brick"
    },
    {
      "x": -15,
      "y": 6,
      "z": 19,
      "name": "Empty"
    },
    {
      "x": -15,
      "y": 7,
      "z": 19,
      "name": "Empty"
    },
    {
      "x": -15,
      "y": 8,
      "z": 19,
      "name": "Empty"
    },
    {
      "x": -15,
      "y": 9,
      "z": 19,
      "name": "Empty"
    },
    {
      "x": -15,
      "y": 10,
      "z": 19,
      "name": "Empty"
    },
    {
      "x": -15,
      "y": 11,
      "z": 19,
      "name": "Rock_Shale_Brick"
    },
    {
      "x": -15,
      "y": 1,
      "z": 20,
      "name": "Rock_Shale_Brick"
    },
    {
      "x": -15,
      "y": 2,
      "z": 20,
      "name": "Rock_Shale_Brick"
    },
    {
      "x": -15,
      "y": 3,
      "z": 20,
      "name": "Rock_Shale_Brick"
    },
    {
      "x": -15,
      "y": 4,
      "z": 20,
      "name": "Rock_Shale_Brick"
    },
    {
      "x": -15,
      "y": 5,
      "z": 20,
      "name": "Rock_Shale_Brick"
    },
    {
      "x": -15,
      "y": 6,
      "z": 20,
      "name": "Rock_Shale_Brick"
    },
    {
      "x": -15,
      "y": 7,
      "z": 20,
      "name": "Rock_Shale_Brick"
    },
    {
      "x": -15,
      "y": 8,
      "z": 20,
      "name": "Rock_Shale_Brick"
    },
    {
      "x": -15,
      "y": 9,
      "z": 20,
      "name": "Rock_Shale_Brick"
    },
    {
      "x": -15,
      "y": 10,
      "z": 20,
      "name": "Rock_Shale_Brick"
    },
    {
      "x": -15,
      "y": 11,
      "z": 20,
      "name": "Rock_Shale_Brick"
    },
    {
      "x": -14,
      "y": 1,
      "z": 15,
      "name": "Rock_Shale_Brick"
    },
    {
      "x": -14,
      "y": 2,
      "z": 15,
      "name": "Rock_Shale_Brick"
    },
    {
      "x": -14,
      "y": 3,
      "z": 15,
      "name": "Rock_Shale_Brick"
    },
    {
      "x": -14,
      "y": 4,
      "z": 15,
      "name": "Rock_Shale_Brick"
    },
    {
      "x": -14,
      "y": 5,
      "z": 15,
      "name": "Rock_Shale_Brick"
    },
    {
      "x": -14,
      "y": 6,
      "z": 15,
      "name": "Rock_Shale_Brick"
    },
    {
      "x": -14,
      "y": 7,
      "z": 15,
      "name": "Rock_Shale_Brick"
    },
    {
      "x": -14,
      "y": 8,
      "z": 15,
      "name": "Rock_Shale_Brick"
    },
    {
      "x": -14,
      "y": 9,
      "z": 15,
      "name": "Rock_Shale_Brick"
    },
    {
      "x": -14,
      "y": 10,
      "z": 15,
      "name": "Rock_Shale_Brick"
    },
    {
      "x": -14,
      "y": 11,
      "z": 15,
      "name": "Rock_Shale_Brick"
    },
    {
      "x": -14,
      "y": 1,
      "z": 16,
      "name": "Rock_Shale_Brick"
    },
    {
      "x": -14,
      "y": 2,
      "z": 16,
      "name": "Empty"
    },
    {
      "x": -14,
      "y": 3,
      "z": 16,
      "name": "Empty"
    },
    {
      "x": -14,
      "y": 4,
      "z": 16,
      "name": "Empty"
    },
    {
      "x": -14,
      "y": 5,
      "z": 16,
      "name": "Empty"
    },
    {
      "x": -14,
      "y": 6,
      "z": 16,
      "name": "Empty"
    },
    {
      "x": -14,
      "y": 7,
      "z": 16,
      "name": "Empty"
    },
    {
      "x": -14,
      "y": 8,
      "z": 16,
      "name": "Empty"
    },
    {
      "x": -14,
      "y": 9,
      "z": 16,
      "name": "Empty"
    },
    {
      "x": -14,
      "y": 10,
      "z": 16,
      "name": "Empty"
    },
    {
      "x": -14,
      "y": 11,
      "z": 16,
      "name": "Rock_Shale_Brick"
    },
    {
      "x": -14,
      "y": 1,
      "z": 17,
      "name": "Rock_Shale_Brick"
    },
    {
      "x": -14,
      "y": 2,
      "z": 17,
      "name": "Empty"
    },
    {
      "x": -14,
      "y": 3,
      "z": 17,
      "name": "Empty"
    },
    {
      "x": -14,
      "y": 4,
      "z": 17,
      "name": "Empty"
    },
    {
      "x": -14,
      "y": 5,
      "z": 17,
      "name": "Empty"
    },
    {
      "x": -14,
      "y": 6,
      "z": 17,
      "name": "Empty"
    },
    {
      "x": -14,
      "y": 7,
      "z": 17,
      "name": "Empty"
    },
    {
      "x": -14,
      "y": 8,
      "z": 17,
      "name": "Empty"
    },
    {
      "x": -14,
      "y": 9,
      "z": 17,
      "name": "Empty"
    },
    {
      "x": -14,
      "y": 10,
      "z": 17,
      "name": "Empty"
    },
    {
      "x": -14,
      "y": 11,
      "z": 17,
      "name": "Rock_Shale_Brick"
    },
    {
      "x": -14,
      "y": 1,
      "z": 18,
      "name": "Rock_Shale_Brick"
    },
    {
      "x": -14,
      "y": 2,
      "z": 18,
      "name": "Empty"
    },
    {
      "x": -14,
      "y": 3,
      "z": 18,
      "name": "Empty"
    },
    {
      "x": -14,
      "y": 4,
      "z": 18,
      "name": "Empty"
    },
    {
      "x": -14,
      "y": 5,
      "z": 18,
      "name": "Empty"
    },
    {
      "x": -14,
      "y": 6,
      "z": 18,
      "name": "Empty"
    },
    {
      "x": -14,
      "y": 7,
      "z": 18,
      "name": "Empty"
    },
    {
      "x": -14,
      "y": 8,
      "z": 18,
      "name": "Empty"
    },
    {
      "x": -14,
      "y": 9,
      "z": 18,
      "name": "Empty"
    },
    {
      "x": -14,
      "y": 10,
      "z": 18,
      "name": "Empty"
    },
    {
      "x": -14,
      "y": 11,
      "z": 18,
      "name": "Rock_Shale_Brick"
    },
    {
      "x": -14,
      "y": 1,
      "z": 19,
      "name": "Rock_Shale_Brick"
    },
    {
      "x": -14,
      "y": 2,
      "z": 19,
      "name": "Empty"
    },
    {
      "x": -14,
      "y": 3,
      "z": 19,
      "name": "Empty"
    },
    {
      "x": -14,
      "y": 4,
      "z": 19,
      "name": "Empty"
    },
    {
      "x": -14,
      "y": 5,
      "z": 19,
      "name": "Empty"
    },
    {
      "x": -14,
      "y": 6,
      "z": 19,
      "name": "Empty"
    },
    {
      "x": -14,
      "y": 7,
      "z": 19,
      "name": "Empty"
    },
    {
      "x": -14,
      "y": 8,
      "z": 19,
      "name": "Empty"
    },
    {
      "x": -14,
      "y": 9,
      "z": 19,
      "name": "Empty"
    },
    {
      "x": -14,
      "y": 10,
      "z": 19,
      "name": "Empty"
    },
    {
      "x": -14,
      "y": 11,
      "z": 19,
      "name": "Rock_Shale_Brick"
    },
    {
      "x": -14,
      "y": 1,
      "z": 20,
      "name": "Rock_Shale_Brick"
    },
    {
      "x": -14,
      "y": 2,
      "z": 20,
      "name": "Rock_Shale_Brick"
    },
    {
      "x": -14,
      "y": 3,
      "z": 20,
      "name": "Rock_Shale_Brick"
    },
    {
      "x": -14,
      "y": 4,
      "z": 20,
      "name": "Rock_Shale_Brick"
    },
    {
      "x": -14,
      "y": 5,
      "z": 20,
      "name": "Rock_Shale_Brick"
    },
    {
      "x": -14,
      "y": 6,
      "z": 20,
      "name": "Rock_Shale_Brick"
    },
    {
      "x": -14,
      "y": 7,
      "z": 20,
      "name": "Rock_Shale_Brick"
    },
    {
      "x": -14,
      "y": 8,
      "z": 20,
      "name": "Rock_Shale_Brick"
    },
    {
      "x": -14,
      "y": 9,
      "z": 20,
      "name": "Rock_Shale_Brick"
    },
    {
      "x": -14,
      "y": 10,
      "z": 20,
      "name": "Rock_Shale_Brick"
    },
    {
      "x": -14,
      "y": 11,
      "z": 20,
      "name": "Rock_Shale_Brick"
    },
    {
      "x": -13,
      "y": 1,
      "z": 15,
      "name": "Rock_Shale_Brick"
    },
    {
      "x": -13,
      "y": 2,
      "z": 15,
      "name": "Rock_Shale_Brick"
    },
    {
      "x": -13,
      "y": 3,
      "z": 15,
      "name": "Rock_Shale_Brick"
    },
    {
      "x": -13,
      "y": 4,
      "z": 15,
      "name": "Rock_Shale_Brick"
    },
    {
      "x": -13,
      "y": 5,
      "z": 15,
      "name": "Rock_Shale_Brick"
    },
    {
      "x": -13,
      "y": 6,
      "z": 15,
      "name": "Rock_Shale_Brick"
    },
    {
      "x": -13,
      "y": 7,
      "z": 15,
      "name": "Rock_Shale_Brick"
    },
    {
      "x": -13,
      "y": 8,
      "z": 15,
      "name": "Rock_Shale_Brick"
    },
    {
      "x": -13,
      "y": 9,
      "z": 15,
      "name": "Rock_Shale_Brick"
    },
    {
      "x": -13,
      "y": 10,
      "z": 15,
      "name": "Rock_Shale_Brick"
    },
    {
      "x": -13,
      "y": 11,
      "z": 15,
      "name": "Rock_Shale_Brick"
    },
    {
      "x": -13,
      "y": 1,
      "z": 16,
      "name": "Rock_Shale_Brick"
    },
    {
      "x": -13,
      "y": 2,
      "z": 16,
      "name": "Rubble_Stone_Mossy_Medium"
    },
    {
      "x": -13,
      "y": 3,
      "z": 16,
      "name": "Empty"
    },
    {
      "x": -13,
      "y": 4,
      "z": 16,
      "name": "Empty"
    },
    {
      "x": -13,
      "y": 5,
      "z": 16,
      "name": "Empty"
    },
    {
      "x": -13,
      "y": 6,
      "z": 16,
      "name": "Empty"
    },
    {
      "x": -13,
      "y": 7,
      "z": 16,
      "name": "Empty"
    },
    {
      "x": -13,
      "y": 8,
      "z": 16,
      "name": "Empty"
    },
    {
      "x": -13,
      "y": 9,
      "z": 16,
      "name": "Empty"
    },
    {
      "x": -13,
      "y": 10,
      "z": 16,
      "name": "Empty"
    },
    {
      "x": -13,
      "y": 11,
      "z": 16,
      "name": "Rock_Shale_Brick"
    },
    {
      "x": -13,
      "y": 1,
      "z": 17,
      "name": "Rock_Shale_Brick"
    },
    {
      "x": -13,
      "y": 2,
      "z": 17,
      "name": "Empty"
    },
    {
      "x": -13,
      "y": 3,
      "z": 17,
      "name": "Empty"
    },
    {
      "x": -13,
      "y": 4,
      "z": 17,
      "name": "Empty"
    },
    {
      "x": -13,
      "y": 5,
      "z": 17,
      "name": "Empty"
    },
    {
      "x": -13,
      "y": 6,
      "z": 17,
      "name": "Empty"
    },
    {
      "x": -13,
      "y": 7,
      "z": 17,
      "name": "Empty"
    },
    {
      "x": -13,
      "y": 8,
      "z": 17,
      "name": "Empty"
    },
    {
      "x": -13,
      "y": 9,
      "z": 17,
      "name": "Empty"
    },
    {
      "x": -13,
      "y": 10,
      "z": 17,
      "name": "Empty"
    },
    {
      "x": -13,
      "y": 11,
      "z": 17,
      "name": "Rock_Shale_Brick"
    },
    {
      "x": -13,
      "y": 1,
      "z": 18,
      "name": "Rock_Shale_Brick"
    },
    {
      "x": -13,
      "y": 2,
      "z": 18,
      "name": "Empty"
    },
    {
      "x": -13,
      "y": 3,
      "z": 18,
      "name": "Empty"
    },
    {
      "x": -13,
      "y": 4,
      "z": 18,
      "name": "Empty"
    },
    {
      "x": -13,
      "y": 5,
      "z": 18,
      "name": "Empty"
    },
    {
      "x": -13,
      "y": 6,
      "z": 18,
      "name": "Empty"
    },
    {
      "x": -13,
      "y": 7,
      "z": 18,
      "name": "Empty"
    },
    {
      "x": -13,
      "y": 8,
      "z": 18,
      "name": "Empty"
    },
    {
      "x": -13,
      "y": 9,
      "z": 18,
      "name": "Empty"
    },
    {
      "x": -13,
      "y": 10,
      "z": 18,
      "name": "Empty"
    },
    {
      "x": -13,
      "y": 11,
      "z": 18,
      "name": "Rock_Shale_Brick"
    },
    {
      "x": -13,
      "y": 1,
      "z": 19,
      "name": "Rock_Shale_Brick"
    },
    {
      "x": -13,
      "y": 2,
      "z": 19,
      "name": "Empty"
    },
    {
      "x": -13,
      "y": 3,
      "z": 19,
      "name": "Empty"
    },
    {
      "x": -13,
      "y": 4,
      "z": 19,
      "name": "Empty"
    },
    {
      "x": -13,
      "y": 5,
      "z": 19,
      "name": "Empty"
    },
    {
      "x": -13,
      "y": 6,
      "z": 19,
      "name": "Empty"
    },
    {
      "x": -13,
      "y": 7,
      "z": 19,
      "name": "Empty"
    },
    {
      "x": -13,
      "y": 8,
      "z": 19,
      "name": "Empty"
    },
    {
      "x": -13,
      "y": 9,
      "z": 19,
      "name": "Empty"
    },
    {
      "x": -13,
      "y": 10,
      "z": 19,
      "name": "Empty"
    },
    {
      "x": -13,
      "y": 11,
      "z": 19,
      "name": "Rock_Shale_Brick"
    },
    {
      "x": -13,
      "y": 1,
      "z": 20,
      "name": "Rock_Shale_Brick"
    },
    {
      "x": -13,
      "y": 2,
      "z": 20,
      "name": "Rock_Shale_Brick"
    },
    {
      "x": -13,
      "y": 3,
      "z": 20,
      "name": "Rock_Shale_Brick"
    },
    {
      "x": -13,
      "y": 4,
      "z": 20,
      "name": "Rock_Shale_Brick"
    },
    {
      "x": -13,
      "y": 5,
      "z": 20,
      "name": "Rock_Shale_Brick"
    },
    {
      "x": -13,
      "y": 6,
      "z": 20,
      "name": "Rock_Shale_Brick"
    },
    {
      "x": -13,
      "y": 7,
      "z": 20,
      "name": "Rock_Shale_Brick"
    },
    {
      "x": -13,
      "y": 8,
      "z": 20,
      "name": "Rock_Shale_Brick"
    },
    {
      "x": -13,
      "y": 9,
      "z": 20,
      "name": "Rock_Shale_Brick"
    },
    {
      "x": -13,
      "y": 10,
      "z": 20,
      "name": "Rock_Shale_Brick"
    },
    {
      "x": -13,
      "y": 11,
      "z": 20,
      "name": "Rock_Shale_Brick"
    },
    {
      "x": -12,
      "y": 1,
      "z": 15,
      "name": "Rock_Shale_Brick"
    },
    {
      "x": -12,
      "y": 2,
      "z": 15,
      "name": "Rock_Shale_Brick"
    },
    {
      "x": -12,
      "y": 3,
      "z": 15,
      "name": "Rock_Shale_Brick"
    },
    {
      "x": -12,
      "y": 4,
      "z": 15,
      "name": "Rock_Shale_Brick"
    },
    {
      "x": -12,
      "y": 5,
      "z": 15,
      "name": "Rock_Shale_Brick"
    },
    {
      "x": -12,
      "y": 6,
      "z": 15,
      "name": "Rock_Shale_Brick"
    },
    {
      "x": -12,
      "y": 7,
      "z": 15,
      "name": "Rock_Shale_Brick"
    },
    {
      "x": -12,
      "y": 8,
      "z": 15,
      "name": "Rock_Shale_Brick"
    },
    {
      "x": -12,
      "y": 9,
      "z": 15,
      "name": "Rock_Shale_Brick"
    },
    {
      "x": -12,
      "y": 10,
      "z": 15,
      "name": "Rock_Shale_Brick"
    },
    {
      "x": -12,
      "y": 11,
      "z": 15,
      "name": "Rock_Shale_Brick"
    },
    {
      "x": -12,
      "y": 1,
      "z": 16,
      "name": "Rock_Shale_Brick"
    },
    {
      "x": -12,
      "y": 2,
      "z": 16,
      "name": "Empty"
    },
    {
      "x": -12,
      "y": 3,
      "z": 16,
      "name": "Empty"
    },
    {
      "x": -12,
      "y": 4,
      "z": 16,
      "name": "Empty"
    },
    {
      "x": -12,
      "y": 5,
      "z": 16,
      "name": "Empty"
    },
    {
      "x": -12,
      "y": 6,
      "z": 16,
      "name": "Empty"
    },
    {
      "x": -12,
      "y": 7,
      "z": 16,
      "name": "Empty"
    },
    {
      "x": -12,
      "y": 8,
      "z": 16,
      "name": "Empty"
    },
    {
      "x": -12,
      "y": 9,
      "z": 16,
      "name": "Plant_Moss_Wall_Green_Dark",
      "support": 15
    },
    {
      "x": -12,
      "y": 10,
      "z": 16,
      "name": "Empty"
    },
    {
      "x": -12,
      "y": 11,
      "z": 16,
      "name": "Rock_Shale_Brick"
    },
    {
      "x": -12,
      "y": 1,
      "z": 17,
      "name": "Rock_Shale_Brick"
    },
    {
      "x": -12,
      "y": 2,
      "z": 17,
      "name": "Empty"
    },
    {
      "x": -12,
      "y": 3,
      "z": 17,
      "name": "Empty"
    },
    {
      "x": -12,
      "y": 4,
      "z": 17,
      "name": "Empty"
    },
    {
      "x": -12,
      "y": 5,
      "z": 17,
      "name": "Empty"
    },
    {
      "x": -12,
      "y": 6,
      "z": 17,
      "name": "Empty"
    },
    {
      "x": -12,
      "y": 7,
      "z": 17,
      "name": "Empty"
    },
    {
      "x": -12,
      "y": 8,
      "z": 17,
      "name": "Empty"
    },
    {
      "x": -12,
      "y": 9,
      "z": 17,
      "name": "Empty"
    },
    {
      "x": -12,
      "y": 10,
      "z": 17,
      "name": "Empty"
    },
    {
      "x": -12,
      "y": 11,
      "z": 17,
      "name": "Rock_Shale_Brick"
    },
    {
      "x": -12,
      "y": 1,
      "z": 18,
      "name": "Rock_Shale_Brick"
    },
    {
      "x": -12,
      "y": 2,
      "z": 18,
      "name": "Empty"
    },
    {
      "x": -12,
      "y": 3,
      "z": 18,
      "name": "Empty"
    },
    {
      "x": -12,
      "y": 4,
      "z": 18,
      "name": "Empty"
    },
    {
      "x": -12,
      "y": 5,
      "z": 18,
      "name": "Empty"
    },
    {
      "x": -12,
      "y": 6,
      "z": 18,
      "name": "Empty"
    },
    {
      "x": -12,
      "y": 7,
      "z": 18,
      "name": "Empty"
    },
    {
      "x": -12,
      "y": 8,
      "z": 18,
      "name": "Empty"
    },
    {
      "x": -12,
      "y": 9,
      "z": 18,
      "name": "Empty"
    },
    {
      "x": -12,
      "y": 10,
      "z": 18,
      "name": "Empty"
    },
    {
      "x": -12,
      "y": 11,
      "z": 18,
      "name": "Rock_Shale_Brick"
    },
    {
      "x": -12,
      "y": 1,
      "z": 19,
      "name": "Rock_Shale_Brick"
    },
    {
      "x": -12,
      "y": 2,
      "z": 19,
      "name": "Empty"
    },
    {
      "x": -12,
      "y": 3,
      "z": 19,
      "name": "Empty"
    },
    {
      "x": -12,
      "y": 4,
      "z": 19,
      "name": "Empty"
    },
    {
      "x": -12,
      "y": 5,
      "z": 19,
      "name": "Empty"
    },
    {
      "x": -12,
      "y": 6,
      "z": 19,
      "name": "Empty"
    },
    {
      "x": -12,
      "y": 7,
      "z": 19,
      "name": "Empty"
    },
    {
      "x": -12,
      "y": 8,
      "z": 19,
      "name": "Empty"
    },
    {
      "x": -12,
      "y": 9,
      "z": 19,
      "name": "Empty"
    },
    {
      "x": -12,
      "y": 10,
      "z": 19,
      "name": "Empty"
    },
    {
      "x": -12,
      "y": 11,
      "z": 19,
      "name": "Rock_Shale_Brick"
    },
    {
      "x": -12,
      "y": 1,
      "z": 20,
      "name": "Rock_Shale_Brick"
    },
    {
      "x": -12,
      "y": 2,
      "z": 20,
      "name": "Rock_Shale_Brick"
    },
    {
      "x": -12,
      "y": 3,
      "z": 20,
      "name": "Rock_Shale_Brick"
    },
    {
      "x": -12,
      "y": 4,
      "z": 20,
      "name": "Rock_Shale_Brick"
    },
    {
      "x": -12,
      "y": 5,
      "z": 20,
      "name": "Rock_Shale_Brick"
    },
    {
      "x": -12,
      "y": 6,
      "z": 20,
      "name": "Rock_Shale_Brick"
    },
    {
      "x": -12,
      "y": 7,
      "z": 20,
      "name": "Rock_Shale_Brick"
    },
    {
      "x": -12,
      "y": 8,
      "z": 20,
      "name": "Rock_Shale_Brick"
    },
    {
      "x": -12,
      "y": 9,
      "z": 20,
      "name": "Rock_Shale_Brick"
    },
    {
      "x": -12,
      "y": 10,
      "z": 20,
      "name": "Rock_Shale_Brick"
    },
    {
      "x": -12,
      "y": 11,
      "z": 20,
      "name": "Rock_Shale_Brick"
    },
    {
      "x": -11,
      "y": 1,
      "z": 15,
      "name": "Rock_Shale_Brick"
    },
    {
      "x": -11,
      "y": 2,
      "z": 15,
      "name": "Rock_Shale_Brick"
    },
    {
      "x": -11,
      "y": 3,
      "z": 15,
      "name": "Rock_Shale_Brick"
    },
    {
      "x": -11,
      "y": 4,
      "z": 15,
      "name": "Rock_Shale_Brick"
    },
    {
      "x": -11,
      "y": 5,
      "z": 15,
      "name": "Rock_Shale_Brick"
    },
    {
      "x": -11,
      "y": 6,
      "z": 15,
      "name": "Rock_Shale_Brick"
    },
    {
      "x": -11,
      "y": 7,
      "z": 15,
      "name": "Rock_Shale_Brick"
    },
    {
      "x": -11,
      "y": 8,
      "z": 15,
      "name": "Rock_Shale_Brick"
    },
    {
      "x": -11,
      "y": 9,
      "z": 15,
      "name": "Rock_Shale_Brick"
    },
    {
      "x": -11,
      "y": 10,
      "z": 15,
      "name": "Rock_Shale_Brick"
    },
    {
      "x": -11,
      "y": 11,
      "z": 15,
      "name": "Rock_Shale_Brick"
    },
    {
      "x": -11,
      "y": 1,
      "z": 16,
      "name": "Rock_Shale_Brick"
    },
    {
      "x": -11,
      "y": 2,
      "z": 16,
      "name": "Empty"
    },
    {
      "x": -11,
      "y": 3,
      "z": 16,
      "name": "Empty"
    },
    {
      "x": -11,
      "y": 4,
      "z": 16,
      "name": "Empty"
    },
    {
      "x": -11,
      "y": 5,
      "z": 16,
      "name": "Empty"
    },
    {
      "x": -11,
      "y": 6,
      "z": 16,
      "name": "Empty"
    },
    {
      "x": -11,
      "y": 7,
      "z": 16,
      "name": "Empty"
    },
    {
      "x": -11,
      "y": 8,
      "z": 16,
      "name": "Plant_Moss_Wall_Green_Dark",
      "support": 15
    },
    {
      "x": -11,
      "y": 9,
      "z": 16,
      "name": "Plant_Moss_Wall_Green_Dark",
      "support": 15
    },
    {
      "x": -11,
      "y": 10,
      "z": 16,
      "name": "Plant_Moss_Wall_Green_Dark",
      "support": 15,
      "rotation": 3
    },
    {
      "x": -11,
      "y": 11,
      "z": 16,
      "name": "Rock_Shale_Brick"
    },
    {
      "x": -11,
      "y": 1,
      "z": 17,
      "name": "Rock_Shale_Brick"
    },
    {
      "x": -11,
      "y": 2,
      "z": 17,
      "name": "Empty"
    },
    {
      "x": -11,
      "y": 3,
      "z": 17,
      "name": "Empty"
    },
    {
      "x": -11,
      "y": 4,
      "z": 17,
      "name": "Empty"
    },
    {
      "x": -11,
      "y": 5,
      "z": 17,
      "name": "Empty"
    },
    {
      "x": -11,
      "y": 6,
      "z": 17,
      "name": "Empty"
    },
    {
      "x": -11,
      "y": 7,
      "z": 17,
      "name": "Empty"
    },
    {
      "x": -11,
      "y": 8,
      "z": 17,
      "name": "Empty"
    },
    {
      "x": -11,
      "y": 9,
      "z": 17,
      "name": "Empty"
    },
    {
      "x": -11,
      "y": 10,
      "z": 17,
      "name": "Plant_Moss_Wall_Green_Dark",
      "support": 15,
      "rotation": 3
    },
    {
      "x": -11,
      "y": 11,
      "z": 17,
      "name": "Rock_Shale_Brick"
    },
    {
      "x": -11,
      "y": 1,
      "z": 18,
      "name": "Rock_Shale_Brick"
    },
    {
      "x": -11,
      "y": 2,
      "z": 18,
      "name": "Empty"
    },
    {
      "x": -11,
      "y": 3,
      "z": 18,
      "name": "Empty"
    },
    {
      "x": -11,
      "y": 4,
      "z": 18,
      "name": "Empty"
    },
    {
      "x": -11,
      "y": 5,
      "z": 18,
      "name": "Empty"
    },
    {
      "x": -11,
      "y": 6,
      "z": 18,
      "name": "Empty"
    },
    {
      "x": -11,
      "y": 7,
      "z": 18,
      "name": "Empty"
    },
    {
      "x": -11,
      "y": 8,
      "z": 18,
      "name": "Empty"
    },
    {
      "x": -11,
      "y": 9,
      "z": 18,
      "name": "Empty"
    },
    {
      "x": -11,
      "y": 10,
      "z": 18,
      "name": "Plant_Moss_Cave_Green_Dark",
      "support": 15,
      "rotation": 8
    },
    {
      "x": -11,
      "y": 11,
      "z": 18,
      "name": "Rock_Shale_Brick"
    },
    {
      "x": -11,
      "y": 1,
      "z": 19,
      "name": "Rock_Shale_Brick"
    },
    {
      "x": -11,
      "y": 2,
      "z": 19,
      "name": "Plant_Seaweed_Wet_Stack"
    },
    {
      "x": -11,
      "y": 3,
      "z": 19,
      "name": "Plant_Seaweed_Wet_Stack"
    },
    {
      "x": -11,
      "y": 4,
      "z": 19,
      "name": "Plant_Seaweed_Wet_Stack"
    },
    {
      "x": -11,
      "y": 5,
      "z": 19,
      "name": "Empty"
    },
    {
      "x": -11,
      "y": 6,
      "z": 19,
      "name": "Empty"
    },
    {
      "x": -11,
      "y": 7,
      "z": 19,
      "name": "Empty"
    },
    {
      "x": -11,
      "y": 8,
      "z": 19,
      "name": "Empty"
    },
    {
      "x": -11,
      "y": 9,
      "z": 19,
      "name": "Empty"
    },
    {
      "x": -11,
      "y": 10,
      "z": 19,
      "name": "Empty"
    },
    {
      "x": -11,
      "y": 11,
      "z": 19,
      "name": "Rock_Shale_Brick"
    },
    {
      "x": -11,
      "y": 1,
      "z": 20,
      "name": "Rock_Shale_Brick"
    },
    {
      "x": -11,
      "y": 2,
      "z": 20,
      "name": "Rock_Shale_Brick"
    },
    {
      "x": -11,
      "y": 3,
      "z": 20,
      "name": "Rock_Shale_Brick"
    },
    {
      "x": -11,
      "y": 4,
      "z": 20,
      "name": "Rock_Shale_Brick"
    },
    {
      "x": -11,
      "y": 5,
      "z": 20,
      "name": "Rock_Shale_Brick"
    },
    {
      "x": -11,
      "y": 6,
      "z": 20,
      "name": "Rock_Shale_Brick"
    },
    {
      "x": -11,
      "y": 7,
      "z": 20,
      "name": "Rock_Shale_Brick"
    },
    {
      "x": -11,
      "y": 8,
      "z": 20,
      "name": "Rock_Shale_Brick"
    },
    {
      "x": -11,
      "y": 9,
      "z": 20,
      "name": "Rock_Shale_Brick"
    },
    {
      "x": -11,
      "y": 10,
      "z": 20,
      "name": "Rock_Shale_Brick"
    },
    {
      "x": -11,
      "y": 11,
      "z": 20,
      "name": "Rock_Shale_Brick"
    },
    {
      "x": -10,
      "y": 1,
      "z": 15,
      "name": "Rock_Shale_Brick"
    },
    {
      "x": -10,
      "y": 2,
      "z": 15,
      "name": "Rock_Shale_Brick"
    },
    {
      "x": -10,
      "y": 3,
      "z": 15,
      "name": "Rock_Shale_Brick"
    },
    {
      "x": -10,
      "y": 4,
      "z": 15,
      "name": "Rock_Shale_Brick"
    },
    {
      "x": -10,
      "y": 5,
      "z": 15,
      "name": "Rock_Shale_Brick"
    },
    {
      "x": -10,
      "y": 6,
      "z": 15,
      "name": "Rock_Shale_Brick"
    },
    {
      "x": -10,
      "y": 7,
      "z": 15,
      "name": "Rock_Shale_Brick"
    },
    {
      "x": -10,
      "y": 8,
      "z": 15,
      "name": "Rock_Shale_Brick"
    },
    {
      "x": -10,
      "y": 9,
      "z": 15,
      "name": "Rock_Shale_Brick"
    },
    {
      "x": -10,
      "y": 10,
      "z": 15,
      "name": "Rock_Shale_Brick"
    },
    {
      "x": -10,
      "y": 11,
      "z": 15,
      "name": "Rock_Shale_Brick"
    },
    {
      "x": -10,
      "y": 1,
      "z": 16,
      "name": "Rock_Shale_Brick"
    },
    {
      "x": -10,
      "y": 2,
      "z": 16,
      "name": "Empty"
    },
    {
      "x": -10,
      "y": 3,
      "z": 16,
      "name": "Empty"
    },
    {
      "x": -10,
      "y": 4,
      "z": 16,
      "name": "Empty"
    },
    {
      "x": -10,
      "y": 5,
      "z": 16,
      "name": "Empty"
    },
    {
      "x": -10,
      "y": 6,
      "z": 16,
      "name": "Rock_Shale_Brick"
    },
    {
      "x": -10,
      "y": 7,
      "z": 16,
      "name": "Rock_Shale_Brick"
    },
    {
      "x": -10,
      "y": 8,
      "z": 16,
      "name": "Rock_Shale_Brick"
    },
    {
      "x": -10,
      "y": 9,
      "z": 16,
      "name": "Rock_Shale_Brick"
    },
    {
      "x": -10,
      "y": 10,
      "z": 16,
      "name": "Rock_Shale_Brick"
    },
    {
      "x": -10,
      "y": 11,
      "z": 16,
      "name": "Rock_Shale_Brick"
    },
    {
      "x": -10,
      "y": 1,
      "z": 17,
      "name": "Rock_Shale_Brick"
    },
    {
      "x": -10,
      "y": 2,
      "z": 17,
      "name": "Empty"
    },
    {
      "x": -10,
      "y": 3,
      "z": 17,
      "name": "Empty"
    },
    {
      "x": -10,
      "y": 4,
      "z": 17,
      "name": "Empty"
    },
    {
      "x": -10,
      "y": 5,
      "z": 17,
      "name": "Empty"
    },
    {
      "x": -10,
      "y": 6,
      "z": 17,
      "name": "Rock_Shale_Brick"
    },
    {
      "x": -10,
      "y": 7,
      "z": 17,
      "name": "Rock_Shale_Brick"
    },
    {
      "x": -10,
      "y": 8,
      "z": 17,
      "name": "Rock_Shale_Brick"
    },
    {
      "x": -10,
      "y": 9,
      "z": 17,
      "name": "Rock_Shale_Brick"
    },
    {
      "x": -10,
      "y": 10,
      "z": 17,
      "name": "Rock_Shale_Brick"
    },
    {
      "x": -10,
      "y": 11,
      "z": 17,
      "name": "Rock_Shale_Brick"
    },
    {
      "x": -10,
      "y": 1,
      "z": 18,
      "name": "Rock_Shale_Brick"
    },
    {
      "x": -10,
      "y": 2,
      "z": 18,
      "name": "Empty"
    },
    {
      "x": -10,
      "y": 3,
      "z": 18,
      "name": "Empty"
    },
    {
      "x": -10,
      "y": 4,
      "z": 18,
      "name": "Empty"
    },
    {
      "x": -10,
      "y": 5,
      "z": 18,
      "name": "Empty"
    },
    {
      "x": -10,
      "y": 6,
      "z": 18,
      "name": "Rock_Shale_Brick"
    },
    {
      "x": -10,
      "y": 7,
      "z": 18,
      "name": "Rock_Shale_Brick"
    },
    {
      "x": -10,
      "y": 8,
      "z": 18,
      "name": "Rock_Shale_Brick"
    },
    {
      "x": -10,
      "y": 9,
      "z": 18,
      "name": "Rock_Shale_Brick"
    },
    {
      "x": -10,
      "y": 10,
      "z": 18,
      "name": "Rock_Shale_Brick"
    },
    {
      "x": -10,
      "y": 11,
      "z": 18,
      "name": "Rock_Shale_Brick"
    },
    {
      "x": -10,
      "y": 1,
      "z": 19,
      "name": "Rock_Shale_Brick"
    },
    {
      "x": -10,
      "y": 2,
      "z": 19,
      "name": "Empty"
    },
    {
      "x": -10,
      "y": 3,
      "z": 19,
      "name": "Empty"
    },
    {
      "x": -10,
      "y": 4,
      "z": 19,
      "name": "Empty"
    },
    {
      "x": -10,
      "y": 5,
      "z": 19,
      "name": "Empty"
    },
    {
      "x": -10,
      "y": 6,
      "z": 19,
      "name": "Rock_Shale_Brick"
    },
    {
      "x": -10,
      "y": 7,
      "z": 19,
      "name": "Rock_Shale_Brick"
    },
    {
      "x": -10,
      "y": 8,
      "z": 19,
      "name": "Rock_Shale_Brick"
    },
    {
      "x": -10,
      "y": 9,
      "z": 19,
      "name": "Rock_Shale_Brick"
    },
    {
      "x": -10,
      "y": 10,
      "z": 19,
      "name": "Rock_Shale_Brick"
    },
    {
      "x": -10,
      "y": 11,
      "z": 19,
      "name": "Rock_Shale_Brick"
    },
    {
      "x": -10,
      "y": 1,
      "z": 20,
      "name": "Rock_Shale_Brick"
    },
    {
      "x": -10,
      "y": 2,
      "z": 20,
      "name": "Rock_Shale_Brick"
    },
    {
      "x": -10,
      "y": 3,
      "z": 20,
      "name": "Rock_Shale_Brick"
    },
    {
      "x": -10,
      "y": 4,
      "z": 20,
      "name": "Rock_Shale_Brick"
    },
    {
      "x": -10,
      "y": 5,
      "z": 20,
      "name": "Rock_Shale_Brick"
    },
    {
      "x": -10,
      "y": 6,
      "z": 20,
      "name": "Rock_Shale_Brick"
    },
    {
      "x": -10,
      "y": 7,
      "z": 20,
      "name": "Rock_Shale_Brick"
    },
    {
      "x": -10,
      "y": 8,
      "z": 20,
      "name": "Rock_Shale_Brick"
    },
    {
      "x": -10,
      "y": 9,
      "z": 20,
      "name": "Rock_Shale_Brick"
    },
    {
      "x": -10,
      "y": 10,
      "z": 20,
      "name": "Rock_Shale_Brick"
    },
    {
      "x": -10,
      "y": 11,
      "z": 20,
      "name": "Rock_Shale_Brick"
    },
    {
      "x": -9,
      "y": 12,
      "z": -10,
      "name": "Soil_Dirt"
    },
    {
      "x": -9,
      "y": 13,
      "z": -10,
      "name": "Soil_Dirt"
    },
    {
      "x": -9,
      "y": 14,
      "z": -10,
      "name": "Soil_Dirt"
    },
    {
      "x": -9,
      "y": 15,
      "z": -10,
      "name": "Soil_Dirt"
    },
    {
      "x": -9,
      "y": 16,
      "z": -10,
      "name": "Soil_Dirt"
    },
    {
      "x": -9,
      "y": 17,
      "z": -10,
      "name": "Soil_Dirt"
    },
    {
      "x": -9,
      "y": 18,
      "z": -10,
      "name": "Soil_Grass"
    },
    {
      "x": -9,
      "y": 12,
      "z": -9,
      "name": "Soil_Dirt"
    },
    {
      "x": -9,
      "y": 13,
      "z": -9,
      "name": "Soil_Dirt"
    },
    {
      "x": -9,
      "y": 14,
      "z": -9,
      "name": "Soil_Dirt"
    },
    {
      "x": -9,
      "y": 15,
      "z": -9,
      "name": "Soil_Dirt"
    },
    {
      "x": -9,
      "y": 16,
      "z": -9,
      "name": "Soil_Dirt"
    },
    {
      "x": -9,
      "y": 17,
      "z": -9,
      "name": "Soil_Dirt"
    },
    {
      "x": -9,
      "y": 18,
      "z": -9,
      "name": "Soil_Grass"
    },
    {
      "x": -9,
      "y": 12,
      "z": -8,
      "name": "Soil_Dirt"
    },
    {
      "x": -9,
      "y": 13,
      "z": -8,
      "name": "Soil_Dirt"
    },
    {
      "x": -9,
      "y": 14,
      "z": -8,
      "name": "Soil_Dirt"
    },
    {
      "x": -9,
      "y": 15,
      "z": -8,
      "name": "Soil_Dirt"
    },
    {
      "x": -9,
      "y": 16,
      "z": -8,
      "name": "Soil_Dirt"
    },
    {
      "x": -9,
      "y": 17,
      "z": -8,
      "name": "Soil_Dirt"
    },
    {
      "x": -9,
      "y": 18,
      "z": -8,
      "name": "Soil_Grass"
    },
    {
      "x": -9,
      "y": 12,
      "z": -7,
      "name": "Soil_Dirt"
    },
    {
      "x": -9,
      "y": 13,
      "z": -7,
      "name": "Soil_Dirt"
    },
    {
      "x": -9,
      "y": 14,
      "z": -7,
      "name": "Soil_Dirt"
    },
    {
      "x": -9,
      "y": 15,
      "z": -7,
      "name": "Soil_Dirt"
    },
    {
      "x": -9,
      "y": 16,
      "z": -7,
      "name": "Soil_Dirt"
    },
    {
      "x": -9,
      "y": 17,
      "z": -7,
      "name": "Soil_Dirt"
    },
    {
