{
  "version": 8,
  "blockIdVersion": 11,
  "anchorX": 0,
  "anchorY": 0,
  "anchorZ": 0,
  "blocks": [
    {
      "x": -19,
      "y": 60,
      "z": -2,
      "name": "Rock_Shale_Brick_Smooth",
      "rotation": 1
    },
    {
      "x": -19,
      "y": 64,
      "z": -2,
      "name": "Rock_Shale_Brick_Smooth",
      "rotation": 1
    },
    {
      "x": -19,
      "y": 60,
      "z": -1,
      "name": "Rock_Shale_Brick_Smooth",
      "rotation": 1
    },
    {
      "x": -19,
      "y": 64,
      "z": -1,
      "name": "Rock_Shale_Brick_Smooth",
      "rotation": 1
    },
    {
      "x": -19,
      "y": 60,
      "z": 0,
      "name": "Rock_Shale_Brick_Smooth",
      "rotation": 1
    },
    {
      "x": -19,
      "y": 64,
      "z": 0,
      "name": "Rock_Shale_Brick_Smooth",
      "rotation": 1
    },
    {
      "x": -19,
      "y": 60,
      "z": 1,
      "name": "Rock_Shale_Brick_Smooth",
      "rotation": 1
    },
    {
      "x": -19,
      "y": 64,
      "z": 1,
      "name": "Rock_Shale_Brick_Smooth",
      "rotation": 1
    },
    {
      "x": -19,
      "y": 60,
      "z": 2,
      "name": "Rock_Shale_Brick_Smooth",
      "rotation": 1
    },
    {
      "x": -19,
      "y": 64,
      "z": 2,
      "name": "Rock_Shale_Brick_Smooth",
      "rotation": 1
    },
    {
      "x": -19,
      "y": 60,
      "z": 3,
      "name": "Rock_Shale_Brick_Smooth",
      "rotation": 1
    },
    {
      "x": -19,
      "y": 64,
      "z": 3,
      "name": "Rock_Shale_Brick_Smooth",
      "rotation": 1
    },
    {
      "x": -18,
      "y": 60,
      "z": -3,
      "name": "Rock_Shale_Brick_Smooth",
      "rotation": 1
    },
    {
      "x": -18,
      "y": 64,
      "z": -3,
      "name": "Rock_Shale_Brick_Smooth",
      "rotation": 1
    },
    {
      "x": -18,
      "y": 60,
      "z": -2,
      "name": "Rock_Shale_Cobble",
      "rotation": 7
    },
    {
      "x": -18,
      "y": 61,
      "z": -2,
      "name": "Rock_Shale_Cobble",
      "rotation": 7
    },
    {
      "x": -18,
      "y": 62,
      "z": -2,
      "name": "Build_Lightsource_Cyan",
      "rotation": 7
    },
    {
      "x": -18,
      "y": 63,
      "z": -2,
      "name": "Rock_Shale_Cobble",
      "rotation": 7
    },
    {
      "x": -18,
      "y": 64,
      "z": -2,
      "name": "Rock_Shale_Cobble",
      "rotation": 7
    },
    {
      "x": -18,
      "y": 59,
      "z": -1,
      "name": "Rock_Shale_Cobble_Half",
      "rotation": 7
    },
    {
      "x": -18,
      "y": 60,
      "z": -1,
      "name": "Rock_Shale_Cobble",
      "rotation": 7
    },
    {
      "x": -18,
      "y": 61,
      "z": -1,
      "name": "Rock_Shale_Cobble",
      "rotation": 7
    },
    {
      "x": -18,
      "y": 62,
      "z": -1,
      "name": "Build_Lightsource_Cyan",
      "rotation": 17
    },
    {
      "x": -18,
      "y": 63,
      "z": -1,
      "name": "Rock_Shale_Cobble",
      "rotation": 7
    },
    {
      "x": -18,
      "y": 64,
      "z": -1,
      "name": "Rock_Shale_Cobble",
      "rotation": 7
    },
    {
      "x": -18,
      "y": 65,
      "z": -1,
      "name": "Rock_Shale_Cobble_Half",
      "rotation": 7
    },
    {
      "x": -18,
      "y": 60,
      "z": 0,
      "name": "Rock_Shale_Cobble",
      "rotation": 7
    },
    {
      "x": -18,
      "y": 61,
      "z": 0,
      "name": "Rock_Shale_Cobble",
      "rotation": 7
    },
    {
      "x": -18,
      "y": 62,
      "z": 0,
      "name": "Build_Lightsource_Cyan",
      "rotation": 17
    },
    {
      "x": -18,
      "y": 63,
      "z": 0,
      "name": "Rock_Shale_Cobble",
      "rotation": 7
    },
    {
      "x": -18,
      "y": 64,
      "z": 0,
      "name": "Rock_Shale_Cobble",
      "rotation": 7
    },
    {
      "x": -18,
      "y": 60,
      "z": 1,
      "name": "Rock_Shale_Cobble",
      "rotation": 7
    },
    {
      "x": -18,
      "y": 61,
      "z": 1,
      "name": "Rock_Shale_Cobble",
      "rotation": 7
    },
    {
      "x": -18,
      "y": 62,
      "z": 1,
      "name": "Build_Lightsource_Cyan",
      "rotation": 17
    },
    {
      "x": -18,
      "y": 63,
      "z": 1,
      "name": "Rock_Shale_Cobble",
      "rotation": 7
    },
    {
      "x": -18,
      "y": 64,
      "z": 1,
      "name": "Rock_Shale_Cobble",
      "rotation": 7
    },
    {
      "x": -18,
      "y": 59,
      "z": 2,
      "name": "Rock_Shale_Cobble_Half",
      "rotation": 7
    },
    {
      "x": -18,
      "y": 60,
      "z": 2,
      "name": "Rock_Shale_Cobble",
      "rotation": 7
    },
    {
      "x": -18,
      "y": 61,
      "z": 2,
      "name": "Rock_Shale_Cobble",
      "rotation": 7
    },
    {
      "x": -18,
      "y": 62,
      "z": 2,
      "name": "Build_Lightsource_Cyan",
      "rotation": 7
    },
    {
      "x": -18,
      "y": 63,
      "z": 2,
      "name": "Rock_Shale_Cobble",
      "rotation": 7
    },
    {
      "x": -18,
      "y": 64,
      "z": 2,
      "name": "Rock_Shale_Cobble",
      "rotation": 7
    },
    {
      "x": -18,
      "y": 65,
      "z": 2,
      "name": "Rock_Shale_Cobble_Half",
      "rotation": 7
    },
    {
      "x": -18,
      "y": 60,
      "z": 3,
      "name": "Rock_Shale_Cobble",
      "rotation": 7
    },
    {
      "x": -18,
      "y": 61,
      "z": 3,
      "name": "Rock_Shale_Cobble",
      "rotation": 7
    },
    {
      "x": -18,
      "y": 62,
      "z": 3,
      "name": "Build_Lightsource_Cyan",
      "rotation": 7
    },
    {
      "x": -18,
      "y": 63,
      "z": 3,
      "name": "Rock_Shale_Cobble",
      "rotation": 7
    },
    {
      "x": -18,
      "y": 64,
      "z": 3,
      "name": "Rock_Shale_Cobble",
      "rotation": 7
    },
    {
      "x": -18,
      "y": 60,
      "z": 4,
      "name": "Rock_Shale_Brick_Smooth",
      "rotation": 1
    },
    {
      "x": -18,
      "y": 64,
      "z": 4,
      "name": "Rock_Shale_Brick_Smooth",
      "rotation": 1
    },
    {
      "x": -17,
      "y": 60,
      "z": -4,
      "name": "Rock_Shale_Brick_Smooth",
      "rotation": 1
    },
    {
      "x": -17,
      "y": 64,
      "z": -4,
      "name": "Rock_Shale_Brick_Smooth",
      "rotation": 1
    },
    {
      "x": -17,
      "y": 60,
      "z": -3,
      "name": "Rock_Shale_Cobble",
      "rotation": 7
    },
    {
      "x": -17,
      "y": 61,
      "z": -3,
      "name": "Rock_Shale_Cobble",
      "rotation": 7
    },
    {
      "x": -17,
      "y": 62,
      "z": -3,
      "name": "Build_Lightsource_Cyan",
      "rotation": 17
    },
    {
      "x": -17,
      "y": 63,
      "z": -3,
      "name": "Rock_Shale_Cobble",
      "rotation": 7
    },
    {
      "x": -17,
      "y": 64,
      "z": -3,
      "name": "Rock_Shale_Cobble",
      "rotation": 1
    },
    {
      "x": -17,
      "y": 59,
      "z": -2,
      "name": "Rock_Shale_Cobble",
      "rotation": 17
    },
    {
      "x": -17,
      "y": 60,
      "z": -2,
      "name": "Rock_Shale_Cobble",
      "rotation": 6
    },
    {
      "x": -17,
      "y": 61,
      "z": -2,
      "name": "Rock_Shale_Cobble",
      "rotation": 6
    },
    {
      "x": -17,
      "y": 62,
      "z": -2,
      "name": "Rock_Shale_Cobble",
      "rotation": 6
    },
    {
      "x": -17,
      "y": 63,
      "z": -2,
      "name": "Rock_Shale_Cobble",
      "rotation": 6
    },
    {
      "x": -17,
      "y": 64,
      "z": -2,
      "name": "Rock_Shale_Cobble",
      "rotation": 7
    },
    {
      "x": -17,
      "y": 65,
      "z": -2,
      "name": "Rock_Shale_Cobble",
      "rotation": 4
    },
    {
      "x": -17,
      "y": 56,
      "z": -1,
      "name": "Rock_Shale_Cobble_Half",
      "rotation": 7
    },
    {
      "x": -17,
      "y": 57,
      "z": -1,
      "name": "Rock_Shale_Cobble_Half",
      "rotation": 7
    },
    {
      "x": -17,
      "y": 58,
      "z": -1,
      "name": "Rock_Shale_Cobble_Half",
      "rotation": 7
    },
    {
      "x": -17,
      "y": 59,
      "z": -1,
      "name": "Rock_Shale_Cobble",
      "rotation": 17
    },
    {
      "x": -17,
      "y": 60,
      "z": -1,
      "name": "Rock_Shale_Cobble",
      "rotation": 6
    },
    {
      "x": -17,
      "y": 61,
      "z": -1,
      "name": "Rock_Shale_Cobble",
      "rotation": 6
    },
    {
      "x": -17,
      "y": 62,
      "z": -1,
      "name": "Rock_Shale_Cobble",
      "rotation": 6
    },
    {
      "x": -17,
      "y": 63,
      "z": -1,
      "name": "Rock_Shale_Cobble",
      "rotation": 6
    },
    {
      "x": -17,
      "y": 64,
      "z": -1,
      "name": "Rock_Shale_Cobble",
      "rotation": 6
    },
    {
      "x": -17,
      "y": 65,
      "z": -1,
      "name": "Rock_Shale_Cobble",
      "rotation": 4
    },
    {
      "x": -17,
      "y": 66,
      "z": -1,
      "name": "Rock_Shale_Cobble_Half",
      "rotation": 7
    },
    {
      "x": -17,
      "y": 67,
      "z": -1,
      "name": "Rock_Shale_Cobble_Half",
      "rotation": 7
    },
    {
      "x": -17,
      "y": 68,
      "z": -1,
      "name": "Rock_Shale_Cobble_Half",
      "rotation": 7
    },
    {
      "x": -17,
      "y": 59,
      "z": 0,
      "name": "Rock_Shale_Cobble",
      "rotation": 17
    },
    {
      "x": -17,
      "y": 60,
      "z": 0,
      "name": "Rock_Shale_Cobble",
      "rotation": 6
    },
    {
      "x": -17,
      "y": 61,
      "z": 0,
      "name": "Rock_Shale_Cobble",
      "rotation": 6
    },
    {
      "x": -17,
      "y": 62,
      "z": 0,
      "name": "Rock_Shale_Cobble",
      "rotation": 6
    },
    {
      "x": -17,
      "y": 63,
      "z": 0,
      "name": "Rock_Shale_Cobble",
      "rotation": 6
    },
    {
      "x": -17,
      "y": 64,
      "z": 0,
      "name": "Rock_Shale_Cobble",
      "rotation": 6
    },
    {
      "x": -17,
      "y": 65,
      "z": 0,
      "name": "Rock_Shale_Cobble",
      "rotation": 4
    },
    {
      "x": -17,
      "y": 59,
      "z": 1,
      "name": "Rock_Shale_Cobble",
      "rotation": 17
    },
    {
      "x": -17,
      "y": 60,
      "z": 1,
      "name": "Rock_Shale_Cobble",
      "rotation": 6
    },
    {
      "x": -17,
      "y": 61,
      "z": 1,
      "name": "Rock_Shale_Cobble",
      "rotation": 6
    },
    {
      "x": -17,
      "y": 62,
      "z": 1,
      "name": "Rock_Shale_Cobble",
      "rotation": 6
    },
    {
      "x": -17,
      "y": 63,
      "z": 1,
      "name": "Rock_Shale_Cobble",
      "rotation": 6
    },
    {
      "x": -17,
      "y": 64,
      "z": 1,
      "name": "Rock_Shale_Cobble",
      "rotation": 6
    },
    {
      "x": -17,
      "y": 65,
      "z": 1,
      "name": "Rock_Shale_Cobble",
      "rotation": 4
    },
    {
      "x": -17,
      "y": 56,
      "z": 2,
      "name": "Rock_Shale_Cobble_Half",
      "rotation": 7
    },
    {
      "x": -17,
      "y": 57,
      "z": 2,
      "name": "Rock_Shale_Cobble_Half",
      "rotation": 7
    },
    {
      "x": -17,
      "y": 58,
      "z": 2,
      "name": "Rock_Shale_Cobble_Half",
      "rotation": 7
    },
    {
      "x": -17,
      "y": 59,
      "z": 2,
      "name": "Rock_Shale_Cobble",
      "rotation": 17
    },
    {
      "x": -17,
      "y": 60,
      "z": 2,
      "name": "Rock_Shale_Cobble",
      "rotation": 6
    },
    {
      "x": -17,
      "y": 61,
      "z": 2,
      "name": "Rock_Shale_Cobble",
      "rotation": 6
    },
    {
      "x": -17,
      "y": 62,
      "z": 2,
      "name": "Rock_Shale_Cobble",
      "rotation": 6
    },
    {
      "x": -17,
      "y": 63,
      "z": 2,
      "name": "Rock_Shale_Cobble",
      "rotation": 6
    },
    {
      "x": -17,
      "y": 64,
      "z": 2,
      "name": "Rock_Shale_Cobble",
      "rotation": 6
    },
    {
      "x": -17,
      "y": 65,
      "z": 2,
      "name": "Rock_Shale_Cobble",
      "rotation": 4
    },
    {
      "x": -17,
      "y": 66,
      "z": 2,
      "name": "Rock_Shale_Cobble_Half",
      "rotation": 7
    },
    {
      "x": -17,
      "y": 67,
      "z": 2,
      "name": "Rock_Shale_Cobble_Half",
      "rotation": 7
    },
    {
      "x": -17,
      "y": 68,
      "z": 2,
      "name": "Rock_Shale_Cobble_Half",
      "rotation": 7
    },
    {
      "x": -17,
      "y": 59,
      "z": 3,
      "name": "Rock_Shale_Cobble",
      "rotation": 17
    },
    {
      "x": -17,
      "y": 60,
      "z": 3,
      "name": "Rock_Shale_Cobble",
      "rotation": 6
    },
    {
      "x": -17,
      "y": 61,
      "z": 3,
      "name": "Rock_Shale_Cobble",
      "rotation": 6
    },
    {
      "x": -17,
      "y": 62,
      "z": 3,
      "name": "Rock_Shale_Cobble",
      "rotation": 6
    },
    {
      "x": -17,
      "y": 63,
      "z": 3,
      "name": "Rock_Shale_Cobble",
      "rotation": 6
    },
    {
      "x": -17,
      "y": 64,
      "z": 3,
      "name": "Rock_Shale_Cobble",
      "rotation": 6
    },
    {
      "x": -17,
      "y": 65,
      "z": 3,
      "name": "Rock_Shale_Cobble",
      "rotation": 4
    },
    {
      "x": -17,
      "y": 60,
      "z": 4,
      "name": "Rock_Shale_Cobble",
      "rotation": 7
    },
    {
      "x": -17,
      "y": 61,
      "z": 4,
      "name": "Rock_Shale_Cobble",
      "rotation": 7
    },
    {
      "x": -17,
      "y": 62,
      "z": 4,
      "name": "Build_Lightsource_Cyan",
      "rotation": 17
    },
    {
      "x": -17,
      "y": 63,
      "z": 4,
      "name": "Rock_Shale_Cobble",
      "rotation": 7
    },
    {
      "x": -17,
      "y": 64,
      "z": 4,
      "name": "Rock_Shale_Cobble",
      "rotation": 7
    },
    {
      "x": -17,
      "y": 60,
      "z": 5,
      "name": "Rock_Shale_Brick_Smooth",
      "rotation": 1
    },
    {
      "x": -17,
      "y": 64,
      "z": 5,
      "name": "Rock_Shale_Brick_Smooth",
      "rotation": 1
    },
    {
      "x": -16,
      "y": 60,
      "z": -4,
      "name": "Rock_Shale_Brick_Smooth",
      "rotation": 1
    },
    {
      "x": -16,
      "y": 64,
      "z": -4,
      "name": "Rock_Shale_Brick_Smooth",
      "rotation": 1
    },
    {
      "x": -16,
      "y": 60,
      "z": -3,
      "name": "Rock_Shale_Cobble",
      "rotation": 7
    },
    {
      "x": -16,
      "y": 61,
      "z": -3,
      "name": "Rock_Shale_Cobble",
      "rotation": 7
    },
    {
      "x": -16,
      "y": 62,
      "z": -3,
      "name": "Build_Lightsource_Cyan",
      "rotation": 17
    },
    {
      "x": -16,
      "y": 63,
      "z": -3,
      "name": "Rock_Shale_Cobble",
      "rotation": 7
    },
    {
      "x": -16,
      "y": 64,
      "z": -3,
      "name": "Rock_Shale_Cobble",
      "rotation": 1
    },
    {
      "x": -16,
      "y": 56,
      "z": -2,
      "name": "Rock_Shale_Cobble",
      "rotation": 17
    },
    {
      "x": -16,
      "y": 57,
      "z": -2,
      "name": "Rock_Shale_Cobble",
      "rotation": 17
    },
    {
      "x": -16,
      "y": 58,
      "z": -2,
      "name": "Rock_Shale_Cobble",
      "rotation": 17
    },
    {
      "x": -16,
      "y": 59,
      "z": -2,
      "name": "Rock_Shale_Cobble",
      "rotation": 17
    },
    {
      "x": -16,
      "y": 60,
      "z": -2,
      "name": "Rock_Shale_Cobble",
      "rotation": 6
    },
    {
      "x": -16,
      "y": 61,
      "z": -2,
      "name": "Rock_Shale_Cobble",
      "rotation": 6
    },
    {
      "x": -16,
      "y": 62,
      "z": -2,
      "name": "Rock_Shale_Cobble",
      "rotation": 6
    },
    {
      "x": -16,
      "y": 63,
      "z": -2,
      "name": "Rock_Shale_Cobble",
      "rotation": 6
    },
    {
      "x": -16,
      "y": 64,
      "z": -2,
      "name": "Rock_Shale_Cobble",
      "rotation": 7
    },
    {
      "x": -16,
      "y": 65,
      "z": -2,
      "name": "Rock_Shale_Cobble",
      "rotation": 4
    },
    {
      "x": -16,
      "y": 66,
      "z": -2,
      "name": "Rock_Shale_Cobble",
      "rotation": 4
    },
    {
      "x": -16,
      "y": 67,
      "z": -2,
      "name": "Rock_Shale_Cobble",
      "rotation": 4
    },
    {
      "x": -16,
      "y": 68,
      "z": -2,
      "name": "Rock_Shale_Cobble",
      "rotation": 4
    },
    {
      "x": -16,
      "y": 54,
      "z": -1,
      "name": "Rock_Shale_Cobble_Half",
      "rotation": 7
    },
    {
      "x": -16,
      "y": 55,
      "z": -1,
      "name": "Rock_Shale_Cobble_Half",
      "rotation": 7
    },
    {
      "x": -16,
      "y": 56,
      "z": -1,
      "name": "Rock_Shale_Cobble",
      "rotation": 17
    },
    {
      "x": -16,
      "y": 57,
      "z": -1,
      "name": "Rock_Shale_Cobble",
      "rotation": 17
    },
    {
      "x": -16,
      "y": 58,
      "z": -1,
      "name": "Rock_Shale_Cobble",
      "rotation": 17
    },
    {
      "x": -16,
      "y": 59,
      "z": -1,
      "name": "Rock_Shale_Cobble",
      "rotation": 17
    },
    {
      "x": -16,
      "y": 60,
      "z": -1,
      "name": "Rock_Shale_Cobble",
      "rotation": 6
    },
    {
      "x": -16,
      "y": 61,
      "z": -1,
      "name": "Rock_Shale_Cobble",
      "rotation": 6
    },
    {
      "x": -16,
      "y": 62,
      "z": -1,
      "name": "Rock_Shale_Cobble",
      "rotation": 6
    },
    {
      "x": -16,
      "y": 63,
      "z": -1,
      "name": "Rock_Shale_Cobble",
      "rotation": 6
    },
    {
      "x": -16,
      "y": 64,
      "z": -1,
      "name": "Rock_Shale_Cobble",
      "rotation": 6
    },
    {
      "x": -16,
      "y": 65,
      "z": -1,
      "name": "Rock_Shale_Cobble",
      "rotation": 4
    },
    {
      "x": -16,
      "y": 66,
      "z": -1,
      "name": "Rock_Shale_Cobble",
      "rotation": 4
    },
    {
      "x": -16,
      "y": 67,
      "z": -1,
      "name": "Rock_Shale_Cobble",
      "rotation": 4
    },
    {
      "x": -16,
      "y": 68,
      "z": -1,
      "name": "Rock_Shale_Cobble",
      "rotation": 4
    },
    {
      "x": -16,
      "y": 69,
      "z": -1,
      "name": "Rock_Shale_Cobble_Half",
      "rotation": 7
    },
    {
      "x": -16,
      "y": 70,
      "z": -1,
      "name": "Rock_Shale_Cobble_Half",
      "rotation": 7
    },
    {
      "x": -16,
      "y": 56,
      "z": 0,
      "name": "Rock_Shale_Cobble",
      "rotation": 17
    },
    {
      "x": -16,
      "y": 57,
      "z": 0,
      "name": "Rock_Shale_Cobble",
      "rotation": 17
    },
    {
      "x": -16,
      "y": 58,
      "z": 0,
      "name": "Rock_Shale_Cobble",
      "rotation": 17
    },
    {
      "x": -16,
      "y": 59,
      "z": 0,
      "name": "Rock_Shale_Cobble",
      "rotation": 17
    },
    {
      "x": -16,
      "y": 60,
      "z": 0,
      "name": "Rock_Shale_Cobble",
      "rotation": 6
    },
    {
      "x": -16,
      "y": 61,
      "z": 0,
      "name": "Rock_Shale_Cobble",
      "rotation": 6
    },
    {
      "x": -16,
      "y": 62,
      "z": 0,
      "name": "Rock_Shale_Cobble",
      "rotation": 6
    },
    {
      "x": -16,
      "y": 63,
      "z": 0,
      "name": "Rock_Shale_Cobble",
      "rotation": 6
    },
    {
      "x": -16,
      "y": 64,
      "z": 0,
      "name": "Rock_Shale_Cobble",
      "rotation": 6
    },
    {
      "x": -16,
      "y": 65,
      "z": 0,
      "name": "Rock_Shale_Cobble",
      "rotation": 4
    },
    {
      "x": -16,
      "y": 66,
      "z": 0,
      "name": "Rock_Shale_Cobble",
      "rotation": 4
    },
    {
      "x": -16,
      "y": 67,
      "z": 0,
      "name": "Rock_Shale_Cobble",
      "rotation": 4
    },
    {
      "x": -16,
      "y": 68,
      "z": 0,
      "name": "Rock_Shale_Cobble",
      "rotation": 4
    },
    {
      "x": -16,
      "y": 56,
      "z": 1,
      "name": "Rock_Shale_Cobble",
      "rotation": 17
    },
    {
      "x": -16,
      "y": 57,
      "z": 1,
      "name": "Rock_Shale_Cobble",
      "rotation": 17
    },
    {
      "x": -16,
      "y": 58,
      "z": 1,
      "name": "Rock_Shale_Cobble",
      "rotation": 17
    },
    {
      "x": -16,
      "y": 59,
      "z": 1,
      "name": "Rock_Shale_Cobble",
      "rotation": 17
    },
    {
      "x": -16,
      "y": 60,
      "z": 1,
      "name": "Rock_Shale_Cobble",
      "rotation": 6
    },
    {
      "x": -16,
      "y": 61,
      "z": 1,
      "name": "Rock_Shale_Cobble",
      "rotation": 6
    },
    {
      "x": -16,
      "y": 62,
      "z": 1,
      "name": "Rock_Shale_Cobble",
      "rotation": 6
    },
    {
      "x": -16,
      "y": 63,
      "z": 1,
      "name": "Rock_Shale_Cobble",
      "rotation": 6
    },
    {
      "x": -16,
      "y": 64,
      "z": 1,
      "name": "Rock_Shale_Cobble",
      "rotation": 6
    },
    {
      "x": -16,
      "y": 65,
      "z": 1,
      "name": "Rock_Shale_Cobble",
      "rotation": 4
    },
    {
      "x": -16,
      "y": 66,
      "z": 1,
      "name": "Rock_Shale_Cobble",
      "rotation": 4
    },
    {
      "x": -16,
      "y": 67,
      "z": 1,
      "name": "Rock_Shale_Cobble",
      "rotation": 4
    },
    {
      "x": -16,
      "y": 68,
      "z": 1,
      "name": "Rock_Shale_Cobble",
      "rotation": 4
    },
    {
      "x": -16,
      "y": 54,
      "z": 2,
      "name": "Rock_Shale_Cobble_Half",
      "rotation": 7
    },
    {
      "x": -16,
      "y": 55,
      "z": 2,
      "name": "Rock_Shale_Cobble_Half",
      "rotation": 7
    },
    {
      "x": -16,
      "y": 56,
      "z": 2,
      "name": "Rock_Shale_Cobble",
      "rotation": 17
    },
    {
      "x": -16,
      "y": 57,
      "z": 2,
      "name": "Rock_Shale_Cobble",
      "rotation": 17
    },
    {
      "x": -16,
      "y": 58,
      "z": 2,
      "name": "Rock_Shale_Cobble",
      "rotation": 17
    },
    {
      "x": -16,
      "y": 59,
      "z": 2,
      "name": "Rock_Shale_Cobble",
      "rotation": 17
    },
    {
      "x": -16,
      "y": 60,
      "z": 2,
      "name": "Rock_Shale_Cobble",
      "rotation": 6
    },
    {
      "x": -16,
      "y": 61,
      "z": 2,
      "name": "Rock_Shale_Cobble",
      "rotation": 6
    },
    {
      "x": -16,
      "y": 62,
      "z": 2,
      "name": "Rock_Shale_Cobble",
      "rotation": 6
    },
    {
      "x": -16,
      "y": 63,
      "z": 2,
      "name": "Rock_Shale_Cobble",
      "rotation": 6
    },
    {
      "x": -16,
      "y": 64,
      "z": 2,
      "name": "Rock_Shale_Cobble",
      "rotation": 6
    },
    {
      "x": -16,
      "y": 65,
      "z": 2,
      "name": "Rock_Shale_Cobble",
      "rotation": 4
    },
    {
      "x": -16,
      "y": 66,
      "z": 2,
      "name": "Rock_Shale_Cobble",
      "rotation": 4
    },
    {
      "x": -16,
      "y": 67,
      "z": 2,
      "name": "Rock_Shale_Cobble",
      "rotation": 4
    },
    {
      "x": -16,
      "y": 68,
      "z": 2,
      "name": "Rock_Shale_Cobble",
      "rotation": 4
    },
    {
      "x": -16,
      "y": 69,
      "z": 2,
      "name": "Rock_Shale_Cobble_Half",
      "rotation": 7
    },
    {
      "x": -16,
      "y": 70,
      "z": 2,
      "name": "Rock_Shale_Cobble_Half",
      "rotation": 7
    },
    {
      "x": -16,
      "y": 56,
      "z": 3,
      "name": "Rock_Shale_Cobble",
      "rotation": 17
    },
    {
      "x": -16,
      "y": 57,
      "z": 3,
      "name": "Rock_Shale_Cobble",
      "rotation": 17
    },
    {
      "x": -16,
      "y": 58,
      "z": 3,
      "name": "Rock_Shale_Cobble",
      "rotation": 17
    },
    {
      "x": -16,
      "y": 59,
      "z": 3,
      "name": "Rock_Shale_Cobble",
      "rotation": 17
    },
    {
      "x": -16,
      "y": 60,
      "z": 3,
      "name": "Rock_Shale_Cobble",
      "rotation": 6
    },
    {
      "x": -16,
      "y": 61,
      "z": 3,
      "name": "Rock_Shale_Cobble",
      "rotation": 6
    },
    {
      "x": -16,
      "y": 62,
      "z": 3,
      "name": "Rock_Shale_Cobble",
      "rotation": 6
    },
    {
      "x": -16,
      "y": 63,
      "z": 3,
      "name": "Rock_Shale_Cobble",
      "rotation": 6
    },
    {
      "x": -16,
      "y": 64,
      "z": 3,
      "name": "Rock_Shale_Cobble",
      "rotation": 6
    },
    {
      "x": -16,
      "y": 65,
      "z": 3,
      "name": "Rock_Shale_Cobble",
      "rotation": 4
    },
    {
      "x": -16,
      "y": 66,
      "z": 3,
      "name": "Rock_Shale_Cobble",
      "rotation": 4
    },
    {
      "x": -16,
      "y": 67,
      "z": 3,
      "name": "Rock_Shale_Cobble",
      "rotation": 4
    },
    {
      "x": -16,
      "y": 68,
      "z": 3,
      "name": "Rock_Shale_Cobble",
      "rotation": 4
    },
    {
      "x": -16,
      "y": 60,
      "z": 4,
      "name": "Rock_Shale_Cobble",
      "rotation": 7
    },
    {
      "x": -16,
      "y": 61,
      "z": 4,
      "name": "Rock_Shale_Cobble",
      "rotation": 7
    },
    {
      "x": -16,
      "y": 62,
      "z": 4,
      "name": "Build_Lightsource_Cyan",
      "rotation": 7
    },
    {
      "x": -16,
      "y": 63,
      "z": 4,
      "name": "Rock_Shale_Cobble",
      "rotation": 7
    },
    {
      "x": -16,
      "y": 64,
      "z": 4,
      "name": "Rock_Shale_Cobble",
      "rotation": 7
    },
    {
      "x": -16,
      "y": 60,
      "z": 5,
      "name": "Rock_Shale_Brick_Smooth",
      "rotation": 1
    },
    {
      "x": -16,
      "y": 64,
      "z": 5,
      "name": "Rock_Shale_Brick_Smooth",
      "rotation": 1
    },
    {
      "x": -15,
      "y": 60,
      "z": -4,
      "name": "Rock_Shale_Brick_Smooth",
      "rotation": 1
    },
    {
      "x": -15,
      "y": 64,
      "z": -4,
      "name": "Rock_Shale_Brick_Smooth",
      "rotation": 1
    },
    {
      "x": -15,
      "y": 60,
      "z": -3,
      "name": "Rock_Shale_Cobble",
      "rotation": 7
    },
    {
      "x": -15,
      "y": 61,
      "z": -3,
      "name": "Rock_Shale_Cobble",
      "rotation": 7
    },
    {
      "x": -15,
      "y": 62,
      "z": -3,
      "name": "Build_Lightsource_Cyan",
      "rotation": 7
    },
    {
      "x": -15,
      "y": 63,
      "z": -3,
      "name": "Rock_Shale_Cobble",
      "rotation": 7
    },
    {
      "x": -15,
      "y": 64,
      "z": -3,
      "name": "Rock_Shale_Cobble",
      "rotation": 1
    },
    {
      "x": -15,
      "y": 54,
      "z": -2,
      "name": "Rock_Shale_Cobble",
      "rotation": 17
    },
    {
      "x": -15,
      "y": 55,
      "z": -2,
      "name": "Rock_Shale_Cobble",
      "rotation": 17
    },
    {
      "x": -15,
      "y": 56,
      "z": -2,
      "name": "Rock_Shale_Cobble",
      "rotation": 17
    },
    {
      "x": -15,
      "y": 57,
      "z": -2,
      "name": "Rock_Shale_Cobble",
      "rotation": 17
    },
    {
      "x": -15,
      "y": 58,
      "z": -2,
      "name": "Rock_Shale_Cobble",
      "rotation": 17
    },
    {
      "x": -15,
      "y": 59,
      "z": -2,
      "name": "Rock_Shale_Cobble",
      "rotation": 17
    },
    {
      "x": -15,
      "y": 60,
      "z": -2,
      "name": "Rock_Shale_Cobble",
      "rotation": 6
    },
    {
      "x": -15,
      "y": 61,
      "z": -2,
      "name": "Rock_Shale_Cobble",
      "rotation": 6
    },
    {
      "x": -15,
      "y": 62,
      "z": -2,
      "name": "Rock_Shale_Cobble",
      "rotation": 6
    },
    {
      "x": -15,
      "y": 63,
      "z": -2,
      "name": "Rock_Shale_Cobble",
      "rotation": 6
    },
    {
      "x": -15,
      "y": 64,
      "z": -2,
      "name": "Rock_Shale_Cobble",
      "rotation": 7
    },
    {
      "x": -15,
      "y": 65,
      "z": -2,
      "name": "Rock_Shale_Cobble",
      "rotation": 4
    },
    {
      "x": -15,
      "y": 66,
      "z": -2,
      "name": "Rock_Shale_Cobble",
      "rotation": 4
    },
    {
      "x": -15,
      "y": 67,
      "z": -2,
      "name": "Rock_Shale_Cobble",
      "rotation": 4
    },
    {
      "x": -15,
      "y": 68,
      "z": -2,
      "name": "Rock_Shale_Cobble",
      "rotation": 4
    },
    {
      "x": -15,
      "y": 69,
      "z": -2,
      "name": "Rock_Shale_Cobble",
      "rotation": 4
    },
    {
      "x": -15,
      "y": 70,
      "z": -2,
      "name": "Rock_Shale_Cobble",
      "rotation": 4
    },
    {
      "x": -15,
      "y": 52,
      "z": -1,
      "name": "Rock_Shale_Cobble_Half",
      "rotation": 7
    },
    {
      "x": -15,
      "y": 53,
      "z": -1,
      "name": "Rock_Shale_Cobble_Half",
      "rotation": 7
    },
    {
      "x": -15,
      "y": 54,
      "z": -1,
      "name": "Rock_Shale_Cobble",
      "rotation": 17
    },
    {
      "x": -15,
      "y": 55,
      "z": -1,
      "name": "Rock_Shale_Cobble",
      "rotation": 17
    },
    {
      "x": -15,
      "y": 56,
      "z": -1,
      "name": "Rock_Shale_Cobble",
      "rotation": 17
    },
    {
      "x": -15,
      "y": 57,
      "z": -1,
      "name": "Rock_Shale_Cobble",
      "rotation": 17
    },
    {
      "x": -15,
      "y": 58,
      "z": -1,
      "name": "Rock_Shale_Cobble",
      "rotation": 17
    },
    {
      "x": -15,
      "y": 59,
      "z": -1,
      "name": "Rock_Shale_Cobble",
      "rotation": 17
    },
    {
      "x": -15,
      "y": 60,
      "z": -1,
      "name": "Rock_Shale_Cobble",
      "rotation": 6
    },
    {
      "x": -15,
      "y": 61,
      "z": -1,
      "name": "Rock_Shale_Cobble",
      "rotation": 6
    },
    {
      "x": -15,
      "y": 62,
      "z": -1,
      "name": "Rock_Shale_Cobble",
      "rotation": 6
    },
    {
      "x": -15,
      "y": 63,
      "z": -1,
      "name": "Rock_Shale_Cobble",
      "rotation": 6
    },
    {
      "x": -15,
      "y": 64,
      "z": -1,
      "name": "Rock_Shale_Cobble",
      "rotation": 6
    },
    {
      "x": -15,
      "y": 65,
      "z": -1,
      "name": "Rock_Shale_Cobble",
      "rotation": 4
    },
    {
      "x": -15,
      "y": 66,
      "z": -1,
      "name": "Rock_Shale_Cobble",
      "rotation": 4
    },
    {
      "x": -15,
      "y": 67,
      "z": -1,
      "name": "Rock_Shale_Cobble",
      "rotation": 4
    },
    {
      "x": -15,
      "y": 68,
      "z": -1,
      "name": "Rock_Shale_Cobble",
      "rotation": 4
    },
    {
      "x": -15,
      "y": 69,
      "z": -1,
      "name": "Rock_Shale_Cobble",
      "rotation": 4
    },
    {
      "x": -15,
      "y": 70,
      "z": -1,
      "name": "Rock_Shale_Cobble",
      "rotation": 4
    },
    {
      "x": -15,
      "y": 71,
      "z": -1,
      "name": "Rock_Shale_Cobble_Half",
      "rotation": 7
    },
    {
      "x": -15,
      "y": 72,
      "z": -1,
      "name": "Rock_Shale_Cobble_Half",
      "rotation": 7
    },
    {
      "x": -15,
      "y": 54,
      "z": 0,
      "name": "Rock_Shale_Cobble",
      "rotation": 17
    },
    {
      "x": -15,
      "y": 55,
      "z": 0,
      "name": "Rock_Shale_Cobble",
      "rotation": 17
    },
    {
      "x": -15,
      "y": 56,
      "z": 0,
      "name": "Rock_Shale_Cobble",
      "rotation": 17
    },
    {
      "x": -15,
      "y": 57,
      "z": 0,
      "name": "Rock_Shale_Cobble",
      "rotation": 17
    },
    {
      "x": -15,
      "y": 58,
      "z": 0,
      "name": "Rock_Shale_Cobble",
      "rotation": 17
    },
    {
      "x": -15,
      "y": 59,
      "z": 0,
      "name": "Rock_Shale_Cobble",
      "rotation": 17
    },
    {
      "x": -15,
      "y": 60,
      "z": 0,
      "name": "Rock_Shale_Cobble",
      "rotation": 6
    },
    {
      "x": -15,
      "y": 61,
      "z": 0,
      "name": "Rock_Shale_Cobble",
      "rotation": 6
    },
    {
      "x": -15,
      "y": 62,
      "z": 0,
      "name": "Rock_Shale_Cobble",
      "rotation": 6
    },
    {
      "x": -15,
      "y": 63,
      "z": 0,
      "name": "Rock_Shale_Cobble",
      "rotation": 6
    },
    {
      "x": -15,
      "y": 64,
      "z": 0,
      "name": "Rock_Shale_Cobble",
      "rotation": 6
    },
    {
      "x": -15,
      "y": 65,
      "z": 0,
      "name": "Rock_Shale_Cobble",
      "rotation": 4
    },
    {
      "x": -15,
      "y": 66,
      "z": 0,
      "name": "Rock_Shale_Cobble",
      "rotation": 4
    },
    {
      "x": -15,
      "y": 67,
      "z": 0,
      "name": "Rock_Shale_Cobble",
      "rotation": 4
    },
    {
      "x": -15,
      "y": 68,
      "z": 0,
      "name": "Rock_Shale_Cobble",
      "rotation": 4
    },
    {
      "x": -15,
      "y": 69,
      "z": 0,
      "name": "Rock_Shale_Cobble",
      "rotation": 4
    },
    {
      "x": -15,
      "y": 70,
      "z": 0,
      "name": "Rock_Shale_Cobble",
      "rotation": 4
    },
    {
      "x": -15,
      "y": 54,
      "z": 1,
      "name": "Rock_Shale_Cobble",
      "rotation": 17
    },
    {
      "x": -15,
      "y": 55,
      "z": 1,
      "name": "Rock_Shale_Cobble",
      "rotation": 17
    },
    {
      "x": -15,
      "y": 56,
      "z": 1,
      "name": "Rock_Shale_Cobble",
      "rotation": 17
    },
    {
      "x": -15,
      "y": 57,
      "z": 1,
      "name": "Rock_Shale_Cobble",
      "rotation": 17
    },
    {
      "x": -15,
      "y": 58,
      "z": 1,
      "name": "Rock_Shale_Cobble",
      "rotation": 17
    },
    {
      "x": -15,
      "y": 59,
      "z": 1,
      "name": "Rock_Shale_Cobble",
      "rotation": 17
    },
    {
      "x": -15,
      "y": 60,
      "z": 1,
      "name": "Rock_Shale_Cobble",
      "rotation": 6
    },
    {
      "x": -15,
      "y": 61,
      "z": 1,
      "name": "Rock_Shale_Cobble",
      "rotation": 6
    },
    {
      "x": -15,
      "y": 62,
      "z": 1,
      "name": "Rock_Shale_Cobble",
      "rotation": 6
    },
    {
      "x": -15,
      "y": 63,
      "z": 1,
      "name": "Rock_Shale_Cobble",
      "rotation": 6
    },
    {
      "x": -15,
      "y": 64,
      "z": 1,
      "name": "Rock_Shale_Cobble",
      "rotation": 6
    },
    {
      "x": -15,
      "y": 65,
      "z": 1,
      "name": "Rock_Shale_Cobble",
      "rotation": 4
    },
    {
      "x": -15,
      "y": 66,
      "z": 1,
      "name": "Rock_Shale_Cobble",
      "rotation": 4
    },
    {
      "x": -15,
      "y": 67,
      "z": 1,
      "name": "Rock_Shale_Cobble",
      "rotation": 4
    },
    {
      "x": -15,
      "y": 68,
      "z": 1,
      "name": "Rock_Shale_Cobble",
      "rotation": 4
    },
    {
      "x": -15,
      "y": 69,
      "z": 1,
      "name": "Rock_Shale_Cobble",
      "rotation": 4
    },
    {
      "x": -15,
      "y": 70,
      "z": 1,
      "name": "Rock_Shale_Cobble",
      "rotation": 4
    },
    {
      "x": -15,
      "y": 52,
      "z": 2,
      "name": "Rock_Shale_Cobble_Half",
      "rotation": 7
    },
    {
      "x": -15,
      "y": 53,
      "z": 2,
      "name": "Rock_Shale_Cobble_Half",
      "rotation": 7
    },
    {
      "x": -15,
      "y": 54,
      "z": 2,
      "name": "Rock_Shale_Cobble",
      "rotation": 17
    },
    {
      "x": -15,
      "y": 55,
      "z": 2,
      "name": "Rock_Shale_Cobble",
      "rotation": 17
    },
    {
      "x": -15,
      "y": 56,
      "z": 2,
      "name": "Rock_Shale_Cobble",
      "rotation": 17
    },
    {
      "x": -15,
      "y": 57,
      "z": 2,
      "name": "Rock_Shale_Cobble",
      "rotation": 17
    },
    {
      "x": -15,
      "y": 58,
      "z": 2,
      "name": "Rock_Shale_Cobble",
      "rotation": 17
    },
    {
      "x": -15,
      "y": 59,
      "z": 2,
      "name": "Rock_Shale_Cobble",
      "rotation": 17
    },
    {
      "x": -15,
      "y": 60,
      "z": 2,
      "name": "Rock_Shale_Cobble",
      "rotation": 6
    },
    {
      "x": -15,
      "y": 61,
      "z": 2,
      "name": "Rock_Shale_Cobble",
      "rotation": 6
    },
    {
      "x": -15,
      "y": 62,
      "z": 2,
      "name": "Rock_Shale_Cobble",
      "rotation": 6
    },
    {
      "x": -15,
      "y": 63,
      "z": 2,
      "name": "Rock_Shale_Cobble",
      "rotation": 6
    },
    {
      "x": -15,
      "y": 64,
      "z": 2,
      "name": "Rock_Shale_Cobble",
      "rotation": 6
    },
    {
      "x": -15,
      "y": 65,
      "z": 2,
      "name": "Rock_Shale_Cobble",
      "rotation": 4
    },
    {
      "x": -15,
      "y": 66,
      "z": 2,
      "name": "Rock_Shale_Cobble",
      "rotation": 4
    },
    {
      "x": -15,
      "y": 67,
      "z": 2,
      "name": "Rock_Shale_Cobble",
      "rotation": 4
    },
    {
      "x": -15,
      "y": 68,
      "z": 2,
      "name": "Rock_Shale_Cobble",
      "rotation": 4
    },
    {
      "x": -15,
      "y": 69,
      "z": 2,
      "name": "Rock_Shale_Cobble",
      "rotation": 4
    },
    {
      "x": -15,
      "y": 70,
      "z": 2,
      "name": "Rock_Shale_Cobble",
      "rotation": 4
    },
    {
      "x": -15,
      "y": 71,
      "z": 2,
      "name": "Rock_Shale_Cobble_Half",
      "rotation": 7
    },
    {
      "x": -15,
      "y": 72,
      "z": 2,
      "name": "Rock_Shale_Cobble_Half",
      "rotation": 7
    },
    {
      "x": -15,
      "y": 54,
      "z": 3,
      "name": "Rock_Shale_Cobble",
      "rotation": 17
    },
    {
      "x": -15,
      "y": 55,
      "z": 3,
      "name": "Rock_Shale_Cobble",
      "rotation": 17
    },
    {
      "x": -15,
      "y": 56,
      "z": 3,
      "name": "Rock_Shale_Cobble",
      "rotation": 17
    },
    {
      "x": -15,
      "y": 57,
      "z": 3,
      "name": "Rock_Shale_Cobble",
      "rotation": 17
    },
    {
      "x": -15,
      "y": 58,
      "z": 3,
      "name": "Rock_Shale_Cobble",
      "rotation": 17
    },
    {
      "x": -15,
      "y": 59,
      "z": 3,
      "name": "Rock_Shale_Cobble",
      "rotation": 17
    },
    {
      "x": -15,
      "y": 60,
      "z": 3,
      "name": "Rock_Shale_Cobble",
      "rotation": 6
    },
    {
      "x": -15,
      "y": 61,
      "z": 3,
      "name": "Rock_Shale_Cobble",
      "rotation": 6
    },
    {
      "x": -15,
      "y": 62,
      "z": 3,
      "name": "Rock_Shale_Cobble",
      "rotation": 6
    },
    {
      "x": -15,
      "y": 63,
      "z": 3,
      "name": "Rock_Shale_Cobble",
      "rotation": 6
    },
    {
      "x": -15,
      "y": 64,
      "z": 3,
      "name": "Rock_Shale_Cobble",
      "rotation": 6
    },
    {
      "x": -15,
      "y": 65,
      "z": 3,
      "name": "Rock_Shale_Cobble",
      "rotation": 4
    },
    {
      "x": -15,
      "y": 66,
      "z": 3,
      "name": "Rock_Shale_Cobble",
      "rotation": 4
    },
    {
      "x": -15,
      "y": 67,
      "z": 3,
      "name": "Rock_Shale_Cobble",
      "rotation": 4
    },
    {
      "x": -15,
      "y": 68,
      "z": 3,
      "name": "Rock_Shale_Cobble",
      "rotation": 4
    },
    {
      "x": -15,
      "y": 69,
      "z": 3,
      "name": "Rock_Shale_Cobble",
      "rotation": 4
    },
    {
      "x": -15,
      "y": 70,
      "z": 3,
      "name": "Rock_Shale_Cobble",
      "rotation": 4
    },
    {
      "x": -15,
      "y": 60,
      "z": 4,
      "name": "Rock_Shale_Cobble",
      "rotation": 7
    },
    {
      "x": -15,
      "y": 61,
      "z": 4,
      "name": "Rock_Shale_Cobble",
      "rotation": 7
    },
    {
      "x": -15,
      "y": 62,
      "z": 4,
      "name": "Build_Lightsource_Cyan",
      "rotation": 17
    },
    {
      "x": -15,
      "y": 63,
      "z": 4,
      "name": "Rock_Shale_Cobble",
      "rotation": 7
    },
    {
      "x": -15,
      "y": 64,
      "z": 4,
      "name": "Rock_Shale_Cobble",
      "rotation": 7
    },
    {
      "x": -15,
      "y": 60,
      "z": 5,
      "name": "Rock_Shale_Brick_Smooth",
      "rotation": 1
    },
    {
      "x": -15,
      "y": 64,
      "z": 5,
      "name": "Rock_Shale_Brick_Smooth",
      "rotation": 1
    },
    {
      "x": -14,
      "y": 60,
      "z": -4,
      "name": "Rock_Shale_Brick_Smooth",
      "rotation": 1
    },
    {
      "x": -14,
      "y": 64,
      "z": -4,
      "name": "Rock_Shale_Brick_Smooth",
      "rotation": 1
    },
    {
      "x": -14,
      "y": 60,
      "z": -3,
      "name": "Rock_Shale_Cobble",
      "rotation": 7
    },
    {
      "x": -14,
      "y": 61,
      "z": -3,
      "name": "Rock_Shale_Cobble",
      "rotation": 7
    },
    {
      "x": -14,
      "y": 62,
      "z": -3,
      "name": "Build_Lightsource_Cyan",
      "rotation": 17
    },
    {
      "x": -14,
      "y": 63,
      "z": -3,
      "name": "Rock_Shale_Cobble",
      "rotation": 7
    },
    {
      "x": -14,
      "y": 64,
      "z": -3,
      "name": "Rock_Shale_Cobble",
      "rotation": 1
    },
    {
      "x": -14,
      "y": 52,
      "z": -2,
      "name": "Rock_Shale_Cobble",
      "rotation": 17
    },
    {
      "x": -14,
      "y": 53,
      "z": -2,
      "name": "Rock_Shale_Cobble",
      "rotation": 17
    },
    {
      "x": -14,
      "y": 54,
      "z": -2,
      "name": "Rock_Shale_Cobble",
      "rotation": 17
    },
    {
      "x": -14,
      "y": 55,
      "z": -2,
      "name": "Rock_Shale_Cobble",
      "rotation": 17
    },
    {
      "x": -14,
      "y": 56,
      "z": -2,
      "name": "Rock_Shale_Cobble",
      "rotation": 17
    },
    {
      "x": -14,
      "y": 57,
      "z": -2,
      "name": "Rock_Shale_Cobble",
      "rotation": 17
    },
    {
      "x": -14,
      "y": 58,
      "z": -2,
      "name": "Rock_Shale_Cobble",
      "rotation": 17
    },
    {
      "x": -14,
      "y": 59,
      "z": -2,
      "name": "Rock_Shale_Cobble",
      "rotation": 17
    },
    {
      "x": -14,
      "y": 60,
      "z": -2,
      "name": "Rock_Shale_Cobble",
      "rotation": 6
    },
    {
      "x": -14,
      "y": 61,
      "z": -2,
      "name": "Rock_Shale_Cobble",
      "rotation": 6
    },
    {
      "x": -14,
      "y": 62,
      "z": -2,
      "name": "Build_Lightsource_Cyan",
      "rotation": 17
    },
    {
      "x": -14,
      "y": 63,
      "z": -2,
      "name": "Rock_Shale_Cobble",
      "rotation": 6
    },
    {
      "x": -14,
      "y": 64,
      "z": -2,
      "name": "Rock_Shale_Cobble",
      "rotation": 7
    },
    {
      "x": -14,
      "y": 65,
      "z": -2,
      "name": "Rock_Shale_Cobble",
      "rotation": 4
    },
    {
      "x": -14,
      "y": 66,
      "z": -2,
      "name": "Rock_Shale_Cobble",
      "rotation": 4
    },
    {
      "x": -14,
      "y": 67,
      "z": -2,
      "name": "Rock_Shale_Cobble",
      "rotation": 4
    },
    {
      "x": -14,
      "y": 68,
      "z": -2,
      "name": "Rock_Shale_Cobble",
      "rotation": 4
    },
    {
      "x": -14,
      "y": 69,
      "z": -2,
      "name": "Rock_Shale_Cobble",
      "rotation": 4
    },
    {
      "x": -14,
      "y": 70,
      "z": -2,
      "name": "Rock_Shale_Cobble",
      "rotation": 4
    },
    {
      "x": -14,
      "y": 71,
      "z": -2,
      "name": "Rock_Shale_Cobble",
      "rotation": 4
    },
    {
      "x": -14,
      "y": 72,
      "z": -2,
      "name": "Rock_Shale_Cobble",
      "rotation": 4
    },
    {
      "x": -14,
      "y": 51,
      "z": -1,
      "name": "Rock_Shale_Cobble_Half",
      "rotation": 7
    },
    {
      "x": -14,
      "y": 52,
      "z": -1,
      "name": "Rock_Shale_Cobble",
      "rotation": 17
    },
    {
      "x": -14,
      "y": 53,
      "z": -1,
      "name": "Rock_Shale_Cobble",
      "rotation": 17
    },
    {
      "x": -14,
      "y": 54,
      "z": -1,
      "name": "Rock_Shale_Cobble",
      "rotation": 17
    },
    {
      "x": -14,
      "y": 55,
      "z": -1,
      "name": "Rock_Shale_Cobble",
      "rotation": 17
    },
    {
      "x": -14,
      "y": 56,
      "z": -1,
      "name": "Rock_Shale_Cobble",
      "rotation": 17
    },
    {
      "x": -14,
      "y": 57,
      "z": -1,
      "name": "Rock_Shale_Cobble",
      "rotation": 17
    },
    {
      "x": -14,
      "y": 58,
      "z": -1,
      "name": "Rock_Shale_Cobble",
      "rotation": 17
    },
    {
      "x": -14,
      "y": 59,
      "z": -1,
      "name": "Rock_Shale_Cobble",
      "rotation": 17
    },
    {
      "x": -14,
      "y": 60,
      "z": -1,
      "name": "Rock_Shale_Cobble",
      "rotation": 6
    },
    {
      "x": -14,
      "y": 61,
      "z": -1,
      "name": "Rock_Shale_Cobble",
      "rotation": 6
    },
    {
      "x": -14,
      "y": 62,
      "z": -1,
      "name": "Rock_Shale_Cobble",
      "rotation": 6
    },
    {
      "x": -14,
      "y": 63,
      "z": -1,
      "name": "Rock_Shale_Cobble",
      "rotation": 6
    },
    {
      "x": -14,
      "y": 64,
      "z": -1,
      "name": "Rock_Shale_Cobble",
      "rotation": 6
    },
    {
      "x": -14,
      "y": 65,
      "z": -1,
      "name": "Rock_Shale_Cobble",
      "rotation": 4
    },
    {
      "x": -14,
      "y": 66,
      "z": -1,
      "name": "Rock_Shale_Cobble",
      "rotation": 4
    },
    {
      "x": -14,
      "y": 67,
      "z": -1,
      "name": "Rock_Shale_Cobble",
      "rotation": 4
    },
    {
      "x": -14,
      "y": 68,
      "z": -1,
      "name": "Rock_Shale_Cobble",
      "rotation": 4
    },
    {
      "x": -14,
      "y": 69,
      "z": -1,
      "name": "Rock_Shale_Cobble",
      "rotation": 4
    },
    {
      "x": -14,
      "y": 70,
      "z": -1,
      "name": "Rock_Shale_Cobble",
      "rotation": 4
    },
    {
      "x": -14,
      "y": 71,
      "z": -1,
      "name": "Rock_Shale_Cobble",
      "rotation": 4
    },
    {
      "x": -14,
      "y": 72,
      "z": -1,
      "name": "Rock_Shale_Cobble",
      "rotation": 4
    },
    {
      "x": -14,
      "y": 73,
      "z": -1,
      "name": "Rock_Shale_Cobble_Half",
      "rotation": 7
    },
    {
      "x": -14,
      "y": 52,
      "z": 0,
      "name": "Rock_Shale_Cobble",
      "rotation": 17
    },
    {
      "x": -14,
      "y": 53,
      "z": 0,
      "name": "Rock_Shale_Cobble",
      "rotation": 17
    },
    {
      "x": -14,
      "y": 54,
      "z": 0,
      "name": "Rock_Shale_Cobble",
      "rotation": 17
    },
    {
      "x": -14,
      "y": 55,
      "z": 0,
      "name": "Rock_Shale_Cobble",
      "rotation": 17
    },
    {
      "x": -14,
      "y": 56,
      "z": 0,
      "name": "Rock_Shale_Cobble",
      "rotation": 17
    },
    {
      "x": -14,
      "y": 57,
      "z": 0,
      "name": "Rock_Shale_Cobble",
      "rotation": 17
    },
    {
      "x": -14,
      "y": 58,
      "z": 0,
      "name": "Rock_Shale_Cobble",
      "rotation": 1
    },
    {
      "x": -14,
      "y": 59,
      "z": 0,
      "name": "Build_Lightsource_Cyan",
      "rotation": 5
    },
    {
      "x": -14,
      "y": 60,
      "z": 0,
      "name": "Build_Lightsource_Cyan",
      "rotation": 5
    },
    {
      "x": -14,
      "y": 61,
      "z": 0,
      "name": "Build_Lightsource_Cyan",
      "rotation": 1
    },
    {
      "x": -14,
      "y": 62,
      "z": 0,
      "name": "Build_Lightsource_Cyan",
      "rotation": 5
    },
    {
      "x": -14,
      "y": 63,
      "z": 0,
      "name": "Build_Lightsource_Cyan",
      "rotation": 5
    },
    {
      "x": -14,
      "y": 64,
      "z": 0,
      "name": "Build_Lightsource_Cyan",
      "rotation": 3
    },
    {
      "x": -14,
      "y": 65,
      "z": 0,
      "name": "Build_Lightsource_Cyan",
      "rotation": 5
    },
    {
      "x": -14,
      "y": 66,
      "z": 0,
      "name": "Rock_Shale_Cobble",
      "rotation": 4
    },
    {
      "x": -14,
      "y": 67,
      "z": 0,
      "name": "Rock_Shale_Cobble",
      "rotation": 4
    },
    {
      "x": -14,
      "y": 68,
      "z": 0,
      "name": "Rock_Shale_Cobble",
      "rotation": 4
    },
    {
      "x": -14,
      "y": 69,
      "z": 0,
      "name": "Rock_Shale_Cobble",
      "rotation": 4
    },
    {
      "x": -14,
      "y": 70,
      "z": 0,
      "name": "Rock_Shale_Cobble",
      "rotation": 4
    },
    {
      "x": -14,
      "y": 71,
      "z": 0,
      "name": "Rock_Shale_Cobble",
      "rotation": 4
    },
    {
      "x": -14,
      "y": 72,
      "z": 0,
      "name": "Rock_Shale_Cobble",
      "rotation": 4
    },
    {
      "x": -14,
      "y": 52,
      "z": 1,
      "name": "Rock_Shale_Cobble",
      "rotation": 17
    },
    {
      "x": -14,
      "y": 53,
      "z": 1,
      "name": "Rock_Shale_Cobble",
      "rotation": 17
    },
    {
      "x": -14,
      "y": 54,
      "z": 1,
      "name": "Rock_Shale_Cobble",
      "rotation": 17
    },
    {
      "x": -14,
      "y": 55,
      "z": 1,
      "name": "Rock_Shale_Cobble",
      "rotation": 17
    },
    {
      "x": -14,
      "y": 56,
      "z": 1,
      "name": "Rock_Shale_Cobble",
      "rotation": 17
    },
    {
      "x": -14,
      "y": 57,
      "z": 1,
      "name": "Rock_Shale_Cobble",
      "rotation": 17
    },
    {
      "x": -14,
      "y": 58,
      "z": 1,
      "name": "Rock_Shale_Cobble",
      "rotation": 1
    },
    {
      "x": -14,
      "y": 59,
      "z": 1,
      "name": "Build_Lightsource_Cyan",
      "rotation": 5
    },
    {
      "x": -14,
      "y": 60,
      "z": 1,
      "name": "Build_Lightsource_Cyan",
      "rotation": 5
    },
    {
      "x": -14,
      "y": 61,
      "z": 1,
      "name": "Build_Lightsource_Cyan",
      "rotation": 1
    },
    {
      "x": -14,
      "y": 62,
      "z": 1,
      "name": "Build_Lightsource_Cyan",
      "rotation": 5
    },
    {
      "x": -14,
      "y": 63,
      "z": 1,
      "name": "Build_Lightsource_Cyan",
      "rotation": 5
    },
    {
      "x": -14,
      "y": 64,
      "z": 1,
      "name": "Build_Lightsource_Cyan",
      "rotation": 3
    },
    {
      "x": -14,
      "y": 65,
      "z": 1,
      "name": "Build_Lightsource_Cyan",
      "rotation": 19
    },
    {
      "x": -14,
      "y": 66,
      "z": 1,
      "name": "Rock_Shale_Cobble",
      "rotation": 4
    },
    {
      "x": -14,
      "y": 67,
      "z": 1,
      "name": "Rock_Shale_Cobble",
      "rotation": 4
    },
    {
      "x": -14,
      "y": 68,
      "z": 1,
      "name": "Rock_Shale_Cobble",
      "rotation": 4
    },
    {
      "x": -14,
      "y": 69,
      "z": 1,
      "name": "Rock_Shale_Cobble",
      "rotation": 4
    },
    {
      "x": -14,
      "y": 70,
      "z": 1,
      "name": "Rock_Shale_Cobble",
      "rotation": 4
    },
    {
      "x": -14,
      "y": 71,
      "z": 1,
      "name": "Rock_Shale_Cobble",
      "rotation": 4
    },
    {
      "x": -14,
      "y": 72,
      "z": 1,
      "name": "Rock_Shale_Cobble",
      "rotation": 4
    },
    {
      "x": -14,
      "y": 51,
      "z": 2,
      "name": "Rock_Shale_Cobble_Half",
      "rotation": 7
    },
    {
      "x": -14,
      "y": 52,
      "z": 2,
      "name": "Rock_Shale_Cobble",
      "rotation": 17
    },
    {
      "x": -14,
      "y": 53,
      "z": 2,
      "name": "Rock_Shale_Cobble",
      "rotation": 17
    },
    {
      "x": -14,
      "y": 54,
      "z": 2,
      "name": "Rock_Shale_Cobble",
      "rotation": 17
    },
    {
      "x": -14,
      "y": 55,
      "z": 2,
      "name": "Rock_Shale_Cobble",
      "rotation": 17
    },
    {
      "x": -14,
      "y": 56,
      "z": 2,
      "name": "Rock_Shale_Cobble",
      "rotation": 17
    },
    {
      "x": -14,
      "y": 57,
      "z": 2,
      "name": "Rock_Shale_Cobble",
      "rotation": 17
    },
    {
      "x": -14,
      "y": 58,
      "z": 2,
      "name": "Rock_Shale_Cobble",
      "rotation": 17
    },
    {
      "x": -14,
      "y": 59,
      "z": 2,
      "name": "Rock_Shale_Cobble",
      "rotation": 17
    },
    {
      "x": -14,
      "y": 60,
      "z": 2,
      "name": "Rock_Shale_Cobble",
      "rotation": 6
    },
    {
      "x": -14,
      "y": 61,
      "z": 2,
      "name": "Rock_Shale_Cobble",
      "rotation": 6
    },
    {
      "x": -14,
      "y": 62,
      "z": 2,
      "name": "Rock_Shale_Cobble",
      "rotation": 6
    },
    {
      "x": -14,
      "y": 63,
      "z": 2,
      "name": "Rock_Shale_Cobble",
      "rotation": 6
    },
    {
      "x": -14,
      "y": 64,
      "z": 2,
      "name": "Build_Lightsource_Cyan",
      "rotation": 5
    },
    {
      "x": -14,
      "y": 65,
      "z": 2,
      "name": "Rock_Shale_Cobble",
      "rotation": 1
    },
    {
      "x": -14,
      "y": 66,
      "z": 2,
      "name": "Rock_Shale_Cobble",
      "rotation": 4
    },
    {
      "x": -14,
      "y": 67,
      "z": 2,
      "name": "Rock_Shale_Cobble",
      "rotation": 4
    },
    {
      "x": -14,
      "y": 68,
      "z": 2,
      "name": "Rock_Shale_Cobble",
      "rotation": 4
    },
    {
      "x": -14,
      "y": 69,
      "z": 2,
      "name": "Rock_Shale_Cobble",
      "rotation": 4
    },
    {
      "x": -14,
      "y": 70,
      "z": 2,
      "name": "Rock_Shale_Cobble",
      "rotation": 4
    },
    {
      "x": -14,
      "y": 71,
      "z": 2,
      "name": "Rock_Shale_Cobble",
      "rotation": 4
    },
    {
      "x": -14,
      "y": 72,
      "z": 2,
      "name": "Rock_Shale_Cobble",
      "rotation": 4
    },
    {
      "x": -14,
      "y": 73,
      "z": 2,
      "name": "Rock_Shale_Cobble_Half",
      "rotation": 7
    },
    {
      "x": -14,
      "y": 52,
      "z": 3,
      "name": "Rock_Shale_Cobble",
      "rotation": 17
    },
    {
      "x": -14,
      "y": 53,
      "z": 3,
      "name": "Rock_Shale_Cobble",
      "rotation": 17
    },
    {
      "x": -14,
      "y": 54,
      "z": 3,
      "name": "Rock_Shale_Cobble",
      "rotation": 17
    },
    {
      "x": -14,
      "y": 55,
      "z": 3,
      "name": "Rock_Shale_Cobble",
      "rotation": 17
    },
    {
      "x": -14,
      "y": 56,
      "z": 3,
      "name": "Rock_Shale_Cobble",
      "rotation": 17
    },
    {
      "x": -14,
      "y": 57,
      "z": 3,
      "name": "Rock_Shale_Cobble",
      "rotation": 17
    },
    {
      "x": -14,
      "y": 58,
      "z": 3,
      "name": "Rock_Shale_Cobble",
      "rotation": 17
    },
    {
      "x": -14,
      "y": 59,
      "z": 3,
      "name": "Rock_Shale_Cobble",
      "rotation": 17
    },
    {
      "x": -14,
      "y": 60,
      "z": 3,
      "name": "Rock_Shale_Cobble",
      "rotation": 6
    },
    {
      "x": -14,
      "y": 61,
      "z": 3,
      "name": "Rock_Shale_Cobble",
      "rotation": 6
    },
    {
      "x": -14,
      "y": 62,
      "z": 3,
      "name": "Build_Lightsource_Cyan",
      "rotation": 17
    },
    {
      "x": -14,
      "y": 63,
      "z": 3,
      "name": "Rock_Shale_Cobble",
      "rotation": 6
    },
    {
      "x": -14,
      "y": 64,
      "z": 3,
      "name": "Rock_Shale_Cobble",
      "rotation": 6
    },
    {
      "x": -14,
      "y": 65,
      "z": 3,
      "name": "Rock_Shale_Cobble",
      "rotation": 4
    },
    {
      "x": -14,
      "y": 66,
      "z": 3,
      "name": "Rock_Shale_Cobble",
      "rotation": 4
    },
    {
      "x": -14,
      "y": 67,
      "z": 3,
      "name": "Rock_Shale_Cobble",
      "rotation": 4
    },
    {
      "x": -14,
      "y": 68,
      "z": 3,
      "name": "Rock_Shale_Cobble",
      "rotation": 4
    },
    {
      "x": -14,
      "y": 69,
      "z": 3,
      "name": "Rock_Shale_Cobble",
      "rotation": 4
    },
    {
      "x": -14,
      "y": 70,
      "z": 3,
      "name": "Rock_Shale_Cobble",
      "rotation": 4
    },
    {
      "x": -14,
      "y": 71,
      "z": 3,
      "name": "Rock_Shale_Cobble",
      "rotation": 4
    },
    {
      "x": -14,
      "y": 72,
      "z": 3,
      "name": "Rock_Shale_Cobble",
      "rotation": 4
    },
    {
      "x": -14,
      "y": 60,
      "z": 4,
      "name": "Rock_Shale_Cobble",
      "rotation": 7
    },
    {
      "x": -14,
      "y": 61,
      "z": 4,
      "name": "Rock_Shale_Cobble",
      "rotation": 7
    },
    {
      "x": -14,
      "y": 62,
      "z": 4,
      "name": "Build_Lightsource_Cyan",
      "rotation": 17
    },
    {
      "x": -14,
      "y": 63,
      "z": 4,
      "name": "Rock_Shale_Cobble",
      "rotation": 7
    },
    {
      "x": -14,
      "y": 64,
      "z": 4,
      "name": "Rock_Shale_Cobble",
      "rotation": 7
    },
    {
      "x": -14,
      "y": 60,
      "z": 5,
      "name": "Rock_Shale_Brick_Smooth",
      "rotation": 1
    },
    {
      "x": -14,
      "y": 64,
      "z": 5,
      "name": "Rock_Shale_Brick_Smooth",
      "rotation": 1
    },
    {
      "x": -13,
      "y": 60,
      "z": -3,
      "name": "Rock_Shale_Brick_Smooth",
      "rotation": 1
    },
    {
      "x": -13,
      "y": 64,
      "z": -3,
      "name": "Rock_Shale_Brick_Smooth",
      "rotation": 1
    },
    {
      "x": -13,
      "y": 51,
      "z": -2,
      "name": "Rock_Shale_Cobble",
      "rotation": 17
    },
    {
      "x": -13,
      "y": 52,
      "z": -2,
      "name": "Rock_Shale_Cobble",
      "rotation": 17
    },
    {
      "x": -13,
      "y": 53,
      "z": -2,
      "name": "Rock_Shale_Cobble",
      "rotation": 17
    },
    {
      "x": -13,
      "y": 54,
      "z": -2,
      "name": "Rock_Shale_Cobble",
      "rotation": 17
    },
    {
      "x": -13,
      "y": 55,
      "z": -2,
      "name": "Rock_Shale_Cobble",
      "rotation": 17
    },
    {
      "x": -13,
      "y": 56,
      "z": -2,
      "name": "Rock_Shale_Cobble",
      "rotation": 17
    },
    {
      "x": -13,
      "y": 57,
      "z": -2,
      "name": "Rock_Shale_Cobble",
      "rotation": 17
    },
    {
      "x": -13,
      "y": 58,
      "z": -2,
      "name": "Rock_Shale_Cobble",
      "rotation": 1
    },
    {
      "x": -13,
      "y": 60,
      "z": -2,
      "name": "Rock_Shale_Cobble",
      "rotation": 7
    },
    {
      "x": -13,
      "y": 61,
      "z": -2,
      "name": "Rock_Shale_Cobble",
      "rotation": 1
    },
    {
      "x": -13,
      "y": 63,
      "z": -2,
      "name": "Rock_Shale_Cobble",
      "rotation": 1
    },
    {
      "x": -13,
      "y": 64,
      "z": -2,
      "name": "Rock_Shale_Cobble",
      "rotation": 7
    },
    {
      "x": -13,
      "y": 66,
      "z": -2,
      "name": "Rock_Shale_Cobble",
      "rotation": 4
    },
    {
      "x": -13,
      "y": 67,
      "z": -2,
      "name": "Rock_Shale_Cobble",
      "rotation": 4
    },
    {
      "x": -13,
      "y": 68,
      "z": -2,
      "name": "Rock_Shale_Cobble",
      "rotation": 4
    },
    {
      "x": -13,
      "y": 69,
      "z": -2,
      "name": "Rock_Shale_Cobble",
      "rotation": 4
    },
    {
      "x": -13,
      "y": 70,
      "z": -2,
      "name": "Rock_Shale_Cobble",
      "rotation": 4
    },
    {
      "x": -13,
      "y": 71,
      "z": -2,
      "name": "Rock_Shale_Cobble",
      "rotation": 4
    },
    {
      "x": -13,
      "y": 72,
      "z": -2,
      "name": "Rock_Shale_Cobble",
      "rotation": 4
    },
    {
      "x": -13,
      "y": 73,
      "z": -2,
      "name": "Rock_Shale_Cobble",
      "rotation": 4
    },
    {
      "x": -13,
      "y": 50,
      "z": -1,
      "name": "Rock_Shale_Cobble_Half",
      "rotation": 7
    },
    {
      "x": -13,
      "y": 51,
      "z": -1,
      "name": "Rock_Shale_Cobble",
      "rotation": 17
    },
    {
      "x": -13,
      "y": 52,
      "z": -1,
      "name": "Rock_Shale_Cobble",
      "rotation": 17
    },
    {
      "x": -13,
      "y": 53,
      "z": -1,
      "name": "Rock_Shale_Cobble",
      "rotation": 17
    },
    {
      "x": -13,
      "y": 54,
      "z": -1,
      "name": "Rock_Shale_Cobble",
      "rotation": 17
    },
    {
      "x": -13,
      "y": 55,
      "z": -1,
      "name": "Rock_Shale_Cobble",
      "rotation": 17
    },
    {
      "x": -13,
      "y": 56,
      "z": -1,
      "name": "Rock_Shale_Cobble",
      "rotation": 17
    },
    {
      "x": -13,
      "y": 57,
      "z": -1,
      "name": "Rock_Shale_Cobble",
      "rotation": 17
    },
    {
      "x": -13,
      "y": 58,
      "z": -1,
      "name": "Rock_Shale_Cobble",
      "rotation": 17
    },
    {
      "x": -13,
      "y": 59,
      "z": -1,
      "name": "Rock_Shale_Brick_Smooth",
      "rotation": 1
    },
    {
      "x": -13,
      "y": 60,
      "z": -1,
      "name": "Rock_Shale_Cobble",
      "rotation": 6
    },
    {
      "x": -13,
      "y": 61,
      "z": -1,
      "name": "Rock_Shale_Brick_Smooth",
      "rotation": 1
    },
    {
      "x": -13,
      "y": 62,
      "z": -1,
      "name": "Rock_Shale_Brick_Smooth",
      "rotation": 1
    },
    {
      "x": -13,
      "y": 63,
      "z": -1,
      "name": "Rock_Shale_Brick_Smooth",
      "rotation": 1
    },
    {
      "x": -13,
      "y": 64,
      "z": -1,
      "name": "Rock_Shale_Cobble",
      "rotation": 7
    },
    {
      "x": -13,
      "y": 65,
      "z": -1,
      "name": "Rock_Shale_Brick_Smooth",
      "rotation": 1
    },
    {
      "x": -13,
      "y": 66,
      "z": -1,
      "name": "Rock_Shale_Cobble",
      "rotation": 4
    },
    {
      "x": -13,
      "y": 67,
      "z": -1,
      "name": "Rock_Shale_Cobble",
      "rotation": 4
    },
    {
      "x": -13,
      "y": 68,
      "z": -1,
      "name": "Rock_Shale_Cobble",
      "rotation": 4
    },
    {
      "x": -13,
      "y": 69,
      "z": -1,
      "name": "Rock_Shale_Cobble",
      "rotation": 4
    },
    {
      "x": -13,
      "y": 70,
      "z": -1,
      "name": "Rock_Shale_Cobble",
      "rotation": 4
    },
    {
      "x": -13,
      "y": 71,
      "z": -1,
      "name": "Rock_Shale_Cobble",
      "rotation": 4
    },
    {
      "x": -13,
      "y": 72,
      "z": -1,
      "name": "Rock_Shale_Cobble",
      "rotation": 4
    },
    {
      "x": -13,
      "y": 73,
      "z": -1,
      "name": "Rock_Shale_Cobble",
      "rotation": 4
    },
    {
      "x": -13,
      "y": 74,
      "z": -1,
      "name": "Rock_Shale_Cobble_Half",
      "rotation": 7
    },
    {
      "x": -13,
      "y": 51,
      "z": 0,
      "name": "Rock_Shale_Cobble",
      "rotation": 17
    },
    {
      "x": -13,
      "y": 52,
      "z": 0,
      "name": "Rock_Shale_Cobble",
      "rotation": 17
    },
    {
      "x": -13,
      "y": 53,
      "z": 0,
      "name": "Rock_Shale_Cobble",
      "rotation": 17
    },
    {
      "x": -13,
      "y": 54,
      "z": 0,
      "name": "Rock_Shale_Cobble",
      "rotation": 17
    },
    {
      "x": -13,
      "y": 55,
      "z": 0,
      "name": "Rock_Shale_Cobble",
      "rotation": 17
    },
    {
      "x": -13,
      "y": 56,
      "z": 0,
      "name": "Build_Lightsource_Cyan",
      "rotation": 5
    },
    {
      "x": -13,
      "y": 57,
      "z": 0,
      "name": "Build_Lightsource_Cyan",
      "rotation": 5
    },
    {
      "x": -13,
      "y": 58,
      "z": 0,
      "name": "Build_Lightsource_Cyan",
      "rotation": 5
    },
    {
      "x": -13,
      "y": 60,
      "z": 0,
      "name": "Rock_Shale_Cobble",
      "rotation": 6
    },
    {
      "x": -13,
      "y": 61,
      "z": 0,
      "name": "Rock_Shale_Cobble",
      "rotation": 1
    },
    {
      "x": -13,
      "y": 63,
      "z": 0,
      "name": "Rock_Shale_Cobble",
      "rotation": 1
    },
    {
      "x": -13,
      "y": 64,
      "z": 0,
      "name": "Rock_Shale_Cobble",
      "rotation": 6
    },
    {
      "x": -13,
      "y": 66,
      "z": 0,
      "name": "Build_Lightsource_Cyan",
      "rotation": 5
    },
    {
      "x": -13,
      "y": 67,
      "z": 0,
      "name": "Build_Lightsource_Cyan",
      "rotation": 5
    },
    {
      "x": -13,
      "y": 68,
      "z": 0,
      "name": "Build_Lightsource_Cyan",
      "rotation": 5
    },
    {
      "x": -13,
      "y": 69,
      "z": 0,
      "name": "Rock_Shale_Cobble",
      "rotation": 4
    },
    {
      "x": -13,
      "y": 70,
      "z": 0,
      "name": "Rock_Shale_Cobble",
      "rotation": 4
    },
    {
      "x": -13,
      "y": 71,
      "z": 0,
      "name": "Rock_Shale_Cobble",
      "rotation": 4
    },
    {
      "x": -13,
      "y": 72,
      "z": 0,
      "name": "Rock_Shale_Cobble",
      "rotation": 4
    },
    {
      "x": -13,
      "y": 73,
      "z": 0,
      "name": "Rock_Shale_Cobble",
      "rotation": 4
    },
    {
      "x": -13,
      "y": 51,
      "z": 1,
      "name": "Rock_Shale_Cobble",
      "rotation": 17
    },
    {
      "x": -13,
      "y": 52,
      "z": 1,
      "name": "Rock_Shale_Cobble",
      "rotation": 17
    },
    {
      "x": -13,
      "y": 53,
      "z": 1,
      "name": "Rock_Shale_Cobble",
      "rotation": 17
    },
    {
      "x": -13,
      "y": 54,
      "z": 1,
      "name": "Rock_Shale_Cobble",
      "rotation": 1
    },
    {
      "x": -13,
      "y": 55,
      "z": 1,
      "name": "Rock_Shale_Cobble",
      "rotation": 17
    },
    {
      "x": -13,
      "y": 56,
      "z": 1,
      "name": "Build_Lightsource_Cyan",
      "rotation": 5
    },
    {
      "x": -13,
      "y": 57,
      "z": 1,
      "name": "Build_Lightsource_Cyan",
      "rotation": 5
    },
    {
      "x": -13,
      "y": 58,
      "z": 1,
      "name": "Build_Lightsource_Cyan",
      "rotation": 5
    },
    {
      "x": -13,
      "y": 60,
      "z": 1,
      "name": "Rock_Shale_Cobble",
      "rotation": 6
    },
    {
      "x": -13,
      "y": 61,
      "z": 1,
      "name": "Rock_Shale_Cobble",
      "rotation": 1
    },
    {
      "x": -13,
      "y": 63,
      "z": 1,
      "name": "Rock_Shale_Cobble",
      "rotation": 1
    },
    {
      "x": -13,
      "y": 64,
      "z": 1,
      "name": "Rock_Shale_Cobble",
      "rotation": 1
    },
    {
      "x": -13,
      "y": 66,
      "z": 1,
      "name": "Build_Lightsource_Cyan",
      "rotation": 5
    },
    {
      "x": -13,
      "y": 67,
      "z": 1,
      "name": "Build_Lightsource_Cyan",
      "rotation": 19
    },
    {
      "x": -13,
      "y": 68,
      "z": 1,
      "name": "Build_Lightsource_Cyan",
      "rotation": 19
    },
    {
      "x": -13,
      "y": 69,
      "z": 1,
      "name": "Rock_Shale_Cobble",
      "rotation": 4
    },
    {
      "x": -13,
      "y": 70,
      "z": 1,
      "name": "Rock_Shale_Cobble",
      "rotation": 4
    },
    {
      "x": -13,
      "y": 71,
      "z": 1,
      "name": "Rock_Shale_Cobble",
      "rotation": 4
    },
    {
      "x": -13,
      "y": 72,
      "z": 1,
      "name": "Rock_Shale_Cobble",
      "rotation": 4
    },
    {
      "x": -13,
      "y": 73,
      "z": 1,
      "name": "Rock_Shale_Cobble",
      "rotation": 4
    },
    {
      "x": -13,
      "y": 50,
      "z": 2,
      "name": "Rock_Shale_Cobble_Half",
      "rotation": 7
    },
    {
      "x": -13,
      "y": 51,
      "z": 2,
      "name": "Rock_Shale_Cobble",
      "rotation": 17
    },
    {
      "x": -13,
      "y": 52,
      "z": 2,
      "name": "Rock_Shale_Cobble",
      "rotation": 17
    },
    {
      "x": -13,
      "y": 53,
      "z": 2,
      "name": "Rock_Shale_Cobble",
      "rotation": 17
    },
    {
      "x": -13,
      "y": 54,
      "z": 2,
      "name": "Rock_Shale_Cobble",
      "rotation": 17
    },
    {
      "x": -13,
      "y": 55,
      "z": 2,
      "name": "Rock_Shale_Cobble",
      "rotation": 17
    },
    {
      "x": -13,
      "y": 56,
      "z": 2,
      "name": "Rock_Shale_Cobble",
      "rotation": 17
    },
    {
      "x": -13,
      "y": 57,
      "z": 2,
      "name": "Rock_Shale_Cobble",
      "rotation": 17
    },
    {
      "x": -13,
      "y": 58,
      "z": 2,
      "name": "Rock_Shale_Cobble",
      "rotation": 17
    },
    {
      "x": -13,
      "y": 59,
      "z": 2,
      "name": "Rock_Shale_Brick_Smooth",
      "rotation": 1
    },
    {
      "x": -13,
      "y": 60,
      "z": 2,
      "name": "Rock_Shale_Cobble",
      "rotation": 6
    },
    {
      "x": -13,
      "y": 61,
      "z": 2,
      "name": "Rock_Shale_Brick_Smooth",
      "rotation": 1
    },
    {
      "x": -13,
      "y": 62,
      "z": 2,
      "name": "Rock_Shale_Brick_Smooth",
      "rotation": 1
    },
    {
      "x": -13,
      "y": 63,
      "z": 2,
      "name": "Rock_Shale_Brick_Smooth",
      "rotation": 1
    },
    {
      "x": -13,
      "y": 64,
      "z": 2,
      "name": "Rock_Shale_Cobble",
      "rotation": 1
    },
    {
      "x": -13,
      "y": 65,
      "z": 2,
      "name": "Rock_Shale_Brick_Smooth",
      "rotation": 1
    },
    {
      "x": -13,
      "y": 66,
      "z": 2,
      "name": "Rock_Shale_Cobble",
      "rotation": 1
    },
    {
      "x": -13,
      "y": 67,
      "z": 2,
      "name": "Rock_Shale_Cobble",
      "rotation": 4
    },
    {
      "x": -13,
      "y": 68,
      "z": 2,
      "name": "Rock_Shale_Cobble",
      "rotation": 4
    },
    {
      "x": -13,
      "y": 69,
      "z": 2,
      "name": "Rock_Shale_Cobble",
      "rotation": 4
    },
    {
      "x": -13,
      "y": 70,
      "z": 2,
      "name": "Rock_Shale_Cobble",
      "rotation": 4
    },
    {
      "x": -13,
      "y": 71,
      "z": 2,
      "name": "Rock_Shale_Cobble",
      "rotation": 4
    },
    {
      "x": -13,
      "y": 72,
      "z": 2,
      "name": "Rock_Shale_Cobble",
      "rotation": 4
    },
    {
      "x": -13,
      "y": 73,
      "z": 2,
      "name": "Rock_Shale_Cobble",
      "rotation": 4
    },
    {
      "x": -13,
      "y": 74,
      "z": 2,
      "name": "Rock_Shale_Cobble_Half",
      "rotation": 7
    },
    {
      "x": -13,
      "y": 51,
      "z": 3,
      "name": "Rock_Shale_Cobble",
      "rotation": 17
    },
    {
      "x": -13,
      "y": 52,
      "z": 3,
      "name": "Rock_Shale_Cobble",
      "rotation": 17
    },
    {
      "x": -13,
      "y": 53,
      "z": 3,
      "name": "Rock_Shale_Cobble",
      "rotation": 17
    },
    {
      "x": -13,
      "y": 54,
      "z": 3,
      "name": "Rock_Shale_Cobble",
      "rotation": 17
    },
    {
      "x": -13,
      "y": 55,
      "z": 3,
      "name": "Rock_Shale_Cobble",
      "rotation": 17
    },
    {
      "x": -13,
      "y": 56,
      "z": 3,
      "name": "Rock_Shale_Cobble",
      "rotation": 17
    },
    {
      "x": -13,
      "y": 57,
      "z": 3,
      "name": "Rock_Shale_Cobble",
      "rotation": 17
    },
    {
      "x": -13,
      "y": 58,
      "z": 3,
      "name": "Rock_Shale_Cobble",
      "rotation": 17
    },
    {
      "x": -13,
      "y": 60,
      "z": 3,
      "name": "Rock_Shale_Cobble",
      "rotation": 7
    },
    {
      "x": -13,
      "y": 61,
      "z": 3,
      "name": "Rock_Shale_Cobble",
      "rotation": 1
    },
    {
      "x": -13,
      "y": 63,
      "z": 3,
      "name": "Rock_Shale_Cobble",
      "rotation": 1
    },
    {
      "x": -13,
      "y": 64,
      "z": 3,
      "name": "Rock_Shale_Cobble",
      "rotation": 6
    },
    {
      "x": -13,
      "y": 66,
      "z": 3,
      "name": "Rock_Shale_Cobble",
      "rotation": 1
    },
    {
      "x": -13,
      "y": 67,
      "z": 3,
      "name": "Rock_Shale_Cobble",
      "rotation": 4
    },
    {
      "x": -13,
      "y": 68,
      "z": 3,
      "name": "Rock_Shale_Cobble",
      "rotation": 4
    },
    {
      "x": -13,
      "y": 69,
      "z": 3,
      "name": "Rock_Shale_Cobble",
      "rotation": 4
    },
    {
      "x": -13,
      "y": 70,
      "z": 3,
      "name": "Rock_Shale_Cobble",
      "rotation": 4
    },
    {
      "x": -13,
      "y": 71,
      "z": 3,
      "name": "Rock_Shale_Cobble",
      "rotation": 4
    },
    {
      "x": -13,
      "y": 72,
      "z": 3,
      "name": "Rock_Shale_Cobble",
      "rotation": 4
    },
    {
      "x": -13,
      "y": 73,
      "z": 3,
      "name": "Rock_Shale_Cobble",
      "rotation": 4
    },
    {
      "x": -13,
      "y": 60,
      "z": 4,
      "name": "Rock_Shale_Brick_Smooth",
      "rotation": 1
    },
    {
      "x": -13,
      "y": 64,
      "z": 4,
      "name": "Rock_Shale_Brick_Smooth",
      "rotation": 1
    },
    {
      "x": -12,
      "y": 50,
      "z": -2,
      "name": "Rock_Shale_Cobble",
      "rotation": 17
    },
    {
      "x": -12,
      "y": 51,
      "z": -2,
      "name": "Rock_Shale_Cobble",
      "rotation": 17
    },
    {
      "x": -12,
      "y": 52,
      "z": -2,
      "name": "Rock_Shale_Cobble",
      "rotation": 17
    },
    {
      "x": -12,
      "y": 53,
      "z": -2,
      "name": "Rock_Shale_Cobble",
      "rotation": 17
    },
    {
      "x": -12,
      "y": 54,
      "z": -2,
      "name": "Rock_Shale_Cobble",
      "rotation": 17
    },
    {
      "x": -12,
      "y": 55,
      "z": -2,
      "name": "Rock_Shale_Cobble",
      "rotation": 17
    },
    {
      "x": -12,
      "y": 60,
      "z": -2,
      "name": "Rock_Shale_Brick_Smooth",
      "rotation": 1
    },
    {
      "x": -12,
      "y": 64,
      "z": -2,
      "name": "Rock_Shale_Brick_Smooth",
      "rotation": 1
    },
    {
      "x": -12,
      "y": 69,
      "z": -2,
      "name": "Rock_Shale_Cobble",
      "rotation": 4
    },
    {
      "x": -12,
      "y": 70,
      "z": -2,
      "name": "Rock_Shale_Cobble",
      "rotation": 4
    },
    {
      "x": -12,
      "y": 71,
      "z": -2,
      "name": "Rock_Shale_Cobble",
      "rotation": 4
    },
    {
      "x": -12,
      "y": 72,
      "z": -2,
      "name": "Rock_Shale_Cobble",
      "rotation": 4
    },
    {
      "x": -12,
      "y": 73,
      "z": -2,
      "name": "Rock_Shale_Cobble",
      "rotation": 4
    },
    {
      "x": -12,
      "y": 74,
      "z": -2,
      "name": "Rock_Shale_Cobble",
      "rotation": 4
    },
    {
      "x": -12,
      "y": 49,
      "z": -1,
      "name": "Rock_Shale_Cobble_Half",
      "rotation": 9
    },
    {
      "x": -12,
      "y": 50,
      "z": -1,
      "name": "Rock_Shale_Cobble",
      "rotation": 17
    },
    {
      "x": -12,
      "y": 51,
      "z": -1,
      "name": "Rock_Shale_Cobble",
      "rotation": 17
    },
    {
      "x": -12,
      "y": 52,
      "z": -1,
      "name": "Rock_Shale_Cobble",
      "rotation": 17
    },
    {
      "x": -12,
      "y": 53,
      "z": -1,
      "name": "Rock_Shale_Cobble",
      "rotation": 17
    },
    {
      "x": -12,
      "y": 54,
      "z": -1,
      "name": "Rock_Shale_Cobble",
      "rotation": 17
    },
    {
      "x": -12,
      "y": 55,
      "z": -1,
      "name": "Rock_Shale_Cobble",
      "rotation": 17
    },
    {
      "x": -12,
      "y": 56,
      "z": -1,
      "name": "Rock_Shale_Brick_Smooth",
      "rotation": 1
    },
    {
      "x": -12,
      "y": 57,
      "z": -1,
      "name": "Rock_Shale_Brick_Smooth",
      "rotation": 1
    },
    {
      "x": -12,
      "y": 58,
      "z": -1,
      "name": "Rock_Shale_Brick_Smooth",
      "rotation": 1
    },
    {
      "x": -12,
      "y": 60,
      "z": -1,
      "name": "Rock_Shale_Brick_Smooth",
      "rotation": 1
    },
    {
      "x": -12,
      "y": 64,
      "z": -1,
      "name": "Rock_Shale_Brick_Smooth",
      "rotation": 1
    },
    {
      "x": -12,
      "y": 66,
      "z": -1,
      "name": "Rock_Shale_Brick_Smooth",
      "rotation": 1
    },
    {
      "x": -12,
      "y": 67,
      "z": -1,
      "name": "Rock_Shale_Brick_Smooth",
      "rotation": 1
    },
    {
      "x": -12,
      "y": 68,
      "z": -1,
      "name": "Rock_Shale_Brick_Smooth",
      "rotation": 1
    },
    {
      "x": -12,
      "y": 69,
      "z": -1,
      "name": "Rock_Shale_Cobble",
      "rotation": 4
    },
    {
      "x": -12,
      "y": 70,
      "z": -1,
      "name": "Rock_Shale_Cobble",
      "rotation": 4
    },
    {
      "x": -12,
      "y": 71,
      "z": -1,
      "name": "Rock_Shale_Cobble",
      "rotation": 4
    },
    {
      "x": -12,
      "y": 72,
      "z": -1,
      "name": "Rock_Shale_Cobble",
      "rotation": 4
    },
    {
      "x": -12,
      "y": 73,
      "z": -1,
      "name": "Rock_Shale_Cobble",
      "rotation": 4
    },
    {
      "x": -12,
      "y": 74,
      "z": -1,
      "name": "Rock_Shale_Cobble",
      "rotation": 4
    },
    {
      "x": -12,
      "y": 75,
      "z": -1,
      "name": "Rock_Shale_Cobble_Half",
      "rotation": 1
    },
    {
      "x": -12,
      "y": 50,
      "z": 0,
      "name": "Rock_Shale_Cobble",
      "rotation": 17
    },
    {
      "x": -12,
      "y": 51,
      "z": 0,
      "name": "Rock_Shale_Cobble",
      "rotation": 17
    },
    {
      "x": -12,
      "y": 52,
      "z": 0,
      "name": "Rock_Shale_Cobble",
      "rotation": 17
    },
    {
      "x": -12,
      "y": 53,
      "z": 0,
      "name": "Rock_Shale_Cobble",
      "rotation": 17
    },
    {
      "x": -12,
      "y": 54,
      "z": 0,
      "name": "Build_Lightsource_Cyan",
      "rotation": 1
    },
    {
      "x": -12,
      "y": 55,
      "z": 0,
      "name": "Build_Lightsource_Cyan",
      "rotation": 1
    },
    {
      "x": -12,
      "y": 60,
      "z": 0,
      "name": "Rock_Shale_Brick_Smooth",
      "rotation": 1
    },
    {
      "x": -12,
      "y": 64,
      "z": 0,
      "name": "Rock_Shale_Brick_Smooth",
      "rotation": 1
    },
    {
      "x": -12,
      "y": 69,
      "z": 0,
      "name": "Build_Lightsource_Cyan",
      "rotation": 9
    },
    {
      "x": -12,
      "y": 70,
      "z": 0,
      "name": "Build_Lightsource_Cyan",
      "rotation": 9
    },
    {
      "x": -12,
      "y": 71,
      "z": 0,
      "name": "Rock_Shale_Cobble",
      "rotation": 4
    },
    {
      "x": -12,
      "y": 72,
      "z": 0,
      "name": "Rock_Shale_Cobble",
      "rotation": 4
    },
    {
      "x": -12,
      "y": 73,
      "z": 0,
      "name": "Rock_Shale_Cobble",
      "rotation": 4
    },
    {
      "x": -12,
      "y": 74,
      "z": 0,
      "name": "Rock_Shale_Cobble",
      "rotation": 4
    },
    {
      "x": -12,
      "y": 50,
      "z": 1,
      "name": "Rock_Shale_Cobble",
      "rotation": 17
    },
    {
      "x": -12,
      "y": 51,
      "z": 1,
      "name": "Rock_Shale_Cobble",
      "rotation": 17
    },
    {
      "x": -12,
      "y": 52,
      "z": 1,
      "name": "Rock_Shale_Cobble",
      "rotation": 17
    },
    {
      "x": -12,
      "y": 53,
      "z": 1,
      "name": "Rock_Shale_Cobble",
      "rotation": 17
    },
    {
      "x": -12,
      "y": 54,
      "z": 1,
      "name": "Build_Lightsource_Cyan",
      "rotation": 1
    },
    {
      "x": -12,
      "y": 55,
      "z": 1,
      "name": "Build_Lightsource_Cyan",
      "rotation": 1
    },
    {
      "x": -12,
      "y": 60,
      "z": 1,
      "name": "Rock_Shale_Brick_Smooth",
      "rotation": 1
    },
    {
      "x": -12,
      "y": 64,
      "z": 1,
      "name": "Rock_Shale_Brick_Smooth",
      "rotation": 1
    },
    {
      "x": -12,
      "y": 69,
      "z": 1,
      "name": "Build_Lightsource_Cyan",
      "rotation": 9
    },
    {
      "x": -12,
      "y": 70,
      "z": 1,
      "name": "Build_Lightsource_Cyan",
      "rotation": 5
    },
    {
      "x": -12,
      "y": 71,
      "z": 1,
      "name": "Rock_Shale_Cobble",
      "rotation": 4
    },
    {
      "x": -12,
      "y": 72,
      "z": 1,
      "name": "Rock_Shale_Cobble",
      "rotation": 4
    },
    {
      "x": -12,
      "y": 73,
      "z": 1,
      "name": "Rock_Shale_Cobble",
      "rotation": 4
    },
    {
      "x": -12,
      "y": 74,
      "z": 1,
      "name": "Rock_Shale_Cobble",
      "rotation": 4
    },
    {
      "x": -12,
      "y": 49,
      "z": 2,
      "name": "Rock_Shale_Cobble_Half",
      "rotation": 9
    },
    {
      "x": -12,
      "y": 50,
      "z": 2,
      "name": "Rock_Shale_Cobble",
      "rotation": 17
    },
    {
      "x": -12,
      "y": 51,
      "z": 2,
      "name": "Rock_Shale_Cobble",
      "rotation": 17
    },
    {
      "x": -12,
      "y": 52,
      "z": 2,
      "name": "Rock_Shale_Cobble",
      "rotation": 17
    },
    {
      "x": -12,
      "y": 53,
      "z": 2,
      "name": "Rock_Shale_Cobble",
      "rotation": 17
    },
    {
      "x": -12,
      "y": 54,
      "z": 2,
      "name": "Rock_Shale_Cobble",
      "rotation": 17
    },
    {
      "x": -12,
      "y": 55,
      "z": 2,
      "name": "Rock_Shale_Cobble",
      "rotation": 1
    },
    {
      "x": -12,
      "y": 56,
      "z": 2,
      "name": "Rock_Shale_Brick_Smooth",
      "rotation": 1
    },
    {
      "x": -12,
      "y": 57,
      "z": 2,
      "name": "Rock_Shale_Brick_Smooth",
      "rotation": 1
    },
    {
      "x": -12,
      "y": 58,
      "z": 2,
      "name": "Rock_Shale_Brick_Smooth",
      "rotation": 1
    },
    {
      "x": -12,
      "y": 60,
      "z": 2,
      "name": "Rock_Shale_Brick_Smooth",
      "rotation": 1
    },
    {
      "x": -12,
      "y": 64,
      "z": 2,
      "name": "Rock_Shale_Brick_Smooth",
      "rotation": 1
    },
    {
      "x": -12,
      "y": 66,
      "z": 2,
      "name": "Rock_Shale_Brick_Smooth",
      "rotation": 1
    },
    {
      "x": -12,
      "y": 67,
      "z": 2,
      "name": "Rock_Shale_Brick_Smooth",
      "rotation": 1
    },
    {
      "x": -12,
      "y": 68,
      "z": 2,
      "name": "Rock_Shale_Brick_Smooth",
      "rotation": 1
    },
    {
      "x": -12,
      "y": 69,
      "z": 2,
      "name": "Rock_Shale_Cobble",
      "rotation": 4
    },
    {
      "x": -12,
      "y": 70,
      "z": 2,
      "name": "Rock_Shale_Cobble",
      "rotation": 4
    },
    {
      "x": -12,
      "y": 71,
      "z": 2,
      "name": "Rock_Shale_Cobble",
      "rotation": 4
    },
    {
      "x": -12,
      "y": 72,
      "z": 2,
      "name": "Rock_Shale_Cobble",
      "rotation": 4
    },
    {
      "x": -12,
      "y": 73,
      "z": 2,
      "name": "Rock_Shale_Cobble",
      "rotation": 4
    },
    {
      "x": -12,
      "y": 74,
      "z": 2,
      "name": "Rock_Shale_Cobble",
      "rotation": 4
    },
    {
      "x": -12,
      "y": 75,
      "z": 2,
      "name": "Rock_Shale_Cobble_Half",
      "rotation": 1
    },
    {
      "x": -12,
      "y": 50,
      "z": 3,
      "name": "Rock_Shale_Cobble",
      "rotation": 17
    },
    {
      "x": -12,
      "y": 51,
      "z": 3,
      "name": "Rock_Shale_Cobble",
      "rotation": 17
    },
    {
      "x": -12,
      "y": 52,
      "z": 3,
      "name": "Rock_Shale_Cobble",
      "rotation": 17
    },
    {
      "x": -12,
      "y": 53,
      "z": 3,
      "name": "Rock_Shale_Cobble",
      "rotation": 17
    },
    {
      "x": -12,
      "y": 54,
      "z": 3,
      "name": "Rock_Shale_Cobble",
      "rotation": 17
    },
    {
      "x": -12,
      "y": 55,
      "z": 3,
      "name": "Rock_Shale_Cobble",
      "rotation": 17
    },
    {
      "x": -12,
      "y": 60,
      "z": 3,
      "name": "Rock_Shale_Brick_Smooth",
      "rotation": 1
    },
    {
      "x": -12,
      "y": 64,
      "z": 3,
      "name": "Rock_Shale_Brick_Smooth",
      "rotation": 1
    },
    {
      "x": -12,
      "y": 69,
      "z": 3,
      "name": "Rock_Shale_Cobble",
      "rotation": 4
    },
    {
      "x": -12,
      "y": 70,
      "z": 3,
      "name": "Rock_Shale_Cobble",
      "rotation": 4
    },
    {
      "x": -12,
      "y": 71,
      "z": 3,
      "name": "Rock_Shale_Cobble",
      "rotation": 4
    },
    {
      "x": -12,
      "y": 72,
      "z": 3,
      "name": "Rock_Shale_Cobble",
      "rotation": 4
    },
    {
      "x": -12,
      "y": 73,
      "z": 3,
      "name": "Rock_Shale_Cobble",
      "rotation": 4
    },
    {
      "x": -12,
      "y": 74,
      "z": 3,
      "name": "Rock_Shale_Cobble",
      "rotation": 4
    },
    {
      "x": -11,
      "y": 49,
      "z": -2,
      "name": "Rock_Shale_Cobble",
      "rotation": 17
    },
    {
      "x": -11,
      "y": 50,
      "z": -2,
      "name": "Rock_Shale_Cobble",
      "rotation": 17
    },
    {
      "x": -11,
      "y": 51,
      "z": -2,
      "name": "Rock_Shale_Cobble",
      "rotation": 17
    },
    {
      "x": -11,
      "y": 52,
      "z": -2,
      "name": "Rock_Shale_Cobble",
      "rotation": 17
    },
    {
      "x": -11,
      "y": 53,
      "z": -2,
      "name": "Rock_Shale_Cobble",
      "rotation": 17
    },
    {
      "x": -11,
      "y": 71,
      "z": -2,
      "name": "Rock_Shale_Cobble",
      "rotation": 4
    },
    {
      "x": -11,
      "y": 72,
      "z": -2,
      "name": "Rock_Shale_Cobble",
      "rotation": 4
    },
    {
      "x": -11,
      "y": 73,
      "z": -2,
      "name": "Rock_Shale_Cobble",
      "rotation": 4
    },
    {
      "x": -11,
      "y": 74,
      "z": -2,
      "name": "Rock_Shale_Cobble",
      "rotation": 4
    },
    {
      "x": -11,
      "y": 75,
      "z": -2,
      "name": "Rock_Shale_Cobble",
      "rotation": 4
    },
    {
      "x": -11,
      "y": 48,
      "z": -1,
      "name": "Rock_Shale_Cobble_Half",
      "rotation": 9
    },
    {
      "x": -11,
      "y": 49,
      "z": -1,
      "name": "Rock_Shale_Cobble",
      "rotation": 17
    },
    {
      "x": -11,
      "y": 50,
      "z": -1,
      "name": "Rock_Shale_Cobble",
      "rotation": 17
    },
    {
      "x": -11,
      "y": 51,
      "z": -1,
      "name": "Rock_Shale_Cobble",
      "rotation": 17
    },
    {
      "x": -11,
      "y": 52,
      "z": -1,
      "name": "Rock_Shale_Cobble",
      "rotation": 17
    },
    {
      "x": -11,
      "y": 53,
      "z": -1,
      "name": "Rock_Shale_Cobble",
      "rotation": 17
    },
    {
      "x": -11,
      "y": 54,
      "z": -1,
      "name": "Rock_Shale_Brick_Smooth",
      "rotation": 1
    },
    {
      "x": -11,
      "y": 55,
      "z": -1,
      "name": "Rock_Shale_Brick_Smooth",
      "rotation": 1
    },
    {
      "x": -11,
      "y": 69,
      "z": -1,
      "name": "Rock_Shale_Brick_Smooth",
      "rotation": 1
    },
    {
      "x": -11,
      "y": 70,
      "z": -1,
      "name": "Rock_Shale_Brick_Smooth",
      "rotation": 1
    },
    {
      "x": -11,
      "y": 71,
      "z": -1,
      "name": "Rock_Shale_Cobble",
      "rotation": 4
    },
    {
      "x": -11,
      "y": 72,
      "z": -1,
      "name": "Rock_Shale_Cobble",
      "rotation": 4
    },
    {
      "x": -11,
      "y": 73,
      "z": -1,
      "name": "Rock_Shale_Cobble",
      "rotation": 4
    },
    {
      "x": -11,
      "y": 74,
      "z": -1,
      "name": "Rock_Shale_Cobble",
      "rotation": 4
    },
    {
      "x": -11,
      "y": 75,
      "z": -1,
      "name": "Rock_Shale_Cobble",
      "rotation": 4
    },
    {
      "x": -11,
      "y": 76,
      "z": -1,
      "name": "Rock_Shale_Cobble_Half",
      "rotation": 1
    },
    {
      "x": -11,
      "y": 49,
      "z": 0,
      "name": "Rock_Shale_Cobble",
      "rotation": 17
    },
    {
      "x": -11,
      "y": 50,
      "z": 0,
      "name": "Rock_Shale_Cobble",
      "rotation": 17
    },
    {
      "x": -11,
      "y": 51,
      "z": 0,
      "name": "Rock_Shale_Cobble",
      "rotation": 17
    },
    {
      "x": -11,
      "y": 52,
      "z": 0,
      "name": "Rock_Shale_Cobble",
      "rotation": 17
    },
    {
      "x": -11,
      "y": 53,
      "z": 0,
      "name": "Build_Lightsource_Cyan",
      "rotation": 1
    },
    {
      "x": -11,
      "y": 71,
      "z": 0,
      "name": "Build_Lightsource_Cyan",
      "rotation": 5
    },
    {
      "x": -11,
      "y": 72,
      "z": 0,
      "name": "Build_Lightsource_Cyan",
      "rotation": 9
    },
    {
      "x": -11,
      "y": 73,
      "z": 0,
      "name": "Rock_Shale_Cobble",
      "rotation": 4
    },
    {
      "x": -11,
      "y": 74,
      "z": 0,
      "name": "Rock_Shale_Cobble",
      "rotation": 4
    },
    {
      "x": -11,
      "y": 75,
      "z": 0,
      "name": "Rock_Shale_Cobble",
      "rotation": 4
    },
    {
      "x": -11,
      "y": 49,
      "z": 1,
      "name": "Rock_Shale_Cobble",
      "rotation": 17
    },
    {
      "x": -11,
      "y": 50,
      "z": 1,
      "name": "Rock_Shale_Cobble",
      "rotation": 17
    },
    {
      "x": -11,
      "y": 51,
      "z": 1,
      "name": "Rock_Shale_Cobble",
      "rotation": 17
    },
    {
      "x": -11,
      "y": 52,
      "z": 1,
      "name": "Rock_Shale_Cobble",
      "rotation": 1
    },
    {
      "x": -11,
      "y": 53,
      "z": 1,
      "name": "Build_Lightsource_Cyan",
      "rotation": 1
    },
    {
      "x": -11,
      "y": 71,
      "z": 1,
      "name": "Build_Lightsource_Cyan",
      "rotation": 9
    },
    {
      "x": -11,
      "y": 72,
      "z": 1,
      "name": "Rock_Shale_Cobble",
      "rotation": 4
    },
    {
      "x": -11,
      "y": 73,
      "z": 1,
      "name": "Rock_Shale_Cobble",
      "rotation": 4
    },
    {
      "x": -11,
      "y": 74,
      "z": 1,
      "name": "Rock_Shale_Cobble",
      "rotation": 4
    },
    {
      "x": -11,
      "y": 75,
      "z": 1,
      "name": "Rock_Shale_Cobble",
      "rotation": 4
    },
    {
      "x": -11,
      "y": 48,
      "z": 2,
      "name": "Rock_Shale_Cobble_Half",
      "rotation": 9
    },
    {
      "x": -11,
      "y": 49,
      "z": 2,
      "name": "Rock_Shale_Cobble",
      "rotation": 17
    },
    {
      "x": -11,
      "y": 50,
      "z": 2,
      "name": "Rock_Shale_Cobble",
      "rotation": 17
    },
    {
      "x": -11,
      "y": 51,
      "z": 2,
      "name": "Rock_Shale_Cobble",
      "rotation": 17
    },
    {
      "x": -11,
      "y": 52,
      "z": 2,
      "name": "Rock_Shale_Cobble",
      "rotation": 1
    },
    {
      "x": -11,
      "y": 53,
      "z": 2,
      "name": "Rock_Shale_Cobble",
      "rotation": 17
    },
    {
      "x": -11,
      "y": 54,
      "z": 2,
      "name": "Rock_Shale_Brick_Smooth",
      "rotation": 1
    },
    {
      "x": -11,
      "y": 55,
      "z": 2,
      "name": "Rock_Shale_Brick_Smooth",
      "rotation": 1
    },
    {
      "x": -11,
      "y": 69,
      "z": 2,
      "name": "Rock_Shale_Brick_Smooth",
      "rotation": 1
    },
    {
      "x": -11,
      "y": 70,
      "z": 2,
      "name": "Rock_Shale_Brick_Smooth",
      "rotation": 1
    },
    {
      "x": -11,
      "y": 71,
      "z": 2,
      "name": "Rock_Shale_Cobble",
      "rotation": 4
    },
    {
      "x": -11,
      "y": 72,
      "z": 2,
      "name": "Rock_Shale_Cobble",
      "rotation": 4
    },
    {
      "x": -11,
      "y": 73,
      "z": 2,
      "name": "Rock_Shale_Cobble",
      "rotation": 4
    },
    {
      "x": -11,
      "y": 74,
      "z": 2,
      "name": "Rock_Shale_Cobble",
      "rotation": 4
    },
    {
      "x": -11,
      "y": 75,
      "z": 2,
      "name": "Rock_Shale_Cobble",
      "rotation": 4
    },
    {
      "x": -11,
      "y": 76,
      "z": 2,
      "name": "Rock_Shale_Cobble_Half",
      "rotation": 1
    },
    {
      "x": -11,
      "y": 49,
      "z": 3,
      "name": "Rock_Shale_Cobble",
      "rotation": 17
    },
    {
      "x": -11,
      "y": 50,
      "z": 3,
      "name": "Rock_Shale_Cobble",
      "rotation": 17
    },
    {
      "x": -11,
      "y": 51,
      "z": 3,
      "name": "Rock_Shale_Cobble",
      "rotation": 17
    },
    {
      "x": -11,
      "y": 52,
      "z": 3,
      "name": "Rock_Shale_Cobble",
      "rotation": 1
    },
    {
      "x": -11,
      "y": 53,
      "z": 3,
      "name": "Rock_Shale_Cobble",
      "rotation": 1
    },
    {
      "x": -11,
      "y": 71,
      "z": 3,
      "name": "Rock_Shale_Cobble",
      "rotation": 4
    },
    {
      "x": -11,
      "y": 72,
      "z": 3,
      "name": "Rock_Shale_Cobble",
      "rotation": 4
    },
    {
      "x": -11,
      "y": 73,
      "z": 3,
      "name": "Rock_Shale_Cobble",
      "rotation": 4
    },
    {
      "x": -11,
      "y": 74,
      "z": 3,
      "name": "Rock_Shale_Cobble",
      "rotation": 4
    },
    {
      "x": -11,
      "y": 75,
      "z": 3,
      "name": "Rock_Shale_Cobble",
      "rotation": 4
    },
    {
      "x": -10,
      "y": 48,
      "z": -2,
      "name": "Rock_Shale_Cobble",
      "rotation": 17
    },
    {
      "x": -10,
      "y": 49,
      "z": -2,
      "name": "Rock_Shale_Cobble",
      "rotation": 17
    },
    {
      "x": -10,
      "y": 50,
      "z": -2,
      "name": "Rock_Shale_Cobble",
      "rotation": 17
    },
    {
      "x": -10,
      "y": 51,
      "z": -2,
      "name": "Rock_Shale_Cobble",
      "rotation": 17
    },
    {
      "x": -10,
      "y": 52,
      "z": -2,
      "name": "Rock_Shale_Cobble",
      "rotation": 17
    },
    {
      "x": -10,
      "y": 72,
      "z": -2,
      "name": "Rock_Shale_Cobble",
      "rotation": 4
    },
    {
      "x": -10,
      "y": 73,
      "z": -2,
      "name": "Rock_Shale_Cobble",
      "rotation": 4
    },
    {
      "x": -10,
      "y": 74,
      "z": -2,
      "name": "Rock_Shale_Cobble",
      "rotation": 4
    },
    {
      "x": -10,
      "y": 75,
      "z": -2,
      "name": "Rock_Shale_Cobble",
      "rotation": 4
    },
    {
      "x": -10,
      "y": 76,
      "z": -2,
      "name": "Rock_Shale_Cobble",
      "rotation": 4
    },
    {
      "x": -10,
      "y": 47,
      "z": -1,
      "name": "Rock_Shale_Cobble_Half",
      "rotation": 9
    },
    {
      "x": -10,
      "y": 48,
      "z": -1,
      "name": "Rock_Shale_Cobble",
      "rotation": 17
    },
    {
      "x": -10,
      "y": 49,
      "z": -1,
      "name": "Rock_Shale_Cobble",
      "rotation": 17
    },
    {
      "x": -10,
      "y": 50,
      "z": -1,
      "name": "Rock_Shale_Cobble",
      "rotation": 17
    },
    {
      "x": -10,
      "y": 51,
      "z": -1,
      "name": "Rock_Shale_Cobble",
      "rotation": 17
    },
    {
      "x": -10,
      "y": 52,
      "z": -1,
      "name": "Rock_Shale_Cobble",
      "rotation": 17
    },
    {
      "x": -10,
      "y": 53,
      "z": -1,
      "name": "Rock_Shale_Brick_Smooth",
      "rotation": 1
    },
    {
      "x": -10,
      "y": 71,
      "z": -1,
      "name": "Rock_Shale_Brick_Smooth",
      "rotation": 1
    },
    {
      "x": -10,
      "y": 72,
      "z": -1,
      "name": "Rock_Shale_Cobble",
      "rotation": 4
    },
    {
      "x": -10,
      "y": 73,
      "z": -1,
      "name": "Rock_Shale_Cobble",
      "rotation": 4
    },
    {
      "x": -10,
      "y": 74,
      "z": -1,
      "name": "Rock_Shale_Cobble",
      "rotation": 4
    },
    {
      "x": -10,
      "y": 75,
      "z": -1,
      "name": "Rock_Shale_Cobble",
      "rotation": 4
    },
    {
      "x": -10,
      "y": 76,
      "z": -1,
      "name": "Rock_Shale_Cobble",
      "rotation": 4
    },
    {
      "x": -10,
      "y": 77,
      "z": -1,
      "name": "Rock_Shale_Cobble_Half",
      "rotation": 1
    },
    {
      "x": -10,
      "y": 48,
      "z": 0,
      "name": "Rock_Shale_Cobble",
      "rotation": 17
    },
    {
      "x": -10,
      "y": 49,
      "z": 0,
      "name": "Rock_Shale_Cobble",
      "rotation": 17
    },
    {
      "x": -10,
      "y": 50,
      "z": 0,
      "name": "Rock_Shale_Cobble",
      "rotation": 17
    },
    {
      "x": -10,
      "y": 51,
      "z": 0,
      "name": "Build_Lightsource_Cyan",
      "rotation": 5
    },
    {
      "x": -10,
      "y": 52,
      "z": 0,
      "name": "Build_Lightsource_Cyan",
      "rotation": 5
    },
    {
      "x": -10,
      "y": 72,
      "z": 0,
      "name": "Build_Lightsource_Cyan",
      "rotation": 9
    },
    {
      "x": -10,
      "y": 73,
      "z": 0,
      "name": "Rock_Shale_Cobble",
      "rotation": 4
    },
    {
      "x": -10,
      "y": 74,
      "z": 0,
      "name": "Rock_Shale_Cobble",
      "rotation": 4
    },
    {
      "x": -10,
      "y": 75,
      "z": 0,
      "name": "Rock_Shale_Cobble",
      "rotation": 4
    },
    {
      "x": -10,
      "y": 76,
      "z": 0,
      "name": "Rock_Shale_Cobble",
      "rotation": 4
    },
    {
      "x": -10,
      "y": 48,
      "z": 1,
      "name": "Rock_Shale_Cobble",
      "rotation": 17
    },
    {
      "x": -10,
      "y": 49,
      "z": 1,
      "name": "Rock_Shale_Cobble",
      "rotation": 17
    },
    {
      "x": -10,
      "y": 50,
      "z": 1,
      "name": "Rock_Shale_Cobble",
      "rotation": 17
    },
    {
      "x": -10,
      "y": 51,
      "z": 1,
      "name": "Rock_Shale_Cobble",
      "rotation": 17
    },
    {
      "x": -10,
      "y": 52,
      "z": 1,
      "name": "Build_Lightsource_Cyan",
      "rotation": 5
    },
    {
      "x": -10,
      "y": 72,
      "z": 1,
      "name": "Build_Lightsource_Cyan",
      "rotation": 9
    },
    {
      "x": -10,
      "y": 73,
      "z": 1,
      "name": "Rock_Shale_Cobble",
      "rotation": 4
    },
    {
      "x": -10,
      "y": 74,
      "z": 1,
      "name": "Rock_Shale_Cobble",
      "rotation": 4
    },
    {
      "x": -10,
      "y": 75,
      "z": 1,
      "name": "Rock_Shale_Cobble",
      "rotation": 4
    },
    {
      "x": -10,
      "y": 76,
      "z": 1,
      "name": "Rock_Shale_Cobble",
      "rotation": 4
    },
    {
      "x": -10,
      "y": 47,
      "z": 2,
      "name": "Rock_Shale_Cobble_Half",
      "rotation": 9
    },
    {
      "x": -10,
      "y": 48,
      "z": 2,
      "name": "Rock_Shale_Cobble",
      "rotation": 17
    },
    {
      "x": -10,
      "y": 49,
      "z": 2,
      "name": "Rock_Shale_Cobble",
      "rotation": 17
    },
    {
      "x": -10,
      "y": 50,
      "z": 2,
      "name": "Rock_Shale_Cobble",
      "rotation": 17
    },
    {
      "x": -10,
      "y": 51,
      "z": 2,
      "name": "Rock_Shale_Cobble",
      "rotation": 17
    },
    {
      "x": -10,
      "y": 52,
      "z": 2,
      "name": "Rock_Shale_Cobble",
      "rotation": 17
    },
    {
      "x": -10,
      "y": 53,
      "z": 2,
      "name": "Rock_Shale_Brick_Smooth",
      "rotation": 1
    },
    {
      "x": -10,
      "y": 71,
      "z": 2,
      "name": "Rock_Shale_Brick_Smooth",
      "rotation": 1
    },
    {
      "x": -10,
      "y": 72,
      "z": 2,
      "name": "Rock_Shale_Cobble",
      "rotation": 4
    },
    {
      "x": -10,
      "y": 73,
      "z": 2,
      "name": "Rock_Shale_Cobble",
      "rotation": 4
    },
    {
      "x": -10,
      "y": 74,
      "z": 2,
      "name": "Rock_Shale_Cobble",
      "rotation": 4
    },
    {
      "x": -10,
      "y": 75,
      "z": 2,
      "name": "Rock_Shale_Cobble",
      "rotation": 4
    },
    {
      "x": -10,
      "y": 76,
      "z": 2,
      "name": "Rock_Shale_Cobble",
      "rotation": 4
    },
    {
      "x": -10,
      "y": 77,
      "z": 2,
      "name": "Rock_Shale_Cobble_Half",
      "rotation": 1
    },
    {
      "x": -10,
      "y": 48,
      "z": 3,
      "name": "Rock_Shale_Cobble",
      "rotation": 17
    },
    {
      "x": -10,
      "y": 49,
      "z": 3,
      "name": "Rock_Shale_Cobble",
      "rotation": 17
    },
    {
      "x": -10,
      "y": 50,
      "z": 3,
      "name": "Rock_Shale_Cobble",
      "rotation": 17
    },
    {
      "x": -10,
      "y": 51,
      "z": 3,
      "name": "Rock_Shale_Cobble",
      "rotation": 17
    },
    {
      "x": -10,
      "y": 52,
      "z": 3,
      "name": "Rock_Shale_Cobble",
      "rotation": 17
    },
    {
      "x": -10,
      "y": 72,
      "z": 3,
      "name": "Rock_Shale_Cobble",
      "rotation": 4
    },
    {
      "x": -10,
      "y": 73,
      "z": 3,
      "name": "Rock_Shale_Cobble",
      "rotation": 4
    },
    {
      "x": -10,
      "y": 74,
      "z": 3,
      "name": "Rock_Shale_Cobble",
      "rotation": 4
    },
    {
      "x": -10,
      "y": 75,
      "z": 3,
      "name": "Rock_Shale_Cobble",
      "rotation": 4
    },
    {
      "x": -10,
      "y": 76,
      "z": 3,
      "name": "Rock_Shale_Cobble",
      "rotation": 4
    },
    {
      "x": -9,
      "y": 48,
      "z": -2,
      "name": "Rock_Shale_Cobble",
      "rotation": 17
    },
    {
      "x": -9,
      "y": 49,
      "z": -2,
      "name": "Rock_Shale_Cobble",
      "rotation": 17
    },
    {
      "x": -9,
      "y": 50,
      "z": -2,
      "name": "Rock_Shale_Cobble",
      "rotation": 17
    },
    {
      "x": -9,
      "y": 51,
      "z": -2,
      "name": "Rock_Shale_Cobble",
      "rotation": 17
    },
    {
      "x": -9,
      "y": 73,
      "z": -2,
      "name": "Rock_Shale_Cobble",
      "rotation": 4
    },
    {
      "x": -9,
      "y": 74,
      "z": -2,
      "name": "Rock_Shale_Cobble",
      "rotation": 4
    },
    {
      "x": -9,
      "y": 75,
      "z": -2,
      "name": "Rock_Shale_Cobble",
      "rotation": 4
    },
    {
      "x": -9,
      "y": 76,
      "z": -2,
      "name": "Rock_Shale_Cobble",
      "rotation": 4
    },
    {
      "x": -9,
      "y": 47,
      "z": -1,
      "name": "Rock_Shale_Cobble_Half",
      "rotation": 9
    },
    {
      "x": -9,
      "y": 48,
      "z": -1,
