{
  "version": 8,
  "blockIdVersion": 11,
  "anchorX": 0,
  "anchorY": 0,
  "anchorZ": 0,
  "blocks": [
    {
      "x": -20,
      "y": 5,
      "z": -2,
      "name": "Plant_Moss_Wall_Green_Dark",
      "rotation": 19
    },
    {
      "x": -20,
      "y": 8,
      "z": -2,
      "name": "Plant_Moss_Wall_Green_Dark",
      "rotation": 19
    },
    {
      "x": -20,
      "y": 7,
      "z": 2,
      "name": "Plant_Moss_Wall_Green_Dark",
      "rotation": 19
    },
    {
      "x": -20,
      "y": 7,
      "z": 3,
      "name": "Plant_Moss_Wall_Green_Dark",
      "rotation": 19
    },
    {
      "x": -19,
      "y": 5,
      "z": -3,
      "name": "Plant_Moss_Rug_Green_Dark",
      "rotation": 12
    },
    {
      "x": -19,
      "y": 8,
      "z": -3,
      "name": "Plant_Moss_Rug_Green_Dark",
      "rotation": 12
    },
    {
      "x": -19,
      "y": 3,
      "z": -2,
      "name": "Rock_Shale_Brick_Smooth",
      "rotation": 27
    },
    {
      "x": -19,
      "y": 4,
      "z": -2,
      "name": "Rock_Shale_Brick_Smooth",
      "rotation": 27
    },
    {
      "x": -19,
      "y": 5,
      "z": -2,
      "name": "Rock_Shale_Brick_Smooth",
      "rotation": 27
    },
    {
      "x": -19,
      "y": 6,
      "z": -2,
      "name": "Rock_Shale_Brick_Smooth",
      "rotation": 27
    },
    {
      "x": -19,
      "y": 7,
      "z": -2,
      "name": "Rock_Shale_Brick_Smooth",
      "rotation": 27
    },
    {
      "x": -19,
      "y": 8,
      "z": -2,
      "name": "Rock_Shale_Brick_Smooth",
      "rotation": 27
    },
    {
      "x": -19,
      "y": 4,
      "z": 1,
      "name": "Plant_Moss_Rug_Green_Dark",
      "rotation": 12
    },
    {
      "x": -19,
      "y": 6,
      "z": 1,
      "name": "Plant_Moss_Rug_Green_Dark",
      "rotation": 12
    },
    {
      "x": -19,
      "y": 7,
      "z": 1,
      "name": "Plant_Moss_Rug_Green_Dark",
      "rotation": 12
    },
    {
      "x": -19,
      "y": 3,
      "z": 2,
      "name": "Rock_Shale_Brick_Smooth",
      "rotation": 27
    },
    {
      "x": -19,
      "y": 4,
      "z": 2,
      "name": "Rock_Shale_Brick_Smooth",
      "rotation": 27
    },
    {
      "x": -19,
      "y": 5,
      "z": 2,
      "name": "Rock_Shale_Brick_Smooth",
      "rotation": 27
    },
    {
      "x": -19,
      "y": 6,
      "z": 2,
      "name": "Rock_Shale_Brick_Smooth",
      "rotation": 27
    },
    {
      "x": -19,
      "y": 7,
      "z": 2,
      "name": "Rock_Shale_Brick_Smooth",
      "rotation": 27
    },
    {
      "x": -19,
      "y": 8,
      "z": 2,
      "name": "Rock_Shale_Brick_Smooth",
      "rotation": 27
    },
    {
      "x": -18,
      "y": 4,
      "z": -3,
      "name": "Rock_Shale_Cobble_Half",
      "rotation": 16
    },
    {
      "x": -18,
      "y": 5,
      "z": -3,
      "name": "Plant_Moss_Rug_Green_Dark",
      "rotation": 12
    },
    {
      "x": -18,
      "y": 6,
      "z": -3,
      "name": "Plant_Moss_Rug_Green_Dark",
      "rotation": 12
    },
    {
      "x": -18,
      "y": 7,
      "z": -3,
      "name": "Rock_Shale_Cobble_Half",
      "rotation": 16
    },
    {
      "x": -18,
      "y": 2,
      "z": -2,
      "name": "Rock_Shale_Brick_Smooth",
      "rotation": 27
    },
    {
      "x": -18,
      "y": 3,
      "z": -2,
      "name": "Rock_Shale_Cobble",
      "rotation": 16
    },
    {
      "x": -18,
      "y": 4,
      "z": -2,
      "name": "Rock_Shale_Cobble",
      "rotation": 16
    },
    {
      "x": -18,
      "y": 5,
      "z": -2,
      "name": "Rock_Shale_Cobble",
      "rotation": 16
    },
    {
      "x": -18,
      "y": 6,
      "z": -2,
      "name": "Rock_Shale_Cobble",
      "rotation": 16
    },
    {
      "x": -18,
      "y": 7,
      "z": -2,
      "name": "Rock_Shale_Cobble",
      "rotation": 16
    },
    {
      "x": -18,
      "y": 8,
      "z": -2,
      "name": "Rock_Shale_Cobble",
      "rotation": 16
    },
    {
      "x": -18,
      "y": 9,
      "z": -2,
      "name": "Rock_Shale_Brick_Smooth",
      "rotation": 27
    },
    {
      "x": -18,
      "y": 3,
      "z": -1,
      "name": "Rock_Shale_Cobble",
      "rotation": 16
    },
    {
      "x": -18,
      "y": 4,
      "z": -1,
      "name": "Rock_Shale_Cobble",
      "rotation": 16
    },
    {
      "x": -18,
      "y": 5,
      "z": -1,
      "name": "Rock_Shale_Cobble",
      "rotation": 16
    },
    {
      "x": -18,
      "y": 6,
      "z": -1,
      "name": "Rock_Shale_Cobble",
      "rotation": 16
    },
    {
      "x": -18,
      "y": 7,
      "z": -1,
      "name": "Rock_Shale_Cobble",
      "rotation": 16
    },
    {
      "x": -18,
      "y": 8,
      "z": -1,
      "name": "Rock_Shale_Cobble",
      "rotation": 16
    },
    {
      "x": -18,
      "y": 3,
      "z": 0,
      "name": "Build_Lightsource_Cyan",
      "rotation": 16
    },
    {
      "x": -18,
      "y": 4,
      "z": 0,
      "name": "Build_Lightsource_Cyan",
      "rotation": 1
    },
    {
      "x": -18,
      "y": 5,
      "z": 0,
      "name": "Build_Lightsource_Cyan",
      "rotation": 1
    },
    {
      "x": -18,
      "y": 6,
      "z": 0,
      "name": "Build_Lightsource_Cyan",
      "rotation": 1
    },
    {
      "x": -18,
      "y": 7,
      "z": 0,
      "name": "Build_Lightsource_Cyan",
      "rotation": 16
    },
    {
      "x": -18,
      "y": 8,
      "z": 0,
      "name": "Build_Lightsource_Cyan",
      "rotation": 16
    },
    {
      "x": -18,
      "y": 2,
      "z": 1,
      "name": "Plant_Moss_Rug_Green_Dark",
      "rotation": 12
    },
    {
      "x": -18,
      "y": 3,
      "z": 1,
      "name": "Rock_Shale_Cobble",
      "rotation": 16
    },
    {
      "x": -18,
      "y": 4,
      "z": 1,
      "name": "Rock_Shale_Cobble",
      "rotation": 16
    },
    {
      "x": -18,
      "y": 5,
      "z": 1,
      "name": "Rock_Shale_Cobble",
      "rotation": 16
    },
    {
      "x": -18,
      "y": 6,
      "z": 1,
      "name": "Rock_Shale_Cobble",
      "rotation": 16
    },
    {
      "x": -18,
      "y": 7,
      "z": 1,
      "name": "Rock_Shale_Cobble",
      "rotation": 16
    },
    {
      "x": -18,
      "y": 8,
      "z": 1,
      "name": "Rock_Shale_Cobble",
      "rotation": 16
    },
    {
      "x": -18,
      "y": 2,
      "z": 2,
      "name": "Rock_Shale_Brick_Smooth",
      "rotation": 27
    },
    {
      "x": -18,
      "y": 3,
      "z": 2,
      "name": "Rock_Shale_Cobble",
      "rotation": 16
    },
    {
      "x": -18,
      "y": 4,
      "z": 2,
      "name": "Rock_Shale_Cobble",
      "rotation": 16
    },
    {
      "x": -18,
      "y": 5,
      "z": 2,
      "name": "Rock_Shale_Cobble",
      "rotation": 16
    },
    {
      "x": -18,
      "y": 6,
      "z": 2,
      "name": "Rock_Shale_Cobble",
      "rotation": 16
    },
    {
      "x": -18,
      "y": 7,
      "z": 2,
      "name": "Rock_Shale_Cobble",
      "rotation": 16
    },
    {
      "x": -18,
      "y": 8,
      "z": 2,
      "name": "Rock_Shale_Cobble",
      "rotation": 16
    },
    {
      "x": -18,
      "y": 9,
      "z": 2,
      "name": "Rock_Shale_Brick_Smooth",
      "rotation": 27
    },
    {
      "x": -18,
      "y": 4,
      "z": 3,
      "name": "Rock_Shale_Cobble_Half",
      "rotation": 16
    },
    {
      "x": -18,
      "y": 7,
      "z": 3,
      "name": "Rock_Shale_Cobble_Half",
      "rotation": 16
    },
    {
      "x": -17,
      "y": 5,
      "z": -4,
      "name": "Plant_Moss_Wall_Green_Dark",
      "rotation": 19
    },
    {
      "x": -17,
      "y": 6,
      "z": -4,
      "name": "Plant_Moss_Rug_Green_Dark",
      "rotation": 12
    },
    {
      "x": -17,
      "y": 7,
      "z": -4,
      "name": "Rock_Shale_Cobble_Half",
      "rotation": 16
    },
    {
      "x": -17,
      "y": 5,
      "z": -3,
      "name": "Rock_Shale_Cobble"
    },
    {
      "x": -17,
      "y": 6,
      "z": -3,
      "name": "Rock_Shale_Cobble"
    },
    {
      "x": -17,
      "y": 7,
      "z": -3,
      "name": "Rock_Shale_Cobble"
    },
    {
      "x": -17,
      "y": 8,
      "z": -3,
      "name": "Rock_Shale_Cobble"
    },
    {
      "x": -17,
      "y": 9,
      "z": -3,
      "name": "Plant_Moss_Rug_Green_Dark",
      "rotation": 12
    },
    {
      "x": -17,
      "y": 1,
      "z": -2,
      "name": "Rock_Shale_Brick_Smooth",
      "rotation": 27
    },
    {
      "x": -17,
      "y": 2,
      "z": -2,
      "name": "Rock_Shale_Cobble",
      "rotation": 27
    },
    {
      "x": -17,
      "y": 3,
      "z": -2,
      "name": "Rock_Shale_Cobble",
      "rotation": 16
    },
    {
      "x": -17,
      "y": 4,
      "z": -2,
      "name": "Rock_Shale_Cobble",
      "rotation": 10
    },
    {
      "x": -17,
      "y": 5,
      "z": -2,
      "name": "Rock_Shale_Cobble",
      "rotation": 10
    },
    {
      "x": -17,
      "y": 6,
      "z": -2,
      "name": "Rock_Shale_Cobble",
      "rotation": 10
    },
    {
      "x": -17,
      "y": 7,
      "z": -2,
      "name": "Rock_Shale_Cobble",
      "rotation": 10
    },
    {
      "x": -17,
      "y": 8,
      "z": -2,
      "name": "Rock_Shale_Cobble",
      "rotation": 10
    },
    {
      "x": -17,
      "y": 9,
      "z": -2,
      "name": "Rock_Shale_Cobble",
      "rotation": 16
    },
    {
      "x": -17,
      "y": 10,
      "z": -2,
      "name": "Rock_Shale_Brick_Smooth",
      "rotation": 27
    },
    {
      "x": -17,
      "y": 2,
      "z": -1,
      "name": "Rock_Shale_Cobble",
      "rotation": 16
    },
    {
      "x": -17,
      "y": 3,
      "z": -1,
      "name": "Rock_Shale_Cobble",
      "rotation": 10
    },
    {
      "x": -17,
      "y": 4,
      "z": -1,
      "name": "Rock_Shale_Cobble",
      "rotation": 10
    },
    {
      "x": -17,
      "y": 5,
      "z": -1,
      "name": "Rock_Shale_Cobble",
      "rotation": 10
    },
    {
      "x": -17,
      "y": 6,
      "z": -1,
      "name": "Rock_Shale_Cobble",
      "rotation": 10
    },
    {
      "x": -17,
      "y": 7,
      "z": -1,
      "name": "Rock_Shale_Cobble",
      "rotation": 10
    },
    {
      "x": -17,
      "y": 8,
      "z": -1,
      "name": "Rock_Shale_Cobble",
      "rotation": 10
    },
    {
      "x": -17,
      "y": 9,
      "z": -1,
      "name": "Rock_Shale_Cobble",
      "rotation": 16
    },
    {
      "x": -17,
      "y": 2,
      "z": 0,
      "name": "Build_Lightsource_Cyan",
      "rotation": 1
    },
    {
      "x": -17,
      "y": 3,
      "z": 0,
      "name": "Rock_Shale_Cobble",
      "rotation": 10
    },
    {
      "x": -17,
      "y": 4,
      "z": 0,
      "name": "Rock_Shale_Cobble",
      "rotation": 10
    },
    {
      "x": -17,
      "y": 5,
      "z": 0,
      "name": "Rock_Shale_Cobble",
      "rotation": 10
    },
    {
      "x": -17,
      "y": 6,
      "z": 0,
      "name": "Rock_Shale_Cobble",
      "rotation": 10
    },
    {
      "x": -17,
      "y": 7,
      "z": 0,
      "name": "Rock_Shale_Cobble",
      "rotation": 10
    },
    {
      "x": -17,
      "y": 8,
      "z": 0,
      "name": "Rock_Shale_Cobble",
      "rotation": 10
    },
    {
      "x": -17,
      "y": 9,
      "z": 0,
      "name": "Build_Lightsource_Cyan",
      "rotation": 1
    },
    {
      "x": -17,
      "y": 1,
      "z": 1,
      "name": "Plant_Moss_Rug_Green_Dark",
      "rotation": 12
    },
    {
      "x": -17,
      "y": 2,
      "z": 1,
      "name": "Rock_Shale_Cobble",
      "rotation": 16
    },
    {
      "x": -17,
      "y": 3,
      "z": 1,
      "name": "Rock_Shale_Cobble",
      "rotation": 10
    },
    {
      "x": -17,
      "y": 4,
      "z": 1,
      "name": "Rock_Shale_Cobble",
      "rotation": 10
    },
    {
      "x": -17,
      "y": 5,
      "z": 1,
      "name": "Rock_Shale_Cobble",
      "rotation": 10
    },
    {
      "x": -17,
      "y": 6,
      "z": 1,
      "name": "Rock_Shale_Cobble",
      "rotation": 10
    },
    {
      "x": -17,
      "y": 7,
      "z": 1,
      "name": "Rock_Shale_Cobble",
      "rotation": 10
    },
    {
      "x": -17,
      "y": 8,
      "z": 1,
      "name": "Rock_Shale_Cobble",
      "rotation": 10
    },
    {
      "x": -17,
      "y": 9,
      "z": 1,
      "name": "Rock_Shale_Cobble",
      "rotation": 16
    },
    {
      "x": -17,
      "y": 1,
      "z": 2,
      "name": "Rock_Shale_Brick_Smooth",
      "rotation": 27
    },
    {
      "x": -17,
      "y": 2,
      "z": 2,
      "name": "Rock_Shale_Cobble",
      "rotation": 16
    },
    {
      "x": -17,
      "y": 3,
      "z": 2,
      "name": "Rock_Shale_Cobble",
      "rotation": 10
    },
    {
      "x": -17,
      "y": 4,
      "z": 2,
      "name": "Rock_Shale_Cobble",
      "rotation": 10
    },
    {
      "x": -17,
      "y": 5,
      "z": 2,
      "name": "Rock_Shale_Cobble",
      "rotation": 10
    },
    {
      "x": -17,
      "y": 6,
      "z": 2,
      "name": "Rock_Shale_Cobble",
      "rotation": 10
    },
    {
      "x": -17,
      "y": 7,
      "z": 2,
      "name": "Rock_Shale_Cobble",
      "rotation": 10
    },
    {
      "x": -17,
      "y": 8,
      "z": 2,
      "name": "Rock_Shale_Cobble",
      "rotation": 10
    },
    {
      "x": -17,
      "y": 9,
      "z": 2,
      "name": "Rock_Shale_Cobble",
      "rotation": 16
    },
    {
      "x": -17,
      "y": 10,
      "z": 2,
      "name": "Rock_Shale_Brick_Smooth",
      "rotation": 27
    },
    {
      "x": -17,
      "y": 3,
      "z": 3,
      "name": "Rock_Shale_Cobble",
      "rotation": 1
    },
    {
      "x": -17,
      "y": 4,
      "z": 3,
      "name": "Rock_Shale_Cobble",
      "rotation": 1
    },
    {
      "x": -17,
      "y": 5,
      "z": 3,
      "name": "Rock_Shale_Cobble",
      "rotation": 1
    },
    {
      "x": -17,
      "y": 6,
      "z": 3,
      "name": "Rock_Shale_Cobble",
      "rotation": 1
    },
    {
      "x": -17,
      "y": 7,
      "z": 3,
      "name": "Rock_Shale_Cobble",
      "rotation": 1
    },
    {
      "x": -17,
      "y": 8,
      "z": 3,
      "name": "Rock_Shale_Cobble",
      "rotation": 1
    },
    {
      "x": -17,
      "y": 4,
      "z": 4,
      "name": "Rock_Shale_Cobble_Half",
      "rotation": 16
    },
    {
      "x": -17,
      "y": 7,
      "z": 4,
      "name": "Rock_Shale_Cobble_Half",
      "rotation": 16
    },
    {
      "x": -17,
      "y": 4,
      "z": 5,
      "name": "Rock_Shale_Cobble_Half",
      "rotation": 16
    },
    {
      "x": -17,
      "y": 7,
      "z": 5,
      "name": "Rock_Shale_Cobble_Half",
      "rotation": 16
    },
    {
      "x": -17,
      "y": 4,
      "z": 6,
      "name": "Rock_Shale_Cobble_Half",
      "rotation": 16
    },
    {
      "x": -17,
      "y": 7,
      "z": 6,
      "name": "Rock_Shale_Cobble_Half",
      "rotation": 16
    },
    {
      "x": -16,
      "y": 5,
      "z": -5,
      "name": "Plant_Moss_Rug_Green_Dark",
      "rotation": 12
    },
    {
      "x": -16,
      "y": 7,
      "z": -5,
      "name": "Plant_Moss_Rug_Green_Dark",
      "rotation": 12
    },
    {
      "x": -16,
      "y": 5,
      "z": -4,
      "name": "Rock_Shale_Cobble"
    },
    {
      "x": -16,
      "y": 6,
      "z": -4,
      "name": "Rock_Shale_Cobble"
    },
    {
      "x": -16,
      "y": 7,
      "z": -4,
      "name": "Rock_Shale_Cobble"
    },
    {
      "x": -16,
      "y": 8,
      "z": -4,
      "name": "Rock_Shale_Cobble"
    },
    {
      "x": -16,
      "y": 2,
      "z": -3,
      "name": "Plant_Moss_Rug_Green_Dark",
      "rotation": 12
    },
    {
      "x": -16,
      "y": 5,
      "z": -3,
      "name": "Rock_Shale_Cobble"
    },
    {
      "x": -16,
      "y": 6,
      "z": -3,
      "name": "Rock_Shale_Cobble"
    },
    {
      "x": -16,
      "y": 7,
      "z": -3,
      "name": "Rock_Shale_Cobble"
    },
    {
      "x": -16,
      "y": 8,
      "z": -3,
      "name": "Rock_Shale_Cobble"
    },
    {
      "x": -16,
      "y": 9,
      "z": -3,
      "name": "Plant_Moss_Rug_Green_Dark",
      "rotation": 12
    },
    {
      "x": -16,
      "y": 10,
      "z": -3,
      "name": "Plant_Moss_Rug_Green_Dark",
      "rotation": 12
    },
    {
      "x": -16,
      "y": 1,
      "z": -2,
      "name": "Rock_Shale_Brick_Smooth",
      "rotation": 27
    },
    {
      "x": -16,
      "y": 2,
      "z": -2,
      "name": "Rock_Shale_Cobble",
      "rotation": 27
    },
    {
      "x": -16,
      "y": 3,
      "z": -2,
      "name": "Rock_Shale_Cobble",
      "rotation": 16
    },
    {
      "x": -16,
      "y": 4,
      "z": -2,
      "name": "Rock_Shale_Cobble",
      "rotation": 10
    },
    {
      "x": -16,
      "y": 5,
      "z": -2,
      "name": "Rock_Shale_Cobble",
      "rotation": 10
    },
    {
      "x": -16,
      "y": 6,
      "z": -2,
      "name": "Rock_Shale_Cobble",
      "rotation": 10
    },
    {
      "x": -16,
      "y": 7,
      "z": -2,
      "name": "Rock_Shale_Cobble",
      "rotation": 10
    },
    {
      "x": -16,
      "y": 8,
      "z": -2,
      "name": "Rock_Shale_Cobble",
      "rotation": 10
    },
    {
      "x": -16,
      "y": 9,
      "z": -2,
      "name": "Rock_Shale_Cobble",
      "rotation": 16
    },
    {
      "x": -16,
      "y": 10,
      "z": -2,
      "name": "Rock_Shale_Brick_Smooth",
      "rotation": 27
    },
    {
      "x": -16,
      "y": 11,
      "z": -2,
      "name": "Plant_Moss_Wall_Green_Dark",
      "rotation": 12
    },
    {
      "x": -16,
      "y": 2,
      "z": -1,
      "name": "Rock_Shale_Cobble",
      "rotation": 16
    },
    {
      "x": -16,
      "y": 3,
      "z": -1,
      "name": "Rock_Shale_Cobble",
      "rotation": 10
    },
    {
      "x": -16,
      "y": 4,
      "z": -1,
      "name": "Rock_Shale_Cobble",
      "rotation": 10
    },
    {
      "x": -16,
      "y": 5,
      "z": -1,
      "name": "Rock_Shale_Cobble",
      "rotation": 10
    },
    {
      "x": -16,
      "y": 6,
      "z": -1,
      "name": "Rock_Shale_Cobble",
      "rotation": 10
    },
    {
      "x": -16,
      "y": 7,
      "z": -1,
      "name": "Rock_Shale_Cobble",
      "rotation": 10
    },
    {
      "x": -16,
      "y": 8,
      "z": -1,
      "name": "Rock_Shale_Cobble",
      "rotation": 10
    },
    {
      "x": -16,
      "y": 9,
      "z": -1,
      "name": "Rock_Shale_Cobble",
      "rotation": 16
    },
    {
      "x": -16,
      "y": 2,
      "z": 0,
      "name": "Build_Lightsource_Cyan",
      "rotation": 1
    },
    {
      "x": -16,
      "y": 3,
      "z": 0,
      "name": "Rock_Shale_Cobble",
      "rotation": 10
    },
    {
      "x": -16,
      "y": 4,
      "z": 0,
      "name": "Rock_Shale_Cobble",
      "rotation": 10
    },
    {
      "x": -16,
      "y": 5,
      "z": 0,
      "name": "Rock_Shale_Cobble",
      "rotation": 10
    },
    {
      "x": -16,
      "y": 6,
      "z": 0,
      "name": "Rock_Shale_Cobble",
      "rotation": 10
    },
    {
      "x": -16,
      "y": 7,
      "z": 0,
      "name": "Rock_Shale_Cobble",
      "rotation": 10
    },
    {
      "x": -16,
      "y": 8,
      "z": 0,
      "name": "Rock_Shale_Cobble",
      "rotation": 10
    },
    {
      "x": -16,
      "y": 9,
      "z": 0,
      "name": "Build_Lightsource_Cyan",
      "rotation": 16
    },
    {
      "x": -16,
      "y": 2,
      "z": 1,
      "name": "Rock_Shale_Cobble",
      "rotation": 16
    },
    {
      "x": -16,
      "y": 3,
      "z": 1,
      "name": "Rock_Shale_Cobble",
      "rotation": 10
    },
    {
      "x": -16,
      "y": 4,
      "z": 1,
      "name": "Rock_Shale_Cobble",
      "rotation": 10
    },
    {
      "x": -16,
      "y": 5,
      "z": 1,
      "name": "Rock_Shale_Cobble",
      "rotation": 10
    },
    {
      "x": -16,
      "y": 6,
      "z": 1,
      "name": "Rock_Shale_Cobble",
      "rotation": 10
    },
    {
      "x": -16,
      "y": 7,
      "z": 1,
      "name": "Rock_Shale_Cobble",
      "rotation": 10
    },
    {
      "x": -16,
      "y": 8,
      "z": 1,
      "name": "Rock_Shale_Cobble",
      "rotation": 10
    },
    {
      "x": -16,
      "y": 9,
      "z": 1,
      "name": "Rock_Shale_Cobble",
      "rotation": 16
    },
    {
      "x": -16,
      "y": 10,
      "z": 1,
      "name": "Plant_Moss_Rug_Green_Dark",
      "rotation": 12
    },
    {
      "x": -16,
      "y": 1,
      "z": 2,
      "name": "Rock_Shale_Brick_Smooth",
      "rotation": 27
    },
    {
      "x": -16,
      "y": 2,
      "z": 2,
      "name": "Rock_Shale_Cobble",
      "rotation": 16
    },
    {
      "x": -16,
      "y": 3,
      "z": 2,
      "name": "Rock_Shale_Cobble",
      "rotation": 10
    },
    {
      "x": -16,
      "y": 4,
      "z": 2,
      "name": "Rock_Shale_Cobble",
      "rotation": 10
    },
    {
      "x": -16,
      "y": 5,
      "z": 2,
      "name": "Rock_Shale_Cobble",
      "rotation": 10
    },
    {
      "x": -16,
      "y": 6,
      "z": 2,
      "name": "Rock_Shale_Cobble",
      "rotation": 10
    },
    {
      "x": -16,
      "y": 7,
      "z": 2,
      "name": "Rock_Shale_Cobble",
      "rotation": 10
    },
    {
      "x": -16,
      "y": 8,
      "z": 2,
      "name": "Rock_Shale_Cobble",
      "rotation": 10
    },
    {
      "x": -16,
      "y": 9,
      "z": 2,
      "name": "Rock_Shale_Cobble",
      "rotation": 16
    },
    {
      "x": -16,
      "y": 10,
      "z": 2,
      "name": "Rock_Shale_Brick_Smooth",
      "rotation": 27
    },
    {
      "x": -16,
      "y": 3,
      "z": 3,
      "name": "Rock_Shale_Cobble",
      "rotation": 1
    },
    {
      "x": -16,
      "y": 4,
      "z": 3,
      "name": "Rock_Shale_Cobble",
      "rotation": 1
    },
    {
      "x": -16,
      "y": 5,
      "z": 3,
      "name": "Rock_Shale_Cobble",
      "rotation": 1
    },
    {
      "x": -16,
      "y": 6,
      "z": 3,
      "name": "Rock_Shale_Cobble",
      "rotation": 1
    },
    {
      "x": -16,
      "y": 7,
      "z": 3,
      "name": "Rock_Shale_Cobble",
      "rotation": 1
    },
    {
      "x": -16,
      "y": 8,
      "z": 3,
      "name": "Rock_Shale_Cobble",
      "rotation": 1
    },
    {
      "x": -16,
      "y": 3,
      "z": 4,
      "name": "Rock_Shale_Cobble",
      "rotation": 1
    },
    {
      "x": -16,
      "y": 4,
      "z": 4,
      "name": "Rock_Shale_Cobble",
      "rotation": 1
    },
    {
      "x": -16,
      "y": 5,
      "z": 4,
      "name": "Rock_Shale_Cobble",
      "rotation": 1
    },
    {
      "x": -16,
      "y": 6,
      "z": 4,
      "name": "Rock_Shale_Cobble",
      "rotation": 1
    },
    {
      "x": -16,
      "y": 7,
      "z": 4,
      "name": "Rock_Shale_Cobble",
      "rotation": 1
    },
    {
      "x": -16,
      "y": 8,
      "z": 4,
      "name": "Rock_Shale_Cobble",
      "rotation": 1
    },
    {
      "x": -16,
      "y": 3,
      "z": 5,
      "name": "Rock_Shale_Cobble",
      "rotation": 1
    },
    {
      "x": -16,
      "y": 4,
      "z": 5,
      "name": "Rock_Shale_Cobble",
      "rotation": 1
    },
    {
      "x": -16,
      "y": 5,
      "z": 5,
      "name": "Rock_Shale_Cobble",
      "rotation": 1
    },
    {
      "x": -16,
      "y": 6,
      "z": 5,
      "name": "Rock_Shale_Cobble",
      "rotation": 1
    },
    {
      "x": -16,
      "y": 7,
      "z": 5,
      "name": "Rock_Shale_Cobble",
      "rotation": 1
    },
    {
      "x": -16,
      "y": 8,
      "z": 5,
      "name": "Rock_Shale_Cobble",
      "rotation": 1
    },
    {
      "x": -16,
      "y": 3,
      "z": 6,
      "name": "Rock_Shale_Cobble",
      "rotation": 1
    },
    {
      "x": -16,
      "y": 4,
      "z": 6,
      "name": "Rock_Shale_Cobble",
      "rotation": 1
    },
    {
      "x": -16,
      "y": 5,
      "z": 6,
      "name": "Rock_Shale_Cobble",
      "rotation": 1
    },
    {
      "x": -16,
      "y": 6,
      "z": 6,
      "name": "Rock_Shale_Cobble",
      "rotation": 1
    },
    {
      "x": -16,
      "y": 7,
      "z": 6,
      "name": "Rock_Shale_Cobble",
      "rotation": 1
    },
    {
      "x": -16,
      "y": 8,
      "z": 6,
      "name": "Rock_Shale_Cobble",
      "rotation": 1
    },
    {
      "x": -16,
      "y": 4,
      "z": 7,
      "name": "Rock_Shale_Cobble_Half",
      "rotation": 16
    },
    {
      "x": -16,
      "y": 7,
      "z": 7,
      "name": "Rock_Shale_Cobble_Half",
      "rotation": 16
    },
    {
      "x": -16,
      "y": 4,
      "z": 8,
      "name": "Rock_Shale_Cobble_Half",
      "rotation": 16
    },
    {
      "x": -16,
      "y": 7,
      "z": 8,
      "name": "Rock_Shale_Cobble_Half",
      "rotation": 16
    },
    {
      "x": -15,
      "y": 8,
      "z": -4,
      "name": "Rock_Shale_Cobble"
    },
    {
      "x": -15,
      "y": 2,
      "z": -3,
      "name": "Plant_Moss_Rug_Green_Dark",
      "rotation": 12
    },
    {
      "x": -15,
      "y": 8,
      "z": -3,
      "name": "Deko_Block_Test"
    },
    {
      "x": -15,
      "y": 1,
      "z": -2,
      "name": "Rock_Shale_Brick_Smooth",
      "rotation": 27
    },
    {
      "x": -15,
      "y": 2,
      "z": -2,
      "name": "Rock_Shale_Cobble",
      "rotation": 27
    },
    {
      "x": -15,
      "y": 3,
      "z": -2,
      "name": "Rock_Shale_Cobble",
      "rotation": 16
    },
    {
      "x": -15,
      "y": 4,
      "z": -2,
      "name": "Rock_Shale_Cobble",
      "rotation": 10
    },
    {
      "x": -15,
      "y": 8,
      "z": -2,
      "name": "Rock_Shale_Cobble",
      "rotation": 10
    },
    {
      "x": -15,
      "y": 9,
      "z": -2,
      "name": "Rock_Shale_Cobble",
      "rotation": 16
    },
    {
      "x": -15,
      "y": 10,
      "z": -2,
      "name": "Rock_Shale_Brick_Smooth",
      "rotation": 27
    },
    {
      "x": -15,
      "y": 2,
      "z": -1,
      "name": "Rock_Shale_Cobble",
      "rotation": 16
    },
    {
      "x": -15,
      "y": 3,
      "z": -1,
      "name": "Rock_Shale_Cobble",
      "rotation": 10
    },
    {
      "x": -15,
      "y": 4,
      "z": -1,
      "name": "Rock_Shale_Cobble",
      "rotation": 10
    },
    {
      "x": -15,
      "y": 5,
      "z": -1,
      "name": "Rock_Shale_Cobble",
      "rotation": 10
    },
    {
      "x": -15,
      "y": 6,
      "z": -1,
      "name": "Rock_Shale_Cobble",
      "rotation": 10
    },
    {
      "x": -15,
      "y": 7,
      "z": -1,
      "name": "Rock_Shale_Cobble",
      "rotation": 10
    },
    {
      "x": -15,
      "y": 8,
      "z": -1,
      "name": "Rock_Shale_Cobble",
      "rotation": 10
    },
    {
      "x": -15,
      "y": 9,
      "z": -1,
      "name": "Rock_Shale_Cobble",
      "rotation": 16
    },
    {
      "x": -15,
      "y": 2,
      "z": 0,
      "name": "Build_Lightsource_Cyan",
      "rotation": 16
    },
    {
      "x": -15,
      "y": 3,
      "z": 0,
      "name": "Rock_Shale_Cobble",
      "rotation": 10
    },
    {
      "x": -15,
      "y": 4,
      "z": 0,
      "name": "Rock_Shale_Cobble",
      "rotation": 10
    },
    {
      "x": -15,
      "y": 5,
      "z": 0,
      "name": "Rock_Shale_Cobble",
      "rotation": 10
    },
    {
      "x": -15,
      "y": 6,
      "z": 0,
      "name": "Rock_Shale_Cobble",
      "rotation": 10
    },
    {
      "x": -15,
      "y": 7,
      "z": 0,
      "name": "Rock_Shale_Cobble",
      "rotation": 10
    },
    {
      "x": -15,
      "y": 8,
      "z": 0,
      "name": "Rock_Shale_Cobble",
      "rotation": 10
    },
    {
      "x": -15,
      "y": 9,
      "z": 0,
      "name": "Build_Lightsource_Cyan",
      "rotation": 1
    },
    {
      "x": -15,
      "y": 2,
      "z": 1,
      "name": "Rock_Shale_Cobble",
      "rotation": 16
    },
    {
      "x": -15,
      "y": 3,
      "z": 1,
      "name": "Rock_Shale_Cobble",
      "rotation": 10
    },
    {
      "x": -15,
      "y": 4,
      "z": 1,
      "name": "Rock_Shale_Cobble",
      "rotation": 10
    },
    {
      "x": -15,
      "y": 5,
      "z": 1,
      "name": "Rock_Shale_Cobble",
      "rotation": 10
    },
    {
      "x": -15,
      "y": 6,
      "z": 1,
      "name": "Rock_Shale_Cobble",
      "rotation": 10
    },
    {
      "x": -15,
      "y": 7,
      "z": 1,
      "name": "Rock_Shale_Cobble",
      "rotation": 10
    },
    {
      "x": -15,
      "y": 8,
      "z": 1,
      "name": "Rock_Shale_Cobble",
      "rotation": 10
    },
    {
      "x": -15,
      "y": 9,
      "z": 1,
      "name": "Rock_Shale_Cobble",
      "rotation": 16
    },
    {
      "x": -15,
      "y": 1,
      "z": 2,
      "name": "Rock_Shale_Brick_Smooth",
      "rotation": 27
    },
    {
      "x": -15,
      "y": 2,
      "z": 2,
      "name": "Rock_Shale_Cobble",
      "rotation": 16
    },
    {
      "x": -15,
      "y": 3,
      "z": 2,
      "name": "Rock_Shale_Cobble",
      "rotation": 10
    },
    {
      "x": -15,
      "y": 4,
      "z": 2,
      "name": "Rock_Shale_Cobble",
      "rotation": 10
    },
    {
      "x": -15,
      "y": 5,
      "z": 2,
      "name": "Rock_Shale_Cobble",
      "rotation": 10
    },
    {
      "x": -15,
      "y": 6,
      "z": 2,
      "name": "Rock_Shale_Cobble",
      "rotation": 10
    },
    {
      "x": -15,
      "y": 7,
      "z": 2,
      "name": "Rock_Shale_Cobble",
      "rotation": 10
    },
    {
      "x": -15,
      "y": 8,
      "z": 2,
      "name": "Rock_Shale_Cobble",
      "rotation": 10
    },
    {
      "x": -15,
      "y": 9,
      "z": 2,
      "name": "Rock_Shale_Cobble",
      "rotation": 16
    },
    {
      "x": -15,
      "y": 10,
      "z": 2,
      "name": "Rock_Shale_Brick_Smooth",
      "rotation": 27
    },
    {
      "x": -15,
      "y": 3,
      "z": 3,
      "name": "Deko_Block_Test",
      "rotation": 10
    },
    {
      "x": -15,
      "y": 4,
      "z": 3,
      "name": "Rock_Shale_Cobble",
      "rotation": 1
    },
    {
      "x": -15,
      "y": 5,
      "z": 3,
      "name": "Rock_Shale_Cobble",
      "rotation": 1
    },
    {
      "x": -15,
      "y": 6,
      "z": 3,
      "name": "Rock_Shale_Cobble",
      "rotation": 1
    },
    {
      "x": -15,
      "y": 7,
      "z": 3,
      "name": "Rock_Shale_Cobble",
      "rotation": 1
    },
    {
      "x": -15,
      "y": 8,
      "z": 3,
      "name": "Deko_Block_Test"
    },
    {
      "x": -15,
      "y": 3,
      "z": 4,
      "name": "Rock_Shale_Cobble",
      "rotation": 1
    },
    {
      "x": -15,
      "y": 4,
      "z": 4,
      "name": "Rock_Shale_Cobble",
      "rotation": 1
    },
    {
      "x": -15,
      "y": 5,
      "z": 4,
      "name": "Rock_Shale_Cobble",
      "rotation": 1
    },
    {
      "x": -15,
      "y": 6,
      "z": 4,
      "name": "Rock_Shale_Cobble",
      "rotation": 1
    },
    {
      "x": -15,
      "y": 7,
      "z": 4,
      "name": "Rock_Shale_Cobble",
      "rotation": 1
    },
    {
      "x": -15,
      "y": 8,
      "z": 4,
      "name": "Rock_Shale_Cobble",
      "rotation": 1
    },
    {
      "x": -15,
      "y": 3,
      "z": 5,
      "name": "Rock_Shale_Cobble",
      "rotation": 1
    },
    {
      "x": -15,
      "y": 4,
      "z": 5,
      "name": "Rock_Shale_Cobble",
      "rotation": 1
    },
    {
      "x": -15,
      "y": 5,
      "z": 5,
      "name": "Rock_Shale_Cobble",
      "rotation": 1
    },
    {
      "x": -15,
      "y": 6,
      "z": 5,
      "name": "Rock_Shale_Cobble",
      "rotation": 1
    },
    {
      "x": -15,
      "y": 7,
      "z": 5,
      "name": "Rock_Shale_Cobble",
      "rotation": 1
    },
    {
      "x": -15,
      "y": 8,
      "z": 5,
      "name": "Rock_Shale_Cobble",
      "rotation": 1
    },
    {
      "x": -15,
      "y": 3,
      "z": 6,
      "name": "Rock_Shale_Cobble",
      "rotation": 1
    },
    {
      "x": -15,
      "y": 4,
      "z": 6,
      "name": "Rock_Shale_Cobble",
      "rotation": 1
    },
    {
      "x": -15,
      "y": 5,
      "z": 6,
      "name": "Rock_Shale_Cobble",
      "rotation": 1
    },
    {
      "x": -15,
      "y": 6,
      "z": 6,
      "name": "Rock_Shale_Cobble",
      "rotation": 1
    },
    {
      "x": -15,
      "y": 7,
      "z": 6,
      "name": "Rock_Shale_Cobble",
      "rotation": 1
    },
    {
      "x": -15,
      "y": 8,
      "z": 6,
      "name": "Rock_Shale_Cobble",
      "rotation": 1
    },
    {
      "x": -15,
      "y": 3,
      "z": 7,
      "name": "Rock_Shale_Cobble",
      "rotation": 1
    },
    {
      "x": -15,
      "y": 4,
      "z": 7,
      "name": "Rock_Shale_Cobble",
      "rotation": 1
    },
    {
      "x": -15,
      "y": 5,
      "z": 7,
      "name": "Rock_Shale_Cobble",
      "rotation": 1
    },
    {
      "x": -15,
      "y": 6,
      "z": 7,
      "name": "Rock_Shale_Cobble",
      "rotation": 1
    },
    {
      "x": -15,
      "y": 7,
      "z": 7,
      "name": "Rock_Shale_Cobble",
      "rotation": 1
    },
    {
      "x": -15,
      "y": 8,
      "z": 7,
      "name": "Rock_Shale_Cobble",
      "rotation": 1
    },
    {
      "x": -15,
      "y": 3,
      "z": 8,
      "name": "Rock_Shale_Cobble",
      "rotation": 1
    },
    {
      "x": -15,
      "y": 4,
      "z": 8,
      "name": "Rock_Shale_Cobble",
      "rotation": 1
    },
    {
      "x": -15,
      "y": 5,
      "z": 8,
      "name": "Rock_Shale_Cobble",
      "rotation": 1
    },
    {
      "x": -15,
      "y": 6,
      "z": 8,
      "name": "Rock_Shale_Cobble",
      "rotation": 1
    },
    {
      "x": -15,
      "y": 7,
      "z": 8,
      "name": "Rock_Shale_Cobble",
      "rotation": 1
    },
    {
      "x": -15,
      "y": 8,
      "z": 8,
      "name": "Rock_Shale_Cobble",
      "rotation": 1
    },
    {
      "x": -15,
      "y": 4,
      "z": 9,
      "name": "Rock_Shale_Cobble_Half",
      "rotation": 16
    },
    {
      "x": -15,
      "y": 7,
      "z": 9,
      "name": "Rock_Shale_Cobble_Half",
      "rotation": 16
    },
    {
      "x": -15,
      "y": 4,
      "z": 10,
      "name": "Rock_Shale_Cobble_Half",
      "rotation": 16
    },
    {
      "x": -15,
      "y": 7,
      "z": 10,
      "name": "Rock_Shale_Cobble_Half",
      "rotation": 16
    },
    {
      "x": -14,
      "y": 4,
      "z": -5,
      "name": "Plant_Moss_Rug_Green_Dark",
      "rotation": 12
    },
    {
      "x": -14,
      "y": 8,
      "z": -5,
      "name": "Plant_Moss_Rug_Green_Dark",
      "rotation": 12
    },
    {
      "x": -14,
      "y": 3,
      "z": -4,
      "name": "Rock_Shale_Cobble"
    },
    {
      "x": -14,
      "y": 4,
      "z": -4,
      "name": "Rock_Shale_Cobble"
    },
    {
      "x": -14,
      "y": 8,
      "z": -4,
      "name": "Rock_Shale_Cobble"
    },
    {
      "x": -14,
      "y": 9,
      "z": -4,
      "name": "Metal_Iron_Glowing_Pipe",
      "rotation": 12
    },
    {
      "x": -14,
      "y": 2,
      "z": -3,
      "name": "Plant_Moss_Rug_Green_Dark",
      "rotation": 12
    },
    {
      "x": -14,
      "y": 3,
      "z": -3,
      "name": "Rock_Shale_Cobble"
    },
    {
      "x": -14,
      "y": 4,
      "z": -3,
      "name": "Rock_Shale_Cobble"
    },
    {
      "x": -14,
      "y": 8,
      "z": -3,
      "name": "Rock_Shale_Cobble"
    },
    {
      "x": -14,
      "y": 9,
      "z": -3,
      "name": "Metal_Iron_Glowing_Pipe_Corner",
      "rotation": 12
    },
    {
      "x": -14,
      "y": 10,
      "z": -3,
      "name": "Plant_Moss_Rug_Green_Dark",
      "rotation": 12
    },
    {
      "x": -14,
      "y": 1,
      "z": -2,
      "name": "Rock_Shale_Brick_Smooth",
      "rotation": 27
    },
    {
      "x": -14,
      "y": 2,
      "z": -2,
      "name": "Rock_Shale_Cobble",
      "rotation": 27
    },
    {
      "x": -14,
      "y": 3,
      "z": -2,
      "name": "Rock_Shale_Cobble",
      "rotation": 16
    },
    {
      "x": -14,
      "y": 4,
      "z": -2,
      "name": "Rock_Shale_Cobble",
      "rotation": 10
    },
    {
      "x": -14,
      "y": 8,
      "z": -2,
      "name": "Rock_Shale_Cobble",
      "rotation": 10
    },
    {
      "x": -14,
      "y": 9,
      "z": -2,
      "name": "Rock_Shale_Cobble",
      "rotation": 16
    },
    {
      "x": -14,
      "y": 10,
      "z": -2,
      "name": "Rock_Shale_Brick_Smooth",
      "rotation": 27
    },
    {
      "x": -14,
      "y": 2,
      "z": -1,
      "name": "Rock_Shale_Cobble",
      "rotation": 16
    },
    {
      "x": -14,
      "y": 3,
      "z": -1,
      "name": "Rock_Shale_Cobble",
      "rotation": 10
    },
    {
      "x": -14,
      "y": 4,
      "z": -1,
      "name": "Rock_Shale_Cobble",
      "rotation": 10
    },
    {
      "x": -14,
      "y": 5,
      "z": -1,
      "name": "Build_Lightsource_Cyan",
      "rotation": 26
    },
    {
      "x": -14,
      "y": 6,
      "z": -1,
      "name": "Build_Lightsource_Cyan",
      "rotation": 26
    },
    {
      "x": -14,
      "y": 7,
      "z": -1,
      "name": "Rock_Shale_Cobble",
      "rotation": 10
    },
    {
      "x": -14,
      "y": 8,
      "z": -1,
      "name": "Rock_Shale_Cobble",
      "rotation": 10
    },
    {
      "x": -14,
      "y": 9,
      "z": -1,
      "name": "Metal_Iron_Glowing_Pipe_Corner",
      "rotation": 14
    },
    {
      "x": -14,
      "y": 2,
      "z": 0,
      "name": "Build_Lightsource_Cyan",
      "rotation": 1
    },
    {
      "x": -14,
      "y": 3,
      "z": 0,
      "name": "Build_Lightsource_Cyan",
      "rotation": 1
    },
    {
      "x": -14,
      "y": 4,
      "z": 0,
      "name": "Rock_Shale_Cobble",
      "rotation": 10
    },
    {
      "x": -14,
      "y": 5,
      "z": 0,
      "name": "Build_Lightsource_Cyan",
      "rotation": 26
    },
    {
      "x": -14,
      "y": 6,
      "z": 0,
      "name": "Build_Lightsource_Cyan",
      "rotation": 26
    },
    {
      "x": -14,
      "y": 7,
      "z": 0,
      "name": "Rock_Shale_Cobble",
      "rotation": 10
    },
    {
      "x": -14,
      "y": 8,
      "z": 0,
      "name": "Build_Lightsource_Cyan",
      "rotation": 1
    },
    {
      "x": -14,
      "y": 9,
      "z": 0,
      "name": "Build_Lightsource_Cyan",
      "rotation": 1
    },
    {
      "x": -14,
      "y": 1,
      "z": 1,
      "name": "Plant_Moss_Rug_Green_Dark",
      "rotation": 12
    },
    {
      "x": -14,
      "y": 2,
      "z": 1,
      "name": "Rock_Shale_Cobble",
      "rotation": 16
    },
    {
      "x": -14,
      "y": 3,
      "z": 1,
      "name": "Rock_Shale_Cobble",
      "rotation": 10
    },
    {
      "x": -14,
      "y": 4,
      "z": 1,
      "name": "Rock_Shale_Cobble",
      "rotation": 10
    },
    {
      "x": -14,
      "y": 5,
      "z": 1,
      "name": "Build_Lightsource_Cyan",
      "rotation": 27
    },
    {
      "x": -14,
      "y": 6,
      "z": 1,
      "name": "Build_Lightsource_Cyan",
      "rotation": 27
    },
    {
      "x": -14,
      "y": 7,
      "z": 1,
      "name": "Rock_Shale_Cobble",
      "rotation": 10
    },
    {
      "x": -14,
      "y": 8,
      "z": 1,
      "name": "Rock_Shale_Cobble",
      "rotation": 10
    },
    {
      "x": -14,
      "y": 9,
      "z": 1,
      "name": "Rock_Shale_Cobble",
      "rotation": 16
    },
    {
      "x": -14,
      "y": 10,
      "z": 1,
      "name": "Plant_Moss_Rug_Green_Dark",
      "rotation": 12
    },
    {
      "x": -14,
      "y": 0,
      "z": 2,
      "name": "Plant_Moss_Wall_Green_Dark",
      "rotation": 6
    },
    {
      "x": -14,
      "y": 1,
      "z": 2,
      "name": "Rock_Shale_Brick_Smooth",
      "rotation": 27
    },
    {
      "x": -14,
      "y": 2,
      "z": 2,
      "name": "Rock_Shale_Cobble",
      "rotation": 16
    },
    {
      "x": -14,
      "y": 3,
      "z": 2,
      "name": "Rock_Shale_Cobble",
      "rotation": 10
    },
    {
      "x": -14,
      "y": 4,
      "z": 2,
      "name": "Rock_Shale_Cobble",
      "rotation": 10
    },
    {
      "x": -14,
      "y": 5,
      "z": 2,
      "name": "Build_Lightsource_Cyan",
      "rotation": 26
    },
    {
      "x": -14,
      "y": 6,
      "z": 2,
      "name": "Build_Lightsource_Cyan",
      "rotation": 26
    },
    {
      "x": -14,
      "y": 7,
      "z": 2,
      "name": "Rock_Shale_Cobble",
      "rotation": 10
    },
    {
      "x": -14,
      "y": 8,
      "z": 2,
      "name": "Rock_Shale_Cobble",
      "rotation": 10
    },
    {
      "x": -14,
      "y": 9,
      "z": 2,
      "name": "Rock_Shale_Cobble",
      "rotation": 16
    },
    {
      "x": -14,
      "y": 10,
      "z": 2,
      "name": "Rock_Shale_Brick_Smooth",
      "rotation": 27
    },
    {
      "x": -14,
      "y": 3,
      "z": 3,
      "name": "Rock_Shale_Cobble",
      "rotation": 1
    },
    {
      "x": -14,
      "y": 4,
      "z": 3,
      "name": "Rock_Shale_Cobble",
      "rotation": 1
    },
    {
      "x": -14,
      "y": 5,
      "z": 3,
      "name": "Build_Lightsource_Cyan",
      "rotation": 26
    },
    {
      "x": -14,
      "y": 6,
      "z": 3,
      "name": "Build_Lightsource_Cyan",
      "rotation": 26
    },
    {
      "x": -14,
      "y": 7,
      "z": 3,
      "name": "Rock_Shale_Cobble",
      "rotation": 1
    },
    {
      "x": -14,
      "y": 8,
      "z": 3,
      "name": "Rock_Shale_Cobble",
      "rotation": 1
    },
    {
      "x": -14,
      "y": 3,
      "z": 4,
      "name": "Rock_Shale_Cobble",
      "rotation": 1
    },
    {
      "x": -14,
      "y": 4,
      "z": 4,
      "name": "Rock_Shale_Cobble",
      "rotation": 1
    },
    {
      "x": -14,
      "y": 5,
      "z": 4,
      "name": "Rock_Shale_Cobble",
      "rotation": 27
    },
    {
      "x": -14,
      "y": 6,
      "z": 4,
      "name": "Rock_Shale_Cobble",
      "rotation": 27
    },
    {
      "x": -14,
      "y": 7,
      "z": 4,
      "name": "Rock_Shale_Cobble",
      "rotation": 1
    },
    {
      "x": -14,
      "y": 8,
      "z": 4,
      "name": "Rock_Shale_Cobble",
      "rotation": 1
    },
    {
      "x": -14,
      "y": 3,
      "z": 5,
      "name": "Rock_Shale_Cobble",
      "rotation": 1
    },
    {
      "x": -14,
      "y": 4,
      "z": 5,
      "name": "Rock_Shale_Cobble",
      "rotation": 1
    },
    {
      "x": -14,
      "y": 5,
      "z": 5,
      "name": "Rock_Shale_Cobble",
      "rotation": 1
    },
    {
      "x": -14,
      "y": 6,
      "z": 5,
      "name": "Rock_Shale_Cobble",
      "rotation": 1
    },
    {
      "x": -14,
      "y": 7,
      "z": 5,
      "name": "Rock_Shale_Cobble",
      "rotation": 1
    },
    {
      "x": -14,
      "y": 8,
      "z": 5,
      "name": "Rock_Shale_Cobble",
      "rotation": 1
    },
    {
      "x": -14,
      "y": 3,
      "z": 6,
      "name": "Rock_Shale_Cobble",
      "rotation": 1
    },
    {
      "x": -14,
      "y": 4,
      "z": 6,
      "name": "Rock_Shale_Cobble",
      "rotation": 1
    },
    {
      "x": -14,
      "y": 5,
      "z": 6,
      "name": "Rock_Shale_Cobble",
      "rotation": 1
    },
    {
      "x": -14,
      "y": 6,
      "z": 6,
      "name": "Rock_Shale_Cobble",
      "rotation": 1
    },
    {
      "x": -14,
      "y": 7,
      "z": 6,
      "name": "Rock_Shale_Cobble",
      "rotation": 1
    },
    {
      "x": -14,
      "y": 8,
      "z": 6,
      "name": "Rock_Shale_Cobble",
      "rotation": 1
    },
    {
      "x": -14,
      "y": 3,
      "z": 7,
      "name": "Rock_Shale_Cobble",
      "rotation": 1
    },
    {
      "x": -14,
      "y": 4,
      "z": 7,
      "name": "Rock_Shale_Cobble",
      "rotation": 1
    },
    {
      "x": -14,
      "y": 5,
      "z": 7,
      "name": "Rock_Shale_Cobble",
      "rotation": 1
    },
    {
      "x": -14,
      "y": 6,
      "z": 7,
      "name": "Rock_Shale_Cobble",
      "rotation": 1
    },
    {
      "x": -14,
      "y": 7,
      "z": 7,
      "name": "Rock_Shale_Cobble",
      "rotation": 1
    },
    {
      "x": -14,
      "y": 8,
      "z": 7,
      "name": "Rock_Shale_Cobble",
      "rotation": 1
    },
    {
      "x": -14,
      "y": 9,
      "z": 7,
      "name": "Metal_Iron_Glowing_Pipe_Corner",
      "rotation": 18
    },
    {
      "x": -14,
      "y": 3,
      "z": 8,
      "name": "Rock_Shale_Cobble",
      "rotation": 1
    },
    {
      "x": -14,
      "y": 4,
      "z": 8,
      "name": "Rock_Shale_Cobble",
      "rotation": 1
    },
    {
      "x": -14,
      "y": 5,
      "z": 8,
      "name": "Rock_Shale_Cobble",
      "rotation": 1
    },
    {
      "x": -14,
      "y": 6,
      "z": 8,
      "name": "Rock_Shale_Cobble",
      "rotation": 1
    },
    {
      "x": -14,
      "y": 7,
      "z": 8,
      "name": "Rock_Shale_Cobble",
      "rotation": 1
    },
    {
      "x": -14,
      "y": 8,
      "z": 8,
      "name": "Rock_Shale_Cobble",
      "rotation": 1
    },
    {
      "x": -14,
      "y": 9,
      "z": 8,
      "name": "Metal_Iron_Glowing_Pipe_Corner",
      "rotation": 12
    },
    {
      "x": -14,
      "y": 3,
      "z": 9,
      "name": "Rock_Shale_Cobble",
      "rotation": 1
    },
    {
      "x": -14,
      "y": 4,
      "z": 9,
      "name": "Rock_Shale_Cobble",
      "rotation": 1
    },
    {
      "x": -14,
      "y": 5,
      "z": 9,
      "name": "Rock_Shale_Cobble",
      "rotation": 1
    },
    {
      "x": -14,
      "y": 6,
      "z": 9,
      "name": "Rock_Shale_Cobble",
      "rotation": 1
    },
    {
      "x": -14,
      "y": 7,
      "z": 9,
      "name": "Rock_Shale_Cobble",
      "rotation": 1
    },
    {
      "x": -14,
      "y": 8,
      "z": 9,
      "name": "Rock_Shale_Cobble",
      "rotation": 1
    },
    {
      "x": -14,
      "y": 3,
      "z": 10,
      "name": "Rock_Shale_Cobble",
      "rotation": 1
    },
    {
      "x": -14,
      "y": 4,
      "z": 10,
      "name": "Rock_Shale_Cobble",
      "rotation": 1
    },
    {
      "x": -14,
      "y": 5,
      "z": 10,
      "name": "Rock_Shale_Cobble",
      "rotation": 1
    },
    {
      "x": -14,
      "y": 6,
      "z": 10,
      "name": "Rock_Shale_Cobble",
      "rotation": 1
    },
    {
      "x": -14,
      "y": 7,
      "z": 10,
      "name": "Rock_Shale_Cobble",
      "rotation": 1
    },
    {
      "x": -14,
      "y": 8,
      "z": 10,
      "name": "Rock_Shale_Cobble",
      "rotation": 1
    },
    {
      "x": -14,
      "y": 4,
      "z": 11,
      "name": "Rock_Shale_Cobble_Half",
      "rotation": 16
    },
    {
      "x": -14,
      "y": 7,
      "z": 11,
      "name": "Rock_Shale_Cobble_Half",
      "rotation": 16
    },
    {
      "x": -13,
      "y": 6,
      "z": -5,
      "name": "Plant_Moss_Rug_Green_Dark",
      "rotation": 12
    },
    {
      "x": -13,
      "y": 7,
      "z": -5,
      "name": "Plant_Moss_Rug_Green_Dark",
      "rotation": 12
    },
    {
      "x": -13,
      "y": 8,
      "z": -5,
      "name": "Plant_Moss_Rug_Green_Dark",
      "rotation": 12
    },
    {
      "x": -13,
      "y": 5,
      "z": -4,
      "name": "Build_Lightsource_Cyan",
      "rotation": 26
    },
    {
      "x": -13,
      "y": 6,
      "z": -4,
      "name": "Build_Lightsource_Cyan",
      "rotation": 26
    },
    {
      "x": -13,
      "y": 7,
      "z": -4,
      "name": "Rock_Shale_Cobble",
      "rotation": 27
    },
    {
      "x": -13,
      "y": 8,
      "z": -4,
      "name": "Rock_Shale_Cobble",
      "rotation": 27
    },
    {
      "x": -13,
      "y": 9,
      "z": -4,
      "name": "Plant_Moss_Wall_Green_Dark",
      "rotation": 12
    },
    {
      "x": -13,
      "y": 7,
      "z": -3,
      "name": "Rock_Shale_Brick_Smooth",
      "rotation": 27
    },
    {
      "x": -13,
      "y": 8,
      "z": -3,
      "name": "Plant_Moss_Rug_Green_Dark",
      "rotation": 12
    },
    {
      "x": -13,
      "y": 2,
      "z": -2,
      "name": "Plant_Moss_Wall_Green_Dark",
      "rotation": 27
    },
    {
      "x": -13,
      "y": 5,
      "z": -2,
      "name": "Rock_Shale_Cobble",
      "rotation": 10
    },
    {
      "x": -13,
      "y": 6,
      "z": -2,
      "name": "Rock_Shale_Cobble",
      "rotation": 27
    },
    {
      "x": -13,
      "y": 7,
      "z": -2,
      "name": "Rock_Shale_Cobble",
      "rotation": 27
    },
    {
      "x": -13,
      "y": 8,
      "z": -2,
      "name": "Rock_Shale_Cobble",
      "rotation": 10
    },
    {
      "x": -13,
      "y": 9,
      "z": -2,
      "name": "Rock_Shale_Brick_Smooth",
      "rotation": 27
    },
    {
      "x": -13,
      "y": 3,
      "z": -1,
      "name": "Rock_Shale_Cobble",
      "rotation": 27
    },
    {
      "x": -13,
      "y": 4,
      "z": -1,
      "name": "Rock_Shale_Brick_Smooth",
      "rotation": 27
    },
    {
      "x": -13,
      "y": 5,
      "z": -1,
      "name": "Rock_Shale_Cobble",
      "rotation": 27
    },
    {
      "x": -13,
      "y": 6,
      "z": -1,
      "name": "Rock_Shale_Cobble",
      "rotation": 27
    },
    {
      "x": -13,
      "y": 7,
      "z": -1,
      "name": "Rock_Shale_Brick_Smooth",
      "rotation": 27
    },
    {
      "x": -13,
      "y": 8,
      "z": -1,
      "name": "Rock_Shale_Cobble",
      "rotation": 27
    },
    {
      "x": -13,
      "y": 3,
      "z": 0,
      "name": "Plant_Moss_Rug_Green_Dark",
      "rotation": 12
    },
    {
      "x": -13,
      "y": 4,
      "z": 0,
      "name": "Rock_Shale_Brick_Smooth",
      "rotation": 27
    },
    {
      "x": -13,
      "y": 7,
      "z": 0,
      "name": "Rock_Shale_Brick_Smooth",
      "rotation": 27
    },
    {
      "x": -13,
      "y": 8,
      "z": 0,
      "name": "Plant_Moss_Rug_Green_Dark",
      "rotation": 12
    },
    {
      "x": -13,
      "y": 3,
      "z": 1,
      "name": "Rock_Shale_Cobble",
      "rotation": 27
    },
    {
      "x": -13,
      "y": 4,
      "z": 1,
      "name": "Rock_Shale_Brick_Smooth",
      "rotation": 27
    },
    {
      "x": -13,
      "y": 5,
      "z": 1,
      "name": "Rock_Shale_Cobble",
      "rotation": 27
    },
    {
      "x": -13,
      "y": 6,
      "z": 1,
      "name": "Rock_Shale_Cobble",
      "rotation": 27
    },
    {
      "x": -13,
      "y": 7,
      "z": 1,
      "name": "Rock_Shale_Brick_Smooth",
      "rotation": 27
    },
    {
      "x": -13,
      "y": 8,
      "z": 1,
      "name": "Rock_Shale_Cobble",
      "rotation": 27
    },
    {
      "x": -13,
      "y": 9,
      "z": 1,
      "name": "Plant_Moss_Rug_Green_Dark",
      "rotation": 12
    },
    {
      "x": -13,
      "y": 2,
      "z": 2,
      "name": "Rock_Shale_Brick_Smooth",
      "rotation": 27
    },
    {
      "x": -13,
      "y": 3,
      "z": 2,
      "name": "Rock_Shale_Cobble",
      "rotation": 16
    },
    {
      "x": -13,
      "y": 4,
      "z": 2,
      "name": "Rock_Shale_Cobble",
      "rotation": 10
    },
    {
      "x": -13,
      "y": 5,
      "z": 2,
      "name": "Rock_Shale_Cobble",
      "rotation": 10
    },
    {
      "x": -13,
      "y": 6,
      "z": 2,
      "name": "Rock_Shale_Cobble",
      "rotation": 10
    },
    {
      "x": -13,
      "y": 7,
      "z": 2,
      "name": "Rock_Shale_Cobble",
      "rotation": 10
    },
    {
      "x": -13,
      "y": 8,
      "z": 2,
      "name": "Rock_Shale_Cobble",
      "rotation": 16
    },
    {
      "x": -13,
      "y": 9,
      "z": 2,
      "name": "Rock_Shale_Brick_Smooth",
      "rotation": 27
    },
    {
      "x": -13,
      "y": 4,
      "z": 3,
      "name": "Rock_Shale_Brick_Smooth",
      "rotation": 27
    },
    {
      "x": -13,
      "y": 7,
      "z": 3,
      "name": "Rock_Shale_Brick_Smooth",
      "rotation": 27
    },
    {
      "x": -13,
      "y": 3,
      "z": 4,
      "name": "Rock_Shale_Cobble",
      "rotation": 27
    },
    {
      "x": -13,
      "y": 4,
      "z": 4,
      "name": "Rock_Shale_Cobble",
      "rotation": 1
    },
    {
      "x": -13,
      "y": 5,
      "z": 4,
      "name": "Build_Lightsource_Cyan",
      "rotation": 26
    },
    {
      "x": -13,
      "y": 6,
      "z": 4,
      "name": "Build_Lightsource_Cyan",
      "rotation": 26
    },
    {
      "x": -13,
      "y": 7,
      "z": 4,
      "name": "Rock_Shale_Cobble",
      "rotation": 1
    },
    {
      "x": -13,
      "y": 8,
      "z": 4,
      "name": "Rock_Shale_Cobble",
      "rotation": 1
    },
    {
      "x": -13,
      "y": 3,
      "z": 5,
      "name": "Rock_Shale_Cobble",
      "rotation": 1
    },
    {
      "x": -13,
      "y": 4,
      "z": 5,
      "name": "Rock_Shale_Cobble",
      "rotation": 1
    },
    {
      "x": -13,
      "y": 5,
      "z": 5,
      "name": "Build_Lightsource_Cyan",
      "rotation": 26
    },
    {
      "x": -13,
      "y": 6,
      "z": 5,
      "name": "Build_Lightsource_Cyan",
      "rotation": 26
    },
    {
      "x": -13,
      "y": 7,
      "z": 5,
      "name": "Rock_Shale_Cobble",
      "rotation": 1
    },
    {
      "x": -13,
      "y": 8,
      "z": 5,
      "name": "Rock_Shale_Cobble",
      "rotation": 1
    },
    {
      "x": -13,
      "y": 3,
      "z": 6,
      "name": "Rock_Shale_Cobble",
      "rotation": 1
    },
    {
      "x": -13,
      "y": 4,
      "z": 6,
      "name": "Rock_Shale_Cobble",
      "rotation": 1
    },
    {
      "x": -13,
      "y": 5,
      "z": 6,
      "name": "Build_Lightsource_Cyan",
      "rotation": 26
    },
    {
      "x": -13,
      "y": 6,
      "z": 6,
      "name": "Build_Lightsource_Cyan",
      "rotation": 26
    },
    {
      "x": -13,
      "y": 7,
      "z": 6,
      "name": "Rock_Shale_Cobble",
      "rotation": 1
    },
    {
      "x": -13,
      "y": 8,
      "z": 6,
      "name": "Rock_Shale_Cobble",
      "rotation": 1
    },
    {
      "x": -13,
      "y": 3,
      "z": 7,
      "name": "Rock_Shale_Cobble",
      "rotation": 1
    },
    {
      "x": -13,
      "y": 4,
      "z": 7,
      "name": "Rock_Shale_Cobble",
      "rotation": 1
    },
    {
      "x": -13,
      "y": 5,
      "z": 7,
      "name": "Rock_Shale_Cobble",
      "rotation": 1
    },
    {
      "x": -13,
      "y": 6,
      "z": 7,
      "name": "Rock_Shale_Cobble",
      "rotation": 1
    },
    {
      "x": -13,
      "y": 7,
      "z": 7,
      "name": "Rock_Shale_Cobble",
      "rotation": 1
    },
    {
      "x": -13,
      "y": 8,
      "z": 7,
      "name": "Rock_Shale_Cobble",
      "rotation": 1
    },
    {
      "x": -13,
      "y": 9,
      "z": 7,
      "name": "Metal_Iron_Glowing_Pipe",
      "rotation": 26
    },
    {
      "x": -13,
      "y": 3,
      "z": 8,
      "name": "Rock_Shale_Cobble",
      "rotation": 1
    },
    {
      "x": -13,
      "y": 4,
      "z": 8,
      "name": "Rock_Shale_Cobble",
      "rotation": 1
    },
    {
      "x": -13,
      "y": 5,
      "z": 8,
      "name": "Rock_Shale_Cobble",
      "rotation": 1
    },
    {
      "x": -13,
      "y": 6,
      "z": 8,
      "name": "Rock_Shale_Cobble",
      "rotation": 27
    },
    {
      "x": -13,
      "y": 7,
      "z": 8,
      "name": "Rock_Shale_Cobble",
      "rotation": 1
    },
    {
      "x": -13,
      "y": 8,
      "z": 8,
      "name": "Rock_Shale_Cobble",
      "rotation": 1
    },
    {
      "x": -13,
      "y": 3,
      "z": 9,
      "name": "Rock_Shale_Cobble",
      "rotation": 1
    },
    {
      "x": -13,
      "y": 4,
      "z": 9,
      "name": "Rock_Shale_Cobble",
      "rotation": 1
    },
    {
      "x": -13,
      "y": 5,
      "z": 9,
      "name": "Rock_Shale_Cobble",
      "rotation": 1
    },
    {
      "x": -13,
      "y": 6,
      "z": 9,
      "name": "Rock_Shale_Cobble",
      "rotation": 1
    },
    {
      "x": -13,
      "y": 7,
      "z": 9,
      "name": "Rock_Shale_Cobble",
      "rotation": 1
    },
    {
      "x": -13,
      "y": 8,
      "z": 9,
      "name": "Rock_Shale_Cobble",
      "rotation": 1
    },
    {
      "x": -13,
      "y": 3,
      "z": 10,
      "name": "Rock_Shale_Cobble",
      "rotation": 1
    },
    {
      "x": -13,
      "y": 4,
      "z": 10,
      "name": "Rock_Shale_Cobble",
      "rotation": 1
    },
    {
      "x": -13,
      "y": 5,
      "z": 10,
      "name": "Rock_Shale_Cobble",
      "rotation": 1
    },
    {
      "x": -13,
      "y": 6,
      "z": 10,
      "name": "Rock_Shale_Cobble",
      "rotation": 1
    },
    {
      "x": -13,
      "y": 7,
      "z": 10,
      "name": "Rock_Shale_Cobble",
      "rotation": 1
    },
    {
      "x": -13,
      "y": 8,
      "z": 10,
      "name": "Rock_Shale_Cobble",
      "rotation": 1
    },
    {
      "x": -13,
      "y": 3,
      "z": 11,
      "name": "Rock_Shale_Cobble",
      "rotation": 1
    },
    {
      "x": -13,
      "y": 4,
      "z": 11,
      "name": "Rock_Shale_Cobble",
      "rotation": 1
    },
    {
      "x": -13,
      "y": 5,
      "z": 11,
      "name": "Rock_Shale_Cobble",
      "rotation": 1
    },
    {
      "x": -13,
      "y": 6,
      "z": 11,
      "name": "Rock_Shale_Cobble",
      "rotation": 1
    },
    {
      "x": -13,
      "y": 7,
      "z": 11,
      "name": "Rock_Shale_Cobble",
      "rotation": 1
    },
    {
      "x": -13,
      "y": 8,
      "z": 11,
      "name": "Rock_Shale_Cobble",
      "rotation": 1
    },
    {
      "x": -13,
      "y": 4,
      "z": 12,
      "name": "Rock_Shale_Cobble_Half",
      "rotation": 16
    },
    {
      "x": -13,
      "y": 7,
      "z": 12,
      "name": "Rock_Shale_Cobble_Half",
      "rotation": 16
    },
    {
      "x": -12,
      "y": 6,
      "z": -4,
      "name": "Plant_Moss_Wall_Green_Dark",
      "rotation": 27
    },
    {
      "x": -12,
      "y": 7,
      "z": -4,
      "name": "Rock_Shale_Brick_Smooth",
      "rotation": 27
    },
    {
      "x": -12,
      "y": 6,
      "z": -3,
      "name": "Plant_Moss_Rug_Green_Dark",
      "rotation": 12
    },
    {
      "x": -12,
      "y": 8,
      "z": -3,
      "name": "Plant_Moss_Rug_Green_Dark",
      "rotation": 12
    },
    {
      "x": -12,
      "y": 5,
      "z": -2,
      "name": "Rock_Shale_Brick_Smooth",
      "rotation": 27
    },
    {
      "x": -12,
      "y": 6,
      "z": -2,
      "name": "Rock_Shale_Brick_Smooth",
      "rotation": 27
    },
    {
      "x": -12,
      "y": 7,
      "z": -2,
      "name": "Rock_Shale_Brick_Smooth",
      "rotation": 27
    },
    {
      "x": -12,
      "y": 8,
      "z": -2,
      "name": "Rock_Shale_Brick_Smooth",
      "rotation": 27
    },
    {
      "x": -12,
      "y": 9,
      "z": -2,
      "name": "Plant_Moss_Wall_Green_Dark",
      "rotation": 12
    },
    {
      "x": -12,
      "y": 3,
      "z": 1,
      "name": "Plant_Moss_Rug_Green_Dark",
      "rotation": 12
    },
    {
      "x": -12,
      "y": 4,
      "z": 1,
      "name": "Plant_Moss_Rug_Green_Dark",
      "rotation": 12
    },
    {
      "x": -12,
      "y": 8,
      "z": 1,
      "name": "Plant_Moss_Rug_Green_Dark",
      "rotation": 12
    },
    {
      "x": -12,
      "y": 2,
      "z": 2,
      "name": "Plant_Moss_Wall_Green_Dark",
      "rotation": 6
    },
    {
      "x": -12,
      "y": 3,
      "z": 2,
      "name": "Rock_Shale_Brick_Smooth",
      "rotation": 27
    },
    {
      "x": -12,
      "y": 4,
      "z": 2,
      "name": "Rock_Shale_Brick_Smooth",
      "rotation": 27
    },
    {
      "x": -12,
      "y": 5,
      "z": 2,
      "name": "Rock_Shale_Brick_Smooth",
      "rotation": 27
    },
    {
      "x": -12,
      "y": 6,
      "z": 2,
      "name": "Rock_Shale_Brick_Smooth",
      "rotation": 27
    },
    {
      "x": -12,
      "y": 7,
      "z": 2,
      "name": "Rock_Shale_Brick_Smooth",
      "rotation": 27
    },
    {
      "x": -12,
      "y": 8,
      "z": 2,
      "name": "Rock_Shale_Brick_Smooth",
      "rotation": 27
    },
    {
      "x": -12,
      "y": 4,
      "z": 3,
      "name": "Plant_Moss_Rug_Green_Dark",
      "rotation": 12
    },
    {
      "x": -12,
      "y": 7,
      "z": 3,
      "name": "Plant_Moss_Rug_Green_Dark",
      "rotation": 12
    },
    {
      "x": -12,
      "y": 4,
      "z": 4,
      "name": "Rock_Shale_Brick_Smooth",
      "rotation": 27
    },
    {
      "x": -12,
      "y": 7,
      "z": 4,
      "name": "Rock_Shale_Brick_Smooth",
      "rotation": 27
    },
    {
      "x": -12,
      "y": 4,
      "z": 5,
      "name": "Rock_Shale_Brick_Smooth",
      "rotation": 27
    },
    {
      "x": -12,
      "y": 7,
      "z": 5,
      "name": "Rock_Shale_Brick_Smooth",
      "rotation": 27
    },
    {
      "x": -12,
      "y": 4,
      "z": 6,
      "name": "Rock_Shale_Brick_Smooth",
      "rotation": 27
    },
    {
      "x": -12,
      "y": 7,
      "z": 6,
      "name": "Rock_Shale_Brick_Smooth",
      "rotation": 27
    },
    {
      "x": -12,
      "y": 8,
      "z": 6,
      "name": "Plant_Moss_Rug_Green_Dark",
      "rotation": 12
    },
    {
      "x": -12,
      "y": 3,
      "z": 7,
      "name": "Rock_Shale_Cobble",
      "rotation": 1
    },
    {
      "x": -12,
      "y": 4,
      "z": 7,
      "name": "Rock_Shale_Cobble",
      "rotation": 1
    },
    {
      "x": -12,
      "y": 5,
      "z": 7,
      "name": "Build_Lightsource_Cyan",
      "rotation": 27
    },
    {
      "x": -12,
      "y": 6,
      "z": 7,
      "name": "Build_Lightsource_Cyan",
      "rotation": 27
    },
    {
      "x": -12,
      "y": 7,
      "z": 7,
      "name": "Rock_Shale_Cobble",
      "rotation": 27
    },
    {
      "x": -12,
      "y": 8,
      "z": 7,
      "name": "Rock_Shale_Cobble",
      "rotation": 1
    },
    {
      "x": -12,
      "y": 9,
      "z": 7,
      "name": "Metal_Iron_Glowing_Pipe",
      "rotation": 26
    },
    {
      "x": -12,
      "y": 3,
      "z": 8,
      "name": "Rock_Shale_Cobble",
      "rotation": 1
    },
    {
      "x": -12,
      "y": 4,
      "z": 8,
      "name": "Rock_Shale_Cobble",
      "rotation": 1
    },
    {
      "x": -12,
      "y": 5,
      "z": 8,
      "name": "Build_Lightsource_Cyan",
      "rotation": 27
    },
    {
      "x": -12,
      "y": 6,
      "z": 8,
      "name": "Build_Lightsource_Cyan",
      "rotation": 27
    },
    {
      "x": -12,
      "y": 7,
      "z": 8,
      "name": "Rock_Shale_Cobble",
      "rotation": 1
    },
    {
      "x": -12,
      "y": 8,
      "z": 8,
      "name": "Rock_Shale_Cobble",
      "rotation": 1
    },
    {
      "x": -12,
      "y": 3,
      "z": 9,
      "name": "Rock_Shale_Cobble",
      "rotation": 1
    },
    {
      "x": -12,
      "y": 4,
      "z": 9,
      "name": "Rock_Shale_Cobble",
      "rotation": 1
    },
    {
      "x": -12,
      "y": 5,
      "z": 9,
      "name": "Rock_Shale_Cobble",
      "rotation": 1
    },
    {
      "x": -12,
      "y": 6,
      "z": 9,
      "name": "Rock_Shale_Cobble",
      "rotation": 1
    },
    {
      "x": -12,
      "y": 7,
      "z": 9,
      "name": "Rock_Shale_Cobble",
      "rotation": 1
    },
    {
      "x": -12,
      "y": 8,
      "z": 9,
      "name": "Rock_Shale_Cobble",
      "rotation": 1
    },
    {
      "x": -12,
      "y": 3,
      "z": 10,
      "name": "Rock_Shale_Cobble",
      "rotation": 1
    },
    {
      "x": -12,
      "y": 4,
      "z": 10,
      "name": "Rock_Shale_Cobble",
      "rotation": 1
    },
    {
      "x": -12,
      "y": 5,
      "z": 10,
      "name": "Rock_Shale_Cobble",
      "rotation": 1
    },
    {
      "x": -12,
      "y": 6,
      "z": 10,
      "name": "Rock_Shale_Cobble",
      "rotation": 1
    },
    {
      "x": -12,
      "y": 7,
      "z": 10,
      "name": "Rock_Shale_Cobble",
      "rotation": 1
    },
    {
      "x": -12,
      "y": 8,
      "z": 10,
      "name": "Rock_Shale_Cobble",
      "rotation": 1
    },
    {
      "x": -12,
      "y": 3,
      "z": 11,
      "name": "Rock_Shale_Cobble",
      "rotation": 1
    },
    {
      "x": -12,
      "y": 4,
      "z": 11,
      "name": "Rock_Shale_Cobble",
      "rotation": 1
    },
    {
      "x": -12,
      "y": 5,
      "z": 11,
      "name": "Rock_Shale_Cobble",
      "rotation": 1
    },
    {
      "x": -12,
      "y": 6,
      "z": 11,
      "name": "Rock_Shale_Cobble",
      "rotation": 1
    },
    {
      "x": -12,
      "y": 7,
      "z": 11,
      "name": "Rock_Shale_Cobble",
      "rotation": 1
    },
    {
      "x": -12,
      "y": 8,
      "z": 11,
      "name": "Rock_Shale_Cobble",
      "rotation": 1
    },
    {
      "x": -12,
      "y": 3,
      "z": 12,
      "name": "Rock_Shale_Cobble",
      "rotation": 1
    },
    {
      "x": -12,
      "y": 4,
      "z": 12,
      "name": "Rock_Shale_Cobble",
      "rotation": 1
    },
    {
      "x": -12,
      "y": 5,
      "z": 12,
      "name": "Rock_Shale_Cobble",
      "rotation": 1
    },
    {
      "x": -12,
      "y": 6,
      "z": 12,
      "name": "Rock_Shale_Cobble",
      "rotation": 1
    },
    {
      "x": -12,
      "y": 7,
      "z": 12,
      "name": "Rock_Shale_Cobble",
      "rotation": 1
    },
    {
      "x": -12,
      "y": 8,
      "z": 12,
      "name": "Rock_Shale_Cobble",
      "rotation": 1
    },
    {
      "x": -12,
      "y": 4,
      "z": 13,
      "name": "Rock_Shale_Cobble_Half",
      "rotation": 25
    },
    {
      "x": -12,
      "y": 7,
      "z": 13,
      "name": "Rock_Shale_Cobble_Half",
      "rotation": 25
    },
    {
      "x": -11,
      "y": 3,
      "z": 2,
      "name": "Plant_Moss_Wall_Green_Dark",
      "rotation": 27
    },
    {
      "x": -11,
      "y": 7,
      "z": 6,
      "name": "Plant_Moss_Rug_Green_Dark",
      "rotation": 12
    },
    {
      "x": -11,
      "y": 4,
      "z": 7,
      "name": "Rock_Shale_Brick_Smooth",
      "rotation": 27
    },
    {
      "x": -11,
      "y": 7,
      "z": 7,
      "name": "Rock_Shale_Brick_Smooth",
      "rotation": 27
    },
    {
      "x": -11,
      "y": 8,
      "z": 7,
      "name": "Plant_Moss_Wall_Green_Dark",
      "rotation": 27
    },
    {
      "x": -11,
      "y": 9,
      "z": 7,
      "name": "Metal_Iron_Glowing_Pipe_Corner",
      "rotation": 17
    },
    {
      "x": -11,
      "y": 3,
      "z": 8,
      "name": "Plant_Moss_Rug_Green_Dark",
      "rotation": 12
    },
    {
      "x": -11,
      "y": 4,
      "z": 8,
      "name": "Rock_Shale_Brick_Smooth",
      "rotation": 27
    },
    {
      "x": -11,
      "y": 7,
      "z": 8,
      "name": "Rock_Shale_Brick_Smooth",
      "rotation": 27
    },
    {
      "x": -11,
      "y": 9,
      "z": 8,
      "name": "Metal_Iron_Glowing_Pipe_Corner",
      "rotation": 19
    },
    {
      "x": -11,
      "y": 2,
      "z": 9,
      "name": "Plant_Moss_Wall_Green_Dark",
      "rotation": 6
    },
    {
      "x": -11,
      "y": 3,
      "z": 9,
      "name": "Rock_Shale_Cobble",
      "rotation": 1
    },
    {
      "x": -11,
      "y": 4,
      "z": 9,
      "name": "Rock_Shale_Cobble",
      "rotation": 1
    },
    {
      "x": -11,
      "y": 5,
      "z": 9,
      "name": "Build_Lightsource_Cyan",
      "rotation": 27
    },
    {
      "x": -11,
      "y": 6,
      "z": 9,
      "name": "Build_Lightsource_Cyan",
      "rotation": 27
    },
    {
      "x": -11,
      "y": 7,
      "z": 9,
      "name": "Rock_Shale_Cobble",
      "rotation": 1
    },
    {
      "x": -11,
      "y": 8,
      "z": 9,
      "name": "Rock_Shale_Cobble",
      "rotation": 27
    },
    {
      "x": -11,
      "y": 3,
      "z": 10,
      "name": "Rock_Shale_Cobble",
      "rotation": 1
    },
    {
      "x": -11,
      "y": 4,
      "z": 10,
      "name": "Rock_Shale_Cobble",
      "rotation": 1
    },
    {
      "x": -11,
      "y": 5,
      "z": 10,
      "name": "Rock_Shale_Cobble",
      "rotation": 1
    },
    {
      "x": -11,
      "y": 6,
      "z": 10,
      "name": "Rock_Shale_Cobble",
      "rotation": 27
    },
    {
      "x": -11,
      "y": 7,
      "z": 10,
      "name": "Rock_Shale_Cobble",
      "rotation": 27
    },
    {
      "x": -11,
      "y": 8,
      "z": 10,
      "name": "Rock_Shale_Cobble",
      "rotation": 27
    },
    {
      "x": -11,
      "y": 3,
      "z": 11,
      "name": "Rock_Shale_Cobble",
      "rotation": 1
    },
    {
      "x": -11,
      "y": 4,
      "z": 11,
      "name": "Rock_Shale_Cobble",
      "rotation": 1
    },
    {
      "x": -11,
      "y": 5,
      "z": 11,
      "name": "Rock_Shale_Cobble",
      "rotation": 1
    },
    {
      "x": -11,
      "y": 6,
      "z": 11,
      "name": "Rock_Shale_Cobble",
      "rotation": 1
    },
    {
      "x": -11,
      "y": 7,
      "z": 11,
      "name": "Rock_Shale_Cobble",
      "rotation": 1
    },
    {
      "x": -11,
      "y": 8,
      "z": 11,
      "name": "Rock_Shale_Cobble",
      "rotation": 1
    },
    {
      "x": -11,
      "y": 3,
      "z": 12,
      "name": "Rock_Shale_Cobble",
      "rotation": 1
    },
    {
      "x": -11,
      "y": 4,
      "z": 12,
      "name": "Rock_Shale_Cobble",
      "rotation": 1
    },
    {
      "x": -11,
      "y": 5,
      "z": 12,
      "name": "Rock_Shale_Cobble",
      "rotation": 1
    },
    {
      "x": -11,
      "y": 6,
      "z": 12,
      "name": "Rock_Shale_Cobble",
      "rotation": 1
    },
    {
      "x": -11,
      "y": 7,
      "z": 12,
      "name": "Rock_Shale_Cobble",
      "rotation": 1
    },
    {
      "x": -11,
      "y": 8,
      "z": 12,
      "name": "Rock_Shale_Cobble",
      "rotation": 1
    },
    {
      "x": -11,
      "y": 3,
      "z": 13,
      "name": "Rock_Shale_Cobble",
      "rotation": 1
    },
    {
      "x": -11,
      "y": 4,
      "z": 13,
      "name": "Rock_Shale_Cobble",
      "rotation": 1
    },
    {
      "x": -11,
      "y": 5,
      "z": 13,
      "name": "Rock_Shale_Cobble",
      "rotation": 1
    },
    {
      "x": -11,
      "y": 6,
      "z": 13,
      "name": "Rock_Shale_Cobble",
      "rotation": 1
    },
    {
      "x": -11,
      "y": 7,
      "z": 13,
      "name": "Rock_Shale_Cobble",
      "rotation": 1
    },
    {
      "x": -11,
      "y": 8,
      "z": 13,
      "name": "Rock_Shale_Cobble",
      "rotation": 1
    },
    {
      "x": -11,
      "y": 4,
      "z": 14,
      "name": "Rock_Shale_Cobble_Half",
      "rotation": 25
    },
    {
      "x": -11,
      "y": 7,
      "z": 14,
      "name": "Rock_Shale_Cobble_Half",
      "rotation": 25
    },
    {
      "x": -10,
      "y": 7,
      "z": 7,
      "name": "Plant_Moss_Wall_Green_Dark",
      "rotation": 27
    },
    {
      "x": -10,
      "y": 5,
      "z": 8,
      "name": "Metal_Iron_Glowing_Pipe_Corner",
      "rotation": 5
    },
    {
      "x": -10,
      "y": 6,
      "z": 8,
      "name": "Metal_Iron_Glowing_Pipe"
    },
    {
      "x": -10,
      "y": 7,
      "z": 8,
      "name": "Metal_Iron_Glowing_Pipe"
    },
    {
      "x": -10,
      "y": 8,
      "z": 8,
      "name": "Metal_Iron_Glowing_Pipe"
    },
    {
      "x": -10,
      "y": 9,
      "z": 8,
      "name": "Metal_Iron_Glowing_Pipe_Corner",
      "rotation": 11
    },
    {
      "x": -10,
      "y": 3,
      "z": 9,
      "name": "Plant_Moss_Rug_Green_Dark",
      "rotation": 12
    },
    {
      "x": -10,
      "y": 4,
      "z": 9,
      "name": "Rock_Shale_Brick_Smooth",
      "rotation": 27
    },
    {
      "x": -10,
      "y": 7,
      "z": 9,
      "name": "Rock_Shale_Brick_Smooth",
      "rotation": 27
    },
    {
      "x": -10,
      "y": 8,
      "z": 9,
      "name": "Plant_Moss_Rug_Green_Dark",
      "rotation": 12
    },
    {
      "x": -10,
      "y": 2,
      "z": 10,
      "name": "Plant_Moss_Wall_Green_Dark",
      "rotation": 6
    },
    {
      "x": -10,
      "y": 3,
      "z": 10,
      "name": "Rock_Shale_Cobble",
      "rotation": 1
    },
    {
      "x": -10,
      "y": 4,
      "z": 10,
      "name": "Rock_Shale_Cobble",
      "rotation": 1
    },
    {
      "x": -10,
      "y": 5,
      "z": 10,
      "name": "Build_Lightsource_Cyan",
      "rotation": 26
    },
    {
      "x": -10,
      "y": 6,
      "z": 10,
      "name": "Build_Lightsource_Cyan",
      "rotation": 26
    },
    {
      "x": -10,
      "y": 7,
      "z": 10,
      "name": "Rock_Shale_Cobble",
      "rotation": 1
    },
    {
      "x": -10,
      "y": 8,
      "z": 10,
      "name": "Rock_Shale_Cobble",
      "rotation": 1
    },
    {
      "x": -10,
      "y": 3,
      "z": 11,
      "name": "Rock_Shale_Cobble",
      "rotation": 1
    },
    {
      "x": -10,
      "y": 4,
      "z": 11,
      "name": "Rock_Shale_Cobble",
      "rotation": 1
    },
    {
      "x": -10,
      "y": 5,
      "z": 11,
      "name": "Build_Lightsource_Cyan",
      "rotation": 26
    },
    {
      "x": -10,
      "y": 6,
      "z": 11,
      "name": "Rock_Shale_Cobble",
      "rotation": 1
    },
    {
      "x": -10,
      "y": 7,
      "z": 11,
      "name": "Rock_Shale_Cobble",
      "rotation": 1
    },
    {
      "x": -10,
      "y": 8,
      "z": 11,
      "name": "Rock_Shale_Cobble",
      "rotation": 1
    },
    {
      "x": -10,
      "y": 3,
      "z": 12,
      "name": "Rock_Shale_Cobble",
      "rotation": 1
    },
    {
      "x": -10,
      "y": 4,
      "z": 12,
      "name": "Rock_Shale_Cobble",
      "rotation": 1
    },
    {
      "x": -10,
      "y": 5,
      "z": 12,
      "name": "Rock_Shale_Cobble",
      "rotation": 1
    },
    {
      "x": -10,
      "y": 6,
      "z": 12,
      "name": "Rock_Shale_Cobble",
      "rotation": 1
    },
    {
      "x": -10,
      "y": 7,
      "z": 12,
      "name": "Rock_Shale_Cobble",
      "rotation": 1
    },
    {
      "x": -10,
      "y": 8,
      "z": 12,
      "name": "Rock_Shale_Cobble",
      "rotation": 1
    },
    {
      "x": -10,
      "y": 3,
      "z": 13,
      "name": "Rock_Shale_Cobble",
      "rotation": 1
    },
    {
      "x": -10,
      "y": 4,
      "z": 13,
      "name": "Rock_Shale_Cobble",
      "rotation": 1
    },
    {
      "x": -10,
      "y": 5,
      "z": 13,
      "name": "Rock_Shale_Cobble",
      "rotation": 1
    },
    {
      "x": -10,
      "y": 6,
      "z": 13,
      "name": "Rock_Shale_Cobble",
      "rotation": 1
    },
    {
      "x": -10,
      "y": 7,
      "z": 13,
      "name": "Rock_Shale_Cobble",
      "rotation": 1
    },
    {
      "x": -10,
      "y": 8,
      "z": 13,
      "name": "Rock_Shale_Cobble",
      "rotation": 1
    },
    {
      "x": -10,
      "y": 3,
      "z": 14,
      "name": "Rock_Shale_Cobble",
      "rotation": 1
    },
    {
      "x": -10,
      "y": 4,
      "z": 14,
      "name": "Rock_Shale_Cobble",
      "rotation": 1
    },
    {
      "x": -10,
      "y": 5,
      "z": 14,
      "name": "Rock_Shale_Cobble",
      "rotation": 1
    },
    {
      "x": -10,
      "y": 6,
      "z": 14,
      "name": "Rock_Shale_Cobble",
      "rotation": 1
    },
    {
      "x": -10,
      "y": 7,
      "z": 14,
      "name": "Rock_Shale_Cobble",
      "rotation": 1
    },
    {
      "x": -10,
      "y": 8,
      "z": 14,
      "name": "Rock_Shale_Cobble",
      "rotation": 1
    },
    {
      "x": -10,
      "y": 4,
      "z": 15,
      "name": "Rock_Shale_Cobble_Half",
      "rotation": 25
    },
    {
      "x": -10,
      "y": 7,
      "z": 15,
      "name": "Rock_Shale_Cobble_Half",
      "rotation": 25
    },
    {
      "x": -9,
      "y": 5,
      "z": 8,
      "name": "Metal_Iron_Glowing_Pipe_Corner",
      "rotation": 17
    },
    {
      "x": -9,
      "y": 2,
      "z": 9,
      "name": "Metal_Iron_Glowing_Pipe_Corner",
      "rotation": 4
    },
    {
      "x": -9,
      "y": 3,
      "z": 9,
      "name": "Metal_Iron_Glowing_Pipe"
    },
    {
      "x": -9,
      "y": 4,
      "z": 9,
      "name": "Metal_Iron_Glowing_Pipe"
    },
    {
      "x": -9,
      "y": 5,
      "z": 9,
      "name": "Metal_Iron_Glowing_Pipe_Corner",
      "rotation": 10
    },
    {
      "x": -9,
      "y": 2,
      "z": 10,
      "name": "Metal_Iron_Glowing_Pipe_Corner",
      "rotation": 26
    },
    {
      "x": -9,
      "y": 4,
      "z": 10,
      "name": "Rock_Shale_Brick_Smooth",
      "rotation": 27
    },
    {
      "x": -9,
      "y": 7,
      "z": 10,
      "name": "Rock_Shale_Brick_Smooth",
      "rotation": 27
    },
    {
      "x": -9,
      "y": 8,
      "z": 10,
      "name": "Plant_Moss_Rug_Green_Dark",
      "rotation": 12
    },
    {
      "x": -9,
      "y": 3,
      "z": 11,
      "name": "Rock_Shale_Cobble",
      "rotation": 1
    },
    {
      "x": -9,
      "y": 4,
      "z": 11,
      "name": "Rock_Shale_Cobble",
      "rotation": 1
    },
    {
      "x": -9,
      "y": 5,
      "z": 11,
      "name": "Build_Lightsource_Cyan",
      "rotation": 27
    },
    {
      "x": -9,
      "y": 6,
      "z": 11,
      "name": "Build_Lightsource_Cyan",
      "rotation": 26
    },
    {
      "x": -9,
      "y": 7,
      "z": 11,
      "name": "Rock_Shale_Cobble",
      "rotation": 1
    },
    {
      "x": -9,
      "y": 8,
      "z": 11,
      "name": "Rock_Shale_Cobble",
      "rotation": 1
    },
    {
      "x": -9,
      "y": 3,
      "z": 12,
      "name": "Rock_Shale_Cobble",
      "rotation": 1
    },
    {
      "x": -9,
      "y": 4,
      "z": 12,
      "name": "Rock_Shale_Cobble",
      "rotation": 1
    },
    {
      "x": -9,
      "y": 5,
      "z": 12,
      "name": "Rock_Shale_Cobble",
      "rotation": 1
    },
    {
      "x": -9,
      "y": 6,
      "z": 12,
      "name": "Rock_Shale_Cobble",
      "rotation": 1
    },
    {
      "x": -9,
      "y": 7,
      "z": 12,
      "name": "Rock_Shale_Cobble",
      "rotation": 1
    },
    {
      "x": -9,
      "y": 8,
      "z": 12,
      "name": "Rock_Shale_Cobble",
      "rotation": 1
    },
    {
      "x": -9,
      "y": 3,
      "z": 13,
      "name": "Rock_Shale_Cobble",
      "rotation": 1
    },
    {
      "x": -9,
      "y": 4,
      "z": 13,
      "name": "Rock_Shale_Cobble",
      "rotation": 1
    },
    {
      "x": -9,
      "y": 5,
      "z": 13,
      "name": "Rock_Shale_Cobble",
      "rotation": 1
    },
    {
      "x": -9,
      "y": 6,
      "z": 13,
      "name": "Rock_Shale_Cobble",
      "rotation": 1
    },
    {
      "x": -9,
      "y": 7,
      "z": 13,
      "name": "Rock_Shale_Cobble",
      "rotation": 1
    },
    {
      "x": -9,
      "y": 8,
      "z": 13,
      "name": "Rock_Shale_Cobble",
      "rotation": 1
    },
    {
      "x": -9,
      "y": 3,
      "z": 14,
      "name": "Rock_Shale_Cobble",
      "rotation": 1
    },
    {
      "x": -9,
      "y": 4,
      "z": 14,
      "name": "Rock_Shale_Cobble",
      "rotation": 1
    },
    {
      "x": -9,
      "y": 5,
      "z": 14,
      "name": "Rock_Shale_Cobble",
      "rotation": 1
    },
    {
      "x": -9,
      "y": 6,
      "z": 14,
      "name": "Rock_Shale_Cobble",
      "rotation": 1
    },
    {
      "x": -9,
      "y": 7,
      "z": 14,
      "name": "Rock_Shale_Cobble",
      "rotation": 1
    },
    {
      "x": -9,
      "y": 8,
      "z": 14,
      "name": "Rock_Shale_Cobble",
      "rotation": 1
    },
    {
      "x": -9,
      "y": 4,
      "z": 15,
      "name": "Rock_Shale_Cobble_Half",
      "rotation": 25
    },
    {
      "x": -9,
      "y": 7,
      "z": 15,
      "name": "Rock_Shale_Cobble_Half",
      "rotation": 25
    },
    {
      "x": -8,
      "y": 2,
      "z": 10,
      "name": "Metal_Iron_Glowing_Pipe_Corner",
      "rotation": 17
    },
    {
      "x": -8,
      "y": 2,
      "z": 11,
      "name": "Metal_Iron_Glowing_Pipe",
      "rotation": 12
    },
    {
      "x": -8,
      "y": 4,
      "z": 11,
      "name": "Rock_Shale_Brick_Smooth",
      "rotation": 27
    },
    {
      "x": -8,
      "y": 7,
      "z": 11,
      "name": "Rock_Shale_Brick_Smooth",
      "rotation": 27
    },
    {
      "x": -8,
      "y": 8,
      "z": 11,
      "name": "Plant_Moss_Wall_Green_Dark",
      "rotation": 27
    },
    {
      "x": -8,
      "y": 2,
      "z": 12,
      "name": "Metal_Iron_Glowing_Pipe_Corner",
      "rotation": 19
    },
    {
      "x": -8,
      "y": 3,
      "z": 12,
      "name": "Rock_Shale_Cobble",
      "rotation": 1
    },
    {
      "x": -8,
      "y": 4,
      "z": 12,
      "name": "Rock_Shale_Cobble",
      "rotation": 1
    },
    {
      "x": -8,
      "y": 5,
      "z": 12,
      "name": "Build_Lightsource_Cyan",
      "rotation": 26
    },
    {
      "x": -8,
      "y": 6,
      "z": 12,
      "name": "Build_Lightsource_Cyan",
      "rotation": 27
    },
    {
      "x": -8,
      "y": 7,
      "z": 12,
      "name": "Rock_Shale_Cobble",
      "rotation": 1
    },
    {
      "x": -8,
      "y": 8,
      "z": 12,
      "name": "Rock_Shale_Cobble",
      "rotation": 1
    },
    {
      "x": -8,
      "y": 3,
      "z": 13,
      "name": "Rock_Shale_Cobble",
      "rotation": 1
    },
    {
      "x": -8,
      "y": 4,
      "z": 13,
      "name": "Rock_Shale_Cobble",
      "rotation": 1
    },
    {
      "x": -8,
      "y": 5,
      "z": 13,
      "name": "Rock_Shale_Cobble",
      "rotation": 1
    },
    {
      "x": -8,
      "y": 6,
      "z": 13,
      "name": "Rock_Shale_Cobble",
      "rotation": 1
    },
    {
      "x": -8,
      "y": 7,
      "z": 13,
      "name": "Rock_Shale_Cobble",
      "rotation": 1
    },
    {
      "x": -8,
      "y": 8,
      "z": 13,
      "name": "Rock_Shale_Cobble",
      "rotation": 1
    },
    {
      "x": -8,
      "y": 3,
      "z": 14,
      "name": "Rock_Shale_Cobble",
      "rotation": 1
    },
    {
      "x": -8,
      "y": 4,
      "z": 14,
      "name": "Rock_Shale_Cobble",
      "rotation": 1
    },
    {
      "x": -8,
      "y": 5,
      "z": 14,
      "name": "Rock_Shale_Cobble",
      "rotation": 1
    },
    {
      "x": -8,
      "y": 6,
      "z": 14,
      "name": "Rock_Shale_Cobble",
      "rotation": 1
    },
    {
      "x": -8,
      "y": 7,
      "z": 14,
      "name": "Rock_Shale_Cobble",
      "rotation": 1
    },
    {
      "x": -8,
      "y": 8,
      "z": 14,
      "name": "Rock_Shale_Cobble",
      "rotation": 1
    },
    {
      "x": -8,
      "y": 3,
      "z": 15,
      "name": "Rock_Shale_Cobble",
      "rotation": 1
    },
    {
      "x": -8,
      "y": 4,
      "z": 15,
      "name": "Rock_Shale_Cobble",
      "rotation": 1
    },
    {
      "x": -8,
      "y": 5,
      "z": 15,
      "name": "Rock_Shale_Cobble",
      "rotation": 1
    },
    {
      "x": -8,
      "y": 6,
      "z": 15,
      "name": "Rock_Shale_Cobble",
      "rotation": 1
    },
    {
      "x": -8,
      "y": 7,
      "z": 15,
      "name": "Rock_Shale_Cobble",
      "rotation": 1
    },
    {
      "x": -8,
      "y": 8,
      "z": 15,
      "name": "Rock_Shale_Cobble",
      "rotation": 1
    },
    {
      "x": -8,
      "y": 4,
      "z": 16,
      "name": "Rock_Shale_Cobble_Half",
      "rotation": 25
    },
    {
      "x": -8,
      "y": 7,
      "z": 16,
      "name": "Rock_Shale_Cobble_Half",
      "rotation": 25
    },
    {
      "x": -7,
      "y": 4,
      "z": 11,
      "name": "Rock_Shale_Brick_Smooth",
      "rotation": 27
    },
    {
      "x": -7,
      "y": 7,
      "z": 11,
      "name": "Rock_Shale_Brick_Smooth",
      "rotation": 27
    },
    {
      "x": -7,
      "y": 2,
      "z": 12,
      "name": "Metal_Iron_Glowing_Pipe_Corner",
      "rotation": 17
    },
    {
      "x": -7,
      "y": 3,
      "z": 12,
      "name": "Rock_Shale_Cobble",
      "rotation": 1
    },
    {
      "x": -7,
      "y": 4,
      "z": 12,
      "name": "Rock_Shale_Cobble",
      "rotation": 1
    },
    {
      "x": -7,
      "y": 5,
      "z": 12,
      "name": "Build_Lightsource_Cyan",
      "rotation": 26
    },
    {
      "x": -7,
      "y": 6,
      "z": 12,
      "name": "Build_Lightsource_Cyan",
      "rotation": 26
    },
    {
      "x": -7,
      "y": 7,
      "z": 12,
      "name": "Rock_Shale_Cobble",
      "rotation": 1
    },
    {
      "x": -7,
      "y": 8,
      "z": 12,
      "name": "Rock_Shale_Cobble",
      "rotation": 1
    },
    {
      "x": -7,
      "y": 2,
      "z": 13,
      "name": "Metal_Iron_Glowing_Pipe_Corner",
      "rotation": 26
    },
    {
      "x": -7,
      "y": 3,
      "z": 13,
      "name": "Rock_Shale_Cobble",
      "rotation": 1
    },
    {
      "x": -7,
      "y": 4,
      "z": 13,
      "name": "Rock_Shale_Cobble",
      "rotation": 1
    },
    {
      "x": -7,
      "y": 5,
      "z": 13,
      "name": "Rock_Shale_Cobble",
      "rotation": 1
    },
    {
      "x": -7,
      "y": 6,
      "z": 13,
      "name": "Rock_Shale_Cobble",
      "rotation": 1
    },
    {
      "x": -7,
      "y": 7,
      "z": 13,
      "name": "Rock_Shale_Cobble",
      "rotation": 1
    },
    {
      "x": -7,
      "y": 8,
      "z": 13,
      "name": "Rock_Shale_Cobble",
      "rotation": 1
    },
    {
      "x": -7,
      "y": 3,
      "z": 14,
      "name": "Rock_Shale_Cobble",
      "rotation": 1
    },
    {
      "x": -7,
      "y": 4,
      "z": 14,
      "name": "Rock_Shale_Cobble",
      "rotation": 1
    },
    {
      "x": -7,
      "y": 5,
      "z": 14,
      "name": "Rock_Shale_Cobble",
      "rotation": 1
    },
    {
      "x": -7,
      "y": 6,
      "z": 14,
      "name": "Rock_Shale_Cobble",
      "rotation": 1
    },
    {
      "x": -7,
      "y": 7,
      "z": 14,
      "name": "Rock_Shale_Cobble",
      "rotation": 1
    },
    {
      "x": -7,
      "y": 8,
      "z": 14,
      "name": "Rock_Shale_Cobble",
      "rotation": 1
    },
    {
      "x": -7,
      "y": 3,
      "z": 15,
      "name": "Rock_Shale_Cobble",
      "rotation": 1
    },
    {
      "x": -7,
      "y": 4,
      "z": 15,
      "name": "Rock_Shale_Cobble",
      "rotation": 1
    },
    {
      "x": -7,
      "y": 5,
      "z": 15,
      "name": "Rock_Shale_Cobble",
      "rotation": 1
    },
    {
      "x": -7,
      "y": 6,
      "z": 15,
      "name": "Rock_Shale_Cobble",
      "rotation": 1
    },
    {
      "x": -7,
      "y": 7,
      "z": 15,
      "name": "Rock_Shale_Cobble",
      "rotation": 1
    },
    {
      "x": -7,
      "y": 8,
      "z": 15,
      "name": "Rock_Shale_Cobble",
      "rotation": 1
    },
    {
      "x": -7,
      "y": 4,
      "z": 16,
      "name": "Rock_Shale_Cobble_Half",
      "rotation": 25
    },
    {
      "x": -7,
      "y": 7,
      "z": 16,
      "name": "Rock_Shale_Cobble_Half",
      "rotation": 25
    },
    {
      "x": -6,
      "y": 4,
      "z": -17,
      "name": "Rock_Shale_Cobble_Half",
      "rotation": 27
    },
    {
      "x": -6,
      "y": 7,
      "z": -17,
      "name": "Rock_Shale_Cobble_Half",
      "rotation": 27
    },
    {
      "x": -6,
      "y": 7,
      "z": -16,
      "name": "Rock_Shale_Cobble"
    },
    {
      "x": -6,
      "y": 8,
      "z": -16,
      "name": "Rock_Shale_Cobble"
    },
    {
      "x": -6,
      "y": 7,
      "z": -15,
      "name": "Rock_Shale_Cobble"
    },
    {
      "x": -6,
      "y": 8,
      "z": -15,
      "name": "Rock_Shale_Cobble"
    },
    {
      "x": -6,
      "y": 7,
      "z": 11,
      "name": "Plant_Moss_Rug_Green_Dark",
      "rotation": 12
    },
    {
      "x": -6,
      "y": 4,
      "z": 12,
      "name": "Rock_Shale_Brick_Smooth",
      "rotation": 27
    },
    {
      "x": -6,
      "y": 7,
      "z": 12,
      "name": "Rock_Shale_Brick_Smooth",
      "rotation": 27
    },
    {
      "x": -6,
      "y": 8,
      "z": 12,
      "name": "Plant_Moss_Rug_Green_Dark",
      "rotation": 12
    },
    {
      "x": -6,
      "y": 2,
      "z": 13,
      "name": "Metal_Iron_Glowing_Pipe",
      "rotation": 26
    },
    {
      "x": -6,
      "y": 3,
      "z": 13,
      "name": "Rock_Shale_Cobble",
      "rotation": 1
    },
    {
      "x": -6,
      "y": 4,
      "z": 13,
      "name": "Rock_Shale_Cobble",
      "rotation": 1
    },
    {
      "x": -6,
      "y": 5,
      "z": 13,
      "name": "Build_Lightsource_Cyan",
      "rotation": 27
    },
    {
      "x": -6,
      "y": 6,
      "z": 13,
      "name": "Build_Lightsource_Cyan",
      "rotation": 10
    },
    {
      "x": -6,
      "y": 7,
      "z": 13,
      "name": "Rock_Shale_Cobble",
      "rotation": 1
    },
    {
      "x": -6,
      "y": 8,
      "z": 13,
      "name": "Rock_Shale_Cobble",
      "rotation": 1
    },
    {
      "x": -6,
      "y": 9,
      "z": 13,
      "name": "Plant_Moss_Wall_Green_Dark",
      "rotation": 12
    },
    {
      "x": -6,
      "y": 3,
      "z": 14,
      "name": "Rock_Shale_Cobble",
      "rotation": 1
    },
    {
      "x": -6,
      "y": 4,
      "z": 14,
      "name": "Rock_Shale_Cobble",
      "rotation": 1
    },
    {
      "x": -6,
      "y": 5,
      "z": 14,
      "name": "Rock_Shale_Cobble",
      "rotation": 1
    },
    {
      "x": -6,
      "y": 6,
      "z": 14,
      "name": "Rock_Shale_Cobble",
      "rotation": 1
    },
    {
      "x": -6,
      "y": 7,
      "z": 14,
      "name": "Rock_Shale_Cobble",
      "rotation": 1
    },
    {
      "x": -6,
      "y": 8,
      "z": 14,
      "name": "Rock_Shale_Cobble",
      "rotation": 1
    },
    {
      "x": -6,
      "y": 3,
      "z": 15,
      "name": "Rock_Shale_Cobble",
      "rotation": 1
    },
    {
      "x": -6,
      "y": 4,
      "z": 15,
      "name": "Rock_Shale_Cobble",
      "rotation": 1
    },
    {
      "x": -6,
      "y": 5,
      "z": 15,
      "name": "Rock_Shale_Cobble",
      "rotation": 1
    },
    {
      "x": -6,
      "y": 6,
      "z": 15,
      "name": "Rock_Shale_Cobble",
      "rotation": 1
    },
    {
      "x": -6,
      "y": 7,
      "z": 15,
      "name": "Rock_Shale_Cobble",
      "rotation": 1
    },
    {
      "x": -6,
      "y": 8,
      "z": 15,
      "name": "Rock_Shale_Cobble",
      "rotation": 1
    },
    {
      "x": -6,
      "y": 3,
      "z": 16,
      "name": "Rock_Shale_Cobble",
      "rotation": 1
    },
    {
      "x": -6,
      "y": 4,
      "z": 16,
      "name": "Rock_Shale_Cobble",
      "rotation": 1
    },
    {
      "x": -6,
      "y": 5,
      "z": 16,
      "name": "Rock_Shale_Cobble",
      "rotation": 1
    },
    {
      "x": -6,
      "y": 6,
      "z": 16,
      "name": "Rock_Shale_Cobble",
      "rotation": 1
    },
    {
      "x": -6,
      "y": 7,
      "z": 16,
      "name": "Rock_Shale_Cobble",
      "rotation": 1
    },
    {
      "x": -6,
      "y": 8,
      "z": 16,
      "name": "Rock_Shale_Cobble",
      "rotation": 1
    },
    {
      "x": -6,
      "y": 4,
      "z": 17,
      "name": "Rock_Shale_Cobble_Half",
      "rotation": 25
    },
    {
      "x": -6,
      "y": 7,
      "z": 17,
      "name": "Rock_Shale_Cobble_Half",
      "rotation": 25
    },
    {
      "x": -5,
      "y": 4,
      "z": -17,
      "name": "Rock_Shale_Cobble_Half",
      "rotation": 27
    },
    {
      "x": -5,
      "y": 6,
      "z": -17,
      "name": "Plant_Moss_Rug_Green_Dark",
      "rotation": 12
    },
    {
      "x": -5,
      "y": 7,
      "z": -17,
      "name": "Rock_Shale_Cobble_Half",
      "rotation": 27
    },
    {
      "x": -5,
      "y": 7,
      "z": -16,
      "name": "Rock_Shale_Cobble"
    },
    {
      "x": -5,
      "y": 8,
      "z": -16,
      "name": "Rock_Shale_Cobble"
    },
    {
      "x": -5,
      "y": 7,
      "z": -15,
      "name": "Rock_Shale_Cobble"
    },
    {
      "x": -5,
      "y": 8,
      "z": -15,
      "name": "Rock_Shale_Cobble"
    },
    {
      "x": -5,
      "y": 4,
      "z": 11,
      "name": "Plant_Moss_Rug_Green_Dark",
      "rotation": 12
    },
    {
      "x": -5,
      "y": 4,
      "z": 12,
      "name": "Rock_Shale_Brick_Smooth",
      "rotation": 27
    },
    {
      "x": -5,
      "y": 7,
      "z": 12,
      "name": "Rock_Shale_Brick_Smooth",
      "rotation": 27
    },
    {
      "x": -5,
      "y": 2,
      "z": 13,
      "name": "Metal_Iron_Glowing_Pipe",
      "rotation": 26
    },
    {
      "x": -5,
      "y": 3,
      "z": 13,
      "name": "Rock_Shale_Cobble",
      "rotation": 1
    },
    {
      "x": -5,
      "y": 4,
      "z": 13,
      "name": "Rock_Shale_Cobble",
      "rotation": 1
    },
    {
      "x": -5,
      "y": 5,
      "z": 13,
      "name": "Build_Lightsource_Cyan",
      "rotation": 27
    },
    {
      "x": -5,
      "y": 6,
      "z": 13,
      "name": "Build_Lightsource_Cyan",
      "rotation": 10
    },
    {
      "x": -5,
      "y": 7,
      "z": 13,
      "name": "Rock_Shale_Cobble",
      "rotation": 1
    },
    {
      "x": -5,
      "y": 8,
      "z": 13,
      "name": "Rock_Shale_Cobble",
      "rotation": 1
    },
    {
      "x": -5,
      "y": 3,
      "z": 14,
      "name": "Rock_Shale_Cobble",
      "rotation": 1
    },
    {
      "x": -5,
      "y": 4,
      "z": 14,
      "name": "Rock_Shale_Cobble",
      "rotation": 1
    },
    {
      "x": -5,
      "y": 5,
      "z": 14,
      "name": "Rock_Shale_Cobble",
      "rotation": 1
    },
    {
      "x": -5,
      "y": 6,
      "z": 14,
      "name": "Rock_Shale_Cobble",
      "rotation": 1
    },
    {
      "x": -5,
      "y": 7,
      "z": 14,
      "name": "Rock_Shale_Cobble",
      "rotation": 1
    },
    {
      "x": -5,
      "y": 8,
      "z": 14,
      "name": "Rock_Shale_Cobble",
      "rotation": 1
    },
    {
      "x": -5,
      "y": 3,
      "z": 15,
      "name": "Rock_Shale_Cobble",
      "rotation": 1
    },
    {
      "x": -5,
      "y": 4,
      "z": 15,
      "name": "Rock_Shale_Cobble",
      "rotation": 1
    },
    {
      "x": -5,
      "y": 5,
      "z": 15,
      "name": "Rock_Shale_Cobble",
      "rotation": 1
    },
    {
      "x": -5,
      "y": 6,
      "z": 15,
      "name": "Rock_Shale_Cobble",
      "rotation": 1
    },
    {
      "x": -5,
      "y": 7,
      "z": 15,
      "name": "Rock_Shale_Cobble",
      "rotation": 1
    },
    {
      "x": -5,
      "y": 8,
      "z": 15,
      "name": "Rock_Shale_Cobble",
      "rotation": 1
    },
    {
      "x": -5,
      "y": 3,
      "z": 16,
      "name": "Rock_Shale_Cobble",
      "rotation": 1
    },
    {
      "x": -5,
      "y": 4,
      "z": 16,
      "name": "Rock_Shale_Cobble",
      "rotation": 1
    },
    {
      "x": -5,
      "y": 5,
      "z": 16,
      "name": "Rock_Shale_Cobble",
      "rotation": 1
    },
    {
      "x": -5,
      "y": 6,
      "z": 16,
      "name": "Rock_Shale_Cobble",
      "rotation": 1
    },
    {
      "x": -5,
      "y": 7,
      "z": 16,
      "name": "Rock_Shale_Cobble",
      "rotation": 1
    },
    {
      "x": -5,
      "y": 8,
      "z": 16,
      "name": "Rock_Shale_Cobble",
      "rotation": 1
    },
    {
      "x": -5,
      "y": 4,
      "z": 17,
      "name": "Rock_Shale_Cobble_Half",
      "rotation": 25
    },
    {
      "x": -5,
      "y": 7,
      "z": 17,
      "name": "Rock_Shale_Cobble_Half",
      "rotation": 25
    },
    {
      "x": -4,
      "y": 3,
      "z": -17,
      "name": "Plant_Moss_Wall_Green_Dark",
      "rotation": 19
    },
    {
      "x": -4,
      "y": 4,
      "z": -17,
      "name": "Rock_Shale_Cobble_Half",
      "rotation": 27
    },
    {
      "x": -4,
      "y": 6,
      "z": -17,
      "name": "Plant_Moss_Wall_Green_Dark",
      "rotation": 19
    },
    {
      "x": -4,
      "y": 7,
      "z": -17,
      "name": "Rock_Shale_Cobble_Half",
      "rotation": 27
    },
    {
      "x": -4,
      "y": 8,
      "z": -17,
      "name": "Plant_Moss_Rug_Green_Dark",
      "rotation": 12
    },
    {
      "x": -4,
      "y": 3,
      "z": -16,
      "name": "Plant_Moss_Wall_Green_Dark",
      "rotation": 19
    },
    {
      "x": -4,
      "y": 5,
      "z": -16,
      "name": "Rock_Shale_Cobble"
    },
    {
      "x": -4,
      "y": 6,
      "z": -16,
      "name": "Rock_Shale_Cobble"
    },
    {
      "x": -4,
      "y": 7,
      "z": -16,
      "name": "Rock_Shale_Cobble"
    },
    {
      "x": -4,
      "y": 8,
      "z": -16,
      "name": "Rock_Shale_Cobble"
    },
    {
      "x": -4,
      "y": 9,
      "z": -16,
      "name": "Plant_Moss_Wall_Green_Dark",
      "rotation": 12
    },
    {
      "x": -4,
      "y": 5,
      "z": -15,
      "name": "Rock_Shale_Cobble"
    },
    {
      "x": -4,
      "y": 6,
      "z": -15,
      "name": "Rock_Shale_Cobble"
    },
    {
      "x": -4,
      "y": 7,
      "z": -15,
      "name": "Rock_Shale_Cobble"
    },
    {
      "x": -4,
      "y": 8,
      "z": -15,
      "name": "Rock_Shale_Cobble"
    },
    {
      "x": -4,
      "y": 5,
      "z": -14,
      "name": "Rock_Shale_Cobble",
      "rotation": 26
    },
    {
      "x": -4,
      "y": 6,
      "z": -14,
      "name": "Rock_Shale_Cobble",
      "rotation": 26
    },
    {
      "x": -4,
      "y": 3,
      "z": 12,
      "name": "Plant_Moss_Rug_Green_Dark",
      "rotation": 12
    },
    {
      "x": -4,
      "y": 4,
      "z": 12,
      "name": "Rock_Shale_Brick_Smooth",
      "rotation": 27
    },
    {
      "x": -4,
      "y": 7,
      "z": 12,
      "name": "Rock_Shale_Brick_Smooth",
      "rotation": 27
    },
    {
      "x": -4,
      "y": 2,
      "z": 13,
      "name": "Metal_Iron_Glowing_Pipe_Corner",
      "rotation": 17
    },
    {
      "x": -4,
      "y": 3,
      "z": 13,
      "name": "Rock_Shale_Cobble",
      "rotation": 1
    },
    {
      "x": -4,
      "y": 4,
      "z": 13,
      "name": "Rock_Shale_Cobble",
      "rotation": 1
    },
    {
      "x": -4,
      "y": 5,
      "z": 13,
      "name": "Build_Lightsource_Cyan",
      "rotation": 27
    },
    {
      "x": -4,
      "y": 6,
      "z": 13,
      "name": "Build_Lightsource_Cyan",
      "rotation": 27
    },
    {
      "x": -4,
      "y": 7,
      "z": 13,
      "name": "Rock_Shale_Cobble",
      "rotation": 1
    },
    {
      "x": -4,
      "y": 8,
      "z": 13,
      "name": "Rock_Shale_Cobble",
      "rotation": 1
    },
    {
      "x": -4,
      "y": 2,
      "z": 14,
      "name": "Metal_Iron_Glowing_Pipe",
      "rotation": 12
    },
    {
      "x": -4,
      "y": 3,
      "z": 14,
      "name": "Rock_Shale_Cobble",
      "rotation": 1
    },
    {
      "x": -4,
      "y": 4,
      "z": 14,
      "name": "Rock_Shale_Cobble",
      "rotation": 1
    },
    {
      "x": -4,
      "y": 5,
      "z": 14,
      "name": "Rock_Shale_Cobble",
      "rotation": 1
    },
    {
      "x": -4,
      "y": 6,
      "z": 14,
      "name": "Rock_Shale_Cobble",
      "rotation": 1
    },
    {
      "x": -4,
      "y": 7,
      "z": 14,
      "name": "Rock_Shale_Cobble",
      "rotation": 1
    },
    {
      "x": -4,
      "y": 8,
      "z": 14,
      "name": "Rock_Shale_Cobble",
      "rotation": 1
    },
    {
      "x": -4,
      "y": 2,
      "z": 15,
      "name": "Metal_Iron_Glowing_Pipe_Corner",
      "rotation": 6
    },
    {
      "x": -4,
      "y": 3,
      "z": 15,
      "name": "Rock_Shale_Cobble",
      "rotation": 1
    },
    {
      "x": -4,
      "y": 4,
      "z": 15,
      "name": "Rock_Shale_Cobble",
      "rotation": 1
    },
    {
      "x": -4,
      "y": 5,
      "z": 15,
      "name": "Rock_Shale_Cobble",
      "rotation": 1
    },
    {
      "x": -4,
      "y": 6,
      "z": 15,
      "name": "Rock_Shale_Cobble",
      "rotation": 1
    },
    {
      "x": -4,
      "y": 7,
      "z": 15,
      "name": "Rock_Shale_Cobble",
      "rotation": 1
    },
    {
      "x": -4,
      "y": 8,
      "z": 15,
      "name": "Rock_Shale_Cobble",
      "rotation": 1
    },
    {
      "x": -4,
      "y": 3,
      "z": 16,
      "name": "Rock_Shale_Cobble",
      "rotation": 1
    },
    {
      "x": -4,
      "y": 4,
      "z": 16,
      "name": "Rock_Shale_Cobble",
      "rotation": 1
    },
    {
      "x": -4,
      "y": 5,
      "z": 16,
      "name": "Rock_Shale_Cobble",
      "rotation": 1
    },
    {
      "x": -4,
      "y": 6,
      "z": 16,
      "name": "Rock_Shale_Cobble",
      "rotation": 1
    },
    {
      "x": -4,
      "y": 7,
      "z": 16,
      "name": "Rock_Shale_Cobble",
      "rotation": 1
    },
    {
      "x": -4,
      "y": 8,
      "z": 16,
      "name": "Rock_Shale_Cobble",
      "rotation": 1
    },
    {
      "x": -4,
      "y": 4,
      "z": 17,
      "name": "Rock_Shale_Cobble_Half",
      "rotation": 25
    },
    {
      "x": -4,
      "y": 7,
      "z": 17,
      "name": "Rock_Shale_Cobble_Half",
      "rotation": 25
    },
    {
      "x": -3,
      "y": 3,
      "z": -18,
      "name": "Plant_Moss_Rug_Green_Dark",
      "rotation": 12
    },
    {
      "x": -3,
      "y": 4,
      "z": -18,
      "name": "Rock_Shale_Cobble_Half",
      "rotation": 27
    },
