{
  "version": 8,
  "blockIdVersion": 11,
  "anchorX": 0,
  "anchorY": 0,
  "anchorZ": 0,
  "blocks": [
    {
      "x": -15,
      "y": 0,
      "z": -21,
      "name": "Soil_Dirt"
    },
    {
      "x": -15,
      "y": 1,
      "z": -21,
      "name": "Soil_Dirt"
    },
    {
      "x": -15,
      "y": 2,
      "z": -21,
      "name": "Soil_Dirt"
    },
    {
      "x": -15,
      "y": 3,
      "z": -21,
      "name": "Soil_Dirt"
    },
    {
      "x": -15,
      "y": 4,
      "z": -21,
      "name": "Soil_Dirt"
    },
    {
      "x": -15,
      "y": 5,
      "z": -21,
      "name": "Soil_Dirt"
    },
    {
      "x": -15,
      "y": 6,
      "z": -21,
      "name": "Soil_Grass"
    },
    {
      "x": -15,
      "y": 0,
      "z": -20,
      "name": "Soil_Dirt"
    },
    {
      "x": -15,
      "y": 1,
      "z": -20,
      "name": "Soil_Dirt"
    },
    {
      "x": -15,
      "y": 2,
      "z": -20,
      "name": "Soil_Dirt"
    },
    {
      "x": -15,
      "y": 3,
      "z": -20,
      "name": "Soil_Dirt"
    },
    {
      "x": -15,
      "y": 4,
      "z": -20,
      "name": "Soil_Dirt"
    },
    {
      "x": -15,
      "y": 5,
      "z": -20,
      "name": "Soil_Dirt"
    },
    {
      "x": -15,
      "y": 6,
      "z": -20,
      "name": "Soil_Grass"
    },
    {
      "x": -15,
      "y": 0,
      "z": -19,
      "name": "Soil_Dirt"
    },
    {
      "x": -15,
      "y": 1,
      "z": -19,
      "name": "Soil_Dirt"
    },
    {
      "x": -15,
      "y": 2,
      "z": -19,
      "name": "Soil_Dirt"
    },
    {
      "x": -15,
      "y": 3,
      "z": -19,
      "name": "Soil_Dirt"
    },
    {
      "x": -15,
      "y": 4,
      "z": -19,
      "name": "Soil_Dirt"
    },
    {
      "x": -15,
      "y": 5,
      "z": -19,
      "name": "Soil_Dirt"
    },
    {
      "x": -15,
      "y": 6,
      "z": -19,
      "name": "Soil_Grass"
    },
    {
      "x": -15,
      "y": 0,
      "z": -18,
      "name": "Soil_Dirt"
    },
    {
      "x": -15,
      "y": 1,
      "z": -18,
      "name": "Soil_Dirt"
    },
    {
      "x": -15,
      "y": 2,
      "z": -18,
      "name": "Soil_Dirt"
    },
    {
      "x": -15,
      "y": 3,
      "z": -18,
      "name": "Soil_Dirt"
    },
    {
      "x": -15,
      "y": 4,
      "z": -18,
      "name": "Soil_Dirt"
    },
    {
      "x": -15,
      "y": 5,
      "z": -18,
      "name": "Soil_Dirt"
    },
    {
      "x": -15,
      "y": 6,
      "z": -18,
      "name": "Soil_Dirt"
    },
    {
      "x": -15,
      "y": 7,
      "z": -18,
      "name": "Soil_Grass"
    },
    {
      "x": -15,
      "y": 0,
      "z": -17,
      "name": "Soil_Dirt"
    },
    {
      "x": -15,
      "y": 1,
      "z": -17,
      "name": "Soil_Dirt"
    },
    {
      "x": -15,
      "y": 2,
      "z": -17,
      "name": "Soil_Dirt"
    },
    {
      "x": -15,
      "y": 3,
      "z": -17,
      "name": "Soil_Dirt"
    },
    {
      "x": -15,
      "y": 4,
      "z": -17,
      "name": "Soil_Dirt"
    },
    {
      "x": -15,
      "y": 5,
      "z": -17,
      "name": "Soil_Dirt"
    },
    {
      "x": -15,
      "y": 6,
      "z": -17,
      "name": "Soil_Dirt"
    },
    {
      "x": -15,
      "y": 7,
      "z": -17,
      "name": "Soil_Grass"
    },
    {
      "x": -15,
      "y": 0,
      "z": -16,
      "name": "Soil_Dirt"
    },
    {
      "x": -15,
      "y": 1,
      "z": -16,
      "name": "Soil_Dirt"
    },
    {
      "x": -15,
      "y": 2,
      "z": -16,
      "name": "Soil_Dirt"
    },
    {
      "x": -15,
      "y": 3,
      "z": -16,
      "name": "Soil_Dirt"
    },
    {
      "x": -15,
      "y": 4,
      "z": -16,
      "name": "Soil_Dirt"
    },
    {
      "x": -15,
      "y": 5,
      "z": -16,
      "name": "Soil_Dirt"
    },
    {
      "x": -15,
      "y": 6,
      "z": -16,
      "name": "Soil_Dirt"
    },
    {
      "x": -15,
      "y": 7,
      "z": -16,
      "name": "Soil_Grass"
    },
    {
      "x": -15,
      "y": 0,
      "z": -15,
      "name": "Soil_Dirt"
    },
    {
      "x": -15,
      "y": 1,
      "z": -15,
      "name": "Soil_Dirt"
    },
    {
      "x": -15,
      "y": 2,
      "z": -15,
      "name": "Soil_Dirt"
    },
    {
      "x": -15,
      "y": 3,
      "z": -15,
      "name": "Soil_Dirt"
    },
    {
      "x": -15,
      "y": 4,
      "z": -15,
      "name": "Soil_Dirt"
    },
    {
      "x": -15,
      "y": 5,
      "z": -15,
      "name": "Soil_Dirt"
    },
    {
      "x": -15,
      "y": 6,
      "z": -15,
      "name": "Soil_Dirt"
    },
    {
      "x": -15,
      "y": 7,
      "z": -15,
      "name": "Soil_Grass"
    },
    {
      "x": -15,
      "y": 0,
      "z": -14,
      "name": "Soil_Dirt"
    },
    {
      "x": -15,
      "y": 1,
      "z": -14,
      "name": "Soil_Dirt"
    },
    {
      "x": -15,
      "y": 2,
      "z": -14,
      "name": "Soil_Dirt"
    },
    {
      "x": -15,
      "y": 3,
      "z": -14,
      "name": "Soil_Dirt"
    },
    {
      "x": -15,
      "y": 4,
      "z": -14,
      "name": "Soil_Dirt"
    },
    {
      "x": -15,
      "y": 5,
      "z": -14,
      "name": "Soil_Dirt"
    },
    {
      "x": -15,
      "y": 6,
      "z": -14,
      "name": "Soil_Dirt"
    },
    {
      "x": -15,
      "y": 7,
      "z": -14,
      "name": "Soil_Grass"
    },
    {
      "x": -15,
      "y": 0,
      "z": -13,
      "name": "Soil_Dirt"
    },
    {
      "x": -15,
      "y": 1,
      "z": -13,
      "name": "Soil_Dirt"
    },
    {
      "x": -15,
      "y": 2,
      "z": -13,
      "name": "Soil_Dirt"
    },
    {
      "x": -15,
      "y": 3,
      "z": -13,
      "name": "Soil_Dirt"
    },
    {
      "x": -15,
      "y": 4,
      "z": -13,
      "name": "Soil_Dirt"
    },
    {
      "x": -15,
      "y": 5,
      "z": -13,
      "name": "Soil_Dirt"
    },
    {
      "x": -15,
      "y": 6,
      "z": -13,
      "name": "Soil_Dirt"
    },
    {
      "x": -15,
      "y": 7,
      "z": -13,
      "name": "Soil_Dirt"
    },
    {
      "x": -15,
      "y": 8,
      "z": -13,
      "name": "Soil_Grass"
    },
    {
      "x": -15,
      "y": 0,
      "z": -12,
      "name": "Soil_Dirt"
    },
    {
      "x": -15,
      "y": 1,
      "z": -12,
      "name": "Soil_Dirt"
    },
    {
      "x": -15,
      "y": 2,
      "z": -12,
      "name": "Soil_Dirt"
    },
    {
      "x": -15,
      "y": 3,
      "z": -12,
      "name": "Soil_Dirt"
    },
    {
      "x": -15,
      "y": 4,
      "z": -12,
      "name": "Soil_Dirt"
    },
    {
      "x": -15,
      "y": 5,
      "z": -12,
      "name": "Soil_Dirt"
    },
    {
      "x": -15,
      "y": 6,
      "z": -12,
      "name": "Soil_Dirt"
    },
    {
      "x": -15,
      "y": 7,
      "z": -12,
      "name": "Soil_Grass"
    },
    {
      "x": -15,
      "y": 0,
      "z": -11,
      "name": "Soil_Dirt"
    },
    {
      "x": -15,
      "y": 1,
      "z": -11,
      "name": "Soil_Dirt"
    },
    {
      "x": -15,
      "y": 2,
      "z": -11,
      "name": "Soil_Dirt"
    },
    {
      "x": -15,
      "y": 3,
      "z": -11,
      "name": "Soil_Dirt"
    },
    {
      "x": -15,
      "y": 4,
      "z": -11,
      "name": "Soil_Dirt"
    },
    {
      "x": -15,
      "y": 5,
      "z": -11,
      "name": "Soil_Dirt"
    },
    {
      "x": -15,
      "y": 6,
      "z": -11,
      "name": "Soil_Dirt"
    },
    {
      "x": -15,
      "y": 7,
      "z": -11,
      "name": "Soil_Grass"
    },
    {
      "x": -15,
      "y": 0,
      "z": -10,
      "name": "Soil_Dirt"
    },
    {
      "x": -15,
      "y": 1,
      "z": -10,
      "name": "Soil_Dirt"
    },
    {
      "x": -15,
      "y": 2,
      "z": -10,
      "name": "Soil_Dirt"
    },
    {
      "x": -15,
      "y": 3,
      "z": -10,
      "name": "Soil_Dirt"
    },
    {
      "x": -15,
      "y": 4,
      "z": -10,
      "name": "Soil_Dirt"
    },
    {
      "x": -15,
      "y": 5,
      "z": -10,
      "name": "Soil_Dirt"
    },
    {
      "x": -15,
      "y": 6,
      "z": -10,
      "name": "Soil_Dirt"
    },
    {
      "x": -15,
      "y": 7,
      "z": -10,
      "name": "Soil_Dirt"
    },
    {
      "x": -15,
      "y": 8,
      "z": -10,
      "name": "Soil_Grass"
    },
    {
      "x": -15,
      "y": 0,
      "z": -9,
      "name": "Soil_Dirt"
    },
    {
      "x": -15,
      "y": 1,
      "z": -9,
      "name": "Soil_Dirt"
    },
    {
      "x": -15,
      "y": 2,
      "z": -9,
      "name": "Soil_Dirt"
    },
    {
      "x": -15,
      "y": 3,
      "z": -9,
      "name": "Soil_Dirt"
    },
    {
      "x": -15,
      "y": 4,
      "z": -9,
      "name": "Soil_Dirt"
    },
    {
      "x": -15,
      "y": 5,
      "z": -9,
      "name": "Soil_Dirt"
    },
    {
      "x": -15,
      "y": 6,
      "z": -9,
      "name": "Soil_Dirt"
    },
    {
      "x": -15,
      "y": 7,
      "z": -9,
      "name": "Soil_Dirt"
    },
    {
      "x": -15,
      "y": 8,
      "z": -9,
      "name": "Soil_Dirt"
    },
    {
      "x": -15,
      "y": 9,
      "z": -9,
      "name": "Soil_Grass"
    },
    {
      "x": -15,
      "y": 0,
      "z": -8,
      "name": "Soil_Dirt"
    },
    {
      "x": -15,
      "y": 1,
      "z": -8,
      "name": "Soil_Dirt"
    },
    {
      "x": -15,
      "y": 2,
      "z": -8,
      "name": "Soil_Dirt"
    },
    {
      "x": -15,
      "y": 3,
      "z": -8,
      "name": "Soil_Dirt"
    },
    {
      "x": -15,
      "y": 4,
      "z": -8,
      "name": "Soil_Dirt"
    },
    {
      "x": -15,
      "y": 5,
      "z": -8,
      "name": "Soil_Dirt"
    },
    {
      "x": -15,
      "y": 6,
      "z": -8,
      "name": "Soil_Dirt"
    },
    {
      "x": -15,
      "y": 7,
      "z": -8,
      "name": "Soil_Dirt"
    },
    {
      "x": -15,
      "y": 8,
      "z": -8,
      "name": "Soil_Dirt"
    },
    {
      "x": -15,
      "y": 9,
      "z": -8,
      "name": "Soil_Grass"
    },
    {
      "x": -15,
      "y": 10,
      "z": -8,
      "name": "Plant_Grass_Sharp_Overgrown",
      "support": 15
    },
    {
      "x": -15,
      "y": 11,
      "z": -8,
      "name": "Plant_Grass_Sharp_Overgrown",
      "filler": 1024
    },
    {
      "x": -15,
      "y": 0,
      "z": -7,
      "name": "Soil_Dirt"
    },
    {
      "x": -15,
      "y": 1,
      "z": -7,
      "name": "Soil_Dirt"
    },
    {
      "x": -15,
      "y": 2,
      "z": -7,
      "name": "Soil_Dirt"
    },
    {
      "x": -15,
      "y": 3,
      "z": -7,
      "name": "Soil_Dirt"
    },
    {
      "x": -15,
      "y": 4,
      "z": -7,
      "name": "Soil_Dirt"
    },
    {
      "x": -15,
      "y": 5,
      "z": -7,
      "name": "Soil_Dirt"
    },
    {
      "x": -15,
      "y": 6,
      "z": -7,
      "name": "Soil_Dirt"
    },
    {
      "x": -15,
      "y": 7,
      "z": -7,
      "name": "Soil_Dirt"
    },
    {
      "x": -15,
      "y": 8,
      "z": -7,
      "name": "Soil_Dirt"
    },
    {
      "x": -15,
      "y": 9,
      "z": -7,
      "name": "Soil_Grass"
    },
    {
      "x": -15,
      "y": 10,
      "z": -7,
      "name": "Plant_Grass_Sharp_Overgrown",
      "support": 15
    },
    {
      "x": -15,
      "y": 11,
      "z": -7,
      "name": "Plant_Grass_Sharp_Overgrown",
      "filler": 1024
    },
    {
      "x": -15,
      "y": 0,
      "z": -6,
      "name": "Soil_Dirt"
    },
    {
      "x": -15,
      "y": 1,
      "z": -6,
      "name": "Soil_Dirt"
    },
    {
      "x": -15,
      "y": 2,
      "z": -6,
      "name": "Soil_Dirt"
    },
    {
      "x": -15,
      "y": 3,
      "z": -6,
      "name": "Soil_Dirt"
    },
    {
      "x": -15,
      "y": 4,
      "z": -6,
      "name": "Soil_Dirt"
    },
    {
      "x": -15,
      "y": 5,
      "z": -6,
      "name": "Soil_Dirt"
    },
    {
      "x": -15,
      "y": 6,
      "z": -6,
      "name": "Soil_Dirt"
    },
    {
      "x": -15,
      "y": 7,
      "z": -6,
      "name": "Soil_Dirt"
    },
    {
      "x": -15,
      "y": 8,
      "z": -6,
      "name": "Soil_Dirt"
    },
    {
      "x": -15,
      "y": 9,
      "z": -6,
      "name": "Soil_Grass"
    },
    {
      "x": -15,
      "y": 0,
      "z": -5,
      "name": "Soil_Dirt"
    },
    {
      "x": -15,
      "y": 1,
      "z": -5,
      "name": "Soil_Dirt"
    },
    {
      "x": -15,
      "y": 2,
      "z": -5,
      "name": "Soil_Dirt"
    },
    {
      "x": -15,
      "y": 3,
      "z": -5,
      "name": "Soil_Dirt"
    },
    {
      "x": -15,
      "y": 4,
      "z": -5,
      "name": "Soil_Dirt"
    },
    {
      "x": -15,
      "y": 5,
      "z": -5,
      "name": "Soil_Dirt"
    },
    {
      "x": -15,
      "y": 6,
      "z": -5,
      "name": "Soil_Dirt"
    },
    {
      "x": -15,
      "y": 7,
      "z": -5,
      "name": "Soil_Dirt"
    },
    {
      "x": -15,
      "y": 8,
      "z": -5,
      "name": "Soil_Grass"
    },
    {
      "x": -15,
      "y": 0,
      "z": -4,
      "name": "Soil_Dirt"
    },
    {
      "x": -15,
      "y": 1,
      "z": -4,
      "name": "Soil_Dirt"
    },
    {
      "x": -15,
      "y": 2,
      "z": -4,
      "name": "Soil_Dirt"
    },
    {
      "x": -15,
      "y": 3,
      "z": -4,
      "name": "Soil_Dirt"
    },
    {
      "x": -15,
      "y": 4,
      "z": -4,
      "name": "Soil_Dirt"
    },
    {
      "x": -15,
      "y": 5,
      "z": -4,
      "name": "Soil_Dirt"
    },
    {
      "x": -15,
      "y": 6,
      "z": -4,
      "name": "Soil_Dirt"
    },
    {
      "x": -15,
      "y": 7,
      "z": -4,
      "name": "Soil_Dirt"
    },
    {
      "x": -15,
      "y": 8,
      "z": -4,
      "name": "Soil_Dirt"
    },
    {
      "x": -15,
      "y": 9,
      "z": -4,
      "name": "Soil_Grass"
    },
    {
      "x": -15,
      "y": 0,
      "z": -3,
      "name": "Soil_Dirt"
    },
    {
      "x": -15,
      "y": 1,
      "z": -3,
      "name": "Soil_Dirt"
    },
    {
      "x": -15,
      "y": 2,
      "z": -3,
      "name": "Soil_Dirt"
    },
    {
      "x": -15,
      "y": 3,
      "z": -3,
      "name": "Soil_Dirt"
    },
    {
      "x": -15,
      "y": 4,
      "z": -3,
      "name": "Soil_Dirt"
    },
    {
      "x": -15,
      "y": 5,
      "z": -3,
      "name": "Soil_Dirt"
    },
    {
      "x": -15,
      "y": 6,
      "z": -3,
      "name": "Soil_Dirt"
    },
    {
      "x": -15,
      "y": 7,
      "z": -3,
      "name": "Soil_Dirt"
    },
    {
      "x": -15,
      "y": 8,
      "z": -3,
      "name": "Soil_Dirt"
    },
    {
      "x": -15,
      "y": 9,
      "z": -3,
      "name": "Soil_Grass"
    },
    {
      "x": -15,
      "y": 10,
      "z": -3,
      "name": "Plant_Grass_Sharp_Tall",
      "support": 15
    },
    {
      "x": -15,
      "y": 11,
      "z": -3,
      "name": "Plant_Grass_Sharp_Tall",
      "filler": 1024
    },
    {
      "x": -15,
      "y": 0,
      "z": -2,
      "name": "Soil_Dirt"
    },
    {
      "x": -15,
      "y": 1,
      "z": -2,
      "name": "Soil_Dirt"
    },
    {
      "x": -15,
      "y": 2,
      "z": -2,
      "name": "Soil_Dirt"
    },
    {
      "x": -15,
      "y": 3,
      "z": -2,
      "name": "Soil_Dirt"
    },
    {
      "x": -15,
      "y": 4,
      "z": -2,
      "name": "Soil_Dirt"
    },
    {
      "x": -15,
      "y": 5,
      "z": -2,
      "name": "Soil_Dirt"
    },
    {
      "x": -15,
      "y": 6,
      "z": -2,
      "name": "Soil_Dirt"
    },
    {
      "x": -15,
      "y": 7,
      "z": -2,
      "name": "Soil_Dirt"
    },
    {
      "x": -15,
      "y": 8,
      "z": -2,
      "name": "Soil_Grass"
    },
    {
      "x": -15,
      "y": 0,
      "z": -1,
      "name": "Soil_Dirt"
    },
    {
      "x": -15,
      "y": 1,
      "z": -1,
      "name": "Soil_Dirt"
    },
    {
      "x": -15,
      "y": 2,
      "z": -1,
      "name": "Soil_Dirt"
    },
    {
      "x": -15,
      "y": 3,
      "z": -1,
      "name": "Soil_Dirt"
    },
    {
      "x": -15,
      "y": 4,
      "z": -1,
      "name": "Soil_Dirt"
    },
    {
      "x": -15,
      "y": 5,
      "z": -1,
      "name": "Soil_Dirt"
    },
    {
      "x": -15,
      "y": 6,
      "z": -1,
      "name": "Soil_Dirt"
    },
    {
      "x": -15,
      "y": 7,
      "z": -1,
      "name": "Soil_Dirt"
    },
    {
      "x": -15,
      "y": 8,
      "z": -1,
      "name": "Soil_Grass"
    },
    {
      "x": -15,
      "y": 0,
      "z": 0,
      "name": "Soil_Dirt"
    },
    {
      "x": -15,
      "y": 1,
      "z": 0,
      "name": "Soil_Dirt"
    },
    {
      "x": -15,
      "y": 2,
      "z": 0,
      "name": "Soil_Dirt"
    },
    {
      "x": -15,
      "y": 3,
      "z": 0,
      "name": "Soil_Dirt"
    },
    {
      "x": -15,
      "y": 4,
      "z": 0,
      "name": "Soil_Dirt"
    },
    {
      "x": -15,
      "y": 5,
      "z": 0,
      "name": "Soil_Dirt"
    },
    {
      "x": -15,
      "y": 6,
      "z": 0,
      "name": "Soil_Dirt"
    },
    {
      "x": -15,
      "y": 7,
      "z": 0,
      "name": "Soil_Dirt"
    },
    {
      "x": -15,
      "y": 8,
      "z": 0,
      "name": "Soil_Grass"
    },
    {
      "x": -15,
      "y": 0,
      "z": 1,
      "name": "Soil_Dirt"
    },
    {
      "x": -15,
      "y": 1,
      "z": 1,
      "name": "Soil_Dirt"
    },
    {
      "x": -15,
      "y": 2,
      "z": 1,
      "name": "Soil_Dirt"
    },
    {
      "x": -15,
      "y": 3,
      "z": 1,
      "name": "Soil_Dirt"
    },
    {
      "x": -15,
      "y": 4,
      "z": 1,
      "name": "Soil_Dirt"
    },
    {
      "x": -15,
      "y": 5,
      "z": 1,
      "name": "Soil_Dirt"
    },
    {
      "x": -15,
      "y": 6,
      "z": 1,
      "name": "Soil_Dirt"
    },
    {
      "x": -15,
      "y": 7,
      "z": 1,
      "name": "Soil_Dirt"
    },
    {
      "x": -15,
      "y": 8,
      "z": 1,
      "name": "Soil_Grass"
    },
    {
      "x": -15,
      "y": 0,
      "z": 2,
      "name": "Soil_Dirt"
    },
    {
      "x": -15,
      "y": 1,
      "z": 2,
      "name": "Soil_Dirt"
    },
    {
      "x": -15,
      "y": 2,
      "z": 2,
      "name": "Soil_Dirt"
    },
    {
      "x": -15,
      "y": 3,
      "z": 2,
      "name": "Soil_Dirt"
    },
    {
      "x": -15,
      "y": 4,
      "z": 2,
      "name": "Soil_Dirt"
    },
    {
      "x": -15,
      "y": 5,
      "z": 2,
      "name": "Soil_Dirt"
    },
    {
      "x": -15,
      "y": 6,
      "z": 2,
      "name": "Soil_Dirt"
    },
    {
      "x": -15,
      "y": 7,
      "z": 2,
      "name": "Soil_Dirt"
    },
    {
      "x": -15,
      "y": 8,
      "z": 2,
      "name": "Soil_Grass"
    },
    {
      "x": -15,
      "y": 0,
      "z": 3,
      "name": "Soil_Dirt"
    },
    {
      "x": -15,
      "y": 1,
      "z": 3,
      "name": "Soil_Dirt"
    },
    {
      "x": -15,
      "y": 2,
      "z": 3,
      "name": "Soil_Dirt"
    },
    {
      "x": -15,
      "y": 3,
      "z": 3,
      "name": "Soil_Dirt"
    },
    {
      "x": -15,
      "y": 4,
      "z": 3,
      "name": "Soil_Dirt"
    },
    {
      "x": -15,
      "y": 5,
      "z": 3,
      "name": "Soil_Dirt"
    },
    {
      "x": -15,
      "y": 6,
      "z": 3,
      "name": "Soil_Dirt"
    },
    {
      "x": -15,
      "y": 7,
      "z": 3,
      "name": "Soil_Dirt"
    },
    {
      "x": -15,
      "y": 8,
      "z": 3,
      "name": "Soil_Dirt"
    },
    {
      "x": -15,
      "y": 9,
      "z": 3,
      "name": "Soil_Grass"
    },
    {
      "x": -15,
      "y": 0,
      "z": 4,
      "name": "Soil_Dirt"
    },
    {
      "x": -15,
      "y": 1,
      "z": 4,
      "name": "Soil_Dirt"
    },
    {
      "x": -15,
      "y": 2,
      "z": 4,
      "name": "Soil_Dirt"
    },
    {
      "x": -15,
      "y": 3,
      "z": 4,
      "name": "Soil_Dirt"
    },
    {
      "x": -15,
      "y": 4,
      "z": 4,
      "name": "Soil_Dirt"
    },
    {
      "x": -15,
      "y": 5,
      "z": 4,
      "name": "Soil_Dirt"
    },
    {
      "x": -15,
      "y": 6,
      "z": 4,
      "name": "Soil_Dirt"
    },
    {
      "x": -15,
      "y": 7,
      "z": 4,
      "name": "Soil_Dirt"
    },
    {
      "x": -15,
      "y": 8,
      "z": 4,
      "name": "Soil_Dirt"
    },
    {
      "x": -15,
      "y": 9,
      "z": 4,
      "name": "Soil_Grass"
    },
    {
      "x": -15,
      "y": 0,
      "z": 5,
      "name": "Soil_Dirt"
    },
    {
      "x": -15,
      "y": 1,
      "z": 5,
      "name": "Soil_Dirt"
    },
    {
      "x": -15,
      "y": 2,
      "z": 5,
      "name": "Soil_Dirt"
    },
    {
      "x": -15,
      "y": 3,
      "z": 5,
      "name": "Soil_Dirt"
    },
    {
      "x": -15,
      "y": 4,
      "z": 5,
      "name": "Soil_Dirt"
    },
    {
      "x": -15,
      "y": 5,
      "z": 5,
      "name": "Soil_Dirt"
    },
    {
      "x": -15,
      "y": 6,
      "z": 5,
      "name": "Soil_Dirt"
    },
    {
      "x": -15,
      "y": 7,
      "z": 5,
      "name": "Soil_Dirt"
    },
    {
      "x": -15,
      "y": 8,
      "z": 5,
      "name": "Soil_Dirt"
    },
    {
      "x": -15,
      "y": 9,
      "z": 5,
      "name": "Soil_Grass"
    },
    {
      "x": -15,
      "y": 10,
      "z": 5,
      "name": "Plant_Grass_Sharp_Overgrown",
      "support": 15
    },
    {
      "x": -15,
      "y": 11,
      "z": 5,
      "name": "Plant_Grass_Sharp_Overgrown",
      "filler": 1024
    },
    {
      "x": -15,
      "y": 0,
      "z": 6,
      "name": "Soil_Dirt"
    },
    {
      "x": -15,
      "y": 1,
      "z": 6,
      "name": "Soil_Dirt"
    },
    {
      "x": -15,
      "y": 2,
      "z": 6,
      "name": "Soil_Dirt"
    },
    {
      "x": -15,
      "y": 3,
      "z": 6,
      "name": "Soil_Dirt"
    },
    {
      "x": -15,
      "y": 4,
      "z": 6,
      "name": "Soil_Dirt"
    },
    {
      "x": -15,
      "y": 5,
      "z": 6,
      "name": "Soil_Dirt"
    },
    {
      "x": -15,
      "y": 6,
      "z": 6,
      "name": "Soil_Dirt"
    },
    {
      "x": -15,
      "y": 7,
      "z": 6,
      "name": "Soil_Dirt"
    },
    {
      "x": -15,
      "y": 8,
      "z": 6,
      "name": "Soil_Dirt"
    },
    {
      "x": -15,
      "y": 9,
      "z": 6,
      "name": "Soil_Dirt"
    },
    {
      "x": -15,
      "y": 10,
      "z": 6,
      "name": "Soil_Grass"
    },
    {
      "x": -15,
      "y": 0,
      "z": 7,
      "name": "Soil_Dirt"
    },
    {
      "x": -15,
      "y": 1,
      "z": 7,
      "name": "Soil_Dirt"
    },
    {
      "x": -15,
      "y": 2,
      "z": 7,
      "name": "Soil_Dirt"
    },
    {
      "x": -15,
      "y": 3,
      "z": 7,
      "name": "Soil_Dirt"
    },
    {
      "x": -15,
      "y": 4,
      "z": 7,
      "name": "Soil_Dirt"
    },
    {
      "x": -15,
      "y": 5,
      "z": 7,
      "name": "Soil_Dirt"
    },
    {
      "x": -15,
      "y": 6,
      "z": 7,
      "name": "Soil_Dirt"
    },
    {
      "x": -15,
      "y": 7,
      "z": 7,
      "name": "Soil_Dirt"
    },
    {
      "x": -15,
      "y": 8,
      "z": 7,
      "name": "Soil_Grass"
    },
    {
      "x": -15,
      "y": 0,
      "z": 8,
      "name": "Soil_Dirt"
    },
    {
      "x": -15,
      "y": 1,
      "z": 8,
      "name": "Soil_Dirt"
    },
    {
      "x": -15,
      "y": 2,
      "z": 8,
      "name": "Soil_Dirt"
    },
    {
      "x": -15,
      "y": 3,
      "z": 8,
      "name": "Soil_Dirt"
    },
    {
      "x": -15,
      "y": 4,
      "z": 8,
      "name": "Soil_Dirt"
    },
    {
      "x": -15,
      "y": 5,
      "z": 8,
      "name": "Soil_Dirt"
    },
    {
      "x": -15,
      "y": 6,
      "z": 8,
      "name": "Soil_Dirt"
    },
    {
      "x": -15,
      "y": 7,
      "z": 8,
      "name": "Soil_Dirt"
    },
    {
      "x": -15,
      "y": 8,
      "z": 8,
      "name": "Soil_Grass"
    },
    {
      "x": -15,
      "y": 0,
      "z": 9,
      "name": "Soil_Dirt"
    },
    {
      "x": -15,
      "y": 1,
      "z": 9,
      "name": "Soil_Dirt"
    },
    {
      "x": -15,
      "y": 2,
      "z": 9,
      "name": "Soil_Dirt"
    },
    {
      "x": -15,
      "y": 3,
      "z": 9,
      "name": "Soil_Dirt"
    },
    {
      "x": -15,
      "y": 4,
      "z": 9,
      "name": "Soil_Dirt"
    },
    {
      "x": -15,
      "y": 5,
      "z": 9,
      "name": "Soil_Dirt"
    },
    {
      "x": -15,
      "y": 6,
      "z": 9,
      "name": "Soil_Dirt"
    },
    {
      "x": -15,
      "y": 7,
      "z": 9,
      "name": "Soil_Dirt"
    },
    {
      "x": -15,
      "y": 8,
      "z": 9,
      "name": "Soil_Grass"
    },
    {
      "x": -15,
      "y": 9,
      "z": 9,
      "name": "Plant_Grass_Jungle_Tall",
      "support": 15
    },
    {
      "x": -15,
      "y": 0,
      "z": 10,
      "name": "Soil_Dirt"
    },
    {
      "x": -15,
      "y": 1,
      "z": 10,
      "name": "Soil_Dirt"
    },
    {
      "x": -15,
      "y": 2,
      "z": 10,
      "name": "Soil_Dirt"
    },
    {
      "x": -15,
      "y": 3,
      "z": 10,
      "name": "Soil_Dirt"
    },
    {
      "x": -15,
      "y": 4,
      "z": 10,
      "name": "Soil_Dirt"
    },
    {
      "x": -15,
      "y": 5,
      "z": 10,
      "name": "Soil_Dirt"
    },
    {
      "x": -15,
      "y": 6,
      "z": 10,
      "name": "Soil_Dirt"
    },
    {
      "x": -15,
      "y": 7,
      "z": 10,
      "name": "Soil_Dirt"
    },
    {
      "x": -15,
      "y": 8,
      "z": 10,
      "name": "Soil_Dirt"
    },
    {
      "x": -15,
      "y": 9,
      "z": 10,
      "name": "Soil_Grass"
    },
    {
      "x": -15,
      "y": 10,
      "z": 10,
      "name": "Plant_Grass_Jungle_Tall",
      "support": 15
    },
    {
      "x": -15,
      "y": 0,
      "z": 11,
      "name": "Soil_Dirt"
    },
    {
      "x": -15,
      "y": 1,
      "z": 11,
      "name": "Soil_Dirt"
    },
    {
      "x": -15,
      "y": 2,
      "z": 11,
      "name": "Soil_Dirt"
    },
    {
      "x": -15,
      "y": 3,
      "z": 11,
      "name": "Soil_Dirt"
    },
    {
      "x": -15,
      "y": 4,
      "z": 11,
      "name": "Soil_Dirt"
    },
    {
      "x": -15,
      "y": 5,
      "z": 11,
      "name": "Soil_Dirt"
    },
    {
      "x": -15,
      "y": 6,
      "z": 11,
      "name": "Soil_Dirt"
    },
    {
      "x": -15,
      "y": 7,
      "z": 11,
      "name": "Soil_Dirt"
    },
    {
      "x": -15,
      "y": 8,
      "z": 11,
      "name": "Soil_Dirt"
    },
    {
      "x": -15,
      "y": 9,
      "z": 11,
      "name": "Soil_Grass"
    },
    {
      "x": -15,
      "y": 0,
      "z": 12,
      "name": "Soil_Dirt"
    },
    {
      "x": -15,
      "y": 1,
      "z": 12,
      "name": "Soil_Dirt"
    },
    {
      "x": -15,
      "y": 2,
      "z": 12,
      "name": "Soil_Dirt"
    },
    {
      "x": -15,
      "y": 3,
      "z": 12,
      "name": "Soil_Dirt"
    },
    {
      "x": -15,
      "y": 4,
      "z": 12,
      "name": "Soil_Dirt"
    },
    {
      "x": -15,
      "y": 5,
      "z": 12,
      "name": "Soil_Dirt"
    },
    {
      "x": -15,
      "y": 6,
      "z": 12,
      "name": "Soil_Dirt"
    },
    {
      "x": -15,
      "y": 7,
      "z": 12,
      "name": "Soil_Dirt"
    },
    {
      "x": -15,
      "y": 8,
      "z": 12,
      "name": "Soil_Dirt"
    },
    {
      "x": -15,
      "y": 9,
      "z": 12,
      "name": "Soil_Grass"
    },
    {
      "x": -15,
      "y": 0,
      "z": 13,
      "name": "Soil_Dirt"
    },
    {
      "x": -15,
      "y": 1,
      "z": 13,
      "name": "Soil_Dirt"
    },
    {
      "x": -15,
      "y": 2,
      "z": 13,
      "name": "Soil_Dirt"
    },
    {
      "x": -15,
      "y": 3,
      "z": 13,
      "name": "Soil_Dirt"
    },
    {
      "x": -15,
      "y": 4,
      "z": 13,
      "name": "Soil_Dirt"
    },
    {
      "x": -15,
      "y": 5,
      "z": 13,
      "name": "Soil_Dirt"
    },
    {
      "x": -15,
      "y": 6,
      "z": 13,
      "name": "Soil_Dirt"
    },
    {
      "x": -15,
      "y": 7,
      "z": 13,
      "name": "Soil_Dirt"
    },
    {
      "x": -15,
      "y": 8,
      "z": 13,
      "name": "Soil_Dirt"
    },
    {
      "x": -15,
      "y": 9,
      "z": 13,
      "name": "Soil_Grass"
    },
    {
      "x": -15,
      "y": 0,
      "z": 14,
      "name": "Soil_Dirt"
    },
    {
      "x": -15,
      "y": 1,
      "z": 14,
      "name": "Soil_Dirt"
    },
    {
      "x": -15,
      "y": 2,
      "z": 14,
      "name": "Soil_Dirt"
    },
    {
      "x": -15,
      "y": 3,
      "z": 14,
      "name": "Soil_Dirt"
    },
    {
      "x": -15,
      "y": 4,
      "z": 14,
      "name": "Soil_Dirt"
    },
    {
      "x": -15,
      "y": 5,
      "z": 14,
      "name": "Soil_Dirt"
    },
    {
      "x": -15,
      "y": 6,
      "z": 14,
      "name": "Soil_Dirt"
    },
    {
      "x": -15,
      "y": 7,
      "z": 14,
      "name": "Soil_Dirt"
    },
    {
      "x": -15,
      "y": 8,
      "z": 14,
      "name": "Soil_Grass"
    },
    {
      "x": -15,
      "y": 0,
      "z": 15,
      "name": "Soil_Dirt"
    },
    {
      "x": -15,
      "y": 1,
      "z": 15,
      "name": "Soil_Dirt"
    },
    {
      "x": -15,
      "y": 2,
      "z": 15,
      "name": "Soil_Dirt"
    },
    {
      "x": -15,
      "y": 3,
      "z": 15,
      "name": "Soil_Dirt"
    },
    {
      "x": -15,
      "y": 4,
      "z": 15,
      "name": "Soil_Dirt"
    },
    {
      "x": -15,
      "y": 5,
      "z": 15,
      "name": "Soil_Dirt"
    },
    {
      "x": -15,
      "y": 6,
      "z": 15,
      "name": "Soil_Dirt"
    },
    {
      "x": -15,
      "y": 7,
      "z": 15,
      "name": "Soil_Dirt"
    },
    {
      "x": -15,
      "y": 8,
      "z": 15,
      "name": "Soil_Grass"
    },
    {
      "x": -15,
      "y": 21,
      "z": 15,
      "name": "Rock_Shale_Brick_Smooth_Half",
      "rotation": 7
    },
    {
      "x": -15,
      "y": 22,
      "z": 15,
      "name": "Rock_Shale_Brick_Smooth_Half",
      "rotation": 7
    },
    {
      "x": -15,
      "y": 0,
      "z": 16,
      "name": "Soil_Dirt"
    },
    {
      "x": -15,
      "y": 1,
      "z": 16,
      "name": "Soil_Dirt"
    },
    {
      "x": -15,
      "y": 2,
      "z": 16,
      "name": "Soil_Dirt"
    },
    {
      "x": -15,
      "y": 3,
      "z": 16,
      "name": "Soil_Dirt"
    },
    {
      "x": -15,
      "y": 4,
      "z": 16,
      "name": "Soil_Dirt"
    },
    {
      "x": -15,
      "y": 5,
      "z": 16,
      "name": "Soil_Dirt"
    },
    {
      "x": -15,
      "y": 6,
      "z": 16,
      "name": "Soil_Dirt"
    },
    {
      "x": -15,
      "y": 7,
      "z": 16,
      "name": "Soil_Dirt"
    },
    {
      "x": -15,
      "y": 8,
      "z": 16,
      "name": "Soil_Grass"
    },
    {
      "x": -15,
      "y": 9,
      "z": 16,
      "name": "Plant_Grass_Jungle_Tall",
      "support": 15
    },
    {
      "x": -15,
      "y": 22,
      "z": 16,
      "name": "Rock_Shale_Brick_Smooth_Half",
      "rotation": 7
    },
    {
      "x": -15,
      "y": 23,
      "z": 16,
      "name": "Rock_Shale_Brick_Smooth_Half",
      "rotation": 7
    },
    {
      "x": -15,
      "y": 0,
      "z": 17,
      "name": "Soil_Dirt"
    },
    {
      "x": -15,
      "y": 1,
      "z": 17,
      "name": "Soil_Dirt"
    },
    {
      "x": -15,
      "y": 2,
      "z": 17,
      "name": "Soil_Dirt"
    },
    {
      "x": -15,
      "y": 3,
      "z": 17,
      "name": "Soil_Dirt"
    },
    {
      "x": -15,
      "y": 4,
      "z": 17,
      "name": "Soil_Dirt"
    },
    {
      "x": -15,
      "y": 5,
      "z": 17,
      "name": "Soil_Dirt"
    },
    {
      "x": -15,
      "y": 6,
      "z": 17,
      "name": "Soil_Dirt"
    },
    {
      "x": -15,
      "y": 7,
      "z": 17,
      "name": "Soil_Dirt"
    },
    {
      "x": -15,
      "y": 8,
      "z": 17,
      "name": "Soil_Dirt"
    },
    {
      "x": -15,
      "y": 9,
      "z": 17,
      "name": "Soil_Grass"
    },
    {
      "x": -15,
      "y": 10,
      "z": 17,
      "name": "Plant_Grass_Jungle_Tall",
      "support": 15
    },
    {
      "x": -15,
      "y": 22,
      "z": 17,
      "name": "Rock_Shale_Brick_Smooth_Half",
      "rotation": 7
    },
    {
      "x": -15,
      "y": 23,
      "z": 17,
      "name": "Rock_Shale_Brick_Smooth_Half",
      "rotation": 7
    },
    {
      "x": -15,
      "y": 24,
      "z": 17,
      "name": "Rock_Shale_Brick_Smooth_Half",
      "rotation": 7
    },
    {
      "x": -15,
      "y": 0,
      "z": 18,
      "name": "Soil_Dirt"
    },
    {
      "x": -15,
      "y": 1,
      "z": 18,
      "name": "Soil_Dirt"
    },
    {
      "x": -15,
      "y": 2,
      "z": 18,
      "name": "Soil_Dirt"
    },
    {
      "x": -15,
      "y": 3,
      "z": 18,
      "name": "Soil_Dirt"
    },
    {
      "x": -15,
      "y": 4,
      "z": 18,
      "name": "Soil_Dirt"
    },
    {
      "x": -15,
      "y": 5,
      "z": 18,
      "name": "Soil_Dirt"
    },
    {
      "x": -15,
      "y": 6,
      "z": 18,
      "name": "Soil_Dirt"
    },
    {
      "x": -15,
      "y": 7,
      "z": 18,
      "name": "Soil_Dirt"
    },
    {
      "x": -15,
      "y": 8,
      "z": 18,
      "name": "Soil_Dirt"
    },
    {
      "x": -15,
      "y": 9,
      "z": 18,
      "name": "Soil_Grass"
    },
    {
      "x": -15,
      "y": 10,
      "z": 18,
      "name": "Plant_Grass_Sharp_Tall",
      "support": 15
    },
    {
      "x": -15,
      "y": 11,
      "z": 18,
      "name": "Plant_Grass_Sharp_Tall",
      "filler": 1024
    },
    {
      "x": -15,
      "y": 23,
      "z": 18,
      "name": "Rock_Shale_Brick_Smooth_Half",
      "rotation": 7
    },
    {
      "x": -15,
      "y": 24,
      "z": 18,
      "name": "Rock_Shale_Brick_Smooth_Half",
      "rotation": 7
    },
    {
      "x": -15,
      "y": 25,
      "z": 18,
      "name": "Rock_Shale_Brick_Smooth_Half",
      "rotation": 7
    },
    {
      "x": -15,
      "y": 0,
      "z": 19,
      "name": "Soil_Dirt"
    },
    {
      "x": -15,
      "y": 1,
      "z": 19,
      "name": "Soil_Dirt"
    },
    {
      "x": -15,
      "y": 2,
      "z": 19,
      "name": "Soil_Dirt"
    },
    {
      "x": -15,
      "y": 3,
      "z": 19,
      "name": "Soil_Dirt"
    },
    {
      "x": -15,
      "y": 4,
      "z": 19,
      "name": "Soil_Dirt"
    },
    {
      "x": -15,
      "y": 5,
      "z": 19,
      "name": "Soil_Dirt"
    },
    {
      "x": -15,
      "y": 6,
      "z": 19,
      "name": "Soil_Dirt"
    },
    {
      "x": -15,
      "y": 7,
      "z": 19,
      "name": "Soil_Dirt"
    },
    {
      "x": -15,
      "y": 8,
      "z": 19,
      "name": "Soil_Grass"
    },
    {
      "x": -15,
      "y": 24,
      "z": 19,
      "name": "Rock_Shale_Brick_Smooth_Half",
      "rotation": 7
    },
    {
      "x": -15,
      "y": 25,
      "z": 19,
      "name": "Rock_Shale_Brick_Smooth_Half",
      "rotation": 7
    },
    {
      "x": -15,
      "y": 26,
      "z": 19,
      "name": "Rock_Shale_Brick_Smooth_Half",
      "rotation": 7
    },
    {
      "x": -15,
      "y": 0,
      "z": 20,
      "name": "Soil_Dirt"
    },
    {
      "x": -15,
      "y": 1,
      "z": 20,
      "name": "Soil_Dirt"
    },
    {
      "x": -15,
      "y": 2,
      "z": 20,
      "name": "Soil_Dirt"
    },
    {
      "x": -15,
      "y": 3,
      "z": 20,
      "name": "Soil_Dirt"
    },
    {
      "x": -15,
      "y": 4,
      "z": 20,
      "name": "Soil_Dirt"
    },
    {
      "x": -15,
      "y": 5,
      "z": 20,
      "name": "Soil_Dirt"
    },
    {
      "x": -15,
      "y": 6,
      "z": 20,
      "name": "Soil_Dirt"
    },
    {
      "x": -15,
      "y": 7,
      "z": 20,
      "name": "Soil_Grass"
    },
    {
      "x": -15,
      "y": 0,
      "z": 21,
      "name": "Soil_Dirt"
    },
    {
      "x": -15,
      "y": 1,
      "z": 21,
      "name": "Soil_Dirt"
    },
    {
      "x": -15,
      "y": 2,
      "z": 21,
      "name": "Soil_Dirt"
    },
    {
      "x": -15,
      "y": 3,
      "z": 21,
      "name": "Soil_Dirt"
    },
    {
      "x": -15,
      "y": 4,
      "z": 21,
      "name": "Soil_Dirt"
    },
    {
      "x": -15,
      "y": 5,
      "z": 21,
      "name": "Soil_Dirt"
    },
    {
      "x": -15,
      "y": 6,
      "z": 21,
      "name": "Soil_Grass"
    },
    {
      "x": -14,
      "y": 0,
      "z": -21,
      "name": "Soil_Dirt"
    },
    {
      "x": -14,
      "y": 1,
      "z": -21,
      "name": "Soil_Dirt"
    },
    {
      "x": -14,
      "y": 2,
      "z": -21,
      "name": "Soil_Dirt"
    },
    {
      "x": -14,
      "y": 3,
      "z": -21,
      "name": "Soil_Dirt"
    },
    {
      "x": -14,
      "y": 4,
      "z": -21,
      "name": "Soil_Dirt"
    },
    {
      "x": -14,
      "y": 5,
      "z": -21,
      "name": "Soil_Dirt"
    },
    {
      "x": -14,
      "y": 6,
      "z": -21,
      "name": "Soil_Grass"
    },
    {
      "x": -14,
      "y": 0,
      "z": -20,
      "name": "Soil_Dirt"
    },
    {
      "x": -14,
      "y": 1,
      "z": -20,
      "name": "Soil_Dirt"
    },
    {
      "x": -14,
      "y": 2,
      "z": -20,
      "name": "Soil_Dirt"
    },
    {
      "x": -14,
      "y": 3,
      "z": -20,
      "name": "Soil_Dirt"
    },
    {
      "x": -14,
      "y": 4,
      "z": -20,
      "name": "Soil_Dirt"
    },
    {
      "x": -14,
      "y": 5,
      "z": -20,
      "name": "Soil_Dirt"
    },
    {
      "x": -14,
      "y": 6,
      "z": -20,
      "name": "Soil_Grass"
    },
    {
      "x": -14,
      "y": 0,
      "z": -19,
      "name": "Soil_Dirt"
    },
    {
      "x": -14,
      "y": 1,
      "z": -19,
      "name": "Soil_Dirt"
    },
    {
      "x": -14,
      "y": 2,
      "z": -19,
      "name": "Soil_Dirt"
    },
    {
      "x": -14,
      "y": 3,
      "z": -19,
      "name": "Soil_Dirt"
    },
    {
      "x": -14,
      "y": 4,
      "z": -19,
      "name": "Soil_Dirt"
    },
    {
      "x": -14,
      "y": 5,
      "z": -19,
      "name": "Soil_Dirt"
    },
    {
      "x": -14,
      "y": 6,
      "z": -19,
      "name": "Soil_Grass"
    },
    {
      "x": -14,
      "y": 0,
      "z": -18,
      "name": "Soil_Dirt"
    },
    {
      "x": -14,
      "y": 1,
      "z": -18,
      "name": "Soil_Dirt"
    },
    {
      "x": -14,
      "y": 2,
      "z": -18,
      "name": "Soil_Dirt"
    },
    {
      "x": -14,
      "y": 3,
      "z": -18,
      "name": "Soil_Dirt"
    },
    {
      "x": -14,
      "y": 4,
      "z": -18,
      "name": "Soil_Dirt"
    },
    {
      "x": -14,
      "y": 5,
      "z": -18,
      "name": "Soil_Dirt"
    },
    {
      "x": -14,
      "y": 6,
      "z": -18,
      "name": "Soil_Dirt"
    },
    {
      "x": -14,
      "y": 7,
      "z": -18,
      "name": "Soil_Grass"
    },
    {
      "x": -14,
      "y": 0,
      "z": -17,
      "name": "Soil_Dirt"
    },
    {
      "x": -14,
      "y": 1,
      "z": -17,
      "name": "Soil_Dirt"
    },
    {
      "x": -14,
      "y": 2,
      "z": -17,
      "name": "Soil_Dirt"
    },
    {
      "x": -14,
      "y": 3,
      "z": -17,
      "name": "Soil_Dirt"
    },
    {
      "x": -14,
      "y": 4,
      "z": -17,
      "name": "Soil_Dirt"
    },
    {
      "x": -14,
      "y": 5,
      "z": -17,
      "name": "Soil_Dirt"
    },
    {
      "x": -14,
      "y": 6,
      "z": -17,
      "name": "Soil_Dirt"
    },
    {
      "x": -14,
      "y": 7,
      "z": -17,
      "name": "Soil_Grass"
    },
    {
      "x": -14,
      "y": 0,
      "z": -16,
      "name": "Soil_Dirt"
    },
    {
      "x": -14,
      "y": 1,
      "z": -16,
      "name": "Soil_Dirt"
    },
    {
      "x": -14,
      "y": 2,
      "z": -16,
      "name": "Soil_Dirt"
    },
    {
      "x": -14,
      "y": 3,
      "z": -16,
      "name": "Soil_Dirt"
    },
    {
      "x": -14,
      "y": 4,
      "z": -16,
      "name": "Soil_Dirt"
    },
    {
      "x": -14,
      "y": 5,
      "z": -16,
      "name": "Soil_Dirt"
    },
    {
      "x": -14,
      "y": 6,
      "z": -16,
      "name": "Soil_Dirt"
    },
    {
      "x": -14,
      "y": 7,
      "z": -16,
      "name": "Soil_Grass"
    },
    {
      "x": -14,
      "y": 0,
      "z": -15,
      "name": "Soil_Dirt"
    },
    {
      "x": -14,
      "y": 1,
      "z": -15,
      "name": "Soil_Dirt"
    },
    {
      "x": -14,
      "y": 2,
      "z": -15,
      "name": "Soil_Dirt"
    },
    {
      "x": -14,
      "y": 3,
      "z": -15,
      "name": "Soil_Dirt"
    },
    {
      "x": -14,
      "y": 4,
      "z": -15,
      "name": "Soil_Dirt"
    },
    {
      "x": -14,
      "y": 5,
      "z": -15,
      "name": "Soil_Dirt"
    },
    {
      "x": -14,
      "y": 6,
      "z": -15,
      "name": "Soil_Dirt"
    },
    {
      "x": -14,
      "y": 7,
      "z": -15,
      "name": "Soil_Grass"
    },
    {
      "x": -14,
      "y": 0,
      "z": -14,
      "name": "Soil_Dirt"
    },
    {
      "x": -14,
      "y": 1,
      "z": -14,
      "name": "Soil_Dirt"
    },
    {
      "x": -14,
      "y": 2,
      "z": -14,
      "name": "Soil_Dirt"
    },
    {
      "x": -14,
      "y": 3,
      "z": -14,
      "name": "Soil_Dirt"
    },
    {
      "x": -14,
      "y": 4,
      "z": -14,
      "name": "Soil_Dirt"
    },
    {
      "x": -14,
      "y": 5,
      "z": -14,
      "name": "Soil_Dirt"
    },
    {
      "x": -14,
      "y": 6,
      "z": -14,
      "name": "Soil_Dirt"
    },
    {
      "x": -14,
      "y": 7,
      "z": -14,
      "name": "Soil_Dirt"
    },
    {
      "x": -14,
      "y": 8,
      "z": -14,
      "name": "Soil_Grass"
    },
    {
      "x": -14,
      "y": 0,
      "z": -13,
      "name": "Soil_Dirt"
    },
    {
      "x": -14,
      "y": 1,
      "z": -13,
      "name": "Soil_Dirt"
    },
    {
      "x": -14,
      "y": 2,
      "z": -13,
      "name": "Soil_Dirt"
    },
    {
      "x": -14,
      "y": 3,
      "z": -13,
      "name": "Soil_Dirt"
    },
    {
      "x": -14,
      "y": 4,
      "z": -13,
      "name": "Soil_Dirt"
    },
    {
      "x": -14,
      "y": 5,
      "z": -13,
      "name": "Soil_Dirt"
    },
    {
      "x": -14,
      "y": 6,
      "z": -13,
      "name": "Soil_Dirt"
    },
    {
      "x": -14,
      "y": 7,
      "z": -13,
      "name": "Soil_Dirt"
    },
    {
      "x": -14,
      "y": 8,
      "z": -13,
      "name": "Soil_Dirt"
    },
    {
      "x": -14,
      "y": 9,
      "z": -13,
      "name": "Soil_Grass"
    },
    {
      "x": -14,
      "y": 10,
      "z": -13,
      "name": "Plant_Grass_Jungle_Tall",
      "support": 15
    },
    {
      "x": -14,
      "y": 0,
      "z": -12,
      "name": "Soil_Dirt"
    },
    {
      "x": -14,
      "y": 1,
      "z": -12,
      "name": "Soil_Dirt"
    },
    {
      "x": -14,
      "y": 2,
      "z": -12,
      "name": "Soil_Dirt"
    },
    {
      "x": -14,
      "y": 3,
      "z": -12,
      "name": "Soil_Dirt"
    },
    {
      "x": -14,
      "y": 4,
      "z": -12,
      "name": "Soil_Dirt"
    },
    {
      "x": -14,
      "y": 5,
      "z": -12,
      "name": "Soil_Dirt"
    },
    {
      "x": -14,
      "y": 6,
      "z": -12,
      "name": "Soil_Dirt"
    },
    {
      "x": -14,
      "y": 7,
      "z": -12,
      "name": "Soil_Dirt"
    },
    {
      "x": -14,
      "y": 8,
      "z": -12,
      "name": "Soil_Grass"
    },
    {
      "x": -14,
      "y": 0,
      "z": -11,
      "name": "Soil_Dirt"
    },
    {
      "x": -14,
      "y": 1,
      "z": -11,
      "name": "Soil_Dirt"
    },
    {
      "x": -14,
      "y": 2,
      "z": -11,
      "name": "Soil_Dirt"
    },
    {
      "x": -14,
      "y": 3,
      "z": -11,
      "name": "Soil_Dirt"
    },
    {
      "x": -14,
      "y": 4,
      "z": -11,
      "name": "Soil_Dirt"
    },
    {
      "x": -14,
      "y": 5,
      "z": -11,
      "name": "Soil_Dirt"
    },
    {
      "x": -14,
      "y": 6,
      "z": -11,
      "name": "Soil_Dirt"
    },
    {
      "x": -14,
      "y": 7,
      "z": -11,
      "name": "Soil_Dirt"
    },
    {
      "x": -14,
      "y": 8,
      "z": -11,
      "name": "Soil_Grass"
    },
    {
      "x": -14,
      "y": 0,
      "z": -10,
      "name": "Soil_Dirt"
    },
    {
      "x": -14,
      "y": 1,
      "z": -10,
      "name": "Soil_Dirt"
    },
    {
      "x": -14,
      "y": 2,
      "z": -10,
      "name": "Soil_Dirt"
    },
    {
      "x": -14,
      "y": 3,
      "z": -10,
      "name": "Soil_Dirt"
    },
    {
      "x": -14,
      "y": 4,
      "z": -10,
      "name": "Soil_Dirt"
    },
    {
      "x": -14,
      "y": 5,
      "z": -10,
      "name": "Soil_Dirt"
    },
    {
      "x": -14,
      "y": 6,
      "z": -10,
      "name": "Soil_Dirt"
    },
    {
      "x": -14,
      "y": 7,
      "z": -10,
      "name": "Soil_Dirt"
    },
    {
      "x": -14,
      "y": 8,
      "z": -10,
      "name": "Soil_Grass"
    },
    {
      "x": -14,
      "y": 0,
      "z": -9,
      "name": "Soil_Dirt"
    },
    {
      "x": -14,
      "y": 1,
      "z": -9,
      "name": "Soil_Dirt"
    },
    {
      "x": -14,
      "y": 2,
      "z": -9,
      "name": "Soil_Dirt"
    },
    {
      "x": -14,
      "y": 3,
      "z": -9,
      "name": "Soil_Dirt"
    },
    {
      "x": -14,
      "y": 4,
      "z": -9,
      "name": "Soil_Dirt"
    },
    {
      "x": -14,
      "y": 5,
      "z": -9,
      "name": "Soil_Dirt"
    },
    {
      "x": -14,
      "y": 6,
      "z": -9,
      "name": "Soil_Dirt"
    },
    {
      "x": -14,
      "y": 7,
      "z": -9,
      "name": "Soil_Dirt"
    },
    {
      "x": -14,
      "y": 8,
      "z": -9,
      "name": "Soil_Dirt"
    },
    {
      "x": -14,
      "y": 9,
      "z": -9,
      "name": "Soil_Grass"
    },
    {
      "x": -14,
      "y": 10,
      "z": -9,
      "name": "Plant_Grass_Sharp_Tall",
      "support": 15
    },
    {
      "x": -14,
      "y": 11,
      "z": -9,
      "name": "Plant_Grass_Sharp_Tall",
      "filler": 1024
    },
    {
      "x": -14,
      "y": 0,
      "z": -8,
      "name": "Soil_Dirt"
    },
    {
      "x": -14,
      "y": 1,
      "z": -8,
      "name": "Soil_Dirt"
    },
    {
      "x": -14,
      "y": 2,
      "z": -8,
      "name": "Soil_Dirt"
    },
    {
      "x": -14,
      "y": 3,
      "z": -8,
      "name": "Soil_Dirt"
    },
    {
      "x": -14,
      "y": 4,
      "z": -8,
      "name": "Soil_Dirt"
    },
    {
      "x": -14,
      "y": 5,
      "z": -8,
      "name": "Soil_Dirt"
    },
    {
      "x": -14,
      "y": 6,
      "z": -8,
      "name": "Soil_Dirt"
    },
    {
      "x": -14,
      "y": 7,
      "z": -8,
      "name": "Soil_Dirt"
    },
    {
      "x": -14,
      "y": 8,
      "z": -8,
      "name": "Soil_Dirt"
    },
    {
      "x": -14,
      "y": 9,
      "z": -8,
      "name": "Soil_Grass"
    },
    {
      "x": -14,
      "y": 10,
      "z": -8,
      "name": "Plant_Grass_Sharp_Tall",
      "support": 15
    },
    {
      "x": -14,
      "y": 11,
      "z": -8,
      "name": "Plant_Grass_Sharp_Tall",
      "filler": 1024
    },
    {
      "x": -14,
      "y": 24,
      "z": -8,
      "name": "Rock_Shale_Brick_Stairs",
      "rotation": 24
    },
    {
      "x": -14,
      "y": 0,
      "z": -7,
      "name": "Soil_Dirt"
    },
    {
      "x": -14,
      "y": 1,
      "z": -7,
      "name": "Soil_Dirt"
    },
    {
      "x": -14,
      "y": 2,
      "z": -7,
      "name": "Soil_Dirt"
    },
    {
      "x": -14,
      "y": 3,
      "z": -7,
      "name": "Soil_Dirt"
    },
    {
      "x": -14,
      "y": 4,
      "z": -7,
      "name": "Soil_Dirt"
    },
    {
      "x": -14,
      "y": 5,
      "z": -7,
      "name": "Soil_Dirt"
    },
    {
      "x": -14,
      "y": 6,
      "z": -7,
      "name": "Soil_Dirt"
    },
    {
      "x": -14,
      "y": 7,
      "z": -7,
      "name": "Soil_Dirt"
    },
    {
      "x": -14,
      "y": 8,
      "z": -7,
      "name": "Soil_Dirt"
    },
    {
      "x": -14,
      "y": 9,
      "z": -7,
      "name": "Soil_Dirt"
    },
    {
      "x": -14,
      "y": 10,
      "z": -7,
      "name": "Soil_Dirt"
    },
    {
      "x": -14,
      "y": 11,
      "z": -7,
      "name": "Soil_Grass"
    },
    {
      "x": -14,
      "y": 12,
      "z": -7,
      "name": "Plant_Grass_Sharp_Tall",
      "support": 15
    },
    {
      "x": -14,
      "y": 13,
      "z": -7,
      "name": "Plant_Grass_Sharp_Tall",
      "filler": 1024
    },
    {
      "x": -14,
      "y": 23,
      "z": -7,
      "name": "Rock_Shale_Brick_Smooth_Half",
      "rotation": 6
    },
    {
      "x": -14,
      "y": 0,
      "z": -6,
      "name": "Soil_Dirt"
    },
    {
      "x": -14,
      "y": 1,
      "z": -6,
      "name": "Soil_Dirt"
    },
    {
      "x": -14,
      "y": 2,
      "z": -6,
      "name": "Soil_Dirt"
    },
    {
      "x": -14,
      "y": 3,
      "z": -6,
      "name": "Soil_Dirt"
    },
    {
      "x": -14,
      "y": 4,
      "z": -6,
      "name": "Soil_Dirt"
    },
    {
      "x": -14,
      "y": 5,
      "z": -6,
      "name": "Soil_Dirt"
    },
    {
      "x": -14,
      "y": 6,
      "z": -6,
      "name": "Soil_Dirt"
    },
    {
      "x": -14,
      "y": 7,
      "z": -6,
      "name": "Soil_Dirt"
    },
    {
      "x": -14,
      "y": 8,
      "z": -6,
      "name": "Soil_Dirt"
    },
    {
      "x": -14,
      "y": 9,
      "z": -6,
      "name": "Soil_Dirt"
    },
    {
      "x": -14,
      "y": 10,
      "z": -6,
      "name": "Soil_Dirt"
    },
    {
      "x": -14,
      "y": 11,
      "z": -6,
      "name": "Soil_Grass"
    },
    {
      "x": -14,
      "y": 22,
      "z": -6,
      "name": "Rock_Shale_Brick_Smooth_Half",
      "rotation": 6
    },
    {
      "x": -14,
      "y": 0,
      "z": -5,
      "name": "Soil_Dirt"
    },
    {
      "x": -14,
      "y": 1,
      "z": -5,
      "name": "Soil_Dirt"
    },
    {
      "x": -14,
      "y": 2,
      "z": -5,
      "name": "Soil_Dirt"
    },
    {
      "x": -14,
      "y": 3,
      "z": -5,
      "name": "Soil_Dirt"
    },
    {
      "x": -14,
      "y": 4,
      "z": -5,
      "name": "Soil_Dirt"
    },
    {
      "x": -14,
      "y": 5,
      "z": -5,
      "name": "Soil_Dirt"
    },
    {
      "x": -14,
      "y": 6,
      "z": -5,
      "name": "Soil_Dirt"
    },
    {
      "x": -14,
      "y": 7,
      "z": -5,
      "name": "Soil_Dirt"
    },
    {
      "x": -14,
      "y": 8,
      "z": -5,
      "name": "Soil_Dirt"
    },
    {
      "x": -14,
      "y": 9,
      "z": -5,
      "name": "Soil_Dirt"
    },
    {
      "x": -14,
      "y": 10,
      "z": -5,
      "name": "Soil_Dirt"
    },
    {
      "x": -14,
      "y": 11,
      "z": -5,
      "name": "Soil_Grass"
    },
    {
      "x": -14,
      "y": 20,
      "z": -5,
      "name": "Rock_Shale_Brick_Smooth_Half",
      "rotation": 7
    },
    {
      "x": -14,
      "y": 21,
      "z": -5,
      "name": "Rock_Shale_Brick_Smooth_Half",
      "rotation": 7
    },
    {
      "x": -14,
      "y": 0,
      "z": -4,
      "name": "Soil_Dirt"
    },
    {
      "x": -14,
      "y": 1,
      "z": -4,
      "name": "Soil_Dirt"
    },
    {
      "x": -14,
      "y": 2,
      "z": -4,
      "name": "Soil_Dirt"
    },
    {
      "x": -14,
      "y": 3,
      "z": -4,
      "name": "Soil_Dirt"
    },
    {
      "x": -14,
      "y": 4,
      "z": -4,
      "name": "Soil_Dirt"
    },
    {
      "x": -14,
      "y": 5,
      "z": -4,
      "name": "Soil_Dirt"
    },
    {
      "x": -14,
      "y": 6,
      "z": -4,
      "name": "Soil_Dirt"
    },
    {
      "x": -14,
      "y": 7,
      "z": -4,
      "name": "Soil_Dirt"
    },
    {
      "x": -14,
      "y": 8,
      "z": -4,
      "name": "Soil_Dirt"
    },
    {
      "x": -14,
      "y": 9,
      "z": -4,
      "name": "Soil_Dirt"
    },
    {
      "x": -14,
      "y": 10,
      "z": -4,
      "name": "Soil_Grass"
    },
    {
      "x": -14,
      "y": 11,
      "z": -4,
      "name": "Plant_Grass_Sharp_Tall",
      "support": 15
    },
    {
      "x": -14,
      "y": 12,
      "z": -4,
      "name": "Plant_Grass_Sharp_Tall",
      "filler": 1024
    },
    {
      "x": -14,
      "y": 20,
      "z": -4,
      "name": "Rock_Shale_Brick_Smooth_Half",
      "rotation": 7
    },
    {
      "x": -14,
      "y": 0,
      "z": -3,
      "name": "Soil_Dirt"
    },
    {
      "x": -14,
      "y": 1,
      "z": -3,
      "name": "Soil_Dirt"
    },
    {
      "x": -14,
      "y": 2,
      "z": -3,
      "name": "Soil_Dirt"
    },
    {
      "x": -14,
      "y": 3,
      "z": -3,
      "name": "Soil_Dirt"
    },
    {
      "x": -14,
      "y": 4,
      "z": -3,
      "name": "Soil_Dirt"
    },
    {
      "x": -14,
      "y": 5,
      "z": -3,
      "name": "Soil_Dirt"
    },
    {
      "x": -14,
      "y": 6,
      "z": -3,
      "name": "Soil_Dirt"
    },
    {
      "x": -14,
      "y": 7,
      "z": -3,
      "name": "Soil_Dirt"
    },
    {
      "x": -14,
      "y": 8,
      "z": -3,
      "name": "Soil_Dirt"
    },
    {
      "x": -14,
      "y": 9,
      "z": -3,
      "name": "Soil_Dirt"
    },
    {
      "x": -14,
      "y": 10,
      "z": -3,
      "name": "Soil_Grass"
    },
    {
      "x": -14,
      "y": 11,
      "z": -3,
      "name": "Plant_Grass_Sharp_Tall",
      "support": 15
    },
    {
      "x": -14,
      "y": 12,
      "z": -3,
      "name": "Plant_Grass_Sharp_Tall",
      "filler": 1024
    },
    {
      "x": -14,
      "y": 0,
      "z": -2,
      "name": "Soil_Dirt"
    },
    {
      "x": -14,
      "y": 1,
      "z": -2,
      "name": "Soil_Dirt"
    },
    {
      "x": -14,
      "y": 2,
      "z": -2,
      "name": "Soil_Dirt"
    },
    {
      "x": -14,
      "y": 3,
      "z": -2,
      "name": "Soil_Dirt"
    },
    {
      "x": -14,
      "y": 4,
      "z": -2,
      "name": "Soil_Dirt"
    },
    {
      "x": -14,
      "y": 5,
      "z": -2,
      "name": "Soil_Dirt"
    },
    {
      "x": -14,
      "y": 6,
      "z": -2,
      "name": "Soil_Dirt"
    },
    {
      "x": -14,
      "y": 7,
      "z": -2,
      "name": "Soil_Dirt"
    },
    {
      "x": -14,
      "y": 8,
      "z": -2,
      "name": "Soil_Dirt"
    },
    {
      "x": -14,
      "y": 9,
      "z": -2,
      "name": "Soil_Dirt"
    },
    {
      "x": -14,
      "y": 10,
      "z": -2,
      "name": "Soil_Grass"
    },
    {
      "x": -14,
      "y": 11,
      "z": -2,
      "name": "Plant_Grass_Sharp_Tall",
      "support": 15
    },
    {
      "x": -14,
      "y": 12,
      "z": -2,
      "name": "Plant_Grass_Sharp_Tall",
      "filler": 1024
    },
    {
      "x": -14,
      "y": 19,
      "z": -2,
      "name": "Rock_Shale_Brick_Smooth_Half",
      "rotation": 7
    },
    {
      "x": -14,
      "y": 20,
      "z": -2,
      "name": "Rock_Shale_Brick_Smooth_Half",
      "rotation": 7
    },
    {
      "x": -14,
      "y": 0,
      "z": -1,
      "name": "Soil_Dirt"
    },
    {
      "x": -14,
      "y": 1,
      "z": -1,
      "name": "Soil_Dirt"
    },
    {
      "x": -14,
      "y": 2,
      "z": -1,
      "name": "Soil_Dirt"
    },
    {
      "x": -14,
      "y": 3,
      "z": -1,
      "name": "Soil_Dirt"
    },
    {
      "x": -14,
      "y": 4,
      "z": -1,
      "name": "Soil_Dirt"
    },
    {
      "x": -14,
      "y": 5,
      "z": -1,
      "name": "Soil_Dirt"
    },
    {
      "x": -14,
      "y": 6,
      "z": -1,
      "name": "Soil_Dirt"
    },
    {
      "x": -14,
      "y": 7,
      "z": -1,
      "name": "Soil_Dirt"
    },
    {
      "x": -14,
      "y": 8,
      "z": -1,
      "name": "Soil_Dirt"
    },
    {
      "x": -14,
      "y": 9,
      "z": -1,
      "name": "Soil_Dirt"
    },
    {
      "x": -14,
      "y": 10,
      "z": -1,
      "name": "Soil_Grass"
    },
    {
      "x": -14,
      "y": 11,
      "z": -1,
      "name": "Plant_Grass_Sharp_Overgrown",
      "support": 15
    },
    {
      "x": -14,
      "y": 12,
      "z": -1,
      "name": "Plant_Grass_Sharp_Overgrown",
      "filler": 1024
    },
    {
      "x": -14,
      "y": 0,
      "z": 0,
      "name": "Soil_Dirt"
    },
    {
      "x": -14,
      "y": 1,
      "z": 0,
      "name": "Soil_Dirt"
    },
    {
      "x": -14,
      "y": 2,
      "z": 0,
      "name": "Soil_Dirt"
    },
    {
      "x": -14,
      "y": 3,
      "z": 0,
      "name": "Soil_Dirt"
    },
    {
      "x": -14,
      "y": 4,
      "z": 0,
      "name": "Soil_Dirt"
    },
    {
      "x": -14,
      "y": 5,
      "z": 0,
      "name": "Soil_Dirt"
    },
    {
      "x": -14,
      "y": 6,
      "z": 0,
      "name": "Soil_Dirt"
    },
    {
      "x": -14,
      "y": 7,
      "z": 0,
      "name": "Soil_Dirt"
    },
    {
      "x": -14,
      "y": 8,
      "z": 0,
      "name": "Soil_Dirt"
    },
    {
      "x": -14,
      "y": 9,
      "z": 0,
      "name": "Soil_Grass"
    },
    {
      "x": -14,
      "y": 10,
      "z": 0,
      "name": "Plant_Grass_Sharp_Overgrown",
      "support": 15
    },
    {
      "x": -14,
      "y": 11,
      "z": 0,
      "name": "Plant_Grass_Sharp_Overgrown",
      "filler": 1024
    },
    {
      "x": -14,
      "y": 0,
      "z": 1,
      "name": "Soil_Dirt"
    },
    {
      "x": -14,
      "y": 1,
      "z": 1,
      "name": "Soil_Dirt"
    },
    {
      "x": -14,
      "y": 2,
      "z": 1,
      "name": "Soil_Dirt"
    },
    {
      "x": -14,
      "y": 3,
      "z": 1,
      "name": "Soil_Dirt"
    },
    {
      "x": -14,
      "y": 4,
      "z": 1,
      "name": "Soil_Dirt"
    },
    {
      "x": -14,
      "y": 5,
      "z": 1,
      "name": "Soil_Dirt"
    },
    {
      "x": -14,
      "y": 6,
      "z": 1,
      "name": "Soil_Dirt"
    },
    {
      "x": -14,
      "y": 7,
      "z": 1,
      "name": "Soil_Dirt"
    },
    {
      "x": -14,
      "y": 8,
      "z": 1,
      "name": "Soil_Grass"
    },
    {
      "x": -14,
      "y": 0,
      "z": 2,
      "name": "Soil_Dirt"
    },
    {
      "x": -14,
      "y": 1,
      "z": 2,
      "name": "Soil_Dirt"
    },
    {
      "x": -14,
      "y": 2,
      "z": 2,
      "name": "Soil_Dirt"
    },
    {
      "x": -14,
      "y": 3,
      "z": 2,
      "name": "Soil_Dirt"
    },
    {
      "x": -14,
      "y": 4,
      "z": 2,
      "name": "Soil_Dirt"
    },
    {
      "x": -14,
      "y": 5,
      "z": 2,
      "name": "Soil_Dirt"
    },
    {
      "x": -14,
      "y": 6,
      "z": 2,
      "name": "Soil_Dirt"
    },
    {
      "x": -14,
      "y": 7,
      "z": 2,
      "name": "Soil_Dirt"
    },
    {
      "x": -14,
      "y": 8,
      "z": 2,
      "name": "Soil_Grass"
    },
    {
      "x": -14,
      "y": 9,
      "z": 2,
      "name": "Plant_Grass_Jungle_Tall",
      "support": 15
    },
    {
      "x": -14,
      "y": 0,
      "z": 3,
      "name": "Soil_Dirt"
    },
    {
      "x": -14,
      "y": 1,
      "z": 3,
      "name": "Soil_Dirt"
    },
    {
      "x": -14,
      "y": 2,
      "z": 3,
      "name": "Soil_Dirt"
    },
    {
      "x": -14,
      "y": 3,
      "z": 3,
      "name": "Soil_Dirt"
    },
    {
      "x": -14,
      "y": 4,
      "z": 3,
      "name": "Soil_Dirt"
    },
    {
      "x": -14,
      "y": 5,
      "z": 3,
      "name": "Soil_Dirt"
    },
    {
      "x": -14,
      "y": 6,
      "z": 3,
      "name": "Soil_Dirt"
    },
    {
      "x": -14,
      "y": 7,
      "z": 3,
      "name": "Soil_Dirt"
    },
    {
      "x": -14,
      "y": 8,
      "z": 3,
      "name": "Soil_Grass"
    },
    {
      "x": -14,
      "y": 9,
      "z": 3,
      "name": "Plant_Grass_Jungle_Tall",
      "support": 15
    },
    {
      "x": -14,
      "y": 0,
      "z": 4,
      "name": "Soil_Dirt"
    },
    {
      "x": -14,
      "y": 1,
      "z": 4,
      "name": "Soil_Dirt"
    },
    {
      "x": -14,
      "y": 2,
      "z": 4,
      "name": "Soil_Dirt"
    },
    {
      "x": -14,
      "y": 3,
      "z": 4,
      "name": "Soil_Dirt"
    },
    {
      "x": -14,
      "y": 4,
      "z": 4,
      "name": "Soil_Dirt"
    },
    {
      "x": -14,
      "y": 5,
      "z": 4,
      "name": "Soil_Dirt"
    },
    {
      "x": -14,
      "y": 6,
      "z": 4,
      "name": "Soil_Dirt"
    },
    {
      "x": -14,
      "y": 7,
      "z": 4,
      "name": "Soil_Dirt"
    },
    {
      "x": -14,
      "y": 8,
      "z": 4,
      "name": "Soil_Dirt"
    },
    {
      "x": -14,
      "y": 9,
      "z": 4,
      "name": "Soil_Dirt"
    },
    {
      "x": -14,
      "y": 10,
      "z": 4,
      "name": "Soil_Grass"
    },
    {
      "x": -14,
      "y": 0,
      "z": 5,
      "name": "Soil_Dirt"
    },
    {
      "x": -14,
      "y": 1,
      "z": 5,
      "name": "Soil_Dirt"
    },
    {
      "x": -14,
      "y": 2,
      "z": 5,
      "name": "Soil_Dirt"
    },
    {
      "x": -14,
      "y": 3,
      "z": 5,
      "name": "Soil_Dirt"
    },
    {
      "x": -14,
      "y": 4,
      "z": 5,
      "name": "Soil_Dirt"
    },
    {
      "x": -14,
      "y": 5,
      "z": 5,
      "name": "Soil_Dirt"
    },
    {
      "x": -14,
      "y": 6,
      "z": 5,
      "name": "Soil_Dirt"
    },
    {
      "x": -14,
      "y": 7,
      "z": 5,
      "name": "Soil_Dirt"
    },
    {
      "x": -14,
      "y": 8,
      "z": 5,
      "name": "Soil_Dirt"
    },
    {
      "x": -14,
      "y": 9,
      "z": 5,
      "name": "Soil_Dirt"
    },
    {
      "x": -14,
      "y": 10,
      "z": 5,
      "name": "Soil_Grass"
    },
    {
      "x": -14,
      "y": 0,
      "z": 6,
      "name": "Soil_Dirt"
    },
    {
      "x": -14,
      "y": 1,
      "z": 6,
      "name": "Soil_Dirt"
    },
    {
      "x": -14,
      "y": 2,
      "z": 6,
      "name": "Soil_Dirt"
    },
    {
      "x": -14,
      "y": 3,
      "z": 6,
      "name": "Soil_Dirt"
    },
    {
      "x": -14,
      "y": 4,
      "z": 6,
      "name": "Soil_Dirt"
    },
    {
      "x": -14,
      "y": 5,
      "z": 6,
      "name": "Soil_Dirt"
    },
    {
      "x": -14,
      "y": 6,
      "z": 6,
      "name": "Soil_Dirt"
    },
    {
      "x": -14,
      "y": 7,
      "z": 6,
      "name": "Soil_Dirt"
    },
    {
      "x": -14,
      "y": 8,
      "z": 6,
      "name": "Soil_Dirt"
    },
    {
      "x": -14,
      "y": 9,
      "z": 6,
      "name": "Soil_Dirt"
    },
    {
      "x": -14,
      "y": 10,
      "z": 6,
      "name": "Soil_Grass"
    },
    {
      "x": -14,
      "y": 0,
      "z": 7,
      "name": "Soil_Dirt"
    },
    {
      "x": -14,
      "y": 1,
      "z": 7,
      "name": "Soil_Dirt"
    },
    {
      "x": -14,
      "y": 2,
      "z": 7,
      "name": "Soil_Dirt"
    },
    {
      "x": -14,
      "y": 3,
      "z": 7,
      "name": "Soil_Dirt"
    },
    {
      "x": -14,
      "y": 4,
      "z": 7,
      "name": "Soil_Dirt"
    },
    {
      "x": -14,
      "y": 5,
      "z": 7,
      "name": "Soil_Dirt"
    },
    {
      "x": -14,
      "y": 6,
      "z": 7,
      "name": "Soil_Dirt"
    },
    {
      "x": -14,
      "y": 7,
      "z": 7,
      "name": "Soil_Dirt"
    },
    {
      "x": -14,
      "y": 8,
      "z": 7,
      "name": "Soil_Dirt"
    },
    {
      "x": -14,
      "y": 9,
      "z": 7,
      "name": "Soil_Dirt"
    },
    {
      "x": -14,
      "y": 10,
      "z": 7,
      "name": "Soil_Grass"
    },
    {
      "x": -14,
      "y": 0,
      "z": 8,
      "name": "Soil_Dirt"
    },
    {
      "x": -14,
      "y": 1,
      "z": 8,
      "name": "Soil_Dirt"
    },
    {
      "x": -14,
      "y": 2,
      "z": 8,
      "name": "Soil_Dirt"
    },
    {
      "x": -14,
      "y": 3,
      "z": 8,
      "name": "Soil_Dirt"
    },
    {
      "x": -14,
      "y": 4,
      "z": 8,
      "name": "Soil_Dirt"
    },
    {
      "x": -14,
      "y": 5,
      "z": 8,
      "name": "Soil_Dirt"
    },
    {
      "x": -14,
      "y": 6,
      "z": 8,
      "name": "Soil_Dirt"
    },
    {
      "x": -14,
      "y": 7,
      "z": 8,
      "name": "Soil_Dirt"
    },
    {
      "x": -14,
      "y": 8,
      "z": 8,
      "name": "Soil_Dirt"
    },
    {
      "x": -14,
      "y": 9,
      "z": 8,
      "name": "Soil_Dirt"
    },
    {
      "x": -14,
      "y": 10,
      "z": 8,
      "name": "Soil_Grass"
    },
    {
      "x": -14,
      "y": 11,
      "z": 8,
      "name": "Plant_Grass_Jungle_Tall",
      "support": 15
    },
    {
      "x": -14,
      "y": 0,
      "z": 9,
      "name": "Soil_Dirt"
    },
    {
      "x": -14,
      "y": 1,
      "z": 9,
      "name": "Soil_Dirt"
    },
    {
      "x": -14,
      "y": 2,
      "z": 9,
      "name": "Soil_Dirt"
    },
    {
      "x": -14,
      "y": 3,
      "z": 9,
      "name": "Soil_Dirt"
    },
    {
      "x": -14,
      "y": 4,
      "z": 9,
      "name": "Soil_Dirt"
    },
    {
      "x": -14,
      "y": 5,
      "z": 9,
      "name": "Soil_Dirt"
    },
    {
      "x": -14,
      "y": 6,
      "z": 9,
      "name": "Soil_Dirt"
    },
    {
      "x": -14,
      "y": 7,
      "z": 9,
      "name": "Soil_Dirt"
    },
    {
      "x": -14,
      "y": 8,
      "z": 9,
      "name": "Soil_Dirt"
    },
    {
      "x": -14,
      "y": 9,
      "z": 9,
      "name": "Soil_Grass"
    },
    {
      "x": -14,
      "y": 0,
      "z": 10,
      "name": "Soil_Dirt"
    },
    {
      "x": -14,
      "y": 1,
      "z": 10,
      "name": "Soil_Dirt"
    },
    {
      "x": -14,
      "y": 2,
      "z": 10,
      "name": "Soil_Dirt"
    },
    {
      "x": -14,
      "y": 3,
      "z": 10,
      "name": "Soil_Dirt"
    },
    {
      "x": -14,
      "y": 4,
      "z": 10,
      "name": "Soil_Dirt"
    },
    {
      "x": -14,
      "y": 5,
      "z": 10,
      "name": "Soil_Dirt"
    },
    {
      "x": -14,
      "y": 6,
      "z": 10,
      "name": "Soil_Dirt"
    },
    {
      "x": -14,
      "y": 7,
      "z": 10,
      "name": "Soil_Dirt"
    },
    {
      "x": -14,
      "y": 8,
      "z": 10,
      "name": "Soil_Dirt"
    },
    {
      "x": -14,
      "y": 9,
      "z": 10,
      "name": "Soil_Grass"
    },
    {
      "x": -14,
      "y": 0,
      "z": 11,
      "name": "Soil_Dirt"
    },
    {
      "x": -14,
      "y": 1,
      "z": 11,
      "name": "Soil_Dirt"
    },
    {
      "x": -14,
      "y": 2,
      "z": 11,
      "name": "Soil_Dirt"
    },
    {
      "x": -14,
      "y": 3,
      "z": 11,
      "name": "Soil_Dirt"
    },
    {
      "x": -14,
      "y": 4,
      "z": 11,
      "name": "Soil_Dirt"
    },
    {
      "x": -14,
      "y": 5,
      "z": 11,
      "name": "Soil_Dirt"
    },
    {
      "x": -14,
      "y": 6,
      "z": 11,
      "name": "Soil_Dirt"
    },
    {
      "x": -14,
      "y": 7,
      "z": 11,
      "name": "Soil_Dirt"
    },
    {
      "x": -14,
      "y": 8,
      "z": 11,
      "name": "Soil_Dirt"
    },
    {
      "x": -14,
      "y": 9,
      "z": 11,
      "name": "Soil_Grass"
    },
    {
      "x": -14,
      "y": 10,
      "z": 11,
      "name": "Plant_Grass_Sharp_Tall",
      "support": 15
    },
    {
      "x": -14,
      "y": 11,
      "z": 11,
      "name": "Plant_Grass_Sharp_Tall",
      "filler": 1024
    },
    {
      "x": -14,
      "y": 0,
      "z": 12,
      "name": "Soil_Dirt"
    },
    {
      "x": -14,
      "y": 1,
      "z": 12,
      "name": "Soil_Dirt"
    },
    {
      "x": -14,
      "y": 2,
      "z": 12,
      "name": "Soil_Dirt"
    },
    {
      "x": -14,
      "y": 3,
      "z": 12,
      "name": "Soil_Dirt"
    },
    {
      "x": -14,
      "y": 4,
      "z": 12,
      "name": "Soil_Dirt"
    },
    {
      "x": -14,
      "y": 5,
      "z": 12,
      "name": "Soil_Dirt"
    },
    {
      "x": -14,
      "y": 6,
      "z": 12,
      "name": "Soil_Dirt"
    },
    {
      "x": -14,
      "y": 7,
      "z": 12,
      "name": "Soil_Dirt"
    },
    {
      "x": -14,
      "y": 8,
      "z": 12,
      "name": "Soil_Dirt"
    },
    {
      "x": -14,
      "y": 9,
      "z": 12,
      "name": "Soil_Dirt"
    },
    {
      "x": -14,
      "y": 10,
      "z": 12,
      "name": "Soil_Grass"
    },
    {
      "x": -14,
      "y": 11,
      "z": 12,
      "name": "Plant_Grass_Sharp_Tall",
      "support": 15
    },
    {
      "x": -14,
      "y": 12,
      "z": 12,
      "name": "Plant_Grass_Sharp_Tall",
      "filler": 1024
    },
    {
      "x": -14,
      "y": 0,
      "z": 13,
      "name": "Soil_Dirt"
    },
    {
      "x": -14,
      "y": 1,
      "z": 13,
      "name": "Soil_Dirt"
    },
    {
      "x": -14,
      "y": 2,
      "z": 13,
      "name": "Soil_Dirt"
    },
    {
      "x": -14,
      "y": 3,
      "z": 13,
      "name": "Soil_Dirt"
    },
    {
      "x": -14,
      "y": 4,
      "z": 13,
      "name": "Soil_Dirt"
    },
    {
      "x": -14,
      "y": 5,
      "z": 13,
      "name": "Soil_Dirt"
    },
    {
      "x": -14,
      "y": 6,
      "z": 13,
      "name": "Soil_Dirt"
    },
    {
      "x": -14,
      "y": 7,
      "z": 13,
      "name": "Soil_Dirt"
    },
    {
      "x": -14,
      "y": 8,
      "z": 13,
      "name": "Soil_Dirt"
    },
    {
      "x": -14,
      "y": 9,
      "z": 13,
      "name": "Soil_Dirt"
    },
    {
      "x": -14,
      "y": 10,
      "z": 13,
      "name": "Soil_Grass"
    },
    {
      "x": -14,
      "y": 11,
      "z": 13,
      "name": "Plant_Grass_Sharp_Overgrown",
      "support": 15
    },
    {
      "x": -14,
      "y": 12,
      "z": 13,
      "name": "Plant_Grass_Sharp_Overgrown",
      "filler": 1024
    },
    {
      "x": -14,
      "y": 0,
      "z": 14,
      "name": "Soil_Dirt"
    },
    {
      "x": -14,
      "y": 1,
      "z": 14,
      "name": "Soil_Dirt"
    },
    {
      "x": -14,
      "y": 2,
      "z": 14,
      "name": "Soil_Dirt"
    },
    {
      "x": -14,
      "y": 3,
      "z": 14,
      "name": "Soil_Dirt"
    },
    {
      "x": -14,
      "y": 4,
      "z": 14,
      "name": "Soil_Dirt"
    },
    {
      "x": -14,
      "y": 5,
      "z": 14,
      "name": "Soil_Dirt"
    },
    {
      "x": -14,
      "y": 6,
      "z": 14,
      "name": "Soil_Dirt"
    },
    {
      "x": -14,
      "y": 7,
      "z": 14,
      "name": "Soil_Dirt"
    },
    {
      "x": -14,
      "y": 8,
      "z": 14,
      "name": "Soil_Dirt"
    },
    {
      "x": -14,
      "y": 9,
      "z": 14,
      "name": "Soil_Dirt"
    },
    {
      "x": -14,
      "y": 10,
      "z": 14,
      "name": "Soil_Grass"
    },
    {
      "x": -14,
      "y": 11,
      "z": 14,
      "name": "Plant_Grass_Sharp_Tall",
      "support": 15
    },
    {
      "x": -14,
      "y": 12,
      "z": 14,
      "name": "Plant_Grass_Sharp_Tall",
      "filler": 1024
    },
    {
      "x": -14,
      "y": 19,
      "z": 14,
      "name": "Rock_Shale_Brick_Smooth_Half",
      "rotation": 7
    },
    {
      "x": -14,
      "y": 20,
      "z": 14,
      "name": "Rock_Shale_Brick_Smooth_Half",
      "rotation": 7
    },
    {
      "x": -14,
      "y": 21,
      "z": 14,
      "name": "Rock_Shale_Brick_Smooth_Half",
      "rotation": 7
    },
    {
      "x": -14,
      "y": 22,
      "z": 14,
      "name": "Rock_Shale_Brick_Smooth_Half",
      "rotation": 7
    },
    {
      "x": -14,
      "y": 0,
      "z": 15,
      "name": "Soil_Dirt"
    },
    {
      "x": -14,
      "y": 1,
      "z": 15,
      "name": "Soil_Dirt"
    },
    {
      "x": -14,
      "y": 2,
      "z": 15,
      "name": "Soil_Dirt"
    },
    {
      "x": -14,
      "y": 3,
      "z": 15,
      "name": "Soil_Dirt"
    },
    {
      "x": -14,
      "y": 4,
      "z": 15,
      "name": "Soil_Dirt"
    },
    {
      "x": -14,
      "y": 5,
      "z": 15,
      "name": "Soil_Dirt"
    },
    {
      "x": -14,
      "y": 6,
      "z": 15,
      "name": "Soil_Dirt"
    },
    {
      "x": -14,
      "y": 7,
      "z": 15,
      "name": "Soil_Dirt"
    },
    {
      "x": -14,
      "y": 8,
      "z": 15,
      "name": "Soil_Dirt"
    },
    {
      "x": -14,
      "y": 9,
      "z": 15,
      "name": "Soil_Grass"
    },
    {
      "x": -14,
      "y": 10,
      "z": 15,
      "name": "Plant_Grass_Sharp_Tall",
      "support": 15
    },
    {
      "x": -14,
      "y": 11,
      "z": 15,
      "name": "Plant_Grass_Sharp_Tall",
      "filler": 1024
    },
    {
      "x": -14,
      "y": 20,
      "z": 15,
      "name": "Rock_Shale_Brick_Smooth_Half",
      "rotation": 7
    },
    {
      "x": -14,
      "y": 21,
      "z": 15,
      "name": "Rock_Shale_Brick_Smooth_Half",
      "rotation": 7
    },
    {
      "x": -14,
      "y": 22,
      "z": 15,
      "name": "Rock_Shale_Brick_Smooth_Half",
      "rotation": 7
    },
    {
      "x": -14,
      "y": 0,
      "z": 16,
      "name": "Soil_Dirt"
    },
    {
      "x": -14,
      "y": 1,
      "z": 16,
      "name": "Soil_Dirt"
    },
    {
      "x": -14,
      "y": 2,
      "z": 16,
      "name": "Soil_Dirt"
    },
    {
      "x": -14,
      "y": 3,
      "z": 16,
      "name": "Soil_Dirt"
    },
    {
      "x": -14,
      "y": 4,
      "z": 16,
      "name": "Soil_Dirt"
    },
    {
      "x": -14,
      "y": 5,
      "z": 16,
      "name": "Soil_Dirt"
    },
    {
      "x": -14,
      "y": 6,
      "z": 16,
      "name": "Soil_Dirt"
    },
    {
      "x": -14,
      "y": 7,
      "z": 16,
      "name": "Soil_Dirt"
    },
    {
      "x": -14,
      "y": 8,
      "z": 16,
      "name": "Soil_Dirt"
    },
    {
      "x": -14,
      "y": 9,
      "z": 16,
      "name": "Soil_Dirt"
    },
    {
      "x": -14,
      "y": 10,
      "z": 16,
      "name": "Soil_Dirt"
    },
    {
      "x": -14,
      "y": 11,
      "z": 16,
      "name": "Soil_Grass"
    },
    {
      "x": -14,
      "y": 12,
      "z": 16,
      "name": "Plant_Grass_Sharp_Tall",
      "support": 15
    },
    {
      "x": -14,
      "y": 13,
      "z": 16,
      "name": "Plant_Grass_Sharp_Tall",
      "filler": 1024
    },
    {
      "x": -14,
      "y": 20,
      "z": 16,
      "name": "Rock_Shale_Brick_Smooth_Half",
      "rotation": 7
    },
    {
      "x": -14,
      "y": 21,
      "z": 16,
      "name": "Rock_Shale_Brick_Smooth_Half",
      "rotation": 7
    },
    {
      "x": -14,
      "y": 22,
      "z": 16,
      "name": "Rock_Shale_Brick_Smooth_Half",
      "rotation": 6
    },
    {
      "x": -14,
      "y": 0,
      "z": 17,
      "name": "Soil_Dirt"
    },
    {
      "x": -14,
      "y": 1,
      "z": 17,
      "name": "Soil_Dirt"
    },
    {
      "x": -14,
      "y": 2,
      "z": 17,
      "name": "Soil_Dirt"
    },
    {
      "x": -14,
      "y": 3,
      "z": 17,
      "name": "Soil_Dirt"
    },
    {
      "x": -14,
      "y": 4,
      "z": 17,
      "name": "Soil_Dirt"
    },
    {
      "x": -14,
      "y": 5,
      "z": 17,
      "name": "Soil_Dirt"
    },
    {
      "x": -14,
      "y": 6,
      "z": 17,
      "name": "Soil_Dirt"
    },
    {
      "x": -14,
      "y": 7,
      "z": 17,
      "name": "Soil_Dirt"
    },
    {
      "x": -14,
      "y": 8,
      "z": 17,
      "name": "Soil_Dirt"
    },
    {
      "x": -14,
      "y": 9,
      "z": 17,
      "name": "Soil_Dirt"
    },
    {
      "x": -14,
      "y": 10,
      "z": 17,
      "name": "Soil_Dirt"
    },
    {
      "x": -14,
      "y": 11,
      "z": 17,
      "name": "Soil_Grass"
    },
    {
      "x": -14,
      "y": 12,
      "z": 17,
      "name": "Plant_Grass_Sharp_Tall",
      "support": 15
    },
    {
      "x": -14,
      "y": 13,
      "z": 17,
      "name": "Plant_Grass_Sharp_Tall",
      "filler": 1024
    },
    {
      "x": -14,
      "y": 20,
      "z": 17,
      "name": "Rock_Shale_Brick_Smooth_Half",
      "rotation": 7
    },
    {
      "x": -14,
      "y": 21,
      "z": 17,
      "name": "Rock_Shale_Brick_Smooth_Half",
      "rotation": 7
    },
    {
      "x": -14,
      "y": 22,
      "z": 17,
      "name": "Rock_Runic_Teal_Brick_Stairs",
      "rotation": 9
    },
    {
      "x": -14,
      "y": 23,
      "z": 17,
      "name": "Rock_Shale_Brick_Smooth_Half",
      "rotation": 6
    },
    {
      "x": -14,
      "y": 0,
      "z": 18,
      "name": "Soil_Dirt"
    },
    {
      "x": -14,
      "y": 1,
      "z": 18,
      "name": "Soil_Dirt"
    },
    {
      "x": -14,
      "y": 2,
      "z": 18,
      "name": "Soil_Dirt"
    },
    {
      "x": -14,
      "y": 3,
      "z": 18,
      "name": "Soil_Dirt"
    },
    {
      "x": -14,
      "y": 4,
      "z": 18,
      "name": "Soil_Dirt"
    },
    {
      "x": -14,
      "y": 5,
      "z": 18,
      "name": "Soil_Dirt"
    },
    {
      "x": -14,
      "y": 6,
      "z": 18,
      "name": "Soil_Dirt"
    },
    {
      "x": -14,
      "y": 7,
      "z": 18,
      "name": "Soil_Dirt"
    },
    {
      "x": -14,
      "y": 8,
      "z": 18,
      "name": "Soil_Dirt"
    },
    {
      "x": -14,
      "y": 9,
      "z": 18,
      "name": "Soil_Dirt"
    },
    {
      "x": -14,
      "y": 10,
      "z": 18,
      "name": "Soil_Dirt"
    },
    {
      "x": -14,
      "y": 11,
      "z": 18,
      "name": "Soil_Grass"
    },
    {
      "x": -14,
      "y": 12,
      "z": 18,
      "name": "Plant_Grass_Sharp_Overgrown",
      "support": 15
    },
    {
      "x": -14,
      "y": 13,
      "z": 18,
      "name": "Plant_Grass_Sharp_Overgrown",
      "filler": 1024
    },
    {
      "x": -14,
      "y": 22,
      "z": 18,
      "name": "Rock_Shale_Brick_Smooth_Half",
      "rotation": 4
    },
    {
      "x": -14,
      "y": 23,
      "z": 18,
      "name": "Rock_Runic_Teal_Brick_Stairs",
      "rotation": 9
    },
    {
      "x": -14,
      "y": 24,
      "z": 18,
      "name": "Rock_Shale_Brick_Smooth_Half",
      "rotation": 6
    },
    {
      "x": -14,
      "y": 0,
      "z": 19,
      "name": "Soil_Dirt"
    },
    {
      "x": -14,
      "y": 1,
      "z": 19,
      "name": "Soil_Dirt"
    },
    {
      "x": -14,
      "y": 2,
      "z": 19,
      "name": "Soil_Dirt"
    },
    {
      "x": -14,
      "y": 3,
      "z": 19,
      "name": "Soil_Dirt"
    },
    {
      "x": -14,
      "y": 4,
      "z": 19,
      "name": "Soil_Dirt"
    },
    {
      "x": -14,
      "y": 5,
      "z": 19,
      "name": "Soil_Dirt"
    },
    {
      "x": -14,
      "y": 6,
      "z": 19,
      "name": "Soil_Dirt"
    },
    {
      "x": -14,
      "y": 7,
      "z": 19,
      "name": "Soil_Dirt"
    },
    {
      "x": -14,
      "y": 8,
      "z": 19,
      "name": "Soil_Dirt"
    },
    {
      "x": -14,
      "y": 9,
      "z": 19,
      "name": "Soil_Dirt"
    },
    {
      "x": -14,
      "y": 10,
      "z": 19,
      "name": "Soil_Grass"
    },
    {
      "x": -14,
      "y": 11,
      "z": 19,
      "name": "Plant_Grass_Sharp_Overgrown",
      "support": 15
    },
    {
      "x": -14,
      "y": 12,
      "z": 19,
      "name": "Plant_Grass_Sharp_Overgrown",
      "filler": 1024
    },
    {
      "x": -14,
      "y": 23,
      "z": 19,
      "name": "Rock_Shale_Brick_Smooth_Half",
      "rotation": 4
    },
    {
      "x": -14,
      "y": 24,
      "z": 19,
      "name": "Rock_Runic_Teal_Brick_Stairs",
      "rotation": 9
    },
    {
      "x": -14,
      "y": 25,
      "z": 19,
      "name": "Rock_Shale_Brick_Smooth_Half",
      "rotation": 6
    },
    {
      "x": -14,
      "y": 26,
      "z": 19,
      "name": "Rock_Shale_Brick_Smooth_Half",
      "rotation": 6
    },
    {
      "x": -14,
      "y": 27,
      "z": 19,
      "name": "Rock_Shale_Brick_Smooth_Half",
      "rotation": 6
    },
    {
      "x": -14,
      "y": 0,
      "z": 20,
      "name": "Soil_Dirt"
    },
    {
      "x": -14,
      "y": 1,
      "z": 20,
      "name": "Soil_Dirt"
    },
    {
      "x": -14,
      "y": 2,
      "z": 20,
      "name": "Soil_Dirt"
    },
    {
      "x": -14,
      "y": 3,
      "z": 20,
      "name": "Soil_Dirt"
    },
    {
      "x": -14,
      "y": 4,
      "z": 20,
      "name": "Soil_Dirt"
    },
    {
      "x": -14,
      "y": 5,
      "z": 20,
      "name": "Soil_Dirt"
    },
    {
      "x": -14,
      "y": 6,
      "z": 20,
      "name": "Soil_Dirt"
    },
    {
      "x": -14,
      "y": 7,
      "z": 20,
      "name": "Soil_Dirt"
    },
    {
      "x": -14,
      "y": 8,
      "z": 20,
      "name": "Soil_Dirt"
    },
    {
      "x": -14,
      "y": 9,
      "z": 20,
      "name": "Soil_Grass"
    },
    {
      "x": -14,
      "y": 10,
      "z": 20,
      "name": "Plant_Grass_Sharp_Overgrown",
      "support": 15
    },
    {
      "x": -14,
      "y": 11,
      "z": 20,
      "name": "Plant_Grass_Sharp_Overgrown",
      "filler": 1024
    },
    {
      "x": -14,
      "y": 24,
      "z": 20,
      "name": "Rock_Shale_Brick_Stairs",
      "rotation": 25
    },
    {
      "x": -14,
      "y": 25,
      "z": 20,
      "name": "Rock_Shale_Brick_Stairs",
      "rotation": 25
    },
    {
      "x": -14,
      "y": 26,
      "z": 20,
      "name": "Rock_Shale_Brick_Stairs",
      "rotation": 25
    },
    {
      "x": -14,
      "y": 27,
      "z": 20,
      "name": "Rock_Shale_Brick_Stairs",
      "rotation": 25
    },
    {
      "x": -14,
      "y": 28,
      "z": 20,
      "name": "Rock_Shale_Brick_Stairs",
      "rotation": 25
    },
    {
      "x": -14,
      "y": 29,
      "z": 20,
      "name": "Rock_Shale_Brick_Beam"
    },
    {
      "x": -14,
      "y": 0,
      "z": 21,
      "name": "Soil_Dirt"
    },
    {
      "x": -14,
      "y": 1,
      "z": 21,
      "name": "Soil_Dirt"
    },
    {
      "x": -14,
      "y": 2,
      "z": 21,
      "name": "Soil_Dirt"
    },
    {
      "x": -14,
      "y": 3,
      "z": 21,
      "name": "Soil_Dirt"
    },
    {
      "x": -14,
      "y": 4,
      "z": 21,
      "name": "Soil_Dirt"
    },
    {
      "x": -14,
      "y": 5,
      "z": 21,
      "name": "Soil_Dirt"
    },
    {
      "x": -14,
      "y": 6,
      "z": 21,
      "name": "Soil_Dirt"
    },
    {
      "x": -14,
      "y": 7,
      "z": 21,
      "name": "Soil_Grass"
    },
    {
      "x": -13,
      "y": 0,
      "z": -21,
      "name": "Soil_Dirt"
    },
    {
      "x": -13,
      "y": 1,
      "z": -21,
      "name": "Soil_Dirt"
    },
    {
      "x": -13,
      "y": 2,
      "z": -21,
      "name": "Soil_Dirt"
    },
    {
      "x": -13,
      "y": 3,
      "z": -21,
      "name": "Soil_Dirt"
    },
    {
      "x": -13,
      "y": 4,
      "z": -21,
      "name": "Soil_Dirt"
    },
    {
      "x": -13,
      "y": 5,
      "z": -21,
      "name": "Soil_Dirt"
    },
    {
      "x": -13,
      "y": 6,
      "z": -21,
      "name": "Soil_Grass"
    },
    {
      "x": -13,
      "y": 0,
      "z": -20,
      "name": "Soil_Dirt"
    },
    {
      "x": -13,
      "y": 1,
      "z": -20,
      "name": "Soil_Dirt"
    },
    {
      "x": -13,
      "y": 2,
      "z": -20,
      "name": "Soil_Dirt"
    },
    {
      "x": -13,
      "y": 3,
      "z": -20,
      "name": "Soil_Dirt"
    },
    {
      "x": -13,
      "y": 4,
      "z": -20,
      "name": "Soil_Dirt"
    },
    {
      "x": -13,
      "y": 5,
      "z": -20,
      "name": "Soil_Dirt"
    },
    {
      "x": -13,
      "y": 6,
      "z": -20,
      "name": "Soil_Dirt"
    },
    {
      "x": -13,
      "y": 7,
      "z": -20,
      "name": "Soil_Grass"
    },
    {
      "x": -13,
      "y": 0,
      "z": -19,
      "name": "Soil_Dirt"
    },
    {
      "x": -13,
      "y": 1,
      "z": -19,
      "name": "Soil_Dirt"
    },
    {
      "x": -13,
      "y": 2,
      "z": -19,
      "name": "Soil_Dirt"
    },
    {
      "x": -13,
      "y": 3,
      "z": -19,
      "name": "Soil_Dirt"
    },
    {
      "x": -13,
      "y": 4,
      "z": -19,
      "name": "Soil_Dirt"
    },
    {
      "x": -13,
      "y": 5,
      "z": -19,
      "name": "Soil_Dirt"
    },
    {
      "x": -13,
      "y": 6,
      "z": -19,
      "name": "Soil_Dirt"
    },
    {
      "x": -13,
      "y": 7,
      "z": -19,
      "name": "Soil_Grass"
    },
    {
      "x": -13,
      "y": 0,
      "z": -18,
      "name": "Soil_Dirt"
    },
    {
      "x": -13,
      "y": 1,
      "z": -18,
      "name": "Soil_Dirt"
    },
    {
      "x": -13,
      "y": 2,
      "z": -18,
      "name": "Soil_Dirt"
    },
    {
      "x": -13,
      "y": 3,
      "z": -18,
      "name": "Soil_Dirt"
    },
    {
      "x": -13,
      "y": 4,
      "z": -18,
      "name": "Soil_Dirt"
    },
    {
      "x": -13,
      "y": 5,
      "z": -18,
      "name": "Soil_Dirt"
    },
    {
      "x": -13,
      "y": 6,
      "z": -18,
      "name": "Soil_Dirt"
    },
    {
      "x": -13,
      "y": 7,
      "z": -18,
      "name": "Soil_Grass"
    },
    {
      "x": -13,
      "y": 0,
      "z": -17,
      "name": "Soil_Dirt"
    },
    {
      "x": -13,
      "y": 1,
      "z": -17,
      "name": "Soil_Dirt"
    },
    {
      "x": -13,
      "y": 2,
      "z": -17,
      "name": "Soil_Dirt"
    },
    {
      "x": -13,
      "y": 3,
      "z": -17,
      "name": "Soil_Dirt"
    },
    {
      "x": -13,
      "y": 4,
      "z": -17,
      "name": "Soil_Dirt"
    },
    {
      "x": -13,
      "y": 5,
      "z": -17,
      "name": "Soil_Dirt"
    },
    {
      "x": -13,
      "y": 6,
      "z": -17,
      "name": "Soil_Dirt"
    },
    {
      "x": -13,
      "y": 7,
      "z": -17,
      "name": "Soil_Grass"
    },
    {
      "x": -13,
      "y": 0,
      "z": -16,
      "name": "Soil_Dirt"
    },
    {
      "x": -13,
      "y": 1,
      "z": -16,
      "name": "Soil_Dirt"
    },
    {
      "x": -13,
      "y": 2,
      "z": -16,
      "name": "Soil_Dirt"
    },
    {
      "x": -13,
      "y": 3,
      "z": -16,
      "name": "Soil_Dirt"
    },
    {
      "x": -13,
      "y": 4,
      "z": -16,
      "name": "Soil_Dirt"
    },
    {
      "x": -13,
      "y": 5,
      "z": -16,
      "name": "Soil_Dirt"
    },
    {
      "x": -13,
      "y": 6,
      "z": -16,
      "name": "Soil_Dirt"
    },
    {
      "x": -13,
      "y": 7,
      "z": -16,
      "name": "Soil_Dirt"
    },
    {
      "x": -13,
      "y": 8,
      "z": -16,
      "name": "Soil_Grass"
    },
    {
      "x": -13,
      "y": 0,
      "z": -15,
      "name": "Soil_Dirt"
    },
    {
      "x": -13,
      "y": 1,
      "z": -15,
      "name": "Soil_Dirt"
    },
    {
      "x": -13,
      "y": 2,
      "z": -15,
      "name": "Soil_Dirt"
    },
    {
      "x": -13,
      "y": 3,
      "z": -15,
      "name": "Soil_Dirt"
    },
    {
      "x": -13,
      "y": 4,
      "z": -15,
      "name": "Soil_Dirt"
    },
    {
      "x": -13,
      "y": 5,
      "z": -15,
      "name": "Soil_Dirt"
    },
    {
      "x": -13,
      "y": 6,
      "z": -15,
      "name": "Soil_Dirt"
    },
    {
      "x": -13,
      "y": 7,
      "z": -15,
      "name": "Soil_Dirt"
    },
    {
      "x": -13,
      "y": 8,
      "z": -15,
      "name": "Soil_Grass"
    },
    {
      "x": -13,
      "y": 0,
      "z": -14,
      "name": "Soil_Dirt"
    },
    {
      "x": -13,
      "y": 1,
      "z": -14,
      "name": "Soil_Dirt"
    },
    {
      "x": -13,
      "y": 2,
      "z": -14,
      "name": "Soil_Dirt"
    },
    {
      "x": -13,
      "y": 3,
      "z": -14,
      "name": "Soil_Dirt"
    },
    {
      "x": -13,
      "y": 4,
      "z": -14,
      "name": "Soil_Dirt"
    },
    {
      "x": -13,
      "y": 5,
      "z": -14,
      "name": "Soil_Dirt"
    },
    {
      "x": -13,
      "y": 6,
      "z": -14,
      "name": "Soil_Dirt"
    },
    {
      "x": -13,
      "y": 7,
      "z": -14,
      "name": "Soil_Dirt"
    },
    {
      "x": -13,
      "y": 8,
      "z": -14,
      "name": "Soil_Dirt"
    },
    {
      "x": -13,
      "y": 9,
      "z": -14,
      "name": "Soil_Grass"
    },
    {
      "x": -13,
      "y": 0,
      "z": -13,
      "name": "Soil_Dirt"
    },
    {
      "x": -13,
      "y": 1,
      "z": -13,
      "name": "Soil_Dirt"
    },
    {
      "x": -13,
      "y": 2,
      "z": -13,
      "name": "Soil_Dirt"
    },
    {
      "x": -13,
      "y": 3,
      "z": -13,
      "name": "Soil_Dirt"
    },
    {
      "x": -13,
      "y": 4,
      "z": -13,
      "name": "Soil_Dirt"
    },
    {
      "x": -13,
      "y": 5,
      "z": -13,
      "name": "Soil_Dirt"
    },
    {
      "x": -13,
      "y": 6,
      "z": -13,
      "name": "Soil_Dirt"
    },
    {
      "x": -13,
      "y": 7,
      "z": -13,
      "name": "Soil_Dirt"
    },
    {
      "x": -13,
      "y": 8,
      "z": -13,
      "name": "Soil_Dirt"
    },
    {
      "x": -13,
      "y": 9,
      "z": -13,
      "name": "Soil_Dirt"
    },
    {
      "x": -13,
      "y": 10,
      "z": -13,
      "name": "Soil_Grass"
    },
    {
      "x": -13,
      "y": 0,
      "z": -12,
      "name": "Soil_Dirt"
    },
    {
      "x": -13,
      "y": 1,
      "z": -12,
      "name": "Soil_Dirt"
    },
    {
      "x": -13,
      "y": 2,
      "z": -12,
      "name": "Soil_Dirt"
    },
    {
      "x": -13,
      "y": 3,
      "z": -12,
      "name": "Soil_Dirt"
    },
    {
      "x": -13,
      "y": 4,
      "z": -12,
      "name": "Soil_Dirt"
    },
    {
      "x": -13,
      "y": 5,
      "z": -12,
      "name": "Soil_Dirt"
    },
    {
      "x": -13,
      "y": 6,
      "z": -12,
      "name": "Soil_Dirt"
    },
    {
      "x": -13,
      "y": 7,
      "z": -12,
      "name": "Soil_Dirt"
    },
    {
      "x": -13,
      "y": 8,
      "z": -12,
      "name": "Soil_Dirt"
    },
    {
      "x": -13,
      "y": 9,
      "z": -12,
      "name": "Soil_Grass"
    },
    {
      "x": -13,
      "y": 0,
      "z": -11,
      "name": "Soil_Dirt"
    },
    {
      "x": -13,
      "y": 1,
      "z": -11,
      "name": "Soil_Dirt"
    },
    {
      "x": -13,
      "y": 2,
      "z": -11,
      "name": "Soil_Dirt"
    },
    {
      "x": -13,
      "y": 3,
      "z": -11,
      "name": "Soil_Dirt"
    },
    {
      "x": -13,
      "y": 4,
      "z": -11,
      "name": "Soil_Dirt"
    },
    {
      "x": -13,
      "y": 5,
      "z": -11,
      "name": "Soil_Dirt"
    },
    {
      "x": -13,
      "y": 6,
      "z": -11,
      "name": "Soil_Dirt"
    },
    {
      "x": -13,
      "y": 7,
      "z": -11,
      "name": "Soil_Dirt"
    },
    {
      "x": -13,
      "y": 8,
      "z": -11,
      "name": "Soil_Dirt"
    },
    {
      "x": -13,
      "y": 9,
      "z": -11,
      "name": "Soil_Grass"
    },
    {
      "x": -13,
      "y": 10,
      "z": -11,
      "name": "Plant_Grass_Sharp_Tall",
      "support": 15
    },
    {
      "x": -13,
      "y": 11,
      "z": -11,
      "name": "Plant_Grass_Sharp_Tall",
      "filler": 1024
    },
    {
      "x": -13,
      "y": 0,
      "z": -10,
      "name": "Soil_Dirt"
    },
    {
      "x": -13,
      "y": 1,
      "z": -10,
      "name": "Soil_Dirt"
    },
    {
      "x": -13,
      "y": 2,
      "z": -10,
      "name": "Soil_Dirt"
    },
    {
      "x": -13,
      "y": 3,
      "z": -10,
      "name": "Soil_Dirt"
    },
    {
      "x": -13,
      "y": 4,
      "z": -10,
      "name": "Soil_Dirt"
    },
    {
      "x": -13,
      "y": 5,
      "z": -10,
      "name": "Soil_Dirt"
    },
    {
      "x": -13,
      "y": 6,
      "z": -10,
      "name": "Soil_Dirt"
    },
    {
      "x": -13,
      "y": 7,
      "z": -10,
      "name": "Soil_Dirt"
    },
    {
      "x": -13,
      "y": 8,
      "z": -10,
      "name": "Soil_Dirt"
    },
    {
      "x": -13,
      "y": 9,
      "z": -10,
      "name": "Soil_Grass"
    },
    {
      "x": -13,
      "y": 0,
      "z": -9,
      "name": "Soil_Dirt"
    },
    {
      "x": -13,
      "y": 1,
      "z": -9,
      "name": "Soil_Dirt"
    },
    {
      "x": -13,
      "y": 2,
      "z": -9,
      "name": "Soil_Dirt"
    },
    {
      "x": -13,
      "y": 3,
      "z": -9,
      "name": "Soil_Dirt"
    },
    {
      "x": -13,
      "y": 4,
      "z": -9,
      "name": "Soil_Dirt"
    },
    {
      "x": -13,
      "y": 5,
      "z": -9,
      "name": "Soil_Dirt"
    },
    {
      "x": -13,
      "y": 6,
      "z": -9,
      "name": "Soil_Dirt"
    },
    {
      "x": -13,
      "y": 7,
      "z": -9,
      "name": "Soil_Dirt"
    },
    {
      "x": -13,
      "y": 8,
      "z": -9,
      "name": "Soil_Dirt"
    },
    {
      "x": -13,
      "y": 9,
      "z": -9,
      "name": "Soil_Grass"
    },
    {
      "x": -13,
      "y": 10,
      "z": -9,
      "name": "Plant_Grass_Jungle_Tall",
      "support": 15
    },
    {
      "x": -13,
      "y": 24,
      "z": -9,
      "name": "Rock_Shale_Brick_Smooth_Half",
      "rotation": 6
    },
    {
      "x": -13,
      "y": 25,
      "z": -9,
      "name": "Rock_Shale_Brick_Smooth_Half",
      "rotation": 6
    },
    {
      "x": -13,
      "y": 26,
      "z": -9,
      "name": "Rock_Shale_Brick_Smooth_Half",
      "rotation": 6
    },
    {
      "x": -13,
      "y": 0,
      "z": -8,
      "name": "Soil_Dirt"
    },
    {
      "x": -13,
      "y": 1,
      "z": -8,
      "name": "Soil_Dirt"
    },
    {
      "x": -13,
      "y": 2,
      "z": -8,
      "name": "Soil_Dirt"
    },
    {
      "x": -13,
      "y": 3,
      "z": -8,
      "name": "Soil_Dirt"
    },
    {
      "x": -13,
      "y": 4,
      "z": -8,
      "name": "Soil_Dirt"
    },
    {
      "x": -13,
      "y": 5,
      "z": -8,
      "name": "Soil_Dirt"
    },
    {
      "x": -13,
      "y": 6,
      "z": -8,
      "name": "Soil_Dirt"
    },
    {
      "x": -13,
      "y": 7,
      "z": -8,
      "name": "Soil_Dirt"
    },
    {
      "x": -13,
      "y": 8,
      "z": -8,
      "name": "Soil_Dirt"
    },
    {
      "x": -13,
      "y": 9,
      "z": -8,
      "name": "Soil_Dirt"
    },
    {
      "x": -13,
      "y": 10,
      "z": -8,
      "name": "Soil_Grass"
    },
    {
      "x": -13,
      "y": 11,
      "z": -8,
      "name": "Plant_Grass_Sharp_Tall",
      "support": 15
    },
    {
      "x": -13,
      "y": 12,
      "z": -8,
      "name": "Plant_Grass_Sharp_Tall",
      "filler": 1024
    },
    {
      "x": -13,
      "y": 23,
      "z": -8,
      "name": "Rock_Shale_Brick_Smooth_Half",
      "rotation": 7
    },
    {
      "x": -13,
      "y": 24,
      "z": -8,
      "name": "Rock_Runic_Teal_Brick_Stairs",
      "rotation": 8
    },
    {
      "x": -13,
      "y": 25,
      "z": -8,
      "name": "Rock_Shale_Brick_Smooth_Half",
      "rotation": 5
    },
    {
      "x": -13,
      "y": 0,
      "z": -7,
      "name": "Soil_Dirt"
    },
    {
      "x": -13,
      "y": 1,
      "z": -7,
      "name": "Soil_Dirt"
    },
    {
      "x": -13,
      "y": 2,
      "z": -7,
      "name": "Soil_Dirt"
    },
    {
      "x": -13,
      "y": 3,
      "z": -7,
      "name": "Soil_Dirt"
    },
    {
      "x": -13,
      "y": 4,
      "z": -7,
      "name": "Soil_Dirt"
    },
    {
      "x": -13,
      "y": 5,
      "z": -7,
      "name": "Soil_Dirt"
    },
    {
      "x": -13,
      "y": 6,
      "z": -7,
      "name": "Soil_Dirt"
    },
    {
      "x": -13,
      "y": 7,
      "z": -7,
      "name": "Soil_Dirt"
    },
    {
      "x": -13,
      "y": 8,
      "z": -7,
      "name": "Soil_Dirt"
    },
    {
      "x": -13,
      "y": 9,
      "z": -7,
      "name": "Soil_Dirt"
    },
    {
      "x": -13,
      "y": 10,
      "z": -7,
      "name": "Soil_Dirt"
    },
    {
      "x": -13,
      "y": 11,
      "z": -7,
      "name": "Soil_Grass"
    },
    {
      "x": -13,
      "y": 24,
      "z": -7,
      "name": "Rock_Shale_Brick_Smooth"
    },
    {
      "x": -13,
      "y": 0,
      "z": -6,
      "name": "Soil_Dirt"
    },
    {
      "x": -13,
      "y": 1,
      "z": -6,
      "name": "Soil_Dirt"
    },
    {
      "x": -13,
      "y": 2,
      "z": -6,
      "name": "Soil_Dirt"
    },
    {
      "x": -13,
      "y": 3,
      "z": -6,
      "name": "Soil_Dirt"
    },
    {
      "x": -13,
      "y": 4,
      "z": -6,
      "name": "Soil_Dirt"
    },
    {
      "x": -13,
      "y": 5,
      "z": -6,
      "name": "Soil_Dirt"
    },
    {
      "x": -13,
      "y": 6,
      "z": -6,
      "name": "Soil_Dirt"
    },
    {
      "x": -13,
      "y": 7,
      "z": -6,
      "name": "Soil_Dirt"
    },
    {
      "x": -13,
      "y": 8,
      "z": -6,
      "name": "Soil_Dirt"
    },
    {
      "x": -13,
      "y": 9,
      "z": -6,
      "name": "Soil_Dirt"
    },
    {
      "x": -13,
      "y": 10,
      "z": -6,
      "name": "Soil_Dirt"
    },
    {
      "x": -13,
      "y": 11,
      "z": -6,
      "name": "Soil_Grass"
    },
    {
      "x": -13,
      "y": 12,
      "z": -6,
      "name": "Plant_Grass_Sharp_Overgrown",
      "support": 15
    },
    {
      "x": -13,
      "y": 13,
      "z": -6,
      "name": "Plant_Grass_Sharp_Overgrown",
      "filler": 1024
    },
    {
      "x": -13,
      "y": 16,
      "z": -6,
      "name": "Plant_Moss_Wall_Green_Dark",
      "support": 15,
      "rotation": 3
    },
    {
      "x": -13,
      "y": 20,
      "z": -6,
      "name": "Rock_Shale_Brick_Smooth_Half",
      "rotation": 6
    },
    {
      "x": -13,
      "y": 21,
      "z": -6,
      "name": "Rock_Shale_Brick_Smooth_Half",
      "rotation": 7
    },
    {
      "x": -13,
      "y": 22,
      "z": -6,
      "name": "Rock_Shale_Brick_Smooth_Half",
      "rotation": 7
    },
    {
      "x": -13,
      "y": 23,
      "z": -6,
      "name": "Rock_Shale_Brick_Smooth"
    },
    {
      "x": -13,
      "y": 0,
      "z": -5,
      "name": "Soil_Dirt"
    },
    {
      "x": -13,
      "y": 1,
      "z": -5,
      "name": "Soil_Dirt"
    },
    {
      "x": -13,
      "y": 2,
      "z": -5,
      "name": "Soil_Dirt"
    },
    {
      "x": -13,
      "y": 3,
      "z": -5,
      "name": "Soil_Dirt"
    },
    {
      "x": -13,
      "y": 4,
      "z": -5,
      "name": "Soil_Dirt"
    },
    {
      "x": -13,
      "y": 5,
      "z": -5,
      "name": "Soil_Dirt"
    },
    {
      "x": -13,
      "y": 6,
      "z": -5,
      "name": "Soil_Dirt"
    },
    {
      "x": -13,
      "y": 7,
      "z": -5,
      "name": "Soil_Dirt"
    },
    {
      "x": -13,
      "y": 8,
      "z": -5,
      "name": "Soil_Dirt"
    },
    {
      "x": -13,
      "y": 9,
      "z": -5,
      "name": "Soil_Dirt"
    },
    {
      "x": -13,
      "y": 10,
      "z": -5,
      "name": "Soil_Dirt"
    },
    {
      "x": -13,
      "y": 11,
      "z": -5,
      "name": "Soil_Grass"
    },
    {
      "x": -13,
      "y": 12,
      "z": -5,
      "name": "Plant_Grass_Jungle_Tall",
      "support": 15
    },
    {
      "x": -13,
      "y": 15,
      "z": -5,
      "name": "Plant_Moss_Wall_Green_Dark",
      "support": 15,
      "rotation": 3
    },
    {
      "x": -13,
      "y": 16,
      "z": -5,
      "name": "Plant_Moss_Wall_Green_Dark",
      "support": 15,
      "rotation": 3
    },
    {
      "x": -13,
      "y": 17,
      "z": -5,
      "name": "Plant_Moss_Wall_Green_Dark",
      "support": 15,
      "rotation": 3
    },
    {
      "x": -13,
      "y": 20,
      "z": -5,
      "name": "Rock_Runic_Teal_Brick_Stairs",
      "rotation": 9
    },
    {
      "x": -13,
      "y": 21,
      "z": -5,
      "name": "Rock_Shale_Brick_Smooth_Half",
      "rotation": 4
    },
    {
      "x": -13,
      "y": 22,
      "z": -5,
      "name": "Rock_Shale_Brick_Smooth_Half",
      "rotation": 5
    },
    {
      "x": -13,
      "y": 0,
      "z": -4,
      "name": "Soil_Dirt"
    },
    {
      "x": -13,
      "y": 1,
      "z": -4,
      "name": "Soil_Dirt"
    },
    {
      "x": -13,
      "y": 2,
      "z": -4,
      "name": "Soil_Dirt"
    },
    {
      "x": -13,
      "y": 3,
      "z": -4,
      "name": "Soil_Dirt"
    },
    {
      "x": -13,
      "y": 4,
      "z": -4,
      "name": "Soil_Dirt"
    },
    {
      "x": -13,
      "y": 5,
      "z": -4,
      "name": "Soil_Dirt"
    },
    {
      "x": -13,
      "y": 6,
      "z": -4,
      "name": "Soil_Dirt"
    },
    {
      "x": -13,
      "y": 7,
      "z": -4,
      "name": "Soil_Dirt"
    },
    {
      "x": -13,
      "y": 8,
      "z": -4,
      "name": "Soil_Dirt"
    },
    {
      "x": -13,
      "y": 9,
      "z": -4,
      "name": "Soil_Dirt"
    },
    {
      "x": -13,
      "y": 10,
      "z": -4,
      "name": "Soil_Dirt"
    },
    {
      "x": -13,
      "y": 11,
      "z": -4,
      "name": "Soil_Grass"
    },
    {
      "x": -13,
      "y": 12,
      "z": -4,
      "name": "Plant_Grass_Jungle_Tall",
      "support": 15
    },
    {
      "x": -13,
      "y": 13,
      "z": -4,
      "name": "Plant_Moss_Wall_Green_Dark",
      "support": 15,
      "rotation": 3
    },
    {
      "x": -13,
      "y": 14,
