{
  "version": 8,
  "blockIdVersion": 11,
  "anchorX": 0,
  "anchorY": 0,
  "anchorZ": 0,
  "blocks": [
    {
      "x": -9,
      "y": 4,
      "z": -4,
      "name": "Furniture_Crude_Platform"
    },
    {
      "x": -9,
      "y": 5,
      "z": -4,
      "name": "*Wood_Hardwood_Fence_State_Definitions_Corner",
      "rotation": 1
    },
    {
      "x": -9,
      "y": 6,
      "z": -4,
      "name": "Wood_Hardwood_Beam"
    },
    {
      "x": -9,
      "y": 7,
      "z": -4,
      "name": "Wood_Hardwood_Beam"
    },
    {
      "x": -9,
      "y": 8,
      "z": -4,
      "name": "*Wood_Tropicalwood_Roof_State_Definitions_Corner_Left",
      "rotation": 2
    },
    {
      "x": -9,
      "y": 4,
      "z": -3,
      "name": "Furniture_Crude_Platform"
    },
    {
      "x": -9,
      "y": 5,
      "z": -3,
      "name": "Wood_Hardwood_Fence",
      "rotation": 3
    },
    {
      "x": -9,
      "y": 8,
      "z": -3,
      "name": "Wood_Tropicalwood_Roof_Hollow",
      "rotation": 3
    },
    {
      "x": -9,
      "y": 4,
      "z": -2,
      "name": "Furniture_Crude_Platform"
    },
    {
      "x": -9,
      "y": 5,
      "z": -2,
      "name": "Wood_Hardwood_Fence",
      "rotation": 3
    },
    {
      "x": -9,
      "y": 8,
      "z": -2,
      "name": "Wood_Tropicalwood_Roof_Hollow",
      "rotation": 3
    },
    {
      "x": -9,
      "y": 4,
      "z": -1,
      "name": "Furniture_Crude_Platform"
    },
    {
      "x": -9,
      "y": 5,
      "z": -1,
      "name": "Wood_Hardwood_Fence",
      "rotation": 3
    },
    {
      "x": -9,
      "y": 8,
      "z": -1,
      "name": "Wood_Tropicalwood_Roof_Hollow",
      "rotation": 3
    },
    {
      "x": -9,
      "y": 4,
      "z": 0,
      "name": "Furniture_Crude_Platform"
    },
    {
      "x": -9,
      "y": 5,
      "z": 0,
      "name": "Wood_Hardwood_Fence",
      "rotation": 3
    },
    {
      "x": -9,
      "y": 8,
      "z": 0,
      "name": "Wood_Tropicalwood_Roof_Hollow",
      "rotation": 3
    },
    {
      "x": -9,
      "y": 4,
      "z": 1,
      "name": "Furniture_Crude_Platform"
    },
    {
      "x": -9,
      "y": 5,
      "z": 1,
      "name": "Wood_Hardwood_Fence",
      "rotation": 3
    },
    {
      "x": -9,
      "y": 8,
      "z": 1,
      "name": "Wood_Tropicalwood_Roof_Hollow",
      "rotation": 3
    },
    {
      "x": -9,
      "y": 4,
      "z": 2,
      "name": "Furniture_Crude_Platform"
    },
    {
      "x": -9,
      "y": 5,
      "z": 2,
      "name": "Wood_Hardwood_Fence",
      "rotation": 3
    },
    {
      "x": -9,
      "y": 8,
      "z": 2,
      "name": "Wood_Tropicalwood_Roof_Hollow",
      "rotation": 3
    },
    {
      "x": -9,
      "y": 4,
      "z": 3,
      "name": "Furniture_Crude_Platform"
    },
    {
      "x": -9,
      "y": 5,
      "z": 3,
      "name": "*Wood_Hardwood_Fence_State_Definitions_Corner",
      "rotation": 2
    },
    {
      "x": -9,
      "y": 6,
      "z": 3,
      "name": "Wood_Hardwood_Beam"
    },
    {
      "x": -9,
      "y": 7,
      "z": 3,
      "name": "Wood_Hardwood_Beam"
    },
    {
      "x": -9,
      "y": 8,
      "z": 3,
      "name": "*Wood_Tropicalwood_Roof_State_Definitions_Corner_Left",
      "rotation": 3
    },
    {
      "x": -8,
      "y": 4,
      "z": -5,
      "name": "Furniture_Crude_Platform"
    },
    {
      "x": -8,
      "y": 5,
      "z": -5,
      "name": "*Wood_Hardwood_Fence_State_Definitions_Corner",
      "rotation": 1
    },
    {
      "x": -8,
      "y": 6,
      "z": -5,
      "name": "Wood_Hardwood_Beam"
    },
    {
      "x": -8,
      "y": 7,
      "z": -5,
      "name": "Wood_Hardwood_Beam"
    },
    {
      "x": -8,
      "y": 8,
      "z": -5,
      "name": "*Wood_Tropicalwood_Roof_State_Definitions_Corner_Left",
      "rotation": 2
    },
    {
      "x": -8,
      "y": 4,
      "z": -4,
      "name": "Furniture_Crude_Platform"
    },
    {
      "x": -8,
      "y": 5,
      "z": -4,
      "name": "*Wood_Hardwood_Fence_State_Definitions_Corner",
      "rotation": 3
    },
    {
      "x": -8,
      "y": 8,
      "z": -4,
      "name": "*Wood_Tropicalwood_Roof_Hollow_State_Definitions_Inverted_Corner_Right",
      "rotation": 3
    },
    {
      "x": -8,
      "y": 4,
      "z": -3,
      "name": "Furniture_Crude_Platform",
      "rotation": 1
    },
    {
      "x": -8,
      "y": 8,
      "z": -3,
      "name": "Wood_Goldenwood_Planks_Half",
      "rotation": 8
    },
    {
      "x": -8,
      "y": 9,
      "z": -3,
      "name": "Wood_Tropicalwood_Roof_Flat",
      "rotation": 3
    },
    {
      "x": -8,
      "y": 4,
      "z": -2,
      "name": "Furniture_Crude_Platform",
      "rotation": 1
    },
    {
      "x": -8,
      "y": 8,
      "z": -2,
      "name": "Wood_Goldenwood_Planks_Half",
      "rotation": 8
    },
    {
      "x": -8,
      "y": 9,
      "z": -2,
      "name": "Wood_Tropicalwood_Roof_Flat",
      "rotation": 3
    },
    {
      "x": -8,
      "y": 4,
      "z": -1,
      "name": "Furniture_Crude_Platform",
      "rotation": 1
    },
    {
      "x": -8,
      "y": 8,
      "z": -1,
      "name": "Wood_Goldenwood_Planks_Half",
      "rotation": 8
    },
    {
      "x": -8,
      "y": 9,
      "z": -1,
      "name": "Wood_Tropicalwood_Roof_Flat",
      "rotation": 3
    },
    {
      "x": -8,
      "y": 4,
      "z": 0,
      "name": "Furniture_Crude_Platform",
      "rotation": 1
    },
    {
      "x": -8,
      "y": 8,
      "z": 0,
      "name": "Wood_Goldenwood_Planks_Half",
      "rotation": 8
    },
    {
      "x": -8,
      "y": 9,
      "z": 0,
      "name": "Wood_Tropicalwood_Roof_Flat",
      "rotation": 3
    },
    {
      "x": -8,
      "y": 4,
      "z": 1,
      "name": "Furniture_Crude_Platform",
      "rotation": 1
    },
    {
      "x": -8,
      "y": 8,
      "z": 1,
      "name": "Wood_Goldenwood_Planks_Half",
      "rotation": 8
    },
    {
      "x": -8,
      "y": 9,
      "z": 1,
      "name": "Wood_Tropicalwood_Roof_Flat",
      "rotation": 3
    },
    {
      "x": -8,
      "y": 4,
      "z": 2,
      "name": "Furniture_Crude_Platform",
      "rotation": 1
    },
    {
      "x": -8,
      "y": 8,
      "z": 2,
      "name": "Wood_Goldenwood_Planks_Half",
      "rotation": 8
    },
    {
      "x": -8,
      "y": 9,
      "z": 2,
      "name": "Wood_Tropicalwood_Roof_Flat",
      "rotation": 3
    },
    {
      "x": -8,
      "y": 4,
      "z": 3,
      "name": "Furniture_Crude_Platform",
      "rotation": 1
    },
    {
      "x": -8,
      "y": 5,
      "z": 3,
      "name": "*Wood_Hardwood_Fence_State_Definitions_Corner"
    },
    {
      "x": -8,
      "y": 8,
      "z": 3,
      "name": "*Wood_Tropicalwood_Roof_Hollow_State_Definitions_Inverted_Corner_Right"
    },
    {
      "x": -8,
      "y": 4,
      "z": 4,
      "name": "Furniture_Crude_Platform"
    },
    {
      "x": -8,
      "y": 5,
      "z": 4,
      "name": "Wood_Hardwood_Fence",
      "rotation": 3
    },
    {
      "x": -8,
      "y": 8,
      "z": 4,
      "name": "Wood_Tropicalwood_Roof_Hollow",
      "rotation": 3
    },
    {
      "x": -8,
      "y": 4,
      "z": 5,
      "name": "Furniture_Crude_Platform"
    },
    {
      "x": -8,
      "y": 5,
      "z": 5,
      "name": "*Wood_Hardwood_Fence_State_Definitions_Corner",
      "rotation": 2
    },
    {
      "x": -8,
      "y": 6,
      "z": 5,
      "name": "Wood_Hardwood_Beam"
    },
    {
      "x": -8,
      "y": 7,
      "z": 5,
      "name": "Wood_Hardwood_Beam"
    },
    {
      "x": -8,
      "y": 8,
      "z": 5,
      "name": "*Wood_Tropicalwood_Roof_State_Definitions_Corner_Left",
      "rotation": 3
    },
    {
      "x": -7,
      "y": 4,
      "z": -6,
      "name": "Furniture_Crude_Platform"
    },
    {
      "x": -7,
      "y": 5,
      "z": -6,
      "name": "*Wood_Hardwood_Fence_State_Definitions_Corner",
      "rotation": 1
    },
    {
      "x": -7,
      "y": 8,
      "z": -6,
      "name": "*Wood_Tropicalwood_Roof_Hollow_State_Definitions_Corner_Left",
      "rotation": 2
    },
    {
      "x": -7,
      "y": 4,
      "z": -5,
      "name": "Furniture_Crude_Platform",
      "rotation": 1
    },
    {
      "x": -7,
      "y": 5,
      "z": -5,
      "name": "*Wood_Hardwood_Fence_State_Definitions_Corner",
      "rotation": 3
    },
    {
      "x": -7,
      "y": 8,
      "z": -5,
      "name": "*Wood_Tropicalwood_Roof_Hollow_State_Definitions_Inverted_Corner_Right",
      "rotation": 3
    },
    {
      "x": -7,
      "y": 4,
      "z": -4,
      "name": "Furniture_Crude_Platform",
      "rotation": 1
    },
    {
      "x": -7,
      "y": 8,
      "z": -4,
      "name": "Wood_Goldenwood_Planks_Half",
      "rotation": 8
    },
    {
      "x": -7,
      "y": 9,
      "z": -4,
      "name": "Wood_Tropicalwood_Roof_Flat",
      "rotation": 3
    },
    {
      "x": -7,
      "y": 4,
      "z": -3,
      "name": "Furniture_Crude_Platform",
      "rotation": 1
    },
    {
      "x": -7,
      "y": 8,
      "z": -3,
      "name": "Wood_Goldenwood_Planks_Half",
      "rotation": 8
    },
    {
      "x": -7,
      "y": 9,
      "z": -3,
      "name": "*Wood_Hardwood_Fence_State_Definitions_Corner",
      "rotation": 1
    },
    {
      "x": -7,
      "y": 10,
      "z": -3,
      "name": "Wood_Hardwood_Beam"
    },
    {
      "x": -7,
      "y": 11,
      "z": -3,
      "name": "Wood_Hardwood_Beam"
    },
    {
      "x": -7,
      "y": 12,
      "z": -3,
      "name": "*Wood_Tropicalwood_Roof_State_Definitions_Corner_Left",
      "rotation": 2
    },
    {
      "x": -7,
      "y": 0,
      "z": -2,
      "name": "Furniture_Crude_Platform",
      "rotation": 1
    },
    {
      "x": -7,
      "y": 1,
      "z": -2,
      "name": "*Wood_Softwood_Fence_State_Definitions_Corner",
      "rotation": 1
    },
    {
      "x": -7,
      "y": 2,
      "z": -2,
      "name": "*Wood_Softwood_Fence_State_Definitions_Corner",
      "rotation": 1
    },
    {
      "x": -7,
      "y": 3,
      "z": -2,
      "name": "*Wood_Softwood_Fence_State_Definitions_Corner",
      "rotation": 1
    },
    {
      "x": -7,
      "y": 4,
      "z": -2,
      "name": "*Wood_Goldenwood_Stairs_State_Definitions_Corner_Right",
      "rotation": 8
    },
    {
      "x": -7,
      "y": 5,
      "z": -2,
      "name": "*Wood_Softwood_Fence_State_Definitions_Corner",
      "rotation": 1
    },
    {
      "x": -7,
      "y": 6,
      "z": -2,
      "name": "*Wood_Softwood_Fence_State_Definitions_Corner",
      "rotation": 1
    },
    {
      "x": -7,
      "y": 7,
      "z": -2,
      "name": "*Wood_Softwood_Fence_State_Definitions_Corner",
      "rotation": 1
    },
    {
      "x": -7,
      "y": 8,
      "z": -2,
      "name": "*Wood_Goldenwood_Stairs_State_Definitions_Corner_Left",
      "rotation": 9
    },
    {
      "x": -7,
      "y": 9,
      "z": -2,
      "name": "Wood_Hardwood_Fence",
      "rotation": 3
    },
    {
      "x": -7,
      "y": 12,
      "z": -2,
      "name": "Wood_Tropicalwood_Roof_Hollow",
      "rotation": 3
    },
    {
      "x": -7,
      "y": 0,
      "z": -1,
      "name": "Furniture_Crude_Platform",
      "rotation": 1
    },
    {
      "x": -7,
      "y": 1,
      "z": -1,
      "name": "Wood_Softwood_Fence",
      "rotation": 3
    },
    {
      "x": -7,
      "y": 2,
      "z": -1,
      "name": "Wood_Softwood_Fence",
      "rotation": 3
    },
    {
      "x": -7,
      "y": 3,
      "z": -1,
      "name": "Wood_Softwood_Fence",
      "rotation": 3
    },
    {
      "x": -7,
      "y": 4,
      "z": -1,
      "name": "Wood_Goldenwood_Stairs",
      "rotation": 9
    },
    {
      "x": -7,
      "y": 5,
      "z": -1,
      "name": "Wood_Softwood_Fence",
      "rotation": 3
    },
    {
      "x": -7,
      "y": 6,
      "z": -1,
      "name": "Wood_Softwood_Fence",
      "rotation": 3
    },
    {
      "x": -7,
      "y": 7,
      "z": -1,
      "name": "Wood_Softwood_Fence",
      "rotation": 3
    },
    {
      "x": -7,
      "y": 8,
      "z": -1,
      "name": "Wood_Goldenwood_Stairs",
      "rotation": 9
    },
    {
      "x": -7,
      "y": 9,
      "z": -1,
      "name": "Wood_Hardwood_Fence",
      "rotation": 3
    },
    {
      "x": -7,
      "y": 12,
      "z": -1,
      "name": "Wood_Tropicalwood_Roof_Hollow",
      "rotation": 3
    },
    {
      "x": -7,
      "y": 0,
      "z": 0,
      "name": "Furniture_Crude_Platform",
      "rotation": 1
    },
    {
      "x": -7,
      "y": 1,
      "z": 0,
      "name": "Wood_Softwood_Fence",
      "rotation": 3
    },
    {
      "x": -7,
      "y": 2,
      "z": 0,
      "name": "Wood_Goldenwood_Fence",
      "rotation": 3
    },
    {
      "x": -7,
      "y": 3,
      "z": 0,
      "name": "Wood_Softwood_Fence",
      "rotation": 3
    },
    {
      "x": -7,
      "y": 4,
      "z": 0,
      "name": "Wood_Goldenwood_Stairs",
      "rotation": 9
    },
    {
      "x": -7,
      "y": 5,
      "z": 0,
      "name": "Wood_Softwood_Fence",
      "rotation": 3
    },
    {
      "x": -7,
      "y": 6,
      "z": 0,
      "name": "Wood_Goldenwood_Fence",
      "rotation": 3
    },
    {
      "x": -7,
      "y": 7,
      "z": 0,
      "name": "Wood_Softwood_Fence",
      "rotation": 3
    },
    {
      "x": -7,
      "y": 8,
      "z": 0,
      "name": "Wood_Goldenwood_Stairs",
      "rotation": 9
    },
    {
      "x": -7,
      "y": 9,
      "z": 0,
      "name": "Wood_Hardwood_Fence",
      "rotation": 3
    },
    {
      "x": -7,
      "y": 12,
      "z": 0,
      "name": "Wood_Tropicalwood_Roof_Hollow",
      "rotation": 3
    },
    {
      "x": -7,
      "y": 0,
      "z": 1,
      "name": "Furniture_Crude_Platform",
      "rotation": 1
    },
    {
      "x": -7,
      "y": 1,
      "z": 1,
      "name": "Wood_Softwood_Fence",
      "rotation": 3
    },
    {
      "x": -7,
      "y": 2,
      "z": 1,
      "name": "Wood_Softwood_Fence",
      "rotation": 3
    },
    {
      "x": -7,
      "y": 3,
      "z": 1,
      "name": "Wood_Softwood_Fence",
      "rotation": 3
    },
    {
      "x": -7,
      "y": 4,
      "z": 1,
      "name": "Wood_Goldenwood_Stairs",
      "rotation": 9
    },
    {
      "x": -7,
      "y": 5,
      "z": 1,
      "name": "Wood_Softwood_Fence",
      "rotation": 3
    },
    {
      "x": -7,
      "y": 6,
      "z": 1,
      "name": "Wood_Softwood_Fence",
      "rotation": 3
    },
    {
      "x": -7,
      "y": 7,
      "z": 1,
      "name": "Wood_Softwood_Fence",
      "rotation": 3
    },
    {
      "x": -7,
      "y": 8,
      "z": 1,
      "name": "Wood_Goldenwood_Stairs",
      "rotation": 9
    },
    {
      "x": -7,
      "y": 9,
      "z": 1,
      "name": "Wood_Hardwood_Fence",
      "rotation": 3
    },
    {
      "x": -7,
      "y": 12,
      "z": 1,
      "name": "Wood_Tropicalwood_Roof_Hollow",
      "rotation": 3
    },
    {
      "x": -7,
      "y": 0,
      "z": 2,
      "name": "Furniture_Crude_Platform",
      "rotation": 1
    },
    {
      "x": -7,
      "y": 1,
      "z": 2,
      "name": "*Wood_Softwood_Fence_State_Definitions_Corner",
      "rotation": 2
    },
    {
      "x": -7,
      "y": 2,
      "z": 2,
      "name": "*Wood_Softwood_Fence_State_Definitions_Corner",
      "rotation": 2
    },
    {
      "x": -7,
      "y": 3,
      "z": 2,
      "name": "*Wood_Softwood_Fence_State_Definitions_Corner",
      "rotation": 2
    },
    {
      "x": -7,
      "y": 4,
      "z": 2,
      "name": "*Wood_Goldenwood_Stairs_State_Definitions_Corner_Right",
      "rotation": 9
    },
    {
      "x": -7,
      "y": 5,
      "z": 2,
      "name": "*Wood_Softwood_Fence_State_Definitions_Corner",
      "rotation": 2
    },
    {
      "x": -7,
      "y": 6,
      "z": 2,
      "name": "*Wood_Softwood_Fence_State_Definitions_Corner",
      "rotation": 2
    },
    {
      "x": -7,
      "y": 7,
      "z": 2,
      "name": "*Wood_Softwood_Fence_State_Definitions_Corner",
      "rotation": 2
    },
    {
      "x": -7,
      "y": 8,
      "z": 2,
      "name": "*Wood_Goldenwood_Stairs_State_Definitions_Corner_Left",
      "rotation": 10
    },
    {
      "x": -7,
      "y": 9,
      "z": 2,
      "name": "Wood_Hardwood_Fence",
      "rotation": 3
    },
    {
      "x": -7,
      "y": 12,
      "z": 2,
      "name": "Wood_Tropicalwood_Roof_Hollow",
      "rotation": 3
    },
    {
      "x": -7,
      "y": 4,
      "z": 3,
      "name": "Furniture_Crude_Platform",
      "rotation": 1
    },
    {
      "x": -7,
      "y": 8,
      "z": 3,
      "name": "Wood_Goldenwood_Planks_Half",
      "rotation": 8
    },
    {
      "x": -7,
      "y": 9,
      "z": 3,
      "name": "*Wood_Hardwood_Fence_State_Definitions_Corner",
      "rotation": 2
    },
    {
      "x": -7,
      "y": 10,
      "z": 3,
      "name": "Wood_Hardwood_Beam"
    },
    {
      "x": -7,
      "y": 11,
      "z": 3,
      "name": "Wood_Hardwood_Beam"
    },
    {
      "x": -7,
      "y": 12,
      "z": 3,
      "name": "*Wood_Tropicalwood_Roof_State_Definitions_Corner_Right"
    },
    {
      "x": -7,
      "y": 4,
      "z": 4,
      "name": "Furniture_Crude_Platform",
      "rotation": 1
    },
    {
      "x": -7,
      "y": 8,
      "z": 4,
      "name": "Wood_Goldenwood_Planks_Half",
      "rotation": 8
    },
    {
      "x": -7,
      "y": 9,
      "z": 4,
      "name": "Wood_Tropicalwood_Roof_Flat",
      "rotation": 3
    },
    {
      "x": -7,
      "y": 4,
      "z": 5,
      "name": "Furniture_Crude_Platform",
      "rotation": 1
    },
    {
      "x": -7,
      "y": 5,
      "z": 5,
      "name": "*Wood_Hardwood_Fence_State_Definitions_Corner"
    },
    {
      "x": -7,
      "y": 8,
      "z": 5,
      "name": "*Wood_Tropicalwood_Roof_Hollow_State_Definitions_Inverted_Corner_Right"
    },
    {
      "x": -7,
      "y": 4,
      "z": 6,
      "name": "Furniture_Crude_Platform"
    },
    {
      "x": -7,
      "y": 5,
      "z": 6,
      "name": "*Wood_Hardwood_Fence_State_Definitions_Corner",
      "rotation": 2
    },
    {
      "x": -7,
      "y": 8,
      "z": 6,
      "name": "*Wood_Tropicalwood_Roof_Hollow_State_Definitions_Corner_Left",
      "rotation": 3
    },
    {
      "x": -6,
      "y": 4,
      "z": -7,
      "name": "Furniture_Crude_Platform",
      "rotation": 1
    },
    {
      "x": -6,
      "y": 5,
      "z": -7,
      "name": "*Wood_Hardwood_Fence_State_Definitions_Corner",
      "rotation": 1
    },
    {
      "x": -6,
      "y": 8,
      "z": -7,
      "name": "*Wood_Tropicalwood_Roof_Hollow_State_Definitions_Corner_Left",
      "rotation": 2
    },
    {
      "x": -6,
      "y": 4,
      "z": -6,
      "name": "Furniture_Crude_Platform"
    },
    {
      "x": -6,
      "y": 5,
      "z": -6,
      "name": "*Wood_Hardwood_Fence_State_Definitions_Corner",
      "rotation": 3
    },
    {
      "x": -6,
      "y": 8,
      "z": -6,
      "name": "*Wood_Tropicalwood_Roof_Hollow_State_Definitions_Inverted_Corner_Right",
      "rotation": 3
    },
    {
      "x": -6,
      "y": 4,
      "z": -5,
      "name": "Furniture_Crude_Platform"
    },
    {
      "x": -6,
      "y": 8,
      "z": -5,
      "name": "Wood_Goldenwood_Planks_Half",
      "rotation": 8
    },
    {
      "x": -6,
      "y": 9,
      "z": -5,
      "name": "Wood_Tropicalwood_Roof_Flat",
      "rotation": 3
    },
    {
      "x": -6,
      "y": 0,
      "z": -4,
      "name": "Furniture_Crude_Platform",
      "rotation": 1
    },
    {
      "x": -6,
      "y": 1,
      "z": -4,
      "name": "*Wood_Softwood_Fence_State_Definitions_Corner",
      "rotation": 1
    },
    {
      "x": -6,
      "y": 2,
      "z": -4,
      "name": "*Wood_Softwood_Fence_State_Definitions_Corner",
      "rotation": 1
    },
    {
      "x": -6,
      "y": 3,
      "z": -4,
      "name": "*Wood_Softwood_Fence_State_Definitions_Corner",
      "rotation": 1
    },
    {
      "x": -6,
      "y": 4,
      "z": -4,
      "name": "*Wood_Goldenwood_Stairs_State_Definitions_Corner_Right",
      "rotation": 8
    },
    {
      "x": -6,
      "y": 5,
      "z": -4,
      "name": "*Wood_Softwood_Fence_State_Definitions_Corner",
      "rotation": 1
    },
    {
      "x": -6,
      "y": 6,
      "z": -4,
      "name": "*Wood_Softwood_Fence_State_Definitions_Corner",
      "rotation": 1
    },
    {
      "x": -6,
      "y": 7,
      "z": -4,
      "name": "*Wood_Softwood_Fence_State_Definitions_Corner",
      "rotation": 1
    },
    {
      "x": -6,
      "y": 8,
      "z": -4,
      "name": "*Wood_Goldenwood_Stairs_State_Definitions_Corner_Left",
      "rotation": 9
    },
    {
      "x": -6,
      "y": 9,
      "z": -4,
      "name": "*Wood_Hardwood_Fence_State_Definitions_Corner",
      "rotation": 1
    },
    {
      "x": -6,
      "y": 12,
      "z": -4,
      "name": "*Wood_Tropicalwood_Roof_Hollow_State_Definitions_Corner_Left",
      "rotation": 2
    },
    {
      "x": -6,
      "y": 0,
      "z": -3,
      "name": "Furniture_Crude_Platform",
      "rotation": 1
    },
    {
      "x": -6,
      "y": 1,
      "z": -3,
      "name": "Wood_Softwood_Fence",
      "rotation": 3
    },
    {
      "x": -6,
      "y": 2,
      "z": -3,
      "name": "Wood_Goldenwood_Fence",
      "rotation": 3
    },
    {
      "x": -6,
      "y": 3,
      "z": -3,
      "name": "Wood_Softwood_Fence",
      "rotation": 3
    },
    {
      "x": -6,
      "y": 4,
      "z": -3,
      "name": "Wood_Goldenwood_Stairs",
      "rotation": 9
    },
    {
      "x": -6,
      "y": 5,
      "z": -3,
      "name": "Wood_Softwood_Fence",
      "rotation": 3
    },
    {
      "x": -6,
      "y": 6,
      "z": -3,
      "name": "Wood_Softwood_Fence",
      "rotation": 3
    },
    {
      "x": -6,
      "y": 7,
      "z": -3,
      "name": "Wood_Softwood_Fence",
      "rotation": 3
    },
    {
      "x": -6,
      "y": 8,
      "z": -3,
      "name": "Wood_Goldenwood_Stairs",
      "rotation": 9
    },
    {
      "x": -6,
      "y": 9,
      "z": -3,
      "name": "*Wood_Hardwood_Fence_State_Definitions_Corner",
      "rotation": 3
    },
    {
      "x": -6,
      "y": 12,
      "z": -3,
      "name": "*Wood_Tropicalwood_Roof_Hollow_State_Definitions_Inverted_Corner_Right",
      "rotation": 3
    },
    {
      "x": -6,
      "y": 0,
      "z": -2,
      "name": "Furniture_Crude_Platform",
      "rotation": 1
    },
    {
      "x": -6,
      "y": 1,
      "z": -2,
      "name": "*Wood_Softwood_Fence_State_Definitions_Corner",
      "rotation": 3
    },
    {
      "x": -6,
      "y": 2,
      "z": -2,
      "name": "*Wood_Softwood_Fence_State_Definitions_Corner",
      "rotation": 3
    },
    {
      "x": -6,
      "y": 3,
      "z": -2,
      "name": "*Wood_Softwood_Fence_State_Definitions_Corner",
      "rotation": 3
    },
    {
      "x": -6,
      "y": 4,
      "z": -2,
      "name": "*Wood_Goldenwood_Stairs_State_Definitions_Inverted_Corner_Left",
      "rotation": 9
    },
    {
      "x": -6,
      "y": 5,
      "z": -2,
      "name": "*Wood_Softwood_Fence_State_Definitions_Corner",
      "rotation": 3
    },
    {
      "x": -6,
      "y": 6,
      "z": -2,
      "name": "*Wood_Softwood_Fence_State_Definitions_Corner",
      "rotation": 3
    },
    {
      "x": -6,
      "y": 7,
      "z": -2,
      "name": "*Wood_Softwood_Fence_State_Definitions_Corner",
      "rotation": 3
    },
    {
      "x": -6,
      "y": 8,
      "z": -2,
      "name": "*Wood_Goldenwood_Stairs_State_Definitions_Inverted_Corner_Right",
      "rotation": 8
    },
    {
      "x": -6,
      "y": 13,
      "z": -2,
      "name": "Wood_Tropicalwood_Roof_Flat",
      "rotation": 1
    },
    {
      "x": -6,
      "y": 0,
      "z": -1,
      "name": "Wood_Goldenwood_Planks_Half",
      "rotation": 8
    },
    {
      "x": -6,
      "y": 4,
      "z": -1,
      "name": "Wood_Goldenwood_Planks_Half",
      "rotation": 8
    },
    {
      "x": -6,
      "y": 8,
      "z": -1,
      "name": "Wood_Goldenwood_Planks_Half",
      "rotation": 8
    },
    {
      "x": -6,
      "y": 13,
      "z": -1,
      "name": "Wood_Tropicalwood_Roof_Flat",
      "rotation": 1
    },
    {
      "x": -6,
      "y": 0,
      "z": 0,
      "name": "Wood_Goldenwood_Planks_Half",
      "rotation": 8
    },
    {
      "x": -6,
      "y": 4,
      "z": 0,
      "name": "Wood_Goldenwood_Planks_Half",
      "rotation": 8
    },
    {
      "x": -6,
      "y": 8,
      "z": 0,
      "name": "Wood_Goldenwood_Planks_Half",
      "rotation": 8
    },
    {
      "x": -6,
      "y": 13,
      "z": 0,
      "name": "Wood_Tropicalwood_Roof_Flat",
      "rotation": 1
    },
    {
      "x": -6,
      "y": 0,
      "z": 1,
      "name": "Wood_Goldenwood_Planks_Half",
      "rotation": 8
    },
    {
      "x": -6,
      "y": 4,
      "z": 1,
      "name": "Wood_Goldenwood_Planks_Half",
      "rotation": 8
    },
    {
      "x": -6,
      "y": 8,
      "z": 1,
      "name": "Wood_Goldenwood_Planks_Half",
      "rotation": 8
    },
    {
      "x": -6,
      "y": 13,
      "z": 1,
      "name": "Wood_Tropicalwood_Roof_Flat",
      "rotation": 3
    },
    {
      "x": -6,
      "y": 0,
      "z": 2,
      "name": "Furniture_Crude_Platform",
      "rotation": 1
    },
    {
      "x": -6,
      "y": 1,
      "z": 2,
      "name": "*Wood_Softwood_Fence_State_Definitions_Corner"
    },
    {
      "x": -6,
      "y": 2,
      "z": 2,
      "name": "*Wood_Softwood_Fence_State_Definitions_Corner"
    },
    {
      "x": -6,
      "y": 3,
      "z": 2,
      "name": "*Wood_Softwood_Fence_State_Definitions_Corner"
    },
    {
      "x": -6,
      "y": 4,
      "z": 2,
      "name": "*Wood_Goldenwood_Stairs_State_Definitions_Inverted_Corner_Left",
      "rotation": 10
    },
    {
      "x": -6,
      "y": 5,
      "z": 2,
      "name": "*Wood_Softwood_Fence_State_Definitions_Corner"
    },
    {
      "x": -6,
      "y": 6,
      "z": 2,
      "name": "*Wood_Softwood_Fence_State_Definitions_Corner"
    },
    {
      "x": -6,
      "y": 7,
      "z": 2,
      "name": "*Wood_Softwood_Fence_State_Definitions_Corner"
    },
    {
      "x": -6,
      "y": 8,
      "z": 2,
      "name": "*Wood_Goldenwood_Stairs_State_Definitions_Inverted_Corner_Right",
      "rotation": 9
    },
    {
      "x": -6,
      "y": 13,
      "z": 2,
      "name": "Wood_Tropicalwood_Roof_Flat",
      "rotation": 3
    },
    {
      "x": -6,
      "y": 0,
      "z": 3,
      "name": "Furniture_Crude_Platform",
      "rotation": 1
    },
    {
      "x": -6,
      "y": 1,
      "z": 3,
      "name": "Wood_Softwood_Fence",
      "rotation": 3
    },
    {
      "x": -6,
      "y": 2,
      "z": 3,
      "name": "Wood_Goldenwood_Fence",
      "rotation": 3
    },
    {
      "x": -6,
      "y": 3,
      "z": 3,
      "name": "Wood_Softwood_Fence",
      "rotation": 3
    },
    {
      "x": -6,
      "y": 4,
      "z": 3,
      "name": "Wood_Goldenwood_Stairs",
      "rotation": 9
    },
    {
      "x": -6,
      "y": 5,
      "z": 3,
      "name": "Wood_Softwood_Fence",
      "rotation": 3
    },
    {
      "x": -6,
      "y": 6,
      "z": 3,
      "name": "Wood_Softwood_Fence",
      "rotation": 3
    },
    {
      "x": -6,
      "y": 7,
      "z": 3,
      "name": "Wood_Softwood_Fence",
      "rotation": 3
    },
    {
      "x": -6,
      "y": 8,
      "z": 3,
      "name": "Wood_Goldenwood_Stairs",
      "rotation": 9
    },
    {
      "x": -6,
      "y": 9,
      "z": 3,
      "name": "*Wood_Hardwood_Fence_State_Definitions_Corner"
    },
    {
      "x": -6,
      "y": 12,
      "z": 3,
      "name": "*Wood_Tropicalwood_Roof_Hollow_State_Definitions_Inverted_Corner_Right"
    },
    {
      "x": -6,
      "y": 0,
      "z": 4,
      "name": "Furniture_Crude_Platform",
      "rotation": 1
    },
    {
      "x": -6,
      "y": 1,
      "z": 4,
      "name": "*Wood_Softwood_Fence_State_Definitions_Corner",
      "rotation": 2
    },
    {
      "x": -6,
      "y": 2,
      "z": 4,
      "name": "*Wood_Softwood_Fence_State_Definitions_Corner",
      "rotation": 2
    },
    {
      "x": -6,
      "y": 3,
      "z": 4,
      "name": "*Wood_Softwood_Fence_State_Definitions_Corner",
      "rotation": 2
    },
    {
      "x": -6,
      "y": 4,
      "z": 4,
      "name": "*Wood_Goldenwood_Stairs_State_Definitions_Corner_Right",
      "rotation": 9
    },
    {
      "x": -6,
      "y": 5,
      "z": 4,
      "name": "*Wood_Softwood_Fence_State_Definitions_Corner",
      "rotation": 2
    },
    {
      "x": -6,
      "y": 6,
      "z": 4,
      "name": "*Wood_Softwood_Fence_State_Definitions_Corner",
      "rotation": 2
    },
    {
      "x": -6,
      "y": 7,
      "z": 4,
      "name": "*Wood_Softwood_Fence_State_Definitions_Corner",
      "rotation": 2
    },
    {
      "x": -6,
      "y": 8,
      "z": 4,
      "name": "*Wood_Goldenwood_Stairs_State_Definitions_Corner_Left",
      "rotation": 10
    },
    {
      "x": -6,
      "y": 9,
      "z": 4,
      "name": "*Wood_Hardwood_Fence_State_Definitions_Corner",
      "rotation": 2
    },
    {
      "x": -6,
      "y": 12,
      "z": 4,
      "name": "*Wood_Tropicalwood_Roof_Hollow_State_Definitions_Corner_Left",
      "rotation": 3
    },
    {
      "x": -6,
      "y": 4,
      "z": 5,
      "name": "Furniture_Crude_Platform"
    },
    {
      "x": -6,
      "y": 8,
      "z": 5,
      "name": "Wood_Goldenwood_Planks_Half",
      "rotation": 8
    },
    {
      "x": -6,
      "y": 9,
      "z": 5,
      "name": "Wood_Tropicalwood_Roof_Flat",
      "rotation": 3
    },
    {
      "x": -6,
      "y": 4,
      "z": 6,
      "name": "Furniture_Crude_Platform"
    },
    {
      "x": -6,
      "y": 5,
      "z": 6,
      "name": "*Wood_Hardwood_Fence_State_Definitions_Corner"
    },
    {
      "x": -6,
      "y": 8,
      "z": 6,
      "name": "*Wood_Tropicalwood_Roof_Hollow_State_Definitions_Inverted_Corner_Right"
    },
    {
      "x": -6,
      "y": 4,
      "z": 7,
      "name": "Furniture_Crude_Platform"
    },
    {
      "x": -6,
      "y": 5,
      "z": 7,
      "name": "*Wood_Hardwood_Fence_State_Definitions_Corner",
      "rotation": 2
    },
    {
      "x": -6,
      "y": 8,
      "z": 7,
      "name": "*Wood_Tropicalwood_Roof_Hollow_State_Definitions_Corner_Left",
      "rotation": 3
    },
    {
      "x": -5,
      "y": 4,
      "z": -8,
      "name": "Furniture_Crude_Platform",
      "rotation": 1
    },
    {
      "x": -5,
      "y": 5,
      "z": -8,
      "name": "*Wood_Hardwood_Fence_State_Definitions_Corner",
      "rotation": 1
    },
    {
      "x": -5,
      "y": 6,
      "z": -8,
      "name": "Wood_Hardwood_Beam"
    },
    {
      "x": -5,
      "y": 7,
      "z": -8,
      "name": "Wood_Hardwood_Beam"
    },
    {
      "x": -5,
      "y": 8,
      "z": -8,
      "name": "*Wood_Tropicalwood_Roof_State_Definitions_Corner_Left",
      "rotation": 2
    },
    {
      "x": -5,
      "y": 4,
      "z": -7,
      "name": "Furniture_Crude_Platform"
    },
    {
      "x": -5,
      "y": 5,
      "z": -7,
      "name": "*Wood_Hardwood_Fence_State_Definitions_Corner",
      "rotation": 3
    },
    {
      "x": -5,
      "y": 8,
      "z": -7,
      "name": "*Wood_Tropicalwood_Roof_Hollow_State_Definitions_Inverted_Corner_Right",
      "rotation": 3
    },
    {
      "x": -5,
      "y": 4,
      "z": -6,
      "name": "Furniture_Crude_Platform"
    },
    {
      "x": -5,
      "y": 8,
      "z": -6,
      "name": "Wood_Goldenwood_Planks_Half",
      "rotation": 8
    },
    {
      "x": -5,
      "y": 9,
      "z": -6,
      "name": "Wood_Tropicalwood_Roof_Flat",
      "rotation": 2
    },
    {
      "x": -5,
      "y": 0,
      "z": -5,
      "name": "Furniture_Crude_Platform"
    },
    {
      "x": -5,
      "y": 1,
      "z": -5,
      "name": "*Wood_Softwood_Fence_State_Definitions_Corner",
      "rotation": 1
    },
    {
      "x": -5,
      "y": 2,
      "z": -5,
      "name": "*Wood_Softwood_Fence_State_Definitions_Corner",
      "rotation": 1
    },
    {
      "x": -5,
      "y": 3,
      "z": -5,
      "name": "*Wood_Softwood_Fence_State_Definitions_Corner",
      "rotation": 1
    },
    {
      "x": -5,
      "y": 4,
      "z": -5,
      "name": "*Wood_Goldenwood_Stairs_State_Definitions_Corner_Right",
      "rotation": 8
    },
    {
      "x": -5,
      "y": 5,
      "z": -5,
      "name": "*Wood_Softwood_Fence_State_Definitions_Corner",
      "rotation": 1
    },
    {
      "x": -5,
      "y": 6,
      "z": -5,
      "name": "*Wood_Softwood_Fence_State_Definitions_Corner",
      "rotation": 1
    },
    {
      "x": -5,
      "y": 7,
      "z": -5,
      "name": "*Wood_Softwood_Fence_State_Definitions_Corner",
      "rotation": 1
    },
    {
      "x": -5,
      "y": 8,
      "z": -5,
      "name": "Wood_Goldenwood_Stairs",
      "rotation": 9
    },
    {
      "x": -5,
      "y": 9,
      "z": -5,
      "name": "*Wood_Hardwood_Fence_State_Definitions_Corner",
      "rotation": 1
    },
    {
      "x": -5,
      "y": 10,
      "z": -5,
      "name": "Wood_Hardwood_Beam"
    },
    {
      "x": -5,
      "y": 11,
      "z": -5,
      "name": "Wood_Hardwood_Beam"
    },
    {
      "x": -5,
      "y": 12,
      "z": -5,
      "name": "*Wood_Tropicalwood_Roof_State_Definitions_Corner_Left",
      "rotation": 2
    },
    {
      "x": -5,
      "y": 0,
      "z": -4,
      "name": "Furniture_Crude_Platform",
      "rotation": 1
    },
    {
      "x": -5,
      "y": 1,
      "z": -4,
      "name": "*Wood_Softwood_Fence_State_Definitions_Corner",
      "rotation": 3
    },
    {
      "x": -5,
      "y": 2,
      "z": -4,
      "name": "*Wood_Softwood_Fence_State_Definitions_Corner",
      "rotation": 3
    },
    {
      "x": -5,
      "y": 3,
      "z": -4,
      "name": "*Wood_Softwood_Fence_State_Definitions_Corner",
      "rotation": 3
    },
    {
      "x": -5,
      "y": 4,
      "z": -4,
      "name": "*Wood_Goldenwood_Stairs_State_Definitions_Inverted_Corner_Left",
      "rotation": 9
    },
    {
      "x": -5,
      "y": 5,
      "z": -4,
      "name": "*Wood_Softwood_Fence_State_Definitions_Corner",
      "rotation": 3
    },
    {
      "x": -5,
      "y": 6,
      "z": -4,
      "name": "*Wood_Softwood_Fence_State_Definitions_Corner",
      "rotation": 3
    },
    {
      "x": -5,
      "y": 7,
      "z": -4,
      "name": "*Wood_Softwood_Fence_State_Definitions_Corner",
      "rotation": 3
    },
    {
      "x": -5,
      "y": 8,
      "z": -4,
      "name": "*Wood_Goldenwood_Stairs_State_Definitions_Inverted_Corner_Right",
      "rotation": 8
    },
    {
      "x": -5,
      "y": 9,
      "z": -4,
      "name": "*Wood_Hardwood_Fence_State_Definitions_Corner",
      "rotation": 3
    },
    {
      "x": -5,
      "y": 12,
      "z": -4,
      "name": "*Wood_Tropicalwood_Roof_Hollow_State_Definitions_Inverted_Corner_Right",
      "rotation": 3
    },
    {
      "x": -5,
      "y": 0,
      "z": -3,
      "name": "Wood_Goldenwood_Planks_Half",
      "rotation": 8
    },
    {
      "x": -5,
      "y": 4,
      "z": -3,
      "name": "Wood_Goldenwood_Planks_Half",
      "rotation": 8
    },
    {
      "x": -5,
      "y": 8,
      "z": -3,
      "name": "Wood_Goldenwood_Planks_Half",
      "rotation": 8
    },
    {
      "x": -5,
      "y": 13,
      "z": -3,
      "name": "Wood_Tropicalwood_Roof_Flat",
      "rotation": 1
    },
    {
      "x": -5,
      "y": 0,
      "z": -2,
      "name": "Wood_Goldenwood_Planks_Half",
      "rotation": 8
    },
    {
      "x": -5,
      "y": 1,
      "z": -2,
      "name": "Furniture_Village_Chair"
    },
    {
      "x": -5,
      "y": 2,
      "z": -2,
      "name": "Furniture_Village_Chair",
      "filler": 1024
    },
    {
      "x": -5,
      "y": 4,
      "z": -2,
      "name": "Wood_Goldenwood_Planks_Half",
      "rotation": 8
    },
    {
      "x": -5,
      "y": 8,
      "z": -2,
      "name": "Wood_Goldenwood_Planks_Half",
      "rotation": 8
    },
    {
      "x": -5,
      "y": 13,
      "z": -2,
      "name": "Wood_Tropicalwood_Roof_Flat",
      "rotation": 1
    },
    {
      "x": -5,
      "y": 0,
      "z": -1,
      "name": "Wood_Goldenwood_Planks_Half",
      "rotation": 8
    },
    {
      "x": -5,
      "y": 4,
      "z": -1,
      "name": "Wood_Goldenwood_Planks_Half",
      "rotation": 8
    },
    {
      "x": -5,
      "y": 8,
      "z": -1,
      "name": "Wood_Goldenwood_Planks_Half",
      "rotation": 8
    },
    {
      "x": -5,
      "y": 13,
      "z": -1,
      "name": "Wood_Tropicalwood_Roof_Flat",
      "rotation": 1
    },
    {
      "x": -5,
      "y": 0,
      "z": 0,
      "name": "Wood_Goldenwood_Planks_Half",
      "rotation": 8
    },
    {
      "x": -5,
      "y": 4,
      "z": 0,
      "name": "Wood_Goldenwood_Planks_Half",
      "rotation": 8
    },
    {
      "x": -5,
      "y": 8,
      "z": 0,
      "name": "Wood_Goldenwood_Planks_Half",
      "rotation": 8
    },
    {
      "x": -5,
      "y": 13,
      "z": 0,
      "name": "Wood_Tropicalwood_Roof_Flat",
      "rotation": 1
    },
    {
      "x": -5,
      "y": 0,
      "z": 1,
      "name": "Wood_Goldenwood_Planks_Half",
      "rotation": 8
    },
    {
      "x": -5,
      "y": 1,
      "z": 1,
      "name": "Furniture_Village_Chair",
      "rotation": 2
    },
    {
      "x": -5,
      "y": 2,
      "z": 1,
      "name": "Furniture_Village_Chair",
      "filler": 1024,
      "rotation": 2
    },
    {
      "x": -5,
      "y": 4,
      "z": 1,
      "name": "Wood_Goldenwood_Planks_Half",
      "rotation": 8
    },
    {
      "x": -5,
      "y": 8,
      "z": 1,
      "name": "Wood_Goldenwood_Planks_Half",
      "rotation": 8
    },
    {
      "x": -5,
      "y": 13,
      "z": 1,
      "name": "Wood_Tropicalwood_Roof_Flat",
      "rotation": 1
    },
    {
      "x": -5,
      "y": 0,
      "z": 2,
      "name": "Wood_Goldenwood_Planks_Half",
      "rotation": 8
    },
    {
      "x": -5,
      "y": 4,
      "z": 2,
      "name": "Wood_Goldenwood_Planks_Half",
      "rotation": 8
    },
    {
      "x": -5,
      "y": 8,
      "z": 2,
      "name": "Wood_Goldenwood_Planks_Half",
      "rotation": 8
    },
    {
      "x": -5,
      "y": 13,
      "z": 2,
      "name": "Wood_Tropicalwood_Roof_Flat",
      "rotation": 1
    },
    {
      "x": -5,
      "y": 0,
      "z": 3,
      "name": "Wood_Goldenwood_Planks_Half",
      "rotation": 8
    },
    {
      "x": -5,
      "y": 4,
      "z": 3,
      "name": "Wood_Goldenwood_Planks_Half",
      "rotation": 8
    },
    {
      "x": -5,
      "y": 8,
      "z": 3,
      "name": "Wood_Goldenwood_Planks_Half",
      "rotation": 8
    },
    {
      "x": -5,
      "y": 13,
      "z": 3,
      "name": "Wood_Tropicalwood_Roof_Flat",
      "rotation": 1
    },
    {
      "x": -5,
      "y": 0,
      "z": 4,
      "name": "Furniture_Crude_Platform",
      "rotation": 1
    },
    {
      "x": -5,
      "y": 1,
      "z": 4,
      "name": "*Wood_Softwood_Fence_State_Definitions_Corner"
    },
    {
      "x": -5,
      "y": 2,
      "z": 4,
      "name": "*Wood_Softwood_Fence_State_Definitions_Corner"
    },
    {
      "x": -5,
      "y": 3,
      "z": 4,
      "name": "*Wood_Softwood_Fence_State_Definitions_Corner"
    },
    {
      "x": -5,
      "y": 4,
      "z": 4,
      "name": "*Wood_Goldenwood_Stairs_State_Definitions_Inverted_Corner_Left",
      "rotation": 10
    },
    {
      "x": -5,
      "y": 5,
      "z": 4,
      "name": "*Wood_Softwood_Fence_State_Definitions_Corner"
    },
    {
      "x": -5,
      "y": 6,
      "z": 4,
      "name": "*Wood_Softwood_Fence_State_Definitions_Corner"
    },
    {
      "x": -5,
      "y": 7,
      "z": 4,
      "name": "*Wood_Softwood_Fence_State_Definitions_Corner"
    },
    {
      "x": -5,
      "y": 8,
      "z": 4,
      "name": "*Wood_Goldenwood_Stairs_State_Definitions_Inverted_Corner_Right",
      "rotation": 9
    },
    {
      "x": -5,
      "y": 9,
      "z": 4,
      "name": "*Wood_Hardwood_Fence_State_Definitions_Corner"
    },
    {
      "x": -5,
      "y": 12,
      "z": 4,
      "name": "*Wood_Tropicalwood_Roof_Hollow_State_Definitions_Inverted_Corner_Right"
    },
    {
      "x": -5,
      "y": 0,
      "z": 5,
      "name": "Furniture_Crude_Platform",
      "rotation": 1
    },
    {
      "x": -5,
      "y": 1,
      "z": 5,
      "name": "*Wood_Softwood_Fence_State_Definitions_Corner",
      "rotation": 2
    },
    {
      "x": -5,
      "y": 2,
      "z": 5,
      "name": "*Wood_Softwood_Fence_State_Definitions_Corner",
      "rotation": 2
    },
    {
      "x": -5,
      "y": 3,
      "z": 5,
      "name": "*Wood_Softwood_Fence_State_Definitions_Corner",
      "rotation": 2
    },
    {
      "x": -5,
      "y": 4,
      "z": 5,
      "name": "*Wood_Goldenwood_Stairs_State_Definitions_Corner_Right",
      "rotation": 9
    },
    {
      "x": -5,
      "y": 5,
      "z": 5,
      "name": "*Wood_Softwood_Fence_State_Definitions_Corner",
      "rotation": 2
    },
    {
      "x": -5,
      "y": 6,
      "z": 5,
      "name": "*Wood_Softwood_Fence_State_Definitions_Corner",
      "rotation": 2
    },
    {
      "x": -5,
      "y": 7,
      "z": 5,
      "name": "*Wood_Softwood_Fence_State_Definitions_Corner",
      "rotation": 2
    },
    {
      "x": -5,
      "y": 8,
      "z": 5,
      "name": "*Wood_Goldenwood_Stairs_State_Definitions_Corner_Left",
      "rotation": 10
    },
    {
      "x": -5,
      "y": 9,
      "z": 5,
      "name": "*Wood_Hardwood_Fence_State_Definitions_Corner",
      "rotation": 2
    },
    {
      "x": -5,
      "y": 10,
      "z": 5,
      "name": "Wood_Hardwood_Beam"
    },
    {
      "x": -5,
      "y": 11,
      "z": 5,
      "name": "Wood_Hardwood_Beam"
    },
    {
      "x": -5,
      "y": 12,
      "z": 5,
      "name": "*Wood_Tropicalwood_Roof_State_Definitions_Corner_Left",
      "rotation": 3
    },
    {
      "x": -5,
      "y": 4,
      "z": 6,
      "name": "Furniture_Crude_Platform"
    },
    {
      "x": -5,
      "y": 8,
      "z": 6,
      "name": "Wood_Goldenwood_Planks_Half",
      "rotation": 8
    },
    {
      "x": -5,
      "y": 9,
      "z": 6,
      "name": "Wood_Tropicalwood_Roof_Flat"
    },
    {
      "x": -5,
      "y": 4,
      "z": 7,
      "name": "Furniture_Crude_Platform"
    },
    {
      "x": -5,
      "y": 5,
      "z": 7,
      "name": "*Wood_Hardwood_Fence_State_Definitions_Corner"
    },
    {
      "x": -5,
      "y": 8,
      "z": 7,
      "name": "*Wood_Tropicalwood_Roof_Hollow_State_Definitions_Inverted_Corner_Right"
    },
    {
      "x": -5,
      "y": 4,
      "z": 8,
      "name": "Furniture_Crude_Platform",
      "rotation": 1
    },
    {
      "x": -5,
      "y": 5,
      "z": 8,
      "name": "*Wood_Hardwood_Fence_State_Definitions_Corner",
      "rotation": 2
    },
    {
      "x": -5,
      "y": 6,
      "z": 8,
      "name": "Wood_Hardwood_Beam"
    },
    {
      "x": -5,
      "y": 7,
      "z": 8,
      "name": "Wood_Hardwood_Beam"
    },
    {
      "x": -5,
      "y": 8,
      "z": 8,
      "name": "*Wood_Tropicalwood_Roof_State_Definitions_Corner_Left",
      "rotation": 3
    },
    {
      "x": -4,
      "y": 8,
      "z": -9,
      "name": "*Wood_Tropicalwood_Roof_Hollow_State_Definitions_Corner_Right",
      "rotation": 3
    },
    {
      "x": -4,
      "y": 4,
      "z": -8,
      "name": "Furniture_Crude_Platform",
      "rotation": 1
    },
    {
      "x": -4,
      "y": 5,
      "z": -8,
      "name": "Wood_Hardwood_Fence",
      "rotation": 2
    },
    {
      "x": -4,
      "y": 8,
      "z": -8,
      "name": "*Wood_Tropicalwood_Roof_Hollow_State_Definitions_Inverted_Corner_Right",
      "rotation": 3
    },
    {
      "x": -4,
      "y": 4,
      "z": -7,
      "name": "Furniture_Crude_Platform"
    },
    {
      "x": -4,
      "y": 8,
      "z": -7,
      "name": "Wood_Goldenwood_Planks_Half",
      "rotation": 8
    },
    {
      "x": -4,
      "y": 9,
      "z": -7,
      "name": "Wood_Tropicalwood_Roof_Flat",
      "rotation": 2
    },
    {
      "x": -4,
      "y": 0,
      "z": -6,
      "name": "Furniture_Crude_Platform"
    },
    {
      "x": -4,
      "y": 1,
      "z": -6,
      "name": "*Wood_Softwood_Fence_State_Definitions_Corner",
      "rotation": 1
    },
    {
      "x": -4,
      "y": 2,
      "z": -6,
      "name": "*Wood_Softwood_Fence_State_Definitions_Corner",
      "rotation": 1
    },
    {
      "x": -4,
      "y": 3,
      "z": -6,
      "name": "*Wood_Softwood_Fence_State_Definitions_Corner",
      "rotation": 1
    },
    {
      "x": -4,
      "y": 4,
      "z": -6,
      "name": "*Wood_Goldenwood_Stairs_State_Definitions_Corner_Left",
      "rotation": 9
    },
    {
      "x": -4,
      "y": 5,
      "z": -6,
      "name": "*Wood_Softwood_Fence_State_Definitions_Corner",
      "rotation": 1
    },
    {
      "x": -4,
      "y": 6,
      "z": -6,
      "name": "*Wood_Softwood_Fence_State_Definitions_Corner",
      "rotation": 1
    },
    {
      "x": -4,
      "y": 7,
      "z": -6,
      "name": "*Wood_Softwood_Fence_State_Definitions_Corner",
      "rotation": 1
    },
    {
      "x": -4,
      "y": 8,
      "z": -6,
      "name": "*Wood_Goldenwood_Stairs_State_Definitions_Corner_Left",
      "rotation": 9
    },
    {
      "x": -4,
      "y": 9,
      "z": -6,
      "name": "*Wood_Hardwood_Fence_State_Definitions_Corner",
      "rotation": 1
    },
    {
      "x": -4,
      "y": 12,
      "z": -6,
      "name": "*Wood_Tropicalwood_Roof_Hollow_State_Definitions_Corner_Left",
      "rotation": 2
    },
    {
      "x": -4,
      "y": 0,
      "z": -5,
      "name": "Furniture_Crude_Platform",
      "rotation": 1
    },
    {
      "x": -4,
      "y": 1,
      "z": -5,
      "name": "*Wood_Softwood_Fence_State_Definitions_Corner",
      "rotation": 3
    },
    {
      "x": -4,
      "y": 2,
      "z": -5,
      "name": "*Wood_Softwood_Fence_State_Definitions_Corner",
      "rotation": 3
    },
    {
      "x": -4,
      "y": 3,
      "z": -5,
      "name": "*Wood_Softwood_Fence_State_Definitions_Corner",
      "rotation": 3
    },
    {
      "x": -4,
      "y": 4,
      "z": -5,
      "name": "*Wood_Goldenwood_Stairs_State_Definitions_Inverted_Corner_Left",
      "rotation": 9
    },
    {
      "x": -4,
      "y": 5,
      "z": -5,
      "name": "*Wood_Softwood_Fence_State_Definitions_Corner",
      "rotation": 3
    },
    {
      "x": -4,
      "y": 6,
      "z": -5,
      "name": "*Wood_Softwood_Fence_State_Definitions_Corner",
      "rotation": 3
    },
    {
      "x": -4,
      "y": 7,
      "z": -5,
      "name": "*Wood_Softwood_Fence_State_Definitions_Corner",
      "rotation": 3
    },
    {
      "x": -4,
      "y": 8,
      "z": -5,
      "name": "Wood_Goldenwood_Planks_Half",
      "rotation": 8
    },
    {
      "x": -4,
      "y": 9,
      "z": -5,
      "name": "*Wood_Hardwood_Fence_State_Definitions_Corner",
      "rotation": 3
    },
    {
      "x": -4,
      "y": 12,
      "z": -5,
      "name": "*Wood_Tropicalwood_Roof_Hollow_State_Definitions_Inverted_Corner_Right",
      "rotation": 3
    },
    {
      "x": -4,
      "y": 0,
      "z": -4,
      "name": "Wood_Goldenwood_Planks_Half",
      "rotation": 8
    },
    {
      "x": -4,
      "y": 4,
      "z": -4,
      "name": "Wood_Goldenwood_Planks_Half",
      "rotation": 8
    },
    {
      "x": -4,
      "y": 8,
      "z": -4,
      "name": "Wood_Goldenwood_Planks_Half",
      "rotation": 8
    },
    {
      "x": -4,
      "y": 13,
      "z": -4,
      "name": "Wood_Tropicalwood_Roof_Flat"
    },
    {
      "x": -4,
      "y": 0,
      "z": -3,
      "name": "Wood_Goldenwood_Planks_Half",
      "rotation": 8
    },
    {
      "x": -4,
      "y": 4,
      "z": -3,
      "name": "Wood_Goldenwood_Planks_Half",
      "rotation": 8
    },
    {
      "x": -4,
      "y": 8,
      "z": -3,
      "name": "Wood_Goldenwood_Planks_Half",
      "rotation": 8
    },
    {
      "x": -4,
      "y": 9,
      "z": -3,
      "name": "Wood_Hardwood_Fence",
      "rotation": 3
    },
    {
      "x": -4,
      "y": 13,
      "z": -3,
      "name": "Wood_Tropicalwood_Roof_Flat",
      "rotation": 1
    },
    {
      "x": -4,
      "y": 0,
      "z": -2,
      "name": "Wood_Goldenwood_Planks_Half",
      "rotation": 8
    },
    {
      "x": -4,
      "y": 4,
      "z": -2,
      "name": "Wood_Goldenwood_Planks_Half",
      "rotation": 8
    },
    {
      "x": -4,
      "y": 8,
      "z": -2,
      "name": "Wood_Goldenwood_Planks_Half",
      "rotation": 8
    },
    {
      "x": -4,
      "y": 9,
      "z": -2,
      "name": "Wood_Hardwood_Fence",
      "rotation": 3
    },
    {
      "x": -4,
      "y": 13,
      "z": -2,
      "name": "Wood_Tropicalwood_Roof_Flat",
      "rotation": 1
    },
    {
      "x": -4,
      "y": 0,
      "z": -1,
      "name": "Wood_Goldenwood_Planks_Half",
      "rotation": 8
    },
    {
      "x": -4,
      "y": 4,
      "z": -1,
      "name": "Wood_Goldenwood_Planks_Half",
      "rotation": 8
    },
    {
      "x": -4,
      "y": 8,
      "z": -1,
      "name": "Wood_Goldenwood_Planks_Half",
      "rotation": 8
    },
    {
      "x": -4,
      "y": 9,
      "z": -1,
      "name": "Wood_Hardwood_Fence",
      "rotation": 3
    },
    {
      "x": -4,
      "y": 13,
      "z": -1,
      "name": "Wood_Tropicalwood_Roof_Flat",
      "rotation": 1
    },
    {
      "x": -4,
      "y": 0,
      "z": 0,
      "name": "Wood_Goldenwood_Planks_Half",
      "rotation": 8
    },
    {
      "x": -4,
      "y": 4,
      "z": 0,
      "name": "Wood_Goldenwood_Planks_Half",
      "rotation": 8
    },
    {
      "x": -4,
      "y": 8,
      "z": 0,
      "name": "Wood_Goldenwood_Planks_Half",
      "rotation": 8
    },
    {
      "x": -4,
      "y": 9,
      "z": 0,
      "name": "Wood_Hardwood_Fence",
      "rotation": 3
    },
    {
      "x": -4,
      "y": 13,
      "z": 0,
      "name": "Wood_Tropicalwood_Roof_Flat",
      "rotation": 1
    },
    {
      "x": -4,
      "y": 0,
      "z": 1,
      "name": "Wood_Goldenwood_Planks_Half",
      "rotation": 8
    },
    {
      "x": -4,
      "y": 4,
      "z": 1,
      "name": "Wood_Goldenwood_Planks_Half",
      "rotation": 8
    },
    {
      "x": -4,
      "y": 8,
      "z": 1,
      "name": "Wood_Goldenwood_Planks_Half",
      "rotation": 8
    },
    {
      "x": -4,
      "y": 9,
      "z": 1,
      "name": "Wood_Hardwood_Fence",
      "rotation": 3
    },
    {
      "x": -4,
      "y": 13,
      "z": 1,
      "name": "Wood_Tropicalwood_Roof_Flat",
      "rotation": 1
    },
    {
      "x": -4,
      "y": 0,
      "z": 2,
      "name": "Wood_Goldenwood_Planks_Half",
      "rotation": 8
    },
    {
      "x": -4,
      "y": 4,
      "z": 2,
      "name": "Wood_Goldenwood_Planks_Half",
      "rotation": 8
    },
    {
      "x": -4,
      "y": 8,
      "z": 2,
      "name": "Wood_Goldenwood_Planks_Half",
      "rotation": 8
    },
    {
      "x": -4,
      "y": 9,
      "z": 2,
      "name": "*Wood_Hardwood_Fence_State_Definitions_Corner",
      "rotation": 2
    },
    {
      "x": -4,
      "y": 13,
      "z": 2,
      "name": "Wood_Tropicalwood_Roof_Flat",
      "rotation": 1
    },
    {
      "x": -4,
      "y": 0,
      "z": 3,
      "name": "Wood_Goldenwood_Planks_Half",
      "rotation": 8
    },
    {
      "x": -4,
      "y": 4,
      "z": 3,
      "name": "Wood_Goldenwood_Planks_Half",
      "rotation": 8
    },
    {
      "x": -4,
      "y": 8,
      "z": 3,
      "name": "Wood_Goldenwood_Planks_Half",
      "rotation": 8
    },
    {
      "x": -4,
      "y": 13,
      "z": 3,
      "name": "Wood_Tropicalwood_Roof_Flat",
      "rotation": 1
    },
    {
      "x": -4,
      "y": 0,
      "z": 4,
      "name": "Wood_Goldenwood_Planks_Half",
      "rotation": 8
    },
    {
      "x": -4,
      "y": 4,
      "z": 4,
      "name": "Wood_Goldenwood_Planks_Half",
      "rotation": 8
    },
    {
      "x": -4,
      "y": 8,
      "z": 4,
      "name": "Wood_Goldenwood_Planks_Half",
      "rotation": 8
    },
    {
      "x": -4,
      "y": 13,
      "z": 4,
      "name": "Wood_Tropicalwood_Roof_Flat"
    },
    {
      "x": -4,
      "y": 0,
      "z": 5,
      "name": "Furniture_Crude_Platform",
      "rotation": 1
    },
    {
      "x": -4,
      "y": 1,
      "z": 5,
      "name": "*Wood_Softwood_Fence_State_Definitions_Corner"
    },
    {
      "x": -4,
      "y": 2,
      "z": 5,
      "name": "*Wood_Softwood_Fence_State_Definitions_Corner"
    },
    {
      "x": -4,
      "y": 3,
      "z": 5,
      "name": "*Wood_Softwood_Fence_State_Definitions_Corner"
    },
    {
      "x": -4,
      "y": 4,
      "z": 5,
      "name": "*Wood_Goldenwood_Stairs_State_Definitions_Inverted_Corner_Left",
      "rotation": 10
    },
    {
      "x": -4,
      "y": 5,
      "z": 5,
      "name": "*Wood_Softwood_Fence_State_Definitions_Corner"
    },
    {
      "x": -4,
      "y": 6,
      "z": 5,
      "name": "*Wood_Softwood_Fence_State_Definitions_Corner"
    },
    {
      "x": -4,
      "y": 7,
      "z": 5,
      "name": "*Wood_Softwood_Fence_State_Definitions_Corner"
    },
    {
      "x": -4,
      "y": 8,
      "z": 5,
      "name": "*Wood_Goldenwood_Stairs_State_Definitions_Inverted_Corner_Right",
      "rotation": 9
    },
    {
      "x": -4,
      "y": 9,
      "z": 5,
      "name": "*Wood_Hardwood_Fence_State_Definitions_Corner"
    },
    {
      "x": -4,
      "y": 12,
      "z": 5,
      "name": "*Wood_Tropicalwood_Roof_Hollow_State_Definitions_Inverted_Corner_Right"
    },
    {
      "x": -4,
      "y": 0,
      "z": 6,
      "name": "Furniture_Crude_Platform"
    },
    {
      "x": -4,
      "y": 1,
      "z": 6,
      "name": "*Wood_Softwood_Fence_State_Definitions_Corner",
      "rotation": 2
    },
    {
      "x": -4,
      "y": 2,
      "z": 6,
      "name": "*Wood_Softwood_Fence_State_Definitions_Corner",
      "rotation": 2
    },
    {
      "x": -4,
      "y": 3,
      "z": 6,
      "name": "*Wood_Softwood_Fence_State_Definitions_Corner",
      "rotation": 2
    },
    {
      "x": -4,
      "y": 4,
      "z": 6,
      "name": "*Wood_Goldenwood_Stairs_State_Definitions_Corner_Right",
      "rotation": 9
    },
    {
      "x": -4,
      "y": 5,
      "z": 6,
      "name": "*Wood_Softwood_Fence_State_Definitions_Corner",
      "rotation": 2
    },
    {
      "x": -4,
      "y": 6,
      "z": 6,
      "name": "*Wood_Softwood_Fence_State_Definitions_Corner",
      "rotation": 2
    },
    {
      "x": -4,
      "y": 7,
      "z": 6,
      "name": "*Wood_Softwood_Fence_State_Definitions_Corner",
      "rotation": 2
    },
    {
      "x": -4,
      "y": 8,
      "z": 6,
      "name": "*Wood_Goldenwood_Stairs_State_Definitions_Corner_Right",
      "rotation": 9
    },
    {
      "x": -4,
      "y": 9,
      "z": 6,
      "name": "*Wood_Hardwood_Fence_State_Definitions_Corner",
      "rotation": 2
    },
    {
      "x": -4,
      "y": 12,
      "z": 6,
      "name": "*Wood_Tropicalwood_Roof_Hollow_State_Definitions_Corner_Left",
      "rotation": 3
    },
    {
      "x": -4,
      "y": 4,
      "z": 7,
      "name": "Furniture_Crude_Platform"
    },
    {
      "x": -4,
      "y": 8,
      "z": 7,
      "name": "Wood_Goldenwood_Planks_Half",
      "rotation": 8
    },
    {
      "x": -4,
      "y": 9,
      "z": 7,
      "name": "Wood_Tropicalwood_Roof_Flat"
    },
    {
      "x": -4,
      "y": 4,
      "z": 8,
      "name": "Furniture_Crude_Platform",
      "rotation": 1
    },
    {
      "x": -4,
      "y": 5,
      "z": 8,
      "name": "Wood_Hardwood_Fence"
    },
    {
      "x": -4,
      "y": 8,
      "z": 8,
      "name": "Wood_Tropicalwood_Roof_Hollow"
    },
    {
      "x": -3,
      "y": 4,
      "z": -9,
      "name": "Furniture_Crude_Platform",
      "rotation": 1
    },
    {
      "x": -3,
      "y": 5,
      "z": -9,
      "name": "*Wood_Hardwood_Fence_State_Definitions_Corner",
      "rotation": 1
    },
    {
      "x": -3,
      "y": 6,
      "z": -9,
      "name": "Wood_Hardwood_Beam"
    },
    {
      "x": -3,
      "y": 7,
      "z": -9,
      "name": "Wood_Hardwood_Beam"
    },
    {
      "x": -3,
      "y": 8,
      "z": -9,
      "name": "Wood_Tropicalwood_Roof",
      "rotation": 2
    },
    {
      "x": -3,
      "y": 4,
      "z": -8,
      "name": "Furniture_Crude_Platform"
    },
    {
      "x": -3,
      "y": 5,
      "z": -8,
      "name": "*Wood_Hardwood_Fence_State_Definitions_Corner",
      "rotation": 3
    },
    {
      "x": -3,
      "y": 8,
      "z": -8,
      "name": "Wood_Goldenwood_Planks_Half",
      "rotation": 8
    },
    {
      "x": -3,
      "y": 9,
      "z": -8,
      "name": "Wood_Tropicalwood_Roof_Flat",
      "rotation": 2
    },
    {
      "x": -3,
      "y": 4,
      "z": -7,
      "name": "Furniture_Crude_Platform"
    },
    {
      "x": -3,
      "y": 8,
      "z": -7,
      "name": "Wood_Goldenwood_Planks_Half",
      "rotation": 8
    },
    {
      "x": -3,
      "y": 9,
      "z": -7,
      "name": "*Wood_Hardwood_Fence_State_Definitions_Corner",
      "rotation": 1
    },
    {
      "x": -3,
      "y": 10,
      "z": -7,
      "name": "Wood_Hardwood_Beam"
    },
    {
      "x": -3,
      "y": 11,
      "z": -7,
      "name": "Wood_Hardwood_Beam"
    },
    {
      "x": -3,
      "y": 12,
      "z": -7,
      "name": "*Wood_Tropicalwood_Roof_State_Definitions_Corner_Left",
      "rotation": 2
    },
    {
      "x": -3,
      "y": 0,
      "z": -6,
      "name": "Furniture_Crude_Platform"
    },
    {
      "x": -3,
      "y": 1,
      "z": -6,
      "name": "Wood_Softwood_Fence",
      "rotation": 2
    },
    {
      "x": -3,
      "y": 2,
      "z": -6,
      "name": "Wood_Goldenwood_Fence",
      "rotation": 2
    },
    {
      "x": -3,
      "y": 3,
      "z": -6,
      "name": "Wood_Softwood_Fence",
      "rotation": 2
    },
    {
      "x": -3,
      "y": 4,
      "z": -6,
      "name": "Wood_Goldenwood_Stairs",
      "rotation": 8
    },
    {
      "x": -3,
      "y": 5,
      "z": -6,
      "name": "Wood_Softwood_Fence",
      "rotation": 2
    },
    {
      "x": -3,
      "y": 6,
      "z": -6,
      "name": "Wood_Softwood_Fence",
      "rotation": 2
    },
    {
      "x": -3,
      "y": 7,
      "z": -6,
      "name": "Wood_Softwood_Fence",
      "rotation": 2
    },
    {
      "x": -3,
      "y": 8,
      "z": -6,
      "name": "Wood_Goldenwood_Stairs",
      "rotation": 8
    },
    {
      "x": -3,
      "y": 9,
      "z": -6,
      "name": "*Wood_Hardwood_Fence_State_Definitions_Corner",
      "rotation": 3
    },
    {
      "x": -3,
      "y": 12,
      "z": -6,
      "name": "*Wood_Tropicalwood_Roof_Hollow_State_Definitions_Inverted_Corner_Right",
      "rotation": 3
    },
    {
      "x": -3,
      "y": 0,
      "z": -5,
      "name": "Wood_Goldenwood_Planks_Half",
      "rotation": 8
    },
    {
      "x": -3,
      "y": 1,
      "z": -5,
      "name": "Furniture_Crude_Chest_Small",
      "components": {
        "Components": {
          "PlacedByInteraction": {
            "WhoPlacedUuid": {
              "$binary": "i+Pl1XV4SJWc91StkZuWWA==",
              "$type": "04"
            }
          },
          "ItemContainerBlock": {
            "ItemContainer": {
              "Capacity": 18,
              "Items": {}
            },
            "Capacity": 18
          }
        }
      }
    },
    {
      "x": -3,
      "y": 4,
      "z": -5,
      "name": "Wood_Goldenwood_Planks_Half",
      "rotation": 8
    },
    {
      "x": -3,
      "y": 8,
      "z": -5,
      "name": "Wood_Goldenwood_Planks_Half",
      "rotation": 8
    },
    {
      "x": -3,
      "y": 13,
      "z": -5,
      "name": "Wood_Tropicalwood_Roof_Flat"
    },
    {
      "x": -3,
      "y": 0,
      "z": -4,
      "name": "Wood_Goldenwood_Planks_Half",
      "rotation": 8
    },
    {
      "x": -3,
      "y": 4,
      "z": -4,
      "name": "Wood_Goldenwood_Planks_Half",
      "rotation": 8
    },
    {
      "x": -3,
      "y": 8,
      "z": -4,
      "name": "Wood_Goldenwood_Planks_Half",
      "rotation": 8
    },
    {
      "x": -3,
      "y": 9,
      "z": -4,
      "name": "Wood_Hardwood_Fence",
      "rotation": 2
    },
    {
      "x": -3,
      "y": 13,
      "z": -4,
      "name": "Wood_Tropicalwood_Roof_Flat"
    },
    {
      "x": -3,
      "y": 0,
      "z": -3,
      "name": "Wood_Goldenwood_Planks_Half",
      "rotation": 8
    },
    {
      "x": -3,
      "y": 4,
      "z": -3,
      "name": "Wood_Goldenwood_Planks_Half",
      "rotation": 8
    },
    {
      "x": -3,
      "y": 13,
      "z": -3,
      "name": "*Wood_Tropicalwood_Roof_Shallow_State_Definitions_Corner_Left",
      "rotation": 2
    },
    {
      "x": -3,
      "y": 0,
      "z": -2,
      "name": "Wood_Goldenwood_Planks_Half",
      "rotation": 8
    },
    {
      "x": -3,
      "y": 4,
      "z": -2,
      "name": "Wood_Goldenwood_Planks_Half",
      "rotation": 8
    },
    {
      "x": -3,
      "y": 7,
      "z": -2,
      "name": "Wood_Goldenwood_Planks_Half"
    },
    {
      "x": -3,
      "y": 13,
      "z": -2,
      "name": "*Wood_Tropicalwood_Roof_Shallow_State_Definitions_Corner_Left",
      "filler": 32,
      "rotation": 2
    },
    {
      "x": -3,
      "y": 0,
      "z": -1,
      "name": "Wood_Goldenwood_Planks_Half",
      "rotation": 8
    },
    {
      "x": -3,
      "y": 4,
      "z": -1,
      "name": "Wood_Goldenwood_Planks_Half",
      "rotation": 8
    },
    {
      "x": -3,
      "y": 6,
      "z": -1,
      "name": "Wood_Goldenwood_Planks_Half",
      "rotation": 8
    },
    {
      "x": -3,
      "y": 13,
      "z": -1,
      "name": "Wood_Tropicalwood_Roof_Shallow",
      "rotation": 3
    },
    {
      "x": -3,
      "y": 0,
      "z": 0,
      "name": "Wood_Goldenwood_Planks_Half",
      "rotation": 8
    },
    {
      "x": -3,
      "y": 4,
      "z": 0,
      "name": "Wood_Goldenwood_Planks_Half",
      "rotation": 8
    },
    {
      "x": -3,
      "y": 6,
      "z": 0,
      "name": "Wood_Goldenwood_Planks_Half"
    },
    {
      "x": -3,
      "y": 13,
      "z": 0,
      "name": "Wood_Tropicalwood_Roof_Shallow",
      "rotation": 3
    },
    {
      "x": -3,
      "y": 0,
      "z": 1,
      "name": "Wood_Goldenwood_Planks_Half",
      "rotation": 8
    },
    {
      "x": -3,
      "y": 4,
      "z": 1,
      "name": "Wood_Goldenwood_Planks_Half",
      "rotation": 8
    },
    {
      "x": -3,
      "y": 5,
      "z": 1,
      "name": "Wood_Goldenwood_Planks_Half",
      "rotation": 8
    },
    {
      "x": -3,
      "y": 13,
      "z": 1,
      "name": "Wood_Tropicalwood_Roof_Shallow",
      "rotation": 3
    },
    {
      "x": -3,
      "y": 0,
      "z": 2,
      "name": "Wood_Goldenwood_Planks_Half",
      "rotation": 8
    },
    {
      "x": -3,
      "y": 4,
      "z": 2,
      "name": "Wood_Tropicalwood_Planks"
    },
    {
      "x": -3,
      "y": 5,
      "z": 2,
      "name": "Wood_Goldenwood_Planks_Half"
    },
    {
      "x": -3,
      "y": 8,
      "z": 2,
      "name": "Wood_Goldenwood_Planks_Half",
      "rotation": 8
    },
    {
      "x": -3,
      "y": 9,
      "z": 2,
      "name": "Wood_Hardwood_Fence"
    },
    {
      "x": -3,
      "y": 13,
      "z": 2,
      "name": "*Wood_Tropicalwood_Roof_Shallow_State_Definitions_Corner_Left",
      "filler": 992,
      "rotation": 3
    },
    {
      "x": -3,
      "y": 0,
      "z": 3,
      "name": "Wood_Goldenwood_Planks_Half",
      "rotation": 8
    },
    {
      "x": -3,
      "y": 4,
      "z": 3,
      "name": "Wood_Goldenwood_Planks_Half",
      "rotation": 8
    },
    {
      "x": -3,
      "y": 8,
      "z": 3,
      "name": "Wood_Goldenwood_Planks_Half",
      "rotation": 8
    },
    {
      "x": -3,
      "y": 13,
      "z": 3,
      "name": "*Wood_Tropicalwood_Roof_Shallow_State_Definitions_Corner_Left",
      "rotation": 3
    },
    {
      "x": -3,
      "y": 0,
      "z": 4,
      "name": "Wood_Goldenwood_Planks_Half",
      "rotation": 8
    },
    {
      "x": -3,
      "y": 4,
      "z": 4,
      "name": "Wood_Goldenwood_Planks_Half",
      "rotation": 8
    },
    {
      "x": -3,
      "y": 8,
      "z": 4,
      "name": "Wood_Goldenwood_Planks_Half",
      "rotation": 8
    },
    {
      "x": -3,
      "y": 13,
      "z": 4,
      "name": "Wood_Tropicalwood_Roof_Flat",
      "rotation": 2
    },
    {
      "x": -3,
      "y": 0,
      "z": 5,
      "name": "Wood_Goldenwood_Planks_Half",
      "rotation": 8
    },
    {
      "x": -3,
      "y": 4,
      "z": 5,
      "name": "Wood_Goldenwood_Planks_Half",
      "rotation": 8
    },
    {
      "x": -3,
      "y": 8,
      "z": 5,
      "name": "Wood_Goldenwood_Planks_Half",
      "rotation": 8
    },
    {
      "x": -3,
      "y": 13,
      "z": 5,
      "name": "Wood_Tropicalwood_Roof_Flat",
      "rotation": 2
    },
    {
      "x": -3,
      "y": 0,
      "z": 6,
      "name": "Furniture_Crude_Platform"
    },
    {
      "x": -3,
      "y": 1,
      "z": 6,
      "name": "Wood_Softwood_Fence"
    },
    {
      "x": -3,
      "y": 2,
      "z": 6,
      "name": "Wood_Goldenwood_Fence"
    },
    {
      "x": -3,
      "y": 3,
      "z": 6,
      "name": "Wood_Softwood_Fence"
    },
    {
      "x": -3,
      "y": 4,
      "z": 6,
      "name": "Wood_Goldenwood_Stairs",
      "rotation": 10
    },
    {
      "x": -3,
      "y": 5,
      "z": 6,
      "name": "Wood_Softwood_Fence"
    },
    {
      "x": -3,
      "y": 6,
      "z": 6,
      "name": "Wood_Softwood_Fence"
    },
    {
      "x": -3,
      "y": 7,
      "z": 6,
      "name": "Wood_Softwood_Fence"
    },
    {
      "x": -3,
      "y": 8,
      "z": 6,
      "name": "Wood_Goldenwood_Stairs",
      "rotation": 10
    },
    {
      "x": -3,
      "y": 9,
      "z": 6,
      "name": "*Wood_Hardwood_Fence_State_Definitions_Corner"
    },
    {
      "x": -3,
      "y": 12,
      "z": 6,
      "name": "Wood_Tropicalwood_Roof_Hollow"
    },
    {
      "x": -3,
      "y": 4,
      "z": 7,
      "name": "Furniture_Crude_Platform"
    },
    {
      "x": -3,
      "y": 8,
      "z": 7,
      "name": "Wood_Goldenwood_Planks_Half",
      "rotation": 8
    },
    {
      "x": -3,
      "y": 9,
      "z": 7,
      "name": "*Wood_Hardwood_Fence_State_Definitions_Corner",
      "rotation": 2
    },
    {
      "x": -3,
      "y": 10,
      "z": 7,
      "name": "Wood_Hardwood_Beam"
    },
    {
      "x": -3,
      "y": 11,
      "z": 7,
      "name": "Wood_Hardwood_Beam"
    },
    {
      "x": -3,
      "y": 4,
      "z": 8,
      "name": "Furniture_Crude_Platform"
    },
    {
      "x": -3,
      "y": 5,
      "z": 8,
      "name": "*Wood_Hardwood_Fence_State_Definitions_Corner"
    },
    {
      "x": -3,
      "y": 8,
      "z": 8,
      "name": "*Wood_Tropicalwood_Roof_Hollow_State_Definitions_Inverted_Corner_Right"
    },
    {
      "x": -3,
      "y": 4,
      "z": 9,
      "name": "Furniture_Crude_Platform",
      "rotation": 1
    },
    {
      "x": -3,
      "y": 5,
      "z": 9,
      "name": "*Wood_Hardwood_Fence_State_Definitions_Corner",
      "rotation": 2
    },
    {
      "x": -3,
      "y": 6,
      "z": 9,
      "name": "Wood_Hardwood_Beam"
    },
    {
      "x": -3,
      "y": 7,
      "z": 9,
      "name": "Wood_Hardwood_Beam"
    },
    {
      "x": -3,
      "y": 8,
      "z": 9,
      "name": "*Wood_Tropicalwood_Roof_State_Definitions_Corner_Left",
      "rotation": 3
    },
    {
      "x": -2,
      "y": 4,
      "z": -9,
      "name": "Furniture_Crude_Platform",
      "rotation": 1
    },
    {
      "x": -2,
      "y": 5,
      "z": -9,
      "name": "Wood_Hardwood_Fence",
      "rotation": 2
    },
    {
      "x": -2,
      "y": 8,
      "z": -9,
      "name": "Wood_Tropicalwood_Roof_Hollow",
      "rotation": 2
    },
    {
      "x": -2,
      "y": 4,
      "z": -8,
      "name": "Furniture_Crude_Platform"
    },
    {
      "x": -2,
      "y": 8,
      "z": -8,
      "name": "Wood_Goldenwood_Planks_Half",
      "rotation": 8
    },
    {
      "x": -2,
      "y": 9,
      "z": -8,
      "name": "Wood_Tropicalwood_Roof_Flat",
      "rotation": 2
    },
    {
      "x": -2,
      "y": 0,
      "z": -7,
      "name": "Furniture_Crude_Platform"
    },
    {
      "x": -2,
      "y": 1,
      "z": -7,
      "name": "*Wood_Softwood_Fence_State_Definitions_Corner",
      "rotation": 1
    },
    {
      "x": -2,
      "y": 2,
      "z": -7,
      "name": "*Wood_Softwood_Fence_State_Definitions_Corner",
      "rotation": 1
    },
    {
      "x": -2,
      "y": 3,
      "z": -7,
      "name": "*Wood_Softwood_Fence_State_Definitions_Corner",
      "rotation": 1
    },
    {
      "x": -2,
      "y": 4,
      "z": -7,
      "name": "*Wood_Goldenwood_Stairs_State_Definitions_Corner_Right",
      "rotation": 8
    },
    {
      "x": -2,
      "y": 5,
      "z": -7,
      "name": "*Wood_Softwood_Fence_State_Definitions_Corner",
      "rotation": 1
    },
    {
      "x": -2,
      "y": 6,
      "z": -7,
      "name": "*Wood_Softwood_Fence_State_Definitions_Corner",
      "rotation": 1
    },
    {
      "x": -2,
      "y": 7,
      "z": -7,
      "name": "*Wood_Softwood_Fence_State_Definitions_Corner",
      "rotation": 1
    },
    {
      "x": -2,
      "y": 8,
      "z": -7,
      "name": "*Wood_Goldenwood_Stairs_State_Definitions_Corner_Left",
      "rotation": 9
    },
    {
      "x": -2,
      "y": 9,
      "z": -7,
      "name": "Wood_Hardwood_Fence",
      "rotation": 2
    },
    {
      "x": -2,
      "y": 12,
      "z": -7,
      "name": "Wood_Tropicalwood_Roof_Hollow",
      "rotation": 2
    },
    {
      "x": -2,
      "y": 0,
      "z": -6,
      "name": "Furniture_Crude_Platform"
    },
    {
      "x": -2,
      "y": 1,
      "z": -6,
      "name": "*Wood_Softwood_Fence_State_Definitions_Corner",
      "rotation": 3
    },
    {
      "x": -2,
      "y": 2,
      "z": -6,
      "name": "*Wood_Softwood_Fence_State_Definitions_Corner",
      "rotation": 3
    },
    {
      "x": -2,
      "y": 3,
      "z": -6,
      "name": "*Wood_Softwood_Fence_State_Definitions_Corner",
      "rotation": 3
    },
    {
      "x": -2,
      "y": 4,
      "z": -6,
      "name": "*Wood_Goldenwood_Stairs_State_Definitions_Inverted_Corner_Left",
      "rotation": 9
    },
    {
      "x": -2,
      "y": 5,
      "z": -6,
      "name": "*Wood_Softwood_Fence_State_Definitions_Corner",
      "rotation": 3
    },
    {
      "x": -2,
      "y": 6,
      "z": -6,
      "name": "*Wood_Softwood_Fence_State_Definitions_Corner",
      "rotation": 3
    },
    {
      "x": -2,
      "y": 7,
      "z": -6,
      "name": "*Wood_Softwood_Fence_State_Definitions_Corner",
      "rotation": 3
    },
    {
      "x": -2,
      "y": 8,
      "z": -6,
      "name": "*Wood_Goldenwood_Stairs_State_Definitions_Inverted_Corner_Right",
      "rotation": 8
    },
    {
      "x": -2,
      "y": 13,
      "z": -6,
      "name": "Wood_Tropicalwood_Roof_Flat"
    },
    {
      "x": -2,
      "y": 0,
      "z": -5,
      "name": "Wood_Goldenwood_Planks_Half",
      "rotation": 8
    },
    {
      "x": -2,
      "y": 4,
      "z": -5,
      "name": "Wood_Goldenwood_Planks_Half",
      "rotation": 8
    },
    {
      "x": -2,
      "y": 8,
      "z": -5,
      "name": "Wood_Goldenwood_Planks_Half",
      "rotation": 8
    },
    {
      "x": -2,
      "y": 13,
      "z": -5,
      "name": "Wood_Tropicalwood_Roof_Flat"
    },
    {
      "x": -2,
      "y": 0,
      "z": -4,
      "name": "Wood_Goldenwood_Planks_Half",
      "rotation": 8
    },
    {
      "x": -2,
      "y": 4,
      "z": -4,
      "name": "Wood_Goldenwood_Planks_Half",
      "rotation": 8
    },
    {
      "x": -2,
      "y": 8,
      "z": -4,
      "name": "Wood_Goldenwood_Planks_Half",
      "rotation": 8
    },
    {
      "x": -2,
      "y": 9,
      "z": -4,
      "name": "Wood_Hardwood_Fence",
      "rotation": 2
    },
    {
      "x": -2,
      "y": 13,
      "z": -4,
      "name": "Wood_Tropicalwood_Roof_Flat"
    },
    {
      "x": -2,
      "y": 0,
      "z": -3,
      "name": "Wood_Goldenwood_Planks_Half",
      "rotation": 8
    },
    {
      "x": -2,
      "y": 4,
      "z": -3,
      "name": "Wood_Goldenwood_Planks_Half",
      "rotation": 8
    },
    {
      "x": -2,
      "y": 7,
      "z": -3,
      "name": "Wood_Goldenwood_Planks_Half"
    },
    {
      "x": -2,
      "y": 13,
      "z": -3,
      "name": "*Wood_Tropicalwood_Roof_Shallow_State_Definitions_Corner_Left",
      "filler": 1,
      "rotation": 2
    },
    {
      "x": -2,
      "y": 0,
      "z": -2,
      "name": "Wood_Goldenwood_Planks_Half",
      "rotation": 8
    },
    {
      "x": -2,
      "y": 4,
      "z": -2,
      "name": "Wood_Goldenwood_Planks_Half",
      "rotation": 8
    },
    {
      "x": -2,
      "y": 7,
      "z": -2,
      "name": "Wood_Goldenwood_Planks_Half"
    },
    {
      "x": -2,
      "y": 13,
      "z": -2,
      "name": "*Wood_Tropicalwood_Roof_Shallow_State_Definitions_Corner_Left",
      "filler": 33,
      "rotation": 2
    },
    {
      "x": -2,
      "y": 0,
      "z": -1,
      "name": "Wood_Goldenwood_Planks_Half",
      "rotation": 8
    },
    {
      "x": -2,
      "y": 1,
      "z": -1,
      "name": "Furniture_Lumberjack_Lamp",
      "filler": 992,
      "rotation": 3
    },
    {
      "x": -2,
      "y": 2,
      "z": -1,
      "name": "Furniture_Lumberjack_Lamp",
      "filler": 2016,
      "rotation": 3
    },
    {
      "x": -2,
      "y": 3,
      "z": -1,
      "name": "Furniture_Lumberjack_Lamp",
      "filler": 3040,
      "rotation": 3
    },
    {
      "x": -2,
      "y": 4,
      "z": -1,
      "name": "Wood_Goldenwood_Planks_Half",
      "rotation": 8
    },
    {
      "x": -2,
      "y": 6,
      "z": -1,
      "name": "Wood_Goldenwood_Planks_Half",
      "rotation": 8
    },
    {
      "x": -2,
      "y": 13,
      "z": -1,
      "name": "Wood_Tropicalwood_Roof_Shallow",
      "filler": 1,
      "rotation": 3
    },
    {
      "x": -2,
      "y": 0,
      "z": 0,
      "name": "Wood_Goldenwood_Planks_Half",
      "rotation": 8
    },
    {
      "x": -2,
      "y": 1,
      "z": 0,
      "name": "Furniture_Lumberjack_Lamp",
      "rotation": 3
    },
    {
      "x": -2,
      "y": 2,
      "z": 0,
      "name": "Furniture_Lumberjack_Lamp",
      "filler": 1024,
      "rotation": 3
    },
    {
      "x": -2,
      "y": 3,
      "z": 0,
      "name": "Furniture_Lumberjack_Lamp",
      "filler": 2048,
      "rotation": 3
    },
    {
      "x": -2,
      "y": 4,
      "z": 0,
      "name": "Wood_Goldenwood_Planks_Half",
      "rotation": 8
    },
    {
      "x": -2,
      "y": 6,
      "z": 0,
      "name": "Wood_Goldenwood_Planks_Half"
    },
    {
      "x": -2,
      "y": 10,
      "z": 0,
      "name": "Wood_Torch_Wall",
      "rotation": 3
    },
    {
      "x": -2,
      "y": 13,
      "z": 0,
      "name": "Wood_Tropicalwood_Roof_Shallow",
      "filler": 1,
      "rotation": 3
    },
    {
      "x": -2,
      "y": 0,
      "z": 1,
      "name": "Wood_Goldenwood_Planks_Half",
      "rotation": 8
    },
    {
      "x": -2,
      "y": 4,
      "z": 1,
      "name": "Wood_Goldenwood_Planks_Half",
      "rotation": 8
    },
    {
      "x": -2,
      "y": 5,
      "z": 1,
      "name": "Wood_Goldenwood_Planks_Half",
      "rotation": 8
    },
    {
      "x": -2,
      "y": 13,
      "z": 1,
      "name": "Wood_Tropicalwood_Roof_Shallow",
      "filler": 1,
      "rotation": 3
    },
    {
      "x": -2,
      "y": 0,
      "z": 2,
      "name": "Wood_Goldenwood_Planks_Half",
      "rotation": 8
    },
    {
      "x": -2,
      "y": 4,
      "z": 2,
      "name": "Wood_Tropicalwood_Planks"
    },
    {
      "x": -2,
      "y": 5,
      "z": 2,
      "name": "Wood_Goldenwood_Planks_Half"
    },
    {
      "x": -2,
      "y": 8,
      "z": 2,
      "name": "Wood_Goldenwood_Planks_Half",
      "rotation": 8
    },
    {
      "x": -2,
      "y": 9,
      "z": 2,
      "name": "Wood_Hardwood_Fence"
    },
    {
      "x": -2,
      "y": 13,
      "z": 2,
      "name": "*Wood_Tropicalwood_Roof_Shallow_State_Definitions_Corner_Left",
      "filler": 993,
      "rotation": 3
    },
    {
      "x": -2,
      "y": 0,
      "z": 3,
      "name": "Wood_Goldenwood_Planks_Half",
      "rotation": 8
    },
    {
      "x": -2,
      "y": 4,
      "z": 3,
      "name": "Wood_Goldenwood_Planks_Half",
      "rotation": 8
    },
    {
      "x": -2,
      "y": 8,
      "z": 3,
      "name": "Wood_Goldenwood_Planks_Half",
      "rotation": 8
    },
    {
      "x": -2,
      "y": 13,
      "z": 3,
      "name": "*Wood_Tropicalwood_Roof_Shallow_State_Definitions_Corner_Left",
      "filler": 1,
      "rotation": 3
    },
    {
      "x": -2,
      "y": 0,
      "z": 4,
      "name": "Wood_Goldenwood_Planks_Half",
      "rotation": 8
    },
    {
      "x": -2,
      "y": 4,
      "z": 4,
      "name": "Wood_Goldenwood_Planks_Half",
      "rotation": 8
    },
    {
      "x": -2,
      "y": 8,
      "z": 4,
      "name": "Wood_Goldenwood_Planks_Half",
      "rotation": 8
    },
    {
      "x": -2,
      "y": 13,
      "z": 4,
      "name": "Wood_Tropicalwood_Roof_Flat",
      "rotation": 2
    },
    {
      "x": -2,
      "y": 0,
      "z": 5,
      "name": "Wood_Goldenwood_Planks_Half",
      "rotation": 8
    },
    {
      "x": -2,
      "y": 4,
      "z": 5,
      "name": "Wood_Goldenwood_Planks_Half",
      "rotation": 8
    },
    {
      "x": -2,
      "y": 8,
      "z": 5,
      "name": "Wood_Goldenwood_Planks_Half",
      "rotation": 8
    },
    {
      "x": -2,
      "y": 13,
      "z": 5,
      "name": "Wood_Tropicalwood_Roof_Flat",
      "rotation": 2
    },
    {
      "x": -2,
      "y": 0,
      "z": 6,
      "name": "Furniture_Crude_Platform"
    },
    {
      "x": -2,
      "y": 1,
      "z": 6,
      "name": "*Wood_Softwood_Fence_State_Definitions_Corner"
    },
    {
      "x": -2,
      "y": 2,
      "z": 6,
      "name": "*Wood_Softwood_Fence_State_Definitions_Corner"
    },
    {
      "x": -2,
      "y": 3,
      "z": 6,
      "name": "*Wood_Softwood_Fence_State_Definitions_Corner"
    },
    {
      "x": -2,
      "y": 4,
      "z": 6,
      "name": "*Wood_Goldenwood_Stairs_State_Definitions_Inverted_Corner_Left",
      "rotation": 10
    },
    {
      "x": -2,
      "y": 5,
      "z": 6,
      "name": "*Wood_Softwood_Fence_State_Definitions_Corner"
    },
    {
      "x": -2,
      "y": 6,
      "z": 6,
      "name": "*Wood_Softwood_Fence_State_Definitions_Corner"
    },
    {
      "x": -2,
      "y": 7,
      "z": 6,
      "name": "*Wood_Softwood_Fence_State_Definitions_Corner"
    },
    {
      "x": -2,
      "y": 8,
      "z": 6,
      "name": "*Wood_Goldenwood_Stairs_State_Definitions_Inverted_Corner_Right",
      "rotation": 9
    },
    {
      "x": -2,
      "y": 12,
      "z": 6,
      "name": "*Wood_Tropicalwood_Roof_Hollow_State_Definitions_Inverted_Corner_Right"
    },
    {
      "x": -2,
      "y": 0,
      "z": 7,
      "name": "Furniture_Crude_Platform"
    },
    {
      "x": -2,
      "y": 1,
      "z": 7,
      "name": "*Wood_Softwood_Fence_State_Definitions_Corner",
      "rotation": 2
    },
    {
      "x": -2,
      "y": 2,
      "z": 7,
      "name": "*Wood_Softwood_Fence_State_Definitions_Corner",
      "rotation": 2
    },
    {
      "x": -2,
      "y": 3,
      "z": 7,
      "name": "*Wood_Softwood_Fence_State_Definitions_Corner",
      "rotation": 2
    },
    {
      "x": -2,
      "y": 4,
      "z": 7,
      "name": "*Wood_Goldenwood_Stairs_State_Definitions_Corner_Right",
      "rotation": 9
    },
    {
      "x": -2,
      "y": 5,
      "z": 7,
      "name": "*Wood_Softwood_Fence_State_Definitions_Corner",
      "rotation": 2
    },
    {
      "x": -2,
      "y": 6,
      "z": 7,
      "name": "*Wood_Softwood_Fence_State_Definitions_Corner",
      "rotation": 2
    },
    {
      "x": -2,
      "y": 7,
      "z": 7,
      "name": "*Wood_Softwood_Fence_State_Definitions_Corner",
      "rotation": 2
    },
    {
      "x": -2,
      "y": 8,
      "z": 7,
      "name": "*Wood_Goldenwood_Stairs_State_Definitions_Corner_Left",
      "rotation": 10
    },
    {
      "x": -2,
      "y": 9,
      "z": 7,
      "name": "Wood_Hardwood_Fence"
    },
    {
      "x": -2,
      "y": 12,
      "z": 7,
      "name": "*Wood_Tropicalwood_Roof_Hollow_State_Definitions_Corner_Left",
      "rotation": 3
    },
    {
      "x": -2,
      "y": 4,
      "z": 8,
      "name": "Furniture_Crude_Platform"
    },
    {
      "x": -2,
      "y": 9,
      "z": 8,
      "name": "Wood_Tropicalwood_Roof_Flat",
      "rotation": 2
    },
    {
      "x": -2,
      "y": 4,
      "z": 9,
      "name": "Furniture_Crude_Platform",
      "rotation": 1
    },
    {
      "x": -2,
      "y": 5,
      "z": 9,
      "name": "Wood_Hardwood_Fence"
    },
    {
      "x": -2,
      "y": 8,
      "z": 9,
      "name": "Wood_Tropicalwood_Roof_Hollow"
    },
    {
      "x": -1,
      "y": 4,
      "z": -9,
      "name": "Furniture_Crude_Platform",
      "rotation": 1
    },
    {
      "x": -1,
      "y": 5,
      "z": -9,
      "name": "Wood_Hardwood_Fence",
      "rotation": 2
    },
    {
      "x": -1,
      "y": 8,
      "z": -9,
      "name": "Wood_Tropicalwood_Roof_Hollow",
      "rotation": 2
    },
    {
      "x": -1,
      "y": 4,
      "z": -8,
      "name": "Furniture_Crude_Platform"
    },
    {
      "x": -1,
      "y": 8,
      "z": -8,
      "name": "Wood_Goldenwood_Planks_Half",
      "rotation": 8
    },
    {
      "x": -1,
      "y": 9,
      "z": -8,
      "name": "Wood_Tropicalwood_Roof_Flat",
      "rotation": 2
    },
    {
      "x": -1,
      "y": 0,
      "z": -7,
      "name": "Furniture_Crude_Platform"
    },
    {
      "x": -1,
      "y": 1,
      "z": -7,
      "name": "Wood_Softwood_Fence",
      "rotation": 2
    },
    {
      "x": -1,
      "y": 2,
      "z": -7,
      "name": "Wood_Softwood_Fence",
      "rotation": 2
    },
    {
      "x": -1,
      "y": 3,
      "z": -7,
      "name": "Wood_Softwood_Fence",
      "rotation": 2
    },
    {
      "x": -1,
      "y": 4,
      "z": -7,
      "name": "Wood_Goldenwood_Stairs",
      "rotation": 8
    },
    {
      "x": -1,
      "y": 5,
      "z": -7,
      "name": "Wood_Softwood_Fence",
      "rotation": 2
    },
    {
      "x": -1,
      "y": 6,
      "z": -7,
      "name": "Wood_Softwood_Fence",
      "rotation": 2
    },
    {
      "x": -1,
      "y": 7,
      "z": -7,
      "name": "Wood_Softwood_Fence",
      "rotation": 2
    },
    {
      "x": -1,
      "y": 8,
      "z": -7,
      "name": "Wood_Goldenwood_Stairs",
      "rotation": 8
    },
    {
      "x": -1,
      "y": 9,
      "z": -7,
      "name": "Wood_Hardwood_Fence",
      "rotation": 2
    },
    {
      "x": -1,
      "y": 12,
      "z": -7,
      "name": "Wood_Tropicalwood_Roof_Hollow",
      "rotation": 2
    },
    {
      "x": -1,
      "y": 0,
      "z": -6,
      "name": "Wood_Goldenwood_Planks_Half",
      "rotation": 8
    },
    {
      "x": -1,
      "y": 1,
      "z": -6,
      "name": "Furniture_Ancient_Bed",
      "filler": 992,
      "rotation": 1
    },
    {
      "x": -1,
      "y": 2,
      "z": -6,
      "name": "Furniture_Ancient_Bed",
      "filler": 2016,
      "rotation": 1
    },
    {
      "x": -1,
      "y": 4,
      "z": -6,
      "name": "Wood_Goldenwood_Planks_Half",
      "rotation": 8
    },
    {
      "x": -1,
      "y": 5,
      "z": -6,
      "name": "Deco_Lantern"
    },
    {
      "x": -1,
      "y": 8,
      "z": -6,
      "name": "Wood_Goldenwood_Planks_Half",
      "rotation": 8
    },
    {
      "x": -1,
      "y": 13,
      "z": -6,
      "name": "Wood_Tropicalwood_Roof_Flat"
    },
    {
      "x": -1,
      "y": 0,
      "z": -5,
      "name": "Wood_Goldenwood_Planks_Half",
      "rotation": 8
    },
    {
      "x": -1,
      "y": 1,
      "z": -5,
      "name": "Furniture_Ancient_Bed",
      "components": {
        "Components": {
          "PlacedByInteraction": {
            "WhoPlacedUuid": {
              "$binary": "i+Pl1XV4SJWc91StkZuWWA==",
              "$type": "04"
            }
          },
          "RespawnBlock": {}
        }
      },
      "rotation": 1
    },
    {
      "x": -1,
      "y": 2,
      "z": -5,
      "name": "Furniture_Ancient_Bed",
      "filler": 1024,
      "rotation": 1
    },
    {
      "x": -1,
      "y": 4,
      "z": -5,
      "name": "Wood_Goldenwood_Planks_Half",
      "rotation": 8
    },
    {
      "x": -1,
      "y": 8,
      "z": -5,
      "name": "Wood_Goldenwood_Planks_Half",
      "rotation": 8
    },
    {
      "x": -1,
      "y": 13,
      "z": -5,
      "name": "Wood_Tropicalwood_Roof_Flat"
    },
    {
      "x": -1,
      "y": 0,
      "z": -4,
      "name": "Wood_Goldenwood_Planks_Half",
      "rotation": 8
    },
    {
      "x": -1,
      "y": 4,
      "z": -4,
      "name": "Wood_Goldenwood_Planks_Half",
      "rotation": 8
    },
    {
      "x": -1,
      "y": 8,
      "z": -4,
      "name": "Wood_Goldenwood_Planks_Half",
      "rotation": 8
    },
    {
      "x": -1,
      "y": 9,
      "z": -4,
      "name": "Wood_Hardwood_Fence",
      "rotation": 2
    },
    {
      "x": -1,
      "y": 13,
      "z": -4,
      "name": "Wood_Tropicalwood_Roof_Flat"
    },
    {
      "x": -1,
      "y": 0,
      "z": -3,
      "name": "Wood_Goldenwood_Planks_Half",
      "rotation": 8
    },
    {
      "x": -1,
      "y": 4,
      "z": -3,
      "name": "Wood_Goldenwood_Planks_Half",
      "rotation": 8
    },
    {
      "x": -1,
      "y": 7,
      "z": -3,
      "name": "Wood_Goldenwood_Planks_Half",
      "rotation": 8
    },
    {
      "x": -1,
      "y": 13,
      "z": -3,
      "name": "Wood_Tropicalwood_Roof_Shallow",
      "rotation": 2
    },
    {
      "x": -1,
      "y": 0,
      "z": -2,
      "name": "Wood_Goldenwood_Planks_Half",
      "rotation": 8
    },
    {
      "x": -1,
      "y": 1,
      "z": -2,
      "name": "Bench_WorkBench",
      "components": {
        "Components": {
          "BenchBlock": {
            "TierLevel": 1,
            "UpgradeItems": []
          },
          "PlacedByInteraction": {
            "WhoPlacedUuid": {
              "$binary": "i+Pl1XV4SJWc91StkZuWWA==",
              "$type": "04"
            }
          }
        }
      },
      "rotation": 2
    },
    {
      "x": -1,
      "y": 4,
      "z": -2,
      "name": "Wood_Goldenwood_Planks_Half",
      "rotation": 8
    },
    {
      "x": -1,
      "y": 7,
      "z": -2,
      "name": "Wood_Goldenwood_Planks_Half",
      "rotation": 8
    },
    {
      "x": -1,
      "y": 13,
      "z": -2,
      "name": "Wood_Tropicalwood_Roof_Shallow",
      "filler": 32,
      "rotation": 2
    },
    {
      "x": -1,
      "y": 0,
      "z": -1,
      "name": "Wood_Sallow_Trunk",
      "rotation": 2
    },
    {
      "x": -1,
      "y": 1,
      "z": -1,
      "name": "Wood_Sallow_Trunk",
      "rotation": 2
    },
    {
      "x": -1,
      "y": 2,
      "z": -1,
      "name": "Wood_Sallow_Trunk",
      "rotation": 2
    },
    {
      "x": -1,
      "y": 3,
      "z": -1,
      "name": "Wood_Sallow_Trunk",
      "rotation": 2
    },
    {
      "x": -1,
      "y": 4,
      "z": -1,
      "name": "Wood_Sallow_Trunk",
      "rotation": 2
    },
    {
      "x": -1,
      "y": 5,
      "z": -1,
      "name": "Wood_Sallow_Trunk",
      "rotation": 2
    },
    {
      "x": -1,
      "y": 6,
      "z": -1,
      "name": "Wood_Sallow_Trunk",
      "rotation": 2
    },
    {
      "x": -1,
      "y": 7,
      "z": -1,
      "name": "Wood_Sallow_Trunk",
      "rotation": 2
    },
    {
      "x": -1,
      "y": 8,
      "z": -1,
      "name": "Wood_Sallow_Trunk",
      "rotation": 2
    },
    {
      "x": -1,
      "y": 9,
      "z": -1,
      "name": "Wood_Sallow_Trunk",
      "rotation": 2
    },
    {
      "x": -1,
      "y": 10,
      "z": -1,
      "name": "Wood_Sallow_Trunk",
      "rotation": 2
    },
    {
      "x": -1,
      "y": 11,
      "z": -1,
      "name": "Wood_Sallow_Trunk",
      "rotation": 2
    },
    {
      "x": -1,
      "y": 12,
      "z": -1,
      "name": "Wood_Sallow_Trunk",
      "rotation": 2
    },
    {
      "x": -1,
      "y": 13,
      "z": -1,
      "name": "Wood_Sallow_Trunk",
      "rotation": 2
    },
    {
      "x": -1,
      "y": 14,
      "z": -1,
      "name": "Wood_Sallow_Trunk",
      "rotation": 2
    },
    {
      "x": -1,
      "y": 0,
      "z": 0,
      "name": "Wood_Sallow_Trunk",
      "rotation": 2
    },
    {
      "x": -1,
      "y": 1,
      "z": 0,
      "name": "Wood_Sallow_Trunk",
      "rotation": 2
    },
    {
      "x": -1,
      "y": 2,
      "z": 0,
      "name": "Wood_Sallow_Trunk",
      "rotation": 2
    },
    {
      "x": -1,
      "y": 3,
      "z": 0,
      "name": "Wood_Sallow_Trunk",
      "rotation": 2
    },
    {
      "x": -1,
      "y": 4,
      "z": 0,
      "name": "Wood_Sallow_Trunk",
      "rotation": 2
    },
    {
      "x": -1,
      "y": 5,
      "z": 0,
      "name": "Wood_Sallow_Trunk",
      "rotation": 2
    },
    {
      "x": -1,
      "y": 6,
      "z": 0,
      "name": "Wood_Sallow_Trunk",
      "rotation": 2
    },
    {
      "x": -1,
      "y": 7,
      "z": 0,
      "name": "Wood_Sallow_Trunk",
      "rotation": 2
    },
    {
      "x": -1,
      "y": 8,
      "z": 0,
      "name": "Wood_Sallow_Trunk",
      "rotation": 2
    },
    {
      "x": -1,
      "y": 9,
      "z": 0,
      "name": "Wood_Sallow_Trunk",
      "rotation": 2
    },
    {
      "x": -1,
      "y": 10,
      "z": 0,
      "name": "Wood_Sallow_Trunk",
      "rotation": 2
    },
    {
      "x": -1,
      "y": 11,
      "z": 0,
      "name": "Wood_Sallow_Trunk",
      "rotation": 2
    },
    {
      "x": -1,
      "y": 12,
      "z": 0,
      "name": "Wood_Sallow_Trunk",
      "rotation": 2
    },
    {
      "x": -1,
      "y": 13,
      "z": 0,
      "name": "Wood_Sallow_Trunk",
      "rotation": 2
    },
    {
      "x": -1,
      "y": 14,
      "z": 0,
      "name": "Wood_Sallow_Trunk",
      "rotation": 2
    },
    {
      "x": -1,
      "y": 0,
      "z": 1,
      "name": "Wood_Sallow_Trunk",
      "rotation": 2
    },
    {
      "x": -1,
      "y": 1,
      "z": 1,
      "name": "Wood_Sallow_Trunk",
      "rotation": 2
    },
    {
      "x": -1,
      "y": 2,
      "z": 1,
      "name": "Wood_Sallow_Trunk",
      "rotation": 2
    },
    {
      "x": -1,
      "y": 3,
      "z": 1,
      "name": "Wood_Sallow_Trunk",
      "rotation": 2
    },
    {
      "x": -1,
      "y": 4,
      "z": 1,
      "name": "Wood_Sallow_Trunk",
      "rotation": 2
    },
    {
      "x": -1,
      "y": 5,
      "z": 1,
      "name": "Wood_Sallow_Trunk",
      "rotation": 2
    },
    {
      "x": -1,
      "y": 6,
      "z": 1,
      "name": "Wood_Sallow_Trunk",
      "rotation": 2
    },
    {
      "x": -1,
      "y": 7,
      "z": 1,
      "name": "Wood_Sallow_Trunk",
      "rotation": 2
    },
    {
      "x": -1,
      "y": 8,
      "z": 1,
      "name": "Wood_Sallow_Trunk",
      "rotation": 2
    },
    {
      "x": -1,
      "y": 9,
      "z": 1,
      "name": "Wood_Sallow_Trunk",
      "rotation": 2
    },
    {
      "x": -1,
      "y": 10,
      "z": 1,
      "name": "Wood_Sallow_Trunk",
      "rotation": 2
    },
    {
      "x": -1,
      "y": 11,
      "z": 1,
      "name": "Wood_Sallow_Trunk",
      "rotation": 2
    },
    {
      "x": -1,
      "y": 12,
      "z": 1,
      "name": "Wood_Sallow_Trunk",
      "rotation": 2
    },
    {
      "x": -1,
      "y": 13,
      "z": 1,
      "name": "Wood_Sallow_Trunk",
      "rotation": 2
    },
    {
      "x": -1,
      "y": 14,
      "z": 1,
      "name": "Wood_Sallow_Trunk",
      "rotation": 2
    },
    {
      "x": -1,
      "y": 0,
      "z": 2,
      "name": "Wood_Goldenwood_Planks_Half",
      "rotation": 8
    },
    {
      "x": -1,
      "y": 4,
      "z": 2,
      "name": "Wood_Goldenwood_Planks_Half",
      "rotation": 8
    },
    {
      "x": -1,
      "y": 8,
      "z": 2,
      "name": "Wood_Goldenwood_Planks_Half",
      "rotation": 8
    },
    {
      "x": -1,
      "y": 13,
      "z": 2,
      "name": "Wood_Tropicalwood_Roof_Shallow",
      "filler": 992
    },
    {
      "x": -1,
      "y": 14,
      "z": 2,
      "name": "Wood_Sallow_Branch_Short",
      "support": 15
    },
    {
      "x": -1,
      "y": 0,
      "z": 3,
      "name": "Wood_Goldenwood_Planks_Half",
      "rotation": 8
    },
    {
      "x": -1,
      "y": 4,
      "z": 3,
      "name": "Wood_Goldenwood_Planks_Half",
      "rotation": 8
    },
    {
      "x": -1,
      "y": 8,
      "z": 3,
      "name": "Wood_Goldenwood_Planks_Half",
      "rotation": 8
    },
    {
      "x": -1,
      "y": 13,
      "z": 3,
      "name": "Wood_Tropicalwood_Roof_Shallow"
    },
    {
      "x": -1,
      "y": 0,
      "z": 4,
      "name": "Wood_Goldenwood_Planks_Half",
      "rotation": 8
    },
    {
      "x": -1,
      "y": 4,
      "z": 4,
      "name": "Wood_Goldenwood_Planks_Half",
      "rotation": 8
    },
    {
      "x": -1,
      "y": 8,
      "z": 4,
      "name": "Wood_Goldenwood_Planks_Half",
      "rotation": 8
    },
    {
      "x": -1,
      "y": 13,
      "z": 4,
      "name": "Wood_Tropicalwood_Roof_Flat",
      "rotation": 2
    },
    {
      "x": -1,
      "y": 0,
      "z": 5,
      "name": "Wood_Goldenwood_Planks_Half",
      "rotation": 8
    },
    {
      "x": -1,
      "y": 1,
      "z": 5,
      "name": "Furniture_Ancient_Bed",
      "filler": 992,
      "rotation": 1
    },
    {
      "x": -1,
      "y": 2,
      "z": 5,
      "name": "Furniture_Ancient_Bed",
      "filler": 2016,
      "rotation": 1
    },
    {
      "x": -1,
      "y": 4,
      "z": 5,
      "name": "Wood_Goldenwood_Planks_Half",
      "rotation": 8
    },
    {
      "x": -1,
      "y": 8,
      "z": 5,
      "name": "Wood_Goldenwood_Planks_Half",
      "rotation": 8
    },
    {
      "x": -1,
      "y": 13,
      "z": 5,
      "name": "Wood_Tropicalwood_Roof_Flat",
      "rotation": 2
    },
    {
      "x": -1,
      "y": 0,
      "z": 6,
      "name": "Wood_Goldenwood_Planks_Half",
      "rotation": 8
    },
    {
      "x": -1,
      "y": 1,
      "z": 6,
      "name": "Furniture_Ancient_Bed",
      "components": {
        "Components": {
          "PlacedByInteraction": {
            "WhoPlacedUuid": {
              "$binary": "i+Pl1XV4SJWc91StkZuWWA==",
              "$type": "04"
            }
          },
          "RespawnBlock": {}
        }
      },
      "rotation": 1
    },
    {
      "x": -1,
      "y": 2,
      "z": 6,
      "name": "Furniture_Ancient_Bed",
      "filler": 1024,
      "rotation": 1
    },
    {
      "x": -1,
      "y": 4,
      "z": 6,
      "name": "Wood_Goldenwood_Planks_Half",
      "rotation": 8
    },
    {
      "x": -1,
      "y": 8,
      "z": 6,
      "name": "Wood_Goldenwood_Planks_Half",
      "rotation": 8
    },
    {
      "x": -1,
      "y": 13,
      "z": 6,
      "name": "Wood_Tropicalwood_Roof_Flat",
      "rotation": 2
    },
    {
      "x": -1,
      "y": 0,
      "z": 7,
      "name": "Furniture_Crude_Platform"
    },
    {
      "x": -1,
      "y": 1,
      "z": 7,
      "name": "Wood_Softwood_Fence"
    },
    {
      "x": -1,
      "y": 2,
      "z": 7,
      "name": "Wood_Softwood_Fence"
    },
    {
      "x": -1,
      "y": 3,
      "z": 7,
      "name": "Wood_Softwood_Fence"
    },
    {
      "x": -1,
      "y": 4,
      "z": 7,
      "name": "Wood_Goldenwood_Stairs",
      "rotation": 10
    },
    {
      "x": -1,
      "y": 5,
      "z": 7,
      "name": "Wood_Softwood_Fence"
    },
    {
      "x": -1,
      "y": 6,
      "z": 7,
      "name": "Wood_Softwood_Fence"
    },
    {
      "x": -1,
      "y": 7,
      "z": 7,
      "name": "Wood_Softwood_Fence"
    },
    {
      "x": -1,
      "y": 8,
      "z": 7,
      "name": "Wood_Goldenwood_Stairs",
      "rotation": 10
    },
    {
      "x": -1,
      "y": 9,
      "z": 7,
      "name": "Wood_Hardwood_Fence"
    },
    {
      "x": -1,
      "y": 12,
      "z": 7,
      "name": "Wood_Tropicalwood_Roof_Hollow"
    },
    {
      "x": -1,
      "y": 4,
      "z": 8,
      "name": "Furniture_Crude_Platform"
    },
    {
      "x": -1,
      "y": 9,
      "z": 8,
      "name": "Wood_Tropicalwood_Roof_Flat",
      "rotation": 2
    },
    {
      "x": -1,
      "y": 4,
      "z": 9,
      "name": "Furniture_Crude_Platform",
      "rotation": 1
    },
    {
      "x": -1,
      "y": 5,
      "z": 9,
      "name": "Wood_Hardwood_Fence"
    },
    {
      "x": -1,
      "y": 8,
      "z": 9,
      "name": "Wood_Tropicalwood_Roof_Hollow"
    },
    {
      "x": 0,
      "y": 4,
      "z": -9,
      "name": "Furniture_Crude_Platform",
      "rotation": 1
    },
    {
      "x": 0,
      "y": 5,
      "z": -9,
      "name": "Wood_Hardwood_Fence",
      "rotation": 2
    },
    {
      "x": 0,
      "y": 8,
      "z": -9,
      "name": "Wood_Tropicalwood_Roof_Hollow",
      "rotation": 2
    },
    {
      "x": 0,
      "y": 4,
      "z": -8,
      "name": "Furniture_Crude_Platform"
    },
    {
      "x": 0,
      "y": 8,
      "z": -8,
      "name": "Wood_Goldenwood_Planks_Half",
      "rotation": 8
    },
    {
      "x": 0,
      "y": 9,
      "z": -8,
      "name": "Wood_Tropicalwood_Roof_Flat",
      "rotation": 2
    },
    {
      "x": 0,
      "y": 0,
      "z": -7,
      "name": "Furniture_Crude_Platform"
    },
    {
      "x": 0,
      "y": 2,
      "z": -7,
      "name": "Wood_Goldenwood_Fence",
      "rotation": 2
    },
    {
      "x": 0,
      "y": 3,
      "z": -7,
      "name": "Wood_Softwood_Fence",
      "rotation": 2
    },
    {
      "x": 0,
      "y": 4,
      "z": -7,
      "name": "Wood_Goldenwood_Stairs",
      "rotation": 8
    },
    {
      "x": 0,
      "y": 5,
      "z": -7,
      "name": "Wood_Softwood_Fence",
      "rotation": 2
    },
    {
      "x": 0,
      "y": 6,
      "z": -7,
      "name": "Wood_Goldenwood_Fence",
      "rotation": 2
    },
    {
      "x": 0,
      "y": 7,
      "z": -7,
      "name": "Wood_Softwood_Fence",
      "rotation": 2
    },
    {
      "x": 0,
      "y": 8,
      "z": -7,
      "name": "Wood_Goldenwood_Stairs",
      "rotation": 8
    },
    {
      "x": 0,
      "y": 9,
      "z": -7,
      "name": "Wood_Hardwood_Fence",
      "rotation": 2
    },
    {
      "x": 0,
      "y": 12,
      "z": -7,
      "name": "Wood_Tropicalwood_Roof_Hollow",
      "rotation": 2
    },
    {
      "x": 0,
      "y": 0,
      "z": -6,
      "name": "Wood_Goldenwood_Planks_Half",
      "rotation": 8
    },
    {
      "x": 0,
      "y": 1,
      "z": -6,
      "name": "Furniture_Ancient_Bed",
      "filler": 993,
      "rotation": 1
    },
    {
      "x": 0,
      "y": 2,
      "z": -6,
      "name": "Furniture_Ancient_Bed",
      "filler": 2017,
      "rotation": 1
    },
    {
      "x": 0,
      "y": 4,
      "z": -6,
      "name": "Wood_Goldenwood_Planks_Half",
      "rotation": 8
    },
    {
      "x": 0,
      "y": 8,
      "z": -6,
      "name": "Wood_Goldenwood_Planks_Half",
      "rotation": 8
    },
    {
      "x": 0,
      "y": 13,
      "z": -6,
      "name": "Wood_Tropicalwood_Roof_Flat"
    },
    {
      "x": 0,
      "y": 0,
      "z": -5,
      "name": "Wood_Goldenwood_Planks_Half",
      "rotation": 8
    },
    {
      "x": 0,
      "y": 1,
      "z": -5,
      "name": "Furniture_Ancient_Bed",
      "filler": 1,
      "rotation": 1
    },
    {
      "x": 0,
      "y": 2,
      "z": -5,
      "name": "Furniture_Ancient_Bed",
      "filler": 1025,
      "rotation": 1
    },
    {
      "x": 0,
      "y": 4,
      "z": -5,
      "name": "Wood_Goldenwood_Planks_Half",
      "rotation": 8
    },
    {
      "x": 0,
      "y": 8,
      "z": -5,
      "name": "Wood_Goldenwood_Planks_Half",
      "rotation": 8
    },
    {
      "x": 0,
