{
  "version": 8,
  "blockIdVersion": 11,
  "anchorX": 0,
  "anchorY": 0,
  "anchorZ": 0,
  "blocks": [
    {
      "x": -3,
      "y": 0,
      "z": 0,
      "name": "Rock_Shale_Cobble"
    },
    {
      "x": -3,
      "y": 2,
      "z": 0,
      "name": "Plant_Moss_Wall_Green_Dark",
      "support": 15,
      "rotation": 3
    },
    {
      "x": -3,
      "y": 1,
      "z": 1,
      "name": "Plant_Moss_Wall_Green_Dark",
      "support": 15,
      "rotation": 3
    },
    {
      "x": -2,
      "y": 2,
      "z": -2,
      "name": "Metal_Iron_Glowing_Pipe_Corner",
      "support": 15,
      "rotation": 25
    },
    {
      "x": -2,
      "y": 2,
      "z": -1,
      "name": "Metal_Iron_Glowing_Pipe_Corner",
      "support": 15
    },
    {
      "x": -2,
      "y": 3,
      "z": -1,
      "name": "Metal_Iron_Glowing_Pipe",
      "support": 15
    },
    {
      "x": -2,
      "y": 4,
      "z": -1,
      "name": "Metal_Iron_Glowing_Pipe_Corner",
      "support": 15,
      "rotation": 14
    },
    {
      "x": -2,
      "y": 0,
      "z": 0,
      "name": "Rock_Shale_Cobble"
    },
    {
      "x": -2,
      "y": 1,
      "z": 0,
      "name": "Rock_Shale_Cobble"
    },
    {
      "x": -2,
      "y": 2,
      "z": 0,
      "name": "Rock_Shale_Cobble"
    },
    {
      "x": -2,
      "y": 3,
      "z": 0,
      "name": "Plant_Moss_Rug_Green_Dark",
      "support": 15
    },
    {
      "x": -2,
      "y": 4,
      "z": 0,
      "name": "Metal_Iron_Glowing_Pipe_Corner",
      "support": 15
    },
    {
      "x": -2,
      "y": 5,
      "z": 0,
      "name": "Metal_Iron_Glowing_Pipe",
      "support": 15
    },
    {
      "x": -2,
      "y": 6,
      "z": 0,
      "name": "Metal_Iron_Glowing_Pipe_Corner",
      "support": 15,
      "rotation": 15
    },
    {
      "x": -2,
      "y": 0,
      "z": 1,
      "name": "Rock_Shale_Cobble"
    },
    {
      "x": -2,
      "y": 1,
      "z": 1,
      "name": "Rock_Shale_Cobble"
    },
    {
      "x": -2,
      "y": 2,
      "z": 1,
      "name": "Plant_Moss_Rug_Green_Dark",
      "support": 15
    },
    {
      "x": -2,
      "y": 0,
      "z": 2,
      "name": "Rock_Shale_Cobble"
    },
    {
      "x": -2,
      "y": 1,
      "z": 2,
      "name": "Plant_Moss_Rug_Green_Dark",
      "support": 15
    },
    {
      "x": -2,
      "y": 0,
      "z": 3,
      "name": "Plant_Moss_Wall_Green_Dark",
      "support": 15
    },
    {
      "x": -1,
      "y": 0,
      "z": -2,
      "name": "Metal_Iron_Glowing_Pipe",
      "support": 15
    },
    {
      "x": -1,
      "y": 1,
      "z": -2,
      "name": "Metal_Iron_Glowing_Pipe",
      "support": 15
    },
    {
      "x": -1,
      "y": 2,
      "z": -2,
      "name": "Metal_Iron_Glowing_Pipe_Corner",
      "support": 15,
      "rotation": 13
    },
    {
      "x": -1,
      "y": 3,
      "z": -2,
      "name": "Plant_Moss_Wall_Green_Dark",
      "support": 15,
      "rotation": 2
    },
    {
      "x": -1,
      "y": 0,
      "z": -1,
      "name": "Rock_Shale_Cobble"
    },
    {
      "x": -1,
      "y": 1,
      "z": -1,
      "name": "Rock_Shale_Cobble"
    },
    {
      "x": -1,
      "y": 2,
      "z": -1,
      "name": "Rock_Shale_Cobble"
    },
    {
      "x": -1,
      "y": 3,
      "z": -1,
      "name": "Rock_Shale_Cobble"
    },
    {
      "x": -1,
      "y": 4,
      "z": -1,
      "name": "Plant_Moss_Rug_Green_Dark",
      "support": 15
    },
    {
      "x": -1,
      "y": 0,
      "z": 0,
      "name": "Rock_Shale_Cobble"
    },
    {
      "x": -1,
      "y": 1,
      "z": 0,
      "name": "Rock_Shale_Cobble"
    },
    {
      "x": -1,
      "y": 2,
      "z": 0,
      "name": "Rock_Shale_Cobble"
    },
    {
      "x": -1,
      "y": 3,
      "z": 0,
      "name": "Rock_Shale_Cobble"
    },
    {
      "x": -1,
      "y": 4,
      "z": 0,
      "name": "Rock_Shale_Cobble"
    },
    {
      "x": -1,
      "y": 5,
      "z": 0,
      "name": "Rock_Shale_Cobble"
    },
    {
      "x": -1,
      "y": 6,
      "z": 0,
      "name": "Metal_Iron_Glowing_Pipe_Corner",
      "support": 15,
      "rotation": 13
    },
    {
      "x": -1,
      "y": 8,
      "z": 0,
      "name": "Plant_Moss_Wall_Green_Dark",
      "support": 15,
      "rotation": 3
    },
    {
      "x": -1,
      "y": 0,
      "z": 1,
      "name": "Rock_Shale_Cobble"
    },
    {
      "x": -1,
      "y": 1,
      "z": 1,
      "name": "Rock_Shale_Cobble"
    },
    {
      "x": -1,
      "y": 2,
      "z": 1,
      "name": "Build_Lightsource_Cyan"
    },
    {
      "x": -1,
      "y": 3,
      "z": 1,
      "name": "Build_Lightsource_Cyan"
    },
    {
      "x": -1,
      "y": 4,
      "z": 1,
      "name": "Build_Lightsource_Cyan"
    },
    {
      "x": -1,
      "y": 0,
      "z": 2,
      "name": "Rock_Shale_Cobble"
    },
    {
      "x": -1,
      "y": 1,
      "z": 2,
      "name": "Rock_Shale_Cobble"
    },
    {
      "x": -1,
      "y": 2,
      "z": 2,
      "name": "Plant_Moss_Rug_Green_Dark",
      "support": 15
    },
    {
      "x": 0,
      "y": 0,
      "z": -3,
      "name": "Plant_Moss_Wall_Green_Dark",
      "support": 15,
      "rotation": 2
    },
    {
      "x": 0,
      "y": 1,
      "z": -3,
      "name": "Plant_Moss_Wall_Green_Dark",
      "support": 15,
      "rotation": 2
    },
    {
      "x": 0,
      "y": 0,
      "z": -2,
      "name": "Rock_Shale_Cobble"
    },
    {
      "x": 0,
      "y": 1,
      "z": -2,
      "name": "Rock_Shale_Cobble"
    },
    {
      "x": 0,
      "y": 2,
      "z": -2,
      "name": "Plant_Moss_Rug_Green_Dark",
      "support": 15
    },
    {
      "x": 0,
      "y": 0,
      "z": -1,
      "name": "Rock_Shale_Cobble"
    },
    {
      "x": 0,
      "y": 1,
      "z": -1,
      "name": "Rock_Shale_Cobble"
    },
    {
      "x": 0,
      "y": 2,
      "z": -1,
      "name": "Build_Lightsource_Cyan",
      "rotation": 4
    },
    {
      "x": 0,
      "y": 3,
      "z": -1,
      "name": "Build_Lightsource_Cyan"
    },
    {
      "x": 0,
      "y": 4,
      "z": -1,
      "name": "Build_Lightsource_Cyan"
    },
    {
      "x": 0,
      "y": 5,
      "z": -1,
      "name": "Rock_Shale_Cobble"
    },
    {
      "x": 0,
      "y": 6,
      "z": -1,
      "name": "Plant_Moss_Rug_Green_Dark",
      "support": 15
    },
    {
      "x": 0,
      "y": 8,
      "z": -1,
      "name": "Plant_Moss_Wall_Green_Dark",
      "support": 15,
      "rotation": 2
    },
    {
      "x": 0,
      "y": 0,
      "z": 0,
      "name": "Rock_Shale_Cobble"
    },
    {
      "x": 0,
      "y": 1,
      "z": 0,
      "name": "Rock_Shale_Cobble"
    },
    {
      "x": 0,
      "y": 2,
      "z": 0,
      "name": "Rock_Shale_Cobble"
    },
    {
      "x": 0,
      "y": 3,
      "z": 0,
      "name": "Rock_Shale_Cobble"
    },
    {
      "x": 0,
      "y": 4,
      "z": 0,
      "name": "Rock_Shale_Cobble"
    },
    {
      "x": 0,
      "y": 5,
      "z": 0,
      "name": "Rock_Shale_Cobble"
    },
    {
      "x": 0,
      "y": 6,
      "z": 0,
      "name": "Rock_Shale_Cobble"
    },
    {
      "x": 0,
      "y": 7,
      "z": 0,
      "name": "Rock_Shale_Cobble"
    },
    {
      "x": 0,
      "y": 8,
      "z": 0,
      "name": "Rock_Shale_Cobble"
    },
    {
      "x": 0,
      "y": 9,
      "z": 0,
      "name": "Plant_Moss_Rug_Green_Dark",
      "support": 15
    },
    {
      "x": 0,
      "y": 0,
      "z": 1,
      "name": "Rock_Shale_Cobble"
    },
    {
      "x": 0,
      "y": 1,
      "z": 1,
      "name": "Rock_Shale_Cobble"
    },
    {
      "x": 0,
      "y": 2,
      "z": 1,
      "name": "Rock_Shale_Cobble"
    },
    {
      "x": 0,
      "y": 0,
      "z": 2,
      "name": "Metal_Iron_Glowing_Pipe",
      "support": 15
    },
    {
      "x": 0,
      "y": 1,
      "z": 2,
      "name": "Metal_Iron_Glowing_Pipe_Corner",
      "support": 15,
      "rotation": 15
    },
    {
      "x": 1,
      "y": 0,
      "z": -3,
      "name": "Plant_Moss_Wall_Green_Dark",
      "support": 15,
      "rotation": 2
    },
    {
      "x": 1,
      "y": 0,
      "z": -2,
      "name": "Rock_Shale_Cobble"
    },
    {
      "x": 1,
      "y": 1,
      "z": -2,
      "name": "Plant_Moss_Rug_Green_Dark",
      "support": 15
    },
    {
      "x": 1,
      "y": 0,
      "z": -1,
      "name": "Rock_Shale_Cobble"
    },
    {
      "x": 1,
      "y": 1,
      "z": -1,
      "name": "Rock_Shale_Cobble"
    },
    {
      "x": 1,
      "y": 2,
      "z": -1,
      "name": "Rock_Shale_Cobble"
    },
    {
      "x": 1,
      "y": 3,
      "z": -1,
      "name": "Rock_Shale_Cobble"
    },
    {
      "x": 1,
      "y": 4,
      "z": -1,
      "name": "Rock_Shale_Cobble"
    },
    {
      "x": 1,
      "y": 0,
      "z": 0,
      "name": "Rock_Shale_Cobble"
    },
    {
      "x": 1,
      "y": 1,
      "z": 0,
      "name": "Rock_Shale_Cobble"
    },
    {
      "x": 1,
      "y": 2,
      "z": 0,
      "name": "Rock_Shale_Cobble"
    },
    {
      "x": 1,
      "y": 3,
      "z": 0,
      "name": "Rock_Shale_Cobble"
    },
    {
      "x": 1,
      "y": 4,
      "z": 0,
      "name": "Build_Lightsource_Cyan"
    },
    {
      "x": 1,
      "y": 5,
      "z": 0,
      "name": "Build_Lightsource_Cyan"
    },
    {
      "x": 1,
      "y": 6,
      "z": 0,
      "name": "Rock_Shale_Cobble"
    },
    {
      "x": 1,
      "y": 7,
      "z": 0,
      "name": "Plant_Moss_Rug_Green_Dark",
      "support": 15
    },
    {
      "x": 1,
      "y": 0,
      "z": 1,
      "name": "Rock_Shale_Cobble"
    },
    {
      "x": 1,
      "y": 1,
      "z": 1,
      "name": "Metal_Iron_Glowing_Pipe_Corner",
      "support": 15,
      "rotation": 2
    },
    {
      "x": 1,
      "y": 2,
      "z": 1,
      "name": "Metal_Iron_Glowing_Pipe_Corner",
      "support": 15,
      "rotation": 13
    },
    {
      "x": 1,
      "y": 1,
      "z": 2,
      "name": "Metal_Iron_Glowing_Pipe_Corner",
      "support": 15,
      "rotation": 27
    },
    {
      "x": 2,
      "y": 0,
      "z": -1,
      "name": "Rock_Shale_Cobble"
    },
    {
      "x": 2,
      "y": 1,
      "z": -1,
      "name": "Rock_Shale_Cobble"
    },
    {
      "x": 2,
      "y": 2,
      "z": -1,
      "name": "Rock_Shale_Cobble"
    },
    {
      "x": 2,
      "y": 3,
      "z": -1,
      "name": "Metal_Iron_Glowing_Pipe_Corner",
      "support": 15,
      "rotation": 3
    },
    {
      "x": 2,
      "y": 4,
      "z": -1,
      "name": "Metal_Iron_Glowing_Pipe",
      "support": 15
    },
    {
      "x": 2,
      "y": 5,
      "z": -1,
      "name": "Metal_Iron_Glowing_Pipe_Corner",
      "support": 15,
      "rotation": 14
    },
    {
      "x": 2,
      "y": 0,
      "z": 0,
      "name": "Build_Lightsource_Cyan"
    },
    {
      "x": 2,
      "y": 1,
      "z": 0,
      "name": "Build_Lightsource_Cyan"
    },
    {
      "x": 2,
      "y": 2,
      "z": 0,
      "name": "Build_Lightsource_Cyan"
    },
    {
      "x": 2,
      "y": 3,
      "z": 0,
      "name": "Rock_Shale_Cobble"
    },
    {
      "x": 2,
      "y": 4,
      "z": 0,
      "name": "Plant_Moss_Rug_Green_Dark",
      "support": 15
    },
    {
      "x": 2,
      "y": 5,
      "z": 0,
      "name": "Metal_Iron_Glowing_Pipe_Corner",
      "support": 15
    },
    {
      "x": 2,
      "y": 6,
      "z": 0,
      "name": "Metal_Iron_Glowing_Pipe_Corner",
      "support": 15,
      "rotation": 13
    },
    {
      "x": 2,
      "y": 2,
      "z": 1,
      "name": "Plant_Moss_Wall_Green_Dark",
      "support": 15
    },
    {
      "x": 2,
      "y": 3,
      "z": 1,
      "name": "Plant_Moss_Wall_Green_Dark",
      "support": 15
    },
    {
      "x": 3,
      "y": 0,
      "z": -1,
      "name": "Rock_Shale_Cobble"
    },
    {
      "x": 3,
      "y": 1,
      "z": -1,
      "name": "Rock_Shale_Cobble"
    },
    {
      "x": 3,
      "y": 2,
      "z": -1,
      "name": "Metal_Iron_Glowing_Pipe_Corner",
      "support": 15,
      "rotation": 2
    },
    {
      "x": 3,
      "y": 3,
      "z": -1,
      "name": "Metal_Iron_Glowing_Pipe_Corner",
      "support": 15,
      "rotation": 13
    },
    {
      "x": 3,
      "y": 0,
      "z": 0,
      "name": "Rock_Shale_Cobble"
    },
    {
      "x": 3,
      "y": 1,
      "z": 0,
      "name": "Metal_Iron_Glowing_Pipe",
      "support": 15
    },
    {
      "x": 3,
      "y": 2,
      "z": 0,
      "name": "Metal_Iron_Glowing_Pipe_Corner",
      "support": 15,
      "rotation": 12
    },
    {
      "x": 3,
      "y": 3,
      "z": 0,
      "name": "Plant_Moss_Wall_Green_Dark",
      "support": 15,
      "rotation": 1
    },
    {
      "x": 4,
      "y": 1,
      "z": -1,
      "name": "Plant_Moss_Wall_Green_Dark",
      "support": 15,
      "rotation": 1
    }
  ],
  "fluids": [
    {
      "x": -3,
      "y": 0,
      "z": 0,
      "name": "Empty",
      "level": 0
    },
    {
      "x": -3,
      "y": 2,
      "z": 0,
      "name": "Empty",
      "level": 0
    },
    {
      "x": -3,
      "y": 1,
      "z": 1,
      "name": "Empty",
      "level": 0
    },
    {
      "x": -2,
      "y": 2,
      "z": -2,
      "name": "Empty",
      "level": 0
    },
    {
      "x": -2,
      "y": 2,
      "z": -1,
      "name": "Empty",
      "level": 0
    },
    {
      "x": -2,
      "y": 3,
      "z": -1,
      "name": "Empty",
      "level": 0
    },
    {
      "x": -2,
      "y": 4,
      "z": -1,
      "name": "Empty",
      "level": 0
    },
    {
      "x": -2,
      "y": 0,
      "z": 0,
      "name": "Empty",
      "level": 0
    },
    {
      "x": -2,
      "y": 1,
      "z": 0,
      "name": "Empty",
      "level": 0
    },
    {
      "x": -2,
      "y": 2,
      "z": 0,
      "name": "Empty",
      "level": 0
    },
    {
      "x": -2,
      "y": 3,
      "z": 0,
      "name": "Empty",
      "level": 0
    },
    {
      "x": -2,
      "y": 4,
      "z": 0,
      "name": "Empty",
      "level": 0
    },
    {
      "x": -2,
      "y": 5,
      "z": 0,
      "name": "Empty",
      "level": 0
    },
    {
      "x": -2,
      "y": 6,
      "z": 0,
      "name": "Empty",
      "level": 0
    },
    {
      "x": -2,
      "y": 0,
      "z": 1,
      "name": "Empty",
      "level": 0
    },
    {
      "x": -2,
      "y": 1,
      "z": 1,
      "name": "Empty",
      "level": 0
    },
    {
      "x": -2,
      "y": 2,
      "z": 1,
      "name": "Empty",
      "level": 0
    },
    {
      "x": -2,
      "y": 0,
      "z": 2,
      "name": "Empty",
      "level": 0
    },
    {
      "x": -2,
      "y": 1,
      "z": 2,
      "name": "Empty",
      "level": 0
    },
    {
      "x": -2,
      "y": 0,
      "z": 3,
      "name": "Empty",
      "level": 0
    },
    {
      "x": -1,
      "y": 0,
      "z": -2,
      "name": "Empty",
      "level": 0
    },
    {
      "x": -1,
      "y": 1,
      "z": -2,
      "name": "Empty",
      "level": 0
    },
    {
      "x": -1,
      "y": 2,
      "z": -2,
      "name": "Empty",
      "level": 0
    },
    {
      "x": -1,
      "y": 3,
      "z": -2,
      "name": "Empty",
      "level": 0
    },
    {
      "x": -1,
      "y": 0,
      "z": -1,
      "name": "Empty",
      "level": 0
    },
    {
      "x": -1,
      "y": 1,
      "z": -1,
      "name": "Empty",
      "level": 0
    },
    {
      "x": -1,
      "y": 2,
      "z": -1,
      "name": "Empty",
      "level": 0
    },
    {
      "x": -1,
      "y": 3,
      "z": -1,
      "name": "Empty",
      "level": 0
    },
    {
      "x": -1,
      "y": 4,
      "z": -1,
      "name": "Empty",
      "level": 0
    },
    {
      "x": -1,
      "y": 0,
      "z": 0,
      "name": "Empty",
      "level": 0
    },
    {
      "x": -1,
      "y": 1,
      "z": 0,
      "name": "Empty",
      "level": 0
    },
    {
      "x": -1,
      "y": 2,
      "z": 0,
      "name": "Empty",
      "level": 0
    },
    {
      "x": -1,
      "y": 3,
      "z": 0,
      "name": "Empty",
      "level": 0
    },
    {
      "x": -1,
      "y": 4,
      "z": 0,
      "name": "Empty",
      "level": 0
    },
    {
      "x": -1,
      "y": 5,
      "z": 0,
      "name": "Empty",
      "level": 0
    },
    {
      "x": -1,
      "y": 6,
      "z": 0,
      "name": "Empty",
      "level": 0
    },
    {
      "x": -1,
      "y": 8,
      "z": 0,
      "name": "Empty",
      "level": 0
    },
    {
      "x": -1,
      "y": 0,
      "z": 1,
      "name": "Empty",
      "level": 0
    },
    {
      "x": -1,
      "y": 1,
      "z": 1,
      "name": "Empty",
      "level": 0
    },
    {
      "x": -1,
      "y": 2,
      "z": 1,
      "name": "Empty",
      "level": 0
    },
    {
      "x": -1,
      "y": 3,
      "z": 1,
      "name": "Empty",
      "level": 0
    },
    {
      "x": -1,
      "y": 4,
      "z": 1,
      "name": "Empty",
      "level": 0
    },
    {
      "x": -1,
      "y": 0,
      "z": 2,
      "name": "Empty",
      "level": 0
    },
    {
      "x": -1,
      "y": 1,
      "z": 2,
      "name": "Empty",
      "level": 0
    },
    {
      "x": -1,
      "y": 2,
      "z": 2,
      "name": "Empty",
      "level": 0
    },
    {
      "x": 0,
      "y": 0,
      "z": -3,
      "name": "Empty",
      "level": 0
    },
    {
      "x": 0,
      "y": 1,
      "z": -3,
      "name": "Empty",
      "level": 0
    },
    {
      "x": 0,
      "y": 0,
      "z": -2,
      "name": "Empty",
      "level": 0
    },
    {
      "x": 0,
      "y": 1,
      "z": -2,
      "name": "Empty",
      "level": 0
    },
    {
      "x": 0,
      "y": 2,
      "z": -2,
      "name": "Empty",
      "level": 0
    },
    {
      "x": 0,
      "y": 0,
      "z": -1,
      "name": "Empty",
      "level": 0
    },
    {
      "x": 0,
      "y": 1,
      "z": -1,
      "name": "Empty",
      "level": 0
    },
    {
      "x": 0,
      "y": 2,
      "z": -1,
      "name": "Empty",
      "level": 0
    },
    {
      "x": 0,
      "y": 3,
      "z": -1,
      "name": "Empty",
      "level": 0
    },
    {
      "x": 0,
      "y": 4,
      "z": -1,
      "name": "Empty",
      "level": 0
    },
    {
      "x": 0,
      "y": 5,
      "z": -1,
      "name": "Empty",
      "level": 0
    },
    {
      "x": 0,
      "y": 6,
      "z": -1,
      "name": "Empty",
      "level": 0
    },
    {
      "x": 0,
      "y": 8,
      "z": -1,
      "name": "Empty",
      "level": 0
    },
    {
      "x": 0,
      "y": 0,
      "z": 0,
      "name": "Empty",
      "level": 0
    },
    {
      "x": 0,
      "y": 1,
      "z": 0,
      "name": "Empty",
      "level": 0
    },
    {
      "x": 0,
      "y": 2,
      "z": 0,
      "name": "Empty",
      "level": 0
    },
    {
      "x": 0,
      "y": 3,
      "z": 0,
      "name": "Empty",
      "level": 0
    },
    {
      "x": 0,
      "y": 4,
      "z": 0,
      "name": "Empty",
      "level": 0
    },
    {
      "x": 0,
      "y": 5,
      "z": 0,
      "name": "Empty",
      "level": 0
    },
    {
      "x": 0,
      "y": 6,
      "z": 0,
      "name": "Empty",
      "level": 0
    },
    {
      "x": 0,
      "y": 7,
      "z": 0,
      "name": "Empty",
      "level": 0
    },
    {
      "x": 0,
      "y": 8,
      "z": 0,
      "name": "Empty",
      "level": 0
    },
    {
      "x": 0,
      "y": 9,
      "z": 0,
      "name": "Empty",
      "level": 0
    },
    {
      "x": 0,
      "y": 0,
      "z": 1,
      "name": "Empty",
      "level": 0
    },
    {
      "x": 0,
      "y": 1,
      "z": 1,
      "name": "Empty",
      "level": 0
    },
    {
      "x": 0,
      "y": 2,
      "z": 1,
      "name": "Empty",
      "level": 0
    },
    {
      "x": 0,
      "y": 0,
      "z": 2,
      "name": "Empty",
      "level": 0
    },
    {
      "x": 0,
      "y": 1,
      "z": 2,
      "name": "Empty",
      "level": 0
    },
    {
      "x": 1,
      "y": 0,
      "z": -3,
      "name": "Empty",
      "level": 0
    },
    {
      "x": 1,
      "y": 0,
      "z": -2,
      "name": "Empty",
      "level": 0
    },
    {
      "x": 1,
      "y": 1,
      "z": -2,
      "name": "Empty",
      "level": 0
    },
    {
      "x": 1,
      "y": 0,
      "z": -1,
      "name": "Empty",
      "level": 0
    },
    {
      "x": 1,
      "y": 1,
      "z": -1,
      "name": "Empty",
      "level": 0
    },
    {
      "x": 1,
      "y": 2,
      "z": -1,
      "name": "Empty",
      "level": 0
    },
    {
      "x": 1,
      "y": 3,
      "z": -1,
      "name": "Empty",
      "level": 0
    },
    {
      "x": 1,
      "y": 4,
      "z": -1,
      "name": "Empty",
      "level": 0
    },
    {
      "x": 1,
      "y": 0,
      "z": 0,
      "name": "Empty",
      "level": 0
    },
    {
      "x": 1,
      "y": 1,
      "z": 0,
      "name": "Empty",
      "level": 0
    },
    {
      "x": 1,
      "y": 2,
      "z": 0,
      "name": "Empty",
      "level": 0
    },
    {
      "x": 1,
      "y": 3,
      "z": 0,
      "name": "Empty",
      "level": 0
    },
    {
      "x": 1,
      "y": 4,
      "z": 0,
      "name": "Empty",
      "level": 0
    },
    {
      "x": 1,
      "y": 5,
      "z": 0,
      "name": "Empty",
      "level": 0
    },
    {
      "x": 1,
      "y": 6,
      "z": 0,
      "name": "Empty",
      "level": 0
    },
    {
      "x": 1,
      "y": 7,
      "z": 0,
      "name": "Empty",
      "level": 0
    },
    {
      "x": 1,
      "y": 0,
      "z": 1,
      "name": "Empty",
      "level": 0
    },
    {
      "x": 1,
      "y": 1,
      "z": 1,
      "name": "Empty",
      "level": 0
    },
    {
      "x": 1,
      "y": 2,
      "z": 1,
      "name": "Empty",
      "level": 0
    },
    {
      "x": 1,
      "y": 1,
      "z": 2,
      "name": "Empty",
      "level": 0
    },
    {
      "x": 2,
      "y": 0,
      "z": -1,
      "name": "Empty",
      "level": 0
    },
    {
      "x": 2,
      "y": 1,
      "z": -1,
      "name": "Empty",
      "level": 0
    },
    {
      "x": 2,
      "y": 2,
      "z": -1,
      "name": "Empty",
      "level": 0
    },
    {
      "x": 2,
      "y": 3,
      "z": -1,
      "name": "Empty",
      "level": 0
    },
    {
      "x": 2,
      "y": 4,
      "z": -1,
      "name": "Empty",
      "level": 0
    },
    {
      "x": 2,
      "y": 5,
      "z": -1,
      "name": "Empty",
      "level": 0
    },
    {
      "x": 2,
      "y": 0,
      "z": 0,
      "name": "Empty",
      "level": 0
    },
    {
      "x": 2,
      "y": 1,
      "z": 0,
      "name": "Empty",
      "level": 0
    },
    {
      "x": 2,
      "y": 2,
      "z": 0,
      "name": "Empty",
      "level": 0
    },
    {
      "x": 2,
      "y": 3,
      "z": 0,
      "name": "Empty",
      "level": 0
    },
    {
      "x": 2,
      "y": 4,
      "z": 0,
      "name": "Empty",
      "level": 0
    },
    {
      "x": 2,
      "y": 5,
      "z": 0,
      "name": "Empty",
      "level": 0
    },
    {
      "x": 2,
      "y": 6,
      "z": 0,
      "name": "Empty",
      "level": 0
    },
    {
      "x": 2,
      "y": 2,
      "z": 1,
      "name": "Empty",
      "level": 0
    },
    {
      "x": 2,
      "y": 3,
      "z": 1,
      "name": "Empty",
      "level": 0
    },
    {
      "x": 3,
      "y": 0,
      "z": -1,
      "name": "Empty",
      "level": 0
    },
    {
      "x": 3,
      "y": 1,
      "z": -1,
      "name": "Empty",
      "level": 0
    },
    {
      "x": 3,
      "y": 2,
      "z": -1,
      "name": "Empty",
      "level": 0
    },
    {
      "x": 3,
      "y": 3,
      "z": -1,
      "name": "Empty",
      "level": 0
    },
    {
      "x": 3,
      "y": 0,
      "z": 0,
      "name": "Empty",
      "level": 0
    },
    {
      "x": 3,
      "y": 1,
      "z": 0,
      "name": "Empty",
      "level": 0
    },
    {
      "x": 3,
      "y": 2,
      "z": 0,
      "name": "Empty",
      "level": 0
    },
    {
      "x": 3,
      "y": 3,
      "z": 0,
      "name": "Empty",
      "level": 0
    },
    {
      "x": 4,
      "y": 1,
      "z": -1,
      "name": "Empty",
      "level": 0
    }
  ]
}