{
  "version": 8,
  "blockIdVersion": 11,
  "anchorX": 0,
  "anchorY": 0,
  "anchorZ": 0,
  "blocks": [
    {
      "x": -11,
      "y": 1,
      "z": 1,
      "name": "Rock_Quartzite"
    },
    {
      "x": -11,
      "y": 2,
      "z": 1,
      "name": "Rock_Quartzite"
    },
    {
      "x": -10,
      "y": 0,
      "z": -2,
      "name": "Rock_Stone"
    },
    {
      "x": -10,
      "y": 1,
      "z": -2,
      "name": "Rock_Stone"
    },
    {
      "x": -10,
      "y": 2,
      "z": -2,
      "name": "Rock_Stone"
    },
    {
      "x": -10,
      "y": 3,
      "z": -2,
      "name": "Rock_Stone"
    },
    {
      "x": -10,
      "y": 4,
      "z": -2,
      "name": "Rock_Stone"
    },
    {
      "x": -10,
      "y": 0,
      "z": -1,
      "name": "Rock_Stone"
    },
    {
      "x": -10,
      "y": 1,
      "z": -1,
      "name": "Rock_Stone"
    },
    {
      "x": -10,
      "y": 2,
      "z": -1,
      "name": "Rock_Stone"
    },
    {
      "x": -10,
      "y": 3,
      "z": -1,
      "name": "Rock_Stone"
    },
    {
      "x": -10,
      "y": 4,
      "z": -1,
      "name": "Rock_Stone"
    },
    {
      "x": -10,
      "y": 5,
      "z": -1,
      "name": "Rock_Stone"
    },
    {
      "x": -10,
      "y": 6,
      "z": -1,
      "name": "Rock_Stone"
    },
    {
      "x": -10,
      "y": 7,
      "z": -1,
      "name": "Rock_Stone"
    },
    {
      "x": -10,
      "y": 0,
      "z": 0,
      "name": "Rock_Stone"
    },
    {
      "x": -10,
      "y": 1,
      "z": 0,
      "name": "Rock_Stone"
    },
    {
      "x": -10,
      "y": 2,
      "z": 0,
      "name": "Rock_Quartzite"
    },
    {
      "x": -10,
      "y": 3,
      "z": 0,
      "name": "Rock_Quartzite"
    },
    {
      "x": -10,
      "y": 4,
      "z": 0,
      "name": "Rock_Quartzite"
    },
    {
      "x": -10,
      "y": 5,
      "z": 0,
      "name": "Rock_Quartzite"
    },
    {
      "x": -10,
      "y": 6,
      "z": 0,
      "name": "Rock_Quartzite"
    },
    {
      "x": -10,
      "y": 7,
      "z": 0,
      "name": "Rock_Quartzite"
    },
    {
      "x": -10,
      "y": 8,
      "z": 0,
      "name": "Rock_Quartzite"
    },
    {
      "x": -10,
      "y": 9,
      "z": 0,
      "name": "Rock_Quartzite"
    },
    {
      "x": -10,
      "y": 10,
      "z": 0,
      "name": "Rock_Quartzite"
    },
    {
      "x": -10,
      "y": 11,
      "z": 0,
      "name": "Rock_Quartzite"
    },
    {
      "x": -10,
      "y": 0,
      "z": 1,
      "name": "Rock_Quartzite"
    },
    {
      "x": -10,
      "y": 1,
      "z": 1,
      "name": "Rock_Quartzite"
    },
    {
      "x": -10,
      "y": 2,
      "z": 1,
      "name": "Rock_Quartzite"
    },
    {
      "x": -10,
      "y": 3,
      "z": 1,
      "name": "Rock_Quartzite"
    },
    {
      "x": -10,
      "y": 4,
      "z": 1,
      "name": "Rock_Quartzite"
    },
    {
      "x": -10,
      "y": 5,
      "z": 1,
      "name": "Rock_Quartzite"
    },
    {
      "x": -10,
      "y": 6,
      "z": 1,
      "name": "Rock_Quartzite"
    },
    {
      "x": -10,
      "y": 7,
      "z": 1,
      "name": "Rock_Quartzite"
    },
    {
      "x": -10,
      "y": 8,
      "z": 1,
      "name": "Rock_Quartzite"
    },
    {
      "x": -10,
      "y": 9,
      "z": 1,
      "name": "Rock_Quartzite"
    },
    {
      "x": -10,
      "y": 10,
      "z": 1,
      "name": "Rock_Quartzite"
    },
    {
      "x": -10,
      "y": 0,
      "z": 2,
      "name": "Rock_Quartzite"
    },
    {
      "x": -10,
      "y": 1,
      "z": 2,
      "name": "Rock_Quartzite"
    },
    {
      "x": -10,
      "y": 2,
      "z": 2,
      "name": "Rock_Quartzite"
    },
    {
      "x": -10,
      "y": 3,
      "z": 2,
      "name": "Rock_Quartzite"
    },
    {
      "x": -10,
      "y": 4,
      "z": 2,
      "name": "Rock_Quartzite"
    },
    {
      "x": -10,
      "y": 5,
      "z": 2,
      "name": "Rock_Quartzite"
    },
    {
      "x": -10,
      "y": 6,
      "z": 2,
      "name": "Rock_Quartzite"
    },
    {
      "x": -10,
      "y": 7,
      "z": 2,
      "name": "Rock_Quartzite"
    },
    {
      "x": -10,
      "y": 8,
      "z": 2,
      "name": "Rock_Quartzite"
    },
    {
      "x": -10,
      "y": 9,
      "z": 2,
      "name": "Rock_Quartzite"
    },
    {
      "x": -10,
      "y": 0,
      "z": 3,
      "name": "Rock_Quartzite"
    },
    {
      "x": -10,
      "y": 1,
      "z": 3,
      "name": "Rock_Quartzite"
    },
    {
      "x": -10,
      "y": 2,
      "z": 3,
      "name": "Rock_Quartzite"
    },
    {
      "x": -10,
      "y": 3,
      "z": 3,
      "name": "Rock_Quartzite"
    },
    {
      "x": -10,
      "y": 4,
      "z": 3,
      "name": "Rock_Quartzite"
    },
    {
      "x": -10,
      "y": 5,
      "z": 3,
      "name": "Rock_Quartzite"
    },
    {
      "x": -10,
      "y": 6,
      "z": 3,
      "name": "Rock_Quartzite"
    },
    {
      "x": -10,
      "y": 7,
      "z": 3,
      "name": "Rock_Quartzite"
    },
    {
      "x": -10,
      "y": 1,
      "z": 4,
      "name": "Rock_Quartzite"
    },
    {
      "x": -10,
      "y": 2,
      "z": 4,
      "name": "Rock_Quartzite"
    },
    {
      "x": -10,
      "y": 3,
      "z": 4,
      "name": "Rock_Quartzite"
    },
    {
      "x": -10,
      "y": 4,
      "z": 4,
      "name": "Rock_Quartzite"
    },
    {
      "x": -10,
      "y": 5,
      "z": 4,
      "name": "Rock_Quartzite"
    },
    {
      "x": -9,
      "y": 0,
      "z": -4,
      "name": "Rock_Stone"
    },
    {
      "x": -9,
      "y": 1,
      "z": -4,
      "name": "Rock_Stone"
    },
    {
      "x": -9,
      "y": 2,
      "z": -4,
      "name": "Rock_Stone"
    },
    {
      "x": -9,
      "y": 3,
      "z": -4,
      "name": "Rock_Stone"
    },
    {
      "x": -9,
      "y": 4,
      "z": -4,
      "name": "Rock_Stone"
    },
    {
      "x": -9,
      "y": 5,
      "z": -4,
      "name": "Rock_Stone"
    },
    {
      "x": -9,
      "y": 0,
      "z": -3,
      "name": "Rock_Stone"
    },
    {
      "x": -9,
      "y": 1,
      "z": -3,
      "name": "Rock_Stone"
    },
    {
      "x": -9,
      "y": 2,
      "z": -3,
      "name": "Rock_Stone"
    },
    {
      "x": -9,
      "y": 3,
      "z": -3,
      "name": "Rock_Stone"
    },
    {
      "x": -9,
      "y": 4,
      "z": -3,
      "name": "Rock_Stone"
    },
    {
      "x": -9,
      "y": 5,
      "z": -3,
      "name": "Rock_Stone"
    },
    {
      "x": -9,
      "y": 6,
      "z": -3,
      "name": "Rock_Stone"
    },
    {
      "x": -9,
      "y": 7,
      "z": -3,
      "name": "Rock_Stone"
    },
    {
      "x": -9,
      "y": 10,
      "z": -3,
      "name": "Rock_Stone"
    },
    {
      "x": -9,
      "y": 11,
      "z": -3,
      "name": "Rock_Stone"
    },
    {
      "x": -9,
      "y": 12,
      "z": -3,
      "name": "Rock_Stone"
    },
    {
      "x": -9,
      "y": 13,
      "z": -3,
      "name": "Rock_Stone"
    },
    {
      "x": -9,
      "y": 0,
      "z": -2,
      "name": "Rock_Stone"
    },
    {
      "x": -9,
      "y": 1,
      "z": -2,
      "name": "Rock_Stone"
    },
    {
      "x": -9,
      "y": 2,
      "z": -2,
      "name": "Rock_Stone"
    },
    {
      "x": -9,
      "y": 3,
      "z": -2,
      "name": "Rock_Stone"
    },
    {
      "x": -9,
      "y": 4,
      "z": -2,
      "name": "Rock_Stone"
    },
    {
      "x": -9,
      "y": 5,
      "z": -2,
      "name": "Rock_Stone"
    },
    {
      "x": -9,
      "y": 6,
      "z": -2,
      "name": "Rock_Stone"
    },
    {
      "x": -9,
      "y": 7,
      "z": -2,
      "name": "Rock_Stone"
    },
    {
      "x": -9,
      "y": 8,
      "z": -2,
      "name": "Rock_Stone"
    },
    {
      "x": -9,
      "y": 9,
      "z": -2,
      "name": "Rock_Stone"
    },
    {
      "x": -9,
      "y": 10,
      "z": -2,
      "name": "Rock_Stone"
    },
    {
      "x": -9,
      "y": 11,
      "z": -2,
      "name": "Rock_Stone"
    },
    {
      "x": -9,
      "y": 12,
      "z": -2,
      "name": "Rock_Stone"
    },
    {
      "x": -9,
      "y": 13,
      "z": -2,
      "name": "Rock_Stone"
    },
    {
      "x": -9,
      "y": 14,
      "z": -2,
      "name": "Rock_Stone"
    },
    {
      "x": -9,
      "y": 15,
      "z": -2,
      "name": "Rock_Stone"
    },
    {
      "x": -9,
      "y": 16,
      "z": -2,
      "name": "Rock_Stone"
    },
    {
      "x": -9,
      "y": 17,
      "z": -2,
      "name": "Rock_Stone"
    },
    {
      "x": -9,
      "y": 18,
      "z": -2,
      "name": "Rock_Stone"
    },
    {
      "x": -9,
      "y": 0,
      "z": -1,
      "name": "Rock_Stone"
    },
    {
      "x": -9,
      "y": 1,
      "z": -1,
      "name": "Rock_Stone"
    },
    {
      "x": -9,
      "y": 2,
      "z": -1,
      "name": "Rock_Stone"
    },
    {
      "x": -9,
      "y": 3,
      "z": -1,
      "name": "Rock_Stone"
    },
    {
      "x": -9,
      "y": 4,
      "z": -1,
      "name": "Rock_Stone"
    },
    {
      "x": -9,
      "y": 5,
      "z": -1,
      "name": "Rock_Stone"
    },
    {
      "x": -9,
      "y": 6,
      "z": -1,
      "name": "Rock_Stone"
    },
    {
      "x": -9,
      "y": 7,
      "z": -1,
      "name": "Rock_Stone"
    },
    {
      "x": -9,
      "y": 8,
      "z": -1,
      "name": "Rock_Stone"
    },
    {
      "x": -9,
      "y": 9,
      "z": -1,
      "name": "Rock_Stone"
    },
    {
      "x": -9,
      "y": 10,
      "z": -1,
      "name": "Rock_Stone"
    },
    {
      "x": -9,
      "y": 11,
      "z": -1,
      "name": "Rock_Stone"
    },
    {
      "x": -9,
      "y": 12,
      "z": -1,
      "name": "Rock_Stone"
    },
    {
      "x": -9,
      "y": 13,
      "z": -1,
      "name": "Rock_Stone"
    },
    {
      "x": -9,
      "y": 14,
      "z": -1,
      "name": "Rock_Stone"
    },
    {
      "x": -9,
      "y": 15,
      "z": -1,
      "name": "Rock_Stone"
    },
    {
      "x": -9,
      "y": 16,
      "z": -1,
      "name": "Rock_Stone"
    },
    {
      "x": -9,
      "y": 17,
      "z": -1,
      "name": "Rock_Stone"
    },
    {
      "x": -9,
      "y": 18,
      "z": -1,
      "name": "Rock_Stone"
    },
    {
      "x": -9,
      "y": 19,
      "z": -1,
      "name": "Soil_Grass"
    },
    {
      "x": -9,
      "y": 0,
      "z": 0,
      "name": "Rock_Stone"
    },
    {
      "x": -9,
      "y": 1,
      "z": 0,
      "name": "Rock_Stone"
    },
    {
      "x": -9,
      "y": 2,
      "z": 0,
      "name": "Rock_Stone"
    },
    {
      "x": -9,
      "y": 3,
      "z": 0,
      "name": "Rock_Quartzite"
    },
    {
      "x": -9,
      "y": 4,
      "z": 0,
      "name": "Rock_Quartzite"
    },
    {
      "x": -9,
      "y": 5,
      "z": 0,
      "name": "Rock_Quartzite"
    },
    {
      "x": -9,
      "y": 6,
      "z": 0,
      "name": "Rock_Quartzite"
    },
    {
      "x": -9,
      "y": 7,
      "z": 0,
      "name": "Rock_Quartzite"
    },
    {
      "x": -9,
      "y": 8,
      "z": 0,
      "name": "Rock_Quartzite"
    },
    {
      "x": -9,
      "y": 9,
      "z": 0,
      "name": "Rock_Quartzite"
    },
    {
      "x": -9,
      "y": 10,
      "z": 0,
      "name": "Rock_Quartzite"
    },
    {
      "x": -9,
      "y": 11,
      "z": 0,
      "name": "Rock_Quartzite"
    },
    {
      "x": -9,
      "y": 12,
      "z": 0,
      "name": "Rock_Quartzite"
    },
    {
      "x": -9,
      "y": 13,
      "z": 0,
      "name": "Rock_Quartzite"
    },
    {
      "x": -9,
      "y": 14,
      "z": 0,
      "name": "Rock_Quartzite"
    },
    {
      "x": -9,
      "y": 15,
      "z": 0,
      "name": "Rock_Quartzite"
    },
    {
      "x": -9,
      "y": 16,
      "z": 0,
      "name": "Rock_Quartzite"
    },
    {
      "x": -9,
      "y": 17,
      "z": 0,
      "name": "Rock_Quartzite"
    },
    {
      "x": -9,
      "y": 18,
      "z": 0,
      "name": "Rock_Quartzite"
    },
    {
      "x": -9,
      "y": 19,
      "z": 0,
      "name": "Soil_Grass"
    },
    {
      "x": -9,
      "y": 0,
      "z": 1,
      "name": "Rock_Quartzite"
    },
    {
      "x": -9,
      "y": 1,
      "z": 1,
      "name": "Rock_Quartzite"
    },
    {
      "x": -9,
      "y": 2,
      "z": 1,
      "name": "Rock_Quartzite"
    },
    {
      "x": -9,
      "y": 3,
      "z": 1,
      "name": "Rock_Quartzite"
    },
    {
      "x": -9,
      "y": 4,
      "z": 1,
      "name": "Rock_Quartzite"
    },
    {
      "x": -9,
      "y": 5,
      "z": 1,
      "name": "Rock_Quartzite"
    },
    {
      "x": -9,
      "y": 6,
      "z": 1,
      "name": "Rock_Quartzite"
    },
    {
      "x": -9,
      "y": 7,
      "z": 1,
      "name": "Rock_Quartzite"
    },
    {
      "x": -9,
      "y": 8,
      "z": 1,
      "name": "Rock_Quartzite"
    },
    {
      "x": -9,
      "y": 9,
      "z": 1,
      "name": "Rock_Quartzite"
    },
    {
      "x": -9,
      "y": 10,
      "z": 1,
      "name": "Rock_Quartzite"
    },
    {
      "x": -9,
      "y": 11,
      "z": 1,
      "name": "Rock_Quartzite"
    },
    {
      "x": -9,
      "y": 12,
      "z": 1,
      "name": "Rock_Quartzite"
    },
    {
      "x": -9,
      "y": 13,
      "z": 1,
      "name": "Rock_Quartzite"
    },
    {
      "x": -9,
      "y": 14,
      "z": 1,
      "name": "Rock_Quartzite"
    },
    {
      "x": -9,
      "y": 15,
      "z": 1,
      "name": "Rock_Quartzite"
    },
    {
      "x": -9,
      "y": 16,
      "z": 1,
      "name": "Rock_Quartzite"
    },
    {
      "x": -9,
      "y": 17,
      "z": 1,
      "name": "Rock_Quartzite"
    },
    {
      "x": -9,
      "y": 18,
      "z": 1,
      "name": "Rock_Quartzite"
    },
    {
      "x": -9,
      "y": 19,
      "z": 1,
      "name": "Soil_Grass"
    },
    {
      "x": -9,
      "y": 0,
      "z": 2,
      "name": "Rock_Quartzite"
    },
    {
      "x": -9,
      "y": 1,
      "z": 2,
      "name": "Rock_Quartzite"
    },
    {
      "x": -9,
      "y": 2,
      "z": 2,
      "name": "Rock_Quartzite"
    },
    {
      "x": -9,
      "y": 3,
      "z": 2,
      "name": "Rock_Quartzite"
    },
    {
      "x": -9,
      "y": 4,
      "z": 2,
      "name": "Rock_Quartzite"
    },
    {
      "x": -9,
      "y": 5,
      "z": 2,
      "name": "Rock_Quartzite"
    },
    {
      "x": -9,
      "y": 6,
      "z": 2,
      "name": "Rock_Quartzite"
    },
    {
      "x": -9,
      "y": 7,
      "z": 2,
      "name": "Rock_Quartzite"
    },
    {
      "x": -9,
      "y": 8,
      "z": 2,
      "name": "Rock_Quartzite"
    },
    {
      "x": -9,
      "y": 9,
      "z": 2,
      "name": "Rock_Quartzite"
    },
    {
      "x": -9,
      "y": 10,
      "z": 2,
      "name": "Rock_Quartzite"
    },
    {
      "x": -9,
      "y": 11,
      "z": 2,
      "name": "Rock_Quartzite"
    },
    {
      "x": -9,
      "y": 12,
      "z": 2,
      "name": "Rock_Quartzite"
    },
    {
      "x": -9,
      "y": 13,
      "z": 2,
      "name": "Rock_Quartzite"
    },
    {
      "x": -9,
      "y": 14,
      "z": 2,
      "name": "Rock_Quartzite"
    },
    {
      "x": -9,
      "y": 15,
      "z": 2,
      "name": "Rock_Quartzite"
    },
    {
      "x": -9,
      "y": 16,
      "z": 2,
      "name": "Rock_Quartzite"
    },
    {
      "x": -9,
      "y": 17,
      "z": 2,
      "name": "Rock_Quartzite"
    },
    {
      "x": -9,
      "y": 18,
      "z": 2,
      "name": "Rock_Quartzite"
    },
    {
      "x": -9,
      "y": 0,
      "z": 3,
      "name": "Rock_Quartzite"
    },
    {
      "x": -9,
      "y": 1,
      "z": 3,
      "name": "Rock_Quartzite"
    },
    {
      "x": -9,
      "y": 2,
      "z": 3,
      "name": "Rock_Quartzite"
    },
    {
      "x": -9,
      "y": 3,
      "z": 3,
      "name": "Rock_Quartzite"
    },
    {
      "x": -9,
      "y": 4,
      "z": 3,
      "name": "Rock_Quartzite"
    },
    {
      "x": -9,
      "y": 5,
      "z": 3,
      "name": "Rock_Quartzite"
    },
    {
      "x": -9,
      "y": 6,
      "z": 3,
      "name": "Rock_Quartzite"
    },
    {
      "x": -9,
      "y": 7,
      "z": 3,
      "name": "Rock_Quartzite"
    },
    {
      "x": -9,
      "y": 8,
      "z": 3,
      "name": "Rock_Quartzite"
    },
    {
      "x": -9,
      "y": 9,
      "z": 3,
      "name": "Rock_Quartzite"
    },
    {
      "x": -9,
      "y": 10,
      "z": 3,
      "name": "Rock_Quartzite"
    },
    {
      "x": -9,
      "y": 11,
      "z": 3,
      "name": "Rock_Quartzite"
    },
    {
      "x": -9,
      "y": 12,
      "z": 3,
      "name": "Rock_Quartzite"
    },
    {
      "x": -9,
      "y": 13,
      "z": 3,
      "name": "Rock_Quartzite"
    },
    {
      "x": -9,
      "y": 14,
      "z": 3,
      "name": "Rock_Quartzite"
    },
    {
      "x": -9,
      "y": 15,
      "z": 3,
      "name": "Rock_Quartzite"
    },
    {
      "x": -9,
      "y": 16,
      "z": 3,
      "name": "Rock_Quartzite"
    },
    {
      "x": -9,
      "y": 0,
      "z": 4,
      "name": "Rock_Quartzite"
    },
    {
      "x": -9,
      "y": 1,
      "z": 4,
      "name": "Rock_Quartzite"
    },
    {
      "x": -9,
      "y": 2,
      "z": 4,
      "name": "Rock_Quartzite"
    },
    {
      "x": -9,
      "y": 3,
      "z": 4,
      "name": "Rock_Quartzite"
    },
    {
      "x": -9,
      "y": 4,
      "z": 4,
      "name": "Rock_Quartzite"
    },
    {
      "x": -9,
      "y": 5,
      "z": 4,
      "name": "Rock_Quartzite"
    },
    {
      "x": -9,
      "y": 6,
      "z": 4,
      "name": "Rock_Quartzite"
    },
    {
      "x": -9,
      "y": 7,
      "z": 4,
      "name": "Rock_Quartzite"
    },
    {
      "x": -9,
      "y": 8,
      "z": 4,
      "name": "Rock_Quartzite"
    },
    {
      "x": -9,
      "y": 9,
      "z": 4,
      "name": "Rock_Quartzite"
    },
    {
      "x": -9,
      "y": 10,
      "z": 4,
      "name": "Rock_Quartzite"
    },
    {
      "x": -9,
      "y": 11,
      "z": 4,
      "name": "Rock_Quartzite"
    },
    {
      "x": -9,
      "y": 12,
      "z": 4,
      "name": "Rock_Quartzite"
    },
    {
      "x": -9,
      "y": 0,
      "z": 5,
      "name": "Rock_Quartzite"
    },
    {
      "x": -9,
      "y": 1,
      "z": 5,
      "name": "Rock_Quartzite"
    },
    {
      "x": -9,
      "y": 2,
      "z": 5,
      "name": "Rock_Quartzite"
    },
    {
      "x": -9,
      "y": 3,
      "z": 5,
      "name": "Rock_Quartzite"
    },
    {
      "x": -9,
      "y": 4,
      "z": 5,
      "name": "Rock_Quartzite"
    },
    {
      "x": -9,
      "y": 5,
      "z": 5,
      "name": "Rock_Quartzite"
    },
    {
      "x": -9,
      "y": 6,
      "z": 5,
      "name": "Rock_Quartzite"
    },
    {
      "x": -9,
      "y": 7,
      "z": 5,
      "name": "Rock_Quartzite"
    },
    {
      "x": -9,
      "y": 8,
      "z": 5,
      "name": "Rock_Quartzite"
    },
    {
      "x": -9,
      "y": 1,
      "z": 6,
      "name": "Rock_Quartzite"
    },
    {
      "x": -9,
      "y": 2,
      "z": 6,
      "name": "Rock_Quartzite"
    },
    {
      "x": -9,
      "y": 3,
      "z": 6,
      "name": "Rock_Quartzite"
    },
    {
      "x": -8,
      "y": 0,
      "z": -5,
      "name": "Rock_Stone"
    },
    {
      "x": -8,
      "y": 1,
      "z": -5,
      "name": "Rock_Stone"
    },
    {
      "x": -8,
      "y": 2,
      "z": -5,
      "name": "Rock_Stone"
    },
    {
      "x": -8,
      "y": 3,
      "z": -5,
      "name": "Rock_Stone"
    },
    {
      "x": -8,
      "y": 4,
      "z": -5,
      "name": "Rock_Stone"
    },
    {
      "x": -8,
      "y": 5,
      "z": -5,
      "name": "Rock_Stone"
    },
    {
      "x": -8,
      "y": 7,
      "z": -5,
      "name": "Rock_Stone"
    },
    {
      "x": -8,
      "y": 8,
      "z": -5,
      "name": "Rock_Stone"
    },
    {
      "x": -8,
      "y": 9,
      "z": -5,
      "name": "Rock_Stone"
    },
    {
      "x": -8,
      "y": 10,
      "z": -5,
      "name": "Rock_Stone"
    },
    {
      "x": -8,
      "y": 11,
      "z": -5,
      "name": "Rock_Stone"
    },
    {
      "x": -8,
      "y": 12,
      "z": -5,
      "name": "Rock_Stone"
    },
    {
      "x": -8,
      "y": 13,
      "z": -5,
      "name": "Rock_Stone"
    },
    {
      "x": -8,
      "y": 14,
      "z": -5,
      "name": "Rock_Stone"
    },
    {
      "x": -8,
      "y": 15,
      "z": -5,
      "name": "Rock_Stone"
    },
    {
      "x": -8,
      "y": 16,
      "z": -5,
      "name": "Rock_Stone"
    },
    {
      "x": -8,
      "y": 17,
      "z": -5,
      "name": "Rock_Stone"
    },
    {
      "x": -8,
      "y": 18,
      "z": -5,
      "name": "Rock_Stone"
    },
    {
      "x": -8,
      "y": 19,
      "z": -5,
      "name": "Rock_Stone"
    },
    {
      "x": -8,
      "y": 0,
      "z": -4,
      "name": "Rock_Stone"
    },
    {
      "x": -8,
      "y": 1,
      "z": -4,
      "name": "Rock_Stone"
    },
    {
      "x": -8,
      "y": 2,
      "z": -4,
      "name": "Rock_Stone"
    },
    {
      "x": -8,
      "y": 3,
      "z": -4,
      "name": "Rock_Stone"
    },
    {
      "x": -8,
      "y": 4,
      "z": -4,
      "name": "Rock_Stone"
    },
    {
      "x": -8,
      "y": 5,
      "z": -4,
      "name": "Rock_Stone"
    },
    {
      "x": -8,
      "y": 6,
      "z": -4,
      "name": "Rock_Stone"
    },
    {
      "x": -8,
      "y": 7,
      "z": -4,
      "name": "Rock_Stone"
    },
    {
      "x": -8,
      "y": 8,
      "z": -4,
      "name": "Rock_Stone"
    },
    {
      "x": -8,
      "y": 9,
      "z": -4,
      "name": "Rock_Stone"
    },
    {
      "x": -8,
      "y": 10,
      "z": -4,
      "name": "Rock_Stone"
    },
    {
      "x": -8,
      "y": 11,
      "z": -4,
      "name": "Rock_Stone"
    },
    {
      "x": -8,
      "y": 12,
      "z": -4,
      "name": "Rock_Stone"
    },
    {
      "x": -8,
      "y": 13,
      "z": -4,
      "name": "Rock_Stone"
    },
    {
      "x": -8,
      "y": 14,
      "z": -4,
      "name": "Rock_Stone"
    },
    {
      "x": -8,
      "y": 15,
      "z": -4,
      "name": "Rock_Stone"
    },
    {
      "x": -8,
      "y": 16,
      "z": -4,
      "name": "Rock_Stone"
    },
    {
      "x": -8,
      "y": 17,
      "z": -4,
      "name": "Rock_Stone"
    },
    {
      "x": -8,
      "y": 18,
      "z": -4,
      "name": "Rock_Stone"
    },
    {
      "x": -8,
      "y": 19,
      "z": -4,
      "name": "Soil_Grass"
    },
    {
      "x": -8,
      "y": 0,
      "z": -3,
      "name": "Rock_Stone"
    },
    {
      "x": -8,
      "y": 1,
      "z": -3,
      "name": "Rock_Stone"
    },
    {
      "x": -8,
      "y": 2,
      "z": -3,
      "name": "Rock_Stone"
    },
    {
      "x": -8,
      "y": 3,
      "z": -3,
      "name": "Rock_Stone"
    },
    {
      "x": -8,
      "y": 4,
      "z": -3,
      "name": "Rock_Stone"
    },
    {
      "x": -8,
      "y": 5,
      "z": -3,
      "name": "Rock_Stone"
    },
    {
      "x": -8,
      "y": 6,
      "z": -3,
      "name": "Rock_Stone"
    },
    {
      "x": -8,
      "y": 7,
      "z": -3,
      "name": "Rock_Stone"
    },
    {
      "x": -8,
      "y": 8,
      "z": -3,
      "name": "Rock_Stone"
    },
    {
      "x": -8,
      "y": 9,
      "z": -3,
      "name": "Rock_Stone"
    },
    {
      "x": -8,
      "y": 10,
      "z": -3,
      "name": "Rock_Stone"
    },
    {
      "x": -8,
      "y": 11,
      "z": -3,
      "name": "Rock_Stone"
    },
    {
      "x": -8,
      "y": 12,
      "z": -3,
      "name": "Rock_Stone"
    },
    {
      "x": -8,
      "y": 13,
      "z": -3,
      "name": "Rock_Stone"
    },
    {
      "x": -8,
      "y": 14,
      "z": -3,
      "name": "Rock_Stone"
    },
    {
      "x": -8,
      "y": 15,
      "z": -3,
      "name": "Rock_Stone"
    },
    {
      "x": -8,
      "y": 16,
      "z": -3,
      "name": "Rock_Stone"
    },
    {
      "x": -8,
      "y": 17,
      "z": -3,
      "name": "Rock_Stone"
    },
    {
      "x": -8,
      "y": 18,
      "z": -3,
      "name": "Rock_Stone"
    },
    {
      "x": -8,
      "y": 19,
      "z": -3,
      "name": "Soil_Grass"
    },
    {
      "x": -8,
      "y": 0,
      "z": -2,
      "name": "Rock_Stone"
    },
    {
      "x": -8,
      "y": 1,
      "z": -2,
      "name": "Rock_Stone"
    },
    {
      "x": -8,
      "y": 2,
      "z": -2,
      "name": "Rock_Stone"
    },
    {
      "x": -8,
      "y": 3,
      "z": -2,
      "name": "Rock_Stone"
    },
    {
      "x": -8,
      "y": 4,
      "z": -2,
      "name": "Rock_Stone"
    },
    {
      "x": -8,
      "y": 5,
      "z": -2,
      "name": "Rock_Stone"
    },
    {
      "x": -8,
      "y": 6,
      "z": -2,
      "name": "Rock_Stone"
    },
    {
      "x": -8,
      "y": 7,
      "z": -2,
      "name": "Rock_Stone"
    },
    {
      "x": -8,
      "y": 8,
      "z": -2,
      "name": "Rock_Stone"
    },
    {
      "x": -8,
      "y": 9,
      "z": -2,
      "name": "Rock_Stone"
    },
    {
      "x": -8,
      "y": 10,
      "z": -2,
      "name": "Rock_Stone"
    },
    {
      "x": -8,
      "y": 11,
      "z": -2,
      "name": "Rock_Stone"
    },
    {
      "x": -8,
      "y": 12,
      "z": -2,
      "name": "Rock_Stone"
    },
    {
      "x": -8,
      "y": 13,
      "z": -2,
      "name": "Rock_Stone"
    },
    {
      "x": -8,
      "y": 14,
      "z": -2,
      "name": "Rock_Stone"
    },
    {
      "x": -8,
      "y": 15,
      "z": -2,
      "name": "Rock_Stone"
    },
    {
      "x": -8,
      "y": 16,
      "z": -2,
      "name": "Rock_Stone"
    },
    {
      "x": -8,
      "y": 17,
      "z": -2,
      "name": "Rock_Stone"
    },
    {
      "x": -8,
      "y": 18,
      "z": -2,
      "name": "Rock_Stone"
    },
    {
      "x": -8,
      "y": 19,
      "z": -2,
      "name": "Soil_Grass"
    },
    {
      "x": -8,
      "y": 0,
      "z": -1,
      "name": "Rock_Stone"
    },
    {
      "x": -8,
      "y": 1,
      "z": -1,
      "name": "Rock_Stone"
    },
    {
      "x": -8,
      "y": 2,
      "z": -1,
      "name": "Rock_Stone"
    },
    {
      "x": -8,
      "y": 3,
      "z": -1,
      "name": "Rock_Stone"
    },
    {
      "x": -8,
      "y": 4,
      "z": -1,
      "name": "Rock_Stone"
    },
    {
      "x": -8,
      "y": 5,
      "z": -1,
      "name": "Rock_Stone"
    },
    {
      "x": -8,
      "y": 6,
      "z": -1,
      "name": "Rock_Stone"
    },
    {
      "x": -8,
      "y": 7,
      "z": -1,
      "name": "Rock_Stone"
    },
    {
      "x": -8,
      "y": 8,
      "z": -1,
      "name": "Rock_Stone"
    },
    {
      "x": -8,
      "y": 9,
      "z": -1,
      "name": "Rock_Quartzite"
    },
    {
      "x": -8,
      "y": 10,
      "z": -1,
      "name": "Rock_Quartzite"
    },
    {
      "x": -8,
      "y": 11,
      "z": -1,
      "name": "Rock_Quartzite"
    },
    {
      "x": -8,
      "y": 12,
      "z": -1,
      "name": "Rock_Quartzite"
    },
    {
      "x": -8,
      "y": 13,
      "z": -1,
      "name": "Rock_Quartzite"
    },
    {
      "x": -8,
      "y": 14,
      "z": -1,
      "name": "Rock_Quartzite"
    },
    {
      "x": -8,
      "y": 15,
      "z": -1,
      "name": "Rock_Quartzite"
    },
    {
      "x": -8,
      "y": 16,
      "z": -1,
      "name": "Rock_Quartzite"
    },
    {
      "x": -8,
      "y": 17,
      "z": -1,
      "name": "Rock_Stone"
    },
    {
      "x": -8,
      "y": 18,
      "z": -1,
      "name": "Rock_Stone"
    },
    {
      "x": -8,
      "y": 19,
      "z": -1,
      "name": "Soil_Grass"
    },
    {
      "x": -8,
      "y": 0,
      "z": 0,
      "name": "Rock_Stone"
    },
    {
      "x": -8,
      "y": 1,
      "z": 0,
      "name": "Rock_Stone"
    },
    {
      "x": -8,
      "y": 2,
      "z": 0,
      "name": "Rock_Quartzite"
    },
    {
      "x": -8,
      "y": 3,
      "z": 0,
      "name": "Rock_Quartzite"
    },
    {
      "x": -8,
      "y": 4,
      "z": 0,
      "name": "Rock_Quartzite"
    },
    {
      "x": -8,
      "y": 5,
      "z": 0,
      "name": "Rock_Quartzite"
    },
    {
      "x": -8,
      "y": 6,
      "z": 0,
      "name": "Rock_Quartzite"
    },
    {
      "x": -8,
      "y": 7,
      "z": 0,
      "name": "Rock_Quartzite"
    },
    {
      "x": -8,
      "y": 8,
      "z": 0,
      "name": "Rock_Quartzite"
    },
    {
      "x": -8,
      "y": 9,
      "z": 0,
      "name": "Rock_Quartzite"
    },
    {
      "x": -8,
      "y": 10,
      "z": 0,
      "name": "Rock_Quartzite"
    },
    {
      "x": -8,
      "y": 11,
      "z": 0,
      "name": "Rock_Quartzite"
    },
    {
      "x": -8,
      "y": 12,
      "z": 0,
      "name": "Rock_Quartzite"
    },
    {
      "x": -8,
      "y": 13,
      "z": 0,
      "name": "Rock_Quartzite"
    },
    {
      "x": -8,
      "y": 14,
      "z": 0,
      "name": "Rock_Quartzite"
    },
    {
      "x": -8,
      "y": 15,
      "z": 0,
      "name": "Rock_Quartzite"
    },
    {
      "x": -8,
      "y": 16,
      "z": 0,
      "name": "Rock_Quartzite"
    },
    {
      "x": -8,
      "y": 17,
      "z": 0,
      "name": "Rock_Quartzite"
    },
    {
      "x": -8,
      "y": 18,
      "z": 0,
      "name": "Rock_Quartzite"
    },
    {
      "x": -8,
      "y": 19,
      "z": 0,
      "name": "Soil_Grass"
    },
    {
      "x": -8,
      "y": 0,
      "z": 1,
      "name": "Rock_Quartzite"
    },
    {
      "x": -8,
      "y": 1,
      "z": 1,
      "name": "Rock_Quartzite"
    },
    {
      "x": -8,
      "y": 2,
      "z": 1,
      "name": "Rock_Quartzite"
    },
    {
      "x": -8,
      "y": 3,
      "z": 1,
      "name": "Rock_Quartzite"
    },
    {
      "x": -8,
      "y": 4,
      "z": 1,
      "name": "Rock_Quartzite"
    },
    {
      "x": -8,
      "y": 5,
      "z": 1,
      "name": "Rock_Quartzite"
    },
    {
      "x": -8,
      "y": 6,
      "z": 1,
      "name": "Rock_Quartzite"
    },
    {
      "x": -8,
      "y": 7,
      "z": 1,
      "name": "Rock_Quartzite"
    },
    {
      "x": -8,
      "y": 8,
      "z": 1,
      "name": "Rock_Quartzite"
    },
    {
      "x": -8,
      "y": 9,
      "z": 1,
      "name": "Rock_Quartzite"
    },
    {
      "x": -8,
      "y": 10,
      "z": 1,
      "name": "Rock_Quartzite"
    },
    {
      "x": -8,
      "y": 11,
      "z": 1,
      "name": "Rock_Quartzite"
    },
    {
      "x": -8,
      "y": 12,
      "z": 1,
      "name": "Rock_Quartzite"
    },
    {
      "x": -8,
      "y": 13,
      "z": 1,
      "name": "Rock_Quartzite"
    },
    {
      "x": -8,
      "y": 14,
      "z": 1,
      "name": "Rock_Quartzite"
    },
    {
      "x": -8,
      "y": 15,
      "z": 1,
      "name": "Rock_Quartzite"
    },
    {
      "x": -8,
      "y": 16,
      "z": 1,
      "name": "Rock_Quartzite"
    },
    {
      "x": -8,
      "y": 17,
      "z": 1,
      "name": "Rock_Quartzite"
    },
    {
      "x": -8,
      "y": 18,
      "z": 1,
      "name": "Soil_Dirt"
    },
    {
      "x": -8,
      "y": 19,
      "z": 1,
      "name": "Soil_Grass"
    },
    {
      "x": -8,
      "y": 0,
      "z": 2,
      "name": "Rock_Quartzite"
    },
    {
      "x": -8,
      "y": 1,
      "z": 2,
      "name": "Rock_Quartzite"
    },
    {
      "x": -8,
      "y": 2,
      "z": 2,
      "name": "Rock_Quartzite"
    },
    {
      "x": -8,
      "y": 3,
      "z": 2,
      "name": "Rock_Quartzite"
    },
    {
      "x": -8,
      "y": 4,
      "z": 2,
      "name": "Rock_Quartzite"
    },
    {
      "x": -8,
      "y": 5,
      "z": 2,
      "name": "Rock_Quartzite"
    },
    {
      "x": -8,
      "y": 6,
      "z": 2,
      "name": "Rock_Quartzite"
    },
    {
      "x": -8,
      "y": 7,
      "z": 2,
      "name": "Rock_Quartzite"
    },
    {
      "x": -8,
      "y": 8,
      "z": 2,
      "name": "Rock_Quartzite"
    },
    {
      "x": -8,
      "y": 9,
      "z": 2,
      "name": "Rock_Quartzite"
    },
    {
      "x": -8,
      "y": 10,
      "z": 2,
      "name": "Rock_Quartzite"
    },
    {
      "x": -8,
      "y": 11,
      "z": 2,
      "name": "Rock_Quartzite"
    },
    {
      "x": -8,
      "y": 12,
      "z": 2,
      "name": "Rock_Quartzite"
    },
    {
      "x": -8,
      "y": 13,
      "z": 2,
      "name": "Rock_Quartzite"
    },
    {
      "x": -8,
      "y": 14,
      "z": 2,
      "name": "Rock_Quartzite"
    },
    {
      "x": -8,
      "y": 15,
      "z": 2,
      "name": "Rock_Quartzite"
    },
    {
      "x": -8,
      "y": 16,
      "z": 2,
      "name": "Rock_Quartzite"
    },
    {
      "x": -8,
      "y": 17,
      "z": 2,
      "name": "Rock_Quartzite"
    },
    {
      "x": -8,
      "y": 18,
      "z": 2,
      "name": "Soil_Dirt"
    },
    {
      "x": -8,
      "y": 19,
      "z": 2,
      "name": "Soil_Grass"
    },
    {
      "x": -8,
      "y": 0,
      "z": 3,
      "name": "Rock_Quartzite"
    },
    {
      "x": -8,
      "y": 1,
      "z": 3,
      "name": "Rock_Quartzite"
    },
    {
      "x": -8,
      "y": 2,
      "z": 3,
      "name": "Rock_Quartzite"
    },
    {
      "x": -8,
      "y": 3,
      "z": 3,
      "name": "Rock_Quartzite"
    },
    {
      "x": -8,
      "y": 4,
      "z": 3,
      "name": "Rock_Quartzite"
    },
    {
      "x": -8,
      "y": 5,
      "z": 3,
      "name": "Rock_Quartzite"
    },
    {
      "x": -8,
      "y": 6,
      "z": 3,
      "name": "Rock_Quartzite"
    },
    {
      "x": -8,
      "y": 7,
      "z": 3,
      "name": "Rock_Quartzite"
    },
    {
      "x": -8,
      "y": 8,
      "z": 3,
      "name": "Rock_Quartzite"
    },
    {
      "x": -8,
      "y": 9,
      "z": 3,
      "name": "Rock_Quartzite"
    },
    {
      "x": -8,
      "y": 10,
      "z": 3,
      "name": "Rock_Quartzite"
    },
    {
      "x": -8,
      "y": 11,
      "z": 3,
      "name": "Rock_Quartzite"
    },
    {
      "x": -8,
      "y": 12,
      "z": 3,
      "name": "Rock_Quartzite"
    },
    {
      "x": -8,
      "y": 13,
      "z": 3,
      "name": "Rock_Quartzite"
    },
    {
      "x": -8,
      "y": 14,
      "z": 3,
      "name": "Rock_Quartzite"
    },
    {
      "x": -8,
      "y": 15,
      "z": 3,
      "name": "Rock_Quartzite"
    },
    {
      "x": -8,
      "y": 16,
      "z": 3,
      "name": "Rock_Quartzite"
    },
    {
      "x": -8,
      "y": 17,
      "z": 3,
      "name": "Rock_Quartzite"
    },
    {
      "x": -8,
      "y": 18,
      "z": 3,
      "name": "Rock_Quartzite"
    },
    {
      "x": -8,
      "y": 0,
      "z": 4,
      "name": "Rock_Quartzite"
    },
    {
      "x": -8,
      "y": 1,
      "z": 4,
      "name": "Rock_Quartzite"
    },
    {
      "x": -8,
      "y": 2,
      "z": 4,
      "name": "Rock_Quartzite"
    },
    {
      "x": -8,
      "y": 3,
      "z": 4,
      "name": "Rock_Quartzite"
    },
    {
      "x": -8,
      "y": 4,
      "z": 4,
      "name": "Rock_Quartzite"
    },
    {
      "x": -8,
      "y": 5,
      "z": 4,
      "name": "Rock_Quartzite"
    },
    {
      "x": -8,
      "y": 6,
      "z": 4,
      "name": "Rock_Quartzite"
    },
    {
      "x": -8,
      "y": 7,
      "z": 4,
      "name": "Rock_Quartzite"
    },
    {
      "x": -8,
      "y": 8,
      "z": 4,
      "name": "Rock_Quartzite"
    },
    {
      "x": -8,
      "y": 9,
      "z": 4,
      "name": "Rock_Quartzite"
    },
    {
      "x": -8,
      "y": 10,
      "z": 4,
      "name": "Rock_Quartzite"
    },
    {
      "x": -8,
      "y": 11,
      "z": 4,
      "name": "Rock_Quartzite"
    },
    {
      "x": -8,
      "y": 12,
      "z": 4,
      "name": "Rock_Quartzite"
    },
    {
      "x": -8,
      "y": 13,
      "z": 4,
      "name": "Rock_Quartzite"
    },
    {
      "x": -8,
      "y": 14,
      "z": 4,
      "name": "Rock_Quartzite"
    },
    {
      "x": -8,
      "y": 15,
      "z": 4,
      "name": "Rock_Quartzite"
    },
    {
      "x": -8,
      "y": 16,
      "z": 4,
      "name": "Rock_Quartzite"
    },
    {
      "x": -8,
      "y": 17,
      "z": 4,
      "name": "Rock_Quartzite"
    },
    {
      "x": -8,
      "y": 18,
      "z": 4,
      "name": "Soil_Grass"
    },
    {
      "x": -8,
      "y": 0,
      "z": 5,
      "name": "Rock_Quartzite"
    },
    {
      "x": -8,
      "y": 1,
      "z": 5,
      "name": "Rock_Quartzite"
    },
    {
      "x": -8,
      "y": 2,
      "z": 5,
      "name": "Rock_Quartzite"
    },
    {
      "x": -8,
      "y": 3,
      "z": 5,
      "name": "Rock_Quartzite"
    },
    {
      "x": -8,
      "y": 4,
      "z": 5,
      "name": "Rock_Quartzite"
    },
    {
      "x": -8,
      "y": 5,
      "z": 5,
      "name": "Rock_Quartzite"
    },
    {
      "x": -8,
      "y": 6,
      "z": 5,
      "name": "Rock_Quartzite"
    },
    {
      "x": -8,
      "y": 7,
      "z": 5,
      "name": "Rock_Quartzite"
    },
    {
      "x": -8,
      "y": 8,
      "z": 5,
      "name": "Rock_Quartzite"
    },
    {
      "x": -8,
      "y": 9,
      "z": 5,
      "name": "Rock_Quartzite"
    },
    {
      "x": -8,
      "y": 10,
      "z": 5,
      "name": "Rock_Quartzite"
    },
    {
      "x": -8,
      "y": 11,
      "z": 5,
      "name": "Rock_Quartzite"
    },
    {
      "x": -8,
      "y": 12,
      "z": 5,
      "name": "Rock_Quartzite"
    },
    {
      "x": -8,
      "y": 13,
      "z": 5,
      "name": "Rock_Quartzite"
    },
    {
      "x": -8,
      "y": 14,
      "z": 5,
      "name": "Rock_Quartzite"
    },
    {
      "x": -8,
      "y": 15,
      "z": 5,
      "name": "Rock_Quartzite"
    },
    {
      "x": -8,
      "y": 16,
      "z": 5,
      "name": "Rock_Quartzite"
    },
    {
      "x": -8,
      "y": 17,
      "z": 5,
      "name": "Rock_Quartzite"
    },
    {
      "x": -8,
      "y": 18,
      "z": 5,
      "name": "Rock_Quartzite"
    },
    {
      "x": -8,
      "y": 0,
      "z": 6,
      "name": "Rock_Quartzite"
    },
    {
      "x": -8,
      "y": 1,
      "z": 6,
      "name": "Rock_Quartzite"
    },
    {
      "x": -8,
      "y": 2,
      "z": 6,
      "name": "Rock_Quartzite"
    },
    {
      "x": -8,
      "y": 3,
      "z": 6,
      "name": "Rock_Quartzite"
    },
    {
      "x": -8,
      "y": 4,
      "z": 6,
      "name": "Rock_Quartzite"
    },
    {
      "x": -8,
      "y": 5,
      "z": 6,
      "name": "Rock_Quartzite"
    },
    {
      "x": -8,
      "y": 6,
      "z": 6,
      "name": "Rock_Quartzite"
    },
    {
      "x": -8,
      "y": 7,
      "z": 6,
      "name": "Rock_Quartzite"
    },
    {
      "x": -8,
      "y": 8,
      "z": 6,
      "name": "Rock_Quartzite"
    },
    {
      "x": -8,
      "y": 9,
      "z": 6,
      "name": "Rock_Quartzite"
    },
    {
      "x": -8,
      "y": 15,
      "z": 6,
      "name": "Rock_Quartzite"
    },
    {
      "x": -8,
      "y": 16,
      "z": 6,
      "name": "Rock_Quartzite"
    },
    {
      "x": -8,
      "y": 17,
      "z": 6,
      "name": "Rock_Quartzite"
    },
    {
      "x": -8,
      "y": 18,
      "z": 6,
      "name": "Rock_Quartzite"
    },
    {
      "x": -8,
      "y": 19,
      "z": 6,
      "name": "Soil_Grass"
    },
    {
      "x": -8,
      "y": 2,
      "z": 7,
      "name": "Rock_Quartzite"
    },
    {
      "x": -8,
      "y": 18,
      "z": 7,
      "name": "Rock_Quartzite"
    },
    {
      "x": -8,
      "y": 19,
      "z": 7,
      "name": "Soil_Grass"
    },
    {
      "x": -7,
      "y": 8,
      "z": -7,
      "name": "Rock_Stone"
    },
    {
      "x": -7,
      "y": 9,
      "z": -7,
      "name": "Rock_Stone"
    },
    {
      "x": -7,
      "y": 10,
      "z": -7,
      "name": "Rock_Stone"
    },
    {
      "x": -7,
      "y": 11,
      "z": -7,
      "name": "Rock_Stone"
    },
    {
      "x": -7,
      "y": 12,
      "z": -7,
      "name": "Rock_Stone"
    },
    {
      "x": -7,
      "y": 13,
      "z": -7,
      "name": "Rock_Stone"
    },
    {
      "x": -7,
      "y": 14,
      "z": -7,
      "name": "Rock_Stone"
    },
    {
      "x": -7,
      "y": 15,
      "z": -7,
      "name": "Rock_Stone"
    },
    {
      "x": -7,
      "y": 16,
      "z": -7,
      "name": "Rock_Stone"
    },
    {
      "x": -7,
      "y": 1,
      "z": -6,
      "name": "Rock_Stone"
    },
    {
      "x": -7,
      "y": 2,
      "z": -6,
      "name": "Rock_Stone"
    },
    {
      "x": -7,
      "y": 3,
      "z": -6,
      "name": "Rock_Stone"
    },
    {
      "x": -7,
      "y": 4,
      "z": -6,
      "name": "Rock_Stone"
    },
    {
      "x": -7,
      "y": 5,
      "z": -6,
      "name": "Rock_Stone"
    },
    {
      "x": -7,
      "y": 6,
      "z": -6,
      "name": "Rock_Stone"
    },
    {
      "x": -7,
      "y": 7,
      "z": -6,
      "name": "Rock_Stone"
    },
    {
      "x": -7,
      "y": 8,
      "z": -6,
      "name": "Rock_Stone"
    },
    {
      "x": -7,
      "y": 9,
      "z": -6,
      "name": "Rock_Stone"
    },
    {
      "x": -7,
      "y": 10,
      "z": -6,
      "name": "Rock_Stone"
    },
    {
      "x": -7,
      "y": 11,
      "z": -6,
      "name": "Rock_Stone"
    },
    {
      "x": -7,
      "y": 12,
      "z": -6,
      "name": "Rock_Stone"
    },
    {
      "x": -7,
      "y": 13,
      "z": -6,
      "name": "Rock_Stone"
    },
    {
      "x": -7,
      "y": 14,
      "z": -6,
      "name": "Rock_Stone"
    },
    {
      "x": -7,
      "y": 15,
      "z": -6,
      "name": "Rock_Stone"
    },
    {
      "x": -7,
      "y": 16,
      "z": -6,
      "name": "Rock_Stone"
    },
    {
      "x": -7,
      "y": 17,
      "z": -6,
      "name": "Rock_Stone"
    },
    {
      "x": -7,
      "y": 18,
      "z": -6,
      "name": "Rock_Stone"
    },
    {
      "x": -7,
      "y": 19,
      "z": -6,
      "name": "Rock_Stone"
    },
    {
      "x": -7,
      "y": 20,
      "z": -6,
      "name": "Soil_Grass"
    },
    {
      "x": -7,
      "y": 0,
      "z": -5,
      "name": "Rock_Stone"
    },
    {
      "x": -7,
      "y": 1,
      "z": -5,
      "name": "Rock_Stone"
    },
    {
      "x": -7,
      "y": 2,
      "z": -5,
      "name": "Rock_Stone"
    },
    {
      "x": -7,
      "y": 3,
      "z": -5,
      "name": "Rock_Stone"
    },
    {
      "x": -7,
      "y": 4,
      "z": -5,
      "name": "Rock_Stone"
    },
    {
      "x": -7,
      "y": 5,
      "z": -5,
      "name": "Rock_Stone"
    },
    {
      "x": -7,
      "y": 6,
      "z": -5,
      "name": "Rock_Stone"
    },
    {
      "x": -7,
      "y": 7,
      "z": -5,
      "name": "Rock_Stone"
    },
    {
      "x": -7,
      "y": 8,
      "z": -5,
      "name": "Rock_Stone"
    },
    {
      "x": -7,
      "y": 9,
      "z": -5,
      "name": "Rock_Stone"
    },
    {
      "x": -7,
      "y": 10,
      "z": -5,
      "name": "Rock_Stone"
    },
    {
      "x": -7,
      "y": 11,
      "z": -5,
      "name": "Rock_Stone"
    },
    {
      "x": -7,
      "y": 12,
      "z": -5,
      "name": "Rock_Stone"
    },
    {
      "x": -7,
      "y": 13,
      "z": -5,
      "name": "Rock_Stone"
    },
    {
      "x": -7,
      "y": 14,
      "z": -5,
      "name": "Rock_Stone"
    },
    {
      "x": -7,
      "y": 15,
      "z": -5,
      "name": "Rock_Stone"
    },
    {
      "x": -7,
      "y": 16,
      "z": -5,
      "name": "Rock_Stone"
    },
    {
      "x": -7,
      "y": 17,
      "z": -5,
      "name": "Rock_Stone"
    },
    {
      "x": -7,
      "y": 18,
      "z": -5,
      "name": "Rock_Stone"
    },
    {
      "x": -7,
      "y": 19,
      "z": -5,
      "name": "Soil_Dirt"
    },
    {
      "x": -7,
      "y": 20,
      "z": -5,
      "name": "Soil_Grass"
    },
    {
      "x": -7,
      "y": 0,
      "z": -4,
      "name": "Rock_Stone"
    },
    {
      "x": -7,
      "y": 1,
      "z": -4,
      "name": "Rock_Stone"
    },
    {
      "x": -7,
      "y": 2,
      "z": -4,
      "name": "Rock_Stone"
    },
    {
      "x": -7,
      "y": 3,
      "z": -4,
      "name": "Rock_Stone"
    },
    {
      "x": -7,
      "y": 4,
      "z": -4,
      "name": "Rock_Stone"
    },
    {
      "x": -7,
      "y": 5,
      "z": -4,
      "name": "Rock_Stone"
    },
    {
      "x": -7,
      "y": 6,
      "z": -4,
      "name": "Rock_Stone"
    },
    {
      "x": -7,
      "y": 7,
      "z": -4,
      "name": "Rock_Stone"
    },
    {
      "x": -7,
      "y": 8,
      "z": -4,
      "name": "Rock_Stone"
    },
    {
      "x": -7,
      "y": 9,
      "z": -4,
      "name": "Rock_Stone"
    },
    {
      "x": -7,
      "y": 10,
      "z": -4,
      "name": "Rock_Stone"
    },
    {
      "x": -7,
      "y": 11,
      "z": -4,
      "name": "Rock_Stone"
    },
    {
      "x": -7,
      "y": 12,
      "z": -4,
      "name": "Rock_Stone"
    },
    {
      "x": -7,
      "y": 13,
      "z": -4,
      "name": "Rock_Stone"
    },
    {
      "x": -7,
      "y": 14,
      "z": -4,
      "name": "Rock_Stone"
    },
    {
      "x": -7,
      "y": 15,
      "z": -4,
      "name": "Rock_Stone"
    },
    {
      "x": -7,
      "y": 16,
      "z": -4,
      "name": "Rock_Stone"
    },
    {
      "x": -7,
      "y": 17,
      "z": -4,
      "name": "Rock_Stone"
    },
    {
      "x": -7,
      "y": 18,
      "z": -4,
      "name": "Rock_Stone"
    },
    {
      "x": -7,
      "y": 19,
      "z": -4,
      "name": "Soil_Grass"
    },
    {
      "x": -7,
      "y": 0,
      "z": -3,
      "name": "Rock_Stone"
    },
    {
      "x": -7,
      "y": 1,
      "z": -3,
      "name": "Rock_Stone"
    },
    {
      "x": -7,
      "y": 2,
      "z": -3,
      "name": "Rock_Stone"
    },
    {
      "x": -7,
      "y": 3,
      "z": -3,
      "name": "Rock_Stone"
    },
    {
      "x": -7,
      "y": 4,
      "z": -3,
      "name": "Rock_Stone"
    },
    {
      "x": -7,
      "y": 5,
      "z": -3,
      "name": "Rock_Stone"
    },
    {
      "x": -7,
      "y": 6,
      "z": -3,
      "name": "Rock_Stone"
    },
    {
      "x": -7,
      "y": 7,
      "z": -3,
      "name": "Rock_Stone"
    },
    {
      "x": -7,
      "y": 8,
      "z": -3,
      "name": "Rock_Stone"
    },
    {
      "x": -7,
      "y": 9,
      "z": -3,
      "name": "Rock_Stone"
    },
    {
      "x": -7,
      "y": 10,
      "z": -3,
      "name": "Rock_Stone"
    },
    {
      "x": -7,
      "y": 11,
      "z": -3,
      "name": "Rock_Stone"
    },
    {
      "x": -7,
      "y": 12,
      "z": -3,
      "name": "Rock_Stone"
    },
    {
      "x": -7,
      "y": 13,
      "z": -3,
      "name": "Rock_Stone"
    },
    {
      "x": -7,
      "y": 14,
      "z": -3,
      "name": "Rock_Stone"
    },
    {
      "x": -7,
      "y": 15,
      "z": -3,
      "name": "Rock_Stone"
    },
    {
      "x": -7,
      "y": 16,
      "z": -3,
      "name": "Rock_Stone"
    },
    {
      "x": -7,
      "y": 17,
      "z": -3,
      "name": "Rock_Stone"
    },
    {
      "x": -7,
      "y": 18,
      "z": -3,
      "name": "Soil_Dirt"
    },
    {
      "x": -7,
      "y": 19,
      "z": -3,
      "name": "Soil_Grass"
    },
    {
      "x": -7,
      "y": 0,
      "z": -2,
      "name": "Rock_Stone"
    },
    {
      "x": -7,
      "y": 1,
      "z": -2,
      "name": "Rock_Stone"
    },
    {
      "x": -7,
      "y": 2,
      "z": -2,
      "name": "Rock_Stone"
    },
    {
      "x": -7,
      "y": 3,
      "z": -2,
      "name": "Rock_Stone"
    },
    {
      "x": -7,
      "y": 4,
      "z": -2,
      "name": "Rock_Stone"
    },
    {
      "x": -7,
      "y": 5,
      "z": -2,
      "name": "Rock_Stone"
    },
    {
      "x": -7,
      "y": 6,
      "z": -2,
      "name": "Rock_Stone"
    },
    {
      "x": -7,
      "y": 7,
      "z": -2,
      "name": "Rock_Stone"
    },
    {
      "x": -7,
      "y": 8,
      "z": -2,
      "name": "Rock_Stone"
    },
    {
      "x": -7,
      "y": 9,
      "z": -2,
      "name": "Rock_Stone"
    },
    {
      "x": -7,
      "y": 10,
      "z": -2,
      "name": "Rock_Quartzite"
    },
    {
      "x": -7,
      "y": 11,
      "z": -2,
      "name": "Rock_Quartzite"
    },
    {
      "x": -7,
      "y": 12,
      "z": -2,
      "name": "Rock_Quartzite"
    },
    {
      "x": -7,
      "y": 13,
      "z": -2,
      "name": "Rock_Quartzite"
    },
    {
      "x": -7,
      "y": 14,
      "z": -2,
      "name": "Rock_Quartzite"
    },
    {
      "x": -7,
      "y": 15,
      "z": -2,
      "name": "Rock_Quartzite"
    },
    {
      "x": -7,
      "y": 16,
      "z": -2,
      "name": "Rock_Quartzite"
    },
    {
      "x": -7,
      "y": 17,
      "z": -2,
      "name": "Rock_Quartzite"
    },
    {
      "x": -7,
      "y": 18,
      "z": -2,
      "name": "Soil_Dirt"
    },
    {
      "x": -7,
      "y": 19,
      "z": -2,
      "name": "Soil_Grass"
    },
    {
      "x": -7,
      "y": 0,
      "z": -1,
      "name": "Rock_Stone"
    },
    {
      "x": -7,
      "y": 1,
      "z": -1,
      "name": "Rock_Stone"
    },
    {
      "x": -7,
      "y": 2,
      "z": -1,
      "name": "Rock_Stone"
    },
    {
      "x": -7,
      "y": 3,
      "z": -1,
      "name": "Rock_Stone"
    },
    {
      "x": -7,
      "y": 4,
      "z": -1,
      "name": "Rock_Quartzite"
    },
    {
      "x": -7,
      "y": 5,
      "z": -1,
      "name": "Rock_Quartzite"
    },
    {
      "x": -7,
      "y": 6,
      "z": -1,
      "name": "Rock_Quartzite"
    },
    {
      "x": -7,
      "y": 7,
      "z": -1,
      "name": "Rock_Quartzite"
    },
    {
      "x": -7,
      "y": 8,
      "z": -1,
      "name": "Rock_Quartzite"
    },
    {
      "x": -7,
      "y": 9,
      "z": -1,
      "name": "Rock_Quartzite"
    },
    {
      "x": -7,
      "y": 10,
      "z": -1,
      "name": "Rock_Quartzite"
    },
    {
      "x": -7,
      "y": 11,
      "z": -1,
      "name": "Rock_Quartzite"
    },
    {
      "x": -7,
      "y": 12,
      "z": -1,
      "name": "Rock_Quartzite"
    },
    {
      "x": -7,
      "y": 13,
      "z": -1,
      "name": "Rock_Quartzite"
    },
    {
      "x": -7,
      "y": 14,
      "z": -1,
      "name": "Rock_Quartzite"
    },
    {
      "x": -7,
      "y": 15,
      "z": -1,
      "name": "Rock_Quartzite"
    },
    {
      "x": -7,
      "y": 16,
      "z": -1,
      "name": "Rock_Quartzite"
    },
    {
      "x": -7,
      "y": 17,
      "z": -1,
      "name": "Rock_Quartzite"
    },
    {
      "x": -7,
      "y": 18,
      "z": -1,
      "name": "Soil_Dirt"
    },
    {
      "x": -7,
      "y": 19,
      "z": -1,
      "name": "Soil_Grass"
    },
    {
      "x": -7,
      "y": 0,
      "z": 0,
      "name": "Rock_Stone"
    },
    {
      "x": -7,
      "y": 1,
      "z": 0,
      "name": "Rock_Stone"
    },
    {
      "x": -7,
      "y": 2,
      "z": 0,
      "name": "Rock_Quartzite"
    },
    {
      "x": -7,
      "y": 3,
      "z": 0,
      "name": "Rock_Quartzite"
    },
    {
      "x": -7,
      "y": 4,
      "z": 0,
      "name": "Rock_Quartzite"
    },
    {
      "x": -7,
      "y": 5,
      "z": 0,
      "name": "Rock_Quartzite"
    },
    {
      "x": -7,
      "y": 6,
      "z": 0,
      "name": "Rock_Quartzite"
    },
    {
      "x": -7,
      "y": 7,
      "z": 0,
      "name": "Rock_Quartzite"
    },
    {
      "x": -7,
      "y": 8,
      "z": 0,
      "name": "Rock_Quartzite"
    },
    {
      "x": -7,
      "y": 9,
      "z": 0,
      "name": "Rock_Quartzite"
    },
    {
      "x": -7,
      "y": 10,
      "z": 0,
      "name": "Rock_Quartzite"
    },
    {
      "x": -7,
      "y": 11,
      "z": 0,
      "name": "Rock_Quartzite"
    },
    {
      "x": -7,
      "y": 12,
      "z": 0,
      "name": "Rock_Quartzite"
    },
    {
      "x": -7,
      "y": 13,
      "z": 0,
      "name": "Rock_Quartzite"
    },
    {
      "x": -7,
      "y": 14,
      "z": 0,
      "name": "Rock_Quartzite"
    },
    {
      "x": -7,
      "y": 15,
      "z": 0,
      "name": "Rock_Quartzite"
    },
    {
      "x": -7,
      "y": 16,
      "z": 0,
      "name": "Rock_Quartzite"
    },
    {
      "x": -7,
      "y": 17,
      "z": 0,
      "name": "Rock_Quartzite"
    },
    {
      "x": -7,
      "y": 18,
      "z": 0,
      "name": "Soil_Dirt"
    },
    {
      "x": -7,
      "y": 19,
      "z": 0,
      "name": "Soil_Grass"
    },
    {
      "x": -7,
      "y": 0,
      "z": 1,
      "name": "Rock_Quartzite"
    },
    {
      "x": -7,
      "y": 1,
      "z": 1,
      "name": "Rock_Quartzite"
    },
    {
      "x": -7,
      "y": 2,
      "z": 1,
      "name": "Rock_Quartzite"
    },
    {
      "x": -7,
      "y": 3,
      "z": 1,
      "name": "Rock_Quartzite"
    },
    {
      "x": -7,
      "y": 4,
      "z": 1,
      "name": "Rock_Quartzite"
    },
    {
      "x": -7,
      "y": 5,
      "z": 1,
      "name": "Rock_Quartzite"
    },
    {
      "x": -7,
      "y": 6,
      "z": 1,
      "name": "Rock_Quartzite"
    },
    {
      "x": -7,
      "y": 7,
      "z": 1,
      "name": "Rock_Quartzite"
    },
    {
      "x": -7,
      "y": 8,
      "z": 1,
      "name": "Rock_Quartzite"
    },
    {
      "x": -7,
      "y": 9,
      "z": 1,
      "name": "Rock_Quartzite"
    },
    {
      "x": -7,
      "y": 10,
      "z": 1,
      "name": "Rock_Quartzite"
    },
    {
      "x": -7,
      "y": 11,
      "z": 1,
      "name": "Rock_Quartzite"
    },
    {
      "x": -7,
      "y": 12,
      "z": 1,
      "name": "Rock_Quartzite"
    },
    {
      "x": -7,
      "y": 13,
      "z": 1,
      "name": "Rock_Quartzite"
    },
    {
      "x": -7,
      "y": 14,
      "z": 1,
      "name": "Rock_Quartzite"
    },
    {
      "x": -7,
      "y": 15,
      "z": 1,
      "name": "Rock_Quartzite"
    },
    {
      "x": -7,
      "y": 16,
      "z": 1,
      "name": "Rock_Quartzite"
    },
    {
      "x": -7,
      "y": 17,
      "z": 1,
      "name": "Rock_Quartzite"
    },
    {
      "x": -7,
      "y": 18,
      "z": 1,
      "name": "Soil_Dirt"
    },
    {
      "x": -7,
      "y": 19,
      "z": 1,
      "name": "Soil_Grass"
    },
    {
      "x": -7,
      "y": 0,
      "z": 2,
      "name": "Rock_Quartzite"
    },
    {
      "x": -7,
      "y": 1,
      "z": 2,
      "name": "Rock_Quartzite"
    },
    {
      "x": -7,
      "y": 2,
      "z": 2,
      "name": "Rock_Quartzite"
    },
    {
      "x": -7,
      "y": 3,
      "z": 2,
      "name": "Rock_Quartzite"
    },
    {
      "x": -7,
      "y": 4,
      "z": 2,
      "name": "Rock_Quartzite"
    },
    {
      "x": -7,
      "y": 5,
      "z": 2,
      "name": "Rock_Quartzite"
    },
    {
      "x": -7,
      "y": 6,
      "z": 2,
      "name": "Rock_Quartzite"
    },
    {
      "x": -7,
      "y": 7,
      "z": 2,
      "name": "Rock_Quartzite"
    },
    {
      "x": -7,
      "y": 8,
      "z": 2,
      "name": "Rock_Quartzite"
    },
    {
      "x": -7,
      "y": 9,
      "z": 2,
      "name": "Rock_Quartzite"
    },
    {
      "x": -7,
      "y": 10,
      "z": 2,
      "name": "Rock_Quartzite"
    },
    {
      "x": -7,
      "y": 11,
      "z": 2,
      "name": "Rock_Quartzite"
    },
    {
      "x": -7,
      "y": 12,
      "z": 2,
      "name": "Rock_Quartzite"
    },
    {
      "x": -7,
      "y": 13,
      "z": 2,
      "name": "Rock_Quartzite"
    },
    {
      "x": -7,
      "y": 14,
      "z": 2,
      "name": "Rock_Quartzite"
    },
    {
      "x": -7,
      "y": 15,
      "z": 2,
      "name": "Rock_Quartzite"
    },
    {
      "x": -7,
      "y": 16,
      "z": 2,
      "name": "Rock_Quartzite"
    },
    {
      "x": -7,
      "y": 17,
      "z": 2,
      "name": "Rock_Quartzite"
    },
    {
      "x": -7,
      "y": 18,
      "z": 2,
      "name": "Soil_Dirt"
    },
    {
      "x": -7,
      "y": 19,
      "z": 2,
      "name": "Soil_Grass"
    },
    {
      "x": -7,
      "y": 0,
      "z": 3,
      "name": "Rock_Quartzite"
    },
    {
      "x": -7,
      "y": 1,
      "z": 3,
      "name": "Rock_Quartzite"
    },
    {
      "x": -7,
      "y": 2,
      "z": 3,
      "name": "Rock_Quartzite"
    },
    {
      "x": -7,
      "y": 3,
      "z": 3,
      "name": "Rock_Quartzite"
    },
    {
      "x": -7,
      "y": 4,
      "z": 3,
      "name": "Rock_Quartzite"
    },
    {
      "x": -7,
      "y": 5,
      "z": 3,
      "name": "Rock_Quartzite"
    },
    {
      "x": -7,
      "y": 6,
      "z": 3,
      "name": "Rock_Quartzite"
    },
    {
      "x": -7,
      "y": 7,
      "z": 3,
      "name": "Rock_Quartzite"
    },
    {
      "x": -7,
      "y": 8,
      "z": 3,
      "name": "Rock_Quartzite"
    },
    {
      "x": -7,
      "y": 9,
      "z": 3,
      "name": "Rock_Quartzite"
    },
    {
      "x": -7,
      "y": 10,
      "z": 3,
      "name": "Rock_Quartzite"
    },
    {
      "x": -7,
      "y": 11,
      "z": 3,
      "name": "Rock_Quartzite"
    },
    {
      "x": -7,
      "y": 12,
      "z": 3,
      "name": "Rock_Quartzite"
    },
    {
      "x": -7,
      "y": 13,
      "z": 3,
      "name": "Rock_Quartzite"
    },
    {
      "x": -7,
      "y": 14,
      "z": 3,
      "name": "Rock_Quartzite"
    },
    {
      "x": -7,
      "y": 15,
      "z": 3,
      "name": "Rock_Quartzite"
    },
    {
      "x": -7,
      "y": 16,
      "z": 3,
      "name": "Rock_Quartzite"
    },
    {
      "x": -7,
      "y": 17,
      "z": 3,
      "name": "Rock_Quartzite"
    },
    {
      "x": -7,
      "y": 18,
      "z": 3,
      "name": "Soil_Grass"
    },
    {
      "x": -7,
      "y": 0,
      "z": 4,
      "name": "Rock_Quartzite"
    },
    {
      "x": -7,
      "y": 1,
      "z": 4,
      "name": "Rock_Quartzite"
    },
    {
      "x": -7,
      "y": 2,
      "z": 4,
      "name": "Rock_Quartzite"
    },
    {
      "x": -7,
      "y": 3,
      "z": 4,
      "name": "Rock_Quartzite"
    },
    {
      "x": -7,
      "y": 4,
      "z": 4,
      "name": "Rock_Quartzite"
    },
    {
      "x": -7,
      "y": 5,
      "z": 4,
      "name": "Rock_Quartzite"
    },
    {
      "x": -7,
      "y": 6,
      "z": 4,
      "name": "Rock_Quartzite"
    },
    {
      "x": -7,
      "y": 7,
      "z": 4,
      "name": "Rock_Quartzite"
    },
    {
      "x": -7,
      "y": 8,
      "z": 4,
      "name": "Rock_Quartzite"
    },
    {
      "x": -7,
      "y": 9,
      "z": 4,
      "name": "Rock_Quartzite"
    },
    {
      "x": -7,
      "y": 10,
      "z": 4,
      "name": "Rock_Quartzite"
    },
    {
      "x": -7,
      "y": 11,
      "z": 4,
      "name": "Rock_Quartzite"
    },
    {
      "x": -7,
      "y": 12,
      "z": 4,
      "name": "Rock_Quartzite"
    },
    {
      "x": -7,
      "y": 13,
      "z": 4,
      "name": "Rock_Quartzite"
    },
    {
      "x": -7,
      "y": 14,
      "z": 4,
      "name": "Rock_Quartzite"
    },
    {
      "x": -7,
      "y": 15,
      "z": 4,
      "name": "Rock_Quartzite"
    },
    {
      "x": -7,
      "y": 16,
      "z": 4,
      "name": "Rock_Quartzite"
    },
    {
      "x": -7,
      "y": 17,
      "z": 4,
      "name": "Rock_Quartzite"
    },
    {
      "x": -7,
      "y": 18,
      "z": 4,
      "name": "Soil_Grass"
    },
    {
      "x": -7,
      "y": 0,
      "z": 5,
      "name": "Rock_Quartzite"
    },
    {
      "x": -7,
      "y": 1,
      "z": 5,
      "name": "Rock_Quartzite"
    },
    {
      "x": -7,
      "y": 2,
      "z": 5,
      "name": "Rock_Quartzite"
    },
    {
      "x": -7,
      "y": 3,
      "z": 5,
      "name": "Rock_Quartzite"
    },
    {
      "x": -7,
      "y": 4,
      "z": 5,
      "name": "Rock_Quartzite"
    },
    {
      "x": -7,
      "y": 5,
      "z": 5,
      "name": "Rock_Quartzite"
    },
    {
      "x": -7,
      "y": 6,
      "z": 5,
      "name": "Rock_Quartzite"
    },
    {
      "x": -7,
      "y": 7,
      "z": 5,
      "name": "Rock_Quartzite"
    },
    {
      "x": -7,
      "y": 8,
      "z": 5,
      "name": "Rock_Quartzite"
    },
    {
      "x": -7,
      "y": 9,
      "z": 5,
      "name": "Rock_Quartzite"
    },
    {
      "x": -7,
      "y": 10,
      "z": 5,
      "name": "Rock_Quartzite"
    },
    {
      "x": -7,
      "y": 11,
      "z": 5,
      "name": "Rock_Quartzite"
    },
    {
      "x": -7,
      "y": 12,
      "z": 5,
      "name": "Rock_Quartzite"
    },
    {
      "x": -7,
      "y": 13,
      "z": 5,
      "name": "Rock_Quartzite"
    },
    {
      "x": -7,
      "y": 14,
      "z": 5,
      "name": "Rock_Quartzite"
    },
    {
      "x": -7,
      "y": 15,
      "z": 5,
      "name": "Rock_Quartzite"
    },
    {
      "x": -7,
      "y": 16,
      "z": 5,
      "name": "Rock_Quartzite"
    },
    {
      "x": -7,
      "y": 17,
      "z": 5,
      "name": "Rock_Quartzite"
    },
    {
      "x": -7,
      "y": 18,
      "z": 5,
      "name": "Soil_Grass"
    },
    {
      "x": -7,
      "y": 0,
      "z": 6,
      "name": "Rock_Quartzite"
    },
    {
      "x": -7,
      "y": 1,
      "z": 6,
      "name": "Rock_Quartzite"
    },
    {
      "x": -7,
      "y": 2,
      "z": 6,
      "name": "Rock_Quartzite"
    },
    {
      "x": -7,
      "y": 3,
      "z": 6,
      "name": "Rock_Quartzite"
    },
    {
      "x": -7,
      "y": 4,
      "z": 6,
      "name": "Rock_Quartzite"
    },
    {
      "x": -7,
      "y": 5,
      "z": 6,
      "name": "Rock_Quartzite"
    },
    {
      "x": -7,
      "y": 6,
      "z": 6,
      "name": "Rock_Quartzite"
    },
    {
      "x": -7,
      "y": 7,
      "z": 6,
      "name": "Rock_Quartzite"
    },
    {
      "x": -7,
      "y": 8,
      "z": 6,
      "name": "Rock_Quartzite"
    },
    {
      "x": -7,
      "y": 9,
      "z": 6,
      "name": "Rock_Quartzite"
    },
    {
      "x": -7,
      "y": 10,
      "z": 6,
      "name": "Rock_Quartzite"
    },
    {
      "x": -7,
      "y": 11,
      "z": 6,
      "name": "Rock_Quartzite"
    },
    {
      "x": -7,
      "y": 12,
      "z": 6,
      "name": "Rock_Quartzite"
    },
    {
      "x": -7,
      "y": 13,
      "z": 6,
      "name": "Rock_Quartzite"
    },
    {
      "x": -7,
      "y": 14,
      "z": 6,
      "name": "Rock_Quartzite"
    },
    {
      "x": -7,
      "y": 15,
      "z": 6,
      "name": "Rock_Quartzite"
    },
    {
      "x": -7,
      "y": 16,
      "z": 6,
      "name": "Rock_Quartzite"
    },
    {
      "x": -7,
      "y": 17,
      "z": 6,
      "name": "Rock_Quartzite"
    },
    {
      "x": -7,
      "y": 18,
      "z": 6,
      "name": "Soil_Dirt"
    },
    {
      "x": -7,
      "y": 19,
      "z": 6,
      "name": "Soil_Grass"
    },
    {
      "x": -7,
      "y": 0,
      "z": 7,
      "name": "Rock_Quartzite"
    },
    {
      "x": -7,
      "y": 1,
      "z": 7,
      "name": "Rock_Quartzite"
    },
    {
      "x": -7,
      "y": 2,
      "z": 7,
      "name": "Rock_Quartzite"
    },
    {
      "x": -7,
      "y": 3,
      "z": 7,
      "name": "Rock_Quartzite"
    },
    {
      "x": -7,
      "y": 4,
      "z": 7,
      "name": "Rock_Quartzite"
    },
    {
      "x": -7,
      "y": 5,
      "z": 7,
      "name": "Rock_Quartzite"
    },
    {
      "x": -7,
      "y": 6,
      "z": 7,
      "name": "Rock_Quartzite"
    },
    {
      "x": -7,
      "y": 7,
      "z": 7,
      "name": "Rock_Quartzite"
    },
    {
      "x": -7,
      "y": 8,
      "z": 7,
      "name": "Rock_Quartzite"
    },
    {
      "x": -7,
      "y": 10,
      "z": 7,
      "name": "Rock_Quartzite"
    },
    {
      "x": -7,
      "y": 11,
      "z": 7,
      "name": "Rock_Quartzite"
    },
    {
      "x": -7,
      "y": 12,
      "z": 7,
      "name": "Rock_Quartzite"
    },
    {
      "x": -7,
      "y": 13,
      "z": 7,
      "name": "Rock_Quartzite"
    },
    {
      "x": -7,
      "y": 14,
      "z": 7,
      "name": "Rock_Quartzite"
    },
    {
      "x": -7,
      "y": 15,
      "z": 7,
      "name": "Rock_Quartzite"
    },
    {
      "x": -7,
      "y": 16,
      "z": 7,
      "name": "Rock_Quartzite"
    },
    {
      "x": -7,
      "y": 17,
      "z": 7,
      "name": "Rock_Stone"
    },
    {
      "x": -7,
      "y": 18,
      "z": 7,
      "name": "Rock_Stone"
    },
    {
      "x": -7,
      "y": 19,
      "z": 7,
      "name": "Soil_Grass"
    },
    {
      "x": -7,
      "y": 17,
      "z": 8,
      "name": "Rock_Stone"
    },
    {
      "x": -7,
      "y": 18,
      "z": 8,
      "name": "Rock_Stone"
    },
    {
      "x": -7,
      "y": 19,
      "z": 8,
      "name": "Rock_Stone"
    },
    {
      "x": -6,
      "y": 7,
      "z": -8,
      "name": "Rock_Stone"
    },
    {
      "x": -6,
      "y": 8,
      "z": -8,
      "name": "Rock_Stone"
    },
    {
      "x": -6,
      "y": 9,
      "z": -8,
      "name": "Rock_Stone"
    },
    {
      "x": -6,
      "y": 10,
      "z": -8,
      "name": "Rock_Stone"
    },
    {
      "x": -6,
      "y": 11,
      "z": -8,
      "name": "Rock_Stone"
    },
    {
      "x": -6,
      "y": 12,
      "z": -8,
      "name": "Rock_Stone"
    },
    {
      "x": -6,
      "y": 13,
      "z": -8,
      "name": "Rock_Stone"
    },
    {
      "x": -6,
      "y": 14,
      "z": -8,
      "name": "Rock_Stone"
    },
    {
      "x": -6,
      "y": 15,
      "z": -8,
      "name": "Rock_Stone"
    },
    {
      "x": -6,
      "y": 16,
      "z": -8,
      "name": "Rock_Stone"
    },
    {
      "x": -6,
      "y": 2,
      "z": -7,
      "name": "Rock_Stone"
    },
    {
      "x": -6,
      "y": 3,
      "z": -7,
      "name": "Rock_Stone"
    },
    {
      "x": -6,
      "y": 4,
      "z": -7,
      "name": "Rock_Stone"
    },
    {
      "x": -6,
      "y": 5,
      "z": -7,
      "name": "Rock_Stone"
    },
    {
      "x": -6,
      "y": 6,
      "z": -7,
      "name": "Rock_Stone"
    },
    {
      "x": -6,
      "y": 7,
      "z": -7,
      "name": "Rock_Stone"
    },
    {
      "x": -6,
      "y": 8,
      "z": -7,
      "name": "Rock_Stone"
    },
    {
      "x": -6,
      "y": 9,
      "z": -7,
      "name": "Rock_Stone"
    },
    {
      "x": -6,
      "y": 10,
      "z": -7,
      "name": "Rock_Stone"
    },
    {
      "x": -6,
      "y": 11,
      "z": -7,
      "name": "Rock_Stone"
    },
    {
      "x": -6,
      "y": 12,
      "z": -7,
      "name": "Rock_Stone"
    },
    {
      "x": -6,
      "y": 13,
      "z": -7,
      "name": "Rock_Stone"
    },
    {
      "x": -6,
      "y": 14,
      "z": -7,
      "name": "Rock_Stone"
    },
    {
      "x": -6,
      "y": 15,
      "z": -7,
      "name": "Rock_Stone"
    },
    {
      "x": -6,
      "y": 16,
      "z": -7,
      "name": "Rock_Stone"
    },
    {
      "x": -6,
      "y": 17,
      "z": -7,
      "name": "Rock_Stone"
    },
    {
      "x": -6,
      "y": 18,
      "z": -7,
      "name": "Rock_Stone"
    },
    {
      "x": -6,
      "y": 19,
      "z": -7,
      "name": "Rock_Stone"
    },
    {
      "x": -6,
      "y": 20,
      "z": -7,
      "name": "Soil_Grass"
    },
    {
      "x": -6,
      "y": 0,
      "z": -6,
      "name": "Rock_Stone"
    },
    {
      "x": -6,
      "y": 1,
      "z": -6,
      "name": "Rock_Stone"
    },
    {
      "x": -6,
      "y": 2,
      "z": -6,
      "name": "Rock_Stone"
    },
    {
      "x": -6,
      "y": 3,
      "z": -6,
      "name": "Rock_Stone"
    },
    {
      "x": -6,
      "y": 4,
      "z": -6,
      "name": "Rock_Stone"
    },
    {
      "x": -6,
      "y": 5,
      "z": -6,
      "name": "Rock_Stone"
    },
    {
      "x": -6,
      "y": 6,
      "z": -6,
      "name": "Rock_Stone"
    },
    {
      "x": -6,
      "y": 7,
      "z": -6,
      "name": "Rock_Stone"
    },
    {
      "x": -6,
      "y": 8,
      "z": -6,
      "name": "Rock_Stone"
    },
    {
      "x": -6,
      "y": 9,
      "z": -6,
      "name": "Rock_Stone"
    },
    {
      "x": -6,
      "y": 10,
      "z": -6,
      "name": "Rock_Stone"
    },
    {
      "x": -6,
      "y": 11,
      "z": -6,
      "name": "Rock_Stone"
    },
    {
      "x": -6,
      "y": 12,
      "z": -6,
      "name": "Rock_Stone"
    },
    {
      "x": -6,
      "y": 13,
      "z": -6,
      "name": "Rock_Stone"
    },
    {
      "x": -6,
      "y": 14,
      "z": -6,
      "name": "Rock_Stone"
    },
    {
      "x": -6,
      "y": 15,
      "z": -6,
      "name": "Rock_Stone"
    },
    {
      "x": -6,
      "y": 16,
      "z": -6,
      "name": "Rock_Stone"
    },
    {
      "x": -6,
      "y": 17,
      "z": -6,
      "name": "Rock_Stone"
    },
    {
      "x": -6,
      "y": 18,
      "z": -6,
      "name": "Rock_Stone"
    },
    {
      "x": -6,
      "y": 19,
      "z": -6,
      "name": "Soil_Dirt"
    },
    {
      "x": -6,
      "y": 20,
      "z": -6,
      "name": "Soil_Grass"
    },
    {
      "x": -6,
      "y": 0,
      "z": -5,
      "name": "Rock_Stone"
    },
    {
      "x": -6,
      "y": 1,
      "z": -5,
      "name": "Rock_Stone"
    },
    {
      "x": -6,
      "y": 2,
      "z": -5,
      "name": "Rock_Stone"
    },
    {
      "x": -6,
      "y": 3,
      "z": -5,
      "name": "Rock_Stone"
    },
    {
      "x": -6,
      "y": 4,
      "z": -5,
      "name": "Rock_Stone"
    },
    {
      "x": -6,
      "y": 5,
      "z": -5,
      "name": "Rock_Stone"
    },
    {
      "x": -6,
      "y": 6,
      "z": -5,
      "name": "Rock_Stone"
    },
    {
      "x": -6,
      "y": 7,
      "z": -5,
      "name": "Rock_Stone"
    },
    {
      "x": -6,
      "y": 8,
      "z": -5,
      "name": "Rock_Stone"
    },
    {
      "x": -6,
      "y": 9,
      "z": -5,
      "name": "Rock_Stone"
    },
    {
      "x": -6,
      "y": 10,
      "z": -5,
      "name": "Rock_Stone"
    },
    {
      "x": -6,
      "y": 11,
      "z": -5,
      "name": "Rock_Stone"
    },
    {
      "x": -6,
      "y": 12,
      "z": -5,
      "name": "Rock_Stone"
    },
    {
      "x": -6,
      "y": 13,
      "z": -5,
      "name": "Rock_Stone"
    },
    {
      "x": -6,
      "y": 14,
      "z": -5,
      "name": "Rock_Stone"
    },
    {
      "x": -6,
      "y": 15,
      "z": -5,
      "name": "Rock_Stone"
    },
    {
      "x": -6,
      "y": 16,
      "z": -5,
      "name": "Rock_Stone"
    },
    {
      "x": -6,
      "y": 17,
      "z": -5,
      "name": "Rock_Stone"
    },
    {
      "x": -6,
      "y": 18,
      "z": -5,
      "name": "Rock_Stone"
    },
    {
      "x": -6,
      "y": 19,
      "z": -5,
      "name": "Soil_Dirt"
    },
    {
      "x": -6,
      "y": 20,
      "z": -5,
      "name": "Soil_Grass"
    },
    {
      "x": -6,
      "y": 0,
      "z": -4,
      "name": "Rock_Stone"
    },
    {
      "x": -6,
      "y": 1,
      "z": -4,
      "name": "Rock_Stone"
    },
    {
      "x": -6,
      "y": 2,
      "z": -4,
      "name": "Rock_Stone"
    },
    {
      "x": -6,
      "y": 3,
      "z": -4,
      "name": "Rock_Stone"
    },
    {
      "x": -6,
      "y": 4,
      "z": -4,
      "name": "Rock_Stone"
    },
    {
      "x": -6,
      "y": 5,
      "z": -4,
      "name": "Rock_Stone"
    },
    {
      "x": -6,
      "y": 6,
      "z": -4,
      "name": "Rock_Stone"
    },
    {
      "x": -6,
      "y": 7,
      "z": -4,
      "name": "Rock_Stone"
    },
    {
      "x": -6,
      "y": 8,
      "z": -4,
      "name": "Rock_Stone"
    },
    {
      "x": -6,
      "y": 9,
      "z": -4,
      "name": "Rock_Stone"
    },
    {
      "x": -6,
      "y": 10,
      "z": -4,
      "name": "Rock_Stone"
    },
    {
      "x": -6,
      "y": 11,
      "z": -4,
      "name": "Rock_Stone"
    },
    {
      "x": -6,
      "y": 12,
      "z": -4,
      "name": "Rock_Stone"
    },
    {
      "x": -6,
      "y": 13,
      "z": -4,
      "name": "Rock_Stone"
    },
    {
      "x": -6,
      "y": 14,
      "z": -4,
      "name": "Rock_Stone"
    },
    {
      "x": -6,
      "y": 15,
      "z": -4,
      "name": "Rock_Stone"
    },
    {
      "x": -6,
      "y": 16,
      "z": -4,
      "name": "Rock_Stone"
    },
    {
      "x": -6,
      "y": 17,
      "z": -4,
      "name": "Rock_Stone"
    },
    {
      "x": -6,
      "y": 18,
      "z": -4,
      "name": "Soil_Dirt"
    },
    {
      "x": -6,
      "y": 19,
      "z": -4,
      "name": "Soil_Dirt"
    },
    {
      "x": -6,
      "y": 20,
      "z": -4,
      "name": "Soil_Grass"
    },
    {
      "x": -6,
      "y": 0,
      "z": -3,
      "name": "Rock_Stone"
    },
    {
      "x": -6,
      "y": 1,
      "z": -3,
      "name": "Rock_Stone"
    },
    {
      "x": -6,
      "y": 2,
      "z": -3,
      "name": "Rock_Stone"
    },
    {
      "x": -6,
      "y": 3,
      "z": -3,
      "name": "Rock_Stone"
    },
    {
      "x": -6,
      "y": 4,
      "z": -3,
      "name": "Rock_Stone"
    },
    {
      "x": -6,
      "y": 5,
      "z": -3,
      "name": "Rock_Stone"
    },
    {
      "x": -6,
      "y": 6,
      "z": -3,
      "name": "Rock_Stone"
    },
    {
      "x": -6,
      "y": 7,
      "z": -3,
      "name": "Rock_Stone"
    },
    {
      "x": -6,
      "y": 8,
      "z": -3,
      "name": "Rock_Quartzite"
    },
    {
      "x": -6,
      "y": 9,
      "z": -3,
      "name": "Rock_Quartzite"
    },
    {
      "x": -6,
      "y": 10,
      "z": -3,
      "name": "Rock_Quartzite"
    },
    {
      "x": -6,
      "y": 11,
      "z": -3,
      "name": "Rock_Quartzite"
    },
    {
      "x": -6,
      "y": 12,
      "z": -3,
      "name": "Rock_Quartzite"
    },
    {
      "x": -6,
      "y": 13,
      "z": -3,
      "name": "Rock_Quartzite"
    },
    {
      "x": -6,
      "y": 14,
      "z": -3,
      "name": "Rock_Quartzite"
    },
    {
      "x": -6,
      "y": 15,
      "z": -3,
      "name": "Rock_Quartzite"
    },
    {
      "x": -6,
      "y": 16,
      "z": -3,
      "name": "Rock_Quartzite"
    },
    {
      "x": -6,
      "y": 17,
      "z": -3,
      "name": "Rock_Quartzite"
    },
    {
      "x": -6,
      "y": 18,
      "z": -3,
      "name": "Soil_Dirt"
    },
    {
      "x": -6,
      "y": 19,
      "z": -3,
      "name": "Soil_Grass"
    },
    {
      "x": -6,
      "y": 0,
      "z": -2,
      "name": "Rock_Stone"
    },
    {
      "x": -6,
      "y": 1,
      "z": -2,
      "name": "Rock_Stone"
    },
    {
      "x": -6,
      "y": 2,
      "z": -2,
      "name": "Rock_Stone"
    },
    {
      "x": -6,
      "y": 3,
      "z": -2,
      "name": "Rock_Stone"
    },
    {
      "x": -6,
      "y": 4,
      "z": -2,
      "name": "Rock_Stone"
    },
    {
      "x": -6,
      "y": 5,
      "z": -2,
      "name": "Rock_Quartzite"
    },
    {
      "x": -6,
      "y": 6,
      "z": -2,
      "name": "Rock_Quartzite"
    },
    {
      "x": -6,
      "y": 7,
      "z": -2,
      "name": "Rock_Quartzite"
    },
    {
      "x": -6,
      "y": 8,
      "z": -2,
      "name": "Rock_Quartzite"
    },
    {
      "x": -6,
      "y": 9,
      "z": -2,
      "name": "Rock_Quartzite"
    },
    {
      "x": -6,
      "y": 10,
      "z": -2,
      "name": "Rock_Quartzite"
    },
    {
      "x": -6,
      "y": 11,
      "z": -2,
      "name": "Rock_Quartzite"
    },
    {
      "x": -6,
      "y": 12,
      "z": -2,
      "name": "Rock_Quartzite"
    },
    {
      "x": -6,
      "y": 13,
      "z": -2,
      "name": "Rock_Quartzite"
    },
    {
      "x": -6,
      "y": 14,
      "z": -2,
      "name": "Rock_Quartzite"
    },
    {
      "x": -6,
      "y": 15,
      "z": -2,
      "name": "Rock_Quartzite"
    },
    {
      "x": -6,
      "y": 16,
      "z": -2,
      "name": "Rock_Quartzite"
    },
    {
      "x": -6,
      "y": 17,
      "z": -2,
      "name": "Soil_Dirt"
    },
    {
      "x": -6,
      "y": 18,
      "z": -2,
      "name": "Soil_Dirt"
    },
    {
      "x": -6,
      "y": 19,
      "z": -2,
      "name": "Soil_Grass"
    },
    {
      "x": -6,
      "y": 0,
      "z": -1,
      "name": "Rock_Stone"
    },
    {
      "x": -6,
      "y": 1,
      "z": -1,
      "name": "Rock_Stone"
    },
    {
      "x": -6,
      "y": 2,
      "z": -1,
      "name": "Rock_Stone"
    },
    {
      "x": -6,
      "y": 3,
      "z": -1,
      "name": "Rock_Quartzite"
    },
    {
      "x": -6,
      "y": 4,
      "z": -1,
      "name": "Rock_Quartzite"
    },
    {
      "x": -6,
      "y": 5,
      "z": -1,
      "name": "Rock_Quartzite"
    },
    {
      "x": -6,
      "y": 6,
      "z": -1,
      "name": "Rock_Quartzite"
    },
    {
      "x": -6,
      "y": 7,
      "z": -1,
      "name": "Rock_Quartzite"
    },
    {
      "x": -6,
      "y": 8,
      "z": -1,
      "name": "Rock_Quartzite"
    },
    {
      "x": -6,
      "y": 9,
      "z": -1,
      "name": "Rock_Quartzite"
    },
    {
      "x": -6,
      "y": 10,
      "z": -1,
      "name": "Rock_Quartzite"
    },
    {
      "x": -6,
      "y": 11,
      "z": -1,
      "name": "Rock_Quartzite"
    },
    {
      "x": -6,
      "y": 12,
      "z": -1,
      "name": "Rock_Quartzite"
    },
    {
      "x": -6,
      "y": 13,
      "z": -1,
      "name": "Rock_Quartzite"
    },
    {
      "x": -6,
      "y": 14,
      "z": -1,
      "name": "Rock_Quartzite"
    },
    {
      "x": -6,
      "y": 15,
      "z": -1,
      "name": "Rock_Quartzite"
    },
    {
      "x": -6,
      "y": 16,
      "z": -1,
      "name": "Rock_Quartzite"
    },
    {
      "x": -6,
      "y": 17,
      "z": -1,
      "name": "Soil_Dirt"
    },
    {
      "x": -6,
      "y": 18,
      "z": -1,
      "name": "Soil_Dirt"
    },
    {
      "x": -6,
      "y": 19,
      "z": -1,
      "name": "Soil_Grass"
    },
    {
      "x": -6,
      "y": 0,
      "z": 0,
      "name": "Rock_Stone"
    },
    {
      "x": -6,
      "y": 1,
      "z": 0,
      "name": "Rock_Stone"
    },
    {
      "x": -6,
      "y": 2,
      "z": 0,
      "name": "Rock_Quartzite"
    },
    {
      "x": -6,
      "y": 3,
      "z": 0,
      "name": "Rock_Quartzite"
    },
    {
      "x": -6,
      "y": 4,
      "z": 0,
      "name": "Rock_Quartzite"
    },
    {
      "x": -6,
      "y": 5,
      "z": 0,
      "name": "Rock_Quartzite"
    },
    {
      "x": -6,
      "y": 6,
      "z": 0,
      "name": "Rock_Quartzite"
    },
    {
      "x": -6,
      "y": 7,
      "z": 0,
      "name": "Rock_Quartzite"
    },
    {
      "x": -6,
      "y": 8,
      "z": 0,
      "name": "Rock_Quartzite"
    },
    {
      "x": -6,
      "y": 9,
      "z": 0,
      "name": "Rock_Quartzite"
    },
    {
      "x": -6,
      "y": 10,
      "z": 0,
      "name": "Rock_Quartzite"
    },
    {
      "x": -6,
      "y": 11,
      "z": 0,
      "name": "Rock_Quartzite"
    },
    {
      "x": -6,
      "y": 12,
      "z": 0,
      "name": "Rock_Quartzite"
    },
    {
      "x": -6,
      "y": 13,
      "z": 0,
      "name": "Rock_Quartzite"
    },
    {
      "x": -6,
      "y": 14,
      "z": 0,
      "name": "Rock_Quartzite"
    },
    {
      "x": -6,
      "y": 15,
      "z": 0,
      "name": "Rock_Quartzite"
    },
    {
      "x": -6,
      "y": 16,
      "z": 0,
      "name": "Rock_Quartzite"
    },
    {
      "x": -6,
      "y": 17,
      "z": 0,
      "name": "Soil_Dirt"
    },
    {
      "x": -6,
      "y": 18,
      "z": 0,
      "name": "Soil_Dirt"
    },
    {
      "x": -6,
      "y": 19,
      "z": 0,
      "name": "Soil_Grass"
    },
    {
      "x": -6,
      "y": 0,
      "z": 1,
      "name": "Rock_Stone"
    },
    {
      "x": -6,
      "y": 1,
      "z": 1,
      "name": "Rock_Quartzite"
    },
    {
      "x": -6,
      "y": 2,
      "z": 1,
      "name": "Rock_Quartzite"
    },
    {
      "x": -6,
      "y": 3,
      "z": 1,
      "name": "Rock_Quartzite"
    },
    {
      "x": -6,
      "y": 4,
      "z": 1,
      "name": "Rock_Quartzite"
    },
    {
      "x": -6,
      "y": 5,
      "z": 1,
      "name": "Rock_Quartzite"
    },
    {
      "x": -6,
      "y": 6,
      "z": 1,
      "name": "Rock_Quartzite"
    },
    {
      "x": -6,
      "y": 7,
      "z": 1,
      "name": "Rock_Quartzite"
    },
    {
      "x": -6,
      "y": 8,
      "z": 1,
      "name": "Rock_Quartzite"
    },
    {
      "x": -6,
      "y": 9,
      "z": 1,
      "name": "Rock_Quartzite"
    },
    {
      "x": -6,
      "y": 10,
      "z": 1,
      "name": "Rock_Quartzite"
    },
    {
      "x": -6,
      "y": 11,
      "z": 1,
      "name": "Rock_Quartzite"
    },
    {
      "x": -6,
      "y": 12,
      "z": 1,
      "name": "Rock_Quartzite"
    },
    {
      "x": -6,
      "y": 13,
      "z": 1,
      "name": "Rock_Quartzite"
    },
    {
      "x": -6,
      "y": 14,
      "z": 1,
      "name": "Rock_Quartzite"
    },
    {
      "x": -6,
      "y": 15,
      "z": 1,
      "name": "Rock_Quartzite"
    },
    {
      "x": -6,
      "y": 16,
      "z": 1,
      "name": "Rock_Quartzite"
    },
    {
      "x": -6,
      "y": 17,
      "z": 1,
      "name": "Soil_Dirt"
    },
    {
      "x": -6,
      "y": 18,
      "z": 1,
      "name": "Soil_Dirt"
    },
    {
      "x": -6,
      "y": 19,
      "z": 1,
      "name": "Soil_Grass"
    },
    {
      "x": -6,
      "y": 0,
      "z": 2,
      "name": "Rock_Quartzite"
    },
    {
      "x": -6,
      "y": 1,
      "z": 2,
      "name": "Rock_Quartzite"
    },
    {
      "x": -6,
      "y": 2,
      "z": 2,
      "name": "Rock_Quartzite"
    },
    {
      "x": -6,
      "y": 3,
      "z": 2,
      "name": "Rock_Quartzite"
    },
    {
      "x": -6,
      "y": 4,
      "z": 2,
      "name": "Rock_Quartzite"
    },
    {
      "x": -6,
      "y": 5,
      "z": 2,
      "name": "Rock_Quartzite"
    },
    {
      "x": -6,
      "y": 6,
      "z": 2,
      "name": "Rock_Quartzite"
    },
    {
      "x": -6,
      "y": 7,
      "z": 2,
      "name": "Rock_Quartzite"
    },
    {
      "x": -6,
      "y": 8,
      "z": 2,
      "name": "Rock_Quartzite"
    },
    {
      "x": -6,
      "y": 9,
      "z": 2,
      "name": "Rock_Quartzite"
    },
    {
      "x": -6,
      "y": 10,
      "z": 2,
      "name": "Rock_Quartzite"
    },
    {
      "x": -6,
      "y": 11,
      "z": 2,
      "name": "Rock_Quartzite"
    },
    {
      "x": -6,
      "y": 12,
      "z": 2,
      "name": "Rock_Quartzite"
    },
    {
      "x": -6,
      "y": 13,
      "z": 2,
      "name": "Rock_Quartzite"
    },
    {
      "x": -6,
      "y": 14,
      "z": 2,
      "name": "Rock_Quartzite"
    },
    {
      "x": -6,
      "y": 15,
      "z": 2,
      "name": "Rock_Quartzite"
    },
    {
      "x": -6,
      "y": 16,
      "z": 2,
      "name": "Rock_Quartzite"
    },
    {
      "x": -6,
      "y": 17,
      "z": 2,
      "name": "Soil_Dirt"
    },
    {
      "x": -6,
      "y": 18,
      "z": 2,
      "name": "Soil_Dirt"
    },
    {
      "x": -6,
      "y": 19,
      "z": 2,
      "name": "Soil_Grass"
    },
    {
      "x": -6,
      "y": 0,
      "z": 3,
      "name": "Rock_Quartzite"
    },
    {
      "x": -6,
      "y": 1,
      "z": 3,
      "name": "Rock_Quartzite"
    },
    {
      "x": -6,
      "y": 2,
      "z": 3,
      "name": "Rock_Quartzite"
    },
    {
      "x": -6,
      "y": 3,
      "z": 3,
      "name": "Rock_Quartzite"
    },
    {
      "x": -6,
      "y": 4,
      "z": 3,
      "name": "Rock_Quartzite"
    },
    {
      "x": -6,
      "y": 5,
      "z": 3,
      "name": "Rock_Quartzite"
    },
    {
      "x": -6,
      "y": 6,
      "z": 3,
      "name": "Rock_Quartzite"
    },
    {
      "x": -6,
      "y": 7,
      "z": 3,
      "name": "Rock_Quartzite"
    },
    {
      "x": -6,
      "y": 8,
      "z": 3,
      "name": "Rock_Quartzite"
    },
    {
      "x": -6,
      "y": 9,
      "z": 3,
      "name": "Rock_Quartzite"
    },
    {
      "x": -6,
      "y": 10,
      "z": 3,
      "name": "Rock_Quartzite"
    },
    {
      "x": -6,
      "y": 11,
      "z": 3,
      "name": "Rock_Quartzite"
    },
    {
      "x": -6,
      "y": 12,
      "z": 3,
      "name": "Rock_Quartzite"
    },
    {
      "x": -6,
      "y": 13,
      "z": 3,
      "name": "Rock_Quartzite"
    },
    {
      "x": -6,
      "y": 14,
      "z": 3,
      "name": "Rock_Quartzite"
    },
    {
      "x": -6,
      "y": 15,
      "z": 3,
      "name": "Rock_Quartzite"
    },
    {
      "x": -6,
      "y": 16,
      "z": 3,
      "name": "Rock_Quartzite"
    },
    {
      "x": -6,
      "y": 17,
      "z": 3,
      "name": "Soil_Dirt"
    },
    {
      "x": -6,
      "y": 18,
      "z": 3,
      "name": "Soil_Dirt"
    },
    {
      "x": -6,
      "y": 19,
      "z": 3,
      "name": "Soil_Grass"
    },
    {
      "x": -6,
      "y": 0,
      "z": 4,
      "name": "Rock_Quartzite"
    },
    {
      "x": -6,
      "y": 1,
      "z": 4,
      "name": "Rock_Quartzite"
    },
    {
      "x": -6,
      "y": 2,
      "z": 4,
      "name": "Rock_Quartzite"
    },
    {
      "x": -6,
      "y": 3,
      "z": 4,
      "name": "Rock_Quartzite"
    },
    {
      "x": -6,
      "y": 4,
      "z": 4,
      "name": "Rock_Quartzite"
    },
    {
      "x": -6,
      "y": 5,
      "z": 4,
      "name": "Rock_Quartzite"
    },
    {
      "x": -6,
      "y": 6,
      "z": 4,
      "name": "Rock_Quartzite"
    },
    {
      "x": -6,
      "y": 7,
      "z": 4,
      "name": "Rock_Quartzite"
    },
    {
      "x": -6,
      "y": 8,
      "z": 4,
      "name": "Rock_Quartzite"
    },
    {
      "x": -6,
      "y": 9,
      "z": 4,
      "name": "Rock_Quartzite"
    },
    {
      "x": -6,
      "y": 10,
      "z": 4,
      "name": "Rock_Quartzite"
    },
    {
      "x": -6,
      "y": 11,
      "z": 4,
      "name": "Rock_Quartzite"
    },
    {
      "x": -6,
      "y": 12,
      "z": 4,
      "name": "Rock_Quartzite"
    },
    {
      "x": -6,
      "y": 13,
      "z": 4,
      "name": "Rock_Quartzite"
    },
    {
      "x": -6,
      "y": 14,
      "z": 4,
      "name": "Rock_Quartzite"
    },
    {
      "x": -6,
      "y": 15,
      "z": 4,
      "name": "Rock_Quartzite"
    },
    {
      "x": -6,
      "y": 16,
      "z": 4,
      "name": "Rock_Quartzite"
    },
    {
      "x": -6,
      "y": 17,
      "z": 4,
      "name": "Rock_Quartzite"
    },
    {
      "x": -6,
      "y": 18,
      "z": 4,
      "name": "Soil_Dirt"
    },
    {
      "x": -6,
      "y": 19,
      "z": 4,
      "name": "Soil_Grass"
    },
    {
      "x": -6,
      "y": 0,
      "z": 5,
      "name": "Rock_Quartzite"
    },
    {
      "x": -6,
      "y": 1,
      "z": 5,
      "name": "Rock_Quartzite"
    },
    {
      "x": -6,
      "y": 2,
      "z": 5,
      "name": "Rock_Quartzite"
    },
    {
      "x": -6,
      "y": 3,
      "z": 5,
      "name": "Rock_Quartzite"
    },
    {
      "x": -6,
      "y": 4,
      "z": 5,
      "name": "Rock_Quartzite"
    },
    {
      "x": -6,
      "y": 5,
      "z": 5,
      "name": "Rock_Quartzite"
    },
    {
      "x": -6,
      "y": 6,
      "z": 5,
      "name": "Rock_Quartzite"
    },
    {
      "x": -6,
      "y": 7,
      "z": 5,
      "name": "Rock_Quartzite"
    },
    {
      "x": -6,
      "y": 8,
      "z": 5,
      "name": "Rock_Quartzite"
    },
    {
      "x": -6,
      "y": 9,
      "z": 5,
      "name": "Rock_Quartzite"
    },
    {
      "x": -6,
      "y": 10,
      "z": 5,
      "name": "Rock_Quartzite"
    },
    {
      "x": -6,
      "y": 11,
      "z": 5,
      "name": "Rock_Quartzite"
    },
    {
      "x": -6,
      "y": 12,
      "z": 5,
      "name": "Rock_Quartzite"
    },
    {
      "x": -6,
      "y": 13,
      "z": 5,
      "name": "Rock_Quartzite"
    },
    {
      "x": -6,
      "y": 14,
      "z": 5,
      "name": "Rock_Quartzite"
    },
    {
      "x": -6,
      "y": 15,
      "z": 5,
      "name": "Rock_Quartzite"
    },
    {
      "x": -6,
      "y": 16,
      "z": 5,
      "name": "Rock_Quartzite"
    },
    {
      "x": -6,
      "y": 17,
      "z": 5,
      "name": "Rock_Quartzite"
    },
    {
      "x": -6,
      "y": 18,
      "z": 5,
      "name": "Soil_Dirt"
    },
    {
      "x": -6,
      "y": 19,
      "z": 5,
      "name": "Soil_Grass"
    },
    {
      "x": -6,
      "y": 0,
      "z": 6,
      "name": "Rock_Stone"
    },
    {
      "x": -6,
      "y": 1,
      "z": 6,
      "name": "Rock_Stone"
    },
    {
      "x": -6,
      "y": 2,
      "z": 6,
      "name": "Rock_Stone"
    },
    {
      "x": -6,
      "y": 3,
      "z": 6,
      "name": "Rock_Stone"
    },
    {
      "x": -6,
      "y": 4,
      "z": 6,
      "name": "Rock_Stone"
    },
    {
      "x": -6,
      "y": 5,
      "z": 6,
      "name": "Rock_Quartzite"
    },
    {
      "x": -6,
      "y": 6,
      "z": 6,
      "name": "Rock_Quartzite"
    },
    {
      "x": -6,
      "y": 7,
      "z": 6,
      "name": "Rock_Quartzite"
    },
    {
      "x": -6,
      "y": 8,
      "z": 6,
      "name": "Rock_Quartzite"
    },
    {
      "x": -6,
      "y": 9,
      "z": 6,
      "name": "Rock_Quartzite"
    },
    {
      "x": -6,
      "y": 10,
      "z": 6,
      "name": "Rock_Quartzite"
    },
    {
      "x": -6,
      "y": 11,
      "z": 6,
      "name": "Rock_Quartzite"
    },
    {
      "x": -6,
      "y": 12,
      "z": 6,
      "name": "Rock_Quartzite"
    },
    {
      "x": -6,
      "y": 13,
      "z": 6,
      "name": "Rock_Quartzite"
    },
    {
      "x": -6,
      "y": 14,
      "z": 6,
      "name": "Rock_Quartzite"
    },
    {
      "x": -6,
      "y": 15,
      "z": 6,
      "name": "Rock_Stone"
    },
    {
      "x": -6,
      "y": 16,
      "z": 6,
      "name": "Rock_Stone"
    },
    {
      "x": -6,
      "y": 17,
      "z": 6,
      "name": "Rock_Stone"
    },
    {
      "x": -6,
      "y": 18,
      "z": 6,
      "name": "Soil_Dirt"
    },
    {
      "x": -6,
      "y": 19,
      "z": 6,
      "name": "Soil_Grass"
    },
    {
      "x": -6,
      "y": 0,
      "z": 7,
      "name": "Rock_Stone"
    },
    {
      "x": -6,
      "y": 1,
      "z": 7,
      "name": "Rock_Stone"
    },
    {
      "x": -6,
      "y": 2,
      "z": 7,
      "name": "Rock_Stone"
    },
    {
      "x": -6,
      "y": 3,
      "z": 7,
      "name": "Rock_Stone"
    },
    {
      "x": -6,
      "y": 4,
      "z": 7,
      "name": "Rock_Stone"
    },
    {
      "x": -6,
      "y": 5,
      "z": 7,
      "name": "Rock_Stone"
    },
    {
      "x": -6,
      "y": 6,
      "z": 7,
      "name": "Rock_Stone"
    },
    {
      "x": -6,
      "y": 7,
      "z": 7,
      "name": "Rock_Stone"
    },
    {
      "x": -6,
      "y": 8,
      "z": 7,
      "name": "Rock_Stone"
    },
    {
      "x": -6,
      "y": 9,
      "z": 7,
      "name": "Rock_Stone"
    },
    {
      "x": -6,
      "y": 10,
      "z": 7,
      "name": "Rock_Stone"
    },
    {
      "x": -6,
      "y": 11,
      "z": 7,
      "name": "Rock_Stone"
    },
    {
      "x": -6,
      "y": 12,
      "z": 7,
      "name": "Rock_Stone"
    },
    {
      "x": -6,
      "y": 13,
      "z": 7,
      "name": "Rock_Stone"
    },
    {
      "x": -6,
      "y": 14,
      "z": 7,
      "name": "Rock_Stone"
    },
    {
      "x": -6,
      "y": 15,
      "z": 7,
      "name": "Rock_Stone"
    },
    {
      "x": -6,
      "y": 16,
      "z": 7,
      "name": "Rock_Stone"
    },
    {
      "x": -6,
      "y": 17,
      "z": 7,
      "name": "Rock_Stone"
    },
    {
      "x": -6,
      "y": 18,
      "z": 7,
      "name": "Rock_Stone"
    },
    {
      "x": -6,
      "y": 19,
      "z": 7,
      "name": "Soil_Grass"
    },
    {
      "x": -6,
      "y": 1,
      "z": 8,
      "name": "Rock_Stone"
    },
    {
      "x": -6,
      "y": 2,
      "z": 8,
      "name": "Rock_Stone"
    },
    {
      "x": -6,
      "y": 3,
      "z": 8,
      "name": "Rock_Stone"
    },
    {
      "x": -6,
      "y": 4,
      "z": 8,
      "name": "Rock_Stone"
    },
    {
      "x": -6,
      "y": 5,
      "z": 8,
      "name": "Rock_Stone"
    },
    {
      "x": -6,
      "y": 6,
      "z": 8,
      "name": "Rock_Stone"
    },
    {
      "x": -6,
      "y": 8,
      "z": 8,
      "name": "Rock_Stone"
    },
    {
      "x": -6,
      "y": 9,
      "z": 8,
      "name": "Rock_Stone"
    },
    {
      "x": -6,
      "y": 10,
      "z": 8,
      "name": "Rock_Stone"
    },
    {
      "x": -6,
      "y": 11,
      "z": 8,
      "name": "Rock_Stone"
    },
    {
      "x": -6,
      "y": 12,
      "z": 8,
      "name": "Rock_Stone"
    },
    {
      "x": -6,
      "y": 13,
      "z": 8,
      "name": "Rock_Stone"
    },
    {
      "x": -6,
      "y": 14,
      "z": 8,
      "name": "Rock_Stone"
    },
    {
      "x": -6,
      "y": 15,
      "z": 8,
      "name": "Rock_Stone"
    },
    {
      "x": -6,
      "y": 16,
      "z": 8,
      "name": "Rock_Stone"
    },
    {
      "x": -6,
      "y": 17,
      "z": 8,
      "name": "Rock_Stone"
    },
    {
      "x": -6,
      "y": 18,
      "z": 8,
      "name": "Rock_Stone"
    },
    {
      "x": -6,
      "y": 19,
      "z": 8,
      "name": "Soil_Grass"
    },
    {
      "x": -5,
      "y": 8,
      "z": -9,
      "name": "Rock_Stone"
    },
    {
      "x": -5,
      "y": 9,
      "z": -9,
      "name": "Rock_Stone"
    },
    {
      "x": -5,
      "y": 10,
      "z": -9,
      "name": "Rock_Stone"
    },
    {
      "x": -5,
      "y": 11,
      "z": -9,
      "name": "Rock_Stone"
    },
    {
      "x": -5,
      "y": 12,
      "z": -9,
      "name": "Rock_Stone"
    },
    {
      "x": -5,
      "y": 13,
      "z": -9,
      "name": "Rock_Stone"
    },
    {
      "x": -5,
      "y": 14,
      "z": -9,
      "name": "Rock_Stone"
    },
    {
      "x": -5,
      "y": 2,
      "z": -8,
      "name": "Rock_Stone"
    },
    {
      "x": -5,
      "y": 3,
      "z": -8,
      "name": "Rock_Stone"
    },
    {
      "x": -5,
      "y": 4,
      "z": -8,
      "name": "Rock_Stone"
    },
    {
      "x": -5,
      "y": 5,
      "z": -8,
      "name": "Rock_Stone"
    },
    {
      "x": -5,
      "y": 6,
      "z": -8,
      "name": "Rock_Stone"
    },
    {
      "x": -5,
      "y": 7,
      "z": -8,
      "name": "Rock_Stone"
    },
    {
      "x": -5,
      "y": 8,
      "z": -8,
      "name": "Rock_Stone"
    },
    {
      "x": -5,
      "y": 9,
      "z": -8,
      "name": "Rock_Stone"
    },
    {
      "x": -5,
      "y": 10,
      "z": -8,
      "name": "Rock_Stone"
    },
    {
      "x": -5,
      "y": 11,
      "z": -8,
      "name": "Rock_Stone"
    },
    {
      "x": -5,
      "y": 12,
      "z": -8,
      "name": "Rock_Stone"
    },
    {
      "x": -5,
      "y": 13,
      "z": -8,
      "name": "Rock_Stone"
    },
    {
      "x": -5,
      "y": 14,
      "z": -8,
      "name": "Rock_Stone"
    },
    {
      "x": -5,
      "y": 15,
      "z": -8,
      "name": "Rock_Stone"
    },
    {
      "x": -5,
      "y": 16,
      "z": -8,
      "name": "Rock_Stone"
    },
    {
      "x": -5,
      "y": 17,
      "z": -8,
      "name": "Rock_Stone"
    },
    {
      "x": -5,
      "y": 18,
      "z": -8,
      "name": "Rock_Stone"
    },
    {
      "x": -5,
      "y": 19,
      "z": -8,
      "name": "Rock_Stone"
    },
    {
      "x": -5,
      "y": 20,
      "z": -8,
      "name": "Rock_Stone"
    },
    {
      "x": -5,
      "y": 1,
      "z": -7,
      "name": "Rock_Stone"
    },
    {
      "x": -5,
      "y": 2,
      "z": -7,
      "name": "Rock_Stone"
    },
    {
      "x": -5,
      "y": 3,
      "z": -7,
      "name": "Rock_Stone"
    },
    {
      "x": -5,
      "y": 4,
      "z": -7,
      "name": "Rock_Stone"
    },
    {
      "x": -5,
      "y": 5,
      "z": -7,
      "name": "Rock_Stone"
    },
    {
      "x": -5,
      "y": 6,
      "z": -7,
      "name": "Rock_Stone"
    },
    {
      "x": -5,
      "y": 7,
      "z": -7,
      "name": "Rock_Stone"
    },
    {
      "x": -5,
      "y": 8,
      "z": -7,
      "name": "Rock_Stone"
    },
    {
      "x": -5,
      "y": 9,
      "z": -7,
      "name": "Rock_Stone"
    },
    {
      "x": -5,
      "y": 10,
      "z": -7,
      "name": "Rock_Stone"
    },
    {
      "x": -5,
      "y": 11,
      "z": -7,
      "name": "Rock_Stone"
    },
    {
      "x": -5,
      "y": 12,
      "z": -7,
      "name": "Rock_Stone"
    },
    {
      "x": -5,
      "y": 13,
      "z": -7,
      "name": "Rock_Stone"
    },
    {
      "x": -5,
      "y": 14,
      "z": -7,
      "name": "Rock_Stone"
    },
    {
      "x": -5,
      "y": 15,
      "z": -7,
      "name": "Rock_Stone"
    },
    {
      "x": -5,
      "y": 16,
      "z": -7,
      "name": "Rock_Stone"
    },
    {
      "x": -5,
      "y": 17,
      "z": -7,
      "name": "Rock_Stone"
    },
    {
      "x": -5,
      "y": 18,
      "z": -7,
      "name": "Rock_Stone"
    },
    {
      "x": -5,
      "y": 19,
      "z": -7,
      "name": "Rock_Stone"
    },
    {
      "x": -5,
      "y": 20,
      "z": -7,
      "name": "Soil_Grass"
    },
    {
      "x": -5,
      "y": 0,
      "z": -6,
      "name": "Rock_Stone"
    },
    {
      "x": -5,
      "y": 1,
      "z": -6,
      "name": "Rock_Stone"
    },
    {
      "x": -5,
      "y": 2,
      "z": -6,
      "name": "Rock_Stone"
    },
    {
      "x": -5,
      "y": 3,
      "z": -6,
      "name": "Rock_Stone"
    },
    {
      "x": -5,
      "y": 4,
      "z": -6,
      "name": "Rock_Stone"
    },
    {
      "x": -5,
      "y": 5,
      "z": -6,
      "name": "Rock_Stone"
    },
    {
      "x": -5,
      "y": 6,
      "z": -6,
      "name": "Rock_Stone"
    },
    {
      "x": -5,
      "y": 7,
      "z": -6,
      "name": "Rock_Stone"
    },
    {
      "x": -5,
      "y": 8,
      "z": -6,
      "name": "Rock_Stone"
    },
    {
      "x": -5,
      "y": 9,
      "z": -6,
      "name": "Rock_Stone"
    },
    {
      "x": -5,
      "y": 10,
      "z": -6,
      "name": "Rock_Stone"
    },
    {
      "x": -5,
      "y": 11,
      "z": -6,
      "name": "Rock_Stone"
    },
    {
      "x": -5,
      "y": 12,
      "z": -6,
      "name": "Rock_Stone"
    },
    {
      "x": -5,
      "y": 13,
      "z": -6,
      "name": "Rock_Stone"
    },
    {
      "x": -5,
      "y": 14,
      "z": -6,
      "name": "Rock_Stone"
    },
    {
      "x": -5,
      "y": 15,
      "z": -6,
      "name": "Rock_Stone"
    },
    {
      "x": -5,
      "y": 16,
      "z": -6,
      "name": "Rock_Stone"
    },
    {
      "x": -5,
      "y": 17,
      "z": -6,
      "name": "Rock_Stone"
    },
    {
      "x": -5,
      "y": 18,
      "z": -6,
      "name": "Rock_Stone"
    },
    {
      "x": -5,
      "y": 19,
      "z": -6,
      "name": "Soil_Dirt"
    },
    {
      "x": -5,
      "y": 20,
      "z": -6,
      "name": "Soil_Grass"
    },
    {
      "x": -5,
      "y": 0,
      "z": -5,
      "name": "Rock_Stone"
    },
    {
      "x": -5,
      "y": 1,
      "z": -5,
      "name": "Rock_Stone"
    },
    {
      "x": -5,
      "y": 2,
      "z": -5,
      "name": "Rock_Stone"
    },
    {
      "x": -5,
      "y": 3,
      "z": -5,
      "name": "Rock_Stone"
    },
    {
      "x": -5,
      "y": 4,
      "z": -5,
      "name": "Rock_Stone"
    },
    {
      "x": -5,
      "y": 5,
      "z": -5,
      "name": "Rock_Stone"
    },
    {
      "x": -5,
      "y": 6,
      "z": -5,
      "name": "Rock_Stone"
    },
    {
      "x": -5,
      "y": 7,
      "z": -5,
      "name": "Rock_Stone"
    },
    {
      "x": -5,
      "y": 8,
      "z": -5,
      "name": "Rock_Stone"
    },
    {
      "x": -5,
      "y": 9,
      "z": -5,
      "name": "Rock_Stone"
    },
    {
      "x": -5,
      "y": 10,
      "z": -5,
      "name": "Rock_Stone"
    },
    {
      "x": -5,
      "y": 11,
      "z": -5,
      "name": "Rock_Stone"
    },
    {
      "x": -5,
      "y": 12,
      "z": -5,
      "name": "Rock_Stone"
    },
    {
      "x": -5,
      "y": 13,
      "z": -5,
      "name": "Rock_Stone"
    },
    {
      "x": -5,
      "y": 14,
      "z": -5,
      "name": "Rock_Stone"
    },
    {
      "x": -5,
      "y": 15,
      "z": -5,
      "name": "Rock_Stone"
    },
    {
      "x": -5,
      "y": 16,
      "z": -5,
      "name": "Rock_Stone"
    },
    {
      "x": -5,
      "y": 17,
      "z": -5,
      "name": "Rock_Stone"
    },
    {
      "x": -5,
      "y": 18,
      "z": -5,
      "name": "Soil_Dirt"
    },
    {
      "x": -5,
      "y": 19,
      "z": -5,
      "name": "Soil_Dirt"
    },
    {
      "x": -5,
      "y": 20,
      "z": -5,
      "name": "Soil_Grass"
    },
    {
      "x": -5,
      "y": 0,
      "z": -4,
      "name": "Rock_Stone"
    },
    {
      "x": -5,
      "y": 1,
      "z": -4,
      "name": "Rock_Stone"
