{
  "version": 8,
  "blockIdVersion": 11,
  "anchorX": 0,
  "anchorY": 0,
  "anchorZ": 0,
  "blocks": [
    {
      "x": -19,
      "y": 17,
      "z": -2,
      "name": "Rock_Shale_Brick_Smooth",
      "rotation": 1
    },
    {
      "x": -19,
      "y": 21,
      "z": -2,
      "name": "Rock_Shale_Brick_Smooth",
      "rotation": 1
    },
    {
      "x": -19,
      "y": 17,
      "z": -1,
      "name": "Rock_Shale_Brick_Smooth",
      "rotation": 1
    },
    {
      "x": -19,
      "y": 21,
      "z": -1,
      "name": "Rock_Shale_Brick_Smooth",
      "rotation": 1
    },
    {
      "x": -19,
      "y": 17,
      "z": 0,
      "name": "Rock_Shale_Brick_Smooth",
      "rotation": 1
    },
    {
      "x": -19,
      "y": 21,
      "z": 0,
      "name": "Rock_Shale_Brick_Smooth",
      "rotation": 1
    },
    {
      "x": -19,
      "y": 17,
      "z": 1,
      "name": "Rock_Shale_Brick_Smooth",
      "rotation": 1
    },
    {
      "x": -19,
      "y": 21,
      "z": 1,
      "name": "Rock_Shale_Brick_Smooth",
      "rotation": 1
    },
    {
      "x": -19,
      "y": 17,
      "z": 2,
      "name": "Rock_Shale_Brick_Smooth",
      "rotation": 1
    },
    {
      "x": -19,
      "y": 21,
      "z": 2,
      "name": "Rock_Shale_Brick_Smooth",
      "rotation": 1
    },
    {
      "x": -19,
      "y": 17,
      "z": 3,
      "name": "Rock_Shale_Brick_Smooth",
      "rotation": 1
    },
    {
      "x": -19,
      "y": 21,
      "z": 3,
      "name": "Rock_Shale_Brick_Smooth",
      "rotation": 1
    },
    {
      "x": -18,
      "y": 17,
      "z": -3,
      "name": "Rock_Shale_Brick_Smooth",
      "rotation": 1
    },
    {
      "x": -18,
      "y": 21,
      "z": -3,
      "name": "Rock_Shale_Brick_Smooth",
      "rotation": 1
    },
    {
      "x": -18,
      "y": 17,
      "z": -2,
      "name": "Rock_Shale_Cobble",
      "rotation": 7
    },
    {
      "x": -18,
      "y": 18,
      "z": -2,
      "name": "Rock_Shale_Cobble",
      "rotation": 7
    },
    {
      "x": -18,
      "y": 19,
      "z": -2,
      "name": "Build_Lightsource_Cyan",
      "rotation": 7
    },
    {
      "x": -18,
      "y": 20,
      "z": -2,
      "name": "Rock_Shale_Cobble",
      "rotation": 7
    },
    {
      "x": -18,
      "y": 21,
      "z": -2,
      "name": "Rock_Shale_Cobble",
      "rotation": 7
    },
    {
      "x": -18,
      "y": 16,
      "z": -1,
      "name": "Rock_Shale_Cobble_Half",
      "rotation": 7
    },
    {
      "x": -18,
      "y": 17,
      "z": -1,
      "name": "Rock_Shale_Cobble",
      "rotation": 7
    },
    {
      "x": -18,
      "y": 18,
      "z": -1,
      "name": "Rock_Shale_Cobble",
      "rotation": 7
    },
    {
      "x": -18,
      "y": 19,
      "z": -1,
      "name": "Build_Lightsource_Cyan",
      "rotation": 17
    },
    {
      "x": -18,
      "y": 20,
      "z": -1,
      "name": "Rock_Shale_Cobble",
      "rotation": 7
    },
    {
      "x": -18,
      "y": 21,
      "z": -1,
      "name": "Rock_Shale_Cobble",
      "rotation": 7
    },
    {
      "x": -18,
      "y": 22,
      "z": -1,
      "name": "Rock_Shale_Cobble_Half",
      "rotation": 7
    },
    {
      "x": -18,
      "y": 17,
      "z": 0,
      "name": "Rock_Shale_Cobble",
      "rotation": 7
    },
    {
      "x": -18,
      "y": 18,
      "z": 0,
      "name": "Rock_Shale_Cobble",
      "rotation": 7
    },
    {
      "x": -18,
      "y": 19,
      "z": 0,
      "name": "Build_Lightsource_Cyan",
      "rotation": 17
    },
    {
      "x": -18,
      "y": 20,
      "z": 0,
      "name": "Rock_Shale_Cobble",
      "rotation": 7
    },
    {
      "x": -18,
      "y": 21,
      "z": 0,
      "name": "Rock_Shale_Cobble",
      "rotation": 7
    },
    {
      "x": -18,
      "y": 17,
      "z": 1,
      "name": "Rock_Shale_Cobble",
      "rotation": 7
    },
    {
      "x": -18,
      "y": 18,
      "z": 1,
      "name": "Rock_Shale_Cobble",
      "rotation": 7
    },
    {
      "x": -18,
      "y": 19,
      "z": 1,
      "name": "Build_Lightsource_Cyan",
      "rotation": 17
    },
    {
      "x": -18,
      "y": 20,
      "z": 1,
      "name": "Rock_Shale_Cobble",
      "rotation": 7
    },
    {
      "x": -18,
      "y": 21,
      "z": 1,
      "name": "Rock_Shale_Cobble",
      "rotation": 7
    },
    {
      "x": -18,
      "y": 16,
      "z": 2,
      "name": "Rock_Shale_Cobble_Half",
      "rotation": 7
    },
    {
      "x": -18,
      "y": 17,
      "z": 2,
      "name": "Rock_Shale_Cobble",
      "rotation": 7
    },
    {
      "x": -18,
      "y": 18,
      "z": 2,
      "name": "Rock_Shale_Cobble",
      "rotation": 7
    },
    {
      "x": -18,
      "y": 19,
      "z": 2,
      "name": "Build_Lightsource_Cyan",
      "rotation": 7
    },
    {
      "x": -18,
      "y": 20,
      "z": 2,
      "name": "Rock_Shale_Cobble",
      "rotation": 7
    },
    {
      "x": -18,
      "y": 21,
      "z": 2,
      "name": "Rock_Shale_Cobble",
      "rotation": 7
    },
    {
      "x": -18,
      "y": 22,
      "z": 2,
      "name": "Rock_Shale_Cobble_Half",
      "rotation": 7
    },
    {
      "x": -18,
      "y": 17,
      "z": 3,
      "name": "Rock_Shale_Cobble",
      "rotation": 7
    },
    {
      "x": -18,
      "y": 18,
      "z": 3,
      "name": "Rock_Shale_Cobble",
      "rotation": 7
    },
    {
      "x": -18,
      "y": 19,
      "z": 3,
      "name": "Build_Lightsource_Cyan",
      "rotation": 7
    },
    {
      "x": -18,
      "y": 20,
      "z": 3,
      "name": "Rock_Shale_Cobble",
      "rotation": 7
    },
    {
      "x": -18,
      "y": 21,
      "z": 3,
      "name": "Rock_Shale_Cobble",
      "rotation": 7
    },
    {
      "x": -18,
      "y": 17,
      "z": 4,
      "name": "Rock_Shale_Brick_Smooth",
      "rotation": 1
    },
    {
      "x": -18,
      "y": 21,
      "z": 4,
      "name": "Rock_Shale_Brick_Smooth",
      "rotation": 1
    },
    {
      "x": -17,
      "y": 17,
      "z": -4,
      "name": "Rock_Shale_Brick_Smooth",
      "rotation": 1
    },
    {
      "x": -17,
      "y": 21,
      "z": -4,
      "name": "Rock_Shale_Brick_Smooth",
      "rotation": 1
    },
    {
      "x": -17,
      "y": 17,
      "z": -3,
      "name": "Rock_Shale_Cobble",
      "rotation": 7
    },
    {
      "x": -17,
      "y": 18,
      "z": -3,
      "name": "Rock_Shale_Cobble",
      "rotation": 7
    },
    {
      "x": -17,
      "y": 19,
      "z": -3,
      "name": "Build_Lightsource_Cyan",
      "rotation": 17
    },
    {
      "x": -17,
      "y": 20,
      "z": -3,
      "name": "Rock_Shale_Cobble",
      "rotation": 7
    },
    {
      "x": -17,
      "y": 21,
      "z": -3,
      "name": "Rock_Shale_Cobble",
      "rotation": 1
    },
    {
      "x": -17,
      "y": 16,
      "z": -2,
      "name": "Rock_Shale_Cobble",
      "rotation": 17
    },
    {
      "x": -17,
      "y": 17,
      "z": -2,
      "name": "Rock_Shale_Cobble",
      "rotation": 6
    },
    {
      "x": -17,
      "y": 18,
      "z": -2,
      "name": "Rock_Shale_Cobble",
      "rotation": 6
    },
    {
      "x": -17,
      "y": 19,
      "z": -2,
      "name": "Rock_Shale_Cobble",
      "rotation": 6
    },
    {
      "x": -17,
      "y": 20,
      "z": -2,
      "name": "Rock_Shale_Cobble",
      "rotation": 6
    },
    {
      "x": -17,
      "y": 21,
      "z": -2,
      "name": "Rock_Shale_Cobble",
      "rotation": 7
    },
    {
      "x": -17,
      "y": 22,
      "z": -2,
      "name": "Rock_Shale_Cobble",
      "rotation": 4
    },
    {
      "x": -17,
      "y": 13,
      "z": -1,
      "name": "Rock_Shale_Cobble_Half",
      "rotation": 7
    },
    {
      "x": -17,
      "y": 14,
      "z": -1,
      "name": "Rock_Shale_Cobble_Half",
      "rotation": 7
    },
    {
      "x": -17,
      "y": 15,
      "z": -1,
      "name": "Rock_Shale_Cobble_Half",
      "rotation": 7
    },
    {
      "x": -17,
      "y": 16,
      "z": -1,
      "name": "Rock_Shale_Cobble",
      "rotation": 17
    },
    {
      "x": -17,
      "y": 17,
      "z": -1,
      "name": "Rock_Shale_Cobble",
      "rotation": 6
    },
    {
      "x": -17,
      "y": 18,
      "z": -1,
      "name": "Rock_Shale_Cobble",
      "rotation": 6
    },
    {
      "x": -17,
      "y": 19,
      "z": -1,
      "name": "Rock_Shale_Cobble",
      "rotation": 6
    },
    {
      "x": -17,
      "y": 20,
      "z": -1,
      "name": "Rock_Shale_Cobble",
      "rotation": 6
    },
    {
      "x": -17,
      "y": 21,
      "z": -1,
      "name": "Rock_Shale_Cobble",
      "rotation": 6
    },
    {
      "x": -17,
      "y": 22,
      "z": -1,
      "name": "Rock_Shale_Cobble",
      "rotation": 4
    },
    {
      "x": -17,
      "y": 23,
      "z": -1,
      "name": "Rock_Shale_Cobble_Half",
      "rotation": 7
    },
    {
      "x": -17,
      "y": 24,
      "z": -1,
      "name": "Rock_Shale_Cobble_Half",
      "rotation": 7
    },
    {
      "x": -17,
      "y": 25,
      "z": -1,
      "name": "Rock_Shale_Cobble_Half",
      "rotation": 7
    },
    {
      "x": -17,
      "y": 16,
      "z": 0,
      "name": "Rock_Shale_Cobble",
      "rotation": 17
    },
    {
      "x": -17,
      "y": 17,
      "z": 0,
      "name": "Rock_Shale_Cobble",
      "rotation": 6
    },
    {
      "x": -17,
      "y": 18,
      "z": 0,
      "name": "Rock_Shale_Cobble",
      "rotation": 6
    },
    {
      "x": -17,
      "y": 19,
      "z": 0,
      "name": "Rock_Shale_Cobble",
      "rotation": 6
    },
    {
      "x": -17,
      "y": 20,
      "z": 0,
      "name": "Rock_Shale_Cobble",
      "rotation": 6
    },
    {
      "x": -17,
      "y": 21,
      "z": 0,
      "name": "Rock_Shale_Cobble",
      "rotation": 6
    },
    {
      "x": -17,
      "y": 22,
      "z": 0,
      "name": "Rock_Shale_Cobble",
      "rotation": 4
    },
    {
      "x": -17,
      "y": 16,
      "z": 1,
      "name": "Rock_Shale_Cobble",
      "rotation": 17
    },
    {
      "x": -17,
      "y": 17,
      "z": 1,
      "name": "Rock_Shale_Cobble",
      "rotation": 6
    },
    {
      "x": -17,
      "y": 18,
      "z": 1,
      "name": "Rock_Shale_Cobble",
      "rotation": 6
    },
    {
      "x": -17,
      "y": 19,
      "z": 1,
      "name": "Rock_Shale_Cobble",
      "rotation": 6
    },
    {
      "x": -17,
      "y": 20,
      "z": 1,
      "name": "Rock_Shale_Cobble",
      "rotation": 6
    },
    {
      "x": -17,
      "y": 21,
      "z": 1,
      "name": "Rock_Shale_Cobble",
      "rotation": 6
    },
    {
      "x": -17,
      "y": 22,
      "z": 1,
      "name": "Rock_Shale_Cobble",
      "rotation": 4
    },
    {
      "x": -17,
      "y": 13,
      "z": 2,
      "name": "Rock_Shale_Cobble_Half",
      "rotation": 7
    },
    {
      "x": -17,
      "y": 14,
      "z": 2,
      "name": "Rock_Shale_Cobble_Half",
      "rotation": 7
    },
    {
      "x": -17,
      "y": 15,
      "z": 2,
      "name": "Rock_Shale_Cobble_Half",
      "rotation": 7
    },
    {
      "x": -17,
      "y": 16,
      "z": 2,
      "name": "Rock_Shale_Cobble",
      "rotation": 17
    },
    {
      "x": -17,
      "y": 17,
      "z": 2,
      "name": "Rock_Shale_Cobble",
      "rotation": 6
    },
    {
      "x": -17,
      "y": 18,
      "z": 2,
      "name": "Rock_Shale_Cobble",
      "rotation": 6
    },
    {
      "x": -17,
      "y": 19,
      "z": 2,
      "name": "Rock_Shale_Cobble",
      "rotation": 6
    },
    {
      "x": -17,
      "y": 20,
      "z": 2,
      "name": "Rock_Shale_Cobble",
      "rotation": 6
    },
    {
      "x": -17,
      "y": 21,
      "z": 2,
      "name": "Rock_Shale_Cobble",
      "rotation": 6
    },
    {
      "x": -17,
      "y": 22,
      "z": 2,
      "name": "Rock_Shale_Cobble",
      "rotation": 4
    },
    {
      "x": -17,
      "y": 23,
      "z": 2,
      "name": "Rock_Shale_Cobble_Half",
      "rotation": 7
    },
    {
      "x": -17,
      "y": 24,
      "z": 2,
      "name": "Rock_Shale_Cobble_Half",
      "rotation": 7
    },
    {
      "x": -17,
      "y": 25,
      "z": 2,
      "name": "Rock_Shale_Cobble_Half",
      "rotation": 7
    },
    {
      "x": -17,
      "y": 16,
      "z": 3,
      "name": "Rock_Shale_Cobble",
      "rotation": 17
    },
    {
      "x": -17,
      "y": 17,
      "z": 3,
      "name": "Rock_Shale_Cobble",
      "rotation": 6
    },
    {
      "x": -17,
      "y": 18,
      "z": 3,
      "name": "Rock_Shale_Cobble",
      "rotation": 6
    },
    {
      "x": -17,
      "y": 19,
      "z": 3,
      "name": "Rock_Shale_Cobble",
      "rotation": 6
    },
    {
      "x": -17,
      "y": 20,
      "z": 3,
      "name": "Rock_Shale_Cobble",
      "rotation": 6
    },
    {
      "x": -17,
      "y": 21,
      "z": 3,
      "name": "Rock_Shale_Cobble",
      "rotation": 6
    },
    {
      "x": -17,
      "y": 22,
      "z": 3,
      "name": "Rock_Shale_Cobble",
      "rotation": 4
    },
    {
      "x": -17,
      "y": 17,
      "z": 4,
      "name": "Rock_Shale_Cobble",
      "rotation": 7
    },
    {
      "x": -17,
      "y": 18,
      "z": 4,
      "name": "Rock_Shale_Cobble",
      "rotation": 7
    },
    {
      "x": -17,
      "y": 19,
      "z": 4,
      "name": "Build_Lightsource_Cyan",
      "rotation": 17
    },
    {
      "x": -17,
      "y": 20,
      "z": 4,
      "name": "Rock_Shale_Cobble",
      "rotation": 7
    },
    {
      "x": -17,
      "y": 21,
      "z": 4,
      "name": "Rock_Shale_Cobble",
      "rotation": 7
    },
    {
      "x": -17,
      "y": 17,
      "z": 5,
      "name": "Rock_Shale_Brick_Smooth",
      "rotation": 1
    },
    {
      "x": -17,
      "y": 21,
      "z": 5,
      "name": "Rock_Shale_Brick_Smooth",
      "rotation": 1
    },
    {
      "x": -16,
      "y": 17,
      "z": -4,
      "name": "Rock_Shale_Brick_Smooth",
      "rotation": 1
    },
    {
      "x": -16,
      "y": 21,
      "z": -4,
      "name": "Rock_Shale_Brick_Smooth",
      "rotation": 1
    },
    {
      "x": -16,
      "y": 17,
      "z": -3,
      "name": "Rock_Shale_Cobble",
      "rotation": 7
    },
    {
      "x": -16,
      "y": 18,
      "z": -3,
      "name": "Rock_Shale_Cobble",
      "rotation": 7
    },
    {
      "x": -16,
      "y": 19,
      "z": -3,
      "name": "Build_Lightsource_Cyan",
      "rotation": 17
    },
    {
      "x": -16,
      "y": 20,
      "z": -3,
      "name": "Rock_Shale_Cobble",
      "rotation": 7
    },
    {
      "x": -16,
      "y": 21,
      "z": -3,
      "name": "Rock_Shale_Cobble",
      "rotation": 1
    },
    {
      "x": -16,
      "y": 29,
      "z": -3,
      "name": "Metal_Iron_Glowing_Pipe_Corner",
      "support": 15,
      "rotation": 18
    },
    {
      "x": -16,
      "y": 13,
      "z": -2,
      "name": "Rock_Shale_Cobble",
      "rotation": 17
    },
    {
      "x": -16,
      "y": 14,
      "z": -2,
      "name": "Rock_Shale_Cobble",
      "rotation": 17
    },
    {
      "x": -16,
      "y": 15,
      "z": -2,
      "name": "Rock_Shale_Cobble",
      "rotation": 17
    },
    {
      "x": -16,
      "y": 16,
      "z": -2,
      "name": "Rock_Shale_Cobble",
      "rotation": 17
    },
    {
      "x": -16,
      "y": 17,
      "z": -2,
      "name": "Rock_Shale_Cobble",
      "rotation": 6
    },
    {
      "x": -16,
      "y": 18,
      "z": -2,
      "name": "Rock_Shale_Cobble",
      "rotation": 6
    },
    {
      "x": -16,
      "y": 19,
      "z": -2,
      "name": "Rock_Shale_Cobble",
      "rotation": 6
    },
    {
      "x": -16,
      "y": 20,
      "z": -2,
      "name": "Rock_Shale_Cobble",
      "rotation": 6
    },
    {
      "x": -16,
      "y": 21,
      "z": -2,
      "name": "Rock_Shale_Cobble",
      "rotation": 7
    },
    {
      "x": -16,
      "y": 22,
      "z": -2,
      "name": "Rock_Shale_Cobble",
      "rotation": 4
    },
    {
      "x": -16,
      "y": 23,
      "z": -2,
      "name": "Rock_Shale_Cobble",
      "rotation": 4
    },
    {
      "x": -16,
      "y": 24,
      "z": -2,
      "name": "Rock_Shale_Cobble",
      "rotation": 4
    },
    {
      "x": -16,
      "y": 25,
      "z": -2,
      "name": "Rock_Shale_Cobble",
      "rotation": 4
    },
    {
      "x": -16,
      "y": 29,
      "z": -2,
      "name": "Metal_Iron_Glowing_Pipe",
      "support": 15,
      "rotation": 4
    },
    {
      "x": -16,
      "y": 11,
      "z": -1,
      "name": "Rock_Shale_Cobble_Half",
      "rotation": 7
    },
    {
      "x": -16,
      "y": 12,
      "z": -1,
      "name": "Rock_Shale_Cobble_Half",
      "rotation": 7
    },
    {
      "x": -16,
      "y": 13,
      "z": -1,
      "name": "Rock_Shale_Cobble",
      "rotation": 17
    },
    {
      "x": -16,
      "y": 14,
      "z": -1,
      "name": "Rock_Shale_Cobble",
      "rotation": 17
    },
    {
      "x": -16,
      "y": 15,
      "z": -1,
      "name": "Rock_Shale_Cobble",
      "rotation": 17
    },
    {
      "x": -16,
      "y": 16,
      "z": -1,
      "name": "Rock_Shale_Cobble",
      "rotation": 17
    },
    {
      "x": -16,
      "y": 17,
      "z": -1,
      "name": "Rock_Shale_Cobble",
      "rotation": 6
    },
    {
      "x": -16,
      "y": 18,
      "z": -1,
      "name": "Rock_Shale_Cobble",
      "rotation": 6
    },
    {
      "x": -16,
      "y": 19,
      "z": -1,
      "name": "Rock_Shale_Cobble",
      "rotation": 6
    },
    {
      "x": -16,
      "y": 20,
      "z": -1,
      "name": "Rock_Shale_Cobble",
      "rotation": 6
    },
    {
      "x": -16,
      "y": 21,
      "z": -1,
      "name": "Rock_Shale_Cobble",
      "rotation": 6
    },
    {
      "x": -16,
      "y": 22,
      "z": -1,
      "name": "Rock_Shale_Cobble",
      "rotation": 4
    },
    {
      "x": -16,
      "y": 23,
      "z": -1,
      "name": "Rock_Shale_Cobble",
      "rotation": 4
    },
    {
      "x": -16,
      "y": 24,
      "z": -1,
      "name": "Rock_Shale_Cobble",
      "rotation": 4
    },
    {
      "x": -16,
      "y": 25,
      "z": -1,
      "name": "Rock_Shale_Cobble",
      "rotation": 4
    },
    {
      "x": -16,
      "y": 26,
      "z": -1,
      "name": "Rock_Shale_Cobble_Half",
      "rotation": 7
    },
    {
      "x": -16,
      "y": 27,
      "z": -1,
      "name": "Rock_Shale_Cobble_Half",
      "rotation": 7
    },
    {
      "x": -16,
      "y": 29,
      "z": -1,
      "name": "Metal_Iron_Glowing_Pipe",
      "support": 15,
      "rotation": 4
    },
    {
      "x": -16,
      "y": 13,
      "z": 0,
      "name": "Rock_Shale_Cobble",
      "rotation": 17
    },
    {
      "x": -16,
      "y": 14,
      "z": 0,
      "name": "Rock_Shale_Cobble",
      "rotation": 17
    },
    {
      "x": -16,
      "y": 15,
      "z": 0,
      "name": "Rock_Shale_Cobble",
      "rotation": 17
    },
    {
      "x": -16,
      "y": 16,
      "z": 0,
      "name": "Rock_Shale_Cobble",
      "rotation": 17
    },
    {
      "x": -16,
      "y": 17,
      "z": 0,
      "name": "Rock_Shale_Cobble",
      "rotation": 6
    },
    {
      "x": -16,
      "y": 18,
      "z": 0,
      "name": "Rock_Shale_Cobble",
      "rotation": 6
    },
    {
      "x": -16,
      "y": 19,
      "z": 0,
      "name": "Rock_Shale_Cobble",
      "rotation": 6
    },
    {
      "x": -16,
      "y": 20,
      "z": 0,
      "name": "Rock_Shale_Cobble",
      "rotation": 6
    },
    {
      "x": -16,
      "y": 21,
      "z": 0,
      "name": "Rock_Shale_Cobble",
      "rotation": 6
    },
    {
      "x": -16,
      "y": 22,
      "z": 0,
      "name": "Rock_Shale_Cobble",
      "rotation": 4
    },
    {
      "x": -16,
      "y": 23,
      "z": 0,
      "name": "Rock_Shale_Cobble",
      "rotation": 4
    },
    {
      "x": -16,
      "y": 24,
      "z": 0,
      "name": "Rock_Shale_Cobble",
      "rotation": 4
    },
    {
      "x": -16,
      "y": 25,
      "z": 0,
      "name": "Rock_Shale_Cobble",
      "rotation": 4
    },
    {
      "x": -16,
      "y": 28,
      "z": 0,
      "name": "Metal_Iron_Glowing_Pipe_Corner",
      "support": 15,
      "rotation": 2
    },
    {
      "x": -16,
      "y": 29,
      "z": 0,
      "name": "Metal_Iron_Glowing_Pipe_Corner",
      "support": 15,
      "rotation": 10
    },
    {
      "x": -16,
      "y": 13,
      "z": 1,
      "name": "Rock_Shale_Cobble",
      "rotation": 17
    },
    {
      "x": -16,
      "y": 14,
      "z": 1,
      "name": "Rock_Shale_Cobble",
      "rotation": 17
    },
    {
      "x": -16,
      "y": 15,
      "z": 1,
      "name": "Rock_Shale_Cobble",
      "rotation": 17
    },
    {
      "x": -16,
      "y": 16,
      "z": 1,
      "name": "Rock_Shale_Cobble",
      "rotation": 17
    },
    {
      "x": -16,
      "y": 17,
      "z": 1,
      "name": "Rock_Shale_Cobble",
      "rotation": 6
    },
    {
      "x": -16,
      "y": 18,
      "z": 1,
      "name": "Rock_Shale_Cobble",
      "rotation": 6
    },
    {
      "x": -16,
      "y": 19,
      "z": 1,
      "name": "Rock_Shale_Cobble",
      "rotation": 6
    },
    {
      "x": -16,
      "y": 20,
      "z": 1,
      "name": "Rock_Shale_Cobble",
      "rotation": 6
    },
    {
      "x": -16,
      "y": 21,
      "z": 1,
      "name": "Rock_Shale_Cobble",
      "rotation": 6
    },
    {
      "x": -16,
      "y": 22,
      "z": 1,
      "name": "Rock_Shale_Cobble",
      "rotation": 4
    },
    {
      "x": -16,
      "y": 23,
      "z": 1,
      "name": "Rock_Shale_Cobble",
      "rotation": 4
    },
    {
      "x": -16,
      "y": 24,
      "z": 1,
      "name": "Rock_Shale_Cobble",
      "rotation": 4
    },
    {
      "x": -16,
      "y": 25,
      "z": 1,
      "name": "Rock_Shale_Cobble",
      "rotation": 4
    },
    {
      "x": -16,
      "y": 28,
      "z": 1,
      "name": "Metal_Iron_Glowing_Pipe",
      "support": 15,
      "rotation": 4
    },
    {
      "x": -16,
      "y": 11,
      "z": 2,
      "name": "Rock_Shale_Cobble_Half",
      "rotation": 7
    },
    {
      "x": -16,
      "y": 12,
      "z": 2,
      "name": "Rock_Shale_Cobble_Half",
      "rotation": 7
    },
    {
      "x": -16,
      "y": 13,
      "z": 2,
      "name": "Rock_Shale_Cobble",
      "rotation": 17
    },
    {
      "x": -16,
      "y": 14,
      "z": 2,
      "name": "Rock_Shale_Cobble",
      "rotation": 17
    },
    {
      "x": -16,
      "y": 15,
      "z": 2,
      "name": "Rock_Shale_Cobble",
      "rotation": 17
    },
    {
      "x": -16,
      "y": 16,
      "z": 2,
      "name": "Rock_Shale_Cobble",
      "rotation": 17
    },
    {
      "x": -16,
      "y": 17,
      "z": 2,
      "name": "Rock_Shale_Cobble",
      "rotation": 6
    },
    {
      "x": -16,
      "y": 18,
      "z": 2,
      "name": "Rock_Shale_Cobble",
      "rotation": 6
    },
    {
      "x": -16,
      "y": 19,
      "z": 2,
      "name": "Rock_Shale_Cobble",
      "rotation": 6
    },
    {
      "x": -16,
      "y": 20,
      "z": 2,
      "name": "Rock_Shale_Cobble",
      "rotation": 6
    },
    {
      "x": -16,
      "y": 21,
      "z": 2,
      "name": "Rock_Shale_Cobble",
      "rotation": 6
    },
    {
      "x": -16,
      "y": 22,
      "z": 2,
      "name": "Rock_Shale_Cobble",
      "rotation": 4
    },
    {
      "x": -16,
      "y": 23,
      "z": 2,
      "name": "Rock_Shale_Cobble",
      "rotation": 4
    },
    {
      "x": -16,
      "y": 24,
      "z": 2,
      "name": "Rock_Shale_Cobble",
      "rotation": 4
    },
    {
      "x": -16,
      "y": 25,
      "z": 2,
      "name": "Rock_Shale_Cobble",
      "rotation": 4
    },
    {
      "x": -16,
      "y": 26,
      "z": 2,
      "name": "Rock_Shale_Cobble_Half",
      "rotation": 7
    },
    {
      "x": -16,
      "y": 27,
      "z": 2,
      "name": "Rock_Shale_Cobble_Half",
      "rotation": 7
    },
    {
      "x": -16,
      "y": 28,
      "z": 2,
      "name": "Metal_Iron_Glowing_Pipe",
      "support": 15,
      "rotation": 4
    },
    {
      "x": -16,
      "y": 13,
      "z": 3,
      "name": "Rock_Shale_Cobble",
      "rotation": 17
    },
    {
      "x": -16,
      "y": 14,
      "z": 3,
      "name": "Rock_Shale_Cobble",
      "rotation": 17
    },
    {
      "x": -16,
      "y": 15,
      "z": 3,
      "name": "Rock_Shale_Cobble",
      "rotation": 17
    },
    {
      "x": -16,
      "y": 16,
      "z": 3,
      "name": "Rock_Shale_Cobble",
      "rotation": 17
    },
    {
      "x": -16,
      "y": 17,
      "z": 3,
      "name": "Rock_Shale_Cobble",
      "rotation": 6
    },
    {
      "x": -16,
      "y": 18,
      "z": 3,
      "name": "Rock_Shale_Cobble",
      "rotation": 6
    },
    {
      "x": -16,
      "y": 19,
      "z": 3,
      "name": "Rock_Shale_Cobble",
      "rotation": 6
    },
    {
      "x": -16,
      "y": 20,
      "z": 3,
      "name": "Rock_Shale_Cobble",
      "rotation": 6
    },
    {
      "x": -16,
      "y": 21,
      "z": 3,
      "name": "Rock_Shale_Cobble",
      "rotation": 6
    },
    {
      "x": -16,
      "y": 22,
      "z": 3,
      "name": "Rock_Shale_Cobble",
      "rotation": 4
    },
    {
      "x": -16,
      "y": 23,
      "z": 3,
      "name": "Rock_Shale_Cobble",
      "rotation": 4
    },
    {
      "x": -16,
      "y": 24,
      "z": 3,
      "name": "Rock_Shale_Cobble",
      "rotation": 4
    },
    {
      "x": -16,
      "y": 25,
      "z": 3,
      "name": "Rock_Shale_Cobble",
      "rotation": 4
    },
    {
      "x": -16,
      "y": 28,
      "z": 3,
      "name": "Metal_Iron_Glowing_Pipe",
      "support": 15,
      "rotation": 4
    },
    {
      "x": -16,
      "y": 17,
      "z": 4,
      "name": "Rock_Shale_Cobble",
      "rotation": 7
    },
    {
      "x": -16,
      "y": 18,
      "z": 4,
      "name": "Rock_Shale_Cobble",
      "rotation": 7
    },
    {
      "x": -16,
      "y": 19,
      "z": 4,
      "name": "Build_Lightsource_Cyan",
      "rotation": 7
    },
    {
      "x": -16,
      "y": 20,
      "z": 4,
      "name": "Rock_Shale_Cobble",
      "rotation": 7
    },
    {
      "x": -16,
      "y": 21,
      "z": 4,
      "name": "Rock_Shale_Cobble",
      "rotation": 7
    },
    {
      "x": -16,
      "y": 27,
      "z": 4,
      "name": "Metal_Iron_Glowing_Pipe_Corner",
      "support": 15,
      "rotation": 3
    },
    {
      "x": -16,
      "y": 28,
      "z": 4,
      "name": "Metal_Iron_Glowing_Pipe_Corner",
      "support": 15,
      "rotation": 12
    },
    {
      "x": -16,
      "y": 17,
      "z": 5,
      "name": "Rock_Shale_Brick_Smooth",
      "rotation": 1
    },
    {
      "x": -16,
      "y": 21,
      "z": 5,
      "name": "Rock_Shale_Brick_Smooth",
      "rotation": 1
    },
    {
      "x": -15,
      "y": 17,
      "z": -4,
      "name": "Rock_Shale_Brick_Smooth",
      "rotation": 1
    },
    {
      "x": -15,
      "y": 21,
      "z": -4,
      "name": "Rock_Shale_Brick_Smooth",
      "rotation": 1
    },
    {
      "x": -15,
      "y": 17,
      "z": -3,
      "name": "Rock_Shale_Cobble",
      "rotation": 7
    },
    {
      "x": -15,
      "y": 18,
      "z": -3,
      "name": "Rock_Shale_Cobble",
      "rotation": 7
    },
    {
      "x": -15,
      "y": 19,
      "z": -3,
      "name": "Build_Lightsource_Cyan",
      "rotation": 7
    },
    {
      "x": -15,
      "y": 20,
      "z": -3,
      "name": "Rock_Shale_Cobble",
      "rotation": 7
    },
    {
      "x": -15,
      "y": 21,
      "z": -3,
      "name": "Rock_Shale_Cobble",
      "rotation": 1
    },
    {
      "x": -15,
      "y": 29,
      "z": -3,
      "name": "Metal_Iron_Glowing_Pipe",
      "support": 15,
      "rotation": 5
    },
    {
      "x": -15,
      "y": 11,
      "z": -2,
      "name": "Rock_Shale_Cobble",
      "rotation": 17
    },
    {
      "x": -15,
      "y": 12,
      "z": -2,
      "name": "Rock_Shale_Cobble",
      "rotation": 17
    },
    {
      "x": -15,
      "y": 13,
      "z": -2,
      "name": "Rock_Shale_Cobble",
      "rotation": 17
    },
    {
      "x": -15,
      "y": 14,
      "z": -2,
      "name": "Rock_Shale_Cobble",
      "rotation": 17
    },
    {
      "x": -15,
      "y": 15,
      "z": -2,
      "name": "Rock_Shale_Cobble",
      "rotation": 17
    },
    {
      "x": -15,
      "y": 16,
      "z": -2,
      "name": "Deko_Block_Test",
      "rotation": 6
    },
    {
      "x": -15,
      "y": 17,
      "z": -2,
      "name": "Rock_Shale_Cobble",
      "rotation": 6
    },
    {
      "x": -15,
      "y": 18,
      "z": -2,
      "name": "Rock_Shale_Cobble",
      "rotation": 6
    },
    {
      "x": -15,
      "y": 19,
      "z": -2,
      "name": "Rock_Shale_Cobble",
      "rotation": 6
    },
    {
      "x": -15,
      "y": 20,
      "z": -2,
      "name": "Rock_Shale_Cobble",
      "rotation": 6
    },
    {
      "x": -15,
      "y": 21,
      "z": -2,
      "name": "Rock_Shale_Cobble",
      "rotation": 7
    },
    {
      "x": -15,
      "y": 22,
      "z": -2,
      "name": "Deko_Block_Test",
      "rotation": 6
    },
    {
      "x": -15,
      "y": 23,
      "z": -2,
      "name": "Rock_Shale_Cobble",
      "rotation": 4
    },
    {
      "x": -15,
      "y": 24,
      "z": -2,
      "name": "Rock_Shale_Cobble",
      "rotation": 4
    },
    {
      "x": -15,
      "y": 25,
      "z": -2,
      "name": "Rock_Shale_Cobble",
      "rotation": 4
    },
    {
      "x": -15,
      "y": 26,
      "z": -2,
      "name": "Rock_Shale_Cobble",
      "rotation": 4
    },
    {
      "x": -15,
      "y": 27,
      "z": -2,
      "name": "Rock_Shale_Cobble",
      "rotation": 4
    },
    {
      "x": -15,
      "y": 9,
      "z": -1,
      "name": "Rock_Shale_Cobble_Half",
      "rotation": 7
    },
    {
      "x": -15,
      "y": 10,
      "z": -1,
      "name": "Rock_Shale_Cobble_Half",
      "rotation": 7
    },
    {
      "x": -15,
      "y": 11,
      "z": -1,
      "name": "Rock_Shale_Cobble",
      "rotation": 17
    },
    {
      "x": -15,
      "y": 12,
      "z": -1,
      "name": "Rock_Shale_Cobble",
      "rotation": 17
    },
    {
      "x": -15,
      "y": 13,
      "z": -1,
      "name": "Rock_Shale_Cobble",
      "rotation": 17
    },
    {
      "x": -15,
      "y": 14,
      "z": -1,
      "name": "Rock_Shale_Cobble",
      "rotation": 17
    },
    {
      "x": -15,
      "y": 15,
      "z": -1,
      "name": "Rock_Shale_Cobble",
      "rotation": 17
    },
    {
      "x": -15,
      "y": 16,
      "z": -1,
      "name": "Rock_Shale_Cobble",
      "rotation": 17
    },
    {
      "x": -15,
      "y": 17,
      "z": -1,
      "name": "Rock_Shale_Cobble",
      "rotation": 6
    },
    {
      "x": -15,
      "y": 18,
      "z": -1,
      "name": "Rock_Shale_Cobble",
      "rotation": 6
    },
    {
      "x": -15,
      "y": 19,
      "z": -1,
      "name": "Rock_Shale_Cobble",
      "rotation": 6
    },
    {
      "x": -15,
      "y": 20,
      "z": -1,
      "name": "Rock_Shale_Cobble",
      "rotation": 6
    },
    {
      "x": -15,
      "y": 21,
      "z": -1,
      "name": "Rock_Shale_Cobble",
      "rotation": 6
    },
    {
      "x": -15,
      "y": 22,
      "z": -1,
      "name": "Rock_Shale_Cobble",
      "rotation": 4
    },
    {
      "x": -15,
      "y": 23,
      "z": -1,
      "name": "Rock_Shale_Cobble",
      "rotation": 4
    },
    {
      "x": -15,
      "y": 24,
      "z": -1,
      "name": "Rock_Shale_Cobble",
      "rotation": 4
    },
    {
      "x": -15,
      "y": 25,
      "z": -1,
      "name": "Rock_Shale_Cobble",
      "rotation": 4
    },
    {
      "x": -15,
      "y": 26,
      "z": -1,
      "name": "Rock_Shale_Cobble",
      "rotation": 4
    },
    {
      "x": -15,
      "y": 27,
      "z": -1,
      "name": "Rock_Shale_Cobble",
      "rotation": 4
    },
    {
      "x": -15,
      "y": 28,
      "z": -1,
      "name": "Rock_Shale_Cobble_Half",
      "rotation": 7
    },
    {
      "x": -15,
      "y": 29,
      "z": -1,
      "name": "Rock_Shale_Cobble_Half",
      "rotation": 7
    },
    {
      "x": -15,
      "y": 11,
      "z": 0,
      "name": "Rock_Shale_Cobble",
      "rotation": 17
    },
    {
      "x": -15,
      "y": 12,
      "z": 0,
      "name": "Rock_Shale_Cobble",
      "rotation": 17
    },
    {
      "x": -15,
      "y": 13,
      "z": 0,
      "name": "Rock_Shale_Cobble",
      "rotation": 17
    },
    {
      "x": -15,
      "y": 14,
      "z": 0,
      "name": "Rock_Shale_Cobble",
      "rotation": 17
    },
    {
      "x": -15,
      "y": 15,
      "z": 0,
      "name": "Rock_Shale_Cobble",
      "rotation": 17
    },
    {
      "x": -15,
      "y": 16,
      "z": 0,
      "name": "Rock_Shale_Cobble",
      "rotation": 17
    },
    {
      "x": -15,
      "y": 17,
      "z": 0,
      "name": "Rock_Shale_Cobble",
      "rotation": 6
    },
    {
      "x": -15,
      "y": 18,
      "z": 0,
      "name": "Rock_Shale_Cobble",
      "rotation": 6
    },
    {
      "x": -15,
      "y": 19,
      "z": 0,
      "name": "Rock_Shale_Cobble",
      "rotation": 6
    },
    {
      "x": -15,
      "y": 20,
      "z": 0,
      "name": "Rock_Shale_Cobble",
      "rotation": 6
    },
    {
      "x": -15,
      "y": 21,
      "z": 0,
      "name": "Rock_Shale_Cobble",
      "rotation": 6
    },
    {
      "x": -15,
      "y": 22,
      "z": 0,
      "name": "Rock_Shale_Cobble",
      "rotation": 4
    },
    {
      "x": -15,
      "y": 23,
      "z": 0,
      "name": "Rock_Shale_Cobble",
      "rotation": 4
    },
    {
      "x": -15,
      "y": 24,
      "z": 0,
      "name": "Rock_Shale_Cobble",
      "rotation": 4
    },
    {
      "x": -15,
      "y": 25,
      "z": 0,
      "name": "Rock_Shale_Cobble",
      "rotation": 4
    },
    {
      "x": -15,
      "y": 26,
      "z": 0,
      "name": "Rock_Shale_Cobble",
      "rotation": 4
    },
    {
      "x": -15,
      "y": 27,
      "z": 0,
      "name": "Rock_Shale_Cobble",
      "rotation": 4
    },
    {
      "x": -15,
      "y": 11,
      "z": 1,
      "name": "Rock_Shale_Cobble",
      "rotation": 17
    },
    {
      "x": -15,
      "y": 12,
      "z": 1,
      "name": "Rock_Shale_Cobble",
      "rotation": 17
    },
    {
      "x": -15,
      "y": 13,
      "z": 1,
      "name": "Rock_Shale_Cobble",
      "rotation": 17
    },
    {
      "x": -15,
      "y": 14,
      "z": 1,
      "name": "Rock_Shale_Cobble",
      "rotation": 17
    },
    {
      "x": -15,
      "y": 15,
      "z": 1,
      "name": "Rock_Shale_Cobble",
      "rotation": 17
    },
    {
      "x": -15,
      "y": 16,
      "z": 1,
      "name": "Rock_Shale_Cobble",
      "rotation": 17
    },
    {
      "x": -15,
      "y": 17,
      "z": 1,
      "name": "Rock_Shale_Cobble",
      "rotation": 6
    },
    {
      "x": -15,
      "y": 18,
      "z": 1,
      "name": "Rock_Shale_Cobble",
      "rotation": 6
    },
    {
      "x": -15,
      "y": 19,
      "z": 1,
      "name": "Rock_Shale_Cobble",
      "rotation": 6
    },
    {
      "x": -15,
      "y": 20,
      "z": 1,
      "name": "Rock_Shale_Cobble",
      "rotation": 6
    },
    {
      "x": -15,
      "y": 21,
      "z": 1,
      "name": "Rock_Shale_Cobble",
      "rotation": 6
    },
    {
      "x": -15,
      "y": 22,
      "z": 1,
      "name": "Rock_Shale_Cobble",
      "rotation": 4
    },
    {
      "x": -15,
      "y": 23,
      "z": 1,
      "name": "Rock_Shale_Cobble",
      "rotation": 4
    },
    {
      "x": -15,
      "y": 24,
      "z": 1,
      "name": "Rock_Shale_Cobble",
      "rotation": 4
    },
    {
      "x": -15,
      "y": 25,
      "z": 1,
      "name": "Rock_Shale_Cobble",
      "rotation": 4
    },
    {
      "x": -15,
      "y": 26,
      "z": 1,
      "name": "Rock_Shale_Cobble",
      "rotation": 4
    },
    {
      "x": -15,
      "y": 27,
      "z": 1,
      "name": "Rock_Shale_Cobble",
      "rotation": 4
    },
    {
      "x": -15,
      "y": 9,
      "z": 2,
      "name": "Rock_Shale_Cobble_Half",
      "rotation": 7
    },
    {
      "x": -15,
      "y": 10,
      "z": 2,
      "name": "Rock_Shale_Cobble_Half",
      "rotation": 7
    },
    {
      "x": -15,
      "y": 11,
      "z": 2,
      "name": "Rock_Shale_Cobble",
      "rotation": 17
    },
    {
      "x": -15,
      "y": 12,
      "z": 2,
      "name": "Rock_Shale_Cobble",
      "rotation": 17
    },
    {
      "x": -15,
      "y": 13,
      "z": 2,
      "name": "Rock_Shale_Cobble",
      "rotation": 17
    },
    {
      "x": -15,
      "y": 14,
      "z": 2,
      "name": "Rock_Shale_Cobble",
      "rotation": 17
    },
    {
      "x": -15,
      "y": 15,
      "z": 2,
      "name": "Rock_Shale_Cobble",
      "rotation": 17
    },
    {
      "x": -15,
      "y": 16,
      "z": 2,
      "name": "Rock_Shale_Cobble",
      "rotation": 17
    },
    {
      "x": -15,
      "y": 17,
      "z": 2,
      "name": "Rock_Shale_Cobble",
      "rotation": 6
    },
    {
      "x": -15,
      "y": 18,
      "z": 2,
      "name": "Rock_Shale_Cobble",
      "rotation": 6
    },
    {
      "x": -15,
      "y": 19,
      "z": 2,
      "name": "Rock_Shale_Cobble",
      "rotation": 6
    },
    {
      "x": -15,
      "y": 20,
      "z": 2,
      "name": "Rock_Shale_Cobble",
      "rotation": 6
    },
    {
      "x": -15,
      "y": 21,
      "z": 2,
      "name": "Rock_Shale_Cobble",
      "rotation": 6
    },
    {
      "x": -15,
      "y": 22,
      "z": 2,
      "name": "Rock_Shale_Cobble",
      "rotation": 4
    },
    {
      "x": -15,
      "y": 23,
      "z": 2,
      "name": "Rock_Shale_Cobble",
      "rotation": 4
    },
    {
      "x": -15,
      "y": 24,
      "z": 2,
      "name": "Rock_Shale_Cobble",
      "rotation": 4
    },
    {
      "x": -15,
      "y": 25,
      "z": 2,
      "name": "Rock_Shale_Cobble",
      "rotation": 4
    },
    {
      "x": -15,
      "y": 26,
      "z": 2,
      "name": "Rock_Shale_Cobble",
      "rotation": 4
    },
    {
      "x": -15,
      "y": 27,
      "z": 2,
      "name": "Rock_Shale_Cobble",
      "rotation": 4
    },
    {
      "x": -15,
      "y": 28,
      "z": 2,
      "name": "Rock_Shale_Cobble_Half",
      "rotation": 7
    },
    {
      "x": -15,
      "y": 29,
      "z": 2,
      "name": "Rock_Shale_Cobble_Half",
      "rotation": 7
    },
    {
      "x": -15,
      "y": 11,
      "z": 3,
      "name": "Rock_Shale_Cobble",
      "rotation": 17
    },
    {
      "x": -15,
      "y": 12,
      "z": 3,
      "name": "Rock_Shale_Cobble",
      "rotation": 17
    },
    {
      "x": -15,
      "y": 13,
      "z": 3,
      "name": "Rock_Shale_Cobble",
      "rotation": 17
    },
    {
      "x": -15,
      "y": 14,
      "z": 3,
      "name": "Rock_Shale_Cobble",
      "rotation": 17
    },
    {
      "x": -15,
      "y": 15,
      "z": 3,
      "name": "Rock_Shale_Cobble",
      "rotation": 17
    },
    {
      "x": -15,
      "y": 16,
      "z": 3,
      "name": "Deko_Block_Test",
      "rotation": 4
    },
    {
      "x": -15,
      "y": 17,
      "z": 3,
      "name": "Rock_Shale_Cobble",
      "rotation": 6
    },
    {
      "x": -15,
      "y": 18,
      "z": 3,
      "name": "Rock_Shale_Cobble",
      "rotation": 6
    },
    {
      "x": -15,
      "y": 19,
      "z": 3,
      "name": "Rock_Shale_Cobble",
      "rotation": 6
    },
    {
      "x": -15,
      "y": 20,
      "z": 3,
      "name": "Rock_Shale_Cobble",
      "rotation": 6
    },
    {
      "x": -15,
      "y": 21,
      "z": 3,
      "name": "Rock_Shale_Cobble",
      "rotation": 6
    },
    {
      "x": -15,
      "y": 22,
      "z": 3,
      "name": "Deko_Block_Test",
      "rotation": 4
    },
    {
      "x": -15,
      "y": 23,
      "z": 3,
      "name": "Rock_Shale_Cobble",
      "rotation": 4
    },
    {
      "x": -15,
      "y": 24,
      "z": 3,
      "name": "Rock_Shale_Cobble",
      "rotation": 4
    },
    {
      "x": -15,
      "y": 25,
      "z": 3,
      "name": "Rock_Shale_Cobble",
      "rotation": 4
    },
    {
      "x": -15,
      "y": 26,
      "z": 3,
      "name": "Rock_Shale_Cobble",
      "rotation": 4
    },
    {
      "x": -15,
      "y": 27,
      "z": 3,
      "name": "Rock_Shale_Cobble",
      "rotation": 4
    },
    {
      "x": -15,
      "y": 17,
      "z": 4,
      "name": "Rock_Shale_Cobble",
      "rotation": 7
    },
    {
      "x": -15,
      "y": 18,
      "z": 4,
      "name": "Rock_Shale_Cobble",
      "rotation": 7
    },
    {
      "x": -15,
      "y": 19,
      "z": 4,
      "name": "Build_Lightsource_Cyan",
      "rotation": 17
    },
    {
      "x": -15,
      "y": 20,
      "z": 4,
      "name": "Rock_Shale_Cobble",
      "rotation": 7
    },
    {
      "x": -15,
      "y": 21,
      "z": 4,
      "name": "Rock_Shale_Cobble",
      "rotation": 7
    },
    {
      "x": -15,
      "y": 25,
      "z": 4,
      "name": "Metal_Iron_Glowing_Pipe_Corner",
      "support": 15,
      "rotation": 3
    },
    {
      "x": -15,
      "y": 26,
      "z": 4,
      "name": "Metal_Iron_Glowing_Pipe",
      "support": 15
    },
    {
      "x": -15,
      "y": 27,
      "z": 4,
      "name": "Metal_Iron_Glowing_Pipe_Corner",
      "support": 15,
      "rotation": 11
    },
    {
      "x": -15,
      "y": 17,
      "z": 5,
      "name": "Rock_Shale_Brick_Smooth",
      "rotation": 1
    },
    {
      "x": -15,
      "y": 21,
      "z": 5,
      "name": "Rock_Shale_Brick_Smooth",
      "rotation": 1
    },
    {
      "x": -14,
      "y": 17,
      "z": -4,
      "name": "Rock_Shale_Brick_Smooth",
      "rotation": 1
    },
    {
      "x": -14,
      "y": 21,
      "z": -4,
      "name": "Rock_Shale_Brick_Smooth",
      "rotation": 1
    },
    {
      "x": -14,
      "y": 17,
      "z": -3,
      "name": "Rock_Shale_Cobble",
      "rotation": 7
    },
    {
      "x": -14,
      "y": 18,
      "z": -3,
      "name": "Rock_Shale_Cobble",
      "rotation": 7
    },
    {
      "x": -14,
      "y": 19,
      "z": -3,
      "name": "Build_Lightsource_Cyan",
      "rotation": 17
    },
    {
      "x": -14,
      "y": 20,
      "z": -3,
      "name": "Rock_Shale_Cobble",
      "rotation": 7
    },
    {
      "x": -14,
      "y": 21,
      "z": -3,
      "name": "Rock_Shale_Cobble",
      "rotation": 1
    },
    {
      "x": -14,
      "y": 29,
      "z": -3,
      "name": "Metal_Iron_Glowing_Pipe",
      "support": 15,
      "rotation": 5
    },
    {
      "x": -14,
      "y": 9,
      "z": -2,
      "name": "Rock_Shale_Cobble",
      "rotation": 17
    },
    {
      "x": -14,
      "y": 10,
      "z": -2,
      "name": "Rock_Shale_Cobble",
      "rotation": 17
    },
    {
      "x": -14,
      "y": 11,
      "z": -2,
      "name": "Rock_Shale_Cobble",
      "rotation": 17
    },
    {
      "x": -14,
      "y": 12,
      "z": -2,
      "name": "Rock_Shale_Cobble",
      "rotation": 17
    },
    {
      "x": -14,
      "y": 13,
      "z": -2,
      "name": "Rock_Shale_Cobble",
      "rotation": 17
    },
    {
      "x": -14,
      "y": 14,
      "z": -2,
      "name": "Rock_Shale_Cobble",
      "rotation": 17
    },
    {
      "x": -14,
      "y": 15,
      "z": -2,
      "name": "Rock_Shale_Cobble",
      "rotation": 17
    },
    {
      "x": -14,
      "y": 16,
      "z": -2,
      "name": "Rock_Shale_Cobble",
      "rotation": 17
    },
    {
      "x": -14,
      "y": 17,
      "z": -2,
      "name": "Rock_Shale_Cobble",
      "rotation": 6
    },
    {
      "x": -14,
      "y": 18,
      "z": -2,
      "name": "Rock_Shale_Cobble",
      "rotation": 6
    },
    {
      "x": -14,
      "y": 19,
      "z": -2,
      "name": "Build_Lightsource_Cyan",
      "rotation": 17
    },
    {
      "x": -14,
      "y": 20,
      "z": -2,
      "name": "Rock_Shale_Cobble",
      "rotation": 6
    },
    {
      "x": -14,
      "y": 21,
      "z": -2,
      "name": "Rock_Shale_Cobble",
      "rotation": 7
    },
    {
      "x": -14,
      "y": 22,
      "z": -2,
      "name": "Rock_Shale_Cobble",
      "rotation": 4
    },
    {
      "x": -14,
      "y": 23,
      "z": -2,
      "name": "Rock_Shale_Cobble",
      "rotation": 4
    },
    {
      "x": -14,
      "y": 24,
      "z": -2,
      "name": "Rock_Shale_Cobble",
      "rotation": 4
    },
    {
      "x": -14,
      "y": 25,
      "z": -2,
      "name": "Rock_Shale_Cobble",
      "rotation": 4
    },
    {
      "x": -14,
      "y": 26,
      "z": -2,
      "name": "Rock_Shale_Cobble",
      "rotation": 4
    },
    {
      "x": -14,
      "y": 27,
      "z": -2,
      "name": "Rock_Shale_Cobble",
      "rotation": 4
    },
    {
      "x": -14,
      "y": 28,
      "z": -2,
      "name": "Rock_Shale_Cobble",
      "rotation": 4
    },
    {
      "x": -14,
      "y": 29,
      "z": -2,
      "name": "Rock_Shale_Cobble",
      "rotation": 4
    },
    {
      "x": -14,
      "y": 8,
      "z": -1,
      "name": "Rock_Shale_Cobble_Half",
      "rotation": 7
    },
    {
      "x": -14,
      "y": 9,
      "z": -1,
      "name": "Rock_Shale_Cobble",
      "rotation": 17
    },
    {
      "x": -14,
      "y": 10,
      "z": -1,
      "name": "Rock_Shale_Cobble",
      "rotation": 17
    },
    {
      "x": -14,
      "y": 11,
      "z": -1,
      "name": "Rock_Shale_Cobble",
      "rotation": 17
    },
    {
      "x": -14,
      "y": 12,
      "z": -1,
      "name": "Rock_Shale_Cobble",
      "rotation": 17
    },
    {
      "x": -14,
      "y": 13,
      "z": -1,
      "name": "Rock_Shale_Cobble",
      "rotation": 17
    },
    {
      "x": -14,
      "y": 14,
      "z": -1,
      "name": "Rock_Shale_Cobble",
      "rotation": 17
    },
    {
      "x": -14,
      "y": 15,
      "z": -1,
      "name": "Rock_Shale_Cobble",
      "rotation": 17
    },
    {
      "x": -14,
      "y": 16,
      "z": -1,
      "name": "Rock_Shale_Cobble",
      "rotation": 17
    },
    {
      "x": -14,
      "y": 17,
      "z": -1,
      "name": "Rock_Shale_Cobble",
      "rotation": 6
    },
    {
      "x": -14,
      "y": 18,
      "z": -1,
      "name": "Rock_Shale_Cobble",
      "rotation": 6
    },
    {
      "x": -14,
      "y": 19,
      "z": -1,
      "name": "Rock_Shale_Cobble",
      "rotation": 6
    },
    {
      "x": -14,
      "y": 20,
      "z": -1,
      "name": "Rock_Shale_Cobble",
      "rotation": 6
    },
    {
      "x": -14,
      "y": 21,
      "z": -1,
      "name": "Rock_Shale_Cobble",
      "rotation": 6
    },
    {
      "x": -14,
      "y": 22,
      "z": -1,
      "name": "Rock_Shale_Cobble",
      "rotation": 4
    },
    {
      "x": -14,
      "y": 23,
      "z": -1,
      "name": "Rock_Shale_Cobble",
      "rotation": 4
    },
    {
      "x": -14,
      "y": 24,
      "z": -1,
      "name": "Rock_Shale_Cobble",
      "rotation": 4
    },
    {
      "x": -14,
      "y": 25,
      "z": -1,
      "name": "Rock_Shale_Cobble",
      "rotation": 4
    },
    {
      "x": -14,
      "y": 26,
      "z": -1,
      "name": "Rock_Shale_Cobble",
      "rotation": 4
    },
    {
      "x": -14,
      "y": 27,
      "z": -1,
      "name": "Rock_Shale_Cobble",
      "rotation": 4
    },
    {
      "x": -14,
      "y": 28,
      "z": -1,
      "name": "Rock_Shale_Cobble",
      "rotation": 4
    },
    {
      "x": -14,
      "y": 29,
      "z": -1,
      "name": "Rock_Shale_Cobble",
      "rotation": 4
    },
    {
      "x": -14,
      "y": 30,
      "z": -1,
      "name": "Rock_Shale_Cobble_Half",
      "rotation": 7
    },
    {
      "x": -14,
      "y": 9,
      "z": 0,
      "name": "Rock_Shale_Cobble",
      "rotation": 17
    },
    {
      "x": -14,
      "y": 10,
      "z": 0,
      "name": "Rock_Shale_Cobble",
      "rotation": 17
    },
    {
      "x": -14,
      "y": 11,
      "z": 0,
      "name": "Rock_Shale_Cobble",
      "rotation": 17
    },
    {
      "x": -14,
      "y": 12,
      "z": 0,
      "name": "Rock_Shale_Cobble",
      "rotation": 17
    },
    {
      "x": -14,
      "y": 13,
      "z": 0,
      "name": "Rock_Shale_Cobble",
      "rotation": 17
    },
    {
      "x": -14,
      "y": 14,
      "z": 0,
      "name": "Rock_Shale_Cobble",
      "rotation": 17
    },
    {
      "x": -14,
      "y": 15,
      "z": 0,
      "name": "Rock_Shale_Cobble",
      "rotation": 1
    },
    {
      "x": -14,
      "y": 16,
      "z": 0,
      "name": "Build_Lightsource_Cyan",
      "rotation": 5
    },
    {
      "x": -14,
      "y": 17,
      "z": 0,
      "name": "Build_Lightsource_Cyan",
      "rotation": 5
    },
    {
      "x": -14,
      "y": 18,
      "z": 0,
      "name": "Build_Lightsource_Cyan",
      "rotation": 1
    },
    {
      "x": -14,
      "y": 19,
      "z": 0,
      "name": "Build_Lightsource_Cyan",
      "rotation": 5
    },
    {
      "x": -14,
      "y": 20,
      "z": 0,
      "name": "Build_Lightsource_Cyan",
      "rotation": 5
    },
    {
      "x": -14,
      "y": 21,
      "z": 0,
      "name": "Build_Lightsource_Cyan",
      "rotation": 3
    },
    {
      "x": -14,
      "y": 22,
      "z": 0,
      "name": "Build_Lightsource_Cyan",
      "rotation": 5
    },
    {
      "x": -14,
      "y": 23,
      "z": 0,
      "name": "Rock_Shale_Cobble",
      "rotation": 4
    },
    {
      "x": -14,
      "y": 24,
      "z": 0,
      "name": "Rock_Shale_Cobble",
      "rotation": 4
    },
    {
      "x": -14,
      "y": 25,
      "z": 0,
      "name": "Rock_Shale_Cobble",
      "rotation": 4
    },
    {
      "x": -14,
      "y": 26,
      "z": 0,
      "name": "Rock_Shale_Cobble",
      "rotation": 4
    },
    {
      "x": -14,
      "y": 27,
      "z": 0,
      "name": "Rock_Shale_Cobble",
      "rotation": 4
    },
    {
      "x": -14,
      "y": 28,
      "z": 0,
      "name": "Rock_Shale_Cobble",
      "rotation": 4
    },
    {
      "x": -14,
      "y": 29,
      "z": 0,
      "name": "Rock_Shale_Cobble",
      "rotation": 4
    },
    {
      "x": -14,
      "y": 9,
      "z": 1,
      "name": "Rock_Shale_Cobble",
      "rotation": 17
    },
    {
      "x": -14,
      "y": 10,
      "z": 1,
      "name": "Rock_Shale_Cobble",
      "rotation": 17
    },
    {
      "x": -14,
      "y": 11,
      "z": 1,
      "name": "Rock_Shale_Cobble",
      "rotation": 17
    },
    {
      "x": -14,
      "y": 12,
      "z": 1,
      "name": "Rock_Shale_Cobble",
      "rotation": 17
    },
    {
      "x": -14,
      "y": 13,
      "z": 1,
      "name": "Rock_Shale_Cobble",
      "rotation": 17
    },
    {
      "x": -14,
      "y": 14,
      "z": 1,
      "name": "Rock_Shale_Cobble",
      "rotation": 17
    },
    {
      "x": -14,
      "y": 15,
      "z": 1,
      "name": "Rock_Shale_Cobble",
      "rotation": 1
    },
    {
      "x": -14,
      "y": 16,
      "z": 1,
      "name": "Build_Lightsource_Cyan",
      "rotation": 5
    },
    {
      "x": -14,
      "y": 17,
      "z": 1,
      "name": "Build_Lightsource_Cyan",
      "rotation": 5
    },
    {
      "x": -14,
      "y": 18,
      "z": 1,
      "name": "Build_Lightsource_Cyan",
      "rotation": 1
    },
    {
      "x": -14,
      "y": 19,
      "z": 1,
      "name": "Build_Lightsource_Cyan",
      "rotation": 5
    },
    {
      "x": -14,
      "y": 20,
      "z": 1,
      "name": "Build_Lightsource_Cyan",
      "rotation": 5
    },
    {
      "x": -14,
      "y": 21,
      "z": 1,
      "name": "Build_Lightsource_Cyan",
      "rotation": 3
    },
    {
      "x": -14,
      "y": 22,
      "z": 1,
      "name": "Build_Lightsource_Cyan",
      "rotation": 19
    },
    {
      "x": -14,
      "y": 23,
      "z": 1,
      "name": "Rock_Shale_Cobble",
      "rotation": 4
    },
    {
      "x": -14,
      "y": 24,
      "z": 1,
      "name": "Rock_Shale_Cobble",
      "rotation": 4
    },
    {
      "x": -14,
      "y": 25,
      "z": 1,
      "name": "Rock_Shale_Cobble",
      "rotation": 4
    },
    {
      "x": -14,
      "y": 26,
      "z": 1,
      "name": "Rock_Shale_Cobble",
      "rotation": 4
    },
    {
      "x": -14,
      "y": 27,
      "z": 1,
      "name": "Rock_Shale_Cobble",
      "rotation": 4
    },
    {
      "x": -14,
      "y": 28,
      "z": 1,
      "name": "Rock_Shale_Cobble",
      "rotation": 4
    },
    {
      "x": -14,
      "y": 29,
      "z": 1,
      "name": "Rock_Shale_Cobble",
      "rotation": 4
    },
    {
      "x": -14,
      "y": 8,
      "z": 2,
      "name": "Rock_Shale_Cobble_Half",
      "rotation": 7
    },
    {
      "x": -14,
      "y": 9,
      "z": 2,
      "name": "Rock_Shale_Cobble",
      "rotation": 17
    },
    {
      "x": -14,
      "y": 10,
      "z": 2,
      "name": "Rock_Shale_Cobble",
      "rotation": 17
    },
    {
      "x": -14,
      "y": 11,
      "z": 2,
      "name": "Rock_Shale_Cobble",
      "rotation": 17
    },
    {
      "x": -14,
      "y": 12,
      "z": 2,
      "name": "Rock_Shale_Cobble",
      "rotation": 17
    },
    {
      "x": -14,
      "y": 13,
      "z": 2,
      "name": "Rock_Shale_Cobble",
      "rotation": 17
    },
    {
      "x": -14,
      "y": 14,
      "z": 2,
      "name": "Rock_Shale_Cobble",
      "rotation": 17
    },
    {
      "x": -14,
      "y": 15,
      "z": 2,
      "name": "Rock_Shale_Cobble",
      "rotation": 17
    },
    {
      "x": -14,
      "y": 16,
      "z": 2,
      "name": "Rock_Shale_Cobble",
      "rotation": 17
    },
    {
      "x": -14,
      "y": 17,
      "z": 2,
      "name": "Rock_Shale_Cobble",
      "rotation": 6
    },
    {
      "x": -14,
      "y": 18,
      "z": 2,
      "name": "Rock_Shale_Cobble",
      "rotation": 6
    },
    {
      "x": -14,
      "y": 19,
      "z": 2,
      "name": "Rock_Shale_Cobble",
      "rotation": 6
    },
    {
      "x": -14,
      "y": 20,
      "z": 2,
      "name": "Rock_Shale_Cobble",
      "rotation": 6
    },
    {
      "x": -14,
      "y": 21,
      "z": 2,
      "name": "Build_Lightsource_Cyan",
      "rotation": 5
    },
    {
      "x": -14,
      "y": 22,
      "z": 2,
      "name": "Rock_Shale_Cobble",
      "rotation": 1
    },
    {
      "x": -14,
      "y": 23,
      "z": 2,
      "name": "Rock_Shale_Cobble",
      "rotation": 4
    },
    {
      "x": -14,
      "y": 24,
      "z": 2,
      "name": "Rock_Shale_Cobble",
      "rotation": 4
    },
    {
      "x": -14,
      "y": 25,
      "z": 2,
      "name": "Rock_Shale_Cobble",
      "rotation": 4
    },
    {
      "x": -14,
      "y": 26,
      "z": 2,
      "name": "Rock_Shale_Cobble",
      "rotation": 4
    },
    {
      "x": -14,
      "y": 27,
      "z": 2,
      "name": "Rock_Shale_Cobble",
      "rotation": 4
    },
    {
      "x": -14,
      "y": 28,
      "z": 2,
      "name": "Rock_Shale_Cobble",
      "rotation": 4
    },
    {
      "x": -14,
      "y": 29,
      "z": 2,
      "name": "Rock_Shale_Cobble",
      "rotation": 4
    },
    {
      "x": -14,
      "y": 30,
      "z": 2,
      "name": "Rock_Shale_Cobble_Half",
      "rotation": 7
    },
    {
      "x": -14,
      "y": 9,
      "z": 3,
      "name": "Rock_Shale_Cobble",
      "rotation": 17
    },
    {
      "x": -14,
      "y": 10,
      "z": 3,
      "name": "Rock_Shale_Cobble",
      "rotation": 17
    },
    {
      "x": -14,
      "y": 11,
      "z": 3,
      "name": "Rock_Shale_Cobble",
      "rotation": 17
    },
    {
      "x": -14,
      "y": 12,
      "z": 3,
      "name": "Rock_Shale_Cobble",
      "rotation": 17
    },
    {
      "x": -14,
      "y": 13,
      "z": 3,
      "name": "Rock_Shale_Cobble",
      "rotation": 17
    },
    {
      "x": -14,
      "y": 14,
      "z": 3,
      "name": "Rock_Shale_Cobble",
      "rotation": 17
    },
    {
      "x": -14,
      "y": 15,
      "z": 3,
      "name": "Rock_Shale_Cobble",
      "rotation": 17
    },
    {
      "x": -14,
      "y": 16,
      "z": 3,
      "name": "Rock_Shale_Cobble",
      "rotation": 17
    },
    {
      "x": -14,
      "y": 17,
      "z": 3,
      "name": "Rock_Shale_Cobble",
      "rotation": 6
    },
    {
      "x": -14,
      "y": 18,
      "z": 3,
      "name": "Rock_Shale_Cobble",
      "rotation": 6
    },
    {
      "x": -14,
      "y": 19,
      "z": 3,
      "name": "Build_Lightsource_Cyan",
      "rotation": 17
    },
    {
      "x": -14,
      "y": 20,
      "z": 3,
      "name": "Rock_Shale_Cobble",
      "rotation": 6
    },
    {
      "x": -14,
      "y": 21,
      "z": 3,
      "name": "Rock_Shale_Cobble",
      "rotation": 6
    },
    {
      "x": -14,
      "y": 22,
      "z": 3,
      "name": "Rock_Shale_Cobble",
      "rotation": 4
    },
    {
      "x": -14,
      "y": 23,
      "z": 3,
      "name": "Rock_Shale_Cobble",
      "rotation": 4
    },
    {
      "x": -14,
      "y": 24,
      "z": 3,
      "name": "Rock_Shale_Cobble",
      "rotation": 4
    },
    {
      "x": -14,
      "y": 25,
      "z": 3,
      "name": "Rock_Shale_Cobble",
      "rotation": 4
    },
    {
      "x": -14,
      "y": 26,
      "z": 3,
      "name": "Rock_Shale_Cobble",
      "rotation": 4
    },
    {
      "x": -14,
      "y": 27,
      "z": 3,
      "name": "Rock_Shale_Cobble",
      "rotation": 4
    },
    {
      "x": -14,
      "y": 28,
      "z": 3,
      "name": "Rock_Shale_Cobble",
      "rotation": 4
    },
    {
      "x": -14,
      "y": 29,
      "z": 3,
      "name": "Rock_Shale_Cobble",
      "rotation": 4
    },
    {
      "x": -14,
      "y": 11,
      "z": 4,
      "name": "Metal_Iron_Glowing_Pipe_Corner",
      "support": 15
    },
    {
      "x": -14,
      "y": 12,
      "z": 4,
      "name": "Metal_Iron_Glowing_Pipe_Corner",
      "support": 15,
      "rotation": 15
    },
    {
      "x": -14,
      "y": 17,
      "z": 4,
      "name": "Rock_Shale_Cobble",
      "rotation": 7
    },
    {
      "x": -14,
      "y": 18,
      "z": 4,
      "name": "Rock_Shale_Cobble",
      "rotation": 7
    },
    {
      "x": -14,
      "y": 19,
      "z": 4,
      "name": "Build_Lightsource_Cyan",
      "rotation": 17
    },
    {
      "x": -14,
      "y": 20,
      "z": 4,
      "name": "Metal_Iron_Glowing_Pipe_Corner",
      "support": 15,
      "rotation": 10
    },
    {
      "x": -14,
      "y": 21,
      "z": 4,
      "name": "Rock_Shale_Cobble",
      "rotation": 7
    },
    {
      "x": -14,
      "y": 22,
      "z": 4,
      "name": "Metal_Iron_Glowing_Pipe_Corner",
      "support": 15
    },
    {
      "x": -14,
      "y": 23,
      "z": 4,
      "name": "Metal_Iron_Glowing_Pipe",
      "support": 15
    },
    {
      "x": -14,
      "y": 24,
      "z": 4,
      "name": "Metal_Iron_Glowing_Pipe",
      "support": 15
    },
    {
      "x": -14,
      "y": 25,
      "z": 4,
      "name": "Metal_Iron_Glowing_Pipe_Corner",
      "support": 15,
      "rotation": 13
    },
    {
      "x": -14,
      "y": 17,
      "z": 5,
      "name": "Rock_Shale_Brick_Smooth",
      "rotation": 1
    },
    {
      "x": -14,
      "y": 21,
      "z": 5,
      "name": "Rock_Shale_Brick_Smooth",
      "rotation": 1
    },
    {
      "x": -13,
      "y": 17,
      "z": -3,
      "name": "Rock_Shale_Brick_Smooth",
      "rotation": 1
    },
    {
      "x": -13,
      "y": 21,
      "z": -3,
      "name": "Rock_Shale_Brick_Smooth",
      "rotation": 1
    },
    {
      "x": -13,
      "y": 29,
      "z": -3,
      "name": "Metal_Iron_Glowing_Pipe",
      "support": 15,
      "rotation": 5
    },
    {
      "x": -13,
      "y": 8,
      "z": -2,
      "name": "Rock_Shale_Cobble",
      "rotation": 17
    },
    {
      "x": -13,
      "y": 9,
      "z": -2,
      "name": "Rock_Shale_Cobble",
      "rotation": 17
    },
    {
      "x": -13,
      "y": 10,
      "z": -2,
      "name": "Rock_Shale_Cobble",
      "rotation": 17
    },
    {
      "x": -13,
      "y": 11,
      "z": -2,
      "name": "Rock_Shale_Cobble",
      "rotation": 17
    },
    {
      "x": -13,
      "y": 12,
      "z": -2,
      "name": "Rock_Shale_Cobble",
      "rotation": 17
    },
    {
      "x": -13,
      "y": 13,
      "z": -2,
      "name": "Rock_Shale_Cobble",
      "rotation": 17
    },
    {
      "x": -13,
      "y": 14,
      "z": -2,
      "name": "Rock_Shale_Cobble",
      "rotation": 17
    },
    {
      "x": -13,
      "y": 15,
      "z": -2,
      "name": "Rock_Shale_Cobble",
      "rotation": 1
    },
    {
      "x": -13,
      "y": 17,
      "z": -2,
      "name": "Rock_Shale_Cobble",
      "rotation": 7
    },
    {
      "x": -13,
      "y": 18,
      "z": -2,
      "name": "Rock_Shale_Cobble",
      "rotation": 1
    },
    {
      "x": -13,
      "y": 20,
      "z": -2,
      "name": "Rock_Shale_Cobble",
      "rotation": 1
    },
    {
      "x": -13,
      "y": 21,
      "z": -2,
      "name": "Rock_Shale_Cobble",
      "rotation": 7
    },
    {
      "x": -13,
      "y": 23,
      "z": -2,
      "name": "Rock_Shale_Cobble",
      "rotation": 4
    },
    {
      "x": -13,
      "y": 24,
      "z": -2,
      "name": "Rock_Shale_Cobble",
      "rotation": 4
    },
    {
      "x": -13,
      "y": 25,
      "z": -2,
      "name": "Rock_Shale_Cobble",
      "rotation": 4
    },
    {
      "x": -13,
      "y": 26,
      "z": -2,
      "name": "Rock_Shale_Cobble",
      "rotation": 4
    },
    {
      "x": -13,
      "y": 27,
      "z": -2,
      "name": "Rock_Shale_Cobble",
      "rotation": 4
    },
    {
      "x": -13,
      "y": 28,
      "z": -2,
      "name": "Rock_Shale_Cobble",
      "rotation": 4
    },
    {
      "x": -13,
      "y": 29,
      "z": -2,
      "name": "Rock_Shale_Cobble",
      "rotation": 4
    },
    {
      "x": -13,
      "y": 30,
      "z": -2,
      "name": "Rock_Shale_Cobble",
      "rotation": 4
    },
    {
      "x": -13,
      "y": 7,
      "z": -1,
      "name": "Rock_Shale_Cobble_Half",
      "rotation": 7
    },
    {
      "x": -13,
      "y": 8,
      "z": -1,
      "name": "Rock_Shale_Cobble",
      "rotation": 17
    },
    {
      "x": -13,
      "y": 9,
      "z": -1,
      "name": "Rock_Shale_Cobble",
      "rotation": 17
    },
    {
      "x": -13,
      "y": 10,
      "z": -1,
      "name": "Rock_Shale_Cobble",
      "rotation": 17
    },
    {
      "x": -13,
      "y": 11,
      "z": -1,
      "name": "Rock_Shale_Cobble",
      "rotation": 17
    },
    {
      "x": -13,
      "y": 12,
      "z": -1,
      "name": "Rock_Shale_Cobble",
      "rotation": 17
    },
    {
      "x": -13,
      "y": 13,
      "z": -1,
      "name": "Rock_Shale_Cobble",
      "rotation": 17
    },
    {
      "x": -13,
      "y": 14,
      "z": -1,
      "name": "Rock_Shale_Cobble",
      "rotation": 17
    },
    {
      "x": -13,
      "y": 15,
      "z": -1,
      "name": "Rock_Shale_Cobble",
      "rotation": 17
    },
    {
      "x": -13,
      "y": 16,
      "z": -1,
      "name": "Rock_Shale_Brick_Smooth",
      "rotation": 1
    },
    {
      "x": -13,
      "y": 17,
      "z": -1,
      "name": "Rock_Shale_Cobble",
      "rotation": 6
    },
    {
      "x": -13,
      "y": 18,
      "z": -1,
      "name": "Rock_Shale_Brick_Smooth",
      "rotation": 1
    },
    {
      "x": -13,
      "y": 19,
      "z": -1,
      "name": "Rock_Shale_Brick_Smooth",
      "rotation": 1
    },
    {
      "x": -13,
      "y": 20,
      "z": -1,
      "name": "Rock_Shale_Brick_Smooth",
      "rotation": 1
    },
    {
      "x": -13,
      "y": 21,
      "z": -1,
      "name": "Rock_Shale_Cobble",
      "rotation": 7
    },
    {
      "x": -13,
      "y": 22,
      "z": -1,
      "name": "Rock_Shale_Brick_Smooth",
      "rotation": 1
    },
    {
      "x": -13,
      "y": 23,
      "z": -1,
      "name": "Rock_Shale_Cobble",
      "rotation": 4
    },
    {
      "x": -13,
      "y": 24,
      "z": -1,
      "name": "Rock_Shale_Cobble",
      "rotation": 4
    },
    {
      "x": -13,
      "y": 25,
      "z": -1,
      "name": "Rock_Shale_Cobble",
      "rotation": 4
    },
    {
      "x": -13,
      "y": 26,
      "z": -1,
      "name": "Rock_Shale_Cobble",
      "rotation": 4
    },
    {
      "x": -13,
      "y": 27,
      "z": -1,
      "name": "Rock_Shale_Cobble",
      "rotation": 4
    },
    {
      "x": -13,
      "y": 28,
      "z": -1,
      "name": "Rock_Shale_Cobble",
      "rotation": 4
    },
    {
      "x": -13,
      "y": 29,
      "z": -1,
      "name": "Rock_Shale_Cobble",
      "rotation": 4
    },
    {
      "x": -13,
      "y": 30,
      "z": -1,
      "name": "Rock_Shale_Cobble",
      "rotation": 4
    },
    {
      "x": -13,
      "y": 31,
      "z": -1,
      "name": "Rock_Shale_Cobble_Half",
      "rotation": 7
    },
    {
      "x": -13,
      "y": 8,
      "z": 0,
      "name": "Rock_Shale_Cobble",
      "rotation": 17
    },
    {
      "x": -13,
      "y": 9,
      "z": 0,
      "name": "Rock_Shale_Cobble",
      "rotation": 17
    },
    {
      "x": -13,
      "y": 10,
      "z": 0,
      "name": "Rock_Shale_Cobble",
      "rotation": 17
    },
    {
      "x": -13,
      "y": 11,
      "z": 0,
      "name": "Rock_Shale_Cobble",
      "rotation": 17
    },
    {
      "x": -13,
      "y": 12,
      "z": 0,
      "name": "Rock_Shale_Cobble",
      "rotation": 17
    },
    {
      "x": -13,
      "y": 13,
      "z": 0,
      "name": "Build_Lightsource_Cyan",
      "rotation": 5
    },
    {
      "x": -13,
      "y": 14,
      "z": 0,
      "name": "Build_Lightsource_Cyan",
      "rotation": 5
    },
    {
      "x": -13,
      "y": 15,
      "z": 0,
      "name": "Build_Lightsource_Cyan",
      "rotation": 5
    },
    {
      "x": -13,
      "y": 17,
      "z": 0,
      "name": "Rock_Shale_Cobble",
      "rotation": 6
    },
    {
      "x": -13,
      "y": 18,
      "z": 0,
      "name": "Rock_Shale_Cobble",
      "rotation": 1
    },
    {
      "x": -13,
      "y": 20,
      "z": 0,
      "name": "Rock_Shale_Cobble",
      "rotation": 1
    },
    {
      "x": -13,
      "y": 21,
      "z": 0,
      "name": "Rock_Shale_Cobble",
      "rotation": 6
    },
    {
      "x": -13,
      "y": 23,
      "z": 0,
      "name": "Build_Lightsource_Cyan",
      "rotation": 5
    },
    {
      "x": -13,
      "y": 24,
      "z": 0,
      "name": "Build_Lightsource_Cyan",
      "rotation": 5
    },
    {
      "x": -13,
      "y": 25,
      "z": 0,
      "name": "Build_Lightsource_Cyan",
      "rotation": 5
    },
    {
      "x": -13,
      "y": 26,
      "z": 0,
      "name": "Rock_Shale_Cobble",
      "rotation": 4
    },
    {
      "x": -13,
      "y": 27,
      "z": 0,
      "name": "Rock_Shale_Cobble",
      "rotation": 4
    },
    {
      "x": -13,
      "y": 28,
      "z": 0,
      "name": "Rock_Shale_Cobble",
      "rotation": 4
    },
    {
      "x": -13,
      "y": 29,
      "z": 0,
      "name": "Rock_Shale_Cobble",
      "rotation": 4
    },
    {
      "x": -13,
      "y": 30,
      "z": 0,
      "name": "Rock_Shale_Cobble",
      "rotation": 4
    },
    {
      "x": -13,
      "y": 8,
      "z": 1,
      "name": "Rock_Shale_Cobble",
      "rotation": 17
    },
    {
      "x": -13,
      "y": 9,
      "z": 1,
      "name": "Rock_Shale_Cobble",
      "rotation": 17
    },
    {
      "x": -13,
      "y": 10,
      "z": 1,
      "name": "Rock_Shale_Cobble",
      "rotation": 17
    },
    {
      "x": -13,
      "y": 11,
      "z": 1,
      "name": "Rock_Shale_Cobble",
      "rotation": 1
    },
    {
      "x": -13,
      "y": 12,
      "z": 1,
      "name": "Rock_Shale_Cobble",
      "rotation": 17
    },
    {
      "x": -13,
      "y": 13,
      "z": 1,
      "name": "Build_Lightsource_Cyan",
      "rotation": 5
    },
    {
      "x": -13,
      "y": 14,
      "z": 1,
      "name": "Build_Lightsource_Cyan",
      "rotation": 5
    },
    {
      "x": -13,
      "y": 15,
      "z": 1,
      "name": "Build_Lightsource_Cyan",
      "rotation": 5
    },
    {
      "x": -13,
      "y": 17,
      "z": 1,
      "name": "Rock_Shale_Cobble",
      "rotation": 6
    },
    {
      "x": -13,
      "y": 18,
      "z": 1,
      "name": "Rock_Shale_Cobble",
      "rotation": 1
    },
    {
      "x": -13,
      "y": 20,
      "z": 1,
      "name": "Rock_Shale_Cobble",
      "rotation": 1
    },
    {
      "x": -13,
      "y": 21,
      "z": 1,
      "name": "Rock_Shale_Cobble",
      "rotation": 1
    },
    {
      "x": -13,
      "y": 23,
      "z": 1,
      "name": "Build_Lightsource_Cyan",
      "rotation": 5
    },
    {
      "x": -13,
      "y": 24,
      "z": 1,
      "name": "Build_Lightsource_Cyan",
      "rotation": 19
    },
    {
      "x": -13,
      "y": 25,
      "z": 1,
      "name": "Build_Lightsource_Cyan",
      "rotation": 19
    },
    {
      "x": -13,
      "y": 26,
      "z": 1,
      "name": "Rock_Shale_Cobble",
      "rotation": 4
    },
    {
      "x": -13,
      "y": 27,
      "z": 1,
      "name": "Rock_Shale_Cobble",
      "rotation": 4
    },
    {
      "x": -13,
      "y": 28,
      "z": 1,
      "name": "Rock_Shale_Cobble",
      "rotation": 4
    },
    {
      "x": -13,
      "y": 29,
      "z": 1,
      "name": "Rock_Shale_Cobble",
      "rotation": 4
    },
    {
      "x": -13,
      "y": 30,
      "z": 1,
      "name": "Rock_Shale_Cobble",
      "rotation": 4
    },
    {
      "x": -13,
      "y": 7,
      "z": 2,
      "name": "Rock_Shale_Cobble_Half",
      "rotation": 7
    },
    {
      "x": -13,
      "y": 8,
      "z": 2,
      "name": "Rock_Shale_Cobble",
      "rotation": 17
    },
    {
      "x": -13,
      "y": 9,
      "z": 2,
      "name": "Rock_Shale_Cobble",
      "rotation": 17
    },
    {
      "x": -13,
      "y": 10,
      "z": 2,
      "name": "Rock_Shale_Cobble",
      "rotation": 17
    },
    {
      "x": -13,
      "y": 11,
      "z": 2,
      "name": "Rock_Shale_Cobble",
      "rotation": 17
    },
    {
      "x": -13,
      "y": 12,
      "z": 2,
      "name": "Rock_Shale_Cobble",
      "rotation": 17
    },
    {
      "x": -13,
      "y": 13,
      "z": 2,
      "name": "Rock_Shale_Cobble",
      "rotation": 17
    },
    {
      "x": -13,
      "y": 14,
      "z": 2,
      "name": "Rock_Shale_Cobble",
      "rotation": 17
    },
    {
      "x": -13,
      "y": 15,
      "z": 2,
      "name": "Rock_Shale_Cobble",
      "rotation": 17
    },
    {
      "x": -13,
      "y": 16,
      "z": 2,
      "name": "Rock_Shale_Brick_Smooth",
      "rotation": 1
    },
    {
      "x": -13,
      "y": 17,
      "z": 2,
      "name": "Rock_Shale_Cobble",
      "rotation": 6
    },
    {
      "x": -13,
      "y": 18,
      "z": 2,
      "name": "Rock_Shale_Brick_Smooth",
      "rotation": 1
    },
    {
      "x": -13,
      "y": 19,
      "z": 2,
      "name": "Rock_Shale_Brick_Smooth",
      "rotation": 1
    },
    {
      "x": -13,
      "y": 20,
      "z": 2,
      "name": "Rock_Shale_Brick_Smooth",
      "rotation": 1
    },
    {
      "x": -13,
      "y": 21,
      "z": 2,
      "name": "Rock_Shale_Cobble",
      "rotation": 1
    },
    {
      "x": -13,
      "y": 22,
      "z": 2,
      "name": "Rock_Shale_Brick_Smooth",
      "rotation": 1
    },
    {
      "x": -13,
      "y": 23,
      "z": 2,
      "name": "Rock_Shale_Cobble",
      "rotation": 1
    },
    {
      "x": -13,
      "y": 24,
      "z": 2,
      "name": "Rock_Shale_Cobble",
      "rotation": 4
    },
    {
      "x": -13,
      "y": 25,
      "z": 2,
      "name": "Rock_Shale_Cobble",
      "rotation": 4
    },
    {
      "x": -13,
      "y": 26,
      "z": 2,
      "name": "Rock_Shale_Cobble",
      "rotation": 4
    },
    {
      "x": -13,
      "y": 27,
      "z": 2,
      "name": "Rock_Shale_Cobble",
      "rotation": 4
    },
    {
      "x": -13,
      "y": 28,
      "z": 2,
      "name": "Rock_Shale_Cobble",
      "rotation": 4
    },
    {
      "x": -13,
      "y": 29,
      "z": 2,
      "name": "Rock_Shale_Cobble",
      "rotation": 4
    },
    {
      "x": -13,
      "y": 30,
      "z": 2,
      "name": "Rock_Shale_Cobble",
      "rotation": 4
    },
    {
      "x": -13,
      "y": 31,
      "z": 2,
      "name": "Rock_Shale_Cobble_Half",
      "rotation": 7
    },
    {
      "x": -13,
      "y": 8,
      "z": 3,
      "name": "Rock_Shale_Cobble",
      "rotation": 17
    },
    {
      "x": -13,
      "y": 9,
      "z": 3,
      "name": "Rock_Shale_Cobble",
      "rotation": 17
    },
    {
      "x": -13,
      "y": 10,
      "z": 3,
      "name": "Rock_Shale_Cobble",
      "rotation": 17
    },
    {
      "x": -13,
      "y": 11,
      "z": 3,
      "name": "Rock_Shale_Cobble",
      "rotation": 17
    },
    {
      "x": -13,
      "y": 12,
      "z": 3,
      "name": "Rock_Shale_Cobble",
      "rotation": 17
    },
    {
      "x": -13,
      "y": 13,
      "z": 3,
      "name": "Rock_Shale_Cobble",
      "rotation": 17
    },
    {
      "x": -13,
      "y": 14,
      "z": 3,
      "name": "Rock_Shale_Cobble",
      "rotation": 17
    },
    {
      "x": -13,
      "y": 15,
      "z": 3,
      "name": "Rock_Shale_Cobble",
      "rotation": 17
    },
    {
      "x": -13,
      "y": 17,
      "z": 3,
      "name": "Rock_Shale_Cobble",
      "rotation": 7
    },
    {
      "x": -13,
      "y": 18,
      "z": 3,
      "name": "Rock_Shale_Cobble",
      "rotation": 1
    },
    {
      "x": -13,
      "y": 20,
      "z": 3,
      "name": "Rock_Shale_Cobble",
      "rotation": 1
    },
    {
      "x": -13,
      "y": 21,
      "z": 3,
      "name": "Rock_Shale_Cobble",
      "rotation": 6
    },
    {
      "x": -13,
      "y": 23,
      "z": 3,
      "name": "Rock_Shale_Cobble",
      "rotation": 1
    },
    {
      "x": -13,
      "y": 24,
      "z": 3,
      "name": "Rock_Shale_Cobble",
      "rotation": 4
    },
    {
      "x": -13,
      "y": 25,
      "z": 3,
      "name": "Rock_Shale_Cobble",
      "rotation": 4
    },
    {
      "x": -13,
      "y": 26,
      "z": 3,
      "name": "Rock_Shale_Cobble",
      "rotation": 4
    },
    {
      "x": -13,
      "y": 27,
      "z": 3,
      "name": "Rock_Shale_Cobble",
      "rotation": 4
    },
    {
      "x": -13,
      "y": 28,
      "z": 3,
      "name": "Rock_Shale_Cobble",
      "rotation": 4
    },
    {
      "x": -13,
      "y": 29,
      "z": 3,
      "name": "Rock_Shale_Cobble",
      "rotation": 4
    },
    {
      "x": -13,
      "y": 30,
      "z": 3,
      "name": "Rock_Shale_Cobble",
      "rotation": 4
    },
    {
      "x": -13,
      "y": 12,
      "z": 4,
      "name": "Metal_Iron_Glowing_Pipe",
      "support": 15,
      "rotation": 5
    },
    {
      "x": -13,
      "y": 17,
      "z": 4,
      "name": "Rock_Shale_Brick_Smooth",
      "rotation": 1
    },
    {
      "x": -13,
      "y": 21,
      "z": 4,
      "name": "Rock_Shale_Brick_Smooth",
      "rotation": 1
    },
    {
      "x": -12,
      "y": 29,
      "z": -3,
      "name": "Metal_Iron_Glowing_Pipe_Corner",
      "support": 15,
      "rotation": 1
    },
    {
      "x": -12,
      "y": 30,
      "z": -3,
      "name": "Metal_Iron_Glowing_Pipe_Corner",
      "support": 15,
      "rotation": 15
    },
    {
      "x": -12,
      "y": 7,
      "z": -2,
      "name": "Rock_Shale_Cobble",
      "rotation": 17
    },
    {
      "x": -12,
      "y": 8,
      "z": -2,
      "name": "Rock_Shale_Cobble",
      "rotation": 17
    },
    {
      "x": -12,
      "y": 9,
      "z": -2,
      "name": "Rock_Shale_Cobble",
      "rotation": 17
    },
    {
      "x": -12,
      "y": 10,
      "z": -2,
      "name": "Rock_Shale_Cobble",
      "rotation": 17
    },
    {
      "x": -12,
      "y": 11,
      "z": -2,
      "name": "Rock_Shale_Cobble",
      "rotation": 17
    },
    {
      "x": -12,
      "y": 12,
      "z": -2,
      "name": "Rock_Shale_Cobble",
      "rotation": 17
    },
    {
      "x": -12,
      "y": 17,
      "z": -2,
      "name": "Rock_Shale_Brick_Smooth",
      "rotation": 1
    },
    {
      "x": -12,
      "y": 21,
      "z": -2,
      "name": "Rock_Shale_Brick_Smooth",
      "rotation": 1
    },
    {
      "x": -12,
      "y": 26,
      "z": -2,
      "name": "Rock_Shale_Cobble",
      "rotation": 4
    },
    {
      "x": -12,
      "y": 27,
      "z": -2,
      "name": "Rock_Shale_Cobble",
      "rotation": 4
    },
    {
      "x": -12,
      "y": 28,
      "z": -2,
      "name": "Rock_Shale_Cobble",
      "rotation": 4
    },
    {
      "x": -12,
      "y": 29,
      "z": -2,
      "name": "Rock_Shale_Cobble",
      "rotation": 4
    },
    {
      "x": -12,
      "y": 30,
      "z": -2,
      "name": "Rock_Shale_Cobble",
      "rotation": 4
    },
    {
      "x": -12,
      "y": 31,
      "z": -2,
      "name": "Rock_Shale_Cobble",
      "rotation": 4
    },
    {
      "x": -12,
      "y": 6,
      "z": -1,
      "name": "Rock_Shale_Cobble_Half",
      "rotation": 35
    },
    {
      "x": -12,
      "y": 7,
      "z": -1,
      "name": "Rock_Shale_Cobble",
      "rotation": 17
    },
    {
      "x": -12,
      "y": 8,
      "z": -1,
      "name": "Rock_Shale_Cobble",
      "rotation": 17
    },
    {
      "x": -12,
      "y": 9,
      "z": -1,
      "name": "Rock_Shale_Cobble",
      "rotation": 17
    },
    {
      "x": -12,
      "y": 10,
      "z": -1,
      "name": "Rock_Shale_Cobble",
      "rotation": 17
    },
    {
      "x": -12,
      "y": 11,
      "z": -1,
      "name": "Rock_Shale_Cobble",
      "rotation": 17
    },
    {
      "x": -12,
      "y": 12,
      "z": -1,
      "name": "Rock_Shale_Cobble",
      "rotation": 17
    },
    {
      "x": -12,
      "y": 13,
      "z": -1,
      "name": "Rock_Shale_Brick_Smooth",
      "rotation": 1
    },
    {
      "x": -12,
      "y": 14,
      "z": -1,
      "name": "Rock_Shale_Brick_Smooth",
      "rotation": 1
    },
    {
      "x": -12,
      "y": 15,
      "z": -1,
      "name": "Rock_Shale_Brick_Smooth",
      "rotation": 1
    },
    {
      "x": -12,
      "y": 17,
      "z": -1,
      "name": "Rock_Shale_Brick_Smooth",
      "rotation": 1
    },
    {
      "x": -12,
      "y": 21,
      "z": -1,
      "name": "Rock_Shale_Brick_Smooth",
      "rotation": 1
    },
    {
      "x": -12,
      "y": 23,
      "z": -1,
      "name": "Rock_Shale_Brick_Smooth",
      "rotation": 1
    },
    {
      "x": -12,
      "y": 24,
      "z": -1,
      "name": "Rock_Shale_Brick_Smooth",
      "rotation": 1
    },
    {
      "x": -12,
      "y": 25,
      "z": -1,
      "name": "Rock_Shale_Brick_Smooth",
      "rotation": 1
    },
    {
      "x": -12,
      "y": 26,
      "z": -1,
      "name": "Rock_Shale_Cobble",
      "rotation": 4
    },
    {
      "x": -12,
      "y": 27,
      "z": -1,
      "name": "Rock_Shale_Cobble",
      "rotation": 4
    },
    {
      "x": -12,
      "y": 28,
      "z": -1,
      "name": "Rock_Shale_Cobble",
      "rotation": 4
    },
    {
      "x": -12,
      "y": 29,
      "z": -1,
      "name": "Rock_Shale_Cobble",
      "rotation": 4
    },
    {
      "x": -12,
      "y": 30,
      "z": -1,
      "name": "Rock_Shale_Cobble",
      "rotation": 4
    },
    {
      "x": -12,
      "y": 31,
      "z": -1,
      "name": "Rock_Shale_Cobble",
      "rotation": 4
    },
    {
      "x": -12,
      "y": 32,
      "z": -1,
      "name": "Rock_Shale_Cobble_Half",
      "rotation": 1
    },
    {
      "x": -12,
      "y": 7,
      "z": 0,
      "name": "Rock_Shale_Cobble",
      "rotation": 17
    },
    {
      "x": -12,
      "y": 8,
      "z": 0,
      "name": "Rock_Shale_Cobble",
      "rotation": 17
    },
    {
      "x": -12,
      "y": 9,
      "z": 0,
      "name": "Rock_Shale_Cobble",
      "rotation": 17
    },
    {
      "x": -12,
      "y": 10,
      "z": 0,
      "name": "Rock_Shale_Cobble",
      "rotation": 17
    },
    {
      "x": -12,
      "y": 11,
      "z": 0,
      "name": "Build_Lightsource_Cyan",
      "rotation": 1
    },
    {
      "x": -12,
      "y": 12,
      "z": 0,
      "name": "Build_Lightsource_Cyan",
      "rotation": 1
    },
    {
      "x": -12,
      "y": 17,
      "z": 0,
      "name": "Rock_Shale_Brick_Smooth",
      "rotation": 1
    },
    {
      "x": -12,
      "y": 21,
      "z": 0,
      "name": "Rock_Shale_Brick_Smooth",
      "rotation": 1
    },
    {
      "x": -12,
      "y": 26,
      "z": 0,
      "name": "Build_Lightsource_Cyan",
      "rotation": 35
    },
    {
      "x": -12,
      "y": 27,
      "z": 0,
      "name": "Build_Lightsource_Cyan",
      "rotation": 35
    },
    {
      "x": -12,
      "y": 28,
      "z": 0,
      "name": "Rock_Shale_Cobble",
      "rotation": 4
    },
    {
      "x": -12,
      "y": 29,
      "z": 0,
      "name": "Rock_Shale_Cobble",
      "rotation": 4
    },
    {
      "x": -12,
      "y": 30,
      "z": 0,
      "name": "Rock_Shale_Cobble",
      "rotation": 4
    },
    {
      "x": -12,
      "y": 31,
      "z": 0,
      "name": "Rock_Shale_Cobble",
      "rotation": 4
    },
    {
      "x": -12,
      "y": 7,
      "z": 1,
      "name": "Rock_Shale_Cobble",
      "rotation": 17
    },
    {
      "x": -12,
      "y": 8,
      "z": 1,
      "name": "Rock_Shale_Cobble",
      "rotation": 17
    },
    {
      "x": -12,
      "y": 9,
      "z": 1,
      "name": "Rock_Shale_Cobble",
      "rotation": 17
    },
    {
      "x": -12,
      "y": 10,
      "z": 1,
      "name": "Rock_Shale_Cobble",
      "rotation": 17
    },
    {
      "x": -12,
      "y": 11,
      "z": 1,
      "name": "Build_Lightsource_Cyan",
      "rotation": 1
    },
    {
      "x": -12,
      "y": 12,
      "z": 1,
      "name": "Build_Lightsource_Cyan",
      "rotation": 1
    },
    {
      "x": -12,
      "y": 17,
      "z": 1,
      "name": "Rock_Shale_Brick_Smooth",
      "rotation": 1
    },
    {
      "x": -12,
      "y": 21,
      "z": 1,
      "name": "Rock_Shale_Brick_Smooth",
      "rotation": 1
    },
    {
      "x": -12,
      "y": 26,
      "z": 1,
      "name": "Build_Lightsource_Cyan",
      "rotation": 35
    },
    {
      "x": -12,
      "y": 27,
      "z": 1,
      "name": "Build_Lightsource_Cyan",
      "rotation": 5
    },
    {
      "x": -12,
      "y": 28,
      "z": 1,
      "name": "Rock_Shale_Cobble",
      "rotation": 4
    },
    {
      "x": -12,
      "y": 29,
      "z": 1,
      "name": "Rock_Shale_Cobble",
      "rotation": 4
    },
    {
      "x": -12,
      "y": 30,
      "z": 1,
      "name": "Rock_Shale_Cobble",
      "rotation": 4
    },
    {
      "x": -12,
      "y": 31,
      "z": 1,
      "name": "Rock_Shale_Cobble",
      "rotation": 4
    },
    {
      "x": -12,
      "y": 6,
      "z": 2,
      "name": "Rock_Shale_Cobble_Half",
      "rotation": 35
    },
    {
      "x": -12,
      "y": 7,
      "z": 2,
      "name": "Rock_Shale_Cobble",
      "rotation": 17
    },
    {
      "x": -12,
      "y": 8,
      "z": 2,
      "name": "Rock_Shale_Cobble",
      "rotation": 17
    },
    {
      "x": -12,
      "y": 9,
      "z": 2,
      "name": "Rock_Shale_Cobble",
      "rotation": 17
    },
    {
      "x": -12,
      "y": 10,
      "z": 2,
      "name": "Rock_Shale_Cobble",
      "rotation": 17
    },
    {
      "x": -12,
      "y": 11,
      "z": 2,
      "name": "Rock_Shale_Cobble",
      "rotation": 17
    },
    {
      "x": -12,
      "y": 12,
      "z": 2,
      "name": "Rock_Shale_Cobble",
      "rotation": 1
    },
    {
      "x": -12,
      "y": 13,
      "z": 2,
      "name": "Rock_Shale_Brick_Smooth",
      "rotation": 1
    },
    {
      "x": -12,
      "y": 14,
      "z": 2,
      "name": "Rock_Shale_Brick_Smooth",
      "rotation": 1
    },
    {
      "x": -12,
      "y": 15,
      "z": 2,
      "name": "Rock_Shale_Brick_Smooth",
      "rotation": 1
    },
    {
      "x": -12,
      "y": 17,
      "z": 2,
      "name": "Rock_Shale_Brick_Smooth",
      "rotation": 1
    },
    {
      "x": -12,
      "y": 21,
      "z": 2,
      "name": "Rock_Shale_Brick_Smooth",
      "rotation": 1
    },
    {
      "x": -12,
      "y": 23,
      "z": 2,
      "name": "Rock_Shale_Brick_Smooth",
      "rotation": 1
    },
    {
      "x": -12,
      "y": 24,
      "z": 2,
      "name": "Rock_Shale_Brick_Smooth",
      "rotation": 1
    },
    {
      "x": -12,
      "y": 25,
      "z": 2,
      "name": "Rock_Shale_Brick_Smooth",
      "rotation": 1
    },
    {
      "x": -12,
      "y": 26,
      "z": 2,
      "name": "Rock_Shale_Cobble",
      "rotation": 4
    },
    {
      "x": -12,
      "y": 27,
      "z": 2,
      "name": "Rock_Shale_Cobble",
      "rotation": 4
    },
    {
      "x": -12,
      "y": 28,
      "z": 2,
      "name": "Rock_Shale_Cobble",
      "rotation": 4
    },
    {
      "x": -12,
      "y": 29,
      "z": 2,
      "name": "Rock_Shale_Cobble",
      "rotation": 4
    },
    {
      "x": -12,
      "y": 30,
      "z": 2,
      "name": "Rock_Shale_Cobble",
      "rotation": 4
    },
    {
      "x": -12,
      "y": 31,
      "z": 2,
      "name": "Rock_Shale_Cobble",
      "rotation": 4
    },
    {
      "x": -12,
      "y": 32,
      "z": 2,
      "name": "Rock_Shale_Cobble_Half",
      "rotation": 1
    },
    {
      "x": -12,
      "y": 7,
      "z": 3,
      "name": "Rock_Shale_Cobble",
      "rotation": 17
    },
    {
      "x": -12,
      "y": 8,
      "z": 3,
      "name": "Rock_Shale_Cobble",
      "rotation": 17
    },
    {
      "x": -12,
      "y": 9,
      "z": 3,
      "name": "Rock_Shale_Cobble",
      "rotation": 17
    },
    {
      "x": -12,
      "y": 10,
      "z": 3,
      "name": "Rock_Shale_Cobble",
      "rotation": 17
    },
    {
      "x": -12,
      "y": 11,
      "z": 3,
      "name": "Rock_Shale_Cobble",
      "rotation": 17
    },
    {
      "x": -12,
      "y": 12,
      "z": 3,
      "name": "Rock_Shale_Cobble",
      "rotation": 17
    },
    {
      "x": -12,
      "y": 17,
      "z": 3,
      "name": "Rock_Shale_Brick_Smooth",
      "rotation": 1
    },
    {
      "x": -12,
      "y": 21,
      "z": 3,
      "name": "Rock_Shale_Brick_Smooth",
      "rotation": 1
    },
    {
      "x": -12,
      "y": 26,
      "z": 3,
      "name": "Rock_Shale_Cobble",
      "rotation": 4
    },
    {
      "x": -12,
      "y": 27,
      "z": 3,
      "name": "Rock_Shale_Cobble",
      "rotation": 4
    },
    {
      "x": -12,
      "y": 28,
      "z": 3,
      "name": "Rock_Shale_Cobble",
      "rotation": 4
    },
    {
      "x": -12,
      "y": 29,
      "z": 3,
      "name": "Rock_Shale_Cobble",
      "rotation": 4
    },
    {
      "x": -12,
      "y": 30,
      "z": 3,
      "name": "Rock_Shale_Cobble",
      "rotation": 4
    },
    {
      "x": -12,
      "y": 31,
      "z": 3,
      "name": "Rock_Shale_Cobble",
      "rotation": 4
    },
    {
      "x": -12,
      "y": 12,
      "z": 4,
      "name": "Metal_Iron_Glowing_Pipe",
      "support": 15,
      "rotation": 5
    },
    {
      "x": -11,
      "y": 30,
      "z": -3,
      "name": "Metal_Iron_Glowing_Pipe",
      "support": 15,
      "rotation": 5
    },
    {
      "x": -11,
      "y": 6,
      "z": -2,
      "name": "Rock_Shale_Cobble",
      "rotation": 17
    },
    {
      "x": -11,
      "y": 7,
      "z": -2,
      "name": "Rock_Shale_Cobble",
      "rotation": 17
    },
    {
      "x": -11,
      "y": 8,
      "z": -2,
      "name": "Rock_Shale_Cobble",
      "rotation": 17
    },
    {
      "x": -11,
      "y": 9,
      "z": -2,
      "name": "Rock_Shale_Cobble",
      "rotation": 17
    },
    {
      "x": -11,
      "y": 10,
      "z": -2,
      "name": "Rock_Shale_Cobble",
      "rotation": 17
    },
    {
      "x": -11,
      "y": 28,
      "z": -2,
      "name": "Rock_Shale_Cobble",
      "rotation": 4
    },
    {
      "x": -11,
      "y": 29,
      "z": -2,
      "name": "Rock_Shale_Cobble",
      "rotation": 4
    },
    {
      "x": -11,
      "y": 30,
      "z": -2,
      "name": "Rock_Shale_Cobble",
      "rotation": 4
    },
    {
      "x": -11,
      "y": 31,
      "z": -2,
      "name": "Rock_Shale_Cobble",
      "rotation": 4
    },
    {
      "x": -11,
      "y": 32,
      "z": -2,
      "name": "Rock_Shale_Cobble",
      "rotation": 4
    },
    {
      "x": -11,
      "y": 5,
      "z": -1,
      "name": "Rock_Shale_Cobble_Half",
      "rotation": 35
    },
    {
      "x": -11,
      "y": 6,
      "z": -1,
      "name": "Rock_Shale_Cobble",
      "rotation": 17
    },
    {
      "x": -11,
      "y": 7,
      "z": -1,
      "name": "Rock_Shale_Cobble",
      "rotation": 17
    },
    {
      "x": -11,
      "y": 8,
      "z": -1,
      "name": "Rock_Shale_Cobble",
      "rotation": 17
    },
    {
      "x": -11,
      "y": 9,
      "z": -1,
      "name": "Rock_Shale_Cobble",
      "rotation": 17
    },
    {
      "x": -11,
      "y": 10,
      "z": -1,
      "name": "Rock_Shale_Cobble",
      "rotation": 17
    },
    {
      "x": -11,
      "y": 11,
      "z": -1,
      "name": "Rock_Shale_Brick_Smooth",
      "rotation": 1
    },
    {
      "x": -11,
      "y": 12,
      "z": -1,
      "name": "Rock_Shale_Brick_Smooth",
      "rotation": 1
    },
    {
      "x": -11,
      "y": 26,
      "z": -1,
      "name": "Rock_Shale_Brick_Smooth",
      "rotation": 1
    },
    {
      "x": -11,
      "y": 27,
      "z": -1,
      "name": "Rock_Shale_Brick_Smooth",
      "rotation": 1
    },
    {
      "x": -11,
      "y": 28,
      "z": -1,
      "name": "Rock_Shale_Cobble",
      "rotation": 4
    },
    {
      "x": -11,
      "y": 29,
      "z": -1,
      "name": "Rock_Shale_Cobble",
      "rotation": 4
    },
    {
      "x": -11,
      "y": 30,
      "z": -1,
      "name": "Rock_Shale_Cobble",
      "rotation": 4
    },
    {
      "x": -11,
      "y": 31,
      "z": -1,
      "name": "Rock_Shale_Cobble",
      "rotation": 4
    },
    {
      "x": -11,
      "y": 32,
      "z": -1,
      "name": "Rock_Shale_Cobble",
      "rotation": 4
    },
    {
      "x": -11,
      "y": 33,
      "z": -1,
      "name": "Rock_Shale_Cobble_Half",
      "rotation": 1
    },
    {
      "x": -11,
      "y": 6,
      "z": 0,
      "name": "Rock_Shale_Cobble",
      "rotation": 17
    },
    {
      "x": -11,
      "y": 7,
      "z": 0,
      "name": "Rock_Shale_Cobble",
      "rotation": 17
    },
    {
      "x": -11,
      "y": 8,
      "z": 0,
      "name": "Rock_Shale_Cobble",
      "rotation": 17
    },
    {
      "x": -11,
      "y": 9,
      "z": 0,
      "name": "Rock_Shale_Cobble",
      "rotation": 17
    },
    {
      "x": -11,
      "y": 10,
      "z": 0,
      "name": "Build_Lightsource_Cyan",
      "rotation": 1
    },
    {
      "x": -11,
      "y": 28,
      "z": 0,
      "name": "Build_Lightsource_Cyan",
      "rotation": 5
    },
    {
      "x": -11,
      "y": 29,
      "z": 0,
      "name": "Build_Lightsource_Cyan",
      "rotation": 35
    },
    {
      "x": -11,
      "y": 30,
      "z": 0,
      "name": "Rock_Shale_Cobble",
      "rotation": 4
    },
    {
      "x": -11,
      "y": 31,
      "z": 0,
      "name": "Rock_Shale_Cobble",
      "rotation": 4
    },
    {
      "x": -11,
      "y": 32,
      "z": 0,
      "name": "Rock_Shale_Cobble",
      "rotation": 4
    },
    {
      "x": -11,
      "y": 6,
      "z": 1,
      "name": "Rock_Shale_Cobble",
      "rotation": 17
    },
    {
      "x": -11,
      "y": 7,
      "z": 1,
      "name": "Rock_Shale_Cobble",
      "rotation": 17
    },
    {
      "x": -11,
      "y": 8,
      "z": 1,
      "name": "Rock_Shale_Cobble",
      "rotation": 17
    },
    {
      "x": -11,
      "y": 9,
      "z": 1,
      "name": "Rock_Shale_Cobble",
      "rotation": 1
    },
    {
      "x": -11,
      "y": 10,
      "z": 1,
      "name": "Build_Lightsource_Cyan",
      "rotation": 1
    },
    {
      "x": -11,
      "y": 28,
      "z": 1,
      "name": "Build_Lightsource_Cyan",
      "rotation": 35
    },
    {
      "x": -11,
      "y": 29,
      "z": 1,
      "name": "Rock_Shale_Cobble",
      "rotation": 4
    },
    {
      "x": -11,
      "y": 30,
      "z": 1,
      "name": "Rock_Shale_Cobble",
      "rotation": 4
    },
    {
      "x": -11,
      "y": 31,
      "z": 1,
      "name": "Rock_Shale_Cobble",
      "rotation": 4
    },
    {
      "x": -11,
      "y": 32,
      "z": 1,
      "name": "Rock_Shale_Cobble",
      "rotation": 4
    },
    {
      "x": -11,
      "y": 5,
      "z": 2,
      "name": "Rock_Shale_Cobble_Half",
      "rotation": 35
    },
    {
      "x": -11,
      "y": 6,
      "z": 2,
      "name": "Rock_Shale_Cobble",
      "rotation": 17
    },
    {
      "x": -11,
      "y": 7,
      "z": 2,
      "name": "Rock_Shale_Cobble",
      "rotation": 17
    },
    {
      "x": -11,
      "y": 8,
      "z": 2,
      "name": "Rock_Shale_Cobble",
      "rotation": 17
    },
    {
      "x": -11,
      "y": 9,
      "z": 2,
      "name": "Rock_Shale_Cobble",
      "rotation": 1
    },
    {
      "x": -11,
      "y": 10,
      "z": 2,
      "name": "Rock_Shale_Cobble",
      "rotation": 17
    },
    {
      "x": -11,
      "y": 11,
      "z": 2,
      "name": "Rock_Shale_Brick_Smooth",
      "rotation": 1
    },
    {
      "x": -11,
      "y": 12,
      "z": 2,
      "name": "Rock_Shale_Brick_Smooth",
      "rotation": 1
    },
    {
      "x": -11,
      "y": 26,
      "z": 2,
      "name": "Rock_Shale_Brick_Smooth",
      "rotation": 1
    },
    {
      "x": -11,
      "y": 27,
      "z": 2,
      "name": "Rock_Shale_Brick_Smooth",
      "rotation": 1
    },
    {
      "x": -11,
      "y": 28,
      "z": 2,
      "name": "Rock_Shale_Cobble",
      "rotation": 4
    },
    {
      "x": -11,
      "y": 29,
      "z": 2,
      "name": "Rock_Shale_Cobble",
      "rotation": 4
    },
    {
      "x": -11,
      "y": 30,
      "z": 2,
      "name": "Rock_Shale_Cobble",
      "rotation": 4
    },
    {
      "x": -11,
      "y": 31,
      "z": 2,
      "name": "Rock_Shale_Cobble",
      "rotation": 4
    },
    {
      "x": -11,
      "y": 32,
      "z": 2,
      "name": "Rock_Shale_Cobble",
      "rotation": 4
    },
    {
      "x": -11,
      "y": 33,
      "z": 2,
      "name": "Rock_Shale_Cobble_Half",
      "rotation": 1
    },
    {
      "x": -11,
      "y": 6,
      "z": 3,
      "name": "Rock_Shale_Cobble",
      "rotation": 17
    },
    {
      "x": -11,
      "y": 7,
      "z": 3,
      "name": "Rock_Shale_Cobble",
      "rotation": 17
    },
    {
      "x": -11,
      "y": 8,
      "z": 3,
      "name": "Rock_Shale_Cobble",
      "rotation": 17
    },
    {
      "x": -11,
      "y": 9,
      "z": 3,
      "name": "Rock_Shale_Cobble",
      "rotation": 1
    },
    {
      "x": -11,
      "y": 10,
      "z": 3,
      "name": "Rock_Shale_Cobble",
      "rotation": 1
    },
    {
      "x": -11,
      "y": 28,
      "z": 3,
      "name": "Rock_Shale_Cobble",
      "rotation": 4
    },
    {
      "x": -11,
      "y": 29,
      "z": 3,
      "name": "Rock_Shale_Cobble",
      "rotation": 4
    },
    {
      "x": -11,
      "y": 30,
      "z": 3,
      "name": "Rock_Shale_Cobble",
      "rotation": 4
    },
    {
      "x": -11,
      "y": 31,
      "z": 3,
      "name": "Rock_Shale_Cobble",
      "rotation": 4
    },
    {
      "x": -11,
      "y": 32,
      "z": 3,
      "name": "Rock_Shale_Cobble",
      "rotation": 4
    },
    {
      "x": -11,
      "y": 11,
      "z": 4,
      "name": "Metal_Iron_Glowing_Pipe_Corner",
      "support": 15,
      "rotation": 3
    },
    {
      "x": -11,
      "y": 12,
      "z": 4,
      "name": "Metal_Iron_Glowing_Pipe_Corner",
      "support": 15,
      "rotation": 11
    },
    {
      "x": -10,
      "y": 30,
      "z": -3,
      "name": "Metal_Iron_Glowing_Pipe_Corner",
      "support": 15,
      "rotation": 24
    },
    {
      "x": -10,
      "y": 5,
      "z": -2,
      "name": "Rock_Shale_Cobble",
      "rotation": 17
    },
    {
      "x": -10,
      "y": 6,
      "z": -2,
      "name": "Rock_Shale_Cobble",
      "rotation": 17
    },
    {
      "x": -10,
      "y": 7,
      "z": -2,
      "name": "Rock_Shale_Cobble",
      "rotation": 17
    },
    {
      "x": -10,
      "y": 8,
      "z": -2,
      "name": "Rock_Shale_Cobble",
      "rotation": 17
    },
    {
      "x": -10,
      "y": 9,
      "z": -2,
      "name": "Rock_Shale_Cobble",
      "rotation": 17
    },
    {
      "x": -10,
      "y": 29,
      "z": -2,
      "name": "Rock_Shale_Cobble",
      "rotation": 4
    },
    {
      "x": -10,
      "y": 30,
      "z": -2,
      "name": "Rock_Shale_Cobble",
      "rotation": 4
    },
    {
      "x": -10,
      "y": 31,
      "z": -2,
      "name": "Rock_Shale_Cobble",
      "rotation": 4
    },
    {
      "x": -10,
      "y": 32,
      "z": -2,
      "name": "Rock_Shale_Cobble",
      "rotation": 4
    },
    {
      "x": -10,
      "y": 33,
      "z": -2,
      "name": "Rock_Shale_Cobble",
      "rotation": 4
    },
    {
      "x": -10,
      "y": 4,
      "z": -1,
      "name": "Rock_Shale_Cobble_Half",
      "rotation": 35
    },
    {
      "x": -10,
      "y": 5,
      "z": -1,
      "name": "Rock_Shale_Cobble",
      "rotation": 17
    },
    {
      "x": -10,
      "y": 6,
      "z": -1,
      "name": "Rock_Shale_Cobble",
      "rotation": 17
    },
    {
      "x": -10,
      "y": 7,
      "z": -1,
      "name": "Rock_Shale_Cobble",
      "rotation": 17
    },
    {
      "x": -10,
      "y": 8,
      "z": -1,
      "name": "Rock_Shale_Cobble",
      "rotation": 17
    },
    {
      "x": -10,
      "y": 9,
      "z": -1,
      "name": "Rock_Shale_Cobble",
      "rotation": 17
    },
    {
      "x": -10,
      "y": 10,
      "z": -1,
      "name": "Rock_Shale_Brick_Smooth",
      "rotation": 1
    },
    {
      "x": -10,
      "y": 28,
      "z": -1,
      "name": "Rock_Shale_Brick_Smooth",
      "rotation": 1
    },
    {
      "x": -10,
      "y": 29,
      "z": -1,
      "name": "Rock_Shale_Cobble",
      "rotation": 4
    },
    {
      "x": -10,
      "y": 30,
      "z": -1,
      "name": "Rock_Shale_Cobble",
      "rotation": 4
    },
    {
      "x": -10,
      "y": 31,
      "z": -1,
      "name": "Rock_Shale_Cobble",
      "rotation": 4
    },
    {
      "x": -10,
      "y": 32,
      "z": -1,
      "name": "Rock_Shale_Cobble",
      "rotation": 4
    },
    {
      "x": -10,
      "y": 33,
      "z": -1,
      "name": "Rock_Shale_Cobble",
      "rotation": 4
    },
    {
      "x": -10,
      "y": 34,
      "z": -1,
      "name": "Rock_Shale_Cobble_Half",
      "rotation": 1
    },
    {
      "x": -10,
      "y": 5,
      "z": 0,
      "name": "Rock_Shale_Cobble",
      "rotation": 17
    },
    {
      "x": -10,
      "y": 6,
      "z": 0,
      "name": "Rock_Shale_Cobble",
      "rotation": 17
    },
    {
      "x": -10,
      "y": 7,
      "z": 0,
      "name": "Rock_Shale_Cobble",
      "rotation": 17
    },
    {
      "x": -10,
      "y": 8,
      "z": 0,
      "name": "Build_Lightsource_Cyan",
      "rotation": 5
    },
    {
      "x": -10,
      "y": 9,
      "z": 0,
      "name": "Build_Lightsource_Cyan",
      "rotation": 5
    },
    {
      "x": -10,
      "y": 11,
      "z": 0,
      "name": "Metal_Iron_Glowing_Pipe_Corner",
      "support": 15,
      "rotation": 18
    },
    {
      "x": -10,
      "y": 29,
      "z": 0,
      "name": "Build_Lightsource_Cyan",
      "rotation": 35
    },
    {
      "x": -10,
      "y": 30,
      "z": 0,
      "name": "Rock_Shale_Cobble",
      "rotation": 4
    },
    {
      "x": -10,
      "y": 31,
      "z": 0,
      "name": "Rock_Shale_Cobble",
      "rotation": 4
    },
    {
      "x": -10,
      "y": 32,
      "z": 0,
      "name": "Rock_Shale_Cobble",
      "rotation": 4
    },
    {
      "x": -10,
      "y": 33,
      "z": 0,
      "name": "Rock_Shale_Cobble",
      "rotation": 4
    },
    {
      "x": -10,
      "y": 5,
      "z": 1,
      "name": "Rock_Shale_Cobble",
      "rotation": 17
    },
    {
      "x": -10,
      "y": 6,
      "z": 1,
      "name": "Rock_Shale_Cobble",
      "rotation": 17
    },
    {
      "x": -10,
      "y": 7,
      "z": 1,
      "name": "Rock_Shale_Cobble",
      "rotation": 17
    },
    {
      "x": -10,
      "y": 8,
      "z": 1,
      "name": "Rock_Shale_Cobble",
      "rotation": 17
    },
    {
      "x": -10,
      "y": 9,
      "z": 1,
      "name": "Build_Lightsource_Cyan",
      "rotation": 5
    },
    {
      "x": -10,
      "y": 11,
      "z": 1,
      "name": "Metal_Iron_Glowing_Pipe",
