{
  "version": 8,
  "blockIdVersion": 11,
  "anchorX": 0,
  "anchorY": 0,
  "anchorZ": 0,
  "blocks": [
    {
      "x": -10,
      "y": 0,
      "z": -2,
      "name": "Wood_Sallow_Trunk_Full",
      "support": 15
    },
    {
      "x": -10,
      "y": 1,
      "z": -2,
      "name": "Plant_Moss_Rug_Green_Dark",
      "support": 15
    },
    {
      "x": -9,
      "y": 1,
      "z": -2,
      "name": "Plant_Moss_Wall_Green_Dark",
      "support": 15,
      "rotation": 2
    },
    {
      "x": -9,
      "y": 0,
      "z": -1,
      "name": "Wood_Sallow_Trunk",
      "support": 15
    },
    {
      "x": -9,
      "y": 1,
      "z": -1,
      "name": "Wood_Sallow_Trunk_Full",
      "support": 15
    },
    {
      "x": -9,
      "y": 2,
      "z": -1,
      "name": "Plant_Moss_Rug_Green_Dark",
      "support": 15
    },
    {
      "x": -9,
      "y": 2,
      "z": 0,
      "name": "Plant_Moss_Wall_Green_Dark",
      "support": 15,
      "rotation": 3
    },
    {
      "x": -9,
      "y": 42,
      "z": 2,
      "name": "Plant_Leaves_Beech"
    },
    {
      "x": -8,
      "y": 41,
      "z": -5,
      "name": "Plant_Leaves_Beech"
    },
    {
      "x": -8,
      "y": 42,
      "z": -5,
      "name": "Plant_Leaves_Beech"
    },
    {
      "x": -8,
      "y": 40,
      "z": -2,
      "name": "Plant_Leaves_Beech"
    },
    {
      "x": -8,
      "y": 41,
      "z": -2,
      "name": "Plant_Leaves_Beech"
    },
    {
      "x": -8,
      "y": 42,
      "z": -2,
      "name": "Plant_Leaves_Beech"
    },
    {
      "x": -8,
      "y": 0,
      "z": -1,
      "name": "Wood_Sallow_Trunk",
      "support": 15
    },
    {
      "x": -8,
      "y": 1,
      "z": -1,
      "name": "Wood_Sallow_Trunk",
      "support": 15
    },
    {
      "x": -8,
      "y": 2,
      "z": -1,
      "name": "Wood_Sallow_Trunk_Full",
      "support": 15
    },
    {
      "x": -8,
      "y": 3,
      "z": -1,
      "name": "Plant_Moss_Rug_Green_Dark",
      "support": 15
    },
    {
      "x": -8,
      "y": 0,
      "z": 0,
      "name": "Wood_Sallow_Trunk",
      "support": 15
    },
    {
      "x": -8,
      "y": 1,
      "z": 0,
      "name": "Wood_Sallow_Trunk",
      "support": 15
    },
    {
      "x": -8,
      "y": 2,
      "z": 0,
      "name": "Wood_Sallow_Trunk_Full",
      "support": 15
    },
    {
      "x": -8,
      "y": 3,
      "z": 0,
      "name": "Plant_Moss_Rug_Green_Dark",
      "support": 15
    },
    {
      "x": -8,
      "y": 42,
      "z": 1,
      "name": "Plant_Leaves_Beech"
    },
    {
      "x": -8,
      "y": 41,
      "z": 2,
      "name": "Plant_Leaves_Beech"
    },
    {
      "x": -8,
      "y": 42,
      "z": 2,
      "name": "Wood_Sallow_Branch_Corner",
      "rotation": 3
    },
    {
      "x": -8,
      "y": 43,
      "z": 2,
      "name": "Plant_Leaves_Beech"
    },
    {
      "x": -8,
      "y": 42,
      "z": 3,
      "name": "Plant_Leaves_Beech"
    },
    {
      "x": -8,
      "y": 45,
      "z": 3,
      "name": "Plant_Leaves_Beech"
    },
    {
      "x": -8,
      "y": 46,
      "z": 3,
      "name": "Plant_Leaves_Beech"
    },
    {
      "x": -8,
      "y": 0,
      "z": 5,
      "name": "Wood_Sallow_Trunk_Full",
      "support": 15
    },
    {
      "x": -7,
      "y": 41,
      "z": -6,
      "name": "Plant_Leaves_Beech"
    },
    {
      "x": -7,
      "y": 42,
      "z": -6,
      "name": "Plant_Leaves_Beech"
    },
    {
      "x": -7,
      "y": 40,
      "z": -5,
      "name": "Plant_Leaves_Beech"
    },
    {
      "x": -7,
      "y": 41,
      "z": -5,
      "name": "Wood_Sallow_Branch_Corner",
      "rotation": 3
    },
    {
      "x": -7,
      "y": 42,
      "z": -5,
      "name": "Wood_Sallow_Branch_Long"
    },
    {
      "x": -7,
      "y": 43,
      "z": -5,
      "name": "Plant_Leaves_Beech"
    },
    {
      "x": -7,
      "y": 46,
      "z": -5,
      "name": "Plant_Leaves_Beech"
    },
    {
      "x": -7,
      "y": 47,
      "z": -5,
      "name": "Plant_Leaves_Beech"
    },
    {
      "x": -7,
      "y": 41,
      "z": -4,
      "name": "Plant_Leaves_Beech"
    },
    {
      "x": -7,
      "y": 42,
      "z": -4,
      "name": "Plant_Leaves_Beech"
    },
    {
      "x": -7,
      "y": 0,
      "z": -3,
      "name": "Wood_Sallow_Trunk_Full",
      "support": 15
    },
    {
      "x": -7,
      "y": 40,
      "z": -3,
      "name": "Plant_Leaves_Beech"
    },
    {
      "x": -7,
      "y": 41,
      "z": -3,
      "name": "Plant_Leaves_Beech"
    },
    {
      "x": -7,
      "y": 39,
      "z": -2,
      "name": "Plant_Leaves_Beech"
    },
    {
      "x": -7,
      "y": 40,
      "z": -2,
      "name": "Wood_Sallow_Branch_Corner",
      "rotation": 3
    },
    {
      "x": -7,
      "y": 41,
      "z": -2,
      "name": "Wood_Sallow_Branch_Long"
    },
    {
      "x": -7,
      "y": 42,
      "z": -2,
      "name": "Wood_Sallow_Branch_Long"
    },
    {
      "x": -7,
      "y": 43,
      "z": -2,
      "name": "Plant_Leaves_Beech"
    },
    {
      "x": -7,
      "y": 40,
      "z": -1,
      "name": "Plant_Leaves_Beech"
    },
    {
      "x": -7,
      "y": 41,
      "z": -1,
      "name": "Plant_Leaves_Beech"
    },
    {
      "x": -7,
      "y": 42,
      "z": -1,
      "name": "Plant_Leaves_Beech"
    },
    {
      "x": -7,
      "y": 0,
      "z": 0,
      "name": "Wood_Sallow_Trunk",
      "support": 15
    },
    {
      "x": -7,
      "y": 1,
      "z": 0,
      "name": "Wood_Sallow_Trunk",
      "support": 15
    },
    {
      "x": -7,
      "y": 2,
      "z": 0,
      "name": "Wood_Sallow_Trunk",
      "support": 15
    },
    {
      "x": -7,
      "y": 3,
      "z": 0,
      "name": "Wood_Sallow_Trunk_Full",
      "support": 15
    },
    {
      "x": -7,
      "y": 0,
      "z": 1,
      "name": "Wood_Sallow_Trunk_Full",
      "support": 15
    },
    {
      "x": -7,
      "y": 1,
      "z": 1,
      "name": "Plant_Moss_Rug_Green_Dark",
      "support": 15
    },
    {
      "x": -7,
      "y": 37,
      "z": 2,
      "name": "Plant_Leaves_Beech"
    },
    {
      "x": -7,
      "y": 38,
      "z": 2,
      "name": "Plant_Leaves_Beech"
    },
    {
      "x": -7,
      "y": 42,
      "z": 2,
      "name": "Wood_Sallow_Branch_Long",
      "rotation": 5
    },
    {
      "x": -7,
      "y": 45,
      "z": 2,
      "name": "Plant_Leaves_Beech"
    },
    {
      "x": -7,
      "y": 46,
      "z": 2,
      "name": "Plant_Leaves_Beech"
    },
    {
      "x": -7,
      "y": 42,
      "z": 3,
      "name": "Plant_Leaves_Beech"
    },
    {
      "x": -7,
      "y": 44,
      "z": 3,
      "name": "Plant_Leaves_Beech"
    },
    {
      "x": -7,
      "y": 45,
      "z": 3,
      "name": "Wood_Sallow_Branch_Corner",
      "rotation": 3
    },
    {
      "x": -7,
      "y": 46,
      "z": 3,
      "name": "Wood_Sallow_Branch_Long"
    },
    {
      "x": -7,
      "y": 47,
      "z": 3,
      "name": "Plant_Leaves_Beech"
    },
    {
      "x": -7,
      "y": 1,
      "z": 4,
      "name": "Plant_Moss_Wall_Green_Dark",
      "support": 15,
      "rotation": 3
    },
    {
      "x": -7,
      "y": 42,
      "z": 4,
      "name": "Plant_Leaves_Beech"
    },
    {
      "x": -7,
      "y": 45,
      "z": 4,
      "name": "Plant_Leaves_Beech"
    },
    {
      "x": -7,
      "y": 46,
      "z": 4,
      "name": "Plant_Leaves_Beech"
    },
    {
      "x": -7,
      "y": 0,
      "z": 5,
      "name": "Wood_Sallow_Trunk",
      "support": 15
    },
    {
      "x": -7,
      "y": 1,
      "z": 5,
      "name": "Wood_Sallow_Trunk_Full",
      "support": 15
    },
    {
      "x": -7,
      "y": 42,
      "z": 5,
      "name": "Plant_Leaves_Beech"
    },
    {
      "x": -6,
      "y": 41,
      "z": -6,
      "name": "Plant_Leaves_Beech"
    },
    {
      "x": -6,
      "y": 46,
      "z": -6,
      "name": "Plant_Leaves_Beech"
    },
    {
      "x": -6,
      "y": 47,
      "z": -6,
      "name": "Plant_Leaves_Beech"
    },
    {
      "x": -6,
      "y": 41,
      "z": -5,
      "name": "Wood_Sallow_Branch_Long",
      "rotation": 5
    },
    {
      "x": -6,
      "y": 42,
      "z": -5,
      "name": "Plant_Leaves_Beech"
    },
    {
      "x": -6,
      "y": 45,
      "z": -5,
      "name": "Plant_Leaves_Beech"
    },
    {
      "x": -6,
      "y": 46,
      "z": -5,
      "name": "Wood_Sallow_Branch_Corner",
      "rotation": 3
    },
    {
      "x": -6,
      "y": 47,
      "z": -5,
      "name": "Wood_Sallow_Branch_Long"
    },
    {
      "x": -6,
      "y": 48,
      "z": -5,
      "name": "Plant_Leaves_Beech"
    },
    {
      "x": -6,
      "y": 41,
      "z": -4,
      "name": "Plant_Leaves_Beech"
    },
    {
      "x": -6,
      "y": 46,
      "z": -4,
      "name": "Plant_Leaves_Beech"
    },
    {
      "x": -6,
      "y": 47,
      "z": -4,
      "name": "Plant_Leaves_Beech"
    },
    {
      "x": -6,
      "y": 0,
      "z": -2,
      "name": "Wood_Sallow_Trunk",
      "support": 15
    },
    {
      "x": -6,
      "y": 1,
      "z": -2,
      "name": "Wood_Sallow_Trunk_Full",
      "support": 15
    },
    {
      "x": -6,
      "y": 39,
      "z": -2,
      "name": "Plant_Leaves_Beech"
    },
    {
      "x": -6,
      "y": 40,
      "z": -2,
      "name": "Wood_Sallow_Branch_Long",
      "rotation": 5
    },
    {
      "x": -6,
      "y": 41,
      "z": -2,
      "name": "Plant_Leaves_Beech"
    },
    {
      "x": -6,
      "y": 42,
      "z": -2,
      "name": "Plant_Leaves_Beech"
    },
    {
      "x": -6,
      "y": 0,
      "z": -1,
      "name": "Wood_Sallow_Trunk",
      "support": 15
    },
    {
      "x": -6,
      "y": 1,
      "z": -1,
      "name": "Wood_Sallow_Trunk",
      "support": 15
    },
    {
      "x": -6,
      "y": 2,
      "z": -1,
      "name": "Wood_Sallow_Trunk_Full",
      "support": 15
    },
    {
      "x": -6,
      "y": 40,
      "z": -1,
      "name": "Plant_Leaves_Beech"
    },
    {
      "x": -6,
      "y": 0,
      "z": 0,
      "name": "Wood_Sallow_Trunk",
      "support": 15
    },
    {
      "x": -6,
      "y": 1,
      "z": 0,
      "name": "Wood_Sallow_Trunk",
      "support": 15
    },
    {
      "x": -6,
      "y": 2,
      "z": 0,
      "name": "Wood_Sallow_Trunk",
      "support": 15
    },
    {
      "x": -6,
      "y": 3,
      "z": 0,
      "name": "Wood_Sallow_Trunk",
      "support": 15
    },
    {
      "x": -6,
      "y": 4,
      "z": 0,
      "name": "Wood_Sallow_Trunk_Full",
      "support": 15
    },
    {
      "x": -6,
      "y": 5,
      "z": 0,
      "name": "Plant_Moss_Rug_Green_Dark",
      "support": 15
    },
    {
      "x": -6,
      "y": 46,
      "z": 0,
      "name": "Plant_Leaves_Beech"
    },
    {
      "x": -6,
      "y": 47,
      "z": 0,
      "name": "Plant_Leaves_Beech"
    },
    {
      "x": -6,
      "y": 0,
      "z": 1,
      "name": "Wood_Sallow_Trunk",
      "support": 15
    },
    {
      "x": -6,
      "y": 1,
      "z": 1,
      "name": "Wood_Sallow_Trunk",
      "support": 15
    },
    {
      "x": -6,
      "y": 2,
      "z": 1,
      "name": "Wood_Sallow_Trunk_Full",
      "support": 15
    },
    {
      "x": -6,
      "y": 4,
      "z": 1,
      "name": "Plant_Moss_Wall_Green_Dark",
      "support": 15
    },
    {
      "x": -6,
      "y": 37,
      "z": 1,
      "name": "Plant_Leaves_Beech"
    },
    {
      "x": -6,
      "y": 38,
      "z": 1,
      "name": "Plant_Leaves_Beech"
    },
    {
      "x": -6,
      "y": 40,
      "z": 1,
      "name": "Wood_Sallow_Trunk_Full",
      "rotation": 4
    },
    {
      "x": -6,
      "y": 36,
      "z": 2,
      "name": "Plant_Leaves_Beech"
    },
    {
      "x": -6,
      "y": 37,
      "z": 2,
      "name": "Wood_Sallow_Branch_Corner",
      "rotation": 3
    },
    {
      "x": -6,
      "y": 38,
      "z": 2,
      "name": "Wood_Sallow_Branch_Long"
    },
    {
      "x": -6,
      "y": 39,
      "z": 2,
      "name": "Plant_Leaves_Beech"
    },
    {
      "x": -6,
      "y": 40,
      "z": 2,
      "name": "Wood_Sallow_Trunk_Full",
      "rotation": 4
    },
    {
      "x": -6,
      "y": 41,
      "z": 2,
      "name": "Wood_Sallow_Trunk"
    },
    {
      "x": -6,
      "y": 42,
      "z": 2,
      "name": "Wood_Sallow_Trunk_Full",
      "support": 3
    },
    {
      "x": -6,
      "y": 45,
      "z": 2,
      "name": "Plant_Leaves_Beech"
    },
    {
      "x": -6,
      "y": 3,
      "z": 3,
      "name": "Plant_Moss_Wall_Green_Dark",
      "support": 15,
      "rotation": 3
    },
    {
      "x": -6,
      "y": 37,
      "z": 3,
      "name": "Plant_Leaves_Beech"
    },
    {
      "x": -6,
      "y": 38,
      "z": 3,
      "name": "Plant_Leaves_Beech"
    },
    {
      "x": -6,
      "y": 42,
      "z": 3,
      "name": "Wood_Sallow_Branch_Long",
      "rotation": 4
    },
    {
      "x": -6,
      "y": 44,
      "z": 3,
      "name": "Plant_Leaves_Beech"
    },
    {
      "x": -6,
      "y": 45,
      "z": 3,
      "name": "Wood_Sallow_Branch_Long",
      "rotation": 5
    },
    {
      "x": -6,
      "y": 46,
      "z": 3,
      "name": "Plant_Leaves_Beech"
    },
    {
      "x": -6,
      "y": 0,
      "z": 4,
      "name": "Wood_Sallow_Trunk",
      "support": 15
    },
    {
      "x": -6,
      "y": 1,
      "z": 4,
      "name": "Wood_Sallow_Trunk_Full",
      "support": 15
    },
    {
      "x": -6,
      "y": 2,
      "z": 4,
      "name": "Plant_Moss_Rug_Green_Dark",
      "support": 15
    },
    {
      "x": -6,
      "y": 41,
      "z": 4,
      "name": "Plant_Leaves_Beech"
    },
    {
      "x": -6,
      "y": 42,
      "z": 4,
      "name": "Wood_Sallow_Branch_Long",
      "rotation": 4
    },
    {
      "x": -6,
      "y": 43,
      "z": 4,
      "name": "Plant_Leaves_Beech"
    },
    {
      "x": -6,
      "y": 45,
      "z": 4,
      "name": "Plant_Leaves_Beech"
    },
    {
      "x": -6,
      "y": 41,
      "z": 5,
      "name": "Plant_Leaves_Beech"
    },
    {
      "x": -6,
      "y": 42,
      "z": 5,
      "name": "Wood_Sallow_Branch_Corner"
    },
    {
      "x": -6,
      "y": 43,
      "z": 5,
      "name": "Plant_Leaves_Beech"
    },
    {
      "x": -6,
      "y": 42,
      "z": 6,
      "name": "Plant_Leaves_Beech"
    },
    {
      "x": -6,
      "y": 0,
      "z": 8,
      "name": "Wood_Sallow_Trunk",
      "support": 15
    },
    {
      "x": -6,
      "y": 1,
      "z": 8,
      "name": "Wood_Sallow_Trunk_Full",
      "support": 15
    },
    {
      "x": -6,
      "y": 2,
      "z": 8,
      "name": "Plant_Moss_Rug_Green_Dark",
      "support": 15
    },
    {
      "x": -6,
      "y": 0,
      "z": 9,
      "name": "Wood_Sallow_Trunk_Full",
      "support": 15
    },
    {
      "x": -6,
      "y": 1,
      "z": 9,
      "name": "Plant_Moss_Rug_Green_Dark",
      "support": 15
    },
    {
      "x": -5,
      "y": 41,
      "z": -8,
      "name": "Plant_Leaves_Beech"
    },
    {
      "x": -5,
      "y": 42,
      "z": -8,
      "name": "Plant_Leaves_Beech"
    },
    {
      "x": -5,
      "y": 41,
      "z": -7,
      "name": "Plant_Leaves_Beech"
    },
    {
      "x": -5,
      "y": 46,
      "z": -6,
      "name": "Plant_Leaves_Beech"
    },
    {
      "x": -5,
      "y": 41,
      "z": -5,
      "name": "Wood_Sallow_Branch_Long",
      "rotation": 5
    },
    {
      "x": -5,
      "y": 46,
      "z": -5,
      "name": "Wood_Sallow_Branch_Long",
      "rotation": 5
    },
    {
      "x": -5,
      "y": 47,
      "z": -5,
      "name": "Plant_Leaves_Beech"
    },
    {
      "x": -5,
      "y": 43,
      "z": -4,
      "name": "Plant_Leaves_Beech"
    },
    {
      "x": -5,
      "y": 46,
      "z": -4,
      "name": "Plant_Leaves_Beech"
    },
    {
      "x": -5,
      "y": 40,
      "z": -2,
      "name": "Wood_Sallow_Branch_Long",
      "rotation": 5
    },
    {
      "x": -5,
      "y": 0,
      "z": -1,
      "name": "Wood_Sallow_Trunk",
      "support": 15
    },
    {
      "x": -5,
      "y": 1,
      "z": -1,
      "name": "Wood_Sallow_Trunk",
      "support": 15
    },
    {
      "x": -5,
      "y": 2,
      "z": -1,
      "name": "Wood_Sallow_Trunk",
      "support": 15
    },
    {
      "x": -5,
      "y": 3,
      "z": -1,
      "name": "Wood_Sallow_Trunk_Full",
      "support": 15
    },
    {
      "x": -5,
      "y": 47,
      "z": -1,
      "name": "Plant_Leaves_Beech"
    },
    {
      "x": -5,
      "y": 0,
      "z": 0,
      "name": "Wood_Sallow_Trunk",
      "support": 15
    },
    {
      "x": -5,
      "y": 1,
      "z": 0,
      "name": "Wood_Sallow_Trunk",
      "support": 15
    },
    {
      "x": -5,
      "y": 2,
      "z": 0,
      "name": "Wood_Sallow_Trunk",
      "support": 15
    },
    {
      "x": -5,
      "y": 3,
      "z": 0,
      "name": "Wood_Sallow_Trunk",
      "support": 15
    },
    {
      "x": -5,
      "y": 4,
      "z": 0,
      "name": "Wood_Sallow_Trunk_Full",
      "support": 15
    },
    {
      "x": -5,
      "y": 5,
      "z": 0,
      "name": "Plant_Moss_Rug_Green_Dark",
      "support": 15
    },
    {
      "x": -5,
      "y": 45,
      "z": 0,
      "name": "Wood_Sallow_Branch_Corner",
      "rotation": 2
    },
    {
      "x": -5,
      "y": 46,
      "z": 0,
      "name": "Wood_Sallow_Branch_Long"
    },
    {
      "x": -5,
      "y": 47,
      "z": 0,
      "name": "Wood_Sallow_Branch_Long"
    },
    {
      "x": -5,
      "y": 48,
      "z": 0,
      "name": "Plant_Leaves_Beech"
    },
    {
      "x": -5,
      "y": 0,
      "z": 1,
      "name": "Wood_Sallow_Trunk",
      "support": 15
    },
    {
      "x": -5,
      "y": 1,
      "z": 1,
      "name": "Wood_Sallow_Trunk",
      "support": 15
    },
    {
      "x": -5,
      "y": 2,
      "z": 1,
      "name": "Wood_Sallow_Trunk_Full",
      "support": 15
    },
    {
      "x": -5,
      "y": 4,
      "z": 1,
      "name": "Plant_Moss_Wall_Green_Dark",
      "support": 15
    },
    {
      "x": -5,
      "y": 37,
      "z": 1,
      "name": "Plant_Leaves_Beech"
    },
    {
      "x": -5,
      "y": 40,
      "z": 1,
      "name": "Wood_Sallow_Trunk",
      "rotation": 5
    },
    {
      "x": -5,
      "y": 45,
      "z": 1,
      "name": "Wood_Sallow_Branch_Corner",
      "rotation": 19
    },
    {
      "x": -5,
      "y": 47,
      "z": 1,
      "name": "Plant_Leaves_Beech"
    },
    {
      "x": -5,
      "y": 3,
      "z": 2,
      "name": "Plant_Moss_Wall_Green_Dark",
      "support": 15,
      "rotation": 2
    },
    {
      "x": -5,
      "y": 37,
      "z": 2,
      "name": "Wood_Sallow_Branch_Long",
      "rotation": 5
    },
    {
      "x": -5,
      "y": 38,
      "z": 2,
      "name": "Plant_Leaves_Beech"
    },
    {
      "x": -5,
      "y": 0,
      "z": 3,
      "name": "Wood_Sallow_Trunk",
      "support": 15
    },
    {
      "x": -5,
      "y": 1,
      "z": 3,
      "name": "Wood_Sallow_Trunk",
      "support": 15
    },
    {
      "x": -5,
      "y": 2,
      "z": 3,
      "name": "Wood_Sallow_Trunk",
      "support": 15
    },
    {
      "x": -5,
      "y": 3,
      "z": 3,
      "name": "Wood_Sallow_Trunk_Full",
      "support": 15
    },
    {
      "x": -5,
      "y": 4,
      "z": 3,
      "name": "Plant_Moss_Rug_Green_Dark",
      "support": 15
    },
    {
      "x": -5,
      "y": 37,
      "z": 3,
      "name": "Plant_Leaves_Beech"
    },
    {
      "x": -5,
      "y": 45,
      "z": 3,
      "name": "Wood_Sallow_Branch_Long",
      "rotation": 5
    },
    {
      "x": -5,
      "y": 0,
      "z": 4,
      "name": "Wood_Sallow_Trunk",
      "support": 15
    },
    {
      "x": -5,
      "y": 1,
      "z": 4,
      "name": "Wood_Sallow_Trunk",
      "support": 15
    },
    {
      "x": -5,
      "y": 2,
      "z": 4,
      "name": "Wood_Sallow_Trunk_Full",
      "support": 15
    },
    {
      "x": -5,
      "y": 3,
      "z": 4,
      "name": "Plant_Moss_Rug_Green_Dark",
      "support": 15
    },
    {
      "x": -5,
      "y": 42,
      "z": 4,
      "name": "Plant_Leaves_Beech"
    },
    {
      "x": -5,
      "y": 2,
      "z": 5,
      "name": "Plant_Moss_Wall_Green_Dark",
      "support": 15
    },
    {
      "x": -5,
      "y": 38,
      "z": 5,
      "name": "Plant_Leaves_Beech"
    },
    {
      "x": -5,
      "y": 39,
      "z": 5,
      "name": "Plant_Leaves_Beech"
    },
    {
      "x": -5,
      "y": 42,
      "z": 5,
      "name": "Plant_Leaves_Beech"
    },
    {
      "x": -5,
      "y": 45,
      "z": 5,
      "name": "Plant_Leaves_Beech"
    },
    {
      "x": -5,
      "y": 3,
      "z": 6,
      "name": "Plant_Moss_Wall_Green_Dark",
      "support": 15,
      "rotation": 3
    },
    {
      "x": -5,
      "y": 45,
      "z": 6,
      "name": "Plant_Leaves_Beech"
    },
    {
      "x": -5,
      "y": 46,
      "z": 6,
      "name": "Plant_Leaves_Beech"
    },
    {
      "x": -5,
      "y": 0,
      "z": 7,
      "name": "Wood_Sallow_Trunk",
      "support": 15
    },
    {
      "x": -5,
      "y": 1,
      "z": 7,
      "name": "Wood_Sallow_Trunk",
      "support": 15
    },
    {
      "x": -5,
      "y": 2,
      "z": 7,
      "name": "Wood_Sallow_Trunk_Full",
      "support": 15
    },
    {
      "x": -5,
      "y": 0,
      "z": 8,
      "name": "Wood_Sallow_Trunk",
      "support": 15
    },
    {
      "x": -5,
      "y": 1,
      "z": 8,
      "name": "Wood_Sallow_Trunk",
      "support": 15
    },
    {
      "x": -5,
      "y": 2,
      "z": 8,
      "name": "Wood_Sallow_Trunk_Full",
      "support": 15
    },
    {
      "x": -5,
      "y": 3,
      "z": 8,
      "name": "Plant_Moss_Rug_Green_Dark",
      "support": 15
    },
    {
      "x": -5,
      "y": 2,
      "z": 9,
      "name": "Plant_Moss_Wall_Green_Dark",
      "support": 15
    },
    {
      "x": -4,
      "y": 42,
      "z": -9,
      "name": "Plant_Leaves_Beech"
    },
    {
      "x": -4,
      "y": 41,
      "z": -8,
      "name": "Wood_Sallow_Branch_Corner",
      "support": 2,
      "rotation": 2
    },
    {
      "x": -4,
      "y": 42,
      "z": -8,
      "name": "Wood_Sallow_Branch_Long",
      "support": 3
    },
    {
      "x": -4,
      "y": 43,
      "z": -8,
      "name": "Plant_Leaves_Beech"
    },
    {
      "x": -4,
      "y": 40,
      "z": -7,
      "name": "Plant_Leaves_Beech"
    },
    {
      "x": -4,
      "y": 41,
      "z": -7,
      "name": "Wood_Sallow_Branch_Long",
      "support": 1,
      "rotation": 4
    },
    {
      "x": -4,
      "y": 42,
      "z": -7,
      "name": "Plant_Leaves_Beech"
    },
    {
      "x": -4,
      "y": 41,
      "z": -6,
      "name": "Wood_Sallow_Branch_Long",
      "rotation": 4
    },
    {
      "x": -4,
      "y": 35,
      "z": -5,
      "name": "Plant_Leaves_Beech"
    },
    {
      "x": -4,
      "y": 41,
      "z": -5,
      "name": "Wood_Sallow_Trunk_Full",
      "rotation": 4
    },
    {
      "x": -4,
      "y": 43,
      "z": -5,
      "name": "Plant_Leaves_Beech"
    },
    {
      "x": -4,
      "y": 46,
      "z": -5,
      "name": "Wood_Sallow_Branch_Long",
      "rotation": 5
    },
    {
      "x": -4,
      "y": 35,
      "z": -4,
      "name": "Plant_Leaves_Beech"
    },
    {
      "x": -4,
      "y": 40,
      "z": -4,
      "name": "Wood_Sallow_Trunk_Full",
      "support": 15,
      "rotation": 5
    },
    {
      "x": -4,
      "y": 41,
      "z": -4,
      "name": "Wood_Sallow_Trunk_Full",
      "rotation": 4
    },
    {
      "x": -4,
      "y": 42,
      "z": -4,
      "name": "Wood_Sallow_Branch_Long"
    },
    {
      "x": -4,
      "y": 43,
      "z": -4,
      "name": "Wood_Sallow_Branch_Long"
    },
    {
      "x": -4,
      "y": 44,
      "z": -4,
      "name": "Plant_Leaves_Beech"
    },
    {
      "x": -4,
      "y": 43,
      "z": -3,
      "name": "Plant_Leaves_Beech"
    },
    {
      "x": -4,
      "y": 48,
      "z": -3,
      "name": "Plant_Leaves_Beech"
    },
    {
      "x": -4,
      "y": 1,
      "z": -2,
      "name": "Plant_Moss_Wall_Green_Dark",
      "support": 15,
      "rotation": 3
    },
    {
      "x": -4,
      "y": 40,
      "z": -2,
      "name": "Wood_Sallow_Branch_Long",
      "rotation": 5
    },
    {
      "x": -4,
      "y": 0,
      "z": 0,
      "name": "Wood_Sallow_Trunk",
      "support": 15
    },
    {
      "x": -4,
      "y": 1,
      "z": 0,
      "name": "Wood_Sallow_Trunk",
      "support": 15
    },
    {
      "x": -4,
      "y": 2,
      "z": 0,
      "name": "Wood_Sallow_Trunk",
      "support": 15
    },
    {
      "x": -4,
      "y": 3,
      "z": 0,
      "name": "Wood_Sallow_Trunk",
      "support": 15
    },
    {
      "x": -4,
      "y": 4,
      "z": 0,
      "name": "Wood_Sallow_Trunk",
      "support": 15
    },
    {
      "x": -4,
      "y": 5,
      "z": 0,
      "name": "Wood_Sallow_Trunk_Full",
      "support": 15
    },
    {
      "x": -4,
      "y": 16,
      "z": 0,
      "name": "Plant_Vine_Liana_End",
      "support": 15,
      "rotation": 3
    },
    {
      "x": -4,
      "y": 17,
      "z": 0,
      "name": "Plant_Vine_Liana",
      "support": 15,
      "rotation": 3
    },
    {
      "x": -4,
      "y": 18,
      "z": 0,
      "name": "Plant_Vine_Liana",
      "support": 15,
      "rotation": 3
    },
    {
      "x": -4,
      "y": 19,
      "z": 0,
      "name": "Plant_Vine_Liana",
      "support": 15,
      "rotation": 3
    },
    {
      "x": -4,
      "y": 20,
      "z": 0,
      "name": "Plant_Vine_Liana",
      "support": 15,
      "rotation": 3
    },
    {
      "x": -4,
      "y": 21,
      "z": 0,
      "name": "Plant_Vine_Liana",
      "support": 15,
      "rotation": 3
    },
    {
      "x": -4,
      "y": 22,
      "z": 0,
      "name": "Plant_Vine_Liana",
      "support": 15,
      "rotation": 3
    },
    {
      "x": -4,
      "y": 23,
      "z": 0,
      "name": "Plant_Vine_Liana",
      "support": 15,
      "rotation": 3
    },
    {
      "x": -4,
      "y": 24,
      "z": 0,
      "name": "Plant_Vine_Liana",
      "support": 15,
      "rotation": 3
    },
    {
      "x": -4,
      "y": 25,
      "z": 0,
      "name": "Plant_Vine_Liana_End",
      "rotation": 3
    },
    {
      "x": -4,
      "y": 26,
      "z": 0,
      "name": "Plant_Vine_Liana",
      "rotation": 3
    },
    {
      "x": -4,
      "y": 27,
      "z": 0,
      "name": "Plant_Vine_Liana",
      "rotation": 3
    },
    {
      "x": -4,
      "y": 28,
      "z": 0,
      "name": "Plant_Vine_Liana",
      "rotation": 3
    },
    {
      "x": -4,
      "y": 29,
      "z": 0,
      "name": "Plant_Vine_Liana",
      "rotation": 3
    },
    {
      "x": -4,
      "y": 30,
      "z": 0,
      "name": "Plant_Vine_Liana",
      "rotation": 3
    },
    {
      "x": -4,
      "y": 31,
      "z": 0,
      "name": "Plant_Vine_Liana",
      "support": 15,
      "rotation": 3
    },
    {
      "x": -4,
      "y": 32,
      "z": 0,
      "name": "Plant_Vine_Liana",
      "support": 15,
      "rotation": 3
    },
    {
      "x": -4,
      "y": 33,
      "z": 0,
      "name": "Plant_Vine_Liana",
      "support": 15,
      "rotation": 3
    },
    {
      "x": -4,
      "y": 34,
      "z": 0,
      "name": "Plant_Vine_Liana",
      "support": 15,
      "rotation": 3
    },
    {
      "x": -4,
      "y": 35,
      "z": 0,
      "name": "Plant_Vine_Liana",
      "support": 15,
      "rotation": 3
    },
    {
      "x": -4,
      "y": 36,
      "z": 0,
      "name": "Plant_Vine_Liana",
      "support": 15,
      "rotation": 3
    },
    {
      "x": -4,
      "y": 37,
      "z": 0,
      "name": "Plant_Vine_Liana",
      "support": 15,
      "rotation": 3
    },
    {
      "x": -4,
      "y": 38,
      "z": 0,
      "name": "Plant_Vine_Liana",
      "support": 15,
      "rotation": 3
    },
    {
      "x": -4,
      "y": 39,
      "z": 0,
      "name": "Plant_Vine_Liana",
      "support": 15,
      "rotation": 3
    },
    {
      "x": -4,
      "y": 47,
      "z": 0,
      "name": "Plant_Leaves_Beech"
    },
    {
      "x": -4,
      "y": 0,
      "z": 1,
      "name": "Wood_Sallow_Trunk",
      "support": 15
    },
    {
      "x": -4,
      "y": 1,
      "z": 1,
      "name": "Wood_Sallow_Trunk",
      "support": 15
    },
    {
      "x": -4,
      "y": 2,
      "z": 1,
      "name": "Wood_Sallow_Trunk",
      "support": 15
    },
    {
      "x": -4,
      "y": 3,
      "z": 1,
      "name": "Wood_Sallow_Trunk",
      "support": 15
    },
    {
      "x": -4,
      "y": 4,
      "z": 1,
      "name": "Wood_Sallow_Trunk_Full",
      "support": 15
    },
    {
      "x": -4,
      "y": 39,
      "z": 1,
      "name": "Wood_Sallow_Trunk_Full",
      "rotation": 5
    },
    {
      "x": -4,
      "y": 40,
      "z": 1,
      "name": "Wood_Sallow_Trunk_Full"
    },
    {
      "x": -4,
      "y": 45,
      "z": 1,
      "name": "Wood_Sallow_Branch_Corner",
      "rotation": 24
    },
    {
      "x": -4,
      "y": 37,
      "z": 2,
      "name": "Wood_Sallow_Branch_Long",
      "rotation": 5
    },
    {
      "x": -4,
      "y": 45,
      "z": 2,
      "name": "Wood_Sallow_Branch_Long",
      "rotation": 4
    },
    {
      "x": -4,
      "y": 0,
      "z": 3,
      "name": "Wood_Sallow_Trunk",
      "support": 15
    },
    {
      "x": -4,
      "y": 1,
      "z": 3,
      "name": "Wood_Sallow_Trunk",
      "support": 15
    },
    {
      "x": -4,
      "y": 2,
      "z": 3,
      "name": "Wood_Sallow_Trunk",
      "support": 15
    },
    {
      "x": -4,
      "y": 3,
      "z": 3,
      "name": "Wood_Sallow_Trunk_Full",
      "support": 15
    },
    {
      "x": -4,
      "y": 44,
      "z": 3,
      "name": "Wood_Sallow_Trunk_Full",
      "support": 3,
      "rotation": 5
    },
    {
      "x": -4,
      "y": 45,
      "z": 3,
      "name": "Wood_Sallow_Trunk_Full"
    },
    {
      "x": -4,
      "y": 38,
      "z": 4,
      "name": "Plant_Leaves_Beech"
    },
    {
      "x": -4,
      "y": 39,
      "z": 4,
      "name": "Plant_Leaves_Beech"
    },
    {
      "x": -4,
      "y": 45,
      "z": 4,
      "name": "Wood_Sallow_Branch_Long",
      "rotation": 4
    },
    {
      "x": -4,
      "y": 37,
      "z": 5,
      "name": "Plant_Leaves_Beech"
    },
    {
      "x": -4,
      "y": 38,
      "z": 5,
      "name": "Wood_Sallow_Branch_Corner",
      "rotation": 3
    },
    {
      "x": -4,
      "y": 39,
      "z": 5,
      "name": "Wood_Sallow_Branch_Long"
    },
    {
      "x": -4,
      "y": 40,
      "z": 5,
      "name": "Plant_Leaves_Beech"
    },
    {
      "x": -4,
      "y": 44,
      "z": 5,
      "name": "Plant_Leaves_Beech"
    },
    {
      "x": -4,
      "y": 45,
      "z": 5,
      "name": "Wood_Sallow_Branch_Long",
      "support": 1,
      "rotation": 4
    },
    {
      "x": -4,
      "y": 46,
      "z": 5,
      "name": "Plant_Leaves_Beech"
    },
    {
      "x": -4,
      "y": 0,
      "z": 6,
      "name": "Wood_Sallow_Trunk",
      "support": 15
    },
    {
      "x": -4,
      "y": 1,
      "z": 6,
      "name": "Wood_Sallow_Trunk",
      "support": 15
    },
    {
      "x": -4,
      "y": 2,
      "z": 6,
      "name": "Wood_Sallow_Trunk",
      "support": 15
    },
    {
      "x": -4,
      "y": 3,
      "z": 6,
      "name": "Wood_Sallow_Trunk_Full",
      "support": 15
    },
    {
      "x": -4,
      "y": 4,
      "z": 6,
      "name": "Plant_Moss_Rug_Green_Dark",
      "support": 15
    },
    {
      "x": -4,
      "y": 38,
      "z": 6,
      "name": "Plant_Leaves_Beech"
    },
    {
      "x": -4,
      "y": 39,
      "z": 6,
      "name": "Plant_Leaves_Beech"
    },
    {
      "x": -4,
      "y": 44,
      "z": 6,
      "name": "Plant_Leaves_Beech"
    },
    {
      "x": -4,
      "y": 45,
      "z": 6,
      "name": "Wood_Sallow_Branch_Corner",
      "support": 2
    },
    {
      "x": -4,
      "y": 46,
      "z": 6,
      "name": "Wood_Sallow_Branch_Long",
      "support": 3
    },
    {
      "x": -4,
      "y": 47,
      "z": 6,
      "name": "Plant_Leaves_Beech"
    },
    {
      "x": -4,
      "y": 0,
      "z": 7,
      "name": "Wood_Sallow_Trunk",
      "support": 15
    },
    {
      "x": -4,
      "y": 1,
      "z": 7,
      "name": "Wood_Sallow_Trunk",
      "support": 15
    },
    {
      "x": -4,
      "y": 2,
      "z": 7,
      "name": "Wood_Sallow_Trunk_Full",
      "support": 15
    },
    {
      "x": -4,
      "y": 45,
      "z": 7,
      "name": "Plant_Leaves_Beech"
    },
    {
      "x": -4,
      "y": 46,
      "z": 7,
      "name": "Plant_Leaves_Beech"
    },
    {
      "x": -4,
      "y": 47,
      "z": 7,
      "name": "Plant_Leaves_Beech"
    },
    {
      "x": -4,
      "y": 2,
      "z": 8,
      "name": "Plant_Moss_Wall_Green_Dark",
      "support": 15,
      "rotation": 1
    },
    {
      "x": -3,
      "y": 42,
      "z": -9,
      "name": "Plant_Leaves_Beech"
    },
    {
      "x": -3,
      "y": 41,
      "z": -8,
      "name": "Plant_Leaves_Beech"
    },
    {
      "x": -3,
      "y": 42,
      "z": -8,
      "name": "Plant_Leaves_Beech"
    },
    {
      "x": -3,
      "y": 41,
      "z": -7,
      "name": "Plant_Leaves_Beech"
    },
    {
      "x": -3,
      "y": 47,
      "z": -7,
      "name": "Plant_Leaves_Beech"
    },
    {
      "x": -3,
      "y": 0,
      "z": -6,
      "name": "Wood_Sallow_Trunk_Full",
      "support": 15
    },
    {
      "x": -3,
      "y": 35,
      "z": -5,
      "name": "Plant_Leaves_Beech"
    },
    {
      "x": -3,
      "y": 46,
      "z": -5,
      "name": "Wood_Sallow_Trunk_Full",
      "support": 2,
      "rotation": 5
    },
    {
      "x": -3,
      "y": 34,
      "z": -4,
      "name": "Plant_Leaves_Beech"
    },
    {
      "x": -3,
      "y": 35,
      "z": -4,
      "name": "Wood_Sallow_Branch_Long",
      "rotation": 5
    },
    {
      "x": -3,
      "y": 36,
      "z": -4,
      "name": "Plant_Leaves_Beech"
    },
    {
      "x": -3,
      "y": 40,
      "z": -4,
      "name": "Wood_Sallow_Trunk_Full",
      "support": 15,
      "rotation": 4
    },
    {
      "x": -3,
      "y": 43,
      "z": -4,
      "name": "Plant_Leaves_Beech"
    },
    {
      "x": -3,
      "y": 46,
      "z": -4,
      "name": "Wood_Sallow_Trunk",
      "support": 1,
      "rotation": 4
    },
    {
      "x": -3,
      "y": 48,
      "z": -4,
      "name": "Plant_Leaves_Beech"
    },
    {
      "x": -3,
      "y": 2,
      "z": -3,
      "name": "Plant_Moss_Wall_Green_Dark",
      "support": 15,
      "rotation": 3
    },
    {
      "x": -3,
      "y": 35,
      "z": -3,
      "name": "Plant_Leaves_Beech"
    },
    {
      "x": -3,
      "y": 36,
      "z": -3,
      "name": "Plant_Leaves_Beech"
    },
    {
      "x": -3,
      "y": 40,
      "z": -3,
      "name": "Wood_Sallow_Trunk",
      "support": 15,
      "rotation": 4
    },
    {
      "x": -3,
      "y": 45,
      "z": -3,
      "name": "Wood_Sallow_Trunk_Full",
      "support": 2
    },
    {
      "x": -3,
      "y": 46,
      "z": -3,
      "name": "Wood_Sallow_Trunk_Full",
      "rotation": 4
    },
    {
      "x": -3,
      "y": 47,
      "z": -3,
      "name": "Wood_Sallow_Branch_Long"
    },
    {
      "x": -3,
      "y": 48,
      "z": -3,
      "name": "Wood_Sallow_Branch_Long"
    },
    {
      "x": -3,
      "y": 49,
      "z": -3,
      "name": "Plant_Leaves_Beech"
    },
    {
      "x": -3,
      "y": 0,
      "z": -2,
      "name": "Wood_Sallow_Trunk",
      "support": 15
    },
    {
      "x": -3,
      "y": 1,
      "z": -2,
      "name": "Wood_Sallow_Trunk_Full",
      "support": 15
    },
    {
      "x": -3,
      "y": 2,
      "z": -2,
      "name": "Plant_Moss_Rug_Green_Dark",
      "support": 15
    },
    {
      "x": -3,
      "y": 40,
      "z": -2,
      "name": "Wood_Sallow_Trunk_Full",
      "rotation": 5
    },
    {
      "x": -3,
      "y": 45,
      "z": -2,
      "name": "Wood_Sallow_Trunk_Full",
      "support": 1,
      "rotation": 4
    },
    {
      "x": -3,
      "y": 48,
      "z": -2,
      "name": "Plant_Leaves_Beech"
    },
    {
      "x": -3,
      "y": 0,
      "z": -1,
      "name": "Wood_Sallow_Trunk",
      "support": 15
    },
    {
      "x": -3,
      "y": 1,
      "z": -1,
      "name": "Wood_Sallow_Trunk",
      "support": 15
    },
    {
      "x": -3,
      "y": 2,
      "z": -1,
      "name": "Wood_Sallow_Trunk",
      "support": 15
    },
    {
      "x": -3,
      "y": 3,
      "z": -1,
      "name": "Wood_Sallow_Trunk_Full",
      "support": 15
    },
    {
      "x": -3,
      "y": 0,
      "z": 0,
      "name": "Wood_Sallow_Trunk",
      "support": 15
    },
    {
      "x": -3,
      "y": 1,
      "z": 0,
      "name": "Wood_Sallow_Trunk",
      "support": 15
    },
    {
      "x": -3,
      "y": 2,
      "z": 0,
      "name": "Wood_Sallow_Trunk",
      "support": 15
    },
    {
      "x": -3,
      "y": 3,
      "z": 0,
      "name": "Wood_Sallow_Trunk",
      "support": 15
    },
    {
      "x": -3,
      "y": 4,
      "z": 0,
      "name": "Wood_Sallow_Trunk",
      "support": 15
    },
    {
      "x": -3,
      "y": 5,
      "z": 0,
      "name": "Wood_Sallow_Trunk",
      "support": 15
    },
    {
      "x": -3,
      "y": 6,
      "z": 0,
      "name": "Wood_Sallow_Trunk_Full",
      "support": 15
    },
    {
      "x": -3,
      "y": 38,
      "z": 0,
      "name": "Wood_Sallow_Trunk_Full",
      "rotation": 5
    },
    {
      "x": -3,
      "y": 39,
      "z": 0,
      "name": "Wood_Sallow_Trunk_Full"
    },
    {
      "x": -3,
      "y": 0,
      "z": 1,
      "name": "Wood_Sallow_Trunk",
      "support": 15
    },
    {
      "x": -3,
      "y": 1,
      "z": 1,
      "name": "Wood_Sallow_Trunk",
      "support": 15
    },
    {
      "x": -3,
      "y": 2,
      "z": 1,
      "name": "Wood_Sallow_Trunk",
      "support": 15
    },
    {
      "x": -3,
      "y": 3,
      "z": 1,
      "name": "Wood_Sallow_Trunk",
      "support": 15
    },
    {
      "x": -3,
      "y": 4,
      "z": 1,
      "name": "Wood_Sallow_Trunk",
      "support": 15
    },
    {
      "x": -3,
      "y": 5,
      "z": 1,
      "name": "Wood_Sallow_Trunk",
      "support": 15
    },
    {
      "x": -3,
      "y": 6,
      "z": 1,
      "name": "Wood_Sallow_Trunk_Full",
      "support": 15
    },
    {
      "x": -3,
      "y": 12,
      "z": 1,
      "name": "Plant_Moss_Wall_Green_Dark",
      "support": 15,
      "rotation": 3
    },
    {
      "x": -3,
      "y": 39,
      "z": 1,
      "name": "Wood_Sallow_Trunk_Full",
      "rotation": 4
    },
    {
      "x": -3,
      "y": 0,
      "z": 2,
      "name": "Wood_Sallow_Trunk",
      "support": 15
    },
    {
      "x": -3,
      "y": 1,
      "z": 2,
      "name": "Wood_Sallow_Trunk",
      "support": 15
    },
    {
      "x": -3,
      "y": 2,
      "z": 2,
      "name": "Wood_Sallow_Trunk",
      "support": 15
    },
    {
      "x": -3,
      "y": 3,
      "z": 2,
      "name": "Wood_Sallow_Trunk",
      "support": 15
    },
    {
      "x": -3,
      "y": 4,
      "z": 2,
      "name": "Wood_Sallow_Trunk",
      "support": 15
    },
    {
      "x": -3,
      "y": 5,
      "z": 2,
      "name": "Wood_Sallow_Trunk_Full",
      "support": 15
    },
    {
      "x": -3,
      "y": 6,
      "z": 2,
      "name": "Plant_Moss_Rug_Green_Dark",
      "support": 15
    },
    {
      "x": -3,
      "y": 37,
      "z": 2,
      "name": "Wood_Sallow_Branch_Long",
      "rotation": 5
    },
    {
      "x": -3,
      "y": 48,
      "z": 2,
      "name": "Plant_Leaves_Beech"
    },
    {
      "x": -3,
      "y": 49,
      "z": 2,
      "name": "Plant_Leaves_Beech"
    },
    {
      "x": -3,
      "y": 0,
      "z": 3,
      "name": "Wood_Sallow_Trunk",
      "support": 15
    },
    {
      "x": -3,
      "y": 1,
      "z": 3,
      "name": "Wood_Sallow_Trunk",
      "support": 15
    },
    {
      "x": -3,
      "y": 2,
      "z": 3,
      "name": "Wood_Sallow_Trunk",
      "support": 15
    },
    {
      "x": -3,
      "y": 3,
      "z": 3,
      "name": "Wood_Sallow_Trunk",
      "support": 15
    },
    {
      "x": -3,
      "y": 4,
      "z": 3,
      "name": "Wood_Sallow_Trunk_Full",
      "support": 15
    },
    {
      "x": -3,
      "y": 34,
      "z": 3,
      "name": "Plant_Vine_Liana",
      "rotation": 3
    },
    {
      "x": -3,
      "y": 35,
      "z": 3,
      "name": "Plant_Vine_Liana",
      "rotation": 3
    },
    {
      "x": -3,
      "y": 36,
      "z": 3,
      "name": "Plant_Vine_Liana",
      "rotation": 3
    },
    {
      "x": -3,
      "y": 37,
      "z": 3,
      "name": "Plant_Vine_Liana",
      "rotation": 3
    },
    {
      "x": -3,
      "y": 38,
      "z": 3,
      "name": "Plant_Vine_Liana",
      "rotation": 3
    },
    {
      "x": -3,
      "y": 44,
      "z": 3,
      "name": "Wood_Sallow_Trunk",
      "support": 2,
      "rotation": 5
    },
    {
      "x": -3,
      "y": 38,
      "z": 4,
      "name": "Plant_Leaves_Beech"
    },
    {
      "x": -3,
      "y": 0,
      "z": 5,
      "name": "Wood_Sallow_Trunk",
      "support": 15
    },
    {
      "x": -3,
      "y": 1,
      "z": 5,
      "name": "Wood_Sallow_Trunk",
      "support": 15
    },
    {
      "x": -3,
      "y": 2,
      "z": 5,
      "name": "Wood_Sallow_Trunk_Full",
      "support": 15
    },
    {
      "x": -3,
      "y": 6,
      "z": 5,
      "name": "Plant_Moss_Wall_Green_Dark",
      "support": 15,
      "rotation": 3
    },
    {
      "x": -3,
      "y": 38,
      "z": 5,
      "name": "Wood_Sallow_Branch_Long",
      "rotation": 5
    },
    {
      "x": -3,
      "y": 39,
      "z": 5,
      "name": "Plant_Leaves_Beech"
    },
    {
      "x": -3,
      "y": 45,
      "z": 5,
      "name": "Plant_Leaves_Beech"
    },
    {
      "x": -3,
      "y": 0,
      "z": 6,
      "name": "Wood_Sallow_Trunk",
      "support": 15
    },
    {
      "x": -3,
      "y": 1,
      "z": 6,
      "name": "Wood_Sallow_Trunk",
      "support": 15
    },
    {
      "x": -3,
      "y": 2,
      "z": 6,
      "name": "Wood_Sallow_Trunk",
      "support": 15
    },
    {
      "x": -3,
      "y": 3,
      "z": 6,
      "name": "Wood_Sallow_Trunk",
      "support": 15
    },
    {
      "x": -3,
      "y": 4,
      "z": 6,
      "name": "Wood_Sallow_Trunk_Full",
      "support": 15
    },
    {
      "x": -3,
      "y": 38,
      "z": 6,
      "name": "Plant_Leaves_Beech"
    },
    {
      "x": -3,
      "y": 41,
      "z": 6,
      "name": "Plant_Leaves_Beech"
    },
    {
      "x": -3,
      "y": 42,
      "z": 6,
      "name": "Plant_Leaves_Beech"
    },
    {
      "x": -3,
      "y": 45,
      "z": 6,
      "name": "Plant_Leaves_Beech"
    },
    {
      "x": -3,
      "y": 46,
      "z": 6,
      "name": "Plant_Leaves_Beech"
    },
    {
      "x": -3,
      "y": 47,
      "z": 6,
      "name": "Plant_Leaves_Beech"
    },
    {
      "x": -3,
      "y": 0,
      "z": 7,
      "name": "Wood_Sallow_Trunk",
      "support": 15
    },
    {
      "x": -3,
      "y": 1,
      "z": 7,
      "name": "Wood_Sallow_Trunk",
      "support": 15
    },
    {
      "x": -3,
      "y": 2,
      "z": 7,
      "name": "Wood_Sallow_Trunk",
      "support": 15
    },
    {
      "x": -3,
      "y": 3,
      "z": 7,
      "name": "Wood_Sallow_Trunk_Full",
      "support": 15
    },
    {
      "x": -3,
      "y": 38,
      "z": 7,
      "name": "Plant_Leaves_Beech",
      "support": 1
    },
    {
      "x": -3,
      "y": 39,
      "z": 7,
      "name": "Plant_Leaves_Beech",
      "support": 2
    },
    {
      "x": -3,
      "y": 45,
      "z": 7,
      "name": "Plant_Leaves_Beech"
    },
    {
      "x": -3,
      "y": 46,
      "z": 7,
      "name": "Wood_Sallow_Branch_Corner",
      "support": 2,
      "rotation": 3
    },
    {
      "x": -3,
      "y": 47,
      "z": 7,
      "name": "Wood_Sallow_Branch_Long",
      "support": 3
    },
    {
      "x": -3,
      "y": 48,
      "z": 7,
      "name": "Plant_Leaves_Beech"
    },
    {
      "x": -3,
      "y": 46,
      "z": 8,
      "name": "Plant_Leaves_Beech"
    },
    {
      "x": -3,
      "y": 47,
      "z": 8,
      "name": "Plant_Leaves_Beech"
    },
    {
      "x": -2,
      "y": 42,
      "z": -10,
      "name": "Plant_Leaves_Beech"
    },
    {
      "x": -2,
      "y": 41,
      "z": -9,
      "name": "Plant_Leaves_Beech"
    },
    {
      "x": -2,
      "y": 42,
      "z": -9,
      "name": "Wood_Sallow_Branch_Corner",
      "rotation": 2
    },
    {
      "x": -2,
      "y": 43,
      "z": -9,
      "name": "Plant_Leaves_Beech"
    },
    {
      "x": -2,
      "y": 46,
      "z": -8,
      "name": "Plant_Leaves_Beech",
      "support": 1
    },
    {
      "x": -2,
      "y": 47,
      "z": -8,
      "name": "Plant_Leaves_Beech"
    },
    {
      "x": -2,
      "y": 46,
      "z": -7,
      "name": "Plant_Leaves_Beech"
    },
    {
      "x": -2,
      "y": 47,
      "z": -7,
      "name": "Wood_Sallow_Branch_Long",
      "support": 1,
      "rotation": 4
    },
    {
      "x": -2,
      "y": 48,
      "z": -7,
      "name": "Plant_Leaves_Beech"
    },
    {
      "x": -2,
      "y": 0,
      "z": -6,
      "name": "Wood_Sallow_Trunk_Full",
      "support": 15
    },
    {
      "x": -2,
      "y": 35,
      "z": -6,
      "name": "Plant_Leaves_Beech"
    },
    {
      "x": -2,
      "y": 46,
      "z": -6,
      "name": "Plant_Leaves_Beech"
    },
    {
      "x": -2,
      "y": 47,
      "z": -6,
      "name": "Wood_Sallow_Branch_Long",
      "rotation": 4
    },
    {
      "x": -2,
      "y": 48,
      "z": -6,
      "name": "Plant_Leaves_Beech"
    },
    {
      "x": -2,
      "y": 0,
      "z": -5,
      "name": "Wood_Sallow_Trunk",
      "support": 15
    },
    {
      "x": -2,
      "y": 1,
      "z": -5,
      "name": "Wood_Sallow_Trunk_Full",
      "support": 15,
      "rotation": 4
    },
    {
      "x": -2,
      "y": 36,
      "z": -5,
      "name": "Plant_Leaves_Beech"
    },
    {
      "x": -2,
      "y": 37,
      "z": -5,
      "name": "Plant_Leaves_Beech"
    },
    {
      "x": -2,
      "y": 46,
      "z": -5,
      "name": "Wood_Sallow_Trunk_Full",
      "support": 3,
      "rotation": 5
    },
    {
      "x": -2,
      "y": 47,
      "z": -5,
      "name": "Wood_Sallow_Trunk_Full"
    },
    {
      "x": -2,
      "y": 0,
      "z": -4,
      "name": "Wood_Sallow_Trunk",
      "support": 15
    },
    {
      "x": -2,
      "y": 1,
      "z": -4,
      "name": "Wood_Sallow_Trunk_Full",
      "support": 15
    },
    {
      "x": -2,
      "y": 34,
      "z": -4,
      "name": "Plant_Leaves_Beech"
    },
    {
      "x": -2,
      "y": 35,
      "z": -4,
      "name": "Wood_Sallow_Branch_Long",
      "rotation": 5
    },
    {
      "x": -2,
      "y": 40,
      "z": -4,
      "name": "Wood_Sallow_Branch_Long",
      "support": 15,
      "rotation": 5
    },
    {
      "x": -2,
      "y": 0,
      "z": -3,
      "name": "Wood_Sallow_Trunk",
      "support": 15
    },
    {
      "x": -2,
      "y": 1,
      "z": -3,
      "name": "Wood_Sallow_Trunk",
      "support": 15
    },
    {
      "x": -2,
      "y": 2,
      "z": -3,
      "name": "Wood_Sallow_Trunk_Full",
      "support": 15
    },
    {
      "x": -2,
      "y": 3,
      "z": -3,
      "name": "Plant_Moss_Rug_Green_Dark",
      "support": 15
    },
    {
      "x": -2,
      "y": 48,
      "z": -3,
      "name": "Plant_Leaves_Beech"
    },
    {
      "x": -2,
      "y": 0,
      "z": -2,
      "name": "Wood_Sallow_Trunk",
      "support": 15
    },
    {
      "x": -2,
      "y": 1,
      "z": -2,
      "name": "Wood_Sallow_Trunk",
      "support": 15
    },
    {
      "x": -2,
      "y": 2,
      "z": -2,
      "name": "Wood_Sallow_Trunk",
      "support": 15
    },
    {
      "x": -2,
      "y": 3,
      "z": -2,
      "name": "Wood_Sallow_Trunk_Full",
      "support": 15
    },
    {
      "x": -2,
      "y": 5,
      "z": -2,
      "name": "Plant_Moss_Wall_Green_Dark",
      "support": 15,
      "rotation": 3
    },
    {
      "x": -2,
      "y": 44,
      "z": -2,
      "name": "Wood_Sallow_Trunk_Full",
      "support": 1,
      "rotation": 4
    },
    {
      "x": -2,
      "y": 45,
      "z": -2,
      "name": "Wood_Sallow_Trunk_Full",
      "rotation": 5
    },
    {
      "x": -2,
      "y": 0,
      "z": -1,
      "name": "Wood_Sallow_Trunk",
      "support": 15
    },
    {
      "x": -2,
      "y": 1,
      "z": -1,
      "name": "Wood_Sallow_Trunk",
      "support": 15
    },
    {
      "x": -2,
      "y": 2,
      "z": -1,
      "name": "Wood_Sallow_Trunk",
      "support": 15
    },
    {
      "x": -2,
      "y": 3,
      "z": -1,
      "name": "Wood_Sallow_Trunk",
      "support": 15
    },
    {
      "x": -2,
      "y": 4,
      "z": -1,
      "name": "Wood_Sallow_Trunk",
      "support": 15
    },
    {
      "x": -2,
      "y": 5,
      "z": -1,
      "name": "Wood_Sallow_Trunk_Full",
      "support": 15
    },
    {
      "x": -2,
      "y": 6,
      "z": -1,
      "name": "Plant_Moss_Rug_Green_Dark",
      "support": 15
    },
    {
      "x": -2,
      "y": 7,
      "z": -1,
      "name": "Plant_Moss_Wall_Green_Dark",
      "support": 15,
      "rotation": 3
    },
    {
      "x": -2,
      "y": 39,
      "z": -1,
      "name": "Wood_Sallow_Trunk_Full",
      "rotation": 4
    },
    {
      "x": -2,
      "y": 40,
      "z": -1,
      "name": "Wood_Sallow_Trunk_Full"
    },
    {
      "x": -2,
      "y": 43,
      "z": -1,
      "name": "Wood_Sallow_Trunk_Full",
      "support": 4
    },
    {
      "x": -2,
      "y": 44,
      "z": -1,
      "name": "Wood_Sallow_Trunk_Full",
      "rotation": 4
    },
    {
      "x": -2,
      "y": 0,
      "z": 0,
      "name": "Wood_Sallow_Trunk",
      "support": 15
    },
    {
      "x": -2,
      "y": 1,
      "z": 0,
      "name": "Wood_Sallow_Trunk",
      "support": 15
    },
    {
      "x": -2,
      "y": 2,
      "z": 0,
      "name": "Wood_Sallow_Trunk",
      "support": 15
    },
    {
      "x": -2,
      "y": 3,
      "z": 0,
      "name": "Wood_Sallow_Trunk",
      "support": 15
    },
    {
      "x": -2,
      "y": 4,
      "z": 0,
      "name": "Wood_Sallow_Trunk",
      "support": 15
    },
    {
      "x": -2,
      "y": 5,
      "z": 0,
      "name": "Wood_Sallow_Trunk",
      "support": 15
    },
    {
      "x": -2,
      "y": 6,
      "z": 0,
      "name": "Wood_Sallow_Trunk",
      "support": 15
    },
    {
      "x": -2,
      "y": 7,
      "z": 0,
      "name": "Wood_Sallow_Trunk",
      "support": 15
    },
    {
      "x": -2,
      "y": 8,
      "z": 0,
      "name": "Wood_Sallow_Trunk",
      "support": 15
    },
    {
      "x": -2,
      "y": 9,
      "z": 0,
      "name": "Wood_Sallow_Trunk_Full",
      "support": 15
    },
    {
      "x": -2,
      "y": 37,
      "z": 0,
      "name": "Wood_Sallow_Trunk_Full",
      "rotation": 5
    },
    {
      "x": -2,
      "y": 38,
      "z": 0,
      "name": "Wood_Sallow_Trunk"
    },
    {
      "x": -2,
      "y": 39,
      "z": 0,
      "name": "Wood_Sallow_Trunk_Full"
    },
    {
      "x": -2,
      "y": 0,
      "z": 1,
      "name": "Wood_Sallow_Trunk",
      "support": 15
    },
    {
      "x": -2,
      "y": 1,
      "z": 1,
      "name": "Wood_Sallow_Trunk",
      "support": 15
    },
    {
      "x": -2,
      "y": 2,
      "z": 1,
      "name": "Wood_Sallow_Trunk",
      "support": 15
    },
    {
      "x": -2,
      "y": 3,
      "z": 1,
      "name": "Wood_Sallow_Trunk",
      "support": 15
    },
    {
      "x": -2,
      "y": 4,
      "z": 1,
      "name": "Wood_Sallow_Trunk",
      "support": 15
    },
    {
      "x": -2,
      "y": 5,
      "z": 1,
      "name": "Wood_Sallow_Trunk",
      "support": 15
    },
    {
      "x": -2,
      "y": 6,
      "z": 1,
      "name": "Wood_Sallow_Trunk",
      "support": 15
    },
    {
      "x": -2,
      "y": 7,
      "z": 1,
      "name": "Wood_Sallow_Trunk",
      "support": 15
    },
    {
      "x": -2,
      "y": 8,
      "z": 1,
      "name": "Wood_Sallow_Trunk",
      "support": 15
    },
    {
      "x": -2,
      "y": 9,
      "z": 1,
      "name": "Wood_Sallow_Trunk",
      "support": 15
    },
    {
      "x": -2,
      "y": 10,
      "z": 1,
      "name": "Wood_Sallow_Trunk",
      "support": 15
    },
    {
      "x": -2,
      "y": 11,
      "z": 1,
      "name": "Wood_Sallow_Trunk",
      "support": 15
    },
    {
      "x": -2,
      "y": 12,
      "z": 1,
      "name": "Wood_Sallow_Trunk_Full",
      "support": 15
    },
    {
      "x": -2,
      "y": 13,
      "z": 1,
      "name": "Plant_Moss_Rug_Green_Dark",
      "support": 15
    },
    {
      "x": -2,
      "y": 19,
      "z": 1,
      "name": "Wood_Sallow_Branch_Short",
      "support": 15,
      "rotation": 3
    },
    {
      "x": -2,
      "y": 33,
      "z": 1,
      "name": "Wood_Sallow_Branch_Short",
      "rotation": 3
    },
    {
      "x": -2,
      "y": 35,
      "z": 1,
      "name": "Wood_Sallow_Branch_Short",
      "rotation": 3
    },
    {
      "x": -2,
      "y": 48,
      "z": 1,
      "name": "Plant_Leaves_Beech"
    },
    {
      "x": -2,
      "y": 49,
      "z": 1,
      "name": "Plant_Leaves_Beech"
    },
    {
      "x": -2,
      "y": 0,
      "z": 2,
      "name": "Wood_Sallow_Trunk",
      "support": 15
    },
    {
      "x": -2,
      "y": 1,
      "z": 2,
      "name": "Wood_Sallow_Trunk",
      "support": 15
    },
    {
      "x": -2,
      "y": 2,
      "z": 2,
      "name": "Wood_Sallow_Trunk",
      "support": 15
    },
    {
      "x": -2,
      "y": 3,
      "z": 2,
      "name": "Wood_Sallow_Trunk",
      "support": 15
    },
    {
      "x": -2,
      "y": 4,
      "z": 2,
      "name": "Wood_Sallow_Trunk",
      "support": 15
    },
    {
      "x": -2,
      "y": 5,
      "z": 2,
      "name": "Wood_Sallow_Trunk",
      "support": 15
    },
    {
      "x": -2,
      "y": 6,
      "z": 2,
      "name": "Wood_Sallow_Trunk",
      "support": 15
    },
    {
      "x": -2,
      "y": 7,
      "z": 2,
      "name": "Wood_Sallow_Trunk",
      "support": 15
    },
    {
      "x": -2,
      "y": 8,
      "z": 2,
      "name": "Wood_Sallow_Trunk",
      "support": 15
    },
    {
      "x": -2,
      "y": 9,
      "z": 2,
      "name": "Wood_Sallow_Trunk",
      "support": 15
    },
    {
      "x": -2,
      "y": 10,
      "z": 2,
      "name": "Wood_Sallow_Trunk_Full",
      "support": 15
    },
    {
      "x": -2,
      "y": 34,
      "z": 2,
      "name": "Wood_Sallow_Trunk_Full",
      "support": 1
    },
    {
      "x": -2,
      "y": 35,
      "z": 2,
      "name": "Wood_Sallow_Trunk"
    },
    {
      "x": -2,
      "y": 36,
      "z": 2,
      "name": "Wood_Sallow_Trunk"
    },
    {
      "x": -2,
      "y": 37,
      "z": 2,
      "name": "Wood_Sallow_Trunk"
    },
    {
      "x": -2,
      "y": 38,
      "z": 2,
      "name": "Wood_Sallow_Trunk_Full"
    },
    {
      "x": -2,
      "y": 43,
      "z": 2,
      "name": "Wood_Sallow_Trunk_Full",
      "support": 3,
      "rotation": 5
    },
    {
      "x": -2,
      "y": 44,
      "z": 2,
      "name": "Wood_Sallow_Trunk_Full"
    },
    {
      "x": -2,
      "y": 47,
      "z": 2,
      "name": "Wood_Sallow_Branch_Corner",
      "rotation": 2
    },
    {
      "x": -2,
      "y": 48,
      "z": 2,
      "name": "Wood_Sallow_Branch_Long",
      "support": 15
    },
    {
      "x": -2,
      "y": 49,
      "z": 2,
      "name": "Wood_Sallow_Branch_Long",
      "support": 15
    },
    {
      "x": -2,
      "y": 50,
      "z": 2,
      "name": "Plant_Leaves_Beech"
    },
    {
      "x": -2,
      "y": 0,
      "z": 3,
      "name": "Wood_Sallow_Trunk",
      "support": 15
    },
    {
      "x": -2,
      "y": 1,
      "z": 3,
      "name": "Wood_Sallow_Trunk",
      "support": 15
    },
    {
      "x": -2,
      "y": 2,
      "z": 3,
      "name": "Wood_Sallow_Trunk",
      "support": 15
    },
    {
      "x": -2,
      "y": 3,
      "z": 3,
      "name": "Wood_Sallow_Trunk",
      "support": 15
    },
    {
      "x": -2,
      "y": 4,
      "z": 3,
      "name": "Wood_Sallow_Trunk",
      "support": 15
    },
    {
      "x": -2,
      "y": 5,
      "z": 3,
      "name": "Wood_Sallow_Trunk",
      "support": 15
    },
    {
      "x": -2,
      "y": 6,
      "z": 3,
      "name": "Wood_Sallow_Trunk",
      "support": 15
    },
    {
      "x": -2,
      "y": 7,
      "z": 3,
      "name": "Wood_Sallow_Trunk",
      "support": 15
    },
    {
      "x": -2,
      "y": 8,
      "z": 3,
      "name": "Wood_Sallow_Trunk_Full",
      "support": 15
    },
    {
      "x": -2,
      "y": 9,
      "z": 3,
      "name": "Plant_Moss_Rug_Green_Dark",
      "support": 15
    },
    {
      "x": -2,
      "y": 30,
      "z": 3,
      "name": "Plant_Vine_Liana",
      "support": 15,
      "rotation": 3
    },
    {
      "x": -2,
      "y": 31,
      "z": 3,
      "name": "Plant_Vine_Liana",
      "support": 15,
      "rotation": 3
    },
    {
      "x": -2,
      "y": 32,
      "z": 3,
      "name": "Plant_Vine_Liana",
      "support": 15,
      "rotation": 3
    },
    {
      "x": -2,
      "y": 33,
      "z": 3,
      "name": "Plant_Vine_Liana",
      "support": 15,
      "rotation": 3
    },
    {
      "x": -2,
      "y": 34,
      "z": 3,
      "name": "Plant_Vine_Liana",
      "support": 15,
      "rotation": 3
    },
    {
      "x": -2,
      "y": 35,
      "z": 3,
      "name": "Plant_Vine_Liana",
      "support": 15,
      "rotation": 3
    },
    {
      "x": -2,
      "y": 36,
      "z": 3,
      "name": "Wood_Sallow_Trunk_Full",
      "support": 15
    },
    {
      "x": -2,
      "y": 37,
      "z": 3,
      "name": "Wood_Sallow_Trunk",
      "support": 15
    },
    {
      "x": -2,
      "y": 38,
      "z": 3,
      "name": "Wood_Sallow_Trunk_Full",
      "support": 15
    },
    {
      "x": -2,
      "y": 44,
      "z": 3,
      "name": "Wood_Sallow_Trunk_Full",
      "support": 1,
      "rotation": 4
    },
    {
      "x": -2,
      "y": 45,
      "z": 3,
      "name": "Wood_Sallow_Branch_Long"
    },
    {
      "x": -2,
      "y": 46,
      "z": 3,
      "name": "Wood_Sallow_Branch_Long"
    },
    {
      "x": -2,
      "y": 47,
      "z": 3,
      "name": "Wood_Sallow_Branch_Corner",
      "rotation": 12
    },
    {
      "x": -2,
      "y": 48,
      "z": 3,
      "name": "Plant_Leaves_Beech"
    },
    {
      "x": -2,
      "y": 49,
      "z": 3,
      "name": "Plant_Leaves_Beech",
      "support": 15
    },
    {
      "x": -2,
      "y": 0,
      "z": 4,
      "name": "Wood_Sallow_Trunk",
      "support": 15
    },
    {
      "x": -2,
      "y": 1,
      "z": 4,
      "name": "Wood_Sallow_Trunk",
      "support": 15
    },
    {
      "x": -2,
      "y": 2,
      "z": 4,
      "name": "Wood_Sallow_Trunk",
      "support": 15
    },
    {
      "x": -2,
      "y": 3,
      "z": 4,
      "name": "Wood_Sallow_Trunk",
      "support": 15
    },
    {
      "x": -2,
      "y": 4,
      "z": 4,
      "name": "Wood_Sallow_Trunk",
      "support": 15
    },
    {
      "x": -2,
      "y": 5,
      "z": 4,
      "name": "Wood_Sallow_Trunk",
      "support": 15
    },
    {
      "x": -2,
      "y": 6,
      "z": 4,
      "name": "Wood_Sallow_Trunk_Full",
      "support": 15
    },
    {
      "x": -2,
      "y": 7,
      "z": 4,
      "name": "Plant_Moss_Rug_Green_Dark",
      "support": 15
    },
    {
      "x": -2,
      "y": 46,
      "z": 4,
      "name": "Plant_Leaves_Beech"
    },
    {
      "x": -2,
      "y": 0,
      "z": 5,
      "name": "Wood_Sallow_Trunk",
      "support": 15
    },
    {
      "x": -2,
      "y": 1,
      "z": 5,
      "name": "Wood_Sallow_Trunk",
      "support": 15
    },
    {
      "x": -2,
      "y": 2,
      "z": 5,
      "name": "Wood_Sallow_Trunk",
      "support": 15
    },
    {
      "x": -2,
      "y": 3,
      "z": 5,
      "name": "Wood_Sallow_Trunk",
      "support": 15
    },
    {
      "x": -2,
      "y": 4,
      "z": 5,
      "name": "Wood_Sallow_Trunk",
      "support": 15
    },
    {
      "x": -2,
      "y": 5,
      "z": 5,
      "name": "Wood_Sallow_Trunk",
      "support": 15
    },
    {
      "x": -2,
      "y": 6,
      "z": 5,
      "name": "Wood_Sallow_Trunk_Full",
      "support": 15
    },
    {
      "x": -2,
      "y": 7,
      "z": 5,
      "name": "Plant_Moss_Rug_Green_Dark",
      "support": 15
    },
    {
      "x": -2,
      "y": 38,
      "z": 5,
      "name": "Wood_Sallow_Branch_Long",
      "rotation": 5
    },
    {
      "x": -2,
      "y": 41,
      "z": 5,
      "name": "Plant_Leaves_Beech"
    },
    {
      "x": -2,
      "y": 42,
      "z": 5,
      "name": "Plant_Leaves_Beech"
    },
    {
      "x": -2,
      "y": 0,
      "z": 6,
      "name": "Wood_Sallow_Trunk",
      "support": 15
    },
    {
      "x": -2,
      "y": 1,
      "z": 6,
      "name": "Wood_Sallow_Trunk",
      "support": 15
    },
    {
      "x": -2,
      "y": 2,
      "z": 6,
      "name": "Wood_Sallow_Trunk",
      "support": 15
    },
    {
      "x": -2,
      "y": 3,
      "z": 6,
      "name": "Wood_Sallow_Trunk_Full",
      "support": 15
    },
    {
      "x": -2,
      "y": 40,
      "z": 6,
      "name": "Plant_Leaves_Beech"
    },
    {
      "x": -2,
      "y": 41,
      "z": 6,
      "name": "Wood_Sallow_Branch_Corner",
      "rotation": 3
    },
    {
      "x": -2,
      "y": 42,
      "z": 6,
      "name": "Wood_Sallow_Branch_Long"
    },
    {
      "x": -2,
      "y": 43,
      "z": 6,
      "name": "Plant_Leaves_Beech"
    },
    {
      "x": -2,
      "y": 46,
      "z": 6,
      "name": "Plant_Leaves_Beech"
    },
    {
      "x": -2,
      "y": 41,
      "z": 7,
      "name": "Plant_Leaves_Beech"
    },
    {
      "x": -2,
      "y": 42,
      "z": 7,
      "name": "Plant_Leaves_Beech"
    },
    {
      "x": -2,
      "y": 46,
      "z": 7,
      "name": "Wood_Sallow_Branch_Long",
      "support": 1,
      "rotation": 5
    },
    {
      "x": -2,
      "y": 47,
      "z": 7,
      "name": "Plant_Leaves_Beech"
    },
    {
      "x": -2,
      "y": 46,
      "z": 8,
      "name": "Plant_Leaves_Beech"
    },
    {
      "x": -1,
      "y": 42,
      "z": -9,
      "name": "Plant_Leaves_Beech"
    },
    {
      "x": -1,
      "y": 47,
      "z": -8,
      "name": "Plant_Leaves_Beech",
      "support": 1
    },
    {
      "x": -1,
      "y": 35,
      "z": -7,
      "name": "Plant_Leaves_Beech"
    },
    {
      "x": -1,
      "y": 47,
      "z": -7,
      "name": "Plant_Leaves_Beech"
    },
    {
      "x": -1,
      "y": 34,
      "z": -6,
      "name": "Plant_Leaves_Beech"
    },
    {
      "x": -1,
      "y": 35,
      "z": -6,
      "name": "Wood_Sallow_Branch_Long",
      "rotation": 4
    },
    {
      "x": -1,
      "y": 36,
      "z": -6,
      "name": "Plant_Leaves_Beech"
    },
    {
      "x": -1,
      "y": 37,
      "z": -6,
      "name": "Plant_Leaves_Beech"
    },
    {
      "x": -1,
      "y": 0,
      "z": -5,
      "name": "Wood_Sallow_Trunk",
      "support": 15
    },
    {
      "x": -1,
      "y": 1,
      "z": -5,
      "name": "Wood_Sallow_Trunk_Full",
      "support": 15
    },
    {
      "x": -1,
      "y": 35,
      "z": -5,
      "name": "Wood_Sallow_Trunk",
      "rotation": 4
    },
    {
      "x": -1,
      "y": 36,
      "z": -5,
      "name": "Wood_Sallow_Branch_Long"
    },
    {
      "x": -1,
      "y": 37,
      "z": -5,
      "name": "Wood_Sallow_Branch_Long"
    },
    {
      "x": -1,
      "y": 38,
      "z": -5,
      "name": "Plant_Leaves_Beech"
    },
    {
      "x": -1,
      "y": 40,
      "z": -5,
      "name": "Plant_Leaves_Beech",
      "support": 5
    },
    {
      "x": -1,
      "y": 47,
      "z": -5,
      "name": "Wood_Sallow_Branch_Long",
      "rotation": 5
    },
    {
      "x": -1,
      "y": 48,
      "z": -5,
      "name": "Plant_Leaves_Beech"
    },
    {
      "x": -1,
      "y": 0,
      "z": -4,
      "name": "Wood_Sallow_Trunk",
      "support": 15
    },
    {
      "x": -1,
      "y": 1,
      "z": -4,
      "name": "Wood_Sallow_Trunk",
      "support": 15
    },
    {
      "x": -1,
      "y": 2,
      "z": -4,
      "name": "Wood_Sallow_Trunk",
      "support": 15
    },
    {
      "x": -1,
      "y": 3,
      "z": -4,
      "name": "Wood_Sallow_Trunk_Full",
      "support": 15
    },
    {
      "x": -1,
      "y": 4,
      "z": -4,
      "name": "Plant_Moss_Rug_Green_Dark",
      "support": 15
    },
    {
      "x": -1,
      "y": 35,
      "z": -4,
      "name": "Wood_Sallow_Trunk",
      "rotation": 4
    },
    {
      "x": -1,
      "y": 39,
      "z": -4,
      "name": "Plant_Leaves_Beech"
    },
    {
      "x": -1,
      "y": 40,
      "z": -4,
      "name": "Wood_Sallow_Branch_Long",
      "support": 4,
      "rotation": 5
    },
    {
      "x": -1,
      "y": 41,
      "z": -4,
      "name": "Plant_Leaves_Beech"
    },
    {
      "x": -1,
      "y": 47,
      "z": -4,
      "name": "Plant_Leaves_Beech"
    },
    {
      "x": -1,
      "y": 0,
      "z": -3,
      "name": "Wood_Sallow_Trunk",
      "support": 15
    },
    {
      "x": -1,
      "y": 1,
      "z": -3,
      "name": "Wood_Sallow_Trunk",
      "support": 15
    },
    {
      "x": -1,
      "y": 2,
      "z": -3,
      "name": "Wood_Sallow_Trunk",
      "support": 15
    },
    {
      "x": -1,
      "y": 3,
      "z": -3,
      "name": "Wood_Sallow_Trunk",
      "support": 15
    },
    {
      "x": -1,
      "y": 4,
      "z": -3,
      "name": "Wood_Sallow_Trunk_Full",
      "support": 15
    },
    {
      "x": -1,
      "y": 35,
      "z": -3,
      "name": "Wood_Sallow_Trunk_Full",
      "rotation": 4
    },
    {
      "x": -1,
      "y": 40,
      "z": -3,
      "name": "Plant_Leaves_Beech",
      "support": 3
    },
    {
      "x": -1,
      "y": 0,
      "z": -2,
      "name": "Wood_Sallow_Trunk",
      "support": 15
    },
    {
      "x": -1,
      "y": 1,
      "z": -2,
      "name": "Wood_Sallow_Trunk",
      "support": 15
    },
    {
      "x": -1,
      "y": 2,
      "z": -2,
      "name": "Wood_Sallow_Trunk",
      "support": 15
    },
    {
      "x": -1,
      "y": 3,
      "z": -2,
      "name": "Wood_Sallow_Trunk",
      "support": 15
    },
    {
      "x": -1,
      "y": 4,
      "z": -2,
      "name": "Wood_Sallow_Trunk",
      "support": 15
    },
    {
      "x": -1,
      "y": 5,
      "z": -2,
      "name": "Wood_Sallow_Trunk_Full",
      "support": 15
    },
    {
      "x": -1,
      "y": 6,
      "z": -2,
      "name": "Plant_Moss_Rug_Green_Dark",
      "support": 15
    },
    {
      "x": -1,
      "y": 7,
      "z": -2,
      "name": "Plant_Moss_Wall_Green_Dark",
      "support": 15,
      "rotation": 2
    },
    {
      "x": -1,
      "y": 0,
      "z": -1,
      "name": "Wood_Sallow_Trunk",
      "support": 15
    },
    {
      "x": -1,
      "y": 1,
      "z": -1,
      "name": "Wood_Sallow_Trunk",
      "support": 15
    },
    {
      "x": -1,
      "y": 2,
      "z": -1,
      "name": "Wood_Sallow_Trunk",
      "support": 15
    },
    {
      "x": -1,
      "y": 3,
      "z": -1,
      "name": "Wood_Sallow_Trunk",
      "support": 15
    },
    {
      "x": -1,
      "y": 4,
      "z": -1,
      "name": "Wood_Sallow_Trunk",
      "support": 15
    },
    {
      "x": -1,
      "y": 5,
      "z": -1,
      "name": "Wood_Sallow_Trunk",
      "support": 15
    },
    {
      "x": -1,
      "y": 6,
      "z": -1,
      "name": "Wood_Sallow_Trunk",
      "support": 15
    },
    {
      "x": -1,
      "y": 7,
      "z": -1,
      "name": "Wood_Sallow_Trunk_Full",
      "support": 15
    },
    {
      "x": -1,
      "y": 8,
      "z": -1,
      "name": "Plant_Moss_Rug_Green_Dark",
      "support": 15
    },
    {
      "x": -1,
      "y": 43,
      "z": -1,
      "name": "Wood_Sallow_Trunk_Full",
      "support": 3,
      "rotation": 5
    },
    {
      "x": -1,
      "y": 0,
      "z": 0,
      "name": "Wood_Sallow_Trunk",
      "support": 15
    },
    {
      "x": -1,
      "y": 1,
      "z": 0,
      "name": "Wood_Sallow_Trunk"
    },
    {
      "x": -1,
      "y": 2,
      "z": 0,
      "name": "Wood_Sallow_Trunk"
    },
    {
      "x": -1,
      "y": 3,
      "z": 0,
      "name": "Wood_Sallow_Trunk"
    },
    {
      "x": -1,
      "y": 4,
      "z": 0,
      "name": "Wood_Sallow_Trunk"
    },
    {
      "x": -1,
      "y": 5,
      "z": 0,
      "name": "Wood_Sallow_Trunk"
    },
    {
      "x": -1,
      "y": 6,
      "z": 0,
      "name": "Wood_Sallow_Trunk"
    },
    {
      "x": -1,
      "y": 7,
      "z": 0,
      "name": "Wood_Sallow_Trunk"
    },
    {
      "x": -1,
      "y": 8,
      "z": 0,
      "name": "Wood_Sallow_Trunk"
    },
    {
      "x": -1,
      "y": 9,
      "z": 0,
      "name": "Wood_Sallow_Trunk"
    },
    {
      "x": -1,
      "y": 10,
      "z": 0,
      "name": "Wood_Sallow_Trunk"
    },
    {
      "x": -1,
      "y": 11,
      "z": 0,
      "name": "Wood_Sallow_Trunk_Full",
      "support": 15
    },
    {
      "x": -1,
      "y": 37,
      "z": 0,
      "name": "Wood_Sallow_Trunk_Full"
    },
    {
      "x": -1,
      "y": 43,
      "z": 0,
      "name": "Wood_Sallow_Trunk",
      "support": 2,
      "rotation": 4
    },
    {
      "x": -1,
      "y": 0,
      "z": 1,
      "name": "Wood_Sallow_Trunk",
      "support": 15
    },
    {
      "x": -1,
      "y": 1,
      "z": 1,
      "name": "Wood_Sallow_Trunk",
      "support": 15
    },
    {
      "x": -1,
      "y": 2,
      "z": 1,
      "name": "Wood_Sallow_Trunk"
    },
    {
      "x": -1,
      "y": 3,
      "z": 1,
      "name": "Wood_Sallow_Trunk"
    },
    {
      "x": -1,
      "y": 4,
      "z": 1,
      "name": "Wood_Sallow_Trunk"
    },
    {
      "x": -1,
      "y": 5,
      "z": 1,
      "name": "Wood_Sallow_Trunk"
    },
    {
      "x": -1,
      "y": 6,
      "z": 1,
      "name": "Wood_Sallow_Trunk"
    },
    {
      "x": -1,
      "y": 7,
      "z": 1,
      "name": "Wood_Sallow_Trunk"
    },
    {
      "x": -1,
      "y": 8,
      "z": 1,
      "name": "Wood_Sallow_Trunk"
    },
    {
      "x": -1,
      "y": 9,
      "z": 1,
      "name": "Wood_Sallow_Trunk"
    },
    {
      "x": -1,
      "y": 10,
      "z": 1,
      "name": "Wood_Sallow_Trunk"
    },
    {
      "x": -1,
      "y": 11,
      "z": 1,
      "name": "Wood_Sallow_Trunk"
    },
    {
      "x": -1,
      "y": 12,
      "z": 1,
      "name": "Wood_Sallow_Trunk"
    },
    {
      "x": -1,
      "y": 13,
      "z": 1,
      "name": "Wood_Sallow_Trunk"
    },
    {
      "x": -1,
      "y": 14,
      "z": 1,
      "name": "Wood_Sallow_Trunk"
    },
    {
      "x": -1,
      "y": 15,
      "z": 1,
      "name": "Wood_Sallow_Trunk"
    },
    {
      "x": -1,
      "y": 16,
      "z": 1,
      "name": "Wood_Sallow_Trunk"
    },
    {
      "x": -1,
      "y": 17,
      "z": 1,
      "name": "Wood_Sallow_Trunk"
    },
    {
      "x": -1,
      "y": 18,
      "z": 1,
      "name": "Wood_Sallow_Trunk"
    },
    {
      "x": -1,
      "y": 19,
      "z": 1,
      "name": "Wood_Sallow_Trunk"
    },
    {
      "x": -1,
      "y": 20,
      "z": 1,
      "name": "Wood_Sallow_Trunk"
    },
    {
      "x": -1,
      "y": 21,
      "z": 1,
      "name": "Wood_Sallow_Trunk"
    },
    {
      "x": -1,
      "y": 22,
      "z": 1,
      "name": "Wood_Sallow_Trunk"
    },
    {
      "x": -1,
      "y": 23,
      "z": 1,
      "name": "Wood_Sallow_Trunk"
    },
    {
      "x": -1,
      "y": 24,
      "z": 1,
      "name": "Wood_Sallow_Trunk"
    },
    {
      "x": -1,
      "y": 25,
      "z": 1,
      "name": "Wood_Sallow_Trunk"
    },
    {
      "x": -1,
      "y": 26,
      "z": 1,
      "name": "Wood_Sallow_Trunk"
    },
    {
      "x": -1,
      "y": 27,
      "z": 1,
      "name": "Wood_Sallow_Trunk"
    },
    {
      "x": -1,
      "y": 28,
      "z": 1,
      "name": "Wood_Sallow_Trunk"
    },
    {
      "x": -1,
      "y": 29,
      "z": 1,
      "name": "Wood_Sallow_Trunk"
    },
    {
      "x": -1,
      "y": 30,
      "z": 1,
      "name": "Wood_Sallow_Trunk"
    },
    {
      "x": -1,
      "y": 31,
      "z": 1,
      "name": "Wood_Sallow_Trunk"
    },
    {
      "x": -1,
      "y": 32,
      "z": 1,
      "name": "Wood_Sallow_Trunk"
    },
    {
      "x": -1,
      "y": 33,
      "z": 1,
      "name": "Wood_Sallow_Trunk"
    },
    {
      "x": -1,
      "y": 34,
      "z": 1,
      "name": "Wood_Sallow_Trunk"
    },
    {
      "x": -1,
      "y": 35,
      "z": 1,
      "name": "Wood_Sallow_Trunk"
    },
    {
      "x": -1,
      "y": 36,
      "z": 1,
      "name": "Wood_Sallow_Trunk"
    },
    {
      "x": -1,
      "y": 37,
      "z": 1,
      "name": "Wood_Sallow_Trunk"
    },
    {
      "x": -1,
      "y": 38,
      "z": 1,
      "name": "Wood_Sallow_Trunk"
    },
    {
      "x": -1,
      "y": 39,
      "z": 1,
      "name": "Wood_Sallow_Trunk"
    },
    {
      "x": -1,
      "y": 40,
      "z": 1,
      "name": "Wood_Sallow_Trunk"
    },
    {
      "x": -1,
      "y": 41,
      "z": 1,
      "name": "Wood_Sallow_Trunk_Full"
    },
    {
      "x": -1,
      "y": 43,
      "z": 1,
      "name": "Wood_Sallow_Trunk_Full",
      "support": 1,
      "rotation": 4
    },
    {
      "x": -1,
      "y": 0,
      "z": 2,
      "name": "Wood_Sallow_Trunk"
    },
    {
      "x": -1,
      "y": 1,
      "z": 2,
      "name": "Wood_Sallow_Trunk"
    },
    {
      "x": -1,
      "y": 2,
      "z": 2,
      "name": "Wood_Sallow_Trunk"
    },
    {
      "x": -1,
      "y": 3,
      "z": 2,
      "name": "Wood_Sallow_Trunk"
    },
    {
      "x": -1,
      "y": 4,
      "z": 2,
      "name": "Wood_Sallow_Trunk"
    },
    {
      "x": -1,
      "y": 5,
      "z": 2,
      "name": "Wood_Sallow_Trunk"
    },
    {
      "x": -1,
      "y": 6,
      "z": 2,
      "name": "Wood_Sallow_Trunk"
    },
    {
      "x": -1,
      "y": 7,
      "z": 2,
      "name": "Wood_Sallow_Trunk"
    },
    {
      "x": -1,
      "y": 8,
      "z": 2,
      "name": "Wood_Sallow_Trunk"
    },
    {
      "x": -1,
      "y": 9,
      "z": 2,
      "name": "Wood_Sallow_Trunk"
    },
    {
      "x": -1,
      "y": 10,
      "z": 2,
      "name": "Wood_Sallow_Trunk"
    },
    {
      "x": -1,
      "y": 11,
      "z": 2,
      "name": "Wood_Sallow_Trunk"
    },
    {
      "x": -1,
      "y": 12,
      "z": 2,
      "name": "Wood_Sallow_Trunk"
    },
    {
      "x": -1,
      "y": 13,
      "z": 2,
      "name": "Wood_Sallow_Trunk"
    },
    {
      "x": -1,
      "y": 14,
      "z": 2,
      "name": "Wood_Sallow_Trunk_Full",
      "support": 15
    },
    {
      "x": -1,
      "y": 32,
      "z": 2,
      "name": "Wood_Sallow_Trunk_Full",
      "support": 15
    },
    {
      "x": -1,
      "y": 33,
      "z": 2,
      "name": "Wood_Sallow_Trunk"
    },
    {
      "x": -1,
      "y": 34,
      "z": 2,
      "name": "Wood_Sallow_Trunk"
    },
    {
      "x": -1,
      "y": 35,
      "z": 2,
      "name": "Wood_Sallow_Trunk"
    },
    {
      "x": -1,
      "y": 36,
      "z": 2,
      "name": "Wood_Sallow_Trunk"
    },
    {
      "x": -1,
      "y": 37,
      "z": 2,
      "name": "Wood_Sallow_Trunk"
    },
    {
      "x": -1,
      "y": 38,
      "z": 2,
      "name": "Wood_Sallow_Trunk"
    },
    {
      "x": -1,
      "y": 39,
      "z": 2,
      "name": "Wood_Sallow_Trunk_Full"
    },
    {
      "x": -1,
      "y": 41,
      "z": 2,
      "name": "Wood_Sallow_Branch_Long",
      "rotation": 4
    },
    {
      "x": -1,
      "y": 43,
      "z": 2,
      "name": "Wood_Sallow_Trunk_Full",
      "support": 2,
      "rotation": 4
    },
    {
      "x": -1,
      "y": 49,
      "z": 2,
      "name": "Plant_Leaves_Beech"
    },
    {
      "x": -1,
      "y": 0,
      "z": 3,
      "name": "Wood_Sallow_Trunk",
      "support": 15
    },
    {
      "x": -1,
      "y": 1,
      "z": 3,
      "name": "Wood_Sallow_Trunk",
      "support": 15
    },
    {
      "x": -1,
      "y": 2,
      "z": 3,
      "name": "Wood_Sallow_Trunk",
      "support": 15
    },
    {
      "x": -1,
      "y": 3,
      "z": 3,
      "name": "Wood_Sallow_Trunk",
      "support": 15
    },
    {
      "x": -1,
      "y": 4,
      "z": 3,
      "name": "Wood_Sallow_Trunk",
      "support": 15
    },
    {
      "x": -1,
      "y": 5,
      "z": 3,
      "name": "Wood_Sallow_Trunk",
      "support": 15
    },
    {
      "x": -1,
      "y": 6,
      "z": 3,
      "name": "Wood_Sallow_Trunk",
      "support": 15
    },
    {
      "x": -1,
      "y": 7,
      "z": 3,
      "name": "Wood_Sallow_Trunk",
      "support": 15
    },
    {
      "x": -1,
      "y": 8,
      "z": 3,
      "name": "Wood_Sallow_Trunk",
      "support": 15
    },
    {
      "x": -1,
      "y": 9,
      "z": 3,
      "name": "Wood_Sallow_Trunk",
      "support": 15
    },
    {
      "x": -1,
      "y": 10,
      "z": 3,
      "name": "Wood_Sallow_Trunk_Full",
      "support": 15
    },
    {
      "x": -1,
      "y": 34,
      "z": 3,
      "name": "Wood_Sallow_Trunk_Full",
      "support": 15
    },
    {
      "x": -1,
      "y": 35,
      "z": 3,
      "name": "Wood_Sallow_Trunk"
    },
    {
      "x": -1,
      "y": 36,
      "z": 3,
      "name": "Wood_Sallow_Trunk"
    },
    {
      "x": -1,
      "y": 37,
      "z": 3,
      "name": "Wood_Sallow_Trunk"
    },
    {
      "x": -1,
      "y": 38,
      "z": 3,
      "name": "Wood_Sallow_Trunk_Full"
    },
    {
      "x": -1,
      "y": 41,
      "z": 3,
      "name": "Wood_Sallow_Branch_Long",
      "rotation": 4
    },
    {
      "x": -1,
      "y": 0,
      "z": 4,
      "name": "Wood_Sallow_Trunk",
      "support": 15
    },
    {
      "x": -1,
      "y": 1,
      "z": 4,
      "name": "Wood_Sallow_Trunk",
      "support": 15
    },
    {
      "x": -1,
      "y": 2,
      "z": 4,
      "name": "Wood_Sallow_Trunk",
      "support": 15
    },
    {
      "x": -1,
      "y": 3,
      "z": 4,
      "name": "Wood_Sallow_Trunk",
      "support": 15
    },
    {
      "x": -1,
      "y": 4,
      "z": 4,
      "name": "Wood_Sallow_Trunk",
      "support": 15
    },
    {
      "x": -1,
      "y": 5,
      "z": 4,
      "name": "Wood_Sallow_Trunk",
      "support": 15
    },
    {
      "x": -1,
      "y": 6,
      "z": 4,
      "name": "Wood_Sallow_Trunk_Full",
      "support": 15
    },
    {
      "x": -1,
      "y": 38,
      "z": 4,
      "name": "Wood_Sallow_Trunk",
      "support": 1,
      "rotation": 4
    },
    {
      "x": -1,
      "y": 41,
      "z": 4,
      "name": "Wood_Sallow_Branch_Long",
      "rotation": 4
    },
    {
      "x": -1,
      "y": 0,
      "z": 5,
      "name": "Wood_Sallow_Trunk",
      "support": 15
    },
    {
      "x": -1,
      "y": 1,
      "z": 5,
      "name": "Wood_Sallow_Trunk",
      "support": 15
    },
    {
      "x": -1,
      "y": 2,
      "z": 5,
      "name": "Wood_Sallow_Trunk",
      "support": 15
    },
    {
      "x": -1,
      "y": 3,
      "z": 5,
      "name": "Wood_Sallow_Trunk",
      "support": 15
    },
    {
      "x": -1,
      "y": 4,
      "z": 5,
      "name": "Wood_Sallow_Trunk",
      "support": 15
    },
    {
      "x": -1,
      "y": 5,
      "z": 5,
      "name": "Wood_Sallow_Trunk_Full",
      "support": 15
    },
    {
      "x": -1,
      "y": 6,
      "z": 5,
      "name": "Plant_Moss_Wall_Green_Dark",
      "support": 15,
      "rotation": 1
    },
    {
      "x": -1,
      "y": 38,
      "z": 5,
      "name": "Wood_Sallow_Trunk_Full",
      "support": 2,
      "rotation": 4
    },
    {
      "x": -1,
      "y": 41,
      "z": 5,
      "name": "Wood_Sallow_Branch_Long",
      "rotation": 4
    },
    {
      "x": -1,
      "y": 41,
      "z": 6,
      "name": "Wood_Sallow_Branch_Corner",
      "rotation": 16
    },
    {
      "x": -1,
      "y": 42,
      "z": 6,
      "name": "Plant_Leaves_Beech"
    },
    {
      "x": -1,
      "y": 46,
      "z": 7,
      "name": "Wood_Sallow_Branch_Long",
      "rotation": 5
    },
    {
      "x": -1,
      "y": 48,
      "z": 7,
      "name": "Plant_Leaves_Beech"
    },
    {
      "x": -1,
      "y": 38,
      "z": 8,
      "name": "Plant_Leaves_Beech",
      "support": 15
    },
    {
      "x": -1,
      "y": 46,
      "z": 8,
      "name": "Plant_Leaves_Beech",
      "support": 15
    },
    {
      "x": -1,
      "y": 38,
      "z": 9,
      "name": "Plant_Leaves_Beech",
      "support": 15
    },
    {
      "x": -1,
      "y": 39,
      "z": 9,
      "name": "Plant_Leaves_Beech",
      "support": 15
    },
    {
      "x": -1,
      "y": 46,
      "z": 9,
      "name": "Plant_Leaves_Beech",
      "support": 15
    },
    {
      "x": -1,
      "y": 47,
      "z": 9,
      "name": "Plant_Leaves_Beech",
      "support": 15
    },
    {
      "x": 0,
      "y": 35,
      "z": -6,
      "name": "Plant_Leaves_Beech"
    },
    {
      "x": 0,
      "y": 47,
      "z": -6,
      "name": "Plant_Leaves_Beech"
    },
    {
      "x": 0,
      "y": 48,
      "z": -6,
      "name": "Plant_Leaves_Beech"
    },
    {
      "x": 0,
      "y": 35,
      "z": -5,
      "name": "Wood_Sallow_Branch_Long",
      "rotation": 5
    },
    {
      "x": 0,
      "y": 36,
      "z": -5,
      "name": "Plant_Leaves_Beech"
    },
    {
      "x": 0,
      "y": 37,
      "z": -5,
      "name": "Plant_Leaves_Beech"
    },
    {
      "x": 0,
      "y": 40,
      "z": -5,
      "name": "Plant_Leaves_Beech",
      "support": 15
    },
    {
      "x": 0,
      "y": 41,
      "z": -5,
      "name": "Plant_Leaves_Beech",
      "support": 15
    },
    {
      "x": 0,
      "y": 46,
      "z": -5,
      "name": "Plant_Leaves_Beech"
    },
    {
      "x": 0,
      "y": 47,
      "z": -5,
      "name": "Wood_Sallow_Branch_Corner",
      "rotation": 1
    },
    {
      "x": 0,
      "y": 48,
      "z": -5,
      "name": "Wood_Sallow_Branch_Long"
    },
    {
      "x": 0,
      "y": 49,
      "z": -5,
      "name": "Plant_Leaves_Beech"
    },
    {
      "x": 0,
      "y": 0,
      "z": -4,
      "name": "Wood_Sallow_Trunk",
      "support": 15
    },
    {
      "x": 0,
      "y": 1,
      "z": -4,
      "name": "Wood_Sallow_Trunk_Full",
      "support": 15
    },
    {
      "x": 0,
      "y": 3,
      "z": -4,
      "name": "Plant_Moss_Wall_Green_Dark",
      "support": 15,
      "rotation": 1
    },
    {
      "x": 0,
      "y": 27,
      "z": -4,
      "name": "Plant_Vine_Liana_End",
      "rotation": 2
    },
    {
      "x": 0,
      "y": 28,
      "z": -4,
      "name": "Plant_Vine_Liana",
      "rotation": 2
    },
    {
      "x": 0,
      "y": 29,
      "z": -4,
      "name": "Plant_Vine_Liana",
      "rotation": 2
    },
    {
      "x": 0,
      "y": 30,
      "z": -4,
      "name": "Plant_Vine_Liana",
      "rotation": 2
    },
    {
      "x": 0,
      "y": 31,
      "z": -4,
      "name": "Plant_Vine_Liana",
      "rotation": 2
    },
    {
      "x": 0,
      "y": 32,
      "z": -4,
      "name": "Plant_Vine_Liana",
      "rotation": 2
    },
    {
      "x": 0,
      "y": 33,
      "z": -4,
      "name": "Plant_Vine_Liana",
      "support": 15,
      "rotation": 2
    },
    {
      "x": 0,
      "y": 34,
      "z": -4,
      "name": "Plant_Vine_Liana",
      "support": 15,
      "rotation": 2
    },
    {
      "x": 0,
      "y": 35,
      "z": -4,
      "name": "Plant_Vine_Liana",
      "support": 15,
      "rotation": 2
    },
    {
      "x": 0,
      "y": 36,
      "z": -4,
      "name": "Plant_Vine_Liana",
      "support": 15,
      "rotation": 2
    },
    {
      "x": 0,
      "y": 37,
      "z": -4,
      "name": "Plant_Vine_Liana",
      "support": 15,
      "rotation": 2
    },
    {
      "x": 0,
      "y": 39,
      "z": -4,
      "name": "Plant_Leaves_Beech",
      "support": 15
    },
    {
      "x": 0,
      "y": 40,
      "z": -4,
      "name": "Wood_Sallow_Branch_Corner",
      "support": 15,
      "rotation": 1
    },
    {
      "x": 0,
      "y": 41,
      "z": -4,
      "name": "Wood_Sallow_Branch_Long"
    },
    {
      "x": 0,
      "y": 42,
      "z": -4,
      "name": "Plant_Leaves_Beech"
    },
    {
      "x": 0,
      "y": 47,
      "z": -4,
      "name": "Plant_Leaves_Beech"
    },
    {
      "x": 0,
      "y": 48,
      "z": -4,
      "name": "Plant_Leaves_Beech"
    },
    {
      "x": 0,
      "y": 0,
      "z": -3,
      "name": "Wood_Sallow_Trunk",
      "support": 15
    },
    {
      "x": 0,
      "y": 1,
      "z": -3,
      "name": "Wood_Sallow_Trunk",
      "support": 15
    },
    {
      "x": 0,
      "y": 2,
      "z": -3,
      "name": "Wood_Sallow_Trunk",
      "support": 15
    },
    {
      "x": 0,
      "y": 3,
      "z": -3,
      "name": "Wood_Sallow_Trunk",
      "support": 15
    },
    {
      "x": 0,
      "y": 4,
      "z": -3,
      "name": "Wood_Sallow_Trunk",
      "support": 15
    },
    {
      "x": 0,
      "y": 5,
      "z": -3,
      "name": "Wood_Sallow_Trunk_Full",
      "support": 15
    },
    {
      "x": 0,
      "y": 35,
      "z": -3,
      "name": "Wood_Sallow_Trunk_Full",
      "rotation": 4
    },
    {
      "x": 0,
      "y": 40,
      "z": -3,
      "name": "Plant_Leaves_Beech",
      "support": 2
    },
    {
      "x": 0,
      "y": 41,
      "z": -3,
      "name": "Plant_Leaves_Beech"
    },
    {
      "x": 0,
      "y": 0,
      "z": -2,
      "name": "Wood_Sallow_Trunk",
      "support": 15
    },
    {
      "x": 0,
      "y": 1,
      "z": -2,
      "name": "Wood_Sallow_Trunk",
      "support": 15
    },
    {
      "x": 0,
      "y": 2,
      "z": -2,
      "name": "Wood_Sallow_Trunk",
      "support": 15
    },
    {
      "x": 0,
      "y": 3,
      "z": -2,
      "name": "Wood_Sallow_Trunk",
      "support": 15
    },
    {
      "x": 0,
      "y": 4,
      "z": -2,
      "name": "Wood_Sallow_Trunk",
      "support": 15
    },
    {
      "x": 0,
      "y": 5,
      "z": -2,
      "name": "Wood_Sallow_Trunk",
      "support": 15
    },
    {
      "x": 0,
      "y": 6,
      "z": -2,
      "name": "Wood_Sallow_Trunk",
      "support": 15
    },
    {
      "x": 0,
      "y": 7,
      "z": -2,
      "name": "Wood_Sallow_Trunk",
      "support": 15
    },
    {
      "x": 0,
      "y": 8,
      "z": -2,
      "name": "Wood_Sallow_Trunk_Full",
      "support": 15
    },
    {
      "x": 0,
      "y": 35,
      "z": -2,
      "name": "Wood_Sallow_Trunk",
      "rotation": 4
    },
    {
      "x": 0,
      "y": 0,
      "z": -1,
      "name": "Wood_Sallow_Trunk",
      "support": 15
    },
    {
      "x": 0,
      "y": 1,
      "z": -1,
      "name": "Wood_Sallow_Trunk",
      "support": 15
    },
    {
      "x": 0,
      "y": 2,
      "z": -1,
      "name": "Wood_Sallow_Trunk",
      "support": 15
    },
    {
      "x": 0,
      "y": 3,
      "z": -1,
      "name": "Wood_Sallow_Trunk",
      "support": 15
    },
    {
      "x": 0,
      "y": 4,
      "z": -1,
      "name": "Wood_Sallow_Trunk",
      "support": 15
    },
    {
      "x": 0,
      "y": 5,
      "z": -1,
      "name": "Wood_Sallow_Trunk",
      "support": 15
    },
    {
      "x": 0,
      "y": 6,
      "z": -1,
      "name": "Wood_Sallow_Trunk",
      "support": 15
    },
    {
      "x": 0,
      "y": 7,
      "z": -1,
      "name": "Wood_Sallow_Trunk",
      "support": 15
    },
    {
      "x": 0,
      "y": 8,
      "z": -1,
      "name": "Wood_Sallow_Trunk",
      "support": 15
    },
    {
      "x": 0,
      "y": 9,
      "z": -1,
      "name": "Wood_Sallow_Trunk",
      "support": 15
    },
    {
      "x": 0,
      "y": 10,
      "z": -1,
      "name": "Wood_Sallow_Trunk_Full",
      "support": 15
    },
    {
      "x": 0,
      "y": 11,
      "z": -1,
      "name": "Plant_Moss_Rug_Green_Dark",
      "support": 15
    },
    {
      "x": 0,
      "y": 33,
      "z": -1,
      "name": "Wood_Sallow_Trunk_Full",
      "support": 1
    },
    {
      "x": 0,
      "y": 34,
      "z": -1,
      "name": "Wood_Sallow_Trunk"
    },
    {
      "x": 0,
      "y": 35,
      "z": -1,
      "name": "Wood_Sallow_Trunk_Full"
    },
    {
      "x": 0,
      "y": 0,
      "z": 0,
      "name": "Wood_Sallow_Trunk"
    },
    {
      "x": 0,
      "y": 1,
      "z": 0,
      "name": "Wood_Sallow_Trunk"
    },
    {
      "x": 0,
      "y": 2,
      "z": 0,
      "name": "Wood_Sallow_Trunk"
    },
    {
      "x": 0,
      "y": 3,
      "z": 0,
      "name": "Wood_Sallow_Trunk"
    },
    {
      "x": 0,
      "y": 4,
      "z": 0,
      "name": "Wood_Sallow_Trunk"
    },
    {
      "x": 0,
      "y": 5,
      "z": 0,
      "name": "Wood_Sallow_Trunk"
    },
    {
      "x": 0,
      "y": 6,
      "z": 0,
      "name": "Wood_Sallow_Trunk"
    },
    {
      "x": 0,
      "y": 7,
      "z": 0,
      "name": "Wood_Sallow_Trunk"
    },
    {
      "x": 0,
      "y": 8,
      "z": 0,
      "name": "Wood_Sallow_Trunk"
    },
    {
      "x": 0,
      "y": 9,
      "z": 0,
      "name": "Wood_Sallow_Trunk"
    },
    {
      "x": 0,
      "y": 10,
      "z": 0,
      "name": "Wood_Sallow_Trunk"
    },
    {
      "x": 0,
      "y": 11,
      "z": 0,
      "name": "Wood_Sallow_Trunk"
    },
    {
      "x": 0,
      "y": 12,
      "z": 0,
      "name": "Wood_Sallow_Trunk"
    },
    {
      "x": 0,
      "y": 13,
      "z": 0,
      "name": "Wood_Sallow_Trunk"
    },
    {
      "x": 0,
      "y": 14,
      "z": 0,
      "name": "Wood_Sallow_Trunk"
    },
    {
      "x": 0,
      "y": 15,
      "z": 0,
      "name": "Wood_Sallow_Trunk"
    },
    {
      "x": 0,
      "y": 16,
      "z": 0,
      "name": "Wood_Sallow_Trunk"
    },
    {
      "x": 0,
      "y": 17,
      "z": 0,
      "name": "Wood_Sallow_Trunk"
    },
    {
      "x": 0,
      "y": 18,
      "z": 0,
      "name": "Wood_Sallow_Trunk"
    },
    {
      "x": 0,
      "y": 19,
      "z": 0,
      "name": "Wood_Sallow_Trunk"
    },
    {
      "x": 0,
      "y": 20,
      "z": 0,
      "name": "Wood_Sallow_Trunk"
    },
    {
      "x": 0,
      "y": 21,
      "z": 0,
      "name": "Wood_Sallow_Trunk"
    },
    {
      "x": 0,
      "y": 22,
      "z": 0,
      "name": "Wood_Sallow_Trunk"
    },
    {
      "x": 0,
      "y": 23,
      "z": 0,
      "name": "Wood_Sallow_Trunk"
    },
    {
      "x": 0,
      "y": 24,
      "z": 0,
      "name": "Wood_Sallow_Trunk"
    },
    {
      "x": 0,
      "y": 25,
      "z": 0,
      "name": "Wood_Sallow_Trunk"
    },
    {
      "x": 0,
      "y": 26,
      "z": 0,
      "name": "Wood_Sallow_Trunk"
    },
    {
      "x": 0,
      "y": 27,
      "z": 0,
      "name": "Wood_Sallow_Trunk"
    },
    {
      "x": 0,
      "y": 28,
      "z": 0,
      "name": "Wood_Sallow_Trunk"
    },
    {
      "x": 0,
      "y": 29,
      "z": 0,
      "name": "Wood_Sallow_Trunk"
    },
    {
      "x": 0,
      "y": 30,
      "z": 0,
      "name": "Wood_Sallow_Trunk"
    },
    {
      "x": 0,
      "y": 31,
      "z": 0,
      "name": "Wood_Sallow_Trunk"
    },
    {
      "x": 0,
      "y": 32,
      "z": 0,
      "name": "Wood_Sallow_Trunk"
    },
    {
      "x": 0,
      "y": 33,
      "z": 0,
      "name": "Wood_Sallow_Trunk"
    },
    {
      "x": 0,
      "y": 34,
      "z": 0,
      "name": "Wood_Sallow_Trunk"
    },
    {
      "x": 0,
      "y": 35,
      "z": 0,
      "name": "Wood_Sallow_Trunk"
    },
    {
      "x": 0,
      "y": 36,
      "z": 0,
      "name": "Wood_Sallow_Trunk"
    },
    {
      "x": 0,
      "y": 37,
      "z": 0,
      "name": "Wood_Sallow_Trunk"
    },
    {
      "x": 0,
      "y": 38,
      "z": 0,
      "name": "Wood_Sallow_Trunk"
    },
    {
      "x": 0,
      "y": 39,
      "z": 0,
      "name": "Wood_Sallow_Trunk"
    },
    {
      "x": 0,
      "y": 40,
      "z": 0,
      "name": "Wood_Sallow_Trunk"
    },
    {
      "x": 0,
      "y": 41,
      "z": 0,
      "name": "Wood_Sallow_Trunk"
    },
    {
      "x": 0,
      "y": 42,
      "z": 0,
      "name": "Wood_Sallow_Trunk_Full"
    },
    {
      "x": 0,
      "y": 0,
      "z": 1,
      "name": "Wood_Sallow_Trunk"
    },
    {
      "x": 0,
      "y": 1,
      "z": 1,
      "name": "Wood_Sallow_Trunk",
      "support": 1
    },
    {
      "x": 0,
      "y": 2,
      "z": 1,
      "name": "Wood_Sallow_Trunk"
    },
    {
      "x": 0,
      "y": 3,
      "z": 1,
      "name": "Wood_Sallow_Trunk"
    },
    {
      "x": 0,
      "y": 4,
      "z": 1,
      "name": "Wood_Sallow_Trunk"
    },
    {
      "x": 0,
      "y": 5,
      "z": 1,
      "name": "Wood_Sallow_Trunk"
    },
    {
      "x": 0,
      "y": 6,
      "z": 1,
      "name": "Wood_Sallow_Trunk"
    },
    {
      "x": 0,
      "y": 7,
      "z": 1,
      "name": "Wood_Sallow_Trunk"
    },
    {
      "x": 0,
      "y": 8,
      "z": 1,
      "name": "Wood_Sallow_Trunk"
    },
    {
      "x": 0,
      "y": 9,
      "z": 1,
      "name": "Wood_Sallow_Trunk"
    },
    {
      "x": 0,
      "y": 10,
      "z": 1,
      "name": "Wood_Sallow_Trunk"
    },
    {
      "x": 0,
      "y": 11,
      "z": 1,
      "name": "Wood_Sallow_Trunk"
    },
    {
      "x": 0,
      "y": 12,
      "z": 1,
      "name": "Wood_Sallow_Trunk"
    },
    {
      "x": 0,
      "y": 13,
      "z": 1,
      "name": "Wood_Sallow_Trunk"
    },
    {
      "x": 0,
      "y": 14,
      "z": 1,
      "name": "Wood_Sallow_Trunk"
    },
    {
      "x": 0,
      "y": 15,
      "z": 1,
      "name": "Wood_Sallow_Trunk"
    },
    {
      "x": 0,
      "y": 16,
      "z": 1,
      "name": "Wood_Sallow_Trunk"
    },
    {
      "x": 0,
      "y": 17,
      "z": 1,
      "name": "Wood_Sallow_Trunk"
    },
    {
      "x": 0,
      "y": 18,
      "z": 1,
      "name": "Wood_Sallow_Trunk"
    },
    {
      "x": 0,
      "y": 19,
      "z": 1,
      "name": "Wood_Sallow_Trunk"
    },
    {
      "x": 0,
      "y": 20,
      "z": 1,
      "name": "Wood_Sallow_Trunk"
    },
    {
      "x": 0,
      "y": 21,
      "z": 1,
      "name": "Wood_Sallow_Trunk"
    },
    {
      "x": 0,
      "y": 22,
      "z": 1,
      "name": "Wood_Sallow_Trunk"
    },
    {
      "x": 0,
      "y": 23,
      "z": 1,
      "name": "Wood_Sallow_Trunk"
    },
    {
      "x": 0,
      "y": 24,
      "z": 1,
      "name": "Wood_Sallow_Trunk"
    },
    {
      "x": 0,
      "y": 25,
      "z": 1,
      "name": "Wood_Sallow_Trunk"
    },
    {
      "x": 0,
      "y": 26,
      "z": 1,
      "name": "Wood_Sallow_Trunk"
    },
    {
      "x": 0,
      "y": 27,
      "z": 1,
      "name": "Wood_Sallow_Trunk"
    },
    {
      "x": 0,
      "y": 28,
      "z": 1,
      "name": "Wood_Sallow_Trunk"
    },
    {
      "x": 0,
      "y": 29,
      "z": 1,
      "name": "Wood_Sallow_Trunk"
    },
    {
      "x": 0,
      "y": 30,
      "z": 1,
      "name": "Wood_Sallow_Trunk"
    },
    {
      "x": 0,
      "y": 31,
      "z": 1,
      "name": "Wood_Sallow_Trunk"
    },
    {
      "x": 0,
      "y": 32,
      "z": 1,
      "name": "Wood_Sallow_Trunk"
    },
    {
      "x": 0,
      "y": 33,
      "z": 1,
      "name": "Wood_Sallow_Trunk"
    },
    {
      "x": 0,
      "y": 34,
      "z": 1,
      "name": "Wood_Sallow_Trunk"
    },
    {
      "x": 0,
      "y": 35,
      "z": 1,
      "name": "Wood_Sallow_Trunk"
    },
    {
      "x": 0,
      "y": 36,
      "z": 1,
      "name": "Wood_Sallow_Trunk"
    },
    {
      "x": 0,
      "y": 37,
      "z": 1,
      "name": "Wood_Sallow_Trunk"
    },
    {
      "x": 0,
      "y": 38,
      "z": 1,
      "name": "Wood_Sallow_Trunk"
    },
    {
      "x": 0,
      "y": 39,
      "z": 1,
      "name": "Wood_Sallow_Trunk"
    },
    {
      "x": 0,
      "y": 40,
      "z": 1,
      "name": "Wood_Sallow_Trunk"
    },
    {
      "x": 0,
      "y": 41,
      "z": 1,
      "name": "Wood_Sallow_Trunk"
    },
    {
      "x": 0,
      "y": 42,
      "z": 1,
      "name": "Wood_Sallow_Trunk"
    },
    {
      "x": 0,
      "y": 43,
      "z": 1,
      "name": "Wood_Sallow_Trunk_Full"
    },
    {
      "x": 0,
      "y": 0,
      "z": 2,
      "name": "Wood_Sallow_Trunk",
      "support": 15
    },
    {
      "x": 0,
      "y": 1,
      "z": 2,
      "name": "Wood_Sallow_Trunk",
      "support": 15
    },
    {
      "x": 0,
      "y": 2,
      "z": 2,
      "name": "Wood_Sallow_Trunk"
    },
    {
      "x": 0,
      "y": 3,
      "z": 2,
      "name": "Wood_Sallow_Trunk"
    },
    {
      "x": 0,
      "y": 4,
      "z": 2,
      "name": "Wood_Sallow_Trunk"
    },
    {
      "x": 0,
      "y": 5,
      "z": 2,
      "name": "Wood_Sallow_Trunk"
    },
    {
      "x": 0,
      "y": 6,
      "z": 2,
      "name": "Wood_Sallow_Trunk"
    },
    {
      "x": 0,
      "y": 7,
      "z": 2,
      "name": "Wood_Sallow_Trunk"
    },
    {
      "x": 0,
      "y": 8,
      "z": 2,
      "name": "Wood_Sallow_Trunk"
    },
    {
      "x": 0,
      "y": 9,
      "z": 2,
      "name": "Wood_Sallow_Trunk"
    },
    {
      "x": 0,
      "y": 10,
      "z": 2,
      "name": "Wood_Sallow_Trunk"
    },
    {
      "x": 0,
      "y": 11,
      "z": 2,
      "name": "Wood_Sallow_Trunk"
    },
    {
      "x": 0,
      "y": 12,
      "z": 2,
      "name": "Wood_Sallow_Trunk"
    },
    {
      "x": 0,
      "y": 13,
      "z": 2,
      "name": "Wood_Sallow_Trunk"
    },
    {
      "x": 0,
      "y": 14,
      "z": 2,
      "name": "Wood_Sallow_Trunk",
      "support": 15
    },
    {
      "x": 0,
      "y": 15,
      "z": 2,
      "name": "Wood_Sallow_Trunk"
    },
    {
      "x": 0,
      "y": 16,
      "z": 2,
      "name": "Wood_Sallow_Trunk"
    },
    {
      "x": 0,
      "y": 17,
      "z": 2,
      "name": "Wood_Sallow_Trunk"
    },
    {
      "x": 0,
      "y": 18,
      "z": 2,
      "name": "Wood_Sallow_Trunk"
    },
    {
      "x": 0,
      "y": 19,
      "z": 2,
      "name": "Wood_Sallow_Trunk"
    },
    {
      "x": 0,
      "y": 20,
      "z": 2,
      "name": "Wood_Sallow_Trunk"
    },
    {
      "x": 0,
      "y": 21,
      "z": 2,
      "name": "Wood_Sallow_Trunk"
    },
    {
      "x": 0,
      "y": 22,
      "z": 2,
      "name": "Wood_Sallow_Trunk"
    },
    {
      "x": 0,
      "y": 23,
      "z": 2,
      "name": "Wood_Sallow_Trunk"
    },
    {
      "x": 0,
      "y": 24,
      "z": 2,
      "name": "Wood_Sallow_Trunk"
    },
    {
      "x": 0,
      "y": 25,
      "z": 2,
      "name": "Wood_Sallow_Trunk"
    },
    {
      "x": 0,
      "y": 26,
      "z": 2,
      "name": "Wood_Sallow_Trunk"
    },
    {
      "x": 0,
      "y": 27,
      "z": 2,
      "name": "Wood_Sallow_Trunk"
    },
    {
      "x": 0,
      "y": 28,
      "z": 2,
      "name": "Wood_Sallow_Trunk"
    },
    {
      "x": 0,
      "y": 29,
      "z": 2,
      "name": "Wood_Sallow_Trunk"
    },
    {
      "x": 0,
      "y": 30,
      "z": 2,
      "name": "Wood_Sallow_Trunk"
    },
    {
      "x": 0,
      "y": 31,
      "z": 2,
      "name": "Wood_Sallow_Trunk"
    },
    {
      "x": 0,
      "y": 32,
      "z": 2,
      "name": "Wood_Sallow_Trunk"
    },
    {
      "x": 0,
      "y": 33,
      "z": 2,
      "name": "Wood_Sallow_Trunk"
    },
    {
      "x": 0,
      "y": 34,
      "z": 2,
      "name": "Wood_Sallow_Trunk"
    },
    {
      "x": 0,
      "y": 35,
      "z": 2,
      "name": "Wood_Sallow_Trunk"
    },
    {
      "x": 0,
      "y": 36,
      "z": 2,
      "name": "Wood_Sallow_Trunk"
    },
    {
      "x": 0,
      "y": 37,
      "z": 2,
      "name": "Wood_Sallow_Trunk"
    },
    {
      "x": 0,
      "y": 38,
      "z": 2,
      "name": "Wood_Sallow_Trunk"
    },
    {
      "x": 0,
      "y": 39,
      "z": 2,
      "name": "Wood_Sallow_Trunk"
    },
    {
      "x": 0,
      "y": 40,
      "z": 2,
      "name": "Wood_Sallow_Trunk_Full"
    },
    {
      "x": 0,
      "y": 43,
      "z": 2,
      "name": "Wood_Sallow_Trunk_Full",
      "support": 1,
      "rotation": 5
    },
    {
      "x": 0,
      "y": 44,
      "z": 2,
      "name": "Wood_Sallow_Trunk_Full",
      "rotation": 4
    },
    {
      "x": 0,
      "y": 0,
      "z": 3,
      "name": "Wood_Sallow_Trunk",
      "support": 15
    },
    {
      "x": 0,
      "y": 1,
      "z": 3,
