{
  "version": 8,
  "blockIdVersion": 11,
  "anchorX": 0,
  "anchorY": 0,
  "anchorZ": 0,
  "blocks": [
    {
      "x": -33,
      "y": 4,
      "z": -22,
      "name": "Soil_Dirt"
    },
    {
      "x": -33,
      "y": 5,
      "z": -22,
      "name": "Soil_Dirt"
    },
    {
      "x": -33,
      "y": 6,
      "z": -22,
      "name": "Soil_Dirt"
    },
    {
      "x": -33,
      "y": 7,
      "z": -22,
      "name": "Soil_Dirt"
    },
    {
      "x": -33,
      "y": 8,
      "z": -22,
      "name": "Soil_Dirt"
    },
    {
      "x": -33,
      "y": 9,
      "z": -22,
      "name": "Soil_Dirt"
    },
    {
      "x": -33,
      "y": 10,
      "z": -22,
      "name": "Soil_Dirt"
    },
    {
      "x": -33,
      "y": 11,
      "z": -22,
      "name": "Soil_Dirt"
    },
    {
      "x": -33,
      "y": 12,
      "z": -22,
      "name": "Soil_Dirt"
    },
    {
      "x": -33,
      "y": 13,
      "z": -22,
      "name": "Soil_Grass"
    },
    {
      "x": -33,
      "y": 4,
      "z": -21,
      "name": "Soil_Dirt"
    },
    {
      "x": -33,
      "y": 5,
      "z": -21,
      "name": "Soil_Dirt"
    },
    {
      "x": -33,
      "y": 6,
      "z": -21,
      "name": "Soil_Dirt"
    },
    {
      "x": -33,
      "y": 7,
      "z": -21,
      "name": "Soil_Dirt"
    },
    {
      "x": -33,
      "y": 8,
      "z": -21,
      "name": "Soil_Dirt"
    },
    {
      "x": -33,
      "y": 9,
      "z": -21,
      "name": "Soil_Dirt"
    },
    {
      "x": -33,
      "y": 10,
      "z": -21,
      "name": "Soil_Dirt"
    },
    {
      "x": -33,
      "y": 11,
      "z": -21,
      "name": "Soil_Dirt"
    },
    {
      "x": -33,
      "y": 12,
      "z": -21,
      "name": "Soil_Dirt"
    },
    {
      "x": -33,
      "y": 13,
      "z": -21,
      "name": "Soil_Grass"
    },
    {
      "x": -33,
      "y": 4,
      "z": -20,
      "name": "Soil_Dirt"
    },
    {
      "x": -33,
      "y": 5,
      "z": -20,
      "name": "Soil_Dirt"
    },
    {
      "x": -33,
      "y": 6,
      "z": -20,
      "name": "Soil_Dirt"
    },
    {
      "x": -33,
      "y": 7,
      "z": -20,
      "name": "Soil_Dirt"
    },
    {
      "x": -33,
      "y": 8,
      "z": -20,
      "name": "Soil_Dirt"
    },
    {
      "x": -33,
      "y": 9,
      "z": -20,
      "name": "Soil_Dirt"
    },
    {
      "x": -33,
      "y": 10,
      "z": -20,
      "name": "Soil_Dirt"
    },
    {
      "x": -33,
      "y": 11,
      "z": -20,
      "name": "Soil_Dirt"
    },
    {
      "x": -33,
      "y": 12,
      "z": -20,
      "name": "Soil_Dirt"
    },
    {
      "x": -33,
      "y": 13,
      "z": -20,
      "name": "Soil_Grass"
    },
    {
      "x": -33,
      "y": 14,
      "z": -20,
      "name": "Plant_Grass_Jungle_Tall",
      "support": 15
    },
    {
      "x": -33,
      "y": 4,
      "z": -19,
      "name": "Soil_Dirt"
    },
    {
      "x": -33,
      "y": 5,
      "z": -19,
      "name": "Soil_Dirt"
    },
    {
      "x": -33,
      "y": 6,
      "z": -19,
      "name": "Soil_Dirt"
    },
    {
      "x": -33,
      "y": 7,
      "z": -19,
      "name": "Soil_Dirt"
    },
    {
      "x": -33,
      "y": 8,
      "z": -19,
      "name": "Soil_Dirt"
    },
    {
      "x": -33,
      "y": 9,
      "z": -19,
      "name": "Soil_Dirt"
    },
    {
      "x": -33,
      "y": 10,
      "z": -19,
      "name": "Soil_Dirt"
    },
    {
      "x": -33,
      "y": 11,
      "z": -19,
      "name": "Soil_Dirt"
    },
    {
      "x": -33,
      "y": 12,
      "z": -19,
      "name": "Soil_Dirt"
    },
    {
      "x": -33,
      "y": 13,
      "z": -19,
      "name": "Soil_Grass"
    },
    {
      "x": -33,
      "y": 14,
      "z": -19,
      "name": "Plant_Grass_Jungle_Tall",
      "support": 15
    },
    {
      "x": -33,
      "y": 4,
      "z": -18,
      "name": "Soil_Dirt"
    },
    {
      "x": -33,
      "y": 5,
      "z": -18,
      "name": "Soil_Dirt"
    },
    {
      "x": -33,
      "y": 6,
      "z": -18,
      "name": "Soil_Dirt"
    },
    {
      "x": -33,
      "y": 7,
      "z": -18,
      "name": "Soil_Dirt"
    },
    {
      "x": -33,
      "y": 8,
      "z": -18,
      "name": "Soil_Dirt"
    },
    {
      "x": -33,
      "y": 9,
      "z": -18,
      "name": "Soil_Dirt"
    },
    {
      "x": -33,
      "y": 10,
      "z": -18,
      "name": "Soil_Dirt"
    },
    {
      "x": -33,
      "y": 11,
      "z": -18,
      "name": "Soil_Dirt"
    },
    {
      "x": -33,
      "y": 12,
      "z": -18,
      "name": "Soil_Dirt"
    },
    {
      "x": -33,
      "y": 13,
      "z": -18,
      "name": "Soil_Grass"
    },
    {
      "x": -33,
      "y": 4,
      "z": -17,
      "name": "Soil_Dirt"
    },
    {
      "x": -33,
      "y": 5,
      "z": -17,
      "name": "Soil_Dirt"
    },
    {
      "x": -33,
      "y": 6,
      "z": -17,
      "name": "Soil_Dirt"
    },
    {
      "x": -33,
      "y": 7,
      "z": -17,
      "name": "Soil_Dirt"
    },
    {
      "x": -33,
      "y": 8,
      "z": -17,
      "name": "Soil_Dirt"
    },
    {
      "x": -33,
      "y": 9,
      "z": -17,
      "name": "Soil_Dirt"
    },
    {
      "x": -33,
      "y": 10,
      "z": -17,
      "name": "Soil_Dirt"
    },
    {
      "x": -33,
      "y": 11,
      "z": -17,
      "name": "Soil_Dirt"
    },
    {
      "x": -33,
      "y": 12,
      "z": -17,
      "name": "Soil_Dirt"
    },
    {
      "x": -33,
      "y": 13,
      "z": -17,
      "name": "Soil_Grass"
    },
    {
      "x": -33,
      "y": 4,
      "z": -16,
      "name": "Soil_Dirt"
    },
    {
      "x": -33,
      "y": 5,
      "z": -16,
      "name": "Soil_Dirt"
    },
    {
      "x": -33,
      "y": 6,
      "z": -16,
      "name": "Soil_Dirt"
    },
    {
      "x": -33,
      "y": 7,
      "z": -16,
      "name": "Soil_Dirt"
    },
    {
      "x": -33,
      "y": 8,
      "z": -16,
      "name": "Soil_Dirt"
    },
    {
      "x": -33,
      "y": 9,
      "z": -16,
      "name": "Soil_Dirt"
    },
    {
      "x": -33,
      "y": 10,
      "z": -16,
      "name": "Soil_Dirt"
    },
    {
      "x": -33,
      "y": 11,
      "z": -16,
      "name": "Soil_Dirt"
    },
    {
      "x": -33,
      "y": 12,
      "z": -16,
      "name": "Soil_Dirt"
    },
    {
      "x": -33,
      "y": 13,
      "z": -16,
      "name": "Soil_Grass"
    },
    {
      "x": -33,
      "y": 14,
      "z": -16,
      "name": "Plant_Grass_Sharp_Wild",
      "support": 15
    },
    {
      "x": -33,
      "y": 15,
      "z": -16,
      "name": "Plant_Grass_Sharp_Wild",
      "filler": 1024
    },
    {
      "x": -33,
      "y": 4,
      "z": -15,
      "name": "Soil_Dirt"
    },
    {
      "x": -33,
      "y": 5,
      "z": -15,
      "name": "Soil_Dirt"
    },
    {
      "x": -33,
      "y": 6,
      "z": -15,
      "name": "Soil_Dirt"
    },
    {
      "x": -33,
      "y": 7,
      "z": -15,
      "name": "Soil_Dirt"
    },
    {
      "x": -33,
      "y": 8,
      "z": -15,
      "name": "Soil_Dirt"
    },
    {
      "x": -33,
      "y": 9,
      "z": -15,
      "name": "Soil_Dirt"
    },
    {
      "x": -33,
      "y": 10,
      "z": -15,
      "name": "Soil_Dirt"
    },
    {
      "x": -33,
      "y": 11,
      "z": -15,
      "name": "Soil_Dirt"
    },
    {
      "x": -33,
      "y": 12,
      "z": -15,
      "name": "Soil_Dirt"
    },
    {
      "x": -33,
      "y": 13,
      "z": -15,
      "name": "Soil_Grass"
    },
    {
      "x": -33,
      "y": 4,
      "z": -14,
      "name": "Soil_Dirt"
    },
    {
      "x": -33,
      "y": 5,
      "z": -14,
      "name": "Soil_Dirt"
    },
    {
      "x": -33,
      "y": 6,
      "z": -14,
      "name": "Soil_Dirt"
    },
    {
      "x": -33,
      "y": 7,
      "z": -14,
      "name": "Soil_Dirt"
    },
    {
      "x": -33,
      "y": 8,
      "z": -14,
      "name": "Soil_Dirt"
    },
    {
      "x": -33,
      "y": 9,
      "z": -14,
      "name": "Soil_Dirt"
    },
    {
      "x": -33,
      "y": 10,
      "z": -14,
      "name": "Soil_Dirt"
    },
    {
      "x": -33,
      "y": 11,
      "z": -14,
      "name": "Soil_Dirt"
    },
    {
      "x": -33,
      "y": 12,
      "z": -14,
      "name": "Soil_Dirt"
    },
    {
      "x": -33,
      "y": 13,
      "z": -14,
      "name": "Soil_Grass"
    },
    {
      "x": -33,
      "y": 4,
      "z": -13,
      "name": "Soil_Dirt"
    },
    {
      "x": -33,
      "y": 5,
      "z": -13,
      "name": "Soil_Dirt"
    },
    {
      "x": -33,
      "y": 6,
      "z": -13,
      "name": "Soil_Dirt"
    },
    {
      "x": -33,
      "y": 7,
      "z": -13,
      "name": "Soil_Dirt"
    },
    {
      "x": -33,
      "y": 8,
      "z": -13,
      "name": "Soil_Dirt"
    },
    {
      "x": -33,
      "y": 9,
      "z": -13,
      "name": "Soil_Dirt"
    },
    {
      "x": -33,
      "y": 10,
      "z": -13,
      "name": "Soil_Dirt"
    },
    {
      "x": -33,
      "y": 11,
      "z": -13,
      "name": "Soil_Dirt"
    },
    {
      "x": -33,
      "y": 12,
      "z": -13,
      "name": "Soil_Dirt"
    },
    {
      "x": -33,
      "y": 13,
      "z": -13,
      "name": "Soil_Grass"
    },
    {
      "x": -32,
      "y": 4,
      "z": -27,
      "name": "Soil_Dirt"
    },
    {
      "x": -32,
      "y": 5,
      "z": -27,
      "name": "Soil_Dirt"
    },
    {
      "x": -32,
      "y": 6,
      "z": -27,
      "name": "Soil_Dirt"
    },
    {
      "x": -32,
      "y": 7,
      "z": -27,
      "name": "Soil_Dirt"
    },
    {
      "x": -32,
      "y": 8,
      "z": -27,
      "name": "Soil_Dirt"
    },
    {
      "x": -32,
      "y": 9,
      "z": -27,
      "name": "Soil_Dirt"
    },
    {
      "x": -32,
      "y": 10,
      "z": -27,
      "name": "Soil_Dirt"
    },
    {
      "x": -32,
      "y": 11,
      "z": -27,
      "name": "Soil_Dirt"
    },
    {
      "x": -32,
      "y": 12,
      "z": -27,
      "name": "Soil_Dirt"
    },
    {
      "x": -32,
      "y": 13,
      "z": -27,
      "name": "Soil_Grass"
    },
    {
      "x": -32,
      "y": 4,
      "z": -26,
      "name": "Soil_Dirt"
    },
    {
      "x": -32,
      "y": 5,
      "z": -26,
      "name": "Soil_Dirt"
    },
    {
      "x": -32,
      "y": 6,
      "z": -26,
      "name": "Soil_Dirt"
    },
    {
      "x": -32,
      "y": 7,
      "z": -26,
      "name": "Soil_Dirt"
    },
    {
      "x": -32,
      "y": 8,
      "z": -26,
      "name": "Soil_Dirt"
    },
    {
      "x": -32,
      "y": 9,
      "z": -26,
      "name": "Soil_Dirt"
    },
    {
      "x": -32,
      "y": 10,
      "z": -26,
      "name": "Soil_Dirt"
    },
    {
      "x": -32,
      "y": 11,
      "z": -26,
      "name": "Soil_Dirt"
    },
    {
      "x": -32,
      "y": 12,
      "z": -26,
      "name": "Soil_Dirt"
    },
    {
      "x": -32,
      "y": 13,
      "z": -26,
      "name": "Soil_Grass"
    },
    {
      "x": -32,
      "y": 4,
      "z": -25,
      "name": "Soil_Dirt"
    },
    {
      "x": -32,
      "y": 5,
      "z": -25,
      "name": "Soil_Dirt"
    },
    {
      "x": -32,
      "y": 6,
      "z": -25,
      "name": "Soil_Dirt"
    },
    {
      "x": -32,
      "y": 7,
      "z": -25,
      "name": "Soil_Dirt"
    },
    {
      "x": -32,
      "y": 8,
      "z": -25,
      "name": "Soil_Dirt"
    },
    {
      "x": -32,
      "y": 9,
      "z": -25,
      "name": "Soil_Dirt"
    },
    {
      "x": -32,
      "y": 10,
      "z": -25,
      "name": "Soil_Dirt"
    },
    {
      "x": -32,
      "y": 11,
      "z": -25,
      "name": "Soil_Dirt"
    },
    {
      "x": -32,
      "y": 12,
      "z": -25,
      "name": "Soil_Dirt"
    },
    {
      "x": -32,
      "y": 13,
      "z": -25,
      "name": "Soil_Grass"
    },
    {
      "x": -32,
      "y": 4,
      "z": -24,
      "name": "Soil_Dirt"
    },
    {
      "x": -32,
      "y": 5,
      "z": -24,
      "name": "Soil_Dirt"
    },
    {
      "x": -32,
      "y": 6,
      "z": -24,
      "name": "Soil_Dirt"
    },
    {
      "x": -32,
      "y": 7,
      "z": -24,
      "name": "Soil_Dirt"
    },
    {
      "x": -32,
      "y": 8,
      "z": -24,
      "name": "Soil_Dirt"
    },
    {
      "x": -32,
      "y": 9,
      "z": -24,
      "name": "Soil_Dirt"
    },
    {
      "x": -32,
      "y": 10,
      "z": -24,
      "name": "Soil_Dirt"
    },
    {
      "x": -32,
      "y": 11,
      "z": -24,
      "name": "Soil_Dirt"
    },
    {
      "x": -32,
      "y": 12,
      "z": -24,
      "name": "Soil_Dirt"
    },
    {
      "x": -32,
      "y": 13,
      "z": -24,
      "name": "Soil_Grass"
    },
    {
      "x": -32,
      "y": 4,
      "z": -23,
      "name": "Soil_Dirt"
    },
    {
      "x": -32,
      "y": 5,
      "z": -23,
      "name": "Soil_Dirt"
    },
    {
      "x": -32,
      "y": 6,
      "z": -23,
      "name": "Soil_Dirt"
    },
    {
      "x": -32,
      "y": 7,
      "z": -23,
      "name": "Soil_Dirt"
    },
    {
      "x": -32,
      "y": 8,
      "z": -23,
      "name": "Soil_Dirt"
    },
    {
      "x": -32,
      "y": 9,
      "z": -23,
      "name": "Soil_Dirt"
    },
    {
      "x": -32,
      "y": 10,
      "z": -23,
      "name": "Soil_Dirt"
    },
    {
      "x": -32,
      "y": 11,
      "z": -23,
      "name": "Soil_Dirt"
    },
    {
      "x": -32,
      "y": 12,
      "z": -23,
      "name": "Soil_Dirt"
    },
    {
      "x": -32,
      "y": 13,
      "z": -23,
      "name": "Soil_Grass"
    },
    {
      "x": -32,
      "y": 4,
      "z": -22,
      "name": "Soil_Dirt"
    },
    {
      "x": -32,
      "y": 5,
      "z": -22,
      "name": "Soil_Dirt"
    },
    {
      "x": -32,
      "y": 6,
      "z": -22,
      "name": "Soil_Dirt"
    },
    {
      "x": -32,
      "y": 7,
      "z": -22,
      "name": "Soil_Dirt"
    },
    {
      "x": -32,
      "y": 8,
      "z": -22,
      "name": "Soil_Dirt"
    },
    {
      "x": -32,
      "y": 9,
      "z": -22,
      "name": "Soil_Dirt"
    },
    {
      "x": -32,
      "y": 10,
      "z": -22,
      "name": "Soil_Dirt"
    },
    {
      "x": -32,
      "y": 11,
      "z": -22,
      "name": "Soil_Dirt"
    },
    {
      "x": -32,
      "y": 12,
      "z": -22,
      "name": "Soil_Dirt"
    },
    {
      "x": -32,
      "y": 13,
      "z": -22,
      "name": "Soil_Grass"
    },
    {
      "x": -32,
      "y": 4,
      "z": -21,
      "name": "Soil_Dirt"
    },
    {
      "x": -32,
      "y": 5,
      "z": -21,
      "name": "Soil_Dirt"
    },
    {
      "x": -32,
      "y": 6,
      "z": -21,
      "name": "Soil_Dirt"
    },
    {
      "x": -32,
      "y": 7,
      "z": -21,
      "name": "Soil_Dirt"
    },
    {
      "x": -32,
      "y": 8,
      "z": -21,
      "name": "Soil_Dirt"
    },
    {
      "x": -32,
      "y": 9,
      "z": -21,
      "name": "Soil_Dirt"
    },
    {
      "x": -32,
      "y": 10,
      "z": -21,
      "name": "Soil_Dirt"
    },
    {
      "x": -32,
      "y": 11,
      "z": -21,
      "name": "Soil_Dirt"
    },
    {
      "x": -32,
      "y": 12,
      "z": -21,
      "name": "Soil_Grass"
    },
    {
      "x": -32,
      "y": 14,
      "z": -21,
      "name": "Soil_Grass"
    },
    {
      "x": -32,
      "y": 4,
      "z": -20,
      "name": "Soil_Dirt"
    },
    {
      "x": -32,
      "y": 5,
      "z": -20,
      "name": "Soil_Dirt"
    },
    {
      "x": -32,
      "y": 6,
      "z": -20,
      "name": "Soil_Dirt"
    },
    {
      "x": -32,
      "y": 7,
      "z": -20,
      "name": "Soil_Dirt"
    },
    {
      "x": -32,
      "y": 8,
      "z": -20,
      "name": "Soil_Dirt"
    },
    {
      "x": -32,
      "y": 9,
      "z": -20,
      "name": "Soil_Dirt"
    },
    {
      "x": -32,
      "y": 10,
      "z": -20,
      "name": "Soil_Dirt"
    },
    {
      "x": -32,
      "y": 11,
      "z": -20,
      "name": "Soil_Dirt"
    },
    {
      "x": -32,
      "y": 12,
      "z": -20,
      "name": "Soil_Grass"
    },
    {
      "x": -32,
      "y": 14,
      "z": -20,
      "name": "Soil_Grass"
    },
    {
      "x": -32,
      "y": 4,
      "z": -19,
      "name": "Soil_Dirt"
    },
    {
      "x": -32,
      "y": 5,
      "z": -19,
      "name": "Soil_Dirt"
    },
    {
      "x": -32,
      "y": 6,
      "z": -19,
      "name": "Soil_Dirt"
    },
    {
      "x": -32,
      "y": 7,
      "z": -19,
      "name": "Soil_Dirt"
    },
    {
      "x": -32,
      "y": 8,
      "z": -19,
      "name": "Soil_Dirt"
    },
    {
      "x": -32,
      "y": 9,
      "z": -19,
      "name": "Soil_Dirt"
    },
    {
      "x": -32,
      "y": 10,
      "z": -19,
      "name": "Soil_Dirt"
    },
    {
      "x": -32,
      "y": 11,
      "z": -19,
      "name": "Soil_Dirt"
    },
    {
      "x": -32,
      "y": 12,
      "z": -19,
      "name": "Soil_Grass"
    },
    {
      "x": -32,
      "y": 14,
      "z": -19,
      "name": "Soil_Grass"
    },
    {
      "x": -32,
      "y": 4,
      "z": -18,
      "name": "Soil_Dirt"
    },
    {
      "x": -32,
      "y": 5,
      "z": -18,
      "name": "Soil_Dirt"
    },
    {
      "x": -32,
      "y": 6,
      "z": -18,
      "name": "Soil_Dirt"
    },
    {
      "x": -32,
      "y": 7,
      "z": -18,
      "name": "Soil_Dirt"
    },
    {
      "x": -32,
      "y": 8,
      "z": -18,
      "name": "Soil_Dirt"
    },
    {
      "x": -32,
      "y": 9,
      "z": -18,
      "name": "Soil_Dirt"
    },
    {
      "x": -32,
      "y": 10,
      "z": -18,
      "name": "Soil_Dirt"
    },
    {
      "x": -32,
      "y": 11,
      "z": -18,
      "name": "Soil_Dirt"
    },
    {
      "x": -32,
      "y": 12,
      "z": -18,
      "name": "Soil_Grass"
    },
    {
      "x": -32,
      "y": 14,
      "z": -18,
      "name": "Soil_Grass"
    },
    {
      "x": -32,
      "y": 4,
      "z": -17,
      "name": "Soil_Dirt"
    },
    {
      "x": -32,
      "y": 5,
      "z": -17,
      "name": "Soil_Dirt"
    },
    {
      "x": -32,
      "y": 6,
      "z": -17,
      "name": "Soil_Dirt"
    },
    {
      "x": -32,
      "y": 7,
      "z": -17,
      "name": "Soil_Dirt"
    },
    {
      "x": -32,
      "y": 8,
      "z": -17,
      "name": "Soil_Dirt"
    },
    {
      "x": -32,
      "y": 9,
      "z": -17,
      "name": "Soil_Dirt"
    },
    {
      "x": -32,
      "y": 10,
      "z": -17,
      "name": "Soil_Dirt"
    },
    {
      "x": -32,
      "y": 11,
      "z": -17,
      "name": "Soil_Dirt"
    },
    {
      "x": -32,
      "y": 12,
      "z": -17,
      "name": "Soil_Grass"
    },
    {
      "x": -32,
      "y": 14,
      "z": -17,
      "name": "Soil_Grass"
    },
    {
      "x": -32,
      "y": 4,
      "z": -16,
      "name": "Soil_Dirt"
    },
    {
      "x": -32,
      "y": 5,
      "z": -16,
      "name": "Soil_Dirt"
    },
    {
      "x": -32,
      "y": 6,
      "z": -16,
      "name": "Soil_Dirt"
    },
    {
      "x": -32,
      "y": 7,
      "z": -16,
      "name": "Soil_Dirt"
    },
    {
      "x": -32,
      "y": 8,
      "z": -16,
      "name": "Soil_Dirt"
    },
    {
      "x": -32,
      "y": 9,
      "z": -16,
      "name": "Soil_Dirt"
    },
    {
      "x": -32,
      "y": 10,
      "z": -16,
      "name": "Soil_Dirt"
    },
    {
      "x": -32,
      "y": 11,
      "z": -16,
      "name": "Soil_Dirt"
    },
    {
      "x": -32,
      "y": 12,
      "z": -16,
      "name": "Soil_Dirt"
    },
    {
      "x": -32,
      "y": 13,
      "z": -16,
      "name": "Soil_Dirt"
    },
    {
      "x": -32,
      "y": 14,
      "z": -16,
      "name": "Soil_Grass"
    },
    {
      "x": -32,
      "y": 15,
      "z": -16,
      "name": "Plant_Grass_Sharp_Wild",
      "support": 15
    },
    {
      "x": -32,
      "y": 16,
      "z": -16,
      "name": "Plant_Grass_Sharp_Wild",
      "filler": 1024
    },
    {
      "x": -32,
      "y": 4,
      "z": -15,
      "name": "Soil_Dirt"
    },
    {
      "x": -32,
      "y": 5,
      "z": -15,
      "name": "Soil_Dirt"
    },
    {
      "x": -32,
      "y": 6,
      "z": -15,
      "name": "Soil_Dirt"
    },
    {
      "x": -32,
      "y": 7,
      "z": -15,
      "name": "Soil_Dirt"
    },
    {
      "x": -32,
      "y": 8,
      "z": -15,
      "name": "Soil_Dirt"
    },
    {
      "x": -32,
      "y": 9,
      "z": -15,
      "name": "Soil_Dirt"
    },
    {
      "x": -32,
      "y": 10,
      "z": -15,
      "name": "Soil_Dirt"
    },
    {
      "x": -32,
      "y": 11,
      "z": -15,
      "name": "Soil_Dirt"
    },
    {
      "x": -32,
      "y": 12,
      "z": -15,
      "name": "Soil_Dirt"
    },
    {
      "x": -32,
      "y": 13,
      "z": -15,
      "name": "Soil_Grass"
    },
    {
      "x": -32,
      "y": 4,
      "z": -14,
      "name": "Soil_Dirt"
    },
    {
      "x": -32,
      "y": 5,
      "z": -14,
      "name": "Soil_Dirt"
    },
    {
      "x": -32,
      "y": 6,
      "z": -14,
      "name": "Soil_Dirt"
    },
    {
      "x": -32,
      "y": 7,
      "z": -14,
      "name": "Soil_Dirt"
    },
    {
      "x": -32,
      "y": 8,
      "z": -14,
      "name": "Soil_Dirt"
    },
    {
      "x": -32,
      "y": 9,
      "z": -14,
      "name": "Soil_Dirt"
    },
    {
      "x": -32,
      "y": 10,
      "z": -14,
      "name": "Soil_Dirt"
    },
    {
      "x": -32,
      "y": 11,
      "z": -14,
      "name": "Soil_Dirt"
    },
    {
      "x": -32,
      "y": 12,
      "z": -14,
      "name": "Soil_Dirt"
    },
    {
      "x": -32,
      "y": 13,
      "z": -14,
      "name": "Soil_Grass"
    },
    {
      "x": -32,
      "y": 14,
      "z": -14,
      "name": "Plant_Grass_Sharp_Overgrown",
      "support": 15
    },
    {
      "x": -32,
      "y": 15,
      "z": -14,
      "name": "Plant_Grass_Sharp_Overgrown",
      "filler": 1024
    },
    {
      "x": -32,
      "y": 4,
      "z": -13,
      "name": "Soil_Dirt"
    },
    {
      "x": -32,
      "y": 5,
      "z": -13,
      "name": "Soil_Dirt"
    },
    {
      "x": -32,
      "y": 6,
      "z": -13,
      "name": "Soil_Dirt"
    },
    {
      "x": -32,
      "y": 7,
      "z": -13,
      "name": "Soil_Dirt"
    },
    {
      "x": -32,
      "y": 8,
      "z": -13,
      "name": "Soil_Dirt"
    },
    {
      "x": -32,
      "y": 9,
      "z": -13,
      "name": "Soil_Dirt"
    },
    {
      "x": -32,
      "y": 10,
      "z": -13,
      "name": "Soil_Dirt"
    },
    {
      "x": -32,
      "y": 11,
      "z": -13,
      "name": "Soil_Dirt"
    },
    {
      "x": -32,
      "y": 12,
      "z": -13,
      "name": "Soil_Dirt"
    },
    {
      "x": -32,
      "y": 13,
      "z": -13,
      "name": "Soil_Grass"
    },
    {
      "x": -32,
      "y": 4,
      "z": -12,
      "name": "Soil_Dirt"
    },
    {
      "x": -32,
      "y": 5,
      "z": -12,
      "name": "Soil_Dirt"
    },
    {
      "x": -32,
      "y": 6,
      "z": -12,
      "name": "Soil_Dirt"
    },
    {
      "x": -32,
      "y": 7,
      "z": -12,
      "name": "Soil_Dirt"
    },
    {
      "x": -32,
      "y": 8,
      "z": -12,
      "name": "Soil_Dirt"
    },
    {
      "x": -32,
      "y": 9,
      "z": -12,
      "name": "Soil_Dirt"
    },
    {
      "x": -32,
      "y": 10,
      "z": -12,
      "name": "Soil_Dirt"
    },
    {
      "x": -32,
      "y": 11,
      "z": -12,
      "name": "Soil_Dirt"
    },
    {
      "x": -32,
      "y": 12,
      "z": -12,
      "name": "Soil_Dirt"
    },
    {
      "x": -32,
      "y": 13,
      "z": -12,
      "name": "Soil_Grass"
    },
    {
      "x": -32,
      "y": 4,
      "z": -11,
      "name": "Soil_Dirt"
    },
    {
      "x": -32,
      "y": 5,
      "z": -11,
      "name": "Soil_Dirt"
    },
    {
      "x": -32,
      "y": 6,
      "z": -11,
      "name": "Soil_Dirt"
    },
    {
      "x": -32,
      "y": 7,
      "z": -11,
      "name": "Soil_Dirt"
    },
    {
      "x": -32,
      "y": 8,
      "z": -11,
      "name": "Soil_Dirt"
    },
    {
      "x": -32,
      "y": 9,
      "z": -11,
      "name": "Soil_Dirt"
    },
    {
      "x": -32,
      "y": 10,
      "z": -11,
      "name": "Soil_Dirt"
    },
    {
      "x": -32,
      "y": 11,
      "z": -11,
      "name": "Soil_Dirt"
    },
    {
      "x": -32,
      "y": 12,
      "z": -11,
      "name": "Soil_Dirt"
    },
    {
      "x": -32,
      "y": 13,
      "z": -11,
      "name": "Soil_Grass"
    },
    {
      "x": -32,
      "y": 4,
      "z": -10,
      "name": "Soil_Dirt"
    },
    {
      "x": -32,
      "y": 5,
      "z": -10,
      "name": "Soil_Dirt"
    },
    {
      "x": -32,
      "y": 6,
      "z": -10,
      "name": "Soil_Dirt"
    },
    {
      "x": -32,
      "y": 7,
      "z": -10,
      "name": "Soil_Dirt"
    },
    {
      "x": -32,
      "y": 8,
      "z": -10,
      "name": "Soil_Dirt"
    },
    {
      "x": -32,
      "y": 9,
      "z": -10,
      "name": "Soil_Dirt"
    },
    {
      "x": -32,
      "y": 10,
      "z": -10,
      "name": "Soil_Dirt"
    },
    {
      "x": -32,
      "y": 11,
      "z": -10,
      "name": "Soil_Dirt"
    },
    {
      "x": -32,
      "y": 12,
      "z": -10,
      "name": "Soil_Dirt"
    },
    {
      "x": -32,
      "y": 13,
      "z": -10,
      "name": "Soil_Grass"
    },
    {
      "x": -32,
      "y": 14,
      "z": -10,
      "name": "Plant_Grass_Sharp_Overgrown",
      "support": 15
    },
    {
      "x": -32,
      "y": 15,
      "z": -10,
      "name": "Plant_Grass_Sharp_Overgrown",
      "filler": 1024
    },
    {
      "x": -32,
      "y": 4,
      "z": -9,
      "name": "Soil_Dirt"
    },
    {
      "x": -32,
      "y": 5,
      "z": -9,
      "name": "Soil_Dirt"
    },
    {
      "x": -32,
      "y": 6,
      "z": -9,
      "name": "Soil_Dirt"
    },
    {
      "x": -32,
      "y": 7,
      "z": -9,
      "name": "Soil_Dirt"
    },
    {
      "x": -32,
      "y": 8,
      "z": -9,
      "name": "Soil_Dirt"
    },
    {
      "x": -32,
      "y": 9,
      "z": -9,
      "name": "Soil_Dirt"
    },
    {
      "x": -32,
      "y": 10,
      "z": -9,
      "name": "Soil_Dirt"
    },
    {
      "x": -32,
      "y": 11,
      "z": -9,
      "name": "Soil_Dirt"
    },
    {
      "x": -32,
      "y": 12,
      "z": -9,
      "name": "Soil_Dirt"
    },
    {
      "x": -32,
      "y": 13,
      "z": -9,
      "name": "Soil_Grass"
    },
    {
      "x": -32,
      "y": 4,
      "z": -8,
      "name": "Soil_Dirt"
    },
    {
      "x": -32,
      "y": 5,
      "z": -8,
      "name": "Soil_Dirt"
    },
    {
      "x": -32,
      "y": 6,
      "z": -8,
      "name": "Soil_Dirt"
    },
    {
      "x": -32,
      "y": 7,
      "z": -8,
      "name": "Soil_Dirt"
    },
    {
      "x": -32,
      "y": 8,
      "z": -8,
      "name": "Soil_Dirt"
    },
    {
      "x": -32,
      "y": 9,
      "z": -8,
      "name": "Soil_Dirt"
    },
    {
      "x": -32,
      "y": 10,
      "z": -8,
      "name": "Soil_Dirt"
    },
    {
      "x": -32,
      "y": 11,
      "z": -8,
      "name": "Soil_Dirt"
    },
    {
      "x": -32,
      "y": 12,
      "z": -8,
      "name": "Soil_Dirt"
    },
    {
      "x": -32,
      "y": 13,
      "z": -8,
      "name": "Soil_Grass"
    },
    {
      "x": -32,
      "y": 4,
      "z": -7,
      "name": "Soil_Dirt"
    },
    {
      "x": -32,
      "y": 5,
      "z": -7,
      "name": "Soil_Dirt"
    },
    {
      "x": -32,
      "y": 6,
      "z": -7,
      "name": "Soil_Dirt"
    },
    {
      "x": -32,
      "y": 7,
      "z": -7,
      "name": "Soil_Dirt"
    },
    {
      "x": -32,
      "y": 8,
      "z": -7,
      "name": "Soil_Dirt"
    },
    {
      "x": -32,
      "y": 9,
      "z": -7,
      "name": "Soil_Dirt"
    },
    {
      "x": -32,
      "y": 10,
      "z": -7,
      "name": "Soil_Dirt"
    },
    {
      "x": -32,
      "y": 11,
      "z": -7,
      "name": "Soil_Dirt"
    },
    {
      "x": -32,
      "y": 12,
      "z": -7,
      "name": "Soil_Grass"
    },
    {
      "x": -32,
      "y": 4,
      "z": -6,
      "name": "Soil_Dirt"
    },
    {
      "x": -32,
      "y": 5,
      "z": -6,
      "name": "Soil_Dirt"
    },
    {
      "x": -32,
      "y": 6,
      "z": -6,
      "name": "Soil_Dirt"
    },
    {
      "x": -32,
      "y": 7,
      "z": -6,
      "name": "Soil_Dirt"
    },
    {
      "x": -32,
      "y": 8,
      "z": -6,
      "name": "Soil_Dirt"
    },
    {
      "x": -32,
      "y": 9,
      "z": -6,
      "name": "Soil_Dirt"
    },
    {
      "x": -32,
      "y": 10,
      "z": -6,
      "name": "Soil_Dirt"
    },
    {
      "x": -32,
      "y": 11,
      "z": -6,
      "name": "Soil_Dirt"
    },
    {
      "x": -32,
      "y": 12,
      "z": -6,
      "name": "Soil_Grass"
    },
    {
      "x": -32,
      "y": 4,
      "z": -5,
      "name": "Soil_Dirt"
    },
    {
      "x": -32,
      "y": 5,
      "z": -5,
      "name": "Soil_Dirt"
    },
    {
      "x": -32,
      "y": 6,
      "z": -5,
      "name": "Soil_Dirt"
    },
    {
      "x": -32,
      "y": 7,
      "z": -5,
      "name": "Soil_Dirt"
    },
    {
      "x": -32,
      "y": 8,
      "z": -5,
      "name": "Soil_Dirt"
    },
    {
      "x": -32,
      "y": 9,
      "z": -5,
      "name": "Soil_Dirt"
    },
    {
      "x": -32,
      "y": 10,
      "z": -5,
      "name": "Soil_Dirt"
    },
    {
      "x": -32,
      "y": 11,
      "z": -5,
      "name": "Soil_Dirt"
    },
    {
      "x": -32,
      "y": 12,
      "z": -5,
      "name": "Soil_Grass"
    },
    {
      "x": -32,
      "y": 4,
      "z": -4,
      "name": "Soil_Dirt"
    },
    {
      "x": -32,
      "y": 5,
      "z": -4,
      "name": "Soil_Dirt"
    },
    {
      "x": -32,
      "y": 6,
      "z": -4,
      "name": "Soil_Dirt"
    },
    {
      "x": -32,
      "y": 7,
      "z": -4,
      "name": "Soil_Dirt"
    },
    {
      "x": -32,
      "y": 8,
      "z": -4,
      "name": "Soil_Dirt"
    },
    {
      "x": -32,
      "y": 9,
      "z": -4,
      "name": "Soil_Dirt"
    },
    {
      "x": -32,
      "y": 10,
      "z": -4,
      "name": "Soil_Dirt"
    },
    {
      "x": -32,
      "y": 11,
      "z": -4,
      "name": "Soil_Dirt"
    },
    {
      "x": -32,
      "y": 12,
      "z": -4,
      "name": "Soil_Grass"
    },
    {
      "x": -32,
      "y": 4,
      "z": -3,
      "name": "Soil_Dirt"
    },
    {
      "x": -32,
      "y": 5,
      "z": -3,
      "name": "Soil_Dirt"
    },
    {
      "x": -32,
      "y": 6,
      "z": -3,
      "name": "Soil_Dirt"
    },
    {
      "x": -32,
      "y": 7,
      "z": -3,
      "name": "Soil_Dirt"
    },
    {
      "x": -32,
      "y": 8,
      "z": -3,
      "name": "Soil_Dirt"
    },
    {
      "x": -32,
      "y": 9,
      "z": -3,
      "name": "Soil_Dirt"
    },
    {
      "x": -32,
      "y": 10,
      "z": -3,
      "name": "Soil_Dirt"
    },
    {
      "x": -32,
      "y": 11,
      "z": -3,
      "name": "Soil_Dirt"
    },
    {
      "x": -32,
      "y": 12,
      "z": -3,
      "name": "Soil_Grass"
    },
    {
      "x": -32,
      "y": 4,
      "z": -2,
      "name": "Soil_Dirt"
    },
    {
      "x": -32,
      "y": 5,
      "z": -2,
      "name": "Soil_Dirt"
    },
    {
      "x": -32,
      "y": 6,
      "z": -2,
      "name": "Soil_Dirt"
    },
    {
      "x": -32,
      "y": 7,
      "z": -2,
      "name": "Soil_Dirt"
    },
    {
      "x": -32,
      "y": 8,
      "z": -2,
      "name": "Soil_Dirt"
    },
    {
      "x": -32,
      "y": 9,
      "z": -2,
      "name": "Soil_Dirt"
    },
    {
      "x": -32,
      "y": 10,
      "z": -2,
      "name": "Soil_Dirt"
    },
    {
      "x": -32,
      "y": 11,
      "z": -2,
      "name": "Soil_Dirt"
    },
    {
      "x": -32,
      "y": 12,
      "z": -2,
      "name": "Soil_Grass"
    },
    {
      "x": -32,
      "y": 4,
      "z": -1,
      "name": "Soil_Dirt"
    },
    {
      "x": -32,
      "y": 5,
      "z": -1,
      "name": "Soil_Dirt"
    },
    {
      "x": -32,
      "y": 6,
      "z": -1,
      "name": "Soil_Dirt"
    },
    {
      "x": -32,
      "y": 7,
      "z": -1,
      "name": "Soil_Dirt"
    },
    {
      "x": -32,
      "y": 8,
      "z": -1,
      "name": "Soil_Dirt"
    },
    {
      "x": -32,
      "y": 9,
      "z": -1,
      "name": "Soil_Dirt"
    },
    {
      "x": -32,
      "y": 10,
      "z": -1,
      "name": "Soil_Dirt"
    },
    {
      "x": -32,
      "y": 11,
      "z": -1,
      "name": "Soil_Dirt"
    },
    {
      "x": -32,
      "y": 12,
      "z": -1,
      "name": "Soil_Dirt"
    },
    {
      "x": -32,
      "y": 13,
      "z": -1,
      "name": "Soil_Grass"
    },
    {
      "x": -32,
      "y": 4,
      "z": 0,
      "name": "Soil_Dirt"
    },
    {
      "x": -32,
      "y": 5,
      "z": 0,
      "name": "Soil_Dirt"
    },
    {
      "x": -32,
      "y": 6,
      "z": 0,
      "name": "Soil_Dirt"
    },
    {
      "x": -32,
      "y": 7,
      "z": 0,
      "name": "Soil_Dirt"
    },
    {
      "x": -32,
      "y": 8,
      "z": 0,
      "name": "Soil_Dirt"
    },
    {
      "x": -32,
      "y": 9,
      "z": 0,
      "name": "Soil_Dirt"
    },
    {
      "x": -32,
      "y": 10,
      "z": 0,
      "name": "Soil_Dirt"
    },
    {
      "x": -32,
      "y": 11,
      "z": 0,
      "name": "Soil_Dirt"
    },
    {
      "x": -32,
      "y": 12,
      "z": 0,
      "name": "Soil_Dirt"
    },
    {
      "x": -32,
      "y": 13,
      "z": 0,
      "name": "Soil_Grass"
    },
    {
      "x": -32,
      "y": 4,
      "z": 1,
      "name": "Soil_Dirt"
    },
    {
      "x": -32,
      "y": 5,
      "z": 1,
      "name": "Soil_Dirt"
    },
    {
      "x": -32,
      "y": 6,
      "z": 1,
      "name": "Soil_Dirt"
    },
    {
      "x": -32,
      "y": 7,
      "z": 1,
      "name": "Soil_Dirt"
    },
    {
      "x": -32,
      "y": 8,
      "z": 1,
      "name": "Soil_Dirt"
    },
    {
      "x": -32,
      "y": 9,
      "z": 1,
      "name": "Soil_Dirt"
    },
    {
      "x": -32,
      "y": 10,
      "z": 1,
      "name": "Soil_Dirt"
    },
    {
      "x": -32,
      "y": 11,
      "z": 1,
      "name": "Soil_Dirt"
    },
    {
      "x": -32,
      "y": 12,
      "z": 1,
      "name": "Soil_Dirt"
    },
    {
      "x": -32,
      "y": 13,
      "z": 1,
      "name": "Soil_Grass"
    },
    {
      "x": -32,
      "y": 4,
      "z": 2,
      "name": "Soil_Dirt"
    },
    {
      "x": -32,
      "y": 5,
      "z": 2,
      "name": "Soil_Dirt"
    },
    {
      "x": -32,
      "y": 6,
      "z": 2,
      "name": "Soil_Dirt"
    },
    {
      "x": -32,
      "y": 7,
      "z": 2,
      "name": "Soil_Dirt"
    },
    {
      "x": -32,
      "y": 8,
      "z": 2,
      "name": "Soil_Dirt"
    },
    {
      "x": -32,
      "y": 9,
      "z": 2,
      "name": "Soil_Dirt"
    },
    {
      "x": -32,
      "y": 10,
      "z": 2,
      "name": "Soil_Dirt"
    },
    {
      "x": -32,
      "y": 11,
      "z": 2,
      "name": "Soil_Dirt"
    },
    {
      "x": -32,
      "y": 12,
      "z": 2,
      "name": "Soil_Dirt"
    },
    {
      "x": -32,
      "y": 13,
      "z": 2,
      "name": "Soil_Grass"
    },
    {
      "x": -32,
      "y": 14,
      "z": 2,
      "name": "Plant_Grass_Sharp_Overgrown",
      "support": 15
    },
    {
      "x": -32,
      "y": 15,
      "z": 2,
      "name": "Plant_Grass_Sharp_Overgrown",
      "filler": 1024
    },
    {
      "x": -32,
      "y": 4,
      "z": 3,
      "name": "Soil_Dirt"
    },
    {
      "x": -32,
      "y": 5,
      "z": 3,
      "name": "Soil_Dirt"
    },
    {
      "x": -32,
      "y": 6,
      "z": 3,
      "name": "Soil_Dirt"
    },
    {
      "x": -32,
      "y": 7,
      "z": 3,
      "name": "Soil_Dirt"
    },
    {
      "x": -32,
      "y": 8,
      "z": 3,
      "name": "Soil_Dirt"
    },
    {
      "x": -32,
      "y": 9,
      "z": 3,
      "name": "Soil_Dirt"
    },
    {
      "x": -32,
      "y": 10,
      "z": 3,
      "name": "Soil_Dirt"
    },
    {
      "x": -32,
      "y": 11,
      "z": 3,
      "name": "Soil_Dirt"
    },
    {
      "x": -32,
      "y": 12,
      "z": 3,
      "name": "Soil_Dirt"
    },
    {
      "x": -32,
      "y": 13,
      "z": 3,
      "name": "Soil_Grass"
    },
    {
      "x": -32,
      "y": 4,
      "z": 4,
      "name": "Soil_Dirt"
    },
    {
      "x": -32,
      "y": 5,
      "z": 4,
      "name": "Soil_Dirt"
    },
    {
      "x": -32,
      "y": 6,
      "z": 4,
      "name": "Soil_Dirt"
    },
    {
      "x": -32,
      "y": 7,
      "z": 4,
      "name": "Soil_Dirt"
    },
    {
      "x": -32,
      "y": 8,
      "z": 4,
      "name": "Soil_Dirt"
    },
    {
      "x": -32,
      "y": 9,
      "z": 4,
      "name": "Soil_Dirt"
    },
    {
      "x": -32,
      "y": 10,
      "z": 4,
      "name": "Soil_Dirt"
    },
    {
      "x": -32,
      "y": 11,
      "z": 4,
      "name": "Soil_Dirt"
    },
    {
      "x": -32,
      "y": 12,
      "z": 4,
      "name": "Soil_Dirt"
    },
    {
      "x": -32,
      "y": 13,
      "z": 4,
      "name": "Soil_Grass"
    },
    {
      "x": -32,
      "y": 4,
      "z": 5,
      "name": "Soil_Dirt"
    },
    {
      "x": -32,
      "y": 5,
      "z": 5,
      "name": "Soil_Dirt"
    },
    {
      "x": -32,
      "y": 6,
      "z": 5,
      "name": "Soil_Dirt"
    },
    {
      "x": -32,
      "y": 7,
      "z": 5,
      "name": "Soil_Dirt"
    },
    {
      "x": -32,
      "y": 8,
      "z": 5,
      "name": "Soil_Dirt"
    },
    {
      "x": -32,
      "y": 9,
      "z": 5,
      "name": "Soil_Dirt"
    },
    {
      "x": -32,
      "y": 10,
      "z": 5,
      "name": "Soil_Dirt"
    },
    {
      "x": -32,
      "y": 11,
      "z": 5,
      "name": "Soil_Dirt"
    },
    {
      "x": -32,
      "y": 12,
      "z": 5,
      "name": "Soil_Grass"
    },
    {
      "x": -32,
      "y": 4,
      "z": 6,
      "name": "Soil_Dirt"
    },
    {
      "x": -32,
      "y": 5,
      "z": 6,
      "name": "Soil_Dirt"
    },
    {
      "x": -32,
      "y": 6,
      "z": 6,
      "name": "Soil_Dirt"
    },
    {
      "x": -32,
      "y": 7,
      "z": 6,
      "name": "Soil_Dirt"
    },
    {
      "x": -32,
      "y": 8,
      "z": 6,
      "name": "Soil_Dirt"
    },
    {
      "x": -32,
      "y": 9,
      "z": 6,
      "name": "Soil_Dirt"
    },
    {
      "x": -32,
      "y": 10,
      "z": 6,
      "name": "Soil_Dirt"
    },
    {
      "x": -32,
      "y": 11,
      "z": 6,
      "name": "Soil_Dirt"
    },
    {
      "x": -32,
      "y": 12,
      "z": 6,
      "name": "Soil_Grass"
    },
    {
      "x": -32,
      "y": 4,
      "z": 7,
      "name": "Soil_Dirt"
    },
    {
      "x": -32,
      "y": 5,
      "z": 7,
      "name": "Soil_Dirt"
    },
    {
      "x": -32,
      "y": 6,
      "z": 7,
      "name": "Soil_Dirt"
    },
    {
      "x": -32,
      "y": 7,
      "z": 7,
      "name": "Soil_Dirt"
    },
    {
      "x": -32,
      "y": 8,
      "z": 7,
      "name": "Soil_Dirt"
    },
    {
      "x": -32,
      "y": 9,
      "z": 7,
      "name": "Soil_Dirt"
    },
    {
      "x": -32,
      "y": 10,
      "z": 7,
      "name": "Soil_Dirt"
    },
    {
      "x": -32,
      "y": 11,
      "z": 7,
      "name": "Soil_Dirt"
    },
    {
      "x": -32,
      "y": 12,
      "z": 7,
      "name": "Soil_Grass"
    },
    {
      "x": -32,
      "y": 4,
      "z": 8,
      "name": "Soil_Dirt"
    },
    {
      "x": -32,
      "y": 5,
      "z": 8,
      "name": "Soil_Dirt"
    },
    {
      "x": -32,
      "y": 6,
      "z": 8,
      "name": "Soil_Dirt"
    },
    {
      "x": -32,
      "y": 7,
      "z": 8,
      "name": "Soil_Dirt"
    },
    {
      "x": -32,
      "y": 8,
      "z": 8,
      "name": "Soil_Dirt"
    },
    {
      "x": -32,
      "y": 9,
      "z": 8,
      "name": "Soil_Dirt"
    },
    {
      "x": -32,
      "y": 10,
      "z": 8,
      "name": "Soil_Dirt"
    },
    {
      "x": -32,
      "y": 11,
      "z": 8,
      "name": "Soil_Dirt"
    },
    {
      "x": -32,
      "y": 12,
      "z": 8,
      "name": "Soil_Grass"
    },
    {
      "x": -32,
      "y": 4,
      "z": 9,
      "name": "Soil_Dirt"
    },
    {
      "x": -32,
      "y": 5,
      "z": 9,
      "name": "Soil_Dirt"
    },
    {
      "x": -32,
      "y": 6,
      "z": 9,
      "name": "Soil_Dirt"
    },
    {
      "x": -32,
      "y": 7,
      "z": 9,
      "name": "Soil_Dirt"
    },
    {
      "x": -32,
      "y": 8,
      "z": 9,
      "name": "Soil_Dirt"
    },
    {
      "x": -32,
      "y": 9,
      "z": 9,
      "name": "Soil_Dirt"
    },
    {
      "x": -32,
      "y": 10,
      "z": 9,
      "name": "Soil_Dirt"
    },
    {
      "x": -32,
      "y": 11,
      "z": 9,
      "name": "Soil_Dirt"
    },
    {
      "x": -32,
      "y": 12,
      "z": 9,
      "name": "Soil_Grass"
    },
    {
      "x": -32,
      "y": 4,
      "z": 10,
      "name": "Soil_Dirt"
    },
    {
      "x": -32,
      "y": 5,
      "z": 10,
      "name": "Soil_Dirt"
    },
    {
      "x": -32,
      "y": 6,
      "z": 10,
      "name": "Soil_Dirt"
    },
    {
      "x": -32,
      "y": 7,
      "z": 10,
      "name": "Soil_Dirt"
    },
    {
      "x": -32,
      "y": 8,
      "z": 10,
      "name": "Soil_Dirt"
    },
    {
      "x": -32,
      "y": 9,
      "z": 10,
      "name": "Soil_Dirt"
    },
    {
      "x": -32,
      "y": 10,
      "z": 10,
      "name": "Soil_Dirt"
    },
    {
      "x": -32,
      "y": 11,
      "z": 10,
      "name": "Soil_Dirt"
    },
    {
      "x": -32,
      "y": 12,
      "z": 10,
      "name": "Soil_Grass"
    },
    {
      "x": -32,
      "y": 4,
      "z": 11,
      "name": "Soil_Dirt"
    },
    {
      "x": -32,
      "y": 5,
      "z": 11,
      "name": "Soil_Dirt"
    },
    {
      "x": -32,
      "y": 6,
      "z": 11,
      "name": "Soil_Dirt"
    },
    {
      "x": -32,
      "y": 7,
      "z": 11,
      "name": "Soil_Dirt"
    },
    {
      "x": -32,
      "y": 8,
      "z": 11,
      "name": "Soil_Dirt"
    },
    {
      "x": -32,
      "y": 9,
      "z": 11,
      "name": "Soil_Dirt"
    },
    {
      "x": -32,
      "y": 10,
      "z": 11,
      "name": "Soil_Dirt"
    },
    {
      "x": -32,
      "y": 11,
      "z": 11,
      "name": "Soil_Dirt"
    },
    {
      "x": -32,
      "y": 12,
      "z": 11,
      "name": "Soil_Grass"
    },
    {
      "x": -32,
      "y": 4,
      "z": 12,
      "name": "Soil_Dirt"
    },
    {
      "x": -32,
      "y": 5,
      "z": 12,
      "name": "Soil_Dirt"
    },
    {
      "x": -32,
      "y": 6,
      "z": 12,
      "name": "Soil_Dirt"
    },
    {
      "x": -32,
      "y": 7,
      "z": 12,
      "name": "Soil_Dirt"
    },
    {
      "x": -32,
      "y": 8,
      "z": 12,
      "name": "Soil_Dirt"
    },
    {
      "x": -32,
      "y": 9,
      "z": 12,
      "name": "Soil_Dirt"
    },
    {
      "x": -32,
      "y": 10,
      "z": 12,
      "name": "Soil_Dirt"
    },
    {
      "x": -32,
      "y": 11,
      "z": 12,
      "name": "Soil_Dirt"
    },
    {
      "x": -32,
      "y": 12,
      "z": 12,
      "name": "Soil_Grass"
    },
    {
      "x": -32,
      "y": 4,
      "z": 13,
      "name": "Soil_Dirt"
    },
    {
      "x": -32,
      "y": 5,
      "z": 13,
      "name": "Soil_Dirt"
    },
    {
      "x": -32,
      "y": 6,
      "z": 13,
      "name": "Soil_Dirt"
    },
    {
      "x": -32,
      "y": 7,
      "z": 13,
      "name": "Soil_Dirt"
    },
    {
      "x": -32,
      "y": 8,
      "z": 13,
      "name": "Soil_Dirt"
    },
    {
      "x": -32,
      "y": 9,
      "z": 13,
      "name": "Soil_Dirt"
    },
    {
      "x": -32,
      "y": 10,
      "z": 13,
      "name": "Soil_Dirt"
    },
    {
      "x": -32,
      "y": 11,
      "z": 13,
      "name": "Soil_Dirt"
    },
    {
      "x": -32,
      "y": 12,
      "z": 13,
      "name": "Soil_Grass"
    },
    {
      "x": -32,
      "y": 4,
      "z": 14,
      "name": "Soil_Dirt"
    },
    {
      "x": -32,
      "y": 5,
      "z": 14,
      "name": "Soil_Dirt"
    },
    {
      "x": -32,
      "y": 6,
      "z": 14,
      "name": "Soil_Dirt"
    },
    {
      "x": -32,
      "y": 7,
      "z": 14,
      "name": "Soil_Dirt"
    },
    {
      "x": -32,
      "y": 8,
      "z": 14,
      "name": "Soil_Dirt"
    },
    {
      "x": -32,
      "y": 9,
      "z": 14,
      "name": "Soil_Dirt"
    },
    {
      "x": -32,
      "y": 10,
      "z": 14,
      "name": "Soil_Dirt"
    },
    {
      "x": -32,
      "y": 11,
      "z": 14,
      "name": "Soil_Dirt"
    },
    {
      "x": -32,
      "y": 12,
      "z": 14,
      "name": "Soil_Grass"
    },
    {
      "x": -32,
      "y": 4,
      "z": 15,
      "name": "Soil_Dirt"
    },
    {
      "x": -32,
      "y": 5,
      "z": 15,
      "name": "Soil_Dirt"
    },
    {
      "x": -32,
      "y": 6,
      "z": 15,
      "name": "Soil_Dirt"
    },
    {
      "x": -32,
      "y": 7,
      "z": 15,
      "name": "Soil_Dirt"
    },
    {
      "x": -32,
      "y": 8,
      "z": 15,
      "name": "Soil_Dirt"
    },
    {
      "x": -32,
      "y": 9,
      "z": 15,
      "name": "Soil_Dirt"
    },
    {
      "x": -32,
      "y": 10,
      "z": 15,
      "name": "Soil_Dirt"
    },
    {
      "x": -32,
      "y": 11,
      "z": 15,
      "name": "Soil_Dirt"
    },
    {
      "x": -32,
      "y": 12,
      "z": 15,
      "name": "Soil_Grass"
    },
    {
      "x": -32,
      "y": 4,
      "z": 16,
      "name": "Soil_Dirt"
    },
    {
      "x": -32,
      "y": 5,
      "z": 16,
      "name": "Soil_Dirt"
    },
    {
      "x": -32,
      "y": 6,
      "z": 16,
      "name": "Soil_Dirt"
    },
    {
      "x": -32,
      "y": 7,
      "z": 16,
      "name": "Soil_Dirt"
    },
    {
      "x": -32,
      "y": 8,
      "z": 16,
      "name": "Soil_Dirt"
    },
    {
      "x": -32,
      "y": 9,
      "z": 16,
      "name": "Soil_Dirt"
    },
    {
      "x": -32,
      "y": 10,
      "z": 16,
      "name": "Soil_Dirt"
    },
    {
      "x": -32,
      "y": 11,
      "z": 16,
      "name": "Soil_Dirt"
    },
    {
      "x": -32,
      "y": 12,
      "z": 16,
      "name": "Soil_Grass"
    },
    {
      "x": -32,
      "y": 4,
      "z": 17,
      "name": "Soil_Dirt"
    },
    {
      "x": -32,
      "y": 5,
      "z": 17,
      "name": "Soil_Dirt"
    },
    {
      "x": -32,
      "y": 6,
      "z": 17,
      "name": "Soil_Dirt"
    },
    {
      "x": -32,
      "y": 7,
      "z": 17,
      "name": "Soil_Dirt"
    },
    {
      "x": -32,
      "y": 8,
      "z": 17,
      "name": "Soil_Dirt"
    },
    {
      "x": -32,
      "y": 9,
      "z": 17,
      "name": "Soil_Dirt"
    },
    {
      "x": -32,
      "y": 10,
      "z": 17,
      "name": "Soil_Dirt"
    },
    {
      "x": -32,
      "y": 11,
      "z": 17,
      "name": "Soil_Dirt"
    },
    {
      "x": -32,
      "y": 12,
      "z": 17,
      "name": "Soil_Grass"
    },
    {
      "x": -32,
      "y": 4,
      "z": 18,
      "name": "Soil_Dirt"
    },
    {
      "x": -32,
      "y": 5,
      "z": 18,
      "name": "Soil_Dirt"
    },
    {
      "x": -32,
      "y": 6,
      "z": 18,
      "name": "Soil_Dirt"
    },
    {
      "x": -32,
      "y": 7,
      "z": 18,
      "name": "Soil_Dirt"
    },
    {
      "x": -32,
      "y": 8,
      "z": 18,
      "name": "Soil_Dirt"
    },
    {
      "x": -32,
      "y": 9,
      "z": 18,
      "name": "Soil_Dirt"
    },
    {
      "x": -32,
      "y": 10,
      "z": 18,
      "name": "Soil_Dirt"
    },
    {
      "x": -32,
      "y": 11,
      "z": 18,
      "name": "Soil_Dirt"
    },
    {
      "x": -32,
      "y": 12,
      "z": 18,
      "name": "Soil_Grass"
    },
    {
      "x": -31,
      "y": 4,
      "z": -28,
      "name": "Soil_Dirt"
    },
    {
      "x": -31,
      "y": 5,
      "z": -28,
      "name": "Soil_Dirt"
    },
    {
      "x": -31,
      "y": 6,
      "z": -28,
      "name": "Soil_Dirt"
    },
    {
      "x": -31,
      "y": 7,
      "z": -28,
      "name": "Soil_Dirt"
    },
    {
      "x": -31,
      "y": 8,
      "z": -28,
      "name": "Soil_Dirt"
    },
    {
      "x": -31,
      "y": 9,
      "z": -28,
      "name": "Soil_Dirt"
    },
    {
      "x": -31,
      "y": 10,
      "z": -28,
      "name": "Soil_Dirt"
    },
    {
      "x": -31,
      "y": 11,
      "z": -28,
      "name": "Soil_Dirt"
    },
    {
      "x": -31,
      "y": 12,
      "z": -28,
      "name": "Soil_Dirt"
    },
    {
      "x": -31,
      "y": 13,
      "z": -28,
      "name": "Soil_Grass"
    },
    {
      "x": -31,
      "y": 4,
      "z": -27,
      "name": "Soil_Dirt"
    },
    {
      "x": -31,
      "y": 5,
      "z": -27,
      "name": "Soil_Dirt"
    },
    {
      "x": -31,
      "y": 6,
      "z": -27,
      "name": "Soil_Dirt"
    },
    {
      "x": -31,
      "y": 7,
      "z": -27,
      "name": "Soil_Dirt"
    },
    {
      "x": -31,
      "y": 8,
      "z": -27,
      "name": "Soil_Dirt"
    },
    {
      "x": -31,
      "y": 9,
      "z": -27,
      "name": "Soil_Dirt"
    },
    {
      "x": -31,
      "y": 10,
      "z": -27,
      "name": "Soil_Dirt"
    },
    {
      "x": -31,
      "y": 11,
      "z": -27,
      "name": "Soil_Dirt"
    },
    {
      "x": -31,
      "y": 12,
      "z": -27,
      "name": "Soil_Dirt"
    },
    {
      "x": -31,
      "y": 13,
      "z": -27,
      "name": "Soil_Grass"
    },
    {
      "x": -31,
      "y": 4,
      "z": -26,
      "name": "Soil_Dirt"
    },
    {
      "x": -31,
      "y": 5,
      "z": -26,
      "name": "Soil_Dirt"
    },
    {
      "x": -31,
      "y": 6,
      "z": -26,
      "name": "Soil_Dirt"
    },
    {
      "x": -31,
      "y": 7,
      "z": -26,
      "name": "Soil_Dirt"
    },
    {
      "x": -31,
      "y": 8,
      "z": -26,
      "name": "Soil_Dirt"
    },
    {
      "x": -31,
      "y": 9,
      "z": -26,
      "name": "Soil_Dirt"
    },
    {
      "x": -31,
      "y": 10,
      "z": -26,
      "name": "Soil_Dirt"
    },
    {
      "x": -31,
      "y": 11,
      "z": -26,
      "name": "Soil_Dirt"
    },
    {
      "x": -31,
      "y": 12,
      "z": -26,
      "name": "Soil_Grass"
    },
    {
      "x": -31,
      "y": 14,
      "z": -26,
      "name": "Soil_Grass"
    },
    {
      "x": -31,
      "y": 4,
      "z": -25,
      "name": "Soil_Dirt"
    },
    {
      "x": -31,
      "y": 5,
      "z": -25,
      "name": "Soil_Dirt"
    },
    {
      "x": -31,
      "y": 6,
      "z": -25,
      "name": "Soil_Dirt"
    },
    {
      "x": -31,
      "y": 7,
      "z": -25,
      "name": "Soil_Dirt"
    },
    {
      "x": -31,
      "y": 8,
      "z": -25,
      "name": "Soil_Dirt"
    },
    {
      "x": -31,
      "y": 9,
      "z": -25,
      "name": "Soil_Dirt"
    },
    {
      "x": -31,
      "y": 10,
      "z": -25,
      "name": "Soil_Dirt"
    },
    {
      "x": -31,
      "y": 11,
      "z": -25,
      "name": "Soil_Dirt"
    },
    {
      "x": -31,
      "y": 12,
      "z": -25,
      "name": "Soil_Grass"
    },
    {
      "x": -31,
      "y": 14,
      "z": -25,
      "name": "Soil_Grass"
    },
    {
      "x": -31,
      "y": 4,
      "z": -24,
      "name": "Soil_Dirt"
    },
    {
      "x": -31,
      "y": 5,
      "z": -24,
      "name": "Soil_Dirt"
    },
    {
      "x": -31,
      "y": 6,
      "z": -24,
      "name": "Soil_Dirt"
    },
    {
      "x": -31,
      "y": 7,
      "z": -24,
      "name": "Soil_Dirt"
    },
    {
      "x": -31,
      "y": 8,
      "z": -24,
      "name": "Soil_Dirt"
    },
    {
      "x": -31,
      "y": 9,
      "z": -24,
      "name": "Soil_Dirt"
    },
    {
      "x": -31,
      "y": 10,
      "z": -24,
      "name": "Soil_Dirt"
    },
    {
      "x": -31,
      "y": 11,
      "z": -24,
      "name": "Soil_Dirt"
    },
    {
      "x": -31,
      "y": 12,
      "z": -24,
      "name": "Soil_Grass"
    },
    {
      "x": -31,
      "y": 14,
      "z": -24,
      "name": "Soil_Grass"
    },
    {
      "x": -31,
      "y": 15,
      "z": -24,
      "name": "Plant_Grass_Jungle_Tall",
      "support": 15
    },
    {
      "x": -31,
      "y": 4,
      "z": -23,
      "name": "Soil_Dirt"
    },
    {
      "x": -31,
      "y": 5,
      "z": -23,
      "name": "Soil_Dirt"
    },
    {
      "x": -31,
      "y": 6,
      "z": -23,
      "name": "Soil_Dirt"
    },
    {
      "x": -31,
      "y": 7,
      "z": -23,
      "name": "Soil_Dirt"
    },
    {
      "x": -31,
      "y": 8,
      "z": -23,
      "name": "Soil_Dirt"
    },
    {
      "x": -31,
      "y": 9,
      "z": -23,
      "name": "Soil_Dirt"
    },
    {
      "x": -31,
      "y": 10,
      "z": -23,
      "name": "Soil_Dirt"
    },
    {
      "x": -31,
      "y": 11,
      "z": -23,
      "name": "Soil_Dirt"
    },
    {
      "x": -31,
      "y": 12,
      "z": -23,
      "name": "Soil_Grass"
    },
    {
      "x": -31,
      "y": 14,
      "z": -23,
      "name": "Soil_Grass"
    },
    {
      "x": -31,
      "y": 4,
      "z": -22,
      "name": "Soil_Dirt"
    },
    {
      "x": -31,
      "y": 5,
      "z": -22,
      "name": "Soil_Dirt"
    },
    {
      "x": -31,
      "y": 6,
      "z": -22,
      "name": "Soil_Dirt"
    },
    {
      "x": -31,
      "y": 7,
      "z": -22,
      "name": "Soil_Dirt"
    },
    {
      "x": -31,
      "y": 8,
      "z": -22,
      "name": "Soil_Dirt"
    },
    {
      "x": -31,
      "y": 9,
      "z": -22,
      "name": "Soil_Dirt"
    },
    {
      "x": -31,
      "y": 10,
      "z": -22,
      "name": "Soil_Dirt"
    },
    {
      "x": -31,
      "y": 11,
      "z": -22,
      "name": "Soil_Dirt"
    },
    {
      "x": -31,
      "y": 12,
      "z": -22,
      "name": "Soil_Grass"
    },
    {
      "x": -31,
      "y": 14,
      "z": -22,
      "name": "Soil_Grass"
    },
    {
      "x": -31,
      "y": 15,
      "z": -22,
      "name": "Plant_Grass_Sharp_Overgrown",
      "support": 15
    },
    {
      "x": -31,
      "y": 16,
      "z": -22,
      "name": "Plant_Grass_Sharp_Overgrown",
      "filler": 1024
    },
    {
      "x": -31,
      "y": 4,
      "z": -21,
      "name": "Soil_Dirt"
    },
    {
      "x": -31,
      "y": 5,
      "z": -21,
      "name": "Soil_Dirt"
    },
    {
      "x": -31,
      "y": 6,
      "z": -21,
      "name": "Soil_Dirt"
    },
    {
      "x": -31,
      "y": 7,
      "z": -21,
      "name": "Soil_Dirt"
    },
    {
      "x": -31,
      "y": 8,
      "z": -21,
      "name": "Soil_Dirt"
    },
    {
      "x": -31,
      "y": 9,
      "z": -21,
      "name": "Soil_Dirt"
    },
    {
      "x": -31,
      "y": 10,
      "z": -21,
      "name": "Soil_Dirt"
    },
    {
      "x": -31,
      "y": 11,
      "z": -21,
      "name": "Soil_Dirt"
    },
    {
      "x": -31,
      "y": 12,
      "z": -21,
      "name": "Soil_Grass"
    },
    {
      "x": -31,
      "y": 14,
      "z": -21,
      "name": "Soil_Grass"
    },
    {
      "x": -31,
      "y": 15,
      "z": -21,
      "name": "Plant_Grass_Jungle_Tall",
      "support": 15
    },
    {
      "x": -31,
      "y": 4,
      "z": -20,
      "name": "Soil_Dirt"
    },
    {
      "x": -31,
      "y": 5,
      "z": -20,
      "name": "Soil_Dirt"
    },
    {
      "x": -31,
      "y": 6,
      "z": -20,
      "name": "Soil_Dirt"
    },
    {
      "x": -31,
      "y": 7,
      "z": -20,
      "name": "Soil_Dirt"
    },
    {
      "x": -31,
      "y": 8,
      "z": -20,
      "name": "Soil_Dirt"
    },
    {
      "x": -31,
      "y": 9,
      "z": -20,
      "name": "Soil_Dirt"
    },
    {
      "x": -31,
      "y": 10,
      "z": -20,
      "name": "Soil_Dirt"
    },
    {
      "x": -31,
      "y": 11,
      "z": -20,
      "name": "Soil_Dirt"
    },
    {
      "x": -31,
      "y": 12,
      "z": -20,
      "name": "Soil_Dirt"
    },
    {
      "x": -31,
      "y": 14,
      "z": -20,
      "name": "Soil_Dirt"
    },
    {
      "x": -31,
      "y": 15,
      "z": -20,
      "name": "Soil_Grass"
    },
    {
      "x": -31,
      "y": 16,
      "z": -20,
      "name": "Plant_Grass_Sharp_Overgrown",
      "support": 15
    },
    {
      "x": -31,
      "y": 17,
      "z": -20,
      "name": "Plant_Grass_Sharp_Overgrown",
      "filler": 1024
    },
    {
      "x": -31,
      "y": 4,
      "z": -19,
      "name": "Soil_Dirt"
    },
    {
      "x": -31,
      "y": 5,
      "z": -19,
      "name": "Soil_Dirt"
    },
    {
      "x": -31,
      "y": 6,
      "z": -19,
      "name": "Soil_Dirt"
    },
    {
      "x": -31,
      "y": 7,
      "z": -19,
      "name": "Soil_Dirt"
    },
    {
      "x": -31,
      "y": 8,
      "z": -19,
      "name": "Soil_Dirt"
    },
    {
      "x": -31,
      "y": 9,
      "z": -19,
      "name": "Soil_Dirt"
    },
    {
      "x": -31,
      "y": 10,
      "z": -19,
      "name": "Soil_Dirt"
    },
    {
      "x": -31,
      "y": 11,
      "z": -19,
      "name": "Soil_Dirt"
    },
    {
      "x": -31,
      "y": 12,
      "z": -19,
      "name": "Soil_Dirt"
    },
    {
      "x": -31,
      "y": 14,
      "z": -19,
      "name": "Soil_Dirt"
    },
    {
      "x": -31,
      "y": 15,
      "z": -19,
      "name": "Soil_Grass"
    },
    {
      "x": -31,
      "y": 4,
      "z": -18,
      "name": "Soil_Dirt"
    },
    {
      "x": -31,
      "y": 5,
      "z": -18,
      "name": "Soil_Dirt"
    },
    {
      "x": -31,
      "y": 6,
      "z": -18,
      "name": "Soil_Dirt"
    },
    {
      "x": -31,
      "y": 7,
      "z": -18,
      "name": "Soil_Dirt"
    },
    {
      "x": -31,
      "y": 8,
      "z": -18,
      "name": "Soil_Dirt"
    },
    {
      "x": -31,
      "y": 9,
      "z": -18,
      "name": "Soil_Dirt"
    },
    {
      "x": -31,
      "y": 10,
      "z": -18,
      "name": "Soil_Dirt"
    },
    {
      "x": -31,
      "y": 11,
      "z": -18,
      "name": "Soil_Dirt"
    },
    {
      "x": -31,
      "y": 12,
      "z": -18,
      "name": "Soil_Dirt"
    },
    {
      "x": -31,
      "y": 14,
      "z": -18,
      "name": "Soil_Dirt"
    },
    {
      "x": -31,
      "y": 15,
      "z": -18,
      "name": "Soil_Grass"
    },
    {
      "x": -31,
      "y": 16,
      "z": -18,
      "name": "Plant_Grass_Jungle_Tall",
      "support": 15
    },
    {
      "x": -31,
      "y": 4,
      "z": -17,
      "name": "Soil_Dirt"
    },
    {
      "x": -31,
      "y": 5,
      "z": -17,
      "name": "Soil_Dirt"
    },
    {
      "x": -31,
      "y": 6,
      "z": -17,
      "name": "Soil_Dirt"
    },
    {
      "x": -31,
      "y": 7,
      "z": -17,
      "name": "Soil_Dirt"
    },
    {
      "x": -31,
      "y": 8,
      "z": -17,
      "name": "Soil_Dirt"
    },
    {
      "x": -31,
      "y": 9,
      "z": -17,
      "name": "Soil_Dirt"
    },
    {
      "x": -31,
      "y": 10,
      "z": -17,
      "name": "Soil_Dirt"
    },
    {
      "x": -31,
      "y": 11,
      "z": -17,
      "name": "Soil_Dirt"
    },
    {
      "x": -31,
      "y": 12,
      "z": -17,
      "name": "Soil_Dirt"
    },
    {
      "x": -31,
      "y": 14,
      "z": -17,
      "name": "Soil_Dirt"
    },
    {
      "x": -31,
      "y": 15,
      "z": -17,
      "name": "Soil_Grass"
    },
    {
      "x": -31,
      "y": 4,
      "z": -16,
      "name": "Soil_Dirt"
    },
    {
      "x": -31,
      "y": 5,
      "z": -16,
      "name": "Soil_Dirt"
    },
    {
      "x": -31,
      "y": 6,
      "z": -16,
      "name": "Soil_Dirt"
    },
    {
      "x": -31,
      "y": 7,
      "z": -16,
      "name": "Soil_Dirt"
    },
    {
      "x": -31,
      "y": 8,
      "z": -16,
      "name": "Soil_Dirt"
    },
    {
      "x": -31,
      "y": 9,
      "z": -16,
      "name": "Soil_Dirt"
    },
    {
      "x": -31,
      "y": 10,
      "z": -16,
      "name": "Soil_Dirt"
    },
    {
      "x": -31,
      "y": 11,
      "z": -16,
      "name": "Soil_Dirt"
    },
    {
      "x": -31,
      "y": 12,
      "z": -16,
      "name": "Soil_Grass"
    },
    {
      "x": -31,
      "y": 14,
      "z": -16,
      "name": "Soil_Dirt"
    },
    {
      "x": -31,
      "y": 15,
      "z": -16,
      "name": "Soil_Grass"
    },
    {
      "x": -31,
      "y": 4,
      "z": -15,
      "name": "Soil_Dirt"
    },
    {
      "x": -31,
      "y": 5,
      "z": -15,
      "name": "Soil_Dirt"
    },
    {
      "x": -31,
      "y": 6,
      "z": -15,
      "name": "Soil_Dirt"
    },
    {
      "x": -31,
      "y": 7,
      "z": -15,
      "name": "Soil_Dirt"
    },
    {
      "x": -31,
      "y": 8,
      "z": -15,
      "name": "Soil_Dirt"
    },
    {
      "x": -31,
      "y": 9,
      "z": -15,
      "name": "Soil_Dirt"
    },
    {
      "x": -31,
      "y": 10,
      "z": -15,
      "name": "Soil_Dirt"
    },
    {
      "x": -31,
      "y": 11,
      "z": -15,
      "name": "Soil_Dirt"
    },
    {
      "x": -31,
      "y": 12,
      "z": -15,
      "name": "Soil_Grass"
    },
    {
      "x": -31,
      "y": 14,
      "z": -15,
      "name": "Soil_Grass"
    },
    {
      "x": -31,
      "y": 4,
      "z": -14,
      "name": "Soil_Dirt"
    },
    {
      "x": -31,
      "y": 5,
      "z": -14,
      "name": "Soil_Dirt"
    },
    {
      "x": -31,
      "y": 6,
      "z": -14,
      "name": "Soil_Dirt"
    },
    {
      "x": -31,
      "y": 7,
      "z": -14,
      "name": "Soil_Dirt"
    },
    {
      "x": -31,
      "y": 8,
      "z": -14,
      "name": "Soil_Dirt"
    },
    {
      "x": -31,
      "y": 9,
      "z": -14,
      "name": "Soil_Dirt"
    },
    {
      "x": -31,
      "y": 10,
      "z": -14,
      "name": "Soil_Dirt"
    },
    {
      "x": -31,
      "y": 11,
      "z": -14,
      "name": "Soil_Dirt"
    },
    {
      "x": -31,
      "y": 12,
      "z": -14,
      "name": "Soil_Grass"
    },
    {
      "x": -31,
      "y": 14,
      "z": -14,
      "name": "Soil_Grass"
    },
    {
      "x": -31,
      "y": 4,
      "z": -13,
      "name": "Soil_Dirt"
    },
    {
      "x": -31,
      "y": 5,
      "z": -13,
      "name": "Soil_Dirt"
    },
    {
      "x": -31,
      "y": 6,
      "z": -13,
      "name": "Soil_Dirt"
    },
    {
      "x": -31,
      "y": 7,
      "z": -13,
      "name": "Soil_Dirt"
    },
    {
      "x": -31,
      "y": 8,
      "z": -13,
      "name": "Soil_Dirt"
    },
    {
      "x": -31,
      "y": 9,
      "z": -13,
      "name": "Soil_Dirt"
    },
    {
      "x": -31,
      "y": 10,
      "z": -13,
      "name": "Soil_Dirt"
    },
    {
      "x": -31,
      "y": 11,
      "z": -13,
      "name": "Soil_Dirt"
    },
    {
      "x": -31,
      "y": 12,
      "z": -13,
      "name": "Soil_Grass"
    },
    {
      "x": -31,
      "y": 14,
      "z": -13,
      "name": "Soil_Grass"
    },
    {
      "x": -31,
      "y": 4,
      "z": -12,
      "name": "Soil_Dirt"
    },
    {
      "x": -31,
      "y": 5,
      "z": -12,
      "name": "Soil_Dirt"
    },
    {
      "x": -31,
      "y": 6,
      "z": -12,
      "name": "Soil_Dirt"
    },
    {
      "x": -31,
      "y": 7,
      "z": -12,
      "name": "Soil_Dirt"
    },
    {
      "x": -31,
      "y": 8,
      "z": -12,
      "name": "Soil_Dirt"
    },
    {
      "x": -31,
      "y": 9,
      "z": -12,
      "name": "Soil_Dirt"
    },
    {
      "x": -31,
      "y": 10,
      "z": -12,
      "name": "Soil_Dirt"
    },
    {
      "x": -31,
      "y": 11,
      "z": -12,
      "name": "Soil_Dirt"
    },
    {
      "x": -31,
      "y": 12,
      "z": -12,
      "name": "Soil_Grass"
    },
    {
      "x": -31,
      "y": 14,
      "z": -12,
      "name": "Soil_Grass"
    },
    {
      "x": -31,
      "y": 15,
      "z": -12,
      "name": "Plant_Grass_Sharp_Overgrown",
      "support": 15
    },
    {
      "x": -31,
      "y": 16,
      "z": -12,
      "name": "Plant_Grass_Sharp_Overgrown",
      "filler": 1024
    },
    {
      "x": -31,
      "y": 4,
      "z": -11,
      "name": "Soil_Dirt"
    },
    {
      "x": -31,
      "y": 5,
      "z": -11,
      "name": "Soil_Dirt"
    },
    {
      "x": -31,
      "y": 6,
      "z": -11,
      "name": "Soil_Dirt"
    },
    {
      "x": -31,
      "y": 7,
      "z": -11,
      "name": "Soil_Dirt"
    },
    {
      "x": -31,
      "y": 8,
      "z": -11,
      "name": "Soil_Dirt"
    },
    {
      "x": -31,
      "y": 9,
      "z": -11,
      "name": "Soil_Dirt"
    },
    {
      "x": -31,
      "y": 10,
      "z": -11,
      "name": "Soil_Dirt"
    },
    {
      "x": -31,
      "y": 11,
      "z": -11,
      "name": "Soil_Dirt"
    },
    {
      "x": -31,
      "y": 12,
      "z": -11,
      "name": "Soil_Grass"
    },
    {
      "x": -31,
      "y": 14,
      "z": -11,
      "name": "Soil_Grass"
    },
    {
      "x": -31,
      "y": 15,
      "z": -11,
      "name": "Plant_Grass_Sharp_Overgrown",
      "support": 15
    },
    {
      "x": -31,
      "y": 16,
      "z": -11,
      "name": "Plant_Grass_Sharp_Overgrown",
      "filler": 1024
    },
    {
      "x": -31,
      "y": 4,
      "z": -10,
      "name": "Soil_Dirt"
    },
    {
      "x": -31,
      "y": 5,
      "z": -10,
      "name": "Soil_Dirt"
    },
    {
      "x": -31,
      "y": 6,
      "z": -10,
      "name": "Soil_Dirt"
    },
    {
      "x": -31,
      "y": 7,
      "z": -10,
      "name": "Soil_Dirt"
    },
    {
      "x": -31,
      "y": 8,
      "z": -10,
      "name": "Soil_Dirt"
    },
    {
      "x": -31,
      "y": 9,
      "z": -10,
      "name": "Soil_Dirt"
    },
    {
      "x": -31,
      "y": 10,
      "z": -10,
      "name": "Soil_Dirt"
    },
    {
      "x": -31,
      "y": 11,
      "z": -10,
      "name": "Soil_Dirt"
    },
    {
      "x": -31,
      "y": 12,
      "z": -10,
      "name": "Soil_Grass"
    },
    {
      "x": -31,
      "y": 14,
      "z": -10,
      "name": "Soil_Grass"
    },
    {
      "x": -31,
      "y": 4,
      "z": -9,
      "name": "Soil_Dirt"
    },
    {
      "x": -31,
      "y": 5,
      "z": -9,
      "name": "Soil_Dirt"
    },
    {
      "x": -31,
      "y": 6,
      "z": -9,
      "name": "Soil_Dirt"
    },
    {
      "x": -31,
      "y": 7,
      "z": -9,
      "name": "Soil_Dirt"
    },
    {
      "x": -31,
      "y": 8,
      "z": -9,
      "name": "Soil_Dirt"
    },
    {
      "x": -31,
      "y": 9,
      "z": -9,
      "name": "Soil_Dirt"
    },
    {
      "x": -31,
      "y": 10,
      "z": -9,
      "name": "Soil_Dirt"
    },
    {
      "x": -31,
      "y": 11,
      "z": -9,
      "name": "Soil_Dirt"
    },
    {
      "x": -31,
      "y": 12,
      "z": -9,
      "name": "Soil_Grass"
    },
    {
      "x": -31,
      "y": 14,
      "z": -9,
      "name": "Soil_Grass"
    },
    {
      "x": -31,
      "y": 4,
      "z": -8,
      "name": "Soil_Dirt"
    },
    {
      "x": -31,
      "y": 5,
      "z": -8,
      "name": "Soil_Dirt"
    },
    {
      "x": -31,
      "y": 6,
      "z": -8,
      "name": "Soil_Dirt"
    },
    {
      "x": -31,
      "y": 7,
      "z": -8,
      "name": "Soil_Dirt"
    },
    {
      "x": -31,
      "y": 8,
      "z": -8,
      "name": "Soil_Dirt"
    },
    {
      "x": -31,
      "y": 9,
      "z": -8,
      "name": "Soil_Dirt"
    },
    {
      "x": -31,
      "y": 10,
      "z": -8,
      "name": "Soil_Dirt"
    },
    {
      "x": -31,
      "y": 11,
      "z": -8,
      "name": "Soil_Dirt"
    },
    {
      "x": -31,
      "y": 12,
      "z": -8,
      "name": "Soil_Dirt"
    },
    {
      "x": -31,
      "y": 13,
      "z": -8,
      "name": "Soil_Dirt"
    },
    {
      "x": -31,
      "y": 14,
      "z": -8,
      "name": "Soil_Grass"
    },
    {
      "x": -31,
      "y": 4,
      "z": -7,
      "name": "Soil_Dirt"
    },
    {
      "x": -31,
      "y": 5,
      "z": -7,
      "name": "Soil_Dirt"
    },
    {
      "x": -31,
      "y": 6,
      "z": -7,
      "name": "Soil_Dirt"
    },
    {
      "x": -31,
      "y": 7,
      "z": -7,
      "name": "Soil_Dirt"
    },
    {
      "x": -31,
      "y": 8,
      "z": -7,
      "name": "Soil_Dirt"
    },
    {
      "x": -31,
      "y": 9,
      "z": -7,
      "name": "Soil_Dirt"
    },
    {
      "x": -31,
      "y": 10,
      "z": -7,
      "name": "Soil_Dirt"
    },
    {
      "x": -31,
      "y": 11,
      "z": -7,
      "name": "Soil_Dirt"
    },
    {
      "x": -31,
      "y": 12,
      "z": -7,
      "name": "Soil_Dirt"
    },
    {
      "x": -31,
      "y": 13,
      "z": -7,
      "name": "Soil_Grass"
    },
    {
      "x": -31,
      "y": 4,
      "z": -6,
      "name": "Soil_Dirt"
    },
    {
      "x": -31,
      "y": 5,
      "z": -6,
      "name": "Soil_Dirt"
    },
    {
      "x": -31,
      "y": 6,
      "z": -6,
      "name": "Soil_Dirt"
    },
    {
      "x": -31,
      "y": 7,
      "z": -6,
      "name": "Soil_Dirt"
    },
    {
      "x": -31,
      "y": 8,
      "z": -6,
      "name": "Soil_Dirt"
    },
    {
      "x": -31,
      "y": 9,
      "z": -6,
      "name": "Soil_Dirt"
    },
    {
      "x": -31,
      "y": 10,
      "z": -6,
      "name": "Soil_Dirt"
    },
    {
      "x": -31,
      "y": 11,
      "z": -6,
      "name": "Soil_Dirt"
    },
    {
      "x": -31,
      "y": 12,
      "z": -6,
      "name": "Soil_Dirt"
    },
    {
      "x": -31,
      "y": 13,
      "z": -6,
      "name": "Soil_Grass"
    },
    {
      "x": -31,
      "y": 4,
      "z": -5,
      "name": "Soil_Dirt"
    },
    {
      "x": -31,
      "y": 5,
      "z": -5,
      "name": "Soil_Dirt"
    },
    {
      "x": -31,
      "y": 6,
      "z": -5,
      "name": "Soil_Dirt"
    },
    {
      "x": -31,
      "y": 7,
      "z": -5,
      "name": "Soil_Dirt"
    },
    {
      "x": -31,
      "y": 8,
      "z": -5,
      "name": "Soil_Dirt"
    },
    {
      "x": -31,
      "y": 9,
      "z": -5,
      "name": "Soil_Dirt"
    },
    {
      "x": -31,
      "y": 10,
      "z": -5,
      "name": "Soil_Dirt"
    },
    {
      "x": -31,
      "y": 11,
      "z": -5,
      "name": "Soil_Dirt"
    },
    {
      "x": -31,
      "y": 12,
      "z": -5,
      "name": "Soil_Dirt"
    },
    {
      "x": -31,
      "y": 13,
      "z": -5,
      "name": "Soil_Grass"
    },
    {
      "x": -31,
      "y": 14,
      "z": -5,
      "name": "Plant_Grass_Sharp_Overgrown",
      "support": 15
    },
    {
      "x": -31,
      "y": 15,
      "z": -5,
      "name": "Plant_Grass_Sharp_Overgrown",
      "filler": 1024
    },
    {
      "x": -31,
      "y": 4,
      "z": -4,
      "name": "Soil_Dirt"
    },
    {
      "x": -31,
      "y": 5,
      "z": -4,
      "name": "Soil_Dirt"
    },
    {
      "x": -31,
      "y": 6,
      "z": -4,
      "name": "Soil_Dirt"
    },
    {
      "x": -31,
      "y": 7,
      "z": -4,
      "name": "Soil_Dirt"
    },
    {
      "x": -31,
      "y": 8,
      "z": -4,
      "name": "Soil_Dirt"
    },
    {
      "x": -31,
      "y": 9,
      "z": -4,
      "name": "Soil_Dirt"
    },
    {
      "x": -31,
      "y": 10,
      "z": -4,
      "name": "Soil_Dirt"
    },
    {
      "x": -31,
      "y": 11,
      "z": -4,
      "name": "Soil_Dirt"
    },
    {
      "x": -31,
      "y": 12,
      "z": -4,
      "name": "Soil_Dirt"
    },
    {
      "x": -31,
      "y": 13,
      "z": -4,
      "name": "Soil_Grass"
    },
    {
      "x": -31,
      "y": 14,
      "z": -4,
      "name": "Plant_Grass_Sharp_Overgrown",
      "support": 15
    },
    {
      "x": -31,
      "y": 15,
      "z": -4,
      "name": "Plant_Grass_Sharp_Overgrown",
      "filler": 1024
    },
    {
      "x": -31,
      "y": 4,
      "z": -3,
      "name": "Soil_Dirt"
    },
    {
      "x": -31,
      "y": 5,
      "z": -3,
      "name": "Soil_Dirt"
    },
    {
      "x": -31,
      "y": 6,
      "z": -3,
      "name": "Soil_Dirt"
    },
    {
      "x": -31,
      "y": 7,
      "z": -3,
      "name": "Soil_Dirt"
    },
    {
      "x": -31,
      "y": 8,
      "z": -3,
      "name": "Soil_Dirt"
    },
    {
      "x": -31,
      "y": 9,
      "z": -3,
      "name": "Soil_Dirt"
    },
    {
      "x": -31,
      "y": 10,
      "z": -3,
      "name": "Soil_Dirt"
    },
    {
      "x": -31,
      "y": 11,
      "z": -3,
      "name": "Soil_Dirt"
    },
    {
      "x": -31,
      "y": 12,
      "z": -3,
      "name": "Soil_Dirt"
    },
    {
      "x": -31,
      "y": 13,
      "z": -3,
      "name": "Soil_Grass"
    },
    {
      "x": -31,
      "y": 4,
      "z": -2,
      "name": "Soil_Dirt"
    },
    {
      "x": -31,
      "y": 5,
      "z": -2,
      "name": "Soil_Dirt"
    },
    {
      "x": -31,
      "y": 6,
      "z": -2,
      "name": "Soil_Dirt"
    },
    {
      "x": -31,
      "y": 7,
      "z": -2,
      "name": "Soil_Dirt"
    },
    {
      "x": -31,
      "y": 8,
      "z": -2,
      "name": "Soil_Dirt"
    },
    {
      "x": -31,
      "y": 9,
      "z": -2,
      "name": "Soil_Dirt"
    },
    {
      "x": -31,
      "y": 10,
      "z": -2,
      "name": "Soil_Dirt"
    },
    {
      "x": -31,
      "y": 11,
      "z": -2,
      "name": "Soil_Dirt"
    },
    {
      "x": -31,
      "y": 12,
      "z": -2,
      "name": "Soil_Dirt"
    },
    {
      "x": -31,
      "y": 13,
      "z": -2,
      "name": "Soil_Grass"
    },
    {
      "x": -31,
      "y": 4,
      "z": -1,
      "name": "Soil_Dirt"
    },
    {
      "x": -31,
      "y": 5,
      "z": -1,
      "name": "Soil_Dirt"
    },
    {
      "x": -31,
      "y": 6,
      "z": -1,
      "name": "Soil_Dirt"
    },
    {
      "x": -31,
      "y": 7,
      "z": -1,
      "name": "Soil_Dirt"
    },
    {
      "x": -31,
      "y": 8,
      "z": -1,
      "name": "Soil_Dirt"
    },
    {
      "x": -31,
      "y": 9,
      "z": -1,
      "name": "Soil_Dirt"
    },
    {
      "x": -31,
      "y": 10,
      "z": -1,
      "name": "Soil_Dirt"
    },
    {
      "x": -31,
      "y": 11,
      "z": -1,
      "name": "Soil_Dirt"
    },
    {
      "x": -31,
      "y": 12,
      "z": -1,
      "name": "Soil_Dirt"
    },
    {
      "x": -31,
      "y": 13,
      "z": -1,
      "name": "Soil_Grass"
    },
    {
      "x": -31,
      "y": 4,
      "z": 0,
      "name": "Soil_Dirt"
    },
    {
      "x": -31,
      "y": 5,
      "z": 0,
      "name": "Soil_Dirt"
    },
    {
      "x": -31,
      "y": 6,
      "z": 0,
      "name": "Soil_Dirt"
    },
    {
      "x": -31,
      "y": 7,
      "z": 0,
      "name": "Soil_Dirt"
    },
    {
      "x": -31,
      "y": 8,
      "z": 0,
      "name": "Soil_Dirt"
    },
    {
      "x": -31,
      "y": 9,
      "z": 0,
      "name": "Soil_Dirt"
    },
    {
      "x": -31,
      "y": 10,
      "z": 0,
      "name": "Soil_Dirt"
    },
    {
      "x": -31,
      "y": 11,
      "z": 0,
      "name": "Soil_Dirt"
    },
    {
      "x": -31,
      "y": 12,
      "z": 0,
      "name": "Soil_Grass"
    },
    {
      "x": -31,
      "y": 14,
      "z": 0,
      "name": "Soil_Grass"
    },
    {
      "x": -31,
      "y": 4,
      "z": 1,
      "name": "Soil_Dirt"
    },
    {
      "x": -31,
      "y": 5,
      "z": 1,
      "name": "Soil_Dirt"
    },
    {
      "x": -31,
      "y": 6,
      "z": 1,
      "name": "Soil_Dirt"
    },
    {
      "x": -31,
      "y": 7,
      "z": 1,
      "name": "Soil_Dirt"
    },
    {
      "x": -31,
      "y": 8,
      "z": 1,
      "name": "Soil_Dirt"
    },
    {
      "x": -31,
      "y": 9,
      "z": 1,
      "name": "Soil_Dirt"
    },
    {
      "x": -31,
      "y": 10,
      "z": 1,
      "name": "Soil_Dirt"
    },
    {
      "x": -31,
      "y": 11,
      "z": 1,
      "name": "Soil_Dirt"
    },
    {
      "x": -31,
      "y": 12,
      "z": 1,
      "name": "Soil_Grass"
    },
    {
      "x": -31,
      "y": 14,
      "z": 1,
      "name": "Soil_Grass"
    },
    {
      "x": -31,
      "y": 4,
      "z": 2,
      "name": "Soil_Dirt"
    },
    {
      "x": -31,
      "y": 5,
      "z": 2,
      "name": "Soil_Dirt"
    },
    {
      "x": -31,
      "y": 6,
      "z": 2,
      "name": "Soil_Dirt"
    },
    {
      "x": -31,
      "y": 7,
      "z": 2,
      "name": "Soil_Dirt"
    },
    {
      "x": -31,
      "y": 8,
      "z": 2,
      "name": "Soil_Dirt"
    },
    {
      "x": -31,
      "y": 9,
      "z": 2,
      "name": "Soil_Dirt"
    },
    {
      "x": -31,
      "y": 10,
      "z": 2,
      "name": "Soil_Dirt"
    },
    {
      "x": -31,
      "y": 11,
      "z": 2,
      "name": "Soil_Dirt"
    },
    {
      "x": -31,
      "y": 12,
      "z": 2,
      "name": "Soil_Dirt"
    },
    {
      "x": -31,
      "y": 13,
      "z": 2,
      "name": "Soil_Dirt"
    },
    {
      "x": -31,
      "y": 14,
      "z": 2,
      "name": "Soil_Grass"
    },
    {
      "x": -31,
      "y": 4,
      "z": 3,
      "name": "Soil_Dirt"
    },
    {
      "x": -31,
      "y": 5,
      "z": 3,
      "name": "Soil_Dirt"
    },
    {
      "x": -31,
      "y": 6,
      "z": 3,
      "name": "Soil_Dirt"
    },
    {
      "x": -31,
      "y": 7,
      "z": 3,
      "name": "Soil_Dirt"
    },
    {
      "x": -31,
      "y": 8,
      "z": 3,
      "name": "Soil_Dirt"
    },
    {
      "x": -31,
      "y": 9,
      "z": 3,
      "name": "Soil_Dirt"
    },
    {
      "x": -31,
      "y": 10,
      "z": 3,
      "name": "Soil_Dirt"
    },
    {
      "x": -31,
      "y": 11,
      "z": 3,
      "name": "Soil_Dirt"
    },
    {
      "x": -31,
      "y": 12,
      "z": 3,
      "name": "Soil_Dirt"
    },
    {
      "x": -31,
      "y": 13,
      "z": 3,
      "name": "Soil_Grass"
    },
    {
      "x": -31,
      "y": 4,
      "z": 4,
      "name": "Soil_Dirt"
    },
    {
      "x": -31,
      "y": 5,
      "z": 4,
      "name": "Soil_Dirt"
    },
    {
      "x": -31,
      "y": 6,
      "z": 4,
      "name": "Soil_Dirt"
    },
    {
      "x": -31,
      "y": 7,
      "z": 4,
      "name": "Soil_Dirt"
    },
    {
      "x": -31,
      "y": 8,
      "z": 4,
      "name": "Soil_Dirt"
    },
    {
      "x": -31,
      "y": 9,
      "z": 4,
      "name": "Soil_Dirt"
    },
    {
      "x": -31,
      "y": 10,
      "z": 4,
      "name": "Soil_Dirt"
    },
    {
      "x": -31,
      "y": 11,
      "z": 4,
      "name": "Soil_Dirt"
    },
    {
      "x": -31,
      "y": 12,
      "z": 4,
      "name": "Soil_Dirt"
    },
    {
      "x": -31,
      "y": 13,
      "z": 4,
      "name": "Soil_Grass"
    },
    {
      "x": -31,
      "y": 4,
      "z": 5,
      "name": "Soil_Dirt"
    },
    {
      "x": -31,
      "y": 5,
      "z": 5,
      "name": "Soil_Dirt"
    },
    {
      "x": -31,
      "y": 6,
      "z": 5,
      "name": "Soil_Dirt"
    },
    {
      "x": -31,
      "y": 7,
      "z": 5,
      "name": "Soil_Dirt"
    },
    {
      "x": -31,
      "y": 8,
      "z": 5,
      "name": "Soil_Dirt"
    },
    {
      "x": -31,
      "y": 9,
      "z": 5,
      "name": "Soil_Dirt"
    },
    {
      "x": -31,
      "y": 10,
      "z": 5,
      "name": "Soil_Dirt"
    },
    {
      "x": -31,
      "y": 11,
      "z": 5,
      "name": "Soil_Dirt"
    },
    {
      "x": -31,
      "y": 12,
      "z": 5,
      "name": "Soil_Dirt"
    },
    {
      "x": -31,
      "y": 13,
      "z": 5,
      "name": "Soil_Grass"
    },
    {
      "x": -31,
      "y": 4,
      "z": 6,
      "name": "Soil_Dirt"
    },
    {
      "x": -31,
      "y": 5,
      "z": 6,
      "name": "Soil_Dirt"
    },
    {
      "x": -31,
      "y": 6,
      "z": 6,
      "name": "Soil_Dirt"
    },
    {
      "x": -31,
      "y": 7,
      "z": 6,
      "name": "Soil_Dirt"
    },
    {
      "x": -31,
      "y": 8,
      "z": 6,
      "name": "Soil_Dirt"
    },
    {
      "x": -31,
      "y": 9,
      "z": 6,
      "name": "Soil_Dirt"
    },
    {
      "x": -31,
      "y": 10,
      "z": 6,
      "name": "Soil_Dirt"
    },
    {
      "x": -31,
      "y": 11,
      "z": 6,
      "name": "Soil_Dirt"
    },
    {
      "x": -31,
      "y": 12,
      "z": 6,
      "name": "Soil_Dirt"
    },
    {
      "x": -31,
      "y": 13,
      "z": 6,
      "name": "Soil_Grass"
    },
    {
      "x": -31,
      "y": 4,
      "z": 7,
      "name": "Soil_Dirt"
    },
    {
      "x": -31,
      "y": 5,
      "z": 7,
      "name": "Soil_Dirt"
    },
    {
      "x": -31,
      "y": 6,
      "z": 7,
      "name": "Soil_Dirt"
    },
    {
      "x": -31,
      "y": 7,
      "z": 7,
      "name": "Soil_Dirt"
    },
    {
      "x": -31,
      "y": 8,
      "z": 7,
      "name": "Soil_Dirt"
    },
    {
      "x": -31,
      "y": 9,
      "z": 7,
      "name": "Soil_Dirt"
    },
    {
      "x": -31,
      "y": 10,
      "z": 7,
      "name": "Soil_Dirt"
    },
    {
      "x": -31,
      "y": 11,
      "z": 7,
      "name": "Soil_Dirt"
    },
    {
      "x": -31,
      "y": 12,
      "z": 7,
      "name": "Soil_Dirt"
    },
    {
      "x": -31,
      "y": 13,
      "z": 7,
      "name": "Soil_Grass"
    },
    {
      "x": -31,
      "y": 14,
      "z": 7,
      "name": "Plant_Flower_Tall_Yellow"
    },
    {
      "x": -31,
      "y": 4,
      "z": 8,
      "name": "Soil_Dirt"
    },
    {
      "x": -31,
      "y": 5,
      "z": 8,
      "name": "Soil_Dirt"
    },
    {
      "x": -31,
      "y": 6,
      "z": 8,
      "name": "Soil_Dirt"
    },
    {
      "x": -31,
      "y": 7,
      "z": 8,
      "name": "Soil_Dirt"
    },
    {
      "x": -31,
      "y": 8,
      "z": 8,
      "name": "Soil_Dirt"
    },
    {
      "x": -31,
      "y": 9,
      "z": 8,
      "name": "Soil_Dirt"
    },
    {
      "x": -31,
      "y": 10,
      "z": 8,
      "name": "Soil_Dirt"
    },
    {
      "x": -31,
      "y": 11,
      "z": 8,
      "name": "Soil_Dirt"
    },
    {
      "x": -31,
      "y": 12,
      "z": 8,
      "name": "Soil_Dirt"
    },
    {
      "x": -31,
      "y": 13,
      "z": 8,
      "name": "Soil_Grass"
    },
    {
      "x": -31,
      "y": 4,
      "z": 9,
      "name": "Soil_Dirt"
    },
    {
      "x": -31,
      "y": 5,
      "z": 9,
      "name": "Soil_Dirt"
    },
    {
      "x": -31,
      "y": 6,
      "z": 9,
      "name": "Soil_Dirt"
    },
    {
      "x": -31,
      "y": 7,
      "z": 9,
      "name": "Soil_Dirt"
    },
    {
      "x": -31,
      "y": 8,
      "z": 9,
      "name": "Soil_Dirt"
    },
    {
      "x": -31,
      "y": 9,
      "z": 9,
      "name": "Soil_Dirt"
    },
    {
      "x": -31,
      "y": 10,
      "z": 9,
      "name": "Soil_Dirt"
    },
    {
      "x": -31,
      "y": 11,
      "z": 9,
      "name": "Soil_Dirt"
    },
    {
      "x": -31,
      "y": 12,
      "z": 9,
      "name": "Soil_Dirt"
    },
    {
      "x": -31,
      "y": 13,
      "z": 9,
      "name": "Soil_Grass"
    },
    {
      "x": -31,
      "y": 4,
      "z": 10,
      "name": "Soil_Dirt"
    },
    {
      "x": -31,
      "y": 5,
      "z": 10,
      "name": "Soil_Dirt"
    },
    {
      "x": -31,
      "y": 6,
      "z": 10,
      "name": "Soil_Dirt"
    },
    {
      "x": -31,
      "y": 7,
      "z": 10,
      "name": "Soil_Dirt"
    },
    {
      "x": -31,
      "y": 8,
      "z": 10,
      "name": "Soil_Dirt"
    },
    {
      "x": -31,
      "y": 9,
      "z": 10,
      "name": "Soil_Dirt"
    },
    {
      "x": -31,
      "y": 10,
      "z": 10,
      "name": "Soil_Dirt"
    },
    {
      "x": -31,
      "y": 11,
      "z": 10,
      "name": "Soil_Dirt"
    },
    {
      "x": -31,
      "y": 12,
      "z": 10,
      "name": "Soil_Dirt"
    },
    {
      "x": -31,
      "y": 13,
      "z": 10,
      "name": "Soil_Grass"
    },
    {
      "x": -31,
      "y": 4,
      "z": 11,
      "name": "Soil_Dirt"
    },
    {
      "x": -31,
      "y": 5,
      "z": 11,
      "name": "Soil_Dirt"
    },
    {
      "x": -31,
      "y": 6,
      "z": 11,
      "name": "Soil_Dirt"
    },
    {
      "x": -31,
      "y": 7,
      "z": 11,
      "name": "Soil_Dirt"
    },
    {
      "x": -31,
      "y": 8,
      "z": 11,
      "name": "Soil_Dirt"
    },
    {
      "x": -31,
      "y": 9,
      "z": 11,
      "name": "Soil_Dirt"
    },
    {
      "x": -31,
      "y": 10,
      "z": 11,
      "name": "Soil_Dirt"
    },
    {
      "x": -31,
      "y": 11,
      "z": 11,
      "name": "Soil_Dirt"
    },
    {
      "x": -31,
      "y": 12,
      "z": 11,
      "name": "Soil_Dirt"
    },
    {
      "x": -31,
      "y": 13,
      "z": 11,
      "name": "Soil_Grass"
    },
    {
      "x": -31,
      "y": 14,
      "z": 11,
      "name": "Plant_Grass_Sharp_Overgrown",
      "support": 15
    },
    {
      "x": -31,
      "y": 15,
      "z": 11,
      "name": "Plant_Grass_Sharp_Overgrown",
      "filler": 1024
    },
    {
      "x": -31,
      "y": 4,
      "z": 12,
      "name": "Soil_Dirt"
    },
    {
      "x": -31,
      "y": 5,
      "z": 12,
      "name": "Soil_Dirt"
    },
    {
      "x": -31,
      "y": 6,
      "z": 12,
      "name": "Soil_Dirt"
    },
    {
      "x": -31,
      "y": 7,
      "z": 12,
      "name": "Soil_Dirt"
    },
    {
      "x": -31,
      "y": 8,
      "z": 12,
      "name": "Soil_Dirt"
    },
    {
      "x": -31,
      "y": 9,
      "z": 12,
      "name": "Soil_Dirt"
    },
    {
      "x": -31,
      "y": 10,
      "z": 12,
      "name": "Soil_Dirt"
    },
    {
      "x": -31,
      "y": 11,
      "z": 12,
      "name": "Soil_Dirt"
    },
    {
      "x": -31,
      "y": 12,
      "z": 12,
      "name": "Soil_Dirt"
    },
    {
      "x": -31,
      "y": 13,
      "z": 12,
      "name": "Soil_Grass"
    },
    {
      "x": -31,
      "y": 4,
      "z": 13,
      "name": "Soil_Dirt"
    },
    {
      "x": -31,
      "y": 5,
      "z": 13,
      "name": "Soil_Dirt"
    },
    {
      "x": -31,
      "y": 6,
      "z": 13,
      "name": "Soil_Dirt"
    },
    {
      "x": -31,
      "y": 7,
      "z": 13,
      "name": "Soil_Dirt"
    },
    {
      "x": -31,
      "y": 8,
      "z": 13,
      "name": "Soil_Dirt"
    },
    {
      "x": -31,
      "y": 9,
      "z": 13,
      "name": "Soil_Dirt"
    },
    {
      "x": -31,
      "y": 10,
      "z": 13,
      "name": "Soil_Dirt"
    },
    {
      "x": -31,
      "y": 11,
      "z": 13,
      "name": "Soil_Dirt"
    },
    {
      "x": -31,
      "y": 12,
      "z": 13,
      "name": "Soil_Dirt"
    },
    {
      "x": -31,
      "y": 13,
      "z": 13,
      "name": "Soil_Grass"
    },
    {
      "x": -31,
      "y": 4,
      "z": 14,
      "name": "Soil_Dirt"
    },
    {
      "x": -31,
      "y": 5,
      "z": 14,
      "name": "Soil_Dirt"
    },
    {
      "x": -31,
      "y": 6,
      "z": 14,
      "name": "Soil_Dirt"
    },
    {
      "x": -31,
      "y": 7,
      "z": 14,
      "name": "Soil_Dirt"
    },
    {
      "x": -31,
      "y": 8,
      "z": 14,
      "name": "Soil_Dirt"
    },
    {
      "x": -31,
      "y": 9,
      "z": 14,
      "name": "Soil_Dirt"
    },
    {
      "x": -31,
      "y": 10,
      "z": 14,
      "name": "Soil_Dirt"
    },
    {
      "x": -31,
      "y": 11,
      "z": 14,
      "name": "Soil_Dirt"
    },
    {
      "x": -31,
      "y": 12,
      "z": 14,
      "name": "Soil_Dirt"
    },
    {
      "x": -31,
      "y": 13,
      "z": 14,
      "name": "Soil_Grass"
    },
    {
      "x": -31,
      "y": 14,
      "z": 14,
      "name": "Plant_Grass_Sharp_Overgrown",
      "support": 15
    },
    {
      "x": -31,
      "y": 15,
      "z": 14,
      "name": "Plant_Grass_Sharp_Overgrown",
      "filler": 1024
    },
    {
      "x": -31,
      "y": 4,
      "z": 15,
      "name": "Soil_Dirt"
    },
    {
      "x": -31,
      "y": 5,
      "z": 15,
      "name": "Soil_Dirt"
    },
    {
      "x": -31,
      "y": 6,
      "z": 15,
      "name": "Soil_Dirt"
    },
    {
      "x": -31,
      "y": 7,
      "z": 15,
      "name": "Soil_Dirt"
    },
    {
      "x": -31,
      "y": 8,
      "z": 15,
      "name": "Soil_Dirt"
    },
    {
      "x": -31,
      "y": 9,
      "z": 15,
      "name": "Soil_Dirt"
    },
    {
      "x": -31,
      "y": 10,
      "z": 15,
      "name": "Soil_Dirt"
    },
    {
      "x": -31,
      "y": 11,
      "z": 15,
      "name": "Soil_Dirt"
    },
    {
      "x": -31,
      "y": 12,
      "z": 15,
      "name": "Soil_Dirt"
    },
    {
      "x": -31,
      "y": 13,
      "z": 15,
      "name": "Soil_Grass"
    },
    {
      "x": -31,
      "y": 14,
      "z": 15,
      "name": "Plant_Grass_Sharp_Overgrown",
      "support": 15
    },
    {
      "x": -31,
      "y": 15,
      "z": 15,
      "name": "Plant_Grass_Sharp_Overgrown",
      "filler": 1024
    },
    {
      "x": -31,
      "y": 4,
      "z": 16,
      "name": "Soil_Dirt"
    },
    {
      "x": -31,
      "y": 5,
      "z": 16,
      "name": "Soil_Dirt"
    },
    {
      "x": -31,
      "y": 6,
      "z": 16,
      "name": "Soil_Dirt"
    },
    {
      "x": -31,
      "y": 7,
      "z": 16,
      "name": "Soil_Dirt"
    },
    {
      "x": -31,
      "y": 8,
      "z": 16,
      "name": "Soil_Dirt"
    },
    {
      "x": -31,
      "y": 9,
      "z": 16,
      "name": "Soil_Dirt"
    },
    {
      "x": -31,
      "y": 10,
      "z": 16,
      "name": "Soil_Dirt"
    },
    {
      "x": -31,
      "y": 11,
      "z": 16,
      "name": "Soil_Dirt"
    },
    {
      "x": -31,
      "y": 12,
      "z": 16,
      "name": "Soil_Dirt"
    },
    {
      "x": -31,
      "y": 13,
      "z": 16,
      "name": "Soil_Grass"
    },
    {
      "x": -31,
      "y": 14,
      "z": 16,
      "name": "Plant_Grass_Sharp_Overgrown",
      "support": 15
    },
    {
      "x": -31,
      "y": 15,
      "z": 16,
      "name": "Plant_Grass_Sharp_Overgrown",
      "filler": 1024
    },
    {
      "x": -31,
      "y": 4,
      "z": 17,
      "name": "Soil_Dirt"
    },
    {
      "x": -31,
      "y": 5,
      "z": 17,
      "name": "Soil_Dirt"
    },
    {
      "x": -31,
      "y": 6,
      "z": 17,
      "name": "Soil_Dirt"
    },
    {
      "x": -31,
      "y": 7,
      "z": 17,
      "name": "Soil_Dirt"
    },
    {
      "x": -31,
      "y": 8,
      "z": 17,
      "name": "Soil_Dirt"
    },
    {
      "x": -31,
      "y": 9,
      "z": 17,
      "name": "Soil_Dirt"
    },
    {
      "x": -31,
      "y": 10,
      "z": 17,
      "name": "Soil_Dirt"
    },
    {
      "x": -31,
      "y": 11,
      "z": 17,
      "name": "Soil_Dirt"
    },
    {
      "x": -31,
      "y": 12,
      "z": 17,
      "name": "Soil_Dirt"
    },
    {
      "x": -31,
      "y": 13,
      "z": 17,
      "name": "Soil_Grass"
    },
    {
      "x": -31,
      "y": 4,
      "z": 18,
      "name": "Soil_Dirt"
    },
    {
      "x": -31,
      "y": 5,
      "z": 18,
      "name": "Soil_Dirt"
    },
    {
      "x": -31,
      "y": 6,
      "z": 18,
      "name": "Soil_Dirt"
    },
    {
      "x": -31,
      "y": 7,
      "z": 18,
      "name": "Soil_Dirt"
    },
    {
      "x": -31,
      "y": 8,
      "z": 18,
      "name": "Soil_Dirt"
    },
    {
      "x": -31,
      "y": 9,
      "z": 18,
      "name": "Soil_Dirt"
    },
    {
      "x": -31,
      "y": 10,
      "z": 18,
      "name": "Soil_Dirt"
    },
    {
      "x": -31,
      "y": 11,
      "z": 18,
      "name": "Soil_Dirt"
    },
    {
      "x": -31,
      "y": 12,
      "z": 18,
      "name": "Soil_Dirt"
    },
    {
      "x": -31,
      "y": 13,
      "z": 18,
      "name": "Soil_Grass"
    },
    {
      "x": -31,
      "y": 13,
      "z": 19,
      "name": "Soil_Grass"
    },
    {
      "x": -30,
      "y": 4,
      "z": -28,
      "name": "Soil_Dirt"
    },
    {
      "x": -30,
      "y": 5,
      "z": -28,
      "name": "Soil_Dirt"
    },
    {
      "x": -30,
      "y": 6,
      "z": -28,
      "name": "Soil_Dirt"
    },
    {
      "x": -30,
      "y": 7,
      "z": -28,
      "name": "Soil_Dirt"
    },
    {
      "x": -30,
      "y": 8,
      "z": -28,
      "name": "Soil_Dirt"
    },
    {
      "x": -30,
      "y": 9,
      "z": -28,
      "name": "Soil_Dirt"
    },
    {
      "x": -30,
      "y": 10,
      "z": -28,
      "name": "Soil_Dirt"
    },
    {
      "x": -30,
      "y": 11,
      "z": -28,
      "name": "Soil_Dirt"
    },
    {
      "x": -30,
      "y": 12,
      "z": -28,
      "name": "Soil_Dirt"
    },
    {
      "x": -30,
      "y": 13,
      "z": -28,
      "name": "Soil_Dirt"
    },
    {
      "x": -30,
      "y": 14,
      "z": -28,
      "name": "Soil_Grass"
    },
    {
      "x": -30,
      "y": 4,
      "z": -27,
      "name": "Soil_Dirt"
    },
    {
      "x": -30,
      "y": 5,
      "z": -27,
      "name": "Soil_Dirt"
    },
    {
      "x": -30,
      "y": 6,
      "z": -27,
      "name": "Soil_Dirt"
    },
    {
      "x": -30,
      "y": 7,
      "z": -27,
      "name": "Soil_Dirt"
    },
    {
      "x": -30,
      "y": 8,
      "z": -27,
      "name": "Soil_Dirt"
    },
    {
      "x": -30,
      "y": 9,
      "z": -27,
      "name": "Soil_Dirt"
    },
    {
      "x": -30,
      "y": 10,
      "z": -27,
      "name": "Soil_Dirt"
    },
    {
      "x": -30,
      "y": 11,
      "z": -27,
      "name": "Soil_Dirt"
    },
    {
      "x": -30,
      "y": 12,
      "z": -27,
      "name": "Soil_Grass"
    },
    {
      "x": -30,
      "y": 14,
      "z": -27,
      "name": "Soil_Grass"
    },
    {
      "x": -30,
      "y": 4,
      "z": -26,
      "name": "Soil_Dirt"
    },
    {
      "x": -30,
      "y": 5,
      "z": -26,
      "name": "Soil_Dirt"
    },
    {
      "x": -30,
      "y": 6,
      "z": -26,
      "name": "Soil_Dirt"
    },
    {
      "x": -30,
      "y": 7,
      "z": -26,
      "name": "Soil_Dirt"
    },
    {
      "x": -30,
      "y": 8,
      "z": -26,
      "name": "Soil_Dirt"
    },
    {
      "x": -30,
      "y": 9,
      "z": -26,
      "name": "Soil_Dirt"
    },
    {
      "x": -30,
      "y": 10,
      "z": -26,
      "name": "Soil_Dirt"
    },
    {
      "x": -30,
      "y": 11,
      "z": -26,
      "name": "Soil_Dirt"
    },
    {
      "x": -30,
      "y": 12,
      "z": -26,
      "name": "Soil_Dirt"
    },
    {
      "x": -30,
      "y": 14,
      "z": -26,
      "name": "Soil_Grass"
    },
    {
      "x": -30,
      "y": 4,
      "z": -25,
      "name": "Soil_Dirt"
    },
    {
      "x": -30,
      "y": 5,
      "z": -25,
      "name": "Soil_Dirt"
    },
    {
      "x": -30,
      "y": 6,
      "z": -25,
      "name": "Soil_Dirt"
    },
    {
      "x": -30,
      "y": 7,
      "z": -25,
      "name": "Soil_Dirt"
    },
    {
      "x": -30,
      "y": 8,
      "z": -25,
      "name": "Soil_Dirt"
    },
    {
      "x": -30,
      "y": 9,
      "z": -25,
      "name": "Soil_Dirt"
    },
    {
      "x": -30,
      "y": 10,
      "z": -25,
      "name": "Soil_Dirt"
    },
    {
      "x": -30,
      "y": 11,
      "z": -25,
      "name": "Soil_Dirt"
    },
    {
      "x": -30,
      "y": 12,
      "z": -25,
      "name": "Soil_Dirt"
    },
    {
      "x": -30,
      "y": 15,
      "z": -25,
      "name": "Soil_Grass"
    },
    {
      "x": -30,
      "y": 4,
      "z": -24,
      "name": "Soil_Dirt"
    },
    {
      "x": -30,
      "y": 5,
      "z": -24,
      "name": "Soil_Dirt"
    },
    {
      "x": -30,
      "y": 6,
      "z": -24,
      "name": "Soil_Dirt"
    },
    {
      "x": -30,
      "y": 7,
      "z": -24,
      "name": "Soil_Dirt"
    },
    {
      "x": -30,
      "y": 8,
      "z": -24,
      "name": "Soil_Dirt"
    },
    {
      "x": -30,
      "y": 9,
      "z": -24,
      "name": "Soil_Dirt"
    },
    {
      "x": -30,
      "y": 10,
      "z": -24,
      "name": "Soil_Dirt"
    },
    {
      "x": -30,
      "y": 11,
      "z": -24,
      "name": "Soil_Dirt"
    },
    {
      "x": -30,
      "y": 12,
      "z": -24,
      "name": "Soil_Dirt"
    },
    {
      "x": -30,
      "y": 15,
      "z": -24,
      "name": "Soil_Grass"
    },
    {
      "x": -30,
      "y": 16,
      "z": -24,
      "name": "Plant_Grass_Jungle_Tall",
      "support": 15
    },
    {
      "x": -30,
      "y": 4,
      "z": -23,
      "name": "Soil_Dirt"
    },
    {
      "x": -30,
      "y": 5,
      "z": -23,
      "name": "Soil_Dirt"
    },
    {
      "x": -30,
      "y": 6,
      "z": -23,
      "name": "Soil_Dirt"
    },
    {
      "x": -30,
      "y": 7,
      "z": -23,
      "name": "Soil_Dirt"
    },
    {
      "x": -30,
      "y": 8,
      "z": -23,
      "name": "Soil_Dirt"
    },
    {
      "x": -30,
      "y": 9,
      "z": -23,
      "name": "Soil_Dirt"
    },
    {
      "x": -30,
      "y": 10,
      "z": -23,
      "name": "Soil_Dirt"
    },
    {
      "x": -30,
      "y": 11,
      "z": -23,
      "name": "Soil_Dirt"
    },
    {
      "x": -30,
      "y": 12,
      "z": -23,
      "name": "Soil_Dirt"
    },
    {
      "x": -30,
      "y": 15,
      "z": -23,
      "name": "Soil_Grass"
    },
    {
      "x": -30,
      "y": 16,
      "z": -23,
      "name": "Plant_Grass_Sharp_Overgrown",
      "support": 15
    },
    {
      "x": -30,
      "y": 17,
      "z": -23,
      "name": "Plant_Grass_Sharp_Overgrown",
      "filler": 1024
    },
    {
      "x": -30,
      "y": 4,
      "z": -22,
      "name": "Soil_Dirt"
    },
    {
      "x": -30,
      "y": 5,
      "z": -22,
      "name": "Soil_Dirt"
    },
    {
      "x": -30,
      "y": 6,
      "z": -22,
      "name": "Soil_Dirt"
    },
    {
      "x": -30,
      "y": 7,
      "z": -22,
      "name": "Soil_Dirt"
    },
    {
      "x": -30,
      "y": 8,
      "z": -22,
      "name": "Soil_Dirt"
    },
    {
      "x": -30,
      "y": 9,
      "z": -22,
      "name": "Soil_Dirt"
    },
    {
      "x": -30,
      "y": 10,
      "z": -22,
      "name": "Soil_Dirt"
    },
    {
      "x": -30,
      "y": 11,
      "z": -22,
      "name": "Soil_Dirt"
    },
    {
      "x": -30,
      "y": 12,
      "z": -22,
      "name": "Soil_Dirt"
    },
    {
      "x": -30,
      "y": 15,
      "z": -22,
      "name": "Soil_Grass"
    },
    {
      "x": -30,
      "y": 4,
      "z": -21,
      "name": "Soil_Dirt"
    },
    {
      "x": -30,
      "y": 5,
      "z": -21,
      "name": "Soil_Dirt"
    },
    {
      "x": -30,
      "y": 6,
      "z": -21,
      "name": "Soil_Dirt"
    },
    {
      "x": -30,
      "y": 7,
      "z": -21,
      "name": "Soil_Dirt"
    },
    {
      "x": -30,
      "y": 8,
      "z": -21,
      "name": "Soil_Dirt"
    },
    {
      "x": -30,
      "y": 9,
      "z": -21,
      "name": "Soil_Dirt"
    },
    {
      "x": -30,
      "y": 10,
      "z": -21,
      "name": "Soil_Dirt"
    },
    {
      "x": -30,
      "y": 11,
      "z": -21,
      "name": "Soil_Dirt"
    },
    {
      "x": -30,
      "y": 12,
      "z": -21,
      "name": "Soil_Dirt"
    },
    {
      "x": -30,
      "y": 15,
      "z": -21,
      "name": "Soil_Grass"
    },
    {
      "x": -30,
      "y": 4,
      "z": -20,
      "name": "Soil_Dirt"
    },
    {
      "x": -30,
      "y": 5,
      "z": -20,
      "name": "Soil_Dirt"
    },
    {
      "x": -30,
      "y": 6,
      "z": -20,
      "name": "Soil_Dirt"
    },
    {
      "x": -30,
      "y": 7,
      "z": -20,
      "name": "Soil_Dirt"
    },
    {
      "x": -30,
      "y": 8,
      "z": -20,
      "name": "Soil_Dirt"
    },
    {
      "x": -30,
      "y": 9,
      "z": -20,
      "name": "Soil_Dirt"
    },
    {
      "x": -30,
      "y": 10,
      "z": -20,
      "name": "Soil_Dirt"
    },
    {
      "x": -30,
      "y": 11,
      "z": -20,
      "name": "Soil_Dirt"
    },
    {
      "x": -30,
      "y": 12,
      "z": -20,
      "name": "Soil_Dirt"
    },
    {
      "x": -30,
      "y": 15,
      "z": -20,
      "name": "Soil_Dirt"
    },
    {
      "x": -30,
      "y": 16,
      "z": -20,
      "name": "Soil_Grass"
    },
    {
      "x": -30,
      "y": 17,
      "z": -20,
      "name": "Plant_Grass_Sharp_Wild",
      "support": 15
    },
    {
      "x": -30,
      "y": 18,
      "z": -20,
      "name": "Plant_Grass_Sharp_Wild",
      "filler": 1024
    },
    {
      "x": -30,
      "y": 4,
      "z": -19,
      "name": "Soil_Dirt"
    },
    {
      "x": -30,
      "y": 5,
      "z": -19,
      "name": "Soil_Dirt"
    },
    {
      "x": -30,
      "y": 6,
      "z": -19,
      "name": "Soil_Dirt"
    },
    {
      "x": -30,
      "y": 7,
      "z": -19,
      "name": "Soil_Dirt"
    },
    {
      "x": -30,
      "y": 8,
      "z": -19,
      "name": "Soil_Dirt"
    },
    {
      "x": -30,
      "y": 9,
      "z": -19,
      "name": "Soil_Dirt"
    },
    {
      "x": -30,
      "y": 10,
      "z": -19,
