{
  "version": 8,
  "blockIdVersion": 11,
  "anchorX": 0,
  "anchorY": 0,
  "anchorZ": 0,
  "blocks": [
    {
      "x": -21,
      "y": 61,
      "z": 11,
      "name": "Plant_Leaves_Beech",
      "support": 15,
      "rotation": 2
    },
    {
      "x": -21,
      "y": 62,
      "z": 11,
      "name": "Plant_Leaves_Beech",
      "support": 15,
      "rotation": 2
    },
    {
      "x": -21,
      "y": 63,
      "z": 11,
      "name": "Plant_Leaves_Beech",
      "support": 15,
      "rotation": 2
    },
    {
      "x": -21,
      "y": 63,
      "z": 12,
      "name": "Plant_Leaves_Beech",
      "support": 15,
      "rotation": 2
    },
    {
      "x": -20,
      "y": 60,
      "z": 8,
      "name": "Plant_Leaves_Beech",
      "support": 15,
      "rotation": 2
    },
    {
      "x": -20,
      "y": 61,
      "z": 10,
      "name": "Plant_Leaves_Beech",
      "support": 15,
      "rotation": 2
    },
    {
      "x": -20,
      "y": 62,
      "z": 10,
      "name": "Plant_Leaves_Beech",
      "support": 15,
      "rotation": 2
    },
    {
      "x": -20,
      "y": 63,
      "z": 10,
      "name": "Plant_Leaves_Beech",
      "support": 15,
      "rotation": 2
    },
    {
      "x": -20,
      "y": 61,
      "z": 11,
      "name": "Wood_Sallow_Branch_Corner",
      "support": 15,
      "rotation": 3
    },
    {
      "x": -20,
      "y": 62,
      "z": 11,
      "name": "Wood_Sallow_Branch_Long",
      "support": 15,
      "rotation": 2
    },
    {
      "x": -20,
      "y": 63,
      "z": 11,
      "name": "Plant_Leaves_Beech",
      "support": 15,
      "rotation": 2
    },
    {
      "x": -20,
      "y": 64,
      "z": 11,
      "name": "Plant_Leaves_Beech",
      "support": 15,
      "rotation": 2
    },
    {
      "x": -20,
      "y": 61,
      "z": 12,
      "name": "Plant_Leaves_Beech",
      "support": 15,
      "rotation": 2
    },
    {
      "x": -20,
      "y": 62,
      "z": 12,
      "name": "Plant_Leaves_Beech",
      "support": 15,
      "rotation": 2
    },
    {
      "x": -20,
      "y": 63,
      "z": 12,
      "name": "Plant_Leaves_Beech",
      "support": 15,
      "rotation": 2
    },
    {
      "x": -19,
      "y": 33,
      "z": 1,
      "name": "Furniture_Crude_Platform"
    },
    {
      "x": -19,
      "y": 34,
      "z": 1,
      "name": "*Wood_Hardwood_Fence_State_Definitions_Corner",
      "rotation": 1
    },
    {
      "x": -19,
      "y": 35,
      "z": 1,
      "name": "Wood_Hardwood_Beam"
    },
    {
      "x": -19,
      "y": 36,
      "z": 1,
      "name": "Wood_Hardwood_Beam"
    },
    {
      "x": -19,
      "y": 37,
      "z": 1,
      "name": "*Wood_Tropicalwood_Roof_State_Definitions_Corner_Left",
      "rotation": 2
    },
    {
      "x": -19,
      "y": 64,
      "z": 1,
      "name": "Plant_Leaves_Beech",
      "support": 15,
      "rotation": 2
    },
    {
      "x": -19,
      "y": 65,
      "z": 1,
      "name": "Plant_Leaves_Beech",
      "support": 15,
      "rotation": 2
    },
    {
      "x": -19,
      "y": 33,
      "z": 2,
      "name": "Furniture_Crude_Platform"
    },
    {
      "x": -19,
      "y": 34,
      "z": 2,
      "name": "Wood_Hardwood_Fence",
      "rotation": 3
    },
    {
      "x": -19,
      "y": 37,
      "z": 2,
      "name": "Wood_Tropicalwood_Roof_Hollow",
      "rotation": 3
    },
    {
      "x": -19,
      "y": 33,
      "z": 3,
      "name": "Furniture_Crude_Platform"
    },
    {
      "x": -19,
      "y": 34,
      "z": 3,
      "name": "Wood_Hardwood_Fence",
      "rotation": 3
    },
    {
      "x": -19,
      "y": 37,
      "z": 3,
      "name": "Wood_Tropicalwood_Roof_Hollow",
      "rotation": 3
    },
    {
      "x": -19,
      "y": 33,
      "z": 4,
      "name": "Furniture_Crude_Platform"
    },
    {
      "x": -19,
      "y": 34,
      "z": 4,
      "name": "Wood_Hardwood_Fence",
      "rotation": 3
    },
    {
      "x": -19,
      "y": 37,
      "z": 4,
      "name": "Wood_Tropicalwood_Roof_Hollow",
      "rotation": 3
    },
    {
      "x": -19,
      "y": 33,
      "z": 5,
      "name": "Furniture_Crude_Platform"
    },
    {
      "x": -19,
      "y": 34,
      "z": 5,
      "name": "Wood_Hardwood_Fence",
      "rotation": 3
    },
    {
      "x": -19,
      "y": 37,
      "z": 5,
      "name": "Wood_Tropicalwood_Roof_Hollow",
      "rotation": 3
    },
    {
      "x": -19,
      "y": 33,
      "z": 6,
      "name": "Furniture_Crude_Platform"
    },
    {
      "x": -19,
      "y": 34,
      "z": 6,
      "name": "Wood_Hardwood_Fence",
      "rotation": 3
    },
    {
      "x": -19,
      "y": 37,
      "z": 6,
      "name": "Wood_Tropicalwood_Roof_Hollow",
      "rotation": 3
    },
    {
      "x": -19,
      "y": 33,
      "z": 7,
      "name": "Furniture_Crude_Platform"
    },
    {
      "x": -19,
      "y": 34,
      "z": 7,
      "name": "Wood_Hardwood_Fence",
      "rotation": 3
    },
    {
      "x": -19,
      "y": 37,
      "z": 7,
      "name": "Wood_Tropicalwood_Roof_Hollow",
      "rotation": 3
    },
    {
      "x": -19,
      "y": 60,
      "z": 7,
      "name": "Plant_Leaves_Beech",
      "support": 15,
      "rotation": 2
    },
    {
      "x": -19,
      "y": 33,
      "z": 8,
      "name": "Furniture_Crude_Platform"
    },
    {
      "x": -19,
      "y": 34,
      "z": 8,
      "name": "*Wood_Hardwood_Fence_State_Definitions_Corner",
      "rotation": 2
    },
    {
      "x": -19,
      "y": 35,
      "z": 8,
      "name": "Wood_Hardwood_Beam"
    },
    {
      "x": -19,
      "y": 36,
      "z": 8,
      "name": "Wood_Hardwood_Beam"
    },
    {
      "x": -19,
      "y": 37,
      "z": 8,
      "name": "*Wood_Tropicalwood_Roof_State_Definitions_Corner_Left",
      "rotation": 3
    },
    {
      "x": -19,
      "y": 59,
      "z": 8,
      "name": "Plant_Leaves_Beech",
      "support": 15,
      "rotation": 2
    },
    {
      "x": -19,
      "y": 60,
      "z": 8,
      "name": "Plant_Leaves_Beech",
      "support": 15,
      "rotation": 2
    },
    {
      "x": -19,
      "y": 61,
      "z": 8,
      "name": "Plant_Leaves_Beech",
      "support": 15,
      "rotation": 2
    },
    {
      "x": -19,
      "y": 61,
      "z": 9,
      "name": "Plant_Leaves_Beech",
      "support": 15,
      "rotation": 2
    },
    {
      "x": -19,
      "y": 61,
      "z": 11,
      "name": "Wood_Sallow_Branch_Long",
      "support": 15,
      "rotation": 7
    },
    {
      "x": -19,
      "y": 62,
      "z": 11,
      "name": "Plant_Leaves_Beech",
      "support": 15,
      "rotation": 2
    },
    {
      "x": -19,
      "y": 63,
      "z": 11,
      "name": "Plant_Leaves_Beech",
      "support": 15,
      "rotation": 2
    },
    {
      "x": -18,
      "y": 2,
      "z": -1,
      "name": "Wood_Sallow_Roots",
      "rotation": 2
    },
    {
      "x": -18,
      "y": 3,
      "z": -1,
      "name": "Wood_Sallow_Trunk_Full",
      "support": 15,
      "rotation": 2
    },
    {
      "x": -18,
      "y": 4,
      "z": -1,
      "name": "Wood_Sallow_Trunk",
      "support": 15,
      "rotation": 2
    },
    {
      "x": -18,
      "y": 5,
      "z": -1,
      "name": "Wood_Sallow_Trunk",
      "support": 15,
      "rotation": 2
    },
    {
      "x": -18,
      "y": 6,
      "z": -1,
      "name": "Wood_Sallow_Trunk",
      "support": 15,
      "rotation": 2
    },
    {
      "x": -18,
      "y": 7,
      "z": -1,
      "name": "Wood_Sallow_Trunk",
      "support": 15,
      "rotation": 2
    },
    {
      "x": -18,
      "y": 8,
      "z": -1,
      "name": "Wood_Sallow_Trunk",
      "support": 15,
      "rotation": 2
    },
    {
      "x": -18,
      "y": 9,
      "z": -1,
      "name": "Wood_Sallow_Trunk_Full",
      "support": 15,
      "rotation": 2
    },
    {
      "x": -18,
      "y": 10,
      "z": -1,
      "name": "Plant_Moss_Rug_Green_Dark",
      "support": 15,
      "rotation": 2
    },
    {
      "x": -18,
      "y": 33,
      "z": 0,
      "name": "Furniture_Crude_Platform"
    },
    {
      "x": -18,
      "y": 34,
      "z": 0,
      "name": "*Wood_Hardwood_Fence_State_Definitions_Corner",
      "rotation": 1
    },
    {
      "x": -18,
      "y": 35,
      "z": 0,
      "name": "Wood_Hardwood_Beam"
    },
    {
      "x": -18,
      "y": 36,
      "z": 0,
      "name": "Wood_Hardwood_Beam"
    },
    {
      "x": -18,
      "y": 37,
      "z": 0,
      "name": "*Wood_Tropicalwood_Roof_State_Definitions_Corner_Left",
      "rotation": 2
    },
    {
      "x": -18,
      "y": 60,
      "z": 0,
      "name": "Plant_Leaves_Beech",
      "support": 15,
      "rotation": 2
    },
    {
      "x": -18,
      "y": 61,
      "z": 0,
      "name": "Plant_Leaves_Beech",
      "support": 15,
      "rotation": 2
    },
    {
      "x": -18,
      "y": 64,
      "z": 0,
      "name": "Plant_Leaves_Beech",
      "support": 15,
      "rotation": 2
    },
    {
      "x": -18,
      "y": 65,
      "z": 0,
      "name": "Plant_Leaves_Beech",
      "support": 15,
      "rotation": 2
    },
    {
      "x": -18,
      "y": 33,
      "z": 1,
      "name": "Furniture_Crude_Platform"
    },
    {
      "x": -18,
      "y": 34,
      "z": 1,
      "name": "*Wood_Hardwood_Fence_State_Definitions_Corner",
      "rotation": 3
    },
    {
      "x": -18,
      "y": 37,
      "z": 1,
      "name": "*Wood_Tropicalwood_Roof_Hollow_State_Definitions_Inverted_Corner_Right",
      "rotation": 3
    },
    {
      "x": -18,
      "y": 63,
      "z": 1,
      "name": "Plant_Leaves_Beech",
      "support": 15,
      "rotation": 2
    },
    {
      "x": -18,
      "y": 64,
      "z": 1,
      "name": "Wood_Sallow_Branch_Corner",
      "support": 15,
      "rotation": 3
    },
    {
      "x": -18,
      "y": 65,
      "z": 1,
      "name": "Wood_Sallow_Branch_Long",
      "support": 15,
      "rotation": 2
    },
    {
      "x": -18,
      "y": 66,
      "z": 1,
      "name": "Plant_Leaves_Beech",
      "support": 15,
      "rotation": 2
    },
    {
      "x": -18,
      "y": 33,
      "z": 2,
      "name": "Furniture_Crude_Platform",
      "rotation": 1
    },
    {
      "x": -18,
      "y": 37,
      "z": 2,
      "name": "Wood_Goldenwood_Planks_Half",
      "rotation": 8
    },
    {
      "x": -18,
      "y": 38,
      "z": 2,
      "name": "Wood_Tropicalwood_Roof_Flat",
      "rotation": 3
    },
    {
      "x": -18,
      "y": 64,
      "z": 2,
      "name": "Plant_Leaves_Beech",
      "support": 15,
      "rotation": 2
    },
    {
      "x": -18,
      "y": 65,
      "z": 2,
      "name": "Plant_Leaves_Beech",
      "support": 15,
      "rotation": 2
    },
    {
      "x": -18,
      "y": 28,
      "z": 3,
      "name": "Plant_Moss_Wall_Green_Dark",
      "support": 15,
      "rotation": 3
    },
    {
      "x": -18,
      "y": 29,
      "z": 3,
      "name": "Plant_Moss_Wall_Green_Dark",
      "support": 15,
      "rotation": 3
    },
    {
      "x": -18,
      "y": 33,
      "z": 3,
      "name": "Furniture_Crude_Platform",
      "rotation": 1
    },
    {
      "x": -18,
      "y": 37,
      "z": 3,
      "name": "Wood_Goldenwood_Planks_Half",
      "rotation": 8
    },
    {
      "x": -18,
      "y": 38,
      "z": 3,
      "name": "Wood_Tropicalwood_Roof_Flat",
      "rotation": 3
    },
    {
      "x": -18,
      "y": 33,
      "z": 4,
      "name": "Furniture_Crude_Platform",
      "rotation": 1
    },
    {
      "x": -18,
      "y": 37,
      "z": 4,
      "name": "Wood_Goldenwood_Planks_Half",
      "rotation": 8
    },
    {
      "x": -18,
      "y": 38,
      "z": 4,
      "name": "Wood_Tropicalwood_Roof_Flat",
      "rotation": 3
    },
    {
      "x": -18,
      "y": 33,
      "z": 5,
      "name": "Furniture_Crude_Platform",
      "rotation": 1
    },
    {
      "x": -18,
      "y": 37,
      "z": 5,
      "name": "Wood_Goldenwood_Planks_Half",
      "rotation": 8
    },
    {
      "x": -18,
      "y": 38,
      "z": 5,
      "name": "Wood_Tropicalwood_Roof_Flat",
      "rotation": 3
    },
    {
      "x": -18,
      "y": 3,
      "z": 6,
      "name": "Wood_Sallow_Roots",
      "rotation": 2
    },
    {
      "x": -18,
      "y": 4,
      "z": 6,
      "name": "Wood_Sallow_Trunk_Full",
      "support": 15,
      "rotation": 2
    },
    {
      "x": -18,
      "y": 5,
      "z": 6,
      "name": "Wood_Sallow_Trunk",
      "support": 15,
      "rotation": 2
    },
    {
      "x": -18,
      "y": 6,
      "z": 6,
      "name": "Wood_Sallow_Trunk",
      "support": 15,
      "rotation": 2
    },
    {
      "x": -18,
      "y": 7,
      "z": 6,
      "name": "Wood_Sallow_Trunk",
      "support": 15,
      "rotation": 2
    },
    {
      "x": -18,
      "y": 8,
      "z": 6,
      "name": "Wood_Sallow_Trunk",
      "support": 15,
      "rotation": 2
    },
    {
      "x": -18,
      "y": 9,
      "z": 6,
      "name": "Wood_Sallow_Trunk_Full",
      "support": 15,
      "rotation": 7
    },
    {
      "x": -18,
      "y": 33,
      "z": 6,
      "name": "Furniture_Crude_Platform",
      "rotation": 1
    },
    {
      "x": -18,
      "y": 37,
      "z": 6,
      "name": "Wood_Goldenwood_Planks_Half",
      "rotation": 8
    },
    {
      "x": -18,
      "y": 38,
      "z": 6,
      "name": "Wood_Tropicalwood_Roof_Flat",
      "rotation": 3
    },
    {
      "x": -18,
      "y": 60,
      "z": 6,
      "name": "Plant_Leaves_Beech",
      "support": 15,
      "rotation": 2
    },
    {
      "x": -18,
      "y": 33,
      "z": 7,
      "name": "Furniture_Crude_Platform",
      "rotation": 1
    },
    {
      "x": -18,
      "y": 37,
      "z": 7,
      "name": "Wood_Goldenwood_Planks_Half",
      "rotation": 8
    },
    {
      "x": -18,
      "y": 38,
      "z": 7,
      "name": "Wood_Tropicalwood_Roof_Flat",
      "rotation": 3
    },
    {
      "x": -18,
      "y": 60,
      "z": 7,
      "name": "Plant_Leaves_Beech",
      "support": 15,
      "rotation": 2
    },
    {
      "x": -18,
      "y": 61,
      "z": 7,
      "name": "Plant_Leaves_Beech",
      "support": 15,
      "rotation": 2
    },
    {
      "x": -18,
      "y": 33,
      "z": 8,
      "name": "Furniture_Crude_Platform",
      "rotation": 1
    },
    {
      "x": -18,
      "y": 34,
      "z": 8,
      "name": "*Wood_Hardwood_Fence_State_Definitions_Corner"
    },
    {
      "x": -18,
      "y": 37,
      "z": 8,
      "name": "*Wood_Tropicalwood_Roof_Hollow_State_Definitions_Inverted_Corner_Right"
    },
    {
      "x": -18,
      "y": 59,
      "z": 8,
      "name": "Wood_Sallow_Branch_Corner",
      "support": 15,
      "rotation": 3
    },
    {
      "x": -18,
      "y": 60,
      "z": 8,
      "name": "Wood_Sallow_Branch_Long",
      "support": 15,
      "rotation": 2
    },
    {
      "x": -18,
      "y": 61,
      "z": 8,
      "name": "Plant_Leaves_Beech",
      "support": 15,
      "rotation": 2
    },
    {
      "x": -18,
      "y": 62,
      "z": 8,
      "name": "Plant_Leaves_Beech",
      "support": 15,
      "rotation": 2
    },
    {
      "x": -18,
      "y": 33,
      "z": 9,
      "name": "Furniture_Crude_Platform"
    },
    {
      "x": -18,
      "y": 34,
      "z": 9,
      "name": "Wood_Hardwood_Fence",
      "rotation": 3
    },
    {
      "x": -18,
      "y": 37,
      "z": 9,
      "name": "Wood_Tropicalwood_Roof_Hollow",
      "rotation": 3
    },
    {
      "x": -18,
      "y": 60,
      "z": 9,
      "name": "Plant_Leaves_Beech",
      "support": 15,
      "rotation": 2
    },
    {
      "x": -18,
      "y": 61,
      "z": 9,
      "name": "Plant_Leaves_Beech",
      "support": 15,
      "rotation": 2
    },
    {
      "x": -18,
      "y": 33,
      "z": 10,
      "name": "Furniture_Crude_Platform"
    },
    {
      "x": -18,
      "y": 34,
      "z": 10,
      "name": "*Wood_Hardwood_Fence_State_Definitions_Corner",
      "rotation": 2
    },
    {
      "x": -18,
      "y": 35,
      "z": 10,
      "name": "Wood_Hardwood_Beam"
    },
    {
      "x": -18,
      "y": 36,
      "z": 10,
      "name": "Wood_Hardwood_Beam"
    },
    {
      "x": -18,
      "y": 37,
      "z": 10,
      "name": "*Wood_Tropicalwood_Roof_State_Definitions_Corner_Left",
      "rotation": 3
    },
    {
      "x": -18,
      "y": 9,
      "z": 11,
      "name": "Plant_Moss_Rug_Green_Dark",
      "support": 15,
      "rotation": 2
    },
    {
      "x": -18,
      "y": 10,
      "z": 11,
      "name": "Plant_Moss_Wall_Green_Dark",
      "support": 15,
      "rotation": 3
    },
    {
      "x": -18,
      "y": 59,
      "z": 11,
      "name": "Plant_Leaves_Beech",
      "support": 15,
      "rotation": 2
    },
    {
      "x": -18,
      "y": 61,
      "z": 11,
      "name": "Wood_Sallow_Branch_Long",
      "support": 15,
      "rotation": 7
    },
    {
      "x": -18,
      "y": 2,
      "z": 12,
      "name": "Wood_Sallow_Roots",
      "rotation": 2
    },
    {
      "x": -18,
      "y": 3,
      "z": 12,
      "name": "Wood_Sallow_Trunk_Full",
      "support": 15,
      "rotation": 2
    },
    {
      "x": -18,
      "y": 4,
      "z": 12,
      "name": "Wood_Sallow_Trunk",
      "support": 15,
      "rotation": 2
    },
    {
      "x": -18,
      "y": 5,
      "z": 12,
      "name": "Wood_Sallow_Trunk",
      "support": 15,
      "rotation": 2
    },
    {
      "x": -18,
      "y": 6,
      "z": 12,
      "name": "Wood_Sallow_Trunk",
      "support": 15,
      "rotation": 2
    },
    {
      "x": -18,
      "y": 7,
      "z": 12,
      "name": "Wood_Sallow_Trunk",
      "support": 15,
      "rotation": 2
    },
    {
      "x": -18,
      "y": 8,
      "z": 12,
      "name": "Wood_Sallow_Trunk",
      "support": 15,
      "rotation": 2
    },
    {
      "x": -18,
      "y": 9,
      "z": 12,
      "name": "Wood_Sallow_Trunk_Full",
      "support": 15,
      "rotation": 2
    },
    {
      "x": -18,
      "y": 10,
      "z": 12,
      "name": "Plant_Moss_Rug_Green_Dark",
      "support": 15,
      "rotation": 2
    },
    {
      "x": -18,
      "y": 62,
      "z": 13,
      "name": "Plant_Leaves_Beech",
      "support": 15,
      "rotation": 2
    },
    {
      "x": -18,
      "y": 63,
      "z": 13,
      "name": "Plant_Leaves_Beech",
      "support": 15,
      "rotation": 2
    },
    {
      "x": -18,
      "y": 61,
      "z": 14,
      "name": "Plant_Leaves_Beech",
      "support": 15,
      "rotation": 2
    },
    {
      "x": -18,
      "y": 62,
      "z": 14,
      "name": "Plant_Leaves_Beech",
      "support": 15,
      "rotation": 2
    },
    {
      "x": -18,
      "y": 63,
      "z": 14,
      "name": "Plant_Leaves_Beech",
      "support": 15,
      "rotation": 2
    },
    {
      "x": -17,
      "y": 33,
      "z": -1,
      "name": "Furniture_Crude_Platform"
    },
    {
      "x": -17,
      "y": 34,
      "z": -1,
      "name": "*Wood_Hardwood_Fence_State_Definitions_Corner",
      "rotation": 1
    },
    {
      "x": -17,
      "y": 37,
      "z": -1,
      "name": "*Wood_Tropicalwood_Roof_Hollow_State_Definitions_Corner_Left",
      "rotation": 2
    },
    {
      "x": -17,
      "y": 60,
      "z": -1,
      "name": "Plant_Leaves_Beech",
      "support": 15,
      "rotation": 2
    },
    {
      "x": -17,
      "y": 61,
      "z": -1,
      "name": "Plant_Leaves_Beech",
      "support": 15,
      "rotation": 2
    },
    {
      "x": -17,
      "y": 3,
      "z": 0,
      "name": "Wood_Sallow_Roots",
      "rotation": 2
    },
    {
      "x": -17,
      "y": 4,
      "z": 0,
      "name": "Wood_Sallow_Trunk_Full",
      "support": 15,
      "rotation": 2
    },
    {
      "x": -17,
      "y": 5,
      "z": 0,
      "name": "Wood_Sallow_Trunk",
      "support": 15,
      "rotation": 2
    },
    {
      "x": -17,
      "y": 6,
      "z": 0,
      "name": "Wood_Sallow_Trunk",
      "support": 15,
      "rotation": 2
    },
    {
      "x": -17,
      "y": 7,
      "z": 0,
      "name": "Wood_Sallow_Trunk",
      "support": 15,
      "rotation": 2
    },
    {
      "x": -17,
      "y": 8,
      "z": 0,
      "name": "Wood_Sallow_Trunk",
      "support": 15,
      "rotation": 2
    },
    {
      "x": -17,
      "y": 9,
      "z": 0,
      "name": "Wood_Sallow_Trunk",
      "support": 15,
      "rotation": 2
    },
    {
      "x": -17,
      "y": 10,
      "z": 0,
      "name": "Wood_Sallow_Trunk_Full",
      "support": 15,
      "rotation": 2
    },
    {
      "x": -17,
      "y": 11,
      "z": 0,
      "name": "Plant_Moss_Rug_Green_Dark",
      "support": 15,
      "rotation": 2
    },
    {
      "x": -17,
      "y": 33,
      "z": 0,
      "name": "Furniture_Crude_Platform",
      "rotation": 1
    },
    {
      "x": -17,
      "y": 34,
      "z": 0,
      "name": "*Wood_Hardwood_Fence_State_Definitions_Corner",
      "rotation": 3
    },
    {
      "x": -17,
      "y": 37,
      "z": 0,
      "name": "*Wood_Tropicalwood_Roof_Hollow_State_Definitions_Inverted_Corner_Right",
      "rotation": 3
    },
    {
      "x": -17,
      "y": 59,
      "z": 0,
      "name": "Plant_Leaves_Beech",
      "support": 15,
      "rotation": 2
    },
    {
      "x": -17,
      "y": 60,
      "z": 0,
      "name": "Wood_Sallow_Branch_Long",
      "support": 15,
      "rotation": 2
    },
    {
      "x": -17,
      "y": 61,
      "z": 0,
      "name": "Wood_Sallow_Branch_Corner",
      "support": 15,
      "rotation": 34
    },
    {
      "x": -17,
      "y": 62,
      "z": 0,
      "name": "Plant_Leaves_Beech",
      "support": 15,
      "rotation": 2
    },
    {
      "x": -17,
      "y": 64,
      "z": 0,
      "name": "Plant_Leaves_Beech",
      "support": 15,
      "rotation": 2
    },
    {
      "x": -17,
      "y": 11,
      "z": 1,
      "name": "Plant_Moss_Wall_Green_Dark",
      "support": 15,
      "rotation": 3
    },
    {
      "x": -17,
      "y": 33,
      "z": 1,
      "name": "Furniture_Crude_Platform",
      "rotation": 1
    },
    {
      "x": -17,
      "y": 37,
      "z": 1,
      "name": "Wood_Goldenwood_Planks_Half",
      "rotation": 8
    },
    {
      "x": -17,
      "y": 38,
      "z": 1,
      "name": "Wood_Tropicalwood_Roof_Flat",
      "rotation": 3
    },
    {
      "x": -17,
      "y": 60,
      "z": 1,
      "name": "Plant_Leaves_Beech",
      "support": 15,
      "rotation": 2
    },
    {
      "x": -17,
      "y": 61,
      "z": 1,
      "name": "Wood_Sallow_Branch_Corner",
      "support": 15,
      "rotation": 19
    },
    {
      "x": -17,
      "y": 63,
      "z": 1,
      "name": "Plant_Leaves_Beech",
      "support": 15,
      "rotation": 2
    },
    {
      "x": -17,
      "y": 64,
      "z": 1,
      "name": "Wood_Sallow_Branch_Long",
      "support": 15,
      "rotation": 7
    },
    {
      "x": -17,
      "y": 65,
      "z": 1,
      "name": "Plant_Leaves_Beech",
      "support": 15,
      "rotation": 2
    },
    {
      "x": -17,
      "y": 29,
      "z": 2,
      "name": "Plant_Moss_Wall_Green_Dark",
      "support": 15,
      "rotation": 2
    },
    {
      "x": -17,
      "y": 33,
      "z": 2,
      "name": "Furniture_Crude_Platform",
      "rotation": 1
    },
    {
      "x": -17,
      "y": 37,
      "z": 2,
      "name": "Wood_Goldenwood_Planks_Half",
      "rotation": 8
    },
    {
      "x": -17,
      "y": 38,
      "z": 2,
      "name": "*Wood_Hardwood_Fence_State_Definitions_Corner",
      "rotation": 1
    },
    {
      "x": -17,
      "y": 39,
      "z": 2,
      "name": "Wood_Hardwood_Beam"
    },
    {
      "x": -17,
      "y": 40,
      "z": 2,
      "name": "Wood_Hardwood_Beam"
    },
    {
      "x": -17,
      "y": 41,
      "z": 2,
      "name": "*Wood_Tropicalwood_Roof_State_Definitions_Corner_Left",
      "rotation": 2
    },
    {
      "x": -17,
      "y": 29,
      "z": 3,
      "name": "Furniture_Crude_Platform",
      "rotation": 1
    },
    {
      "x": -17,
      "y": 30,
      "z": 3,
      "name": "*Wood_Softwood_Fence_State_Definitions_Corner",
      "rotation": 1
    },
    {
      "x": -17,
      "y": 31,
      "z": 3,
      "name": "*Wood_Softwood_Fence_State_Definitions_Corner",
      "rotation": 1
    },
    {
      "x": -17,
      "y": 32,
      "z": 3,
      "name": "*Wood_Softwood_Fence_State_Definitions_Corner",
      "rotation": 1
    },
    {
      "x": -17,
      "y": 33,
      "z": 3,
      "name": "*Wood_Goldenwood_Stairs_State_Definitions_Corner_Right",
      "rotation": 8
    },
    {
      "x": -17,
      "y": 34,
      "z": 3,
      "name": "*Wood_Softwood_Fence_State_Definitions_Corner",
      "rotation": 1
    },
    {
      "x": -17,
      "y": 35,
      "z": 3,
      "name": "*Wood_Softwood_Fence_State_Definitions_Corner",
      "rotation": 1
    },
    {
      "x": -17,
      "y": 36,
      "z": 3,
      "name": "*Wood_Softwood_Fence_State_Definitions_Corner",
      "rotation": 1
    },
    {
      "x": -17,
      "y": 37,
      "z": 3,
      "name": "*Wood_Goldenwood_Stairs_State_Definitions_Corner_Left",
      "rotation": 9
    },
    {
      "x": -17,
      "y": 38,
      "z": 3,
      "name": "Wood_Hardwood_Fence",
      "rotation": 3
    },
    {
      "x": -17,
      "y": 41,
      "z": 3,
      "name": "Wood_Tropicalwood_Roof_Hollow",
      "rotation": 3
    },
    {
      "x": -17,
      "y": 29,
      "z": 4,
      "name": "Furniture_Crude_Platform",
      "rotation": 1
    },
    {
      "x": -17,
      "y": 30,
      "z": 4,
      "name": "Wood_Softwood_Fence",
      "rotation": 3
    },
    {
      "x": -17,
      "y": 31,
      "z": 4,
      "name": "Wood_Softwood_Fence",
      "rotation": 3
    },
    {
      "x": -17,
      "y": 32,
      "z": 4,
      "name": "Wood_Softwood_Fence",
      "rotation": 3
    },
    {
      "x": -17,
      "y": 33,
      "z": 4,
      "name": "Wood_Goldenwood_Stairs",
      "rotation": 9
    },
    {
      "x": -17,
      "y": 34,
      "z": 4,
      "name": "Wood_Softwood_Fence",
      "rotation": 3
    },
    {
      "x": -17,
      "y": 35,
      "z": 4,
      "name": "Wood_Softwood_Fence",
      "rotation": 3
    },
    {
      "x": -17,
      "y": 36,
      "z": 4,
      "name": "Wood_Softwood_Fence",
      "rotation": 3
    },
    {
      "x": -17,
      "y": 37,
      "z": 4,
      "name": "Wood_Goldenwood_Stairs",
      "rotation": 9
    },
    {
      "x": -17,
      "y": 38,
      "z": 4,
      "name": "Wood_Hardwood_Fence",
      "rotation": 3
    },
    {
      "x": -17,
      "y": 41,
      "z": 4,
      "name": "Wood_Tropicalwood_Roof_Hollow",
      "rotation": 3
    },
    {
      "x": -17,
      "y": 59,
      "z": 4,
      "name": "Plant_Leaves_Beech",
      "support": 15,
      "rotation": 2
    },
    {
      "x": -17,
      "y": 60,
      "z": 4,
      "name": "Plant_Leaves_Beech",
      "support": 15,
      "rotation": 2
    },
    {
      "x": -17,
      "y": 29,
      "z": 5,
      "name": "Furniture_Crude_Platform",
      "rotation": 1
    },
    {
      "x": -17,
      "y": 30,
      "z": 5,
      "name": "Wood_Softwood_Fence",
      "rotation": 3
    },
    {
      "x": -17,
      "y": 31,
      "z": 5,
      "name": "Wood_Goldenwood_Fence",
      "rotation": 3
    },
    {
      "x": -17,
      "y": 32,
      "z": 5,
      "name": "Wood_Softwood_Fence",
      "rotation": 3
    },
    {
      "x": -17,
      "y": 33,
      "z": 5,
      "name": "Wood_Goldenwood_Stairs",
      "rotation": 9
    },
    {
      "x": -17,
      "y": 34,
      "z": 5,
      "name": "Wood_Softwood_Fence",
      "rotation": 3
    },
    {
      "x": -17,
      "y": 35,
      "z": 5,
      "name": "Wood_Goldenwood_Fence",
      "rotation": 3
    },
    {
      "x": -17,
      "y": 36,
      "z": 5,
      "name": "Wood_Softwood_Fence",
      "rotation": 3
    },
    {
      "x": -17,
      "y": 37,
      "z": 5,
      "name": "Wood_Goldenwood_Stairs",
      "rotation": 9
    },
    {
      "x": -17,
      "y": 38,
      "z": 5,
      "name": "Wood_Hardwood_Fence",
      "rotation": 3
    },
    {
      "x": -17,
      "y": 41,
      "z": 5,
      "name": "Wood_Tropicalwood_Roof_Hollow",
      "rotation": 3
    },
    {
      "x": -17,
      "y": 56,
      "z": 5,
      "name": "Plant_Leaves_Beech",
      "support": 15,
      "rotation": 2
    },
    {
      "x": -17,
      "y": 4,
      "z": 6,
      "name": "Wood_Sallow_Roots",
      "rotation": 2
    },
    {
      "x": -17,
      "y": 5,
      "z": 6,
      "name": "Wood_Sallow_Trunk_Full",
      "support": 15,
      "rotation": 2
    },
    {
      "x": -17,
      "y": 6,
      "z": 6,
      "name": "Wood_Sallow_Trunk",
      "support": 15,
      "rotation": 2
    },
    {
      "x": -17,
      "y": 7,
      "z": 6,
      "name": "Wood_Sallow_Trunk",
      "support": 15,
      "rotation": 2
    },
    {
      "x": -17,
      "y": 8,
      "z": 6,
      "name": "Wood_Sallow_Trunk",
      "support": 15,
      "rotation": 2
    },
    {
      "x": -17,
      "y": 9,
      "z": 6,
      "name": "Wood_Sallow_Trunk",
      "support": 15,
      "rotation": 2
    },
    {
      "x": -17,
      "y": 10,
      "z": 6,
      "name": "Wood_Sallow_Trunk_Full",
      "support": 15,
      "rotation": 2
    },
    {
      "x": -17,
      "y": 29,
      "z": 6,
      "name": "Furniture_Crude_Platform",
      "rotation": 1
    },
    {
      "x": -17,
      "y": 30,
      "z": 6,
      "name": "Wood_Softwood_Fence",
      "rotation": 3
    },
    {
      "x": -17,
      "y": 31,
      "z": 6,
      "name": "Wood_Softwood_Fence",
      "rotation": 3
    },
    {
      "x": -17,
      "y": 32,
      "z": 6,
      "name": "Wood_Softwood_Fence",
      "rotation": 3
    },
    {
      "x": -17,
      "y": 33,
      "z": 6,
      "name": "Wood_Goldenwood_Stairs",
      "rotation": 9
    },
    {
      "x": -17,
      "y": 34,
      "z": 6,
      "name": "Wood_Softwood_Fence",
      "rotation": 3
    },
    {
      "x": -17,
      "y": 35,
      "z": 6,
      "name": "Wood_Softwood_Fence",
      "rotation": 3
    },
    {
      "x": -17,
      "y": 36,
      "z": 6,
      "name": "Wood_Softwood_Fence",
      "rotation": 3
    },
    {
      "x": -17,
      "y": 37,
      "z": 6,
      "name": "Wood_Goldenwood_Stairs",
      "rotation": 9
    },
    {
      "x": -17,
      "y": 38,
      "z": 6,
      "name": "Wood_Hardwood_Fence",
      "rotation": 3
    },
    {
      "x": -17,
      "y": 41,
      "z": 6,
      "name": "Wood_Tropicalwood_Roof_Hollow",
      "rotation": 3
    },
    {
      "x": -17,
      "y": 29,
      "z": 7,
      "name": "Furniture_Crude_Platform",
      "rotation": 1
    },
    {
      "x": -17,
      "y": 30,
      "z": 7,
      "name": "*Wood_Softwood_Fence_State_Definitions_Corner",
      "rotation": 2
    },
    {
      "x": -17,
      "y": 31,
      "z": 7,
      "name": "*Wood_Softwood_Fence_State_Definitions_Corner",
      "rotation": 2
    },
    {
      "x": -17,
      "y": 32,
      "z": 7,
      "name": "*Wood_Softwood_Fence_State_Definitions_Corner",
      "rotation": 2
    },
    {
      "x": -17,
      "y": 33,
      "z": 7,
      "name": "*Wood_Goldenwood_Stairs_State_Definitions_Corner_Right",
      "rotation": 9
    },
    {
      "x": -17,
      "y": 34,
      "z": 7,
      "name": "*Wood_Softwood_Fence_State_Definitions_Corner",
      "rotation": 2
    },
    {
      "x": -17,
      "y": 35,
      "z": 7,
      "name": "*Wood_Softwood_Fence_State_Definitions_Corner",
      "rotation": 2
    },
    {
      "x": -17,
      "y": 36,
      "z": 7,
      "name": "*Wood_Softwood_Fence_State_Definitions_Corner",
      "rotation": 2
    },
    {
      "x": -17,
      "y": 37,
      "z": 7,
      "name": "*Wood_Goldenwood_Stairs_State_Definitions_Corner_Left",
      "rotation": 10
    },
    {
      "x": -17,
      "y": 38,
      "z": 7,
      "name": "Wood_Hardwood_Fence",
      "rotation": 3
    },
    {
      "x": -17,
      "y": 41,
      "z": 7,
      "name": "Wood_Tropicalwood_Roof_Hollow",
      "rotation": 3
    },
    {
      "x": -17,
      "y": 65,
      "z": 7,
      "name": "Plant_Leaves_Beech",
      "support": 15,
      "rotation": 2
    },
    {
      "x": -17,
      "y": 66,
      "z": 7,
      "name": "Plant_Leaves_Beech",
      "support": 15,
      "rotation": 2
    },
    {
      "x": -17,
      "y": 69,
      "z": 7,
      "name": "Plant_Leaves_Beech",
      "support": 15,
      "rotation": 2
    },
    {
      "x": -17,
      "y": 33,
      "z": 8,
      "name": "Furniture_Crude_Platform",
      "rotation": 1
    },
    {
      "x": -17,
      "y": 37,
      "z": 8,
      "name": "Wood_Goldenwood_Planks_Half",
      "rotation": 8
    },
    {
      "x": -17,
      "y": 38,
      "z": 8,
      "name": "*Wood_Hardwood_Fence_State_Definitions_Corner",
      "rotation": 2
    },
    {
      "x": -17,
      "y": 39,
      "z": 8,
      "name": "Wood_Hardwood_Beam"
    },
    {
      "x": -17,
      "y": 40,
      "z": 8,
      "name": "Wood_Hardwood_Beam"
    },
    {
      "x": -17,
      "y": 41,
      "z": 8,
      "name": "*Wood_Tropicalwood_Roof_State_Definitions_Corner_Right"
    },
    {
      "x": -17,
      "y": 59,
      "z": 8,
      "name": "Wood_Sallow_Branch_Long",
      "support": 15,
      "rotation": 7
    },
    {
      "x": -17,
      "y": 60,
      "z": 8,
      "name": "Plant_Leaves_Beech",
      "support": 15,
      "rotation": 2
    },
    {
      "x": -17,
      "y": 61,
      "z": 8,
      "name": "Plant_Leaves_Beech",
      "support": 15,
      "rotation": 2
    },
    {
      "x": -17,
      "y": 65,
      "z": 8,
      "name": "Plant_Leaves_Beech",
      "support": 15,
      "rotation": 2
    },
    {
      "x": -17,
      "y": 67,
      "z": 8,
      "name": "Plant_Leaves_Beech",
      "support": 15,
      "rotation": 2
    },
    {
      "x": -17,
      "y": 68,
      "z": 8,
      "name": "Plant_Leaves_Beech",
      "support": 15,
      "rotation": 2
    },
    {
      "x": -17,
      "y": 69,
      "z": 8,
      "name": "Plant_Leaves_Beech",
      "support": 15,
      "rotation": 2
    },
    {
      "x": -17,
      "y": 33,
      "z": 9,
      "name": "Furniture_Crude_Platform",
      "rotation": 1
    },
    {
      "x": -17,
      "y": 37,
      "z": 9,
      "name": "Wood_Goldenwood_Planks_Half",
      "rotation": 8
    },
    {
      "x": -17,
      "y": 38,
      "z": 9,
      "name": "Wood_Tropicalwood_Roof_Flat",
      "rotation": 3
    },
    {
      "x": -17,
      "y": 68,
      "z": 9,
      "name": "Plant_Leaves_Beech",
      "support": 15,
      "rotation": 2
    },
    {
      "x": -17,
      "y": 69,
      "z": 9,
      "name": "Plant_Leaves_Beech",
      "support": 15,
      "rotation": 2
    },
    {
      "x": -17,
      "y": 5,
      "z": 10,
      "name": "Wood_Sallow_Trunk_Full",
      "support": 15,
      "rotation": 2
    },
    {
      "x": -17,
      "y": 6,
      "z": 10,
      "name": "Wood_Sallow_Trunk",
      "support": 15,
      "rotation": 2
    },
    {
      "x": -17,
      "y": 7,
      "z": 10,
      "name": "Wood_Sallow_Trunk",
      "support": 15,
      "rotation": 2
    },
    {
      "x": -17,
      "y": 8,
      "z": 10,
      "name": "Wood_Sallow_Trunk",
      "support": 15,
      "rotation": 2
    },
    {
      "x": -17,
      "y": 9,
      "z": 10,
      "name": "Wood_Sallow_Trunk_Full",
      "support": 15,
      "rotation": 7
    },
    {
      "x": -17,
      "y": 33,
      "z": 10,
      "name": "Furniture_Crude_Platform",
      "rotation": 1
    },
    {
      "x": -17,
      "y": 34,
      "z": 10,
      "name": "*Wood_Hardwood_Fence_State_Definitions_Corner"
    },
    {
      "x": -17,
      "y": 37,
      "z": 10,
      "name": "*Wood_Tropicalwood_Roof_Hollow_State_Definitions_Inverted_Corner_Right"
    },
    {
      "x": -17,
      "y": 59,
      "z": 10,
      "name": "Plant_Leaves_Beech",
      "support": 15,
      "rotation": 2
    },
    {
      "x": -17,
      "y": 60,
      "z": 10,
      "name": "Wood_Sallow_Trunk_Full",
      "support": 15,
      "rotation": 7
    },
    {
      "x": -17,
      "y": 65,
      "z": 10,
      "name": "Plant_Leaves_Beech",
      "support": 15,
      "rotation": 2
    },
    {
      "x": -17,
      "y": 3,
      "z": 11,
      "name": "Wood_Sallow_Roots",
      "rotation": 2
    },
    {
      "x": -17,
      "y": 4,
      "z": 11,
      "name": "Wood_Sallow_Trunk_Full",
      "support": 15,
      "rotation": 2
    },
    {
      "x": -17,
      "y": 5,
      "z": 11,
      "name": "Wood_Sallow_Trunk",
      "support": 15,
      "rotation": 2
    },
    {
      "x": -17,
      "y": 6,
      "z": 11,
      "name": "Wood_Sallow_Trunk",
      "support": 15,
      "rotation": 2
    },
    {
      "x": -17,
      "y": 7,
      "z": 11,
      "name": "Wood_Sallow_Trunk",
      "support": 15,
      "rotation": 2
    },
    {
      "x": -17,
      "y": 8,
      "z": 11,
      "name": "Wood_Sallow_Trunk",
      "support": 15,
      "rotation": 2
    },
    {
      "x": -17,
      "y": 9,
      "z": 11,
      "name": "Wood_Sallow_Trunk",
      "support": 15,
      "rotation": 2
    },
    {
      "x": -17,
      "y": 10,
      "z": 11,
      "name": "Wood_Sallow_Trunk_Full",
      "support": 15,
      "rotation": 2
    },
    {
      "x": -17,
      "y": 11,
      "z": 11,
      "name": "Plant_Moss_Rug_Green_Dark",
      "support": 15,
      "rotation": 2
    },
    {
      "x": -17,
      "y": 33,
      "z": 11,
      "name": "Furniture_Crude_Platform"
    },
    {
      "x": -17,
      "y": 34,
      "z": 11,
      "name": "*Wood_Hardwood_Fence_State_Definitions_Corner",
      "rotation": 2
    },
    {
      "x": -17,
      "y": 37,
      "z": 11,
      "name": "*Wood_Tropicalwood_Roof_Hollow_State_Definitions_Corner_Left",
      "rotation": 3
    },
    {
      "x": -17,
      "y": 58,
      "z": 11,
      "name": "Plant_Leaves_Beech",
      "support": 15,
      "rotation": 2
    },
    {
      "x": -17,
      "y": 59,
      "z": 11,
      "name": "Wood_Sallow_Branch_Long",
      "support": 15,
      "rotation": 2
    },
    {
      "x": -17,
      "y": 60,
      "z": 11,
      "name": "Wood_Sallow_Trunk_Full",
      "support": 15,
      "rotation": 6
    },
    {
      "x": -17,
      "y": 61,
      "z": 11,
      "name": "Wood_Sallow_Trunk_Full",
      "support": 15,
      "rotation": 2
    },
    {
      "x": -17,
      "y": 65,
      "z": 11,
      "name": "Plant_Leaves_Beech",
      "support": 15,
      "rotation": 2
    },
    {
      "x": -17,
      "y": 66,
      "z": 11,
      "name": "Plant_Leaves_Beech",
      "support": 15,
      "rotation": 2
    },
    {
      "x": -17,
      "y": 59,
      "z": 12,
      "name": "Plant_Leaves_Beech",
      "support": 15,
      "rotation": 2
    },
    {
      "x": -17,
      "y": 61,
      "z": 12,
      "name": "Wood_Sallow_Branch_Long",
      "support": 15,
      "rotation": 6
    },
    {
      "x": -17,
      "y": 61,
      "z": 13,
      "name": "Wood_Sallow_Branch_Long",
      "support": 15,
      "rotation": 6
    },
    {
      "x": -17,
      "y": 62,
      "z": 13,
      "name": "Plant_Leaves_Beech",
      "support": 15,
      "rotation": 2
    },
    {
      "x": -17,
      "y": 63,
      "z": 13,
      "name": "Plant_Leaves_Beech",
      "support": 15,
      "rotation": 2
    },
    {
      "x": -17,
      "y": 61,
      "z": 14,
      "name": "Wood_Sallow_Branch_Corner",
      "support": 15
    },
    {
      "x": -17,
      "y": 62,
      "z": 14,
      "name": "Wood_Sallow_Branch_Long",
      "support": 15,
      "rotation": 2
    },
    {
      "x": -17,
      "y": 63,
      "z": 14,
      "name": "Plant_Leaves_Beech",
      "support": 15,
      "rotation": 2
    },
    {
      "x": -17,
      "y": 64,
      "z": 14,
      "name": "Plant_Leaves_Beech",
      "support": 15,
      "rotation": 2
    },
    {
      "x": -17,
      "y": 61,
      "z": 15,
      "name": "Plant_Leaves_Beech",
      "support": 15,
      "rotation": 2
    },
    {
      "x": -17,
      "y": 62,
      "z": 15,
      "name": "Plant_Leaves_Beech",
      "support": 15,
      "rotation": 2
    },
    {
      "x": -16,
      "y": 33,
      "z": -2,
      "name": "Furniture_Crude_Platform",
      "rotation": 1
    },
    {
      "x": -16,
      "y": 34,
      "z": -2,
      "name": "*Wood_Hardwood_Fence_State_Definitions_Corner",
      "rotation": 1
    },
    {
      "x": -16,
      "y": 37,
      "z": -2,
      "name": "*Wood_Tropicalwood_Roof_Hollow_State_Definitions_Corner_Left",
      "rotation": 2
    },
    {
      "x": -16,
      "y": 33,
      "z": -1,
      "name": "Furniture_Crude_Platform"
    },
    {
      "x": -16,
      "y": 34,
      "z": -1,
      "name": "*Wood_Hardwood_Fence_State_Definitions_Corner",
      "rotation": 3
    },
    {
      "x": -16,
      "y": 37,
      "z": -1,
      "name": "*Wood_Tropicalwood_Roof_Hollow_State_Definitions_Inverted_Corner_Right",
      "rotation": 3
    },
    {
      "x": -16,
      "y": 64,
      "z": -1,
      "name": "Plant_Leaves_Beech",
      "support": 15,
      "rotation": 2
    },
    {
      "x": -16,
      "y": 65,
      "z": -1,
      "name": "Plant_Leaves_Beech",
      "support": 15,
      "rotation": 2
    },
    {
      "x": -16,
      "y": 5,
      "z": 0,
      "name": "Wood_Sallow_Trunk_Full",
      "support": 15,
      "rotation": 2
    },
    {
      "x": -16,
      "y": 6,
      "z": 0,
      "name": "Wood_Sallow_Trunk",
      "support": 15,
      "rotation": 2
    },
    {
      "x": -16,
      "y": 7,
      "z": 0,
      "name": "Wood_Sallow_Trunk",
      "support": 15,
      "rotation": 2
    },
    {
      "x": -16,
      "y": 8,
      "z": 0,
      "name": "Wood_Sallow_Trunk",
      "support": 15,
      "rotation": 2
    },
    {
      "x": -16,
      "y": 9,
      "z": 0,
      "name": "Wood_Sallow_Trunk",
      "support": 15,
      "rotation": 2
    },
    {
      "x": -16,
      "y": 10,
      "z": 0,
      "name": "Wood_Sallow_Trunk_Full",
      "support": 15,
      "rotation": 2
    },
    {
      "x": -16,
      "y": 11,
      "z": 0,
      "name": "Plant_Moss_Rug_Green_Dark",
      "support": 15,
      "rotation": 2
    },
    {
      "x": -16,
      "y": 33,
      "z": 0,
      "name": "Furniture_Crude_Platform"
    },
    {
      "x": -16,
      "y": 37,
      "z": 0,
      "name": "Wood_Goldenwood_Planks_Half",
      "rotation": 8
    },
    {
      "x": -16,
      "y": 38,
      "z": 0,
      "name": "Wood_Tropicalwood_Roof_Flat",
      "rotation": 3
    },
    {
      "x": -16,
      "y": 60,
      "z": 0,
      "name": "Plant_Leaves_Beech",
      "support": 15,
      "rotation": 2
    },
    {
      "x": -16,
      "y": 61,
      "z": 0,
      "name": "Plant_Leaves_Beech",
      "support": 15,
      "rotation": 2
    },
    {
      "x": -16,
      "y": 64,
      "z": 0,
      "name": "Plant_Leaves_Beech",
      "support": 15,
      "rotation": 2
    },
    {
      "x": -16,
      "y": 4,
      "z": 1,
      "name": "Wood_Sallow_Roots",
      "rotation": 2
    },
    {
      "x": -16,
      "y": 5,
      "z": 1,
      "name": "Wood_Sallow_Trunk_Full",
      "support": 15,
      "rotation": 2
    },
    {
      "x": -16,
      "y": 6,
      "z": 1,
      "name": "Wood_Sallow_Trunk",
      "support": 15,
      "rotation": 2
    },
    {
      "x": -16,
      "y": 7,
      "z": 1,
      "name": "Wood_Sallow_Trunk",
      "support": 15,
      "rotation": 2
    },
    {
      "x": -16,
      "y": 8,
      "z": 1,
      "name": "Wood_Sallow_Trunk",
      "support": 15,
      "rotation": 2
    },
    {
      "x": -16,
      "y": 9,
      "z": 1,
      "name": "Wood_Sallow_Trunk",
      "support": 15,
      "rotation": 2
    },
    {
      "x": -16,
      "y": 10,
      "z": 1,
      "name": "Wood_Sallow_Trunk",
      "support": 15,
      "rotation": 2
    },
    {
      "x": -16,
      "y": 11,
      "z": 1,
      "name": "Wood_Sallow_Trunk_Full",
      "support": 15,
      "rotation": 2
    },
    {
      "x": -16,
      "y": 12,
      "z": 1,
      "name": "Plant_Moss_Rug_Green_Dark",
      "support": 15,
      "rotation": 2
    },
    {
      "x": -16,
      "y": 29,
      "z": 1,
      "name": "Furniture_Crude_Platform",
      "rotation": 1
    },
    {
      "x": -16,
      "y": 30,
      "z": 1,
      "name": "*Wood_Softwood_Fence_State_Definitions_Corner",
      "rotation": 1
    },
    {
      "x": -16,
      "y": 31,
      "z": 1,
      "name": "*Wood_Softwood_Fence_State_Definitions_Corner",
      "rotation": 1
    },
    {
      "x": -16,
      "y": 32,
      "z": 1,
      "name": "*Wood_Softwood_Fence_State_Definitions_Corner",
      "rotation": 1
    },
    {
      "x": -16,
      "y": 33,
      "z": 1,
      "name": "*Wood_Goldenwood_Stairs_State_Definitions_Corner_Right",
      "rotation": 8
    },
    {
      "x": -16,
      "y": 34,
      "z": 1,
      "name": "*Wood_Softwood_Fence_State_Definitions_Corner",
      "rotation": 1
    },
    {
      "x": -16,
      "y": 35,
      "z": 1,
      "name": "*Wood_Softwood_Fence_State_Definitions_Corner",
      "rotation": 1
    },
    {
      "x": -16,
      "y": 36,
      "z": 1,
      "name": "*Wood_Softwood_Fence_State_Definitions_Corner",
      "rotation": 1
    },
    {
      "x": -16,
      "y": 37,
      "z": 1,
      "name": "*Wood_Goldenwood_Stairs_State_Definitions_Corner_Left",
      "rotation": 9
    },
    {
      "x": -16,
      "y": 38,
      "z": 1,
      "name": "*Wood_Hardwood_Fence_State_Definitions_Corner",
      "rotation": 1
    },
    {
      "x": -16,
      "y": 41,
      "z": 1,
      "name": "*Wood_Tropicalwood_Roof_Hollow_State_Definitions_Corner_Left",
      "rotation": 2
    },
    {
      "x": -16,
      "y": 61,
      "z": 1,
      "name": "Wood_Sallow_Branch_Long",
      "support": 15,
      "rotation": 7
    },
    {
      "x": -16,
      "y": 64,
      "z": 1,
      "name": "Wood_Sallow_Branch_Long",
      "support": 15,
      "rotation": 7
    },
    {
      "x": -16,
      "y": 66,
      "z": 1,
      "name": "Plant_Leaves_Beech",
      "support": 15,
      "rotation": 2
    },
    {
      "x": -16,
      "y": 6,
      "z": 2,
      "name": "Wood_Sallow_Trunk_Full",
      "support": 15,
      "rotation": 2
    },
    {
      "x": -16,
      "y": 7,
      "z": 2,
      "name": "Wood_Sallow_Trunk",
      "support": 15,
      "rotation": 2
    },
    {
      "x": -16,
      "y": 8,
      "z": 2,
      "name": "Wood_Sallow_Trunk",
      "support": 15,
      "rotation": 2
    },
    {
      "x": -16,
      "y": 9,
      "z": 2,
      "name": "Wood_Sallow_Trunk_Full",
      "support": 15,
      "rotation": 2
    },
    {
      "x": -16,
      "y": 11,
      "z": 2,
      "name": "Plant_Moss_Wall_Green_Dark",
      "support": 15
    },
    {
      "x": -16,
      "y": 29,
      "z": 2,
      "name": "Furniture_Crude_Platform",
      "rotation": 1
    },
    {
      "x": -16,
      "y": 30,
      "z": 2,
      "name": "Wood_Softwood_Fence",
      "rotation": 3
    },
    {
      "x": -16,
      "y": 31,
      "z": 2,
      "name": "Wood_Goldenwood_Fence",
      "rotation": 3
    },
    {
      "x": -16,
      "y": 32,
      "z": 2,
      "name": "Wood_Softwood_Fence",
      "rotation": 3
    },
    {
      "x": -16,
      "y": 33,
      "z": 2,
      "name": "Wood_Goldenwood_Stairs",
      "rotation": 9
    },
    {
      "x": -16,
      "y": 34,
      "z": 2,
      "name": "Wood_Softwood_Fence",
      "rotation": 3
    },
    {
      "x": -16,
      "y": 35,
      "z": 2,
      "name": "Wood_Softwood_Fence",
      "rotation": 3
    },
    {
      "x": -16,
      "y": 36,
      "z": 2,
      "name": "Wood_Softwood_Fence",
      "rotation": 3
    },
    {
      "x": -16,
      "y": 37,
      "z": 2,
      "name": "Wood_Goldenwood_Stairs",
      "rotation": 9
    },
    {
      "x": -16,
      "y": 38,
      "z": 2,
      "name": "*Wood_Hardwood_Fence_State_Definitions_Corner",
      "rotation": 3
    },
    {
      "x": -16,
      "y": 41,
      "z": 2,
      "name": "*Wood_Tropicalwood_Roof_Hollow_State_Definitions_Inverted_Corner_Right",
      "rotation": 3
    },
    {
      "x": -16,
      "y": 29,
      "z": 3,
      "name": "Furniture_Crude_Platform",
      "rotation": 1
    },
    {
      "x": -16,
      "y": 30,
      "z": 3,
      "name": "*Wood_Softwood_Fence_State_Definitions_Corner",
      "rotation": 3
    },
    {
      "x": -16,
      "y": 31,
      "z": 3,
      "name": "*Wood_Softwood_Fence_State_Definitions_Corner",
      "rotation": 3
    },
    {
      "x": -16,
      "y": 32,
      "z": 3,
      "name": "*Wood_Softwood_Fence_State_Definitions_Corner",
      "rotation": 3
    },
    {
      "x": -16,
      "y": 33,
      "z": 3,
      "name": "*Wood_Goldenwood_Stairs_State_Definitions_Inverted_Corner_Left",
      "rotation": 9
    },
    {
      "x": -16,
      "y": 34,
      "z": 3,
      "name": "*Wood_Softwood_Fence_State_Definitions_Corner",
      "rotation": 3
    },
    {
      "x": -16,
      "y": 35,
      "z": 3,
      "name": "*Wood_Softwood_Fence_State_Definitions_Corner",
      "rotation": 3
    },
    {
      "x": -16,
      "y": 36,
      "z": 3,
      "name": "*Wood_Softwood_Fence_State_Definitions_Corner",
      "rotation": 3
    },
    {
      "x": -16,
      "y": 37,
      "z": 3,
      "name": "*Wood_Goldenwood_Stairs_State_Definitions_Inverted_Corner_Right",
      "rotation": 8
    },
    {
      "x": -16,
      "y": 42,
      "z": 3,
      "name": "Wood_Tropicalwood_Roof_Flat",
      "rotation": 1
    },
    {
      "x": -16,
      "y": 59,
      "z": 3,
      "name": "Plant_Leaves_Beech",
      "support": 15,
      "rotation": 2
    },
    {
      "x": -16,
      "y": 60,
      "z": 3,
      "name": "Plant_Leaves_Beech",
      "support": 15,
      "rotation": 2
    },
    {
      "x": -16,
      "y": 29,
      "z": 4,
      "name": "Wood_Goldenwood_Planks_Half",
      "rotation": 8
    },
    {
      "x": -16,
      "y": 33,
      "z": 4,
      "name": "Wood_Goldenwood_Planks_Half",
      "rotation": 8
    },
    {
      "x": -16,
      "y": 37,
      "z": 4,
      "name": "Wood_Goldenwood_Planks_Half",
      "rotation": 8
    },
    {
      "x": -16,
      "y": 42,
      "z": 4,
      "name": "Wood_Tropicalwood_Roof_Flat",
      "rotation": 1
    },
    {
      "x": -16,
      "y": 55,
      "z": 4,
      "name": "Plant_Leaves_Beech",
      "support": 15,
      "rotation": 2
    },
    {
      "x": -16,
      "y": 56,
      "z": 4,
      "name": "Plant_Leaves_Beech",
      "support": 15,
      "rotation": 2
    },
    {
      "x": -16,
      "y": 58,
      "z": 4,
      "name": "Plant_Leaves_Beech",
      "support": 15,
      "rotation": 2
    },
    {
      "x": -16,
      "y": 59,
      "z": 4,
      "name": "Wood_Sallow_Branch_Corner",
      "support": 15,
      "rotation": 3
    },
    {
      "x": -16,
      "y": 60,
      "z": 4,
      "name": "Wood_Sallow_Branch_Long",
      "support": 15,
      "rotation": 2
    },
    {
      "x": -16,
      "y": 61,
      "z": 4,
      "name": "Plant_Leaves_Beech",
      "support": 15,
      "rotation": 2
    },
    {
      "x": -16,
      "y": 4,
      "z": 5,
      "name": "Wood_Sallow_Roots",
      "rotation": 2
    },
    {
      "x": -16,
      "y": 5,
      "z": 5,
      "name": "Wood_Sallow_Trunk_Full",
      "support": 15,
      "rotation": 2
    },
    {
      "x": -16,
      "y": 6,
      "z": 5,
      "name": "Wood_Sallow_Trunk",
      "support": 15,
      "rotation": 2
    },
    {
      "x": -16,
      "y": 7,
      "z": 5,
      "name": "Wood_Sallow_Trunk",
      "support": 15,
      "rotation": 2
    },
    {
      "x": -16,
      "y": 8,
      "z": 5,
      "name": "Wood_Sallow_Trunk",
      "support": 15,
      "rotation": 2
    },
    {
      "x": -16,
      "y": 9,
      "z": 5,
      "name": "Wood_Sallow_Trunk",
      "support": 15,
      "rotation": 2
    },
    {
      "x": -16,
      "y": 10,
      "z": 5,
      "name": "Wood_Sallow_Trunk",
      "support": 15,
      "rotation": 2
    },
    {
      "x": -16,
      "y": 11,
      "z": 5,
      "name": "Wood_Sallow_Trunk_Full",
      "support": 15,
      "rotation": 2
    },
    {
      "x": -16,
      "y": 29,
      "z": 5,
      "name": "Wood_Goldenwood_Planks_Half",
      "rotation": 8
    },
    {
      "x": -16,
      "y": 33,
      "z": 5,
      "name": "Wood_Goldenwood_Planks_Half",
      "rotation": 8
    },
    {
      "x": -16,
      "y": 37,
      "z": 5,
      "name": "Wood_Goldenwood_Planks_Half",
      "rotation": 8
    },
    {
      "x": -16,
      "y": 42,
      "z": 5,
      "name": "Wood_Tropicalwood_Roof_Flat",
      "rotation": 1
    },
    {
      "x": -16,
      "y": 55,
      "z": 5,
      "name": "Plant_Leaves_Beech",
      "support": 15,
      "rotation": 2
    },
    {
      "x": -16,
      "y": 56,
      "z": 5,
      "name": "Wood_Sallow_Branch_Corner",
      "support": 15,
      "rotation": 3
    },
    {
      "x": -16,
      "y": 57,
      "z": 5,
      "name": "Plant_Leaves_Beech",
      "support": 15,
      "rotation": 2
    },
    {
      "x": -16,
      "y": 59,
      "z": 5,
      "name": "Plant_Leaves_Beech",
      "support": 15,
      "rotation": 2
    },
    {
      "x": -16,
      "y": 60,
      "z": 5,
      "name": "Plant_Leaves_Beech",
      "support": 15,
      "rotation": 2
    },
    {
      "x": -16,
      "y": 29,
      "z": 6,
      "name": "Wood_Goldenwood_Planks_Half",
      "rotation": 8
    },
    {
      "x": -16,
      "y": 33,
      "z": 6,
      "name": "Wood_Goldenwood_Planks_Half",
      "rotation": 8
    },
    {
      "x": -16,
      "y": 37,
      "z": 6,
      "name": "Wood_Goldenwood_Planks_Half",
      "rotation": 8
    },
    {
      "x": -16,
      "y": 42,
      "z": 6,
      "name": "Wood_Tropicalwood_Roof_Flat",
      "rotation": 3
    },
    {
      "x": -16,
      "y": 56,
      "z": 6,
      "name": "Plant_Leaves_Beech",
      "support": 15,
      "rotation": 2
    },
    {
      "x": -16,
      "y": 65,
      "z": 6,
      "name": "Plant_Leaves_Beech",
      "support": 15,
      "rotation": 2
    },
    {
      "x": -16,
      "y": 66,
      "z": 6,
      "name": "Plant_Leaves_Beech",
      "support": 15,
      "rotation": 2
    },
    {
      "x": -16,
      "y": 69,
      "z": 6,
      "name": "Plant_Leaves_Beech",
      "support": 15,
      "rotation": 2
    },
    {
      "x": -16,
      "y": 29,
      "z": 7,
      "name": "Furniture_Crude_Platform",
      "rotation": 1
    },
    {
      "x": -16,
      "y": 30,
      "z": 7,
      "name": "*Wood_Softwood_Fence_State_Definitions_Corner"
    },
    {
      "x": -16,
      "y": 31,
      "z": 7,
      "name": "*Wood_Softwood_Fence_State_Definitions_Corner"
    },
    {
      "x": -16,
      "y": 32,
      "z": 7,
      "name": "*Wood_Softwood_Fence_State_Definitions_Corner"
    },
    {
      "x": -16,
      "y": 33,
      "z": 7,
      "name": "*Wood_Goldenwood_Stairs_State_Definitions_Inverted_Corner_Left",
      "rotation": 10
    },
    {
      "x": -16,
      "y": 34,
      "z": 7,
      "name": "*Wood_Softwood_Fence_State_Definitions_Corner"
    },
    {
      "x": -16,
      "y": 35,
      "z": 7,
      "name": "*Wood_Softwood_Fence_State_Definitions_Corner"
    },
    {
      "x": -16,
      "y": 36,
      "z": 7,
      "name": "*Wood_Softwood_Fence_State_Definitions_Corner"
    },
    {
      "x": -16,
      "y": 37,
      "z": 7,
      "name": "*Wood_Goldenwood_Stairs_State_Definitions_Inverted_Corner_Right",
      "rotation": 9
    },
    {
      "x": -16,
      "y": 42,
      "z": 7,
      "name": "Wood_Tropicalwood_Roof_Flat",
      "rotation": 3
    },
    {
      "x": -16,
      "y": 64,
      "z": 7,
      "name": "Wood_Sallow_Branch_Corner",
      "support": 15,
      "rotation": 3
    },
    {
      "x": -16,
      "y": 65,
      "z": 7,
      "name": "Wood_Sallow_Branch_Long",
      "support": 15,
      "rotation": 2
    },
    {
      "x": -16,
      "y": 66,
      "z": 7,
      "name": "Plant_Leaves_Beech",
      "support": 15,
      "rotation": 2
    },
    {
      "x": -16,
      "y": 67,
      "z": 7,
      "name": "Plant_Leaves_Beech",
      "support": 15,
      "rotation": 2
    },
    {
      "x": -16,
      "y": 68,
      "z": 7,
      "name": "Plant_Leaves_Beech",
      "support": 15,
      "rotation": 2
    },
    {
      "x": -16,
      "y": 69,
      "z": 7,
      "name": "Plant_Leaves_Beech",
      "support": 15,
      "rotation": 2
    },
    {
      "x": -16,
      "y": 70,
      "z": 7,
      "name": "Plant_Leaves_Beech",
      "support": 15,
      "rotation": 2
    },
    {
      "x": -16,
      "y": 29,
      "z": 8,
      "name": "Furniture_Crude_Platform",
      "rotation": 1
    },
    {
      "x": -16,
      "y": 30,
      "z": 8,
      "name": "Wood_Softwood_Fence",
      "rotation": 3
    },
    {
      "x": -16,
      "y": 31,
      "z": 8,
      "name": "Wood_Goldenwood_Fence",
      "rotation": 3
    },
    {
      "x": -16,
      "y": 32,
      "z": 8,
      "name": "Wood_Softwood_Fence",
      "rotation": 3
    },
    {
      "x": -16,
      "y": 33,
      "z": 8,
      "name": "Wood_Goldenwood_Stairs",
      "rotation": 9
    },
    {
      "x": -16,
      "y": 34,
      "z": 8,
      "name": "Wood_Softwood_Fence",
      "rotation": 3
    },
    {
      "x": -16,
      "y": 35,
      "z": 8,
      "name": "Wood_Softwood_Fence",
      "rotation": 3
    },
    {
      "x": -16,
      "y": 36,
      "z": 8,
      "name": "Wood_Softwood_Fence",
      "rotation": 3
    },
    {
      "x": -16,
      "y": 37,
      "z": 8,
      "name": "Wood_Goldenwood_Stairs",
      "rotation": 9
    },
    {
      "x": -16,
      "y": 38,
      "z": 8,
      "name": "*Wood_Hardwood_Fence_State_Definitions_Corner"
    },
    {
      "x": -16,
      "y": 41,
      "z": 8,
      "name": "*Wood_Tropicalwood_Roof_Hollow_State_Definitions_Inverted_Corner_Right"
    },
    {
      "x": -16,
      "y": 59,
      "z": 8,
      "name": "Wood_Sallow_Branch_Long",
      "support": 15,
      "rotation": 7
    },
    {
      "x": -16,
      "y": 65,
      "z": 8,
      "name": "Plant_Leaves_Beech",
      "support": 15,
      "rotation": 2
    },
    {
      "x": -16,
      "y": 66,
      "z": 8,
      "name": "Plant_Leaves_Beech",
      "support": 15,
      "rotation": 2
    },
    {
      "x": -16,
      "y": 67,
      "z": 8,
      "name": "Wood_Sallow_Branch_Corner",
      "support": 15,
      "rotation": 3
    },
    {
      "x": -16,
      "y": 68,
      "z": 8,
      "name": "Wood_Sallow_Branch_Long",
      "support": 15,
      "rotation": 2
    },
    {
      "x": -16,
      "y": 69,
      "z": 8,
      "name": "Plant_Leaves_Beech",
      "support": 15,
      "rotation": 2
    },
    {
      "x": -16,
      "y": 70,
      "z": 8,
      "name": "Plant_Leaves_Beech",
      "support": 15,
      "rotation": 2
    },
    {
      "x": -16,
      "y": 6,
      "z": 9,
      "name": "Wood_Sallow_Trunk_Full",
      "support": 15,
      "rotation": 2
    },
    {
      "x": -16,
      "y": 7,
      "z": 9,
      "name": "Wood_Sallow_Trunk",
      "support": 15,
      "rotation": 2
    },
    {
      "x": -16,
      "y": 8,
      "z": 9,
      "name": "Wood_Sallow_Trunk",
      "support": 15,
      "rotation": 2
    },
    {
      "x": -16,
      "y": 9,
      "z": 9,
      "name": "Wood_Sallow_Trunk_Full",
      "support": 15,
      "rotation": 7
    },
    {
      "x": -16,
      "y": 29,
      "z": 9,
      "name": "Furniture_Crude_Platform",
      "rotation": 1
    },
    {
      "x": -16,
      "y": 30,
      "z": 9,
      "name": "*Wood_Softwood_Fence_State_Definitions_Corner",
      "rotation": 2
    },
    {
      "x": -16,
      "y": 31,
      "z": 9,
      "name": "*Wood_Softwood_Fence_State_Definitions_Corner",
      "rotation": 2
    },
    {
      "x": -16,
      "y": 32,
      "z": 9,
      "name": "*Wood_Softwood_Fence_State_Definitions_Corner",
      "rotation": 2
    },
    {
      "x": -16,
      "y": 33,
      "z": 9,
      "name": "*Wood_Goldenwood_Stairs_State_Definitions_Corner_Right",
      "rotation": 9
    },
    {
      "x": -16,
      "y": 34,
      "z": 9,
      "name": "*Wood_Softwood_Fence_State_Definitions_Corner",
      "rotation": 2
    },
    {
      "x": -16,
      "y": 35,
      "z": 9,
      "name": "*Wood_Softwood_Fence_State_Definitions_Corner",
      "rotation": 2
    },
    {
      "x": -16,
      "y": 36,
      "z": 9,
      "name": "*Wood_Softwood_Fence_State_Definitions_Corner",
      "rotation": 2
    },
    {
      "x": -16,
      "y": 37,
      "z": 9,
      "name": "*Wood_Goldenwood_Stairs_State_Definitions_Corner_Left",
      "rotation": 10
    },
    {
      "x": -16,
      "y": 38,
      "z": 9,
      "name": "*Wood_Hardwood_Fence_State_Definitions_Corner",
      "rotation": 2
    },
    {
      "x": -16,
      "y": 41,
      "z": 9,
      "name": "*Wood_Tropicalwood_Roof_Hollow_State_Definitions_Corner_Left",
      "rotation": 3
    },
    {
      "x": -16,
      "y": 62,
      "z": 9,
      "name": "Plant_Leaves_Beech",
      "support": 15,
      "rotation": 2
    },
    {
      "x": -16,
      "y": 67,
      "z": 9,
      "name": "Plant_Leaves_Beech",
      "support": 15,
      "rotation": 2
    },
    {
      "x": -16,
      "y": 68,
      "z": 9,
      "name": "Plant_Leaves_Beech",
      "support": 15,
      "rotation": 2
    },
    {
      "x": -16,
      "y": 69,
      "z": 9,
      "name": "Plant_Leaves_Beech",
      "support": 15,
      "rotation": 2
    },
    {
      "x": -16,
      "y": 5,
      "z": 10,
      "name": "Wood_Sallow_Roots",
      "rotation": 2
    },
    {
      "x": -16,
      "y": 6,
      "z": 10,
      "name": "Wood_Sallow_Trunk_Full",
      "support": 15,
      "rotation": 2
    },
    {
      "x": -16,
      "y": 7,
      "z": 10,
      "name": "Wood_Sallow_Trunk",
      "support": 15,
      "rotation": 2
    },
    {
      "x": -16,
      "y": 8,
      "z": 10,
      "name": "Wood_Sallow_Trunk",
      "support": 15,
      "rotation": 2
    },
    {
      "x": -16,
      "y": 9,
      "z": 10,
      "name": "Wood_Sallow_Trunk",
      "support": 15,
      "rotation": 2
    },
    {
      "x": -16,
      "y": 10,
      "z": 10,
      "name": "Wood_Sallow_Trunk",
      "support": 15,
      "rotation": 2
    },
    {
      "x": -16,
      "y": 11,
      "z": 10,
      "name": "Wood_Sallow_Trunk_Full",
      "support": 15,
      "rotation": 2
    },
    {
      "x": -16,
      "y": 33,
      "z": 10,
      "name": "Furniture_Crude_Platform"
    },
    {
      "x": -16,
      "y": 37,
      "z": 10,
      "name": "Wood_Goldenwood_Planks_Half",
      "rotation": 8
    },
    {
      "x": -16,
      "y": 38,
      "z": 10,
      "name": "Wood_Tropicalwood_Roof_Flat",
      "rotation": 3
    },
    {
      "x": -16,
      "y": 60,
      "z": 10,
      "name": "Wood_Sallow_Trunk",
      "support": 15,
      "rotation": 7
    },
    {
      "x": -16,
      "y": 65,
      "z": 10,
      "name": "Wood_Sallow_Branch_Corner",
      "support": 15,
      "rotation": 51
    },
    {
      "x": -16,
      "y": 66,
      "z": 10,
      "name": "Plant_Leaves_Beech",
      "support": 15,
      "rotation": 2
    },
    {
      "x": -16,
      "y": 4,
      "z": 11,
      "name": "Wood_Sallow_Roots",
      "rotation": 2
    },
    {
      "x": -16,
      "y": 5,
      "z": 11,
      "name": "Wood_Sallow_Trunk_Full",
      "support": 15,
      "rotation": 2
    },
    {
      "x": -16,
      "y": 6,
      "z": 11,
      "name": "Wood_Sallow_Trunk",
      "support": 15,
      "rotation": 2
    },
    {
      "x": -16,
      "y": 7,
      "z": 11,
      "name": "Wood_Sallow_Trunk",
      "support": 15,
      "rotation": 2
    },
    {
      "x": -16,
      "y": 8,
      "z": 11,
      "name": "Wood_Sallow_Trunk",
      "support": 15,
      "rotation": 2
    },
    {
      "x": -16,
      "y": 9,
      "z": 11,
      "name": "Wood_Sallow_Trunk",
      "support": 15,
      "rotation": 2
    },
    {
      "x": -16,
      "y": 10,
      "z": 11,
      "name": "Wood_Sallow_Trunk",
      "support": 15,
      "rotation": 2
    },
    {
      "x": -16,
      "y": 11,
      "z": 11,
      "name": "Wood_Sallow_Trunk_Full",
      "support": 15,
      "rotation": 2
    },
    {
      "x": -16,
      "y": 33,
      "z": 11,
      "name": "Furniture_Crude_Platform"
    },
    {
      "x": -16,
      "y": 34,
      "z": 11,
      "name": "*Wood_Hardwood_Fence_State_Definitions_Corner"
    },
    {
      "x": -16,
      "y": 37,
      "z": 11,
      "name": "*Wood_Tropicalwood_Roof_Hollow_State_Definitions_Inverted_Corner_Right"
    },
    {
      "x": -16,
      "y": 64,
      "z": 11,
      "name": "Plant_Leaves_Beech",
      "support": 15,
      "rotation": 2
    },
    {
      "x": -16,
      "y": 65,
      "z": 11,
      "name": "Wood_Sallow_Branch_Corner",
      "support": 15
    },
    {
      "x": -16,
      "y": 66,
      "z": 11,
      "name": "Wood_Sallow_Branch_Long",
      "support": 15,
      "rotation": 2
    },
    {
      "x": -16,
      "y": 67,
      "z": 11,
      "name": "Plant_Leaves_Beech",
      "support": 15,
      "rotation": 2
    },
    {
      "x": -16,
      "y": 33,
      "z": 12,
      "name": "Furniture_Crude_Platform"
    },
    {
      "x": -16,
      "y": 34,
      "z": 12,
      "name": "*Wood_Hardwood_Fence_State_Definitions_Corner",
      "rotation": 2
    },
    {
      "x": -16,
      "y": 37,
      "z": 12,
      "name": "*Wood_Tropicalwood_Roof_Hollow_State_Definitions_Corner_Left",
      "rotation": 3
    },
    {
      "x": -16,
      "y": 65,
      "z": 12,
      "name": "Plant_Leaves_Beech",
      "support": 15,
      "rotation": 2
    },
    {
      "x": -16,
      "y": 66,
      "z": 12,
      "name": "Plant_Leaves_Beech",
      "support": 15,
      "rotation": 2
    },
    {
      "x": -16,
      "y": 61,
      "z": 13,
      "name": "Plant_Leaves_Beech",
      "support": 15,
      "rotation": 2
    },
    {
      "x": -16,
      "y": 62,
      "z": 13,
      "name": "Plant_Leaves_Beech",
      "support": 15,
      "rotation": 2
    },
    {
      "x": -16,
      "y": 61,
      "z": 14,
      "name": "Plant_Leaves_Beech",
      "support": 15,
      "rotation": 2
    },
    {
      "x": -16,
      "y": 62,
      "z": 14,
      "name": "Plant_Leaves_Beech",
      "support": 15,
      "rotation": 2
    },
    {
      "x": -16,
      "y": 63,
      "z": 14,
      "name": "Plant_Leaves_Beech",
      "support": 15,
      "rotation": 2
    },
    {
      "x": -16,
      "y": 62,
      "z": 15,
      "name": "Plant_Leaves_Beech",
      "support": 15,
      "rotation": 2
    },
    {
      "x": -15,
      "y": 33,
      "z": -3,
      "name": "Furniture_Crude_Platform",
      "rotation": 1
    },
    {
      "x": -15,
      "y": 34,
      "z": -3,
      "name": "*Wood_Hardwood_Fence_State_Definitions_Corner",
      "rotation": 1
    },
    {
      "x": -15,
      "y": 35,
      "z": -3,
      "name": "Wood_Hardwood_Beam"
    },
    {
      "x": -15,
      "y": 36,
      "z": -3,
      "name": "Wood_Hardwood_Beam"
    },
    {
      "x": -15,
      "y": 37,
      "z": -3,
      "name": "*Wood_Tropicalwood_Roof_State_Definitions_Corner_Left",
      "rotation": 2
    },
    {
      "x": -15,
      "y": 33,
      "z": -2,
      "name": "Furniture_Crude_Platform"
    },
    {
      "x": -15,
      "y": 34,
      "z": -2,
      "name": "*Wood_Hardwood_Fence_State_Definitions_Corner",
      "rotation": 3
    },
    {
      "x": -15,
      "y": 37,
      "z": -2,
      "name": "*Wood_Tropicalwood_Roof_Hollow_State_Definitions_Inverted_Corner_Right",
      "rotation": 3
    },
    {
      "x": -15,
      "y": 58,
      "z": -2,
      "name": "Plant_Leaves_Beech",
      "support": 15,
      "rotation": 2
    },
    {
      "x": -15,
      "y": 59,
      "z": -2,
      "name": "Plant_Leaves_Beech",
      "support": 15,
      "rotation": 2
    },
    {
      "x": -15,
      "y": 64,
      "z": -2,
      "name": "Plant_Leaves_Beech",
      "support": 15,
      "rotation": 2
    },
    {
      "x": -15,
      "y": 65,
      "z": -2,
      "name": "Plant_Leaves_Beech",
      "support": 15,
      "rotation": 2
    },
    {
      "x": -15,
      "y": 33,
      "z": -1,
      "name": "Furniture_Crude_Platform"
    },
    {
      "x": -15,
      "y": 37,
      "z": -1,
      "name": "Wood_Goldenwood_Planks_Half",
      "rotation": 8
    },
    {
      "x": -15,
      "y": 38,
      "z": -1,
      "name": "Wood_Tropicalwood_Roof_Flat",
      "rotation": 2
    },
    {
      "x": -15,
      "y": 63,
      "z": -1,
      "name": "Plant_Leaves_Beech",
      "support": 15,
      "rotation": 2
    },
    {
      "x": -15,
      "y": 64,
      "z": -1,
      "name": "Wood_Sallow_Branch_Corner",
      "support": 15,
      "rotation": 2
    },
    {
      "x": -15,
      "y": 65,
      "z": -1,
      "name": "Wood_Sallow_Branch_Long",
      "support": 15,
      "rotation": 2
    },
    {
      "x": -15,
      "y": 66,
      "z": -1,
      "name": "Plant_Leaves_Beech",
      "support": 15,
      "rotation": 2
    },
    {
      "x": -15,
      "y": 29,
      "z": 0,
      "name": "Furniture_Crude_Platform"
    },
    {
      "x": -15,
      "y": 30,
      "z": 0,
      "name": "*Wood_Softwood_Fence_State_Definitions_Corner",
      "rotation": 1
    },
    {
      "x": -15,
      "y": 31,
      "z": 0,
      "name": "*Wood_Softwood_Fence_State_Definitions_Corner",
      "rotation": 1
    },
    {
      "x": -15,
      "y": 32,
      "z": 0,
      "name": "*Wood_Softwood_Fence_State_Definitions_Corner",
      "rotation": 1
    },
    {
      "x": -15,
      "y": 33,
      "z": 0,
      "name": "*Wood_Goldenwood_Stairs_State_Definitions_Corner_Right",
      "rotation": 8
    },
    {
      "x": -15,
      "y": 34,
      "z": 0,
      "name": "*Wood_Softwood_Fence_State_Definitions_Corner",
      "rotation": 1
    },
    {
      "x": -15,
      "y": 35,
      "z": 0,
      "name": "*Wood_Softwood_Fence_State_Definitions_Corner",
      "rotation": 1
    },
    {
      "x": -15,
      "y": 36,
      "z": 0,
      "name": "*Wood_Softwood_Fence_State_Definitions_Corner",
      "rotation": 1
    },
    {
      "x": -15,
      "y": 37,
      "z": 0,
      "name": "Wood_Goldenwood_Stairs",
      "rotation": 9
    },
    {
      "x": -15,
      "y": 38,
      "z": 0,
      "name": "*Wood_Hardwood_Fence_State_Definitions_Corner",
      "rotation": 1
    },
    {
      "x": -15,
      "y": 39,
      "z": 0,
      "name": "Wood_Hardwood_Beam"
    },
    {
      "x": -15,
      "y": 40,
      "z": 0,
      "name": "Wood_Hardwood_Beam"
    },
    {
      "x": -15,
      "y": 41,
      "z": 0,
      "name": "*Wood_Tropicalwood_Roof_State_Definitions_Corner_Left",
      "rotation": 2
    },
    {
      "x": -15,
      "y": 64,
      "z": 0,
      "name": "Wood_Sallow_Branch_Long",
      "support": 15,
      "rotation": 6
    },
    {
      "x": -15,
      "y": 65,
      "z": 0,
      "name": "Plant_Leaves_Beech",
      "support": 15,
      "rotation": 2
    },
    {
      "x": -15,
      "y": 66,
      "z": 0,
      "name": "Plant_Leaves_Beech",
      "support": 15,
      "rotation": 2
    },
    {
      "x": -15,
      "y": 67,
      "z": 0,
      "name": "Plant_Leaves_Beech",
      "support": 15,
      "rotation": 2
    },
    {
      "x": -15,
      "y": 6,
      "z": 1,
      "name": "Wood_Sallow_Trunk_Full",
      "support": 15,
      "rotation": 2
    },
    {
      "x": -15,
      "y": 7,
      "z": 1,
      "name": "Wood_Sallow_Trunk",
      "support": 15,
      "rotation": 2
    },
    {
      "x": -15,
      "y": 8,
      "z": 1,
      "name": "Wood_Sallow_Trunk",
      "support": 15,
      "rotation": 2
    },
    {
      "x": -15,
      "y": 9,
      "z": 1,
      "name": "Wood_Sallow_Trunk",
      "support": 15,
      "rotation": 2
    },
    {
      "x": -15,
      "y": 10,
      "z": 1,
      "name": "Wood_Sallow_Trunk",
      "support": 15,
      "rotation": 2
    },
    {
      "x": -15,
      "y": 11,
      "z": 1,
      "name": "Wood_Sallow_Trunk",
      "support": 15,
      "rotation": 2
    },
    {
      "x": -15,
      "y": 12,
      "z": 1,
      "name": "Wood_Sallow_Trunk_Full",
      "support": 15,
      "rotation": 2
    },
    {
      "x": -15,
      "y": 29,
      "z": 1,
      "name": "Furniture_Crude_Platform",
      "rotation": 1
    },
    {
      "x": -15,
      "y": 30,
      "z": 1,
      "name": "*Wood_Softwood_Fence_State_Definitions_Corner",
      "rotation": 3
    },
    {
      "x": -15,
      "y": 31,
      "z": 1,
      "name": "*Wood_Softwood_Fence_State_Definitions_Corner",
      "rotation": 3
    },
    {
      "x": -15,
      "y": 32,
      "z": 1,
      "name": "*Wood_Softwood_Fence_State_Definitions_Corner",
      "rotation": 3
    },
    {
      "x": -15,
      "y": 33,
      "z": 1,
      "name": "*Wood_Goldenwood_Stairs_State_Definitions_Inverted_Corner_Left",
      "rotation": 9
    },
    {
      "x": -15,
      "y": 34,
      "z": 1,
      "name": "*Wood_Softwood_Fence_State_Definitions_Corner",
      "rotation": 3
    },
    {
      "x": -15,
      "y": 35,
      "z": 1,
      "name": "*Wood_Softwood_Fence_State_Definitions_Corner",
      "rotation": 3
    },
    {
      "x": -15,
      "y": 36,
      "z": 1,
      "name": "*Wood_Softwood_Fence_State_Definitions_Corner",
      "rotation": 3
    },
    {
      "x": -15,
      "y": 37,
      "z": 1,
      "name": "*Wood_Goldenwood_Stairs_State_Definitions_Inverted_Corner_Right",
      "rotation": 8
    },
    {
      "x": -15,
      "y": 38,
      "z": 1,
      "name": "*Wood_Hardwood_Fence_State_Definitions_Corner",
      "rotation": 3
    },
    {
      "x": -15,
      "y": 41,
      "z": 1,
      "name": "*Wood_Tropicalwood_Roof_Hollow_State_Definitions_Inverted_Corner_Right",
      "rotation": 3
    },
    {
      "x": -15,
      "y": 61,
      "z": 1,
      "name": "Wood_Sallow_Branch_Corner",
      "support": 15,
      "rotation": 1
    },
    {
      "x": -15,
      "y": 62,
      "z": 1,
      "name": "Wood_Sallow_Trunk_Full",
      "support": 15,
      "rotation": 7
    },
    {
      "x": -15,
      "y": 63,
      "z": 1,
      "name": "Wood_Sallow_Trunk",
      "support": 15,
      "rotation": 2
    },
    {
      "x": -15,
      "y": 64,
      "z": 1,
      "name": "Wood_Sallow_Trunk_Full",
      "support": 15,
      "rotation": 2
    },
    {
      "x": -15,
      "y": 65,
      "z": 1,
      "name": "Wood_Sallow_Branch_Long",
      "support": 15,
      "rotation": 2
    },
    {
      "x": -15,
      "y": 66,
      "z": 1,
      "name": "Wood_Sallow_Branch_Long",
      "support": 15,
      "rotation": 2
    },
    {
      "x": -15,
      "y": 67,
      "z": 1,
      "name": "Plant_Leaves_Beech",
      "support": 15,
      "rotation": 2
    },
    {
      "x": -15,
      "y": 5,
      "z": 2,
      "name": "Wood_Sallow_Roots",
      "rotation": 2
    },
    {
      "x": -15,
      "y": 6,
      "z": 2,
      "name": "Wood_Sallow_Trunk_Full",
      "support": 15,
      "rotation": 2
    },
    {
      "x": -15,
      "y": 7,
      "z": 2,
      "name": "Wood_Sallow_Trunk",
      "support": 15,
      "rotation": 2
    },
    {
      "x": -15,
      "y": 8,
      "z": 2,
      "name": "Wood_Sallow_Trunk",
      "support": 15,
      "rotation": 2
    },
    {
      "x": -15,
      "y": 9,
      "z": 2,
      "name": "Wood_Sallow_Trunk",
      "support": 15,
      "rotation": 2
    },
    {
      "x": -15,
      "y": 10,
      "z": 2,
      "name": "Wood_Sallow_Trunk",
      "support": 15,
      "rotation": 2
    },
    {
      "x": -15,
      "y": 11,
      "z": 2,
      "name": "Wood_Sallow_Trunk",
      "support": 15,
      "rotation": 2
    },
    {
      "x": -15,
      "y": 12,
      "z": 2,
      "name": "Wood_Sallow_Trunk",
      "support": 15,
      "rotation": 2
    },
    {
      "x": -15,
      "y": 13,
      "z": 2,
      "name": "Wood_Sallow_Trunk_Full",
      "support": 15,
      "rotation": 2
    },
    {
      "x": -15,
      "y": 29,
      "z": 2,
      "name": "Wood_Goldenwood_Planks_Half",
      "rotation": 8
    },
    {
      "x": -15,
      "y": 33,
      "z": 2,
      "name": "Wood_Goldenwood_Planks_Half",
      "rotation": 8
    },
    {
      "x": -15,
      "y": 37,
      "z": 2,
      "name": "Wood_Goldenwood_Planks_Half",
      "rotation": 8
    },
    {
      "x": -15,
      "y": 42,
      "z": 2,
      "name": "Wood_Tropicalwood_Roof_Flat",
      "rotation": 1
    },
    {
      "x": -15,
      "y": 66,
      "z": 2,
      "name": "Plant_Leaves_Beech",
      "support": 15,
      "rotation": 2
    },
    {
      "x": -15,
      "y": 7,
      "z": 3,
      "name": "Wood_Sallow_Trunk_Full",
      "support": 15,
      "rotation": 2
    },
    {
      "x": -15,
      "y": 8,
      "z": 3,
      "name": "Wood_Sallow_Trunk",
      "support": 15,
      "rotation": 2
    },
    {
      "x": -15,
      "y": 9,
      "z": 3,
      "name": "Wood_Sallow_Trunk",
      "support": 15,
      "rotation": 2
    },
    {
      "x": -15,
      "y": 10,
      "z": 3,
      "name": "Wood_Sallow_Trunk_Full",
      "support": 15,
      "rotation": 2
    },
    {
      "x": -15,
      "y": 29,
      "z": 3,
      "name": "Wood_Goldenwood_Planks_Half",
      "rotation": 8
    },
    {
      "x": -15,
      "y": 30,
      "z": 3,
      "name": "Furniture_Village_Chair"
    },
    {
      "x": -15,
      "y": 31,
      "z": 3,
      "name": "Furniture_Village_Chair",
      "filler": 1024
    },
    {
      "x": -15,
      "y": 33,
      "z": 3,
      "name": "Wood_Goldenwood_Planks_Half",
      "rotation": 8
    },
    {
      "x": -15,
      "y": 37,
      "z": 3,
      "name": "Wood_Goldenwood_Planks_Half",
      "rotation": 8
    },
    {
      "x": -15,
      "y": 42,
      "z": 3,
      "name": "Wood_Tropicalwood_Roof_Flat",
      "rotation": 1
    },
    {
      "x": -15,
      "y": 59,
      "z": 3,
      "name": "Plant_Leaves_Beech",
      "support": 15,
      "rotation": 2
    },
    {
      "x": -15,
      "y": 29,
      "z": 4,
      "name": "Wood_Goldenwood_Planks_Half",
      "rotation": 8
    },
    {
      "x": -15,
      "y": 33,
      "z": 4,
      "name": "Wood_Goldenwood_Planks_Half",
      "rotation": 8
    },
    {
      "x": -15,
      "y": 37,
      "z": 4,
      "name": "Wood_Goldenwood_Planks_Half",
      "rotation": 8
    },
    {
      "x": -15,
      "y": 42,
      "z": 4,
      "name": "Wood_Tropicalwood_Roof_Flat",
      "rotation": 1
    },
    {
      "x": -15,
      "y": 56,
      "z": 4,
      "name": "Plant_Leaves_Beech",
      "support": 15,
      "rotation": 2
    },
    {
      "x": -15,
      "y": 58,
      "z": 4,
      "name": "Plant_Leaves_Beech",
      "support": 15,
      "rotation": 2
    },
    {
      "x": -15,
      "y": 59,
      "z": 4,
      "name": "Wood_Sallow_Branch_Long",
      "support": 15,
      "rotation": 7
    },
    {
      "x": -15,
      "y": 60,
      "z": 4,
      "name": "Plant_Leaves_Beech",
      "support": 15,
      "rotation": 2
    },
    {
      "x": -15,
      "y": 5,
      "z": 5,
      "name": "Wood_Sallow_Roots",
      "rotation": 2
    },
    {
      "x": -15,
      "y": 6,
      "z": 5,
      "name": "Wood_Sallow_Trunk_Full",
      "support": 15,
      "rotation": 2
    },
    {
      "x": -15,
      "y": 7,
      "z": 5,
      "name": "Wood_Sallow_Trunk",
      "support": 15,
      "rotation": 2
    },
    {
      "x": -15,
      "y": 8,
      "z": 5,
      "name": "Wood_Sallow_Trunk",
      "support": 15,
      "rotation": 2
    },
    {
      "x": -15,
      "y": 9,
      "z": 5,
      "name": "Wood_Sallow_Trunk",
      "support": 15,
      "rotation": 2
    },
    {
      "x": -15,
      "y": 10,
      "z": 5,
      "name": "Wood_Sallow_Trunk",
      "support": 15,
      "rotation": 2
    },
    {
      "x": -15,
      "y": 11,
      "z": 5,
      "name": "Wood_Sallow_Trunk_Full",
      "support": 15,
      "rotation": 2
    },
    {
      "x": -15,
      "y": 29,
      "z": 5,
      "name": "Wood_Goldenwood_Planks_Half",
      "rotation": 8
    },
    {
      "x": -15,
      "y": 33,
      "z": 5,
      "name": "Wood_Goldenwood_Planks_Half",
      "rotation": 8
    },
    {
      "x": -15,
      "y": 37,
      "z": 5,
      "name": "Wood_Goldenwood_Planks_Half",
      "rotation": 8
    },
    {
      "x": -15,
      "y": 42,
      "z": 5,
      "name": "Wood_Tropicalwood_Roof_Flat",
      "rotation": 1
    },
    {
      "x": -15,
      "y": 55,
      "z": 5,
      "name": "Plant_Leaves_Beech",
      "support": 15,
      "rotation": 2
    },
    {
      "x": -15,
      "y": 56,
      "z": 5,
      "name": "Wood_Sallow_Branch_Long",
      "support": 15,
      "rotation": 7
    },
    {
      "x": -15,
      "y": 57,
      "z": 5,
      "name": "Plant_Leaves_Beech",
      "support": 15,
      "rotation": 2
    },
    {
      "x": -15,
      "y": 29,
      "z": 6,
      "name": "Wood_Goldenwood_Planks_Half",
      "rotation": 8
    },
    {
      "x": -15,
      "y": 30,
      "z": 6,
      "name": "Furniture_Village_Chair",
      "rotation": 2
    },
    {
      "x": -15,
      "y": 31,
      "z": 6,
      "name": "Furniture_Village_Chair",
      "filler": 1024,
      "rotation": 2
    },
    {
      "x": -15,
      "y": 33,
      "z": 6,
      "name": "Wood_Goldenwood_Planks_Half",
      "rotation": 8
    },
    {
      "x": -15,
      "y": 37,
      "z": 6,
      "name": "Wood_Goldenwood_Planks_Half",
      "rotation": 8
    },
    {
      "x": -15,
      "y": 42,
      "z": 6,
      "name": "Wood_Tropicalwood_Roof_Flat",
      "rotation": 1
    },
    {
      "x": -15,
      "y": 10,
      "z": 7,
      "name": "Plant_Moss_Wall_Green_Dark",
      "support": 15,
      "rotation": 2
    },
    {
      "x": -15,
      "y": 11,
      "z": 7,
      "name": "Plant_Moss_Wall_Green_Dark",
      "support": 15,
      "rotation": 3
    },
    {
      "x": -15,
      "y": 29,
      "z": 7,
      "name": "Wood_Goldenwood_Planks_Half",
      "rotation": 8
    },
    {
      "x": -15,
      "y": 33,
      "z": 7,
      "name": "Wood_Goldenwood_Planks_Half",
      "rotation": 8
    },
    {
      "x": -15,
      "y": 37,
      "z": 7,
      "name": "Wood_Goldenwood_Planks_Half",
      "rotation": 8
    },
    {
      "x": -15,
      "y": 42,
      "z": 7,
      "name": "Wood_Tropicalwood_Roof_Flat",
      "rotation": 1
    },
    {
      "x": -15,
      "y": 64,
      "z": 7,
      "name": "Wood_Sallow_Branch_Long",
      "support": 15,
      "rotation": 7
    },
    {
      "x": -15,
      "y": 67,
      "z": 7,
      "name": "Plant_Leaves_Beech",
      "support": 15,
      "rotation": 2
    },
    {
      "x": -15,
      "y": 69,
      "z": 7,
      "name": "Plant_Leaves_Beech",
      "support": 15,
      "rotation": 2
    },
    {
      "x": -15,
      "y": 7,
      "z": 8,
      "name": "Wood_Sallow_Trunk_Full",
      "support": 15,
      "rotation": 2
    },
    {
      "x": -15,
      "y": 8,
      "z": 8,
      "name": "Wood_Sallow_Trunk",
      "support": 15,
      "rotation": 2
    },
    {
      "x": -15,
      "y": 9,
      "z": 8,
      "name": "Wood_Sallow_Trunk",
      "support": 15,
      "rotation": 2
    },
    {
      "x": -15,
      "y": 10,
      "z": 8,
      "name": "Wood_Sallow_Trunk_Full",
      "support": 15,
      "rotation": 2
    },
    {
      "x": -15,
      "y": 11,
      "z": 8,
      "name": "Plant_Moss_Rug_Green_Dark",
      "support": 15,
      "rotation": 2
    },
    {
      "x": -15,
      "y": 29,
      "z": 8,
      "name": "Wood_Goldenwood_Planks_Half",
      "rotation": 8
    },
    {
      "x": -15,
      "y": 33,
      "z": 8,
      "name": "Wood_Goldenwood_Planks_Half",
      "rotation": 8
    },
    {
      "x": -15,
      "y": 37,
      "z": 8,
      "name": "Wood_Goldenwood_Planks_Half",
      "rotation": 8
    },
    {
      "x": -15,
      "y": 42,
      "z": 8,
      "name": "Wood_Tropicalwood_Roof_Flat",
      "rotation": 1
    },
    {
      "x": -15,
      "y": 59,
      "z": 8,
      "name": "Wood_Sallow_Branch_Long",
      "support": 15,
      "rotation": 7
    },
    {
      "x": -15,
      "y": 62,
      "z": 8,
      "name": "Plant_Leaves_Beech",
      "support": 15,
      "rotation": 2
    },
    {
      "x": -15,
      "y": 67,
      "z": 8,
      "name": "Wood_Sallow_Branch_Long",
      "support": 15,
      "rotation": 7
    },
    {
      "x": -15,
      "y": 68,
      "z": 8,
      "name": "Plant_Leaves_Beech",
      "support": 15,
      "rotation": 2
    },
    {
      "x": -15,
      "y": 69,
      "z": 8,
      "name": "Plant_Leaves_Beech",
      "support": 15,
      "rotation": 2
    },
    {
      "x": -15,
      "y": 6,
      "z": 9,
      "name": "Wood_Sallow_Roots",
      "rotation": 2
    },
    {
      "x": -15,
      "y": 7,
      "z": 9,
      "name": "Wood_Sallow_Trunk_Full",
      "support": 15,
      "rotation": 2
    },
    {
      "x": -15,
      "y": 8,
      "z": 9,
      "name": "Wood_Sallow_Trunk",
      "support": 15,
      "rotation": 2
    },
    {
      "x": -15,
      "y": 9,
      "z": 9,
      "name": "Wood_Sallow_Trunk",
      "support": 15,
      "rotation": 2
    },
    {
      "x": -15,
      "y": 10,
      "z": 9,
      "name": "Wood_Sallow_Trunk",
      "support": 15,
      "rotation": 2
    },
    {
      "x": -15,
      "y": 11,
      "z": 9,
      "name": "Wood_Sallow_Trunk_Full",
      "support": 15,
      "rotation": 2
    },
    {
      "x": -15,
      "y": 29,
      "z": 9,
      "name": "Furniture_Crude_Platform",
      "rotation": 1
    },
    {
      "x": -15,
      "y": 30,
      "z": 9,
      "name": "*Wood_Softwood_Fence_State_Definitions_Corner"
    },
    {
      "x": -15,
      "y": 31,
      "z": 9,
      "name": "*Wood_Softwood_Fence_State_Definitions_Corner"
    },
    {
      "x": -15,
      "y": 32,
      "z": 9,
      "name": "*Wood_Softwood_Fence_State_Definitions_Corner"
    },
    {
      "x": -15,
      "y": 33,
      "z": 9,
      "name": "*Wood_Goldenwood_Stairs_State_Definitions_Inverted_Corner_Left",
      "rotation": 10
    },
    {
      "x": -15,
      "y": 34,
      "z": 9,
      "name": "*Wood_Softwood_Fence_State_Definitions_Corner"
    },
    {
      "x": -15,
      "y": 35,
      "z": 9,
      "name": "*Wood_Softwood_Fence_State_Definitions_Corner"
    },
    {
      "x": -15,
      "y": 36,
      "z": 9,
      "name": "*Wood_Softwood_Fence_State_Definitions_Corner"
    },
    {
      "x": -15,
      "y": 37,
      "z": 9,
      "name": "*Wood_Goldenwood_Stairs_State_Definitions_Inverted_Corner_Right",
      "rotation": 9
    },
    {
      "x": -15,
      "y": 38,
      "z": 9,
      "name": "*Wood_Hardwood_Fence_State_Definitions_Corner"
    },
    {
      "x": -15,
      "y": 41,
      "z": 9,
      "name": "*Wood_Tropicalwood_Roof_Hollow_State_Definitions_Inverted_Corner_Right"
    },
    {
      "x": -15,
      "y": 59,
      "z": 9,
      "name": "Wood_Sallow_Trunk_Full",
      "support": 15,
      "rotation": 7
    },
    {
      "x": -15,
      "y": 60,
      "z": 9,
      "name": "Wood_Sallow_Trunk_Full",
      "support": 15,
      "rotation": 2
    },
    {
      "x": -15,
      "y": 61,
      "z": 9,
      "name": "Wood_Sallow_Branch_Long",
      "support": 15,
      "rotation": 2
    },
    {
      "x": -15,
      "y": 62,
      "z": 9,
      "name": "Wood_Sallow_Branch_Long",
      "support": 15,
      "rotation": 2
    },
    {
      "x": -15,
      "y": 63,
      "z": 9,
      "name": "Plant_Leaves_Beech",
      "support": 15,
      "rotation": 2
    },
    {
      "x": -15,
      "y": 68,
      "z": 9,
      "name": "Plant_Leaves_Beech",
      "support": 15,
      "rotation": 2
    },
    {
      "x": -15,
      "y": 69,
      "z": 9,
      "name": "Plant_Leaves_Beech",
      "support": 15,
      "rotation": 2
    },
    {
      "x": -15,
      "y": 6,
      "z": 10,
      "name": "Wood_Sallow_Roots",
      "rotation": 2
    },
    {
      "x": -15,
      "y": 7,
      "z": 10,
      "name": "Wood_Sallow_Trunk_Full",
      "support": 15,
      "rotation": 2
    },
    {
      "x": -15,
      "y": 8,
      "z": 10,
      "name": "Wood_Sallow_Trunk",
      "support": 15,
      "rotation": 2
    },
    {
      "x": -15,
      "y": 9,
      "z": 10,
      "name": "Wood_Sallow_Trunk",
      "support": 15,
      "rotation": 2
    },
    {
      "x": -15,
      "y": 10,
      "z": 10,
      "name": "Wood_Sallow_Trunk",
      "support": 15,
      "rotation": 2
    },
    {
      "x": -15,
      "y": 11,
      "z": 10,
      "name": "Wood_Sallow_Trunk",
      "support": 15,
      "rotation": 2
    },
    {
      "x": -15,
      "y": 12,
      "z": 10,
      "name": "Wood_Sallow_Trunk_Full",
      "support": 15,
      "rotation": 2
    },
    {
      "x": -15,
      "y": 29,
      "z": 10,
      "name": "Furniture_Crude_Platform",
      "rotation": 1
    },
    {
      "x": -15,
      "y": 30,
      "z": 10,
      "name": "*Wood_Softwood_Fence_State_Definitions_Corner",
      "rotation": 2
    },
    {
      "x": -15,
      "y": 31,
      "z": 10,
      "name": "*Wood_Softwood_Fence_State_Definitions_Corner",
      "rotation": 2
    },
    {
      "x": -15,
      "y": 32,
      "z": 10,
      "name": "*Wood_Softwood_Fence_State_Definitions_Corner",
      "rotation": 2
    },
    {
      "x": -15,
      "y": 33,
      "z": 10,
      "name": "*Wood_Goldenwood_Stairs_State_Definitions_Corner_Right",
      "rotation": 9
    },
    {
      "x": -15,
      "y": 34,
      "z": 10,
      "name": "*Wood_Softwood_Fence_State_Definitions_Corner",
      "rotation": 2
    },
    {
      "x": -15,
      "y": 35,
      "z": 10,
      "name": "*Wood_Softwood_Fence_State_Definitions_Corner",
      "rotation": 2
    },
    {
      "x": -15,
      "y": 36,
      "z": 10,
      "name": "*Wood_Softwood_Fence_State_Definitions_Corner",
      "rotation": 2
    },
    {
      "x": -15,
      "y": 37,
      "z": 10,
      "name": "*Wood_Goldenwood_Stairs_State_Definitions_Corner_Left",
      "rotation": 10
    },
    {
      "x": -15,
      "y": 38,
      "z": 10,
      "name": "*Wood_Hardwood_Fence_State_Definitions_Corner",
      "rotation": 2
    },
    {
      "x": -15,
      "y": 39,
      "z": 10,
      "name": "Wood_Hardwood_Beam"
    },
    {
      "x": -15,
      "y": 40,
      "z": 10,
      "name": "Wood_Hardwood_Beam"
    },
    {
      "x": -15,
      "y": 41,
      "z": 10,
      "name": "*Wood_Tropicalwood_Roof_State_Definitions_Corner_Left",
      "rotation": 3
    },
    {
      "x": -15,
      "y": 60,
      "z": 10,
      "name": "Wood_Sallow_Trunk_Full",
      "support": 15,
      "rotation": 7
    },
    {
      "x": -15,
      "y": 62,
      "z": 10,
      "name": "Plant_Leaves_Beech",
      "support": 15,
      "rotation": 2
    },
    {
      "x": -15,
      "y": 65,
      "z": 10,
      "name": "Wood_Sallow_Branch_Long",
      "support": 15,
      "rotation": 7
    },
    {
      "x": -15,
      "y": 5,
      "z": 11,
      "name": "Wood_Sallow_Roots",
      "rotation": 2
    },
    {
      "x": -15,
      "y": 6,
      "z": 11,
      "name": "Wood_Sallow_Trunk_Full",
      "support": 15,
      "rotation": 2
    },
    {
      "x": -15,
      "y": 7,
      "z": 11,
      "name": "Wood_Sallow_Trunk",
      "support": 15,
      "rotation": 2
    },
    {
      "x": -15,
      "y": 8,
      "z": 11,
      "name": "Wood_Sallow_Trunk",
      "support": 15,
      "rotation": 2
    },
    {
      "x": -15,
      "y": 9,
      "z": 11,
      "name": "Wood_Sallow_Trunk",
      "support": 15,
      "rotation": 2
    },
    {
      "x": -15,
      "y": 10,
      "z": 11,
      "name": "Wood_Sallow_Trunk",
      "support": 15,
      "rotation": 2
    },
    {
      "x": -15,
      "y": 11,
      "z": 11,
      "name": "Wood_Sallow_Trunk_Full",
      "support": 15,
      "rotation": 2
    },
    {
      "x": -15,
      "y": 33,
      "z": 11,
      "name": "Furniture_Crude_Platform"
    },
    {
      "x": -15,
      "y": 37,
      "z": 11,
      "name": "Wood_Goldenwood_Planks_Half",
      "rotation": 8
    },
    {
      "x": -15,
      "y": 38,
      "z": 11,
      "name": "Wood_Tropicalwood_Roof_Flat"
    },
    {
      "x": -15,
      "y": 40,
      "z": 11,
      "name": "Plant_Moss_Wall_Green_Dark",
      "support": 15,
      "rotation": 3
    },
    {
      "x": -15,
      "y": 65,
      "z": 11,
      "name": "Plant_Leaves_Beech",
      "support": 15,
      "rotation": 2
    },
    {
      "x": -15,
      "y": 66,
      "z": 11,
      "name": "Plant_Leaves_Beech",
      "support": 15,
      "rotation": 2
    },
    {
      "x": -15,
      "y": 33,
      "z": 12,
      "name": "Furniture_Crude_Platform"
    },
    {
      "x": -15,
      "y": 34,
      "z": 12,
      "name": "*Wood_Hardwood_Fence_State_Definitions_Corner"
    },
    {
      "x": -15,
      "y": 37,
      "z": 12,
      "name": "*Wood_Tropicalwood_Roof_Hollow_State_Definitions_Inverted_Corner_Right"
    },
    {
      "x": -15,
      "y": 33,
      "z": 13,
      "name": "Furniture_Crude_Platform",
      "rotation": 1
    },
    {
      "x": -15,
      "y": 34,
      "z": 13,
      "name": "*Wood_Hardwood_Fence_State_Definitions_Corner",
      "rotation": 2
    },
    {
      "x": -15,
      "y": 35,
      "z": 13,
      "name": "Wood_Hardwood_Beam"
    },
    {
      "x": -15,
      "y": 36,
      "z": 13,
      "name": "Wood_Hardwood_Beam"
    },
    {
      "x": -15,
      "y": 37,
      "z": 13,
      "name": "*Wood_Tropicalwood_Roof_State_Definitions_Corner_Left",
      "rotation": 3
    },
    {
      "x": -14,
      "y": 3,
      "z": -6,
      "name": "Wood_Sallow_Roots",
      "rotation": 2
    },
    {
      "x": -14,
      "y": 4,
      "z": -6,
      "name": "Wood_Sallow_Trunk_Full",
      "support": 15,
      "rotation": 2
    },
    {
      "x": -14,
      "y": 5,
      "z": -6,
      "name": "Wood_Sallow_Trunk",
      "support": 15,
      "rotation": 2
    },
    {
      "x": -14,
      "y": 6,
      "z": -6,
      "name": "Wood_Sallow_Trunk",
      "support": 15,
      "rotation": 2
    },
    {
      "x": -14,
      "y": 7,
      "z": -6,
      "name": "Wood_Sallow_Trunk",
      "support": 15,
      "rotation": 2
    },
    {
      "x": -14,
      "y": 8,
      "z": -6,
      "name": "Wood_Sallow_Trunk",
      "support": 15,
      "rotation": 2
    },
    {
      "x": -14,
      "y": 9,
      "z": -6,
      "name": "Wood_Sallow_Trunk_Full",
      "support": 15,
      "rotation": 2
    },
    {
      "x": -14,
      "y": 4,
      "z": -5,
      "name": "Wood_Sallow_Roots",
      "rotation": 2
    },
    {
      "x": -14,
      "y": 5,
      "z": -5,
      "name": "Wood_Sallow_Trunk_Full",
      "support": 15,
      "rotation": 2
    },
    {
      "x": -14,
      "y": 6,
      "z": -5,
      "name": "Wood_Sallow_Trunk",
      "support": 15,
      "rotation": 2
    },
    {
      "x": -14,
      "y": 7,
      "z": -5,
      "name": "Wood_Sallow_Trunk",
      "support": 15,
      "rotation": 2
    },
    {
      "x": -14,
      "y": 8,
      "z": -5,
      "name": "Wood_Sallow_Trunk",
      "support": 15,
      "rotation": 2
    },
    {
      "x": -14,
      "y": 9,
      "z": -5,
      "name": "Wood_Sallow_Trunk_Full",
      "support": 15,
      "rotation": 2
    },
    {
      "x": -14,
      "y": 37,
      "z": -4,
      "name": "*Wood_Tropicalwood_Roof_Hollow_State_Definitions_Corner_Right",
      "rotation": 3
    },
    {
      "x": -14,
      "y": 10,
      "z": -3,
      "name": "Plant_Moss_Wall_Green_Dark",
      "support": 15,
      "rotation": 3
    },
    {
      "x": -14,
      "y": 33,
      "z": -3,
      "name": "Furniture_Crude_Platform",
      "rotation": 1
    },
    {
      "x": -14,
      "y": 34,
      "z": -3,
      "name": "Wood_Hardwood_Fence",
      "rotation": 2
    },
    {
      "x": -14,
      "y": 37,
      "z": -3,
      "name": "*Wood_Tropicalwood_Roof_Hollow_State_Definitions_Inverted_Corner_Right",
      "rotation": 3
    },
    {
      "x": -14,
      "y": 58,
      "z": -3,
      "name": "Plant_Leaves_Beech",
      "support": 15,
      "rotation": 2
    },
    {
      "x": -14,
      "y": 59,
      "z": -3,
      "name": "Plant_Leaves_Beech",
      "support": 15,
      "rotation": 2
    },
    {
      "x": -14,
      "y": 33,
      "z": -2,
      "name": "Furniture_Crude_Platform"
    },
    {
      "x": -14,
      "y": 37,
      "z": -2,
      "name": "Wood_Goldenwood_Planks_Half",
      "rotation": 8
    },
    {
      "x": -14,
      "y": 38,
      "z": -2,
      "name": "Wood_Tropicalwood_Roof_Flat",
      "rotation": 2
    },
    {
      "x": -14,
      "y": 57,
      "z": -2,
      "name": "Plant_Leaves_Beech",
      "support": 15,
      "rotation": 2
    },
    {
      "x": -14,
      "y": 58,
      "z": -2,
      "name": "Wood_Sallow_Branch_Corner",
      "support": 15,
      "rotation": 3
    },
    {
      "x": -14,
      "y": 59,
      "z": -2,
      "name": "Wood_Sallow_Branch_Long",
      "support": 15,
      "rotation": 2
    },
    {
      "x": -14,
      "y": 60,
      "z": -2,
      "name": "Plant_Leaves_Beech",
      "support": 15,
      "rotation": 2
    },
    {
      "x": -14,
      "y": 62,
      "z": -2,
      "name": "Plant_Leaves_Beech",
      "support": 15,
      "rotation": 2
    },
    {
      "x": -14,
      "y": 63,
      "z": -2,
      "name": "Plant_Leaves_Beech",
      "support": 15,
      "rotation": 2
    },
    {
      "x": -14,
      "y": 29,
      "z": -1,
      "name": "Furniture_Crude_Platform"
    },
    {
      "x": -14,
      "y": 30,
      "z": -1,
      "name": "*Wood_Softwood_Fence_State_Definitions_Corner",
      "rotation": 1
    },
    {
      "x": -14,
      "y": 31,
      "z": -1,
      "name": "*Wood_Softwood_Fence_State_Definitions_Corner",
      "rotation": 1
    },
    {
      "x": -14,
      "y": 32,
      "z": -1,
      "name": "*Wood_Softwood_Fence_State_Definitions_Corner",
      "rotation": 1
    },
    {
      "x": -14,
      "y": 33,
      "z": -1,
      "name": "*Wood_Goldenwood_Stairs_State_Definitions_Corner_Left",
      "rotation": 9
    },
    {
      "x": -14,
      "y": 34,
      "z": -1,
      "name": "*Wood_Softwood_Fence_State_Definitions_Corner",
      "rotation": 1
    },
    {
      "x": -14,
      "y": 35,
      "z": -1,
      "name": "*Wood_Softwood_Fence_State_Definitions_Corner",
      "rotation": 1
    },
    {
      "x": -14,
      "y": 36,
      "z": -1,
      "name": "*Wood_Softwood_Fence_State_Definitions_Corner",
      "rotation": 1
    },
    {
      "x": -14,
      "y": 37,
      "z": -1,
      "name": "*Wood_Goldenwood_Stairs_State_Definitions_Corner_Left",
      "rotation": 9
    },
    {
      "x": -14,
      "y": 38,
      "z": -1,
      "name": "*Wood_Hardwood_Fence_State_Definitions_Corner",
      "rotation": 1
    },
    {
      "x": -14,
      "y": 41,
      "z": -1,
      "name": "*Wood_Tropicalwood_Roof_Hollow_State_Definitions_Corner_Left",
      "rotation": 2
    },
    {
      "x": -14,
      "y": 58,
      "z": -1,
      "name": "Plant_Leaves_Beech",
      "support": 15,
      "rotation": 2
    },
    {
      "x": -14,
      "y": 59,
      "z": -1,
      "name": "Plant_Leaves_Beech",
      "support": 15,
      "rotation": 2
    },
    {
      "x": -14,
      "y": 62,
      "z": -1,
      "name": "Plant_Leaves_Beech",
      "support": 15,
      "rotation": 2
    },
    {
      "x": -14,
      "y": 65,
      "z": -1,
      "name": "Plant_Leaves_Beech",
      "support": 15,
      "rotation": 2
    },
    {
      "x": -14,
      "y": 29,
      "z": 0,
      "name": "Furniture_Crude_Platform",
      "rotation": 1
    },
    {
      "x": -14,
      "y": 30,
      "z": 0,
      "name": "*Wood_Softwood_Fence_State_Definitions_Corner",
      "rotation": 3
    },
    {
      "x": -14,
      "y": 31,
      "z": 0,
      "name": "*Wood_Softwood_Fence_State_Definitions_Corner",
      "rotation": 3
    },
    {
      "x": -14,
      "y": 32,
      "z": 0,
      "name": "*Wood_Softwood_Fence_State_Definitions_Corner",
      "rotation": 3
